File: XRD/EFRW_Parent/PB_Ge220_2.5SS_500umDS_RS1_Rod_2.5SS_Hypix1D_Eurofer_Weld6_Parent.ras
*RAS_DATA_START
*RAS_HEADER_START
*DISP_FMT_X "%.3f"
*DISP_FMT_Y "%.0f"
*DISP_FULLSCALE "356.9269752793"
*DISP_LINE_COLOR "255.0000000000"
*DISP_LINE_STYLE "0.0000000000"
*DISP_LINE_WIDTH "0.2500000000"
*DISP_NOTE "Collected Data-264"
*DISP_OFFSET_Y "0.0000000000"
*DISP_PEAKSEARCH_UNIT_Y "cps"
*DISP_RANGE_BOTTOM "0.0000000000"
*DISP_RANGE_LEFT "40.0000000000"
*DISP_RANGE_LOGCUTOFF "0.0100000000"
*DISP_RANGE_RIGHT "130.0000000000"
*DISP_RANGE_TOP "356.9269752793"
*DISP_SCALE_MODE_Y "0.0000000000"
*DISP_TAB_NAME "Theta/2-Theta"
*DISP_TITLE_Y "Intensity"
*DISP_UNIT_Y "cps"
*DISP_WINDOW_NAME "MSG_MACROENGINE"
*FILE_COMMENT " "
*FILE_MD5 ""
*FILE_MEMO " "
*FILE_OPERATOR "Administrator"
*FILE_PART_ID "MEAS_KHP2_00061"
*FILE_SAMPLE " "
*FILE_TYPE "RAS_RAW"
*FILE_USERGROUP "System Manager"
*FILE_VERSION "1.0000000000"
*HW_ATTACHMENT_ID "ATT0021"
*HW_ATTACHMENT_NAME "XY-20mm|XY-20mm"
*HW_COUNTER_ID-0 "CUT0041"
*HW_COUNTER_ID-1 "CUT0051"
*HW_COUNTER_ID-2 "CUT0020"
*HW_COUNTER_ID-3 "CSL0021"
*HW_COUNTER_ID-4 "CMC0021"
*HW_COUNTER_NAME-0 "D/teX Ultra 250|D/teX Ultra 250"
*HW_COUNTER_NAME-1 "HyPix 3000(H)|HyPix 3000(H)"
*HW_COUNTER_NAME-2 "None|None"
*HW_COUNTER_NAME-3 "BBM|BBM"
*HW_COUNTER_NAME-4 "検出器モノクロメータ|Detector monochromator"
*HW_COUNTER_SELECT_NAME "HyPix 3000(H)|HyPix 3000(H)"
*HW_GONIOMETER_ID "GON0024"
*HW_GONIOMETER_NAME "SmartLab(In-plane)|SmartLab(In-plane)"
*HW_GONIOMETER_RADIUS-0 "90.0"
*HW_GONIOMETER_RADIUS-1 "114.0"
*HW_GONIOMETER_RADIUS-2 "190.0"
*HW_GONIOMETER_RADIUS-3 "300.0"
*HW_GONIOMETER_RADIUS-4 "187.0"
*HW_GONIOMETER_RADIUS-5 "300.0"
*HW_GONIOMETER_RADIUS-6 "113.0"
*HW_GONIOMETER_RADIUS-7 "331.0"
*HW_I_OPT_ID-0 "CBO0021"
*HW_I_OPT_ID-1 "ICR0021"
*HW_I_OPT_ID-2 "ISL0021"
*HW_I_OPT_ID-3 "ISO0021"
*HW_I_OPT_ID-4 "IAD0021"
*HW_I_OPT_ID-5 "IPR0001"
*HW_I_OPT_NAME-0 "CBOユニット|CBO unit"
*HW_I_OPT_NAME-1 "標準入射光学ユニット|Standard incident optical unit"
*HW_I_OPT_NAME-2 "標準入射スリットボックス|Standard incident slit box"
*HW_I_OPT_NAME-3 "入射平行スリット|Incident parallel slit"
*HW_I_OPT_NAME-4 "長手制限スリット|Length limiting slit"
*HW_I_OPT_NAME-5 "None|None"
*HW_R_ATTENUATER_AUTOMODE "0"
*HW_R_OPT_ID-0 "RSS0022"
*HW_R_OPT_ID-1 "RCR0022"
*HW_R_OPT_ID-2 "RSO0021"
*HW_R_OPT_ID-3 "RRS0022"
*HW_R_OPT_ID-4 "ATN0020"
*HW_R_OPT_ID-5 "RFL0021"
*HW_R_OPT_ID-6 "RAD0021"
*HW_R_OPT_NAME-0 "受光スリットボックス1(Zr軸付)|Receiving slit box # 1 (w/ Zr Axis)"
*HW_R_OPT_NAME-1 "標準受光光学ユニット1|Standard receiving unit # 1"
*HW_R_OPT_NAME-2 "標準受光光学ユニット2|Standard receiving optical unit # 2"
*HW_R_OPT_NAME-3 "仮想受光スリット2|Virtual receiving slit #2"
*HW_R_OPT_NAME-4 "無し|None"
*HW_R_OPT_NAME-5 "Cu Kβ|Cu K-beta"
*HW_R_OPT_NAME-6 "調整用受光スリット|Alignment receiving slit"
*HW_SAMPLE_HOLDER_ID "SMP0021"
*HW_SAMPLE_HOLDER_NAME "χφZクレードル|Chi phi Z cradle"
*HW_XG_CURRENT_MAX "40"
*HW_XG_CURRENT_MIN "2"
*HW_XG_CURRENT_RESOLUTION "1"
*HW_XG_CURRENT_UNIT "mA"
*HW_XG_FOCUS "0.4mm x 8mm"
*HW_XG_FOCUS_TYPE "Fine"
*HW_XG_ID "1200"
*HW_XG_NAME "3kW 封入管(ID:1200)|3kW Sealed tube(ID:1200)"
*HW_XG_TARGET_ATOMIC_NUMBER "29.0000000000"
*HW_XG_TARGET_NAME "Cu"
*HW_XG_TYPE "Hermetic"
*HW_XG_VOLTAGE_MAX "40"
*HW_XG_VOLTAGE_MIN "20"
*HW_XG_VOLTAGE_RESOLUTION "1"
*HW_XG_VOLTAGE_UNIT "kV"
*HW_XG_WATT_MAX "1.500"
*HW_XG_WATT_UNIT "kW"
*HW_XG_WAVE_LENGTH_ALPHA1 "1.540593"
*HW_XG_WAVE_LENGTH_ALPHA2 "1.544414"
*HW_XG_WAVE_LENGTH_BETA "1.392250"
*MEAS_COND_AXIS_NAME-0 "Theta/2-Theta"
*MEAS_COND_AXIS_NAME-1 "2-Theta"
*MEAS_COND_AXIS_NAME-2 "Omega"
*MEAS_COND_AXIS_NAME-3 "Chi"
*MEAS_COND_AXIS_NAME-4 "Phi"
*MEAS_COND_AXIS_NAME-5 "Z"
*MEAS_COND_AXIS_NAME-6 "X"
*MEAS_COND_AXIS_NAME-7 "Y"
*MEAS_COND_AXIS_NAME-8 "2-Theta/Omega"
*MEAS_COND_AXIS_NAME-9 "2-ThetaChi"
*MEAS_COND_AXIS_NAME-10 "2-ThetaChi/Phi"
*MEAS_COND_AXIS_NAME-11 "Alpha"
*MEAS_COND_AXIS_NAME-12 "Beta"
*MEAS_COND_AXIS_NAME-13 "Theta_s"
*MEAS_COND_AXIS_NAME-14 "Theta_d"
*MEAS_COND_AXIS_NAME-15 "Ts"
*MEAS_COND_AXIS_NAME-16 "CBO selection slit"
*MEAS_COND_AXIS_NAME-17 "M"
*MEAS_COND_AXIS_NAME-18 "Incident parallel slit"
*MEAS_COND_AXIS_NAME-19 "Incident slit"
*MEAS_COND_AXIS_NAME-20 ""
*MEAS_COND_AXIS_NAME-21 "Zs"
*MEAS_COND_AXIS_NAME-22 "Incident optical device"
*MEAS_COND_AXIS_NAME-23 "Omega_m"
*MEAS_COND_AXIS_NAME-24 "Length limiting slit"
*MEAS_COND_AXIS_NAME-25 "Center slit"
*MEAS_COND_AXIS_NAME-26 "Filter"
*MEAS_COND_AXIS_NAME-27 "Receiving slit # 1"
*MEAS_COND_AXIS_NAME-28 "Receiving slit # 2"
*MEAS_COND_AXIS_NAME-29 "Receiving optical device"
*MEAS_COND_AXIS_NAME-30 "Receiving parallel slit"
*MEAS_COND_AXIS_NAME-31 "Alignment receiving slit"
*MEAS_COND_AXIS_NAME-32 ""
*MEAS_COND_AXIS_NAME-33 ""
*MEAS_COND_AXIS_NAME-34 "Zd"
*MEAS_COND_AXIS_NAME-35 "Attenuator"
*MEAS_COND_AXIS_NAME-36 "Diffracted beam monochromator"
*MEAS_COND_AXIS_NAME-37 "Monochromator slit"
*MEAS_COND_AXIS_NAME-38 "2-ThetaB"
*MEAS_COND_AXIS_NAME-39 ""
*MEAS_COND_AXIS_NAME-40 ""
*MEAS_COND_AXIS_NAME-41 "Zr"
*MEAS_COND_AXIS_NAME-42 "Primary beam"
*MEAS_COND_AXIS_NAME_INTERNAL-0 "TwoThetaTheta"
*MEAS_COND_AXIS_NAME_INTERNAL-1 "TwoTheta"
*MEAS_COND_AXIS_NAME_INTERNAL-2 "Omega"
*MEAS_COND_AXIS_NAME_INTERNAL-3 "Chi"
*MEAS_COND_AXIS_NAME_INTERNAL-4 "Phi"
*MEAS_COND_AXIS_NAME_INTERNAL-5 "Z"
*MEAS_COND_AXIS_NAME_INTERNAL-6 "X"
*MEAS_COND_AXIS_NAME_INTERNAL-7 "Y"
*MEAS_COND_AXIS_NAME_INTERNAL-8 "TwoThetaOmega"
*MEAS_COND_AXIS_NAME_INTERNAL-9 "TwoThetaChi"
*MEAS_COND_AXIS_NAME_INTERNAL-10 "TwoThetaChiPhi"
*MEAS_COND_AXIS_NAME_INTERNAL-11 "Alpha"
*MEAS_COND_AXIS_NAME_INTERNAL-12 "Beta"
*MEAS_COND_AXIS_NAME_INTERNAL-13 "ThetaS"
*MEAS_COND_AXIS_NAME_INTERNAL-14 "ThetaD"
*MEAS_COND_AXIS_NAME_INTERNAL-15 "Ts"
*MEAS_COND_AXIS_NAME_INTERNAL-16 "CBO"
*MEAS_COND_AXIS_NAME_INTERNAL-17 "CBO-M"
*MEAS_COND_AXIS_NAME_INTERNAL-18 "IncidentSollerSlit"
*MEAS_COND_AXIS_NAME_INTERNAL-19 "IncidentSlitBox"
*MEAS_COND_AXIS_NAME_INTERNAL-20 "IncidentSlitBox-_Axis"
*MEAS_COND_AXIS_NAME_INTERNAL-21 "Zs"
*MEAS_COND_AXIS_NAME_INTERNAL-22 "IncidentMonochromator"
*MEAS_COND_AXIS_NAME_INTERNAL-23 "IncidentMonochromator-OmegaM"
*MEAS_COND_AXIS_NAME_INTERNAL-24 "IncidentAxdSlit"
*MEAS_COND_AXIS_NAME_INTERNAL-25 "CenterSlit"
*MEAS_COND_AXIS_NAME_INTERNAL-26 "Filter"
*MEAS_COND_AXIS_NAME_INTERNAL-27 "ReceivingSlitBox1"
*MEAS_COND_AXIS_NAME_INTERNAL-28 "ReceivingSlitBox2"
*MEAS_COND_AXIS_NAME_INTERNAL-29 "ReceivingOptics"
*MEAS_COND_AXIS_NAME_INTERNAL-30 "ReceivingSollerSlit"
*MEAS_COND_AXIS_NAME_INTERNAL-31 "ReceivingAxdSlit"
*MEAS_COND_AXIS_NAME_INTERNAL-32 "ReceivingSlitBox1-_Axis"
*MEAS_COND_AXIS_NAME_INTERNAL-33 "ReceivingSlitBox2-_Axis"
*MEAS_COND_AXIS_NAME_INTERNAL-34 "ReceivingSlitBox2-Zd"
*MEAS_COND_AXIS_NAME_INTERNAL-35 "Attenuator"
*MEAS_COND_AXIS_NAME_INTERNAL-36 "CounterMonochromator"
*MEAS_COND_AXIS_NAME_INTERNAL-37 "CounterSlit"
*MEAS_COND_AXIS_NAME_INTERNAL-38 "TwoThetaB"
*MEAS_COND_AXIS_NAME_INTERNAL-39 "AlphaR"
*MEAS_COND_AXIS_NAME_INTERNAL-40 "BetaR"
*MEAS_COND_AXIS_NAME_INTERNAL-41 "ReceivingSlitBox1-Zr"
*MEAS_COND_AXIS_NAME_INTERNAL-42 "IncidentPrimary"
*MEAS_COND_AXIS_NAME_MAGICNO-0 "83951616.0000000000"
*MEAS_COND_AXIS_NAME_MAGICNO-1 "268632064.0000000000"
*MEAS_COND_AXIS_NAME_MAGICNO-2 "268500992.0000000000"
*MEAS_COND_AXIS_NAME_MAGICNO-3 "268500992.0000000000"
*MEAS_COND_AXIS_NAME_MAGICNO-4 "268500992.0000000000"
*MEAS_COND_AXIS_NAME_MAGICNO-5 "285278208.0000000000"
*MEAS_COND_AXIS_NAME_MAGICNO-6 "268500992.0000000000"
*MEAS_COND_AXIS_NAME_MAGICNO-7 "268500992.0000000000"
*MEAS_COND_AXIS_NAME_MAGICNO-8 "83951616.0000000000"
*MEAS_COND_AXIS_NAME_MAGICNO-9 "268632064.0000000000"
*MEAS_COND_AXIS_NAME_MAGICNO-10 "83951616.0000000000"
*MEAS_COND_AXIS_NAME_MAGICNO-11 "17039360.0000000000"
*MEAS_COND_AXIS_NAME_MAGICNO-12 "17039360.0000000000"
*MEAS_COND_AXIS_NAME_MAGICNO-13 "131072.0000000000"
*MEAS_COND_AXIS_NAME_MAGICNO-14 "131072.0000000000"
*MEAS_COND_AXIS_NAME_MAGICNO-15 "318898176.0000000000"
*MEAS_COND_AXIS_NAME_MAGICNO-16 "20971521.0000000000"
*MEAS_COND_AXIS_NAME_MAGICNO-17 "285343744.0000000000"
*MEAS_COND_AXIS_NAME_MAGICNO-18 "20971521.0000000000"
*MEAS_COND_AXIS_NAME_MAGICNO-19 "22020097.0000000000"
*MEAS_COND_AXIS_NAME_MAGICNO-20 "25165824.0000000000"
*MEAS_COND_AXIS_NAME_MAGICNO-21 "318898176.0000000000"
*MEAS_COND_AXIS_NAME_MAGICNO-22 "20971521.0000000000"
*MEAS_COND_AXIS_NAME_MAGICNO-23 "285343744.0000000000"
*MEAS_COND_AXIS_NAME_MAGICNO-24 "20971521.0000000000"
*MEAS_COND_AXIS_NAME_MAGICNO-25 "20971521.0000000000"
*MEAS_COND_AXIS_NAME_MAGICNO-26 "20971521.0000000000"
*MEAS_COND_AXIS_NAME_MAGICNO-27 "23068673.0000000000"
*MEAS_COND_AXIS_NAME_MAGICNO-28 "23068673.0000000000"
*MEAS_COND_AXIS_NAME_MAGICNO-29 "20971521.0000000000"
*MEAS_COND_AXIS_NAME_MAGICNO-30 "20971521.0000000000"
*MEAS_COND_AXIS_NAME_MAGICNO-31 "20971521.0000000000"
*MEAS_COND_AXIS_NAME_MAGICNO-32 "25165824.0000000000"
*MEAS_COND_AXIS_NAME_MAGICNO-33 "25165824.0000000000"
*MEAS_COND_AXIS_NAME_MAGICNO-34 "285343744.0000000000"
*MEAS_COND_AXIS_NAME_MAGICNO-35 "0.0000000000"
*MEAS_COND_AXIS_NAME_MAGICNO-36 "20971521.0000000000"
*MEAS_COND_AXIS_NAME_MAGICNO-37 "20971521.0000000000"
*MEAS_COND_AXIS_NAME_MAGICNO-38 "17039360.0000000000"
*MEAS_COND_AXIS_NAME_MAGICNO-39 "8388608.0000000000"
*MEAS_COND_AXIS_NAME_MAGICNO-40 "8388608.0000000000"
*MEAS_COND_AXIS_NAME_MAGICNO-41 "285343744.0000000000"
*MEAS_COND_AXIS_NAME_MAGICNO-42 "20971521.0000000000"
*MEAS_COND_AXIS_OFFSET-0 "-"
*MEAS_COND_AXIS_OFFSET-1 "0.9848000000"
*MEAS_COND_AXIS_OFFSET-2 "1.2091000000"
*MEAS_COND_AXIS_OFFSET-3 "0.0000000000"
*MEAS_COND_AXIS_OFFSET-4 "0.0000000000"
*MEAS_COND_AXIS_OFFSET-5 "-"
*MEAS_COND_AXIS_OFFSET-6 "0.0000000000"
*MEAS_COND_AXIS_OFFSET-7 "0.0000000000"
*MEAS_COND_AXIS_OFFSET-8 "-"
*MEAS_COND_AXIS_OFFSET-9 "0.0000000000"
*MEAS_COND_AXIS_OFFSET-10 "-"
*MEAS_COND_AXIS_OFFSET-11 "-"
*MEAS_COND_AXIS_OFFSET-12 "-"
*MEAS_COND_AXIS_OFFSET-13 "1.2091000000"
*MEAS_COND_AXIS_OFFSET-14 "-0.2243000000"
*MEAS_COND_AXIS_OFFSET-15 "-"
*MEAS_COND_AXIS_OFFSET-16 "-"
*MEAS_COND_AXIS_OFFSET-17 "-"
*MEAS_COND_AXIS_OFFSET-18 "-"
*MEAS_COND_AXIS_OFFSET-19 "-"
*MEAS_COND_AXIS_OFFSET-20 "-"
*MEAS_COND_AXIS_OFFSET-21 "-"
*MEAS_COND_AXIS_OFFSET-22 "-"
*MEAS_COND_AXIS_OFFSET-23 "-"
*MEAS_COND_AXIS_OFFSET-24 "-"
*MEAS_COND_AXIS_OFFSET-25 "-"
*MEAS_COND_AXIS_OFFSET-26 "-"
*MEAS_COND_AXIS_OFFSET-27 "-"
*MEAS_COND_AXIS_OFFSET-28 "-"
*MEAS_COND_AXIS_OFFSET-29 "-"
*MEAS_COND_AXIS_OFFSET-30 "-"
*MEAS_COND_AXIS_OFFSET-31 "-"
*MEAS_COND_AXIS_OFFSET-32 "-"
*MEAS_COND_AXIS_OFFSET-33 "-"
*MEAS_COND_AXIS_OFFSET-34 "-"
*MEAS_COND_AXIS_OFFSET-35 "-"
*MEAS_COND_AXIS_OFFSET-36 "-"
*MEAS_COND_AXIS_OFFSET-37 "-"
*MEAS_COND_AXIS_OFFSET-38 "-"
*MEAS_COND_AXIS_OFFSET-39 "0.0000000000"
*MEAS_COND_AXIS_OFFSET-40 "0.0000000000"
*MEAS_COND_AXIS_OFFSET-41 "-"
*MEAS_COND_AXIS_OFFSET-42 "-"
*MEAS_COND_AXIS_POSITION-0 "40.0000000000"
*MEAS_COND_AXIS_POSITION-1 "40.0000000000"
*MEAS_COND_AXIS_POSITION-2 "20.0000000000"
*MEAS_COND_AXIS_POSITION-3 "0.0000000000"
*MEAS_COND_AXIS_POSITION-4 "0.0000000000"
*MEAS_COND_AXIS_POSITION-5 "-1.6089000000"
*MEAS_COND_AXIS_POSITION-6 "-0.0945000000"
*MEAS_COND_AXIS_POSITION-7 "-7.7000000000"
*MEAS_COND_AXIS_POSITION-8 "40.0000000000"
*MEAS_COND_AXIS_POSITION-9 "0.0000000000"
*MEAS_COND_AXIS_POSITION-10 "0.0000000000"
*MEAS_COND_AXIS_POSITION-11 "90.0000000000"
*MEAS_COND_AXIS_POSITION-12 "0.0000000000"
*MEAS_COND_AXIS_POSITION-13 "20.0000000000"
*MEAS_COND_AXIS_POSITION-14 "20.0000000000"
*MEAS_COND_AXIS_POSITION-15 "-5.7342500000"
*MEAS_COND_AXIS_POSITION-16 "PB"
*MEAS_COND_AXIS_POSITION-17 "0.0000000000"
*MEAS_COND_AXIS_POSITION-18 "Soller_slit_2.5deg_s"
*MEAS_COND_AXIS_POSITION-19 "1.000mm"
*MEAS_COND_AXIS_POSITION-20 "1.0000000000"
*MEAS_COND_AXIS_POSITION-21 "-1.4943800000"
*MEAS_COND_AXIS_POSITION-22 "Ge(220)x2"
*MEAS_COND_AXIS_POSITION-23 "0.0000000000"
*MEAS_COND_AXIS_POSITION-24 "0.5mm"
*MEAS_COND_AXIS_POSITION-25 "None"
*MEAS_COND_AXIS_POSITION-26 "None"
*MEAS_COND_AXIS_POSITION-27 "20.000mm"
*MEAS_COND_AXIS_POSITION-28 "38.500mm"
*MEAS_COND_AXIS_POSITION-29 "PSA_open"
*MEAS_COND_AXIS_POSITION-30 "Soller_slit_2.5deg"
*MEAS_COND_AXIS_POSITION-31 "None"
*MEAS_COND_AXIS_POSITION-32 "20.0000000000"
*MEAS_COND_AXIS_POSITION-33 "38.5000000000"
*MEAS_COND_AXIS_POSITION-34 "0.0000000000"
*MEAS_COND_AXIS_POSITION-35 "-"
*MEAS_COND_AXIS_POSITION-36 "No_unit"
*MEAS_COND_AXIS_POSITION-37 "None"
*MEAS_COND_AXIS_POSITION-38 "40.0000000000"
*MEAS_COND_AXIS_POSITION-39 "0.0000000000"
*MEAS_COND_AXIS_POSITION-40 "0.0000000000"
*MEAS_COND_AXIS_POSITION-41 "0.1090600000"
*MEAS_COND_AXIS_POSITION-42 "None"
*MEAS_COND_AXIS_UNIT-0 "deg"
*MEAS_COND_AXIS_UNIT-1 "deg"
*MEAS_COND_AXIS_UNIT-2 "deg"
*MEAS_COND_AXIS_UNIT-3 "deg"
*MEAS_COND_AXIS_UNIT-4 "deg"
*MEAS_COND_AXIS_UNIT-5 "mm"
*MEAS_COND_AXIS_UNIT-6 "mm"
*MEAS_COND_AXIS_UNIT-7 "mm"
*MEAS_COND_AXIS_UNIT-8 "deg"
*MEAS_COND_AXIS_UNIT-9 "deg"
*MEAS_COND_AXIS_UNIT-10 "deg"
*MEAS_COND_AXIS_UNIT-11 "deg"
*MEAS_COND_AXIS_UNIT-12 "deg"
*MEAS_COND_AXIS_UNIT-13 "deg"
*MEAS_COND_AXIS_UNIT-14 "deg"
*MEAS_COND_AXIS_UNIT-15 "mm"
*MEAS_COND_AXIS_UNIT-16 ""
*MEAS_COND_AXIS_UNIT-17 "pulse"
*MEAS_COND_AXIS_UNIT-18 ""
*MEAS_COND_AXIS_UNIT-19 ""
*MEAS_COND_AXIS_UNIT-20 "mm"
*MEAS_COND_AXIS_UNIT-21 "mm"
*MEAS_COND_AXIS_UNIT-22 ""
*MEAS_COND_AXIS_UNIT-23 "pulse"
*MEAS_COND_AXIS_UNIT-24 ""
*MEAS_COND_AXIS_UNIT-25 ""
*MEAS_COND_AXIS_UNIT-26 ""
*MEAS_COND_AXIS_UNIT-27 ""
*MEAS_COND_AXIS_UNIT-28 ""
*MEAS_COND_AXIS_UNIT-29 ""
*MEAS_COND_AXIS_UNIT-30 ""
*MEAS_COND_AXIS_UNIT-31 ""
*MEAS_COND_AXIS_UNIT-32 "mm"
*MEAS_COND_AXIS_UNIT-33 "mm"
*MEAS_COND_AXIS_UNIT-34 "mm"
*MEAS_COND_AXIS_UNIT-35 ""
*MEAS_COND_AXIS_UNIT-36 ""
*MEAS_COND_AXIS_UNIT-37 ""
*MEAS_COND_AXIS_UNIT-38 "deg"
*MEAS_COND_AXIS_UNIT-39 "deg"
*MEAS_COND_AXIS_UNIT-40 "deg"
*MEAS_COND_AXIS_UNIT-41 "mm"
*MEAS_COND_AXIS_UNIT-42 ""
*MEAS_COND_COUNTER_CNTLOSS_CORR "0.0000000000"
*MEAS_COND_COUNTER_TAUDIFF "0.0000000000"
*MEAS_COND_COUNTER_TAUINT "0.0000000000"
*MEAS_COND_COUNTER_TEMP_CONDITION "NORMAL"
*MEAS_COND_IRRADIATION_MODE "OFF"
*MEAS_COND_IRRADIATION_WIDTH ""
*MEAS_COND_OPT_ATTR "High resolution parallel beam Ge(220)x2/RS"
*MEAS_COND_OPT_NAME "@High resolution PB-Ge(220)x2"
*MEAS_COND_UNSYMMETRIC_MODE "OFF"
*MEAS_COND_XG_CURRENT "30.0000000000"
*MEAS_COND_XG_VOLTAGE "40.0000000000"
*MEAS_COND_XG_WAVE_TYPE "Ka1"
*MEAS_DATA_COUNT "1801.0000000000"
*MEAS_SCAN_AXIS_X "Theta/2-Theta"
*MEAS_SCAN_AXIS_X_INTERNAL "TwoThetaTheta"
*MEAS_SCAN_END_TIME "03/11/21 09:26:41"
*MEAS_SCAN_MODE "CONTINUOUS"
*MEAS_SCAN_MONITOR "0"
*MEAS_SCAN_RESOLUTION_X "0.0002"
*MEAS_SCAN_SPEED "0.503240"
*MEAS_SCAN_SPEED_UNIT "deg/min"
*MEAS_SCAN_SPEED_USER "0.5"
*MEAS_SCAN_START "40.0000000000"
*MEAS_SCAN_START_TIME "03/11/21 06:11:52"
*MEAS_SCAN_STEP "0.0500000000"
*MEAS_SCAN_STOP "130.0000000000"
*MEAS_SCAN_UNIT_X "deg"
*MEAS_SCAN_UNIT_Y "counts"
*RAS_HEADER_END
*RAS_INT_START
40.0000 26.5370 1.0000
40.1000 28.5454 1.0000
40.2000 30.5292 1.0000
40.3000 23.2752 1.0000
40.4000 33.8884 1.0000
40.5000 28.2469 1.0000
40.6000 37.5145 1.0000
40.7000 38.3013 1.0000
40.8000 29.0587 1.0000
40.9000 31.0875 1.0000
41.0000 35.0629 1.0000
41.1000 38.5480 1.0000
41.2000 22.5885 1.0000
41.3000 25.9344 1.0000
41.4000 25.3509 1.0000
41.5000 38.2049 1.0000
41.6000 20.5314 1.0000
41.7000 37.6183 1.0000
41.8000 33.3141 1.0000
41.9000 34.7343 1.0000
42.0000 25.9433 1.0000
42.1000 34.1997 1.0000
42.2000 33.0080 1.0000
42.3000 18.7124 1.0000
42.4000 37.4302 1.0000
42.5000 36.7600 1.0000
42.6000 23.9110 1.0000
42.7000 33.4619 1.0000
42.8000 19.6128 1.0000
42.9000 26.6657 1.0000
43.0000 33.0246 1.0000
43.1000 27.4182 1.0000
43.2000 34.6599 1.0000
43.3000 40.7497 1.0000
43.4000 27.4094 1.0000
43.5000 36.5933 1.0000
43.6000 30.4502 1.0000
43.7000 35.5027 1.0000
43.8000 22.6590 1.0000
43.9000 29.7266 1.0000
44.0000 47.8855 1.0000
44.1000 38.7791 1.0000
44.2000 57.0057 1.0000
44.3000 97.7565 1.0000
44.4000 240.5769 1.0000
44.5000 1271.1493 1.0000
44.6000 1454.9343 1.0000
44.7000 350.4905 1.0000
44.8000 107.9415 1.0000
44.9000 54.9396 1.0000
45.0000 40.6144 1.0000
45.1000 24.1069 1.0000
45.2000 36.3088 1.0000
45.3000 41.4439 1.0000
45.4000 22.5307 1.0000
45.5000 30.7840 1.0000
45.6000 32.1673 1.0000
45.7000 25.2967 1.0000
45.8000 27.3886 1.0000
45.9000 32.8089 1.0000
46.0000 25.5817 1.0000
46.1000 30.9486 1.0000
46.2000 20.6155 1.0000
46.3000 23.7597 1.0000
46.4000 38.2075 1.0000
46.5000 27.9892 1.0000
46.6000 31.3629 1.0000
46.7000 18.4401 1.0000
46.8000 24.5078 1.0000
46.9000 32.8371 1.0000
47.0000 26.6987 1.0000
47.1000 18.3541 1.0000
47.2000 36.4503 1.0000
47.3000 26.4770 1.0000
47.4000 28.8909 1.0000
47.5000 25.6441 1.0000
47.6000 19.2660 1.0000
47.7000 25.3245 1.0000
47.8000 30.2289 1.0000
47.9000 33.2406 1.0000
48.0000 22.0437 1.0000
48.1000 29.8058 1.0000
48.2000 20.4901 1.0000
48.3000 20.9104 1.0000
48.4000 31.7083 1.0000
48.5000 19.2494 1.0000
48.6000 28.8681 1.0000
48.7000 25.2970 1.0000
48.8000 34.7075 1.0000
48.9000 21.9969 1.0000
49.0000 21.5771 1.0000
49.1000 22.3481 1.0000
49.2000 34.6178 1.0000
49.3000 22.8354 1.0000
49.4000 24.6507 1.0000
49.5000 22.5039 1.0000
49.6000 26.4120 1.0000
49.7000 20.5713 1.0000
49.8000 20.5427 1.0000
49.9000 34.9414 1.0000
50.0000 24.0122 1.0000
50.1000 25.0443 1.0000
50.2000 18.4476 1.0000
50.3000 23.7983 1.0000
50.4000 27.9619 1.0000
50.5000 23.6036 1.0000
50.6000 22.9104 1.0000
50.7000 25.4607 1.0000
50.8000 37.9928 1.0000
50.9000 24.3110 1.0000
51.0000 28.7855 1.0000
51.1000 33.5922 1.0000
51.2000 38.6402 1.0000
51.3000 21.6488 1.0000
51.4000 19.7223 1.0000
51.5000 21.5857 1.0000
51.6000 28.5402 1.0000
51.7000 23.1096 1.0000
51.8000 32.3863 1.0000
51.9000 27.8939 1.0000
52.0000 32.1392 1.0000
52.1000 28.6576 1.0000
52.2000 20.0098 1.0000
52.3000 25.1743 1.0000
52.4000 21.7072 1.0000
52.5000 20.6135 1.0000
52.6000 16.6805 1.0000
52.7000 25.9920 1.0000
52.8000 23.8204 1.0000
52.9000 29.3172 1.0000
53.0000 26.7595 1.0000
53.1000 23.1654 1.0000
53.2000 21.3110 1.0000
53.3000 28.0795 1.0000
53.4000 23.1649 1.0000
53.5000 16.2264 1.0000
53.6000 22.9215 1.0000
53.7000 21.1415 1.0000
53.8000 31.0657 1.0000
53.9000 20.8521 1.0000
54.0000 19.4374 1.0000
54.1000 24.4510 1.0000
54.2000 28.0432 1.0000
54.3000 14.8816 1.0000
54.4000 24.3418 1.0000
54.5000 23.4340 1.0000
54.6000 27.4122 1.0000
54.7000 23.3033 1.0000
54.8000 27.5792 1.0000
54.9000 28.9520 1.0000
55.0000 25.2427 1.0000
55.1000 21.6449 1.0000
55.2000 17.4209 1.0000
55.3000 24.4790 1.0000
55.4000 25.4990 1.0000
55.5000 25.1393 1.0000
55.6000 28.9424 1.0000
55.7000 20.9424 1.0000
55.8000 21.1160 1.0000
55.9000 11.6333 1.0000
56.0000 26.5315 1.0000
56.1000 29.8903 1.0000
56.2000 18.8391 1.0000
56.3000 20.5577 1.0000
56.4000 21.5729 1.0000
56.5000 21.9975 1.0000
56.6000 20.7600 1.0000
56.7000 25.6809 1.0000
56.8000 30.5904 1.0000
56.9000 33.3169 1.0000
57.0000 30.0810 1.0000
57.1000 26.6609 1.0000
57.2000 29.6755 1.0000
57.3000 15.5329 1.0000
57.4000 30.7939 1.0000
57.5000 18.0698 1.0000
57.6000 32.3024 1.0000
57.7000 33.2413 1.0000
57.8000 16.5579 1.0000
57.9000 25.3015 1.0000
58.0000 27.1505 1.0000
58.1000 27.8756 1.0000
58.2000 27.0834 1.0000
58.3000 30.6752 1.0000
58.4000 26.6955 1.0000
58.5000 33.3529 1.0000
58.6000 22.8320 1.0000
58.7000 27.7115 1.0000
58.8000 31.7675 1.0000
58.9000 26.3726 1.0000
59.0000 29.2193 1.0000
59.1000 20.4541 1.0000
59.2000 26.7701 1.0000
59.3000 29.5094 1.0000
59.4000 27.9330 1.0000
59.5000 23.4499 1.0000
59.6000 22.3815 1.0000
59.7000 27.5877 1.0000
59.8000 22.7666 1.0000
59.9000 25.3370 1.0000
60.0000 20.9609 1.0000
60.1000 25.6439 1.0000
60.2000 15.4637 1.0000
60.3000 20.1615 1.0000
60.4000 26.6218 1.0000
60.5000 25.4314 1.0000
60.6000 31.4417 1.0000
60.7000 25.2629 1.0000
60.8000 21.6494 1.0000
60.9000 17.3508 1.0000
61.0000 25.0125 1.0000
61.1000 19.3018 1.0000
61.2000 15.4068 1.0000
61.3000 32.4765 1.0000
61.4000 22.5890 1.0000
61.5000 25.5516 1.0000
61.6000 40.6823 1.0000
61.7000 12.2120 1.0000
61.8000 19.1086 1.0000
61.9000 30.0969 1.0000
62.0000 27.0560 1.0000
62.1000 24.9149 1.0000
62.2000 24.0091 1.0000
62.3000 23.3271 1.0000
62.4000 30.5215 1.0000
62.5000 22.9884 1.0000
62.6000 19.2430 1.0000
62.7000 32.1930 1.0000
62.8000 32.8505 1.0000
62.9000 21.8104 1.0000
63.0000 24.2215 1.0000
63.1000 20.2732 1.0000
63.2000 18.7809 1.0000
63.3000 28.4878 1.0000
63.4000 19.1863 1.0000
63.5000 19.5743 1.0000
63.6000 17.0123 1.0000
63.7000 23.2059 1.0000
63.8000 24.7759 1.0000
63.9000 18.0160 1.0000
64.0000 28.6495 1.0000
64.1000 22.9220 1.0000
64.2000 28.4532 1.0000
64.3000 25.5065 1.0000
64.4000 24.1206 1.0000
64.5000 26.9925 1.0000
64.6000 41.7181 1.0000
64.7000 50.3680 1.0000
64.8000 80.7637 1.0000
64.9000 51.4035 1.0000
65.0000 39.8234 1.0000
65.1000 30.6456 1.0000
65.2000 27.7293 1.0000
65.3000 16.2872 1.0000
65.4000 18.5140 1.0000
65.5000 28.1662 1.0000
65.6000 26.6349 1.0000
65.7000 20.9761 1.0000
65.8000 16.9461 1.0000
65.9000 21.7159 1.0000
66.0000 20.3936 1.0000
66.1000 31.4851 1.0000
66.2000 28.4145 1.0000
66.3000 21.4552 1.0000
66.4000 18.0354 1.0000
66.5000 22.5173 1.0000
66.6000 22.0291 1.0000
66.7000 15.0107 1.0000
66.8000 16.7836 1.0000
66.9000 25.6034 1.0000
67.0000 19.5520 1.0000
67.1000 21.2986 1.0000
67.2000 23.9284 1.0000
67.3000 24.1527 1.0000
67.4000 12.9396 1.0000
67.5000 23.7789 1.0000
67.6000 18.6269 1.0000
67.7000 22.1985 1.0000
67.8000 27.8444 1.0000
67.9000 27.8077 1.0000
68.0000 28.9189 1.0000
68.1000 20.8521 1.0000
68.2000 22.0498 1.0000
68.3000 23.4960 1.0000
68.4000 19.7946 1.0000
68.5000 19.7967 1.0000
68.6000 25.7589 1.0000
68.7000 25.0252 1.0000
68.8000 27.4979 1.0000
68.9000 20.1123 1.0000
69.0000 21.9574 1.0000
69.1000 27.0586 1.0000
69.2000 18.6335 1.0000
69.3000 27.4390 1.0000
69.4000 28.1894 1.0000
69.5000 25.0820 1.0000
69.6000 20.5201 1.0000
69.7000 20.9255 1.0000
69.8000 21.1984 1.0000
69.9000 24.9129 1.0000
70.0000 20.0094 1.0000
70.1000 23.4943 1.0000
70.2000 24.5822 1.0000
70.3000 25.7803 1.0000
70.4000 24.4932 1.0000
70.5000 18.4311 1.0000
70.6000 24.6782 1.0000
70.7000 34.3697 1.0000
70.8000 25.1899 1.0000
70.9000 23.4323 1.0000
71.0000 22.4831 1.0000
71.1000 24.3448 1.0000
71.2000 24.6901 1.0000
71.3000 16.8490 1.0000
71.4000 17.8698 1.0000
71.5000 24.9354 1.0000
71.6000 23.4054 1.0000
71.7000 18.7042 1.0000
71.8000 20.3030 1.0000
71.9000 18.7343 1.0000
72.0000 21.6609 1.0000
72.1000 23.0987 1.0000
72.2000 27.0868 1.0000
72.3000 31.1951 1.0000
72.4000 17.9912 1.0000
72.5000 17.6834 1.0000
72.6000 26.9617 1.0000
72.7000 24.9940 1.0000
72.8000 32.2524 1.0000
72.9000 15.7442 1.0000
73.0000 20.5163 1.0000
73.1000 20.1099 1.0000
73.2000 31.7880 1.0000
73.3000 16.0425 1.0000
73.4000 26.7081 1.0000
73.5000 23.2603 1.0000
73.6000 25.1898 1.0000
73.7000 27.2889 1.0000
73.8000 24.4830 1.0000
73.9000 16.4033 1.0000
74.0000 39.0571 1.0000
74.1000 26.8561 1.0000
74.2000 21.6736 1.0000
74.3000 26.3961 1.0000
74.4000 25.7942 1.0000
74.5000 33.3781 1.0000
74.6000 24.8031 1.0000
74.7000 25.0000 1.0000
74.8000 18.6966 1.0000
74.9000 17.7496 1.0000
75.0000 19.6238 1.0000
75.1000 21.4837 1.0000
75.2000 20.4225 1.0000
75.3000 25.3394 1.0000
75.4000 26.6506 1.0000
75.5000 24.8695 1.0000
75.6000 26.7782 1.0000
75.7000 17.6163 1.0000
75.8000 22.6109 1.0000
75.9000 32.0425 1.0000
76.0000 34.7885 1.0000
76.1000 20.0433 1.0000
76.2000 13.8028 1.0000
76.3000 17.7965 1.0000
76.4000 30.9910 1.0000
76.5000 19.0307 1.0000
76.6000 23.9744 1.0000
76.7000 27.0994 1.0000
76.8000 26.3472 1.0000
76.9000 26.6363 1.0000
77.0000 23.2124 1.0000
77.1000 19.4358 1.0000
77.2000 20.8437 1.0000
77.3000 33.0507 1.0000
77.4000 27.7128 1.0000
77.5000 19.7913 1.0000
77.6000 23.3159 1.0000
77.7000 20.2244 1.0000
77.8000 21.3011 1.0000
77.9000 22.7660 1.0000
78.0000 20.9943 1.0000
78.1000 20.7364 1.0000
78.2000 31.7996 1.0000
78.3000 26.6352 1.0000
78.4000 25.5071 1.0000
78.5000 20.5025 1.0000
78.6000 24.0504 1.0000
78.7000 27.8591 1.0000
78.8000 11.8120 1.0000
78.9000 22.4406 1.0000
79.0000 28.7794 1.0000
79.1000 18.6902 1.0000
79.2000 21.8118 1.0000
79.3000 30.7233 1.0000
79.4000 26.5225 1.0000
79.5000 27.9388 1.0000
79.6000 21.5305 1.0000
79.7000 22.2835 1.0000
79.8000 19.7863 1.0000
79.9000 17.7373 1.0000
80.0000 21.3802 1.0000
80.1000 16.7936 1.0000
80.2000 19.3263 1.0000
80.3000 30.2562 1.0000
80.4000 19.6459 1.0000
80.5000 23.8963 1.0000
80.6000 24.0336 1.0000
80.7000 21.4672 1.0000
80.8000 12.9615 1.0000
80.9000 19.6315 1.0000
81.0000 31.5401 1.0000
81.1000 28.3473 1.0000
81.2000 28.0425 1.0000
81.3000 21.2254 1.0000
81.4000 23.5785 1.0000
81.5000 22.7437 1.0000
81.6000 29.7451 1.0000
81.7000 28.7200 1.0000
81.8000 47.4248 1.0000
81.9000 67.7217 1.0000
82.0000 138.6985 1.0000
82.1000 155.2693 1.0000
82.2000 109.4573 1.0000
82.3000 45.8733 1.0000
82.4000 30.1635 1.0000
82.5000 21.4149 1.0000
82.6000 30.0137 1.0000
82.7000 28.7715 1.0000
82.8000 21.0254 1.0000
82.9000 17.0886 1.0000
83.0000 22.1847 1.0000
83.1000 21.7836 1.0000
83.2000 20.7150 1.0000
83.3000 19.8306 1.0000
83.4000 22.0567 1.0000
83.5000 23.2403 1.0000
83.6000 22.8517 1.0000
83.7000 22.6016 1.0000
83.8000 24.5745 1.0000
83.9000 26.2827 1.0000
84.0000 21.5560 1.0000
84.1000 15.7641 1.0000
84.2000 23.0935 1.0000
84.3000 21.7886 1.0000
84.4000 24.5935 1.0000
84.5000 28.4711 1.0000
84.6000 33.9395 1.0000
84.7000 16.0522 1.0000
84.8000 21.6836 1.0000
84.9000 23.6952 1.0000
85.0000 30.8991 1.0000
85.1000 23.4764 1.0000
85.2000 27.2521 1.0000
85.3000 15.9413 1.0000
85.4000 24.6067 1.0000
85.5000 28.6264 1.0000
85.6000 30.1980 1.0000
85.7000 23.9376 1.0000
85.8000 28.3303 1.0000
85.9000 25.3992 1.0000
86.0000 26.4889 1.0000
86.1000 21.1080 1.0000
86.2000 21.3770 1.0000
86.3000 24.5102 1.0000
86.4000 15.8234 1.0000
86.5000 26.3927 1.0000
86.6000 24.2411 1.0000
86.7000 25.9999 1.0000
86.8000 18.8520 1.0000
86.9000 21.0218 1.0000
87.0000 24.6798 1.0000
87.1000 16.2988 1.0000
87.2000 25.5379 1.0000
87.3000 26.3288 1.0000
87.4000 21.8765 1.0000
87.5000 21.2301 1.0000
87.6000 12.5296 1.0000
87.7000 20.0976 1.0000
87.8000 32.7383 1.0000
87.9000 13.8825 1.0000
88.0000 21.0726 1.0000
88.1000 21.3087 1.0000
88.2000 17.1156 1.0000
88.3000 28.5071 1.0000
88.4000 21.7307 1.0000
88.5000 16.2511 1.0000
88.6000 16.9773 1.0000
88.7000 20.9316 1.0000
88.8000 23.1592 1.0000
88.9000 19.6607 1.0000
89.0000 13.5573 1.0000
89.1000 26.8007 1.0000
89.2000 23.4275 1.0000
89.3000 17.7916 1.0000
89.4000 16.7285 1.0000
89.5000 17.8362 1.0000
89.6000 26.7362 1.0000
89.7000 23.9051 1.0000
89.8000 18.5355 1.0000
89.9000 24.8412 1.0000
90.0000 20.0166 1.0000
90.1000 14.0719 1.0000
90.2000 23.0791 1.0000
90.3000 23.0978 1.0000
90.4000 30.9614 1.0000
90.5000 30.1960 1.0000
90.6000 22.4787 1.0000
90.7000 21.4742 1.0000
90.8000 32.5689 1.0000
90.9000 30.8198 1.0000
91.0000 25.4609 1.0000
91.1000 22.4798 1.0000
91.2000 21.7437 1.0000
91.3000 14.5610 1.0000
91.4000 22.5745 1.0000
91.5000 13.8306 1.0000
91.6000 24.0694 1.0000
91.7000 26.5542 1.0000
91.8000 25.2793 1.0000
91.9000 32.2330 1.0000
92.0000 21.2143 1.0000
92.1000 23.2689 1.0000
92.2000 12.3356 1.0000
92.3000 20.6720 1.0000
92.4000 28.5271 1.0000
92.5000 17.5553 1.0000
92.6000 15.9965 1.0000
92.7000 21.8000 1.0000
92.8000 20.6232 1.0000
92.9000 22.5328 1.0000
93.0000 21.8684 1.0000
93.1000 26.7372 1.0000
93.2000 16.5312 1.0000
93.3000 26.8217 1.0000
93.4000 20.9662 1.0000
93.5000 27.1227 1.0000
93.6000 20.8674 1.0000
93.7000 13.3377 1.0000
93.8000 19.2904 1.0000
93.9000 29.4455 1.0000
94.0000 9.8344 1.0000
94.1000 27.9291 1.0000
94.2000 28.8160 1.0000
94.3000 21.3835 1.0000
94.4000 19.9766 1.0000
94.5000 15.7295 1.0000
94.6000 17.5951 1.0000
94.7000 20.8343 1.0000
94.8000 21.4749 1.0000
94.9000 16.2813 1.0000
95.0000 20.0165 1.0000
95.1000 15.6187 1.0000
95.2000 24.0526 1.0000
95.3000 12.9690 1.0000
95.4000 18.3361 1.0000
95.5000 21.6322 1.0000
95.6000 21.1379 1.0000
95.7000 28.6513 1.0000
95.8000 17.7054 1.0000
95.9000 16.9508 1.0000
96.0000 28.6651 1.0000
96.1000 21.8164 1.0000
96.2000 23.0289 1.0000
96.3000 24.6532 1.0000
96.4000 28.2867 1.0000
96.5000 16.4142 1.0000
96.6000 20.3249 1.0000
96.7000 27.2937 1.0000
96.8000 17.3272 1.0000
96.9000 28.5681 1.0000
97.0000 30.1900 1.0000
97.1000 20.6535 1.0000
97.2000 20.0411 1.0000
97.3000 20.1358 1.0000
97.4000 22.0205 1.0000
97.5000 13.4695 1.0000
97.6000 22.1882 1.0000
97.7000 18.8986 1.0000
97.8000 23.7219 1.0000
97.9000 26.5986 1.0000
98.0000 29.2057 1.0000
98.1000 27.5953 1.0000
98.2000 32.6470 1.0000
98.3000 40.4899 1.0000
98.4000 43.6483 1.0000
98.5000 86.7531 1.0000
98.6000 117.6142 1.0000
98.7000 100.8339 1.0000
98.8000 56.7747 1.0000
98.9000 27.4451 1.0000
99.0000 19.9327 1.0000
99.1000 30.5140 1.0000
99.2000 25.8753 1.0000
99.3000 24.4604 1.0000
99.4000 26.1051 1.0000
99.5000 21.2971 1.0000
99.6000 22.8600 1.0000
99.7000 25.9562 1.0000
99.8000 21.9622 1.0000
99.9000 18.4609 1.0000
100.0000 25.6856 1.0000
100.1000 32.7828 1.0000
100.2000 33.1678 1.0000
100.3000 18.6754 1.0000
100.4000 27.2843 1.0000
100.5000 19.0625 1.0000
100.6000 21.0049 1.0000
100.7000 26.9112 1.0000
100.8000 21.1969 1.0000
100.9000 20.5854 1.0000
101.0000 25.1700 1.0000
101.1000 26.3196 1.0000
101.2000 19.6332 1.0000
101.3000 32.9286 1.0000
101.4000 19.8776 1.0000
101.5000 23.8835 1.0000
101.6000 15.4430 1.0000
101.7000 15.9415 1.0000
101.8000 26.1680 1.0000
101.9000 30.8600 1.0000
102.0000 18.2348 1.0000
102.1000 20.7071 1.0000
102.2000 21.9406 1.0000
102.3000 25.5903 1.0000
102.4000 28.3019 1.0000
102.5000 23.9819 1.0000
102.6000 21.7742 1.0000
102.7000 25.5217 1.0000
102.8000 13.7412 1.0000
102.9000 30.3814 1.0000
103.0000 9.4072 1.0000
103.1000 26.0885 1.0000
103.2000 28.8130 1.0000
103.3000 21.9915 1.0000
103.4000 14.5274 1.0000
103.5000 17.3577 1.0000
103.6000 22.2845 1.0000
103.7000 15.1695 1.0000
103.8000 22.3217 1.0000
103.9000 32.9368 1.0000
104.0000 22.9493 1.0000
104.1000 23.6004 1.0000
104.2000 20.3506 1.0000
104.3000 20.5153 1.0000
104.4000 25.9837 1.0000
104.5000 23.8223 1.0000
104.6000 23.9591 1.0000
104.7000 31.9565 1.0000
104.8000 18.0900 1.0000
104.9000 29.3394 1.0000
105.0000 22.4353 1.0000
105.1000 24.0198 1.0000
105.2000 25.4125 1.0000
105.3000 19.5060 1.0000
105.4000 21.2791 1.0000
105.5000 21.9014 1.0000
105.6000 26.5223 1.0000
105.7000 18.9587 1.0000
105.8000 29.2428 1.0000
105.9000 23.1610 1.0000
106.0000 19.6486 1.0000
106.1000 17.6257 1.0000
106.2000 22.7409 1.0000
106.3000 19.4617 1.0000
106.4000 19.3976 1.0000
106.5000 22.0598 1.0000
106.6000 25.7919 1.0000
106.7000 23.4943 1.0000
106.8000 17.5704 1.0000
106.9000 19.6052 1.0000
107.0000 26.4501 1.0000
107.1000 22.8879 1.0000
107.2000 26.0854 1.0000
107.3000 19.0067 1.0000
107.4000 17.0084 1.0000
107.5000 21.5504 1.0000
107.6000 22.9305 1.0000
107.7000 29.9558 1.0000
107.8000 21.7591 1.0000
107.9000 27.6850 1.0000
108.0000 18.7551 1.0000
108.1000 25.5376 1.0000
108.2000 24.4820 1.0000
108.3000 27.8702 1.0000
108.4000 24.2579 1.0000
108.5000 24.9019 1.0000
108.6000 18.1782 1.0000
108.7000 20.1680 1.0000
108.8000 18.6818 1.0000
108.9000 15.6555 1.0000
109.0000 26.5998 1.0000
109.1000 18.4469 1.0000
109.2000 24.8430 1.0000
109.3000 21.9181 1.0000
109.4000 12.7242 1.0000
109.5000 20.1102 1.0000
109.6000 18.6903 1.0000
109.7000 19.7651 1.0000
109.8000 19.5677 1.0000
109.9000 30.4738 1.0000
110.0000 16.3724 1.0000
110.1000 15.5362 1.0000
110.2000 21.6230 1.0000
110.3000 26.7102 1.0000
110.4000 15.9936 1.0000
110.5000 20.6431 1.0000
110.6000 15.2039 1.0000
110.7000 23.7921 1.0000
110.8000 26.0885 1.0000
110.9000 23.8694 1.0000
111.0000 20.6461 1.0000
111.1000 19.4081 1.0000
111.2000 16.9460 1.0000
111.3000 14.3922 1.0000
111.4000 13.3668 1.0000
111.5000 23.6875 1.0000
111.6000 24.5737 1.0000
111.7000 18.5469 1.0000
111.8000 14.5098 1.0000
111.9000 22.9599 1.0000
112.0000 23.0366 1.0000
112.1000 27.1969 1.0000
112.2000 15.7643 1.0000
112.3000 19.5270 1.0000
112.4000 14.4459 1.0000
112.5000 29.3098 1.0000
112.6000 30.3377 1.0000
112.7000 26.4054 1.0000
112.8000 19.2860 1.0000
112.9000 21.5500 1.0000
113.0000 18.4657 1.0000
113.1000 30.3576 1.0000
113.2000 25.1501 1.0000
113.3000 16.8493 1.0000
113.4000 19.5850 1.0000
113.5000 19.4039 1.0000
113.6000 23.4874 1.0000
113.7000 27.4119 1.0000
113.8000 10.9562 1.0000
113.9000 21.4342 1.0000
114.0000 17.2850 1.0000
114.1000 21.5258 1.0000
114.2000 21.0554 1.0000
114.3000 25.1190 1.0000
114.4000 14.5565 1.0000
114.5000 21.4773 1.0000
114.6000 13.9819 1.0000
114.7000 38.8257 1.0000
114.8000 22.7836 1.0000
114.9000 18.1371 1.0000
115.0000 27.5328 1.0000
115.1000 30.1757 1.0000
115.2000 15.9858 1.0000
115.3000 28.9150 1.0000
115.4000 30.5548 1.0000
115.5000 31.8983 1.0000
115.6000 43.9866 1.0000
115.7000 60.2413 1.0000
115.8000 56.5398 1.0000
115.9000 58.0522 1.0000
116.0000 51.6872 1.0000
116.1000 37.6425 1.0000
116.2000 22.8503 1.0000
116.3000 27.5232 1.0000
116.4000 29.0133 1.0000
116.5000 24.9067 1.0000
116.6000 19.6456 1.0000
116.7000 21.5203 1.0000
116.8000 21.6505 1.0000
116.9000 14.3895 1.0000
117.0000 32.1188 1.0000
117.1000 17.3928 1.0000
117.2000 21.0258 1.0000
117.3000 25.3143 1.0000
117.4000 24.5094 1.0000
117.5000 24.6801 1.0000
117.6000 26.8112 1.0000
117.7000 20.2458 1.0000
117.8000 18.3307 1.0000
117.9000 20.9474 1.0000
118.0000 33.9964 1.0000
118.1000 15.9746 1.0000
118.2000 14.0984 1.0000
118.3000 19.3754 1.0000
118.4000 20.5498 1.0000
118.5000 29.3119 1.0000
118.6000 15.8163 1.0000
118.7000 14.9278 1.0000
118.8000 22.6205 1.0000
118.9000 16.4623 1.0000
119.0000 21.3463 1.0000
119.1000 18.8027 1.0000
119.2000 22.7742 1.0000
119.3000 19.6159 1.0000
119.4000 31.7701 1.0000
119.5000 15.1190 1.0000
119.6000 24.0399 1.0000
119.7000 13.8256 1.0000
119.8000 18.5067 1.0000
119.9000 28.7190 1.0000
120.0000 17.0004 1.0000
120.1000 26.8992 1.0000
120.2000 26.3540 1.0000
120.3000 27.4885 1.0000
120.4000 17.1144 1.0000
120.5000 21.0429 1.0000
120.6000 22.0766 1.0000
120.7000 15.8836 1.0000
120.8000 20.5341 1.0000
120.9000 24.2901 1.0000
121.0000 21.1981 1.0000
121.1000 30.0138 1.0000
121.2000 24.1209 1.0000
121.3000 19.6678 1.0000
121.4000 26.3577 1.0000
121.5000 20.5714 1.0000
121.6000 23.4428 1.0000
121.7000 14.9481 1.0000
121.8000 23.4425 1.0000
121.9000 27.6628 1.0000
122.0000 20.0559 1.0000
122.1000 21.2096 1.0000
122.2000 22.7324 1.0000
122.3000 24.3095 1.0000
122.4000 22.9365 1.0000
122.5000 23.8337 1.0000
122.6000 16.0506 1.0000
122.7000 24.7641 1.0000
122.8000 17.7016 1.0000
122.9000 20.0088 1.0000
123.0000 25.4648 1.0000
123.1000 23.2974 1.0000
123.2000 14.4655 1.0000
123.3000 22.1909 1.0000
123.4000 16.7595 1.0000
123.5000 34.3749 1.0000
123.6000 23.5873 1.0000
123.7000 16.9030 1.0000
123.8000 13.5478 1.0000
123.9000 30.5133 1.0000
124.0000 27.6861 1.0000
124.1000 20.3606 1.0000
124.2000 21.7581 1.0000
124.3000 22.3863 1.0000
124.4000 19.1859 1.0000
124.5000 19.3401 1.0000
124.6000 20.9251 1.0000
124.7000 23.8404 1.0000
124.8000 17.7063 1.0000
124.9000 28.7944 1.0000
125.0000 24.4768 1.0000
125.1000 24.8987 1.0000
125.2000 14.6785 1.0000
125.3000 22.3638 1.0000
125.4000 30.3103 1.0000
125.5000 12.2023 1.0000
125.6000 18.6192 1.0000
125.7000 21.7828 1.0000
125.8000 23.0513 1.0000
125.9000 20.3398 1.0000
126.0000 11.9889 1.0000
126.1000 32.6375 1.0000
126.2000 26.1581 1.0000
126.3000 24.9250 1.0000
126.4000 25.2796 1.0000
126.5000 13.9399 1.0000
126.6000 17.8981 1.0000
126.7000 19.2970 1.0000
126.8000 17.3982 1.0000
126.9000 12.1349 1.0000
127.0000 20.9026 1.0000
127.1000 28.8022 1.0000
127.2000 14.1178 1.0000
127.3000 21.3399 1.0000
127.4000 24.2504 1.0000
127.5000 34.5475 1.0000
127.6000 19.6630 1.0000
127.7000 17.6531 1.0000
127.8000 28.7090 1.0000
127.9000 23.1595 1.0000
128.0000 15.6685 1.0000
128.1000 16.5415 1.0000
128.2000 24.8933 1.0000
128.3000 20.5743 1.0000
128.4000 26.2830 1.0000
128.5000 13.7313 1.0000
128.6000 24.5008 1.0000
128.7000 25.9306 1.0000
128.8000 22.1218 1.0000
128.9000 21.6601 1.0000
129.0000 18.6751 1.0000
129.1000 19.1789 1.0000
129.2000 16.7380 1.0000
129.3000 18.5819 1.0000
129.4000 23.1564 1.0000
129.5000 23.0443 1.0000
129.6000 23.2708 1.0000
129.7000 19.4096 1.0000
129.8000 17.4858 1.0000
129.9000 24.0478 1.0000
130.0000 9.1792 1.0000
*RAS_INT_END
*RAS_TEMPERATURE_START
*RAS_TEMPERATURE_END
*RAS_HEADER_START
*DISP_FMT_X "%.3f"
*DISP_FMT_Y "%.0f"
*DISP_FULLSCALE "354.9860857344"
*DISP_LINE_COLOR "255.0000000000"
*DISP_LINE_STYLE "0.0000000000"
*DISP_LINE_WIDTH "0.2500000000"
*DISP_NOTE "Collected Data-265"
*DISP_OFFSET_Y "0.0000000000"
*DISP_PEAKSEARCH_UNIT_Y "cps"
*DISP_RANGE_BOTTOM "0.0000000000"
*DISP_RANGE_LEFT "40.0000000000"
*DISP_RANGE_LOGCUTOFF "0.0100000000"
*DISP_RANGE_RIGHT "130.0000000000"
*DISP_RANGE_TOP "354.9860857344"
*DISP_SCALE_MODE_Y "0.0000000000"
*DISP_TAB_NAME "Theta/2-Theta"
*DISP_TITLE_Y "Intensity"
*DISP_UNIT_Y "cps"
*DISP_WINDOW_NAME "MSG_MACROENGINE"
*FILE_COMMENT " "
*FILE_MD5 ""
*FILE_MEMO " "
*FILE_OPERATOR "Administrator"
*FILE_PART_ID "MEAS_KHP2_00061"
*FILE_SAMPLE " "
*FILE_TYPE "RAS_RAW"
*FILE_USERGROUP "System Manager"
*FILE_VERSION "1.0000000000"
*HW_ATTACHMENT_ID "ATT0021"
*HW_ATTACHMENT_NAME "XY-20mm|XY-20mm"
*HW_COUNTER_ID-0 "CUT0041"
*HW_COUNTER_ID-1 "CUT0051"
*HW_COUNTER_ID-2 "CUT0020"
*HW_COUNTER_ID-3 "CSL0021"
*HW_COUNTER_ID-4 "CMC0021"
*HW_COUNTER_NAME-0 "D/teX Ultra 250|D/teX Ultra 250"
*HW_COUNTER_NAME-1 "HyPix 3000(H)|HyPix 3000(H)"
*HW_COUNTER_NAME-2 "None|None"
*HW_COUNTER_NAME-3 "BBM|BBM"
*HW_COUNTER_NAME-4 "検出器モノクロメータ|Detector monochromator"
*HW_COUNTER_SELECT_NAME "HyPix 3000(H)|HyPix 3000(H)"
*HW_GONIOMETER_ID "GON0024"
*HW_GONIOMETER_NAME "SmartLab(In-plane)|SmartLab(In-plane)"
*HW_GONIOMETER_RADIUS-0 "90.0"
*HW_GONIOMETER_RADIUS-1 "114.0"
*HW_GONIOMETER_RADIUS-2 "190.0"
*HW_GONIOMETER_RADIUS-3 "300.0"
*HW_GONIOMETER_RADIUS-4 "187.0"
*HW_GONIOMETER_RADIUS-5 "300.0"
*HW_GONIOMETER_RADIUS-6 "113.0"
*HW_GONIOMETER_RADIUS-7 "331.0"
*HW_I_OPT_ID-0 "CBO0021"
*HW_I_OPT_ID-1 "ICR0021"
*HW_I_OPT_ID-2 "ISL0021"
*HW_I_OPT_ID-3 "ISO0021"
*HW_I_OPT_ID-4 "IAD0021"
*HW_I_OPT_ID-5 "IPR0001"
*HW_I_OPT_NAME-0 "CBOユニット|CBO unit"
*HW_I_OPT_NAME-1 "標準入射光学ユニット|Standard incident optical unit"
*HW_I_OPT_NAME-2 "標準入射スリットボックス|Standard incident slit box"
*HW_I_OPT_NAME-3 "入射平行スリット|Incident parallel slit"
*HW_I_OPT_NAME-4 "長手制限スリット|Length limiting slit"
*HW_I_OPT_NAME-5 "None|None"
*HW_R_ATTENUATER_AUTOMODE "0"
*HW_R_OPT_ID-0 "RSS0022"
*HW_R_OPT_ID-1 "RCR0022"
*HW_R_OPT_ID-2 "RSO0021"
*HW_R_OPT_ID-3 "RRS0022"
*HW_R_OPT_ID-4 "ATN0020"
*HW_R_OPT_ID-5 "RFL0021"
*HW_R_OPT_ID-6 "RAD0021"
*HW_R_OPT_NAME-0 "受光スリットボックス1(Zr軸付)|Receiving slit box # 1 (w/ Zr Axis)"
*HW_R_OPT_NAME-1 "標準受光光学ユニット1|Standard receiving unit # 1"
*HW_R_OPT_NAME-2 "標準受光光学ユニット2|Standard receiving optical unit # 2"
*HW_R_OPT_NAME-3 "仮想受光スリット2|Virtual receiving slit #2"
*HW_R_OPT_NAME-4 "無し|None"
*HW_R_OPT_NAME-5 "Cu Kβ|Cu K-beta"
*HW_R_OPT_NAME-6 "調整用受光スリット|Alignment receiving slit"
*HW_SAMPLE_HOLDER_ID "SMP0021"
*HW_SAMPLE_HOLDER_NAME "χφZクレードル|Chi phi Z cradle"
*HW_XG_CURRENT_MAX "40"
*HW_XG_CURRENT_MIN "2"
*HW_XG_CURRENT_RESOLUTION "1"
*HW_XG_CURRENT_UNIT "mA"
*HW_XG_FOCUS "0.4mm x 8mm"
*HW_XG_FOCUS_TYPE "Fine"
*HW_XG_ID "1200"
*HW_XG_NAME "3kW 封入管(ID:1200)|3kW Sealed tube(ID:1200)"
*HW_XG_TARGET_ATOMIC_NUMBER "29.0000000000"
*HW_XG_TARGET_NAME "Cu"
*HW_XG_TYPE "Hermetic"
*HW_XG_VOLTAGE_MAX "40"
*HW_XG_VOLTAGE_MIN "20"
*HW_XG_VOLTAGE_RESOLUTION "1"
*HW_XG_VOLTAGE_UNIT "kV"
*HW_XG_WATT_MAX "1.500"
*HW_XG_WATT_UNIT "kW"
*HW_XG_WAVE_LENGTH_ALPHA1 "1.540593"
*HW_XG_WAVE_LENGTH_ALPHA2 "1.544414"
*HW_XG_WAVE_LENGTH_BETA "1.392250"
*MEAS_COND_AXIS_NAME-0 "Theta/2-Theta"
*MEAS_COND_AXIS_NAME-1 "2-Theta"
*MEAS_COND_AXIS_NAME-2 "Omega"
*MEAS_COND_AXIS_NAME-3 "Chi"
*MEAS_COND_AXIS_NAME-4 "Phi"
*MEAS_COND_AXIS_NAME-5 "Z"
*MEAS_COND_AXIS_NAME-6 "X"
*MEAS_COND_AXIS_NAME-7 "Y"
*MEAS_COND_AXIS_NAME-8 "2-Theta/Omega"
*MEAS_COND_AXIS_NAME-9 "2-ThetaChi"
*MEAS_COND_AXIS_NAME-10 "2-ThetaChi/Phi"
*MEAS_COND_AXIS_NAME-11 "Alpha"
*MEAS_COND_AXIS_NAME-12 "Beta"
*MEAS_COND_AXIS_NAME-13 "Theta_s"
*MEAS_COND_AXIS_NAME-14 "Theta_d"
*MEAS_COND_AXIS_NAME-15 "Ts"
*MEAS_COND_AXIS_NAME-16 "CBO selection slit"
*MEAS_COND_AXIS_NAME-17 "M"
*MEAS_COND_AXIS_NAME-18 "Incident parallel slit"
*MEAS_COND_AXIS_NAME-19 "Incident slit"
*MEAS_COND_AXIS_NAME-20 ""
*MEAS_COND_AXIS_NAME-21 "Zs"
*MEAS_COND_AXIS_NAME-22 "Incident optical device"
*MEAS_COND_AXIS_NAME-23 "Omega_m"
*MEAS_COND_AXIS_NAME-24 "Length limiting slit"
*MEAS_COND_AXIS_NAME-25 "Center slit"
*MEAS_COND_AXIS_NAME-26 "Filter"
[...]
44.8000 111.4365 1.0000
44.9000 58.1849 1.0000
45.0000 30.9007 1.0000
45.1000 23.7751 1.0000
45.2000 33.4267 1.0000
45.3000 34.3122 1.0000
45.4000 32.7880 1.0000
45.5000 23.9528 1.0000
45.6000 34.1572 1.0000
45.7000 33.6395 1.0000
45.8000 22.1818 1.0000
45.9000 18.3366 1.0000
46.0000 31.9899 1.0000
46.1000 27.9137 1.0000
46.2000 29.3639 1.0000
46.3000 32.7626 1.0000
46.4000 32.7635 1.0000
46.5000 24.2481 1.0000
46.6000 26.4617 1.0000
46.7000 22.6641 1.0000
46.8000 29.8530 1.0000
46.9000 22.1833 1.0000
47.0000 31.4079 1.0000
47.1000 27.2211 1.0000
47.2000 21.1916 1.0000
47.3000 20.5447 1.0000
47.4000 38.7228 1.0000
47.5000 15.8680 1.0000
47.6000 21.2599 1.0000
47.7000 24.6120 1.0000
47.8000 22.6542 1.0000
47.9000 23.5131 1.0000
48.0000 25.7548 1.0000
48.1000 30.1172 1.0000
48.2000 35.8387 1.0000
48.3000 29.8187 1.0000
48.4000 30.2542 1.0000
48.5000 32.2130 1.0000
48.6000 22.4621 1.0000
48.7000 25.2290 1.0000
48.8000 29.6097 1.0000
48.9000 26.7325 1.0000
49.0000 31.8843 1.0000
49.1000 21.8711 1.0000
49.2000 28.1253 1.0000
49.3000 22.5353 1.0000
49.4000 24.2643 1.0000
49.5000 16.6248 1.0000
49.6000 31.1290 1.0000
49.7000 22.1926 1.0000
49.8000 17.0944 1.0000
49.9000 39.7333 1.0000
50.0000 27.2957 1.0000
50.1000 24.0310 1.0000
50.2000 29.3836 1.0000
50.3000 22.0905 1.0000
50.4000 26.6374 1.0000
50.5000 24.9579 1.0000
50.6000 33.9009 1.0000
50.7000 31.2804 1.0000
50.8000 25.5437 1.0000
50.9000 32.6551 1.0000
51.0000 33.4058 1.0000
51.1000 23.4619 1.0000
51.2000 30.8745 1.0000
51.3000 20.4051 1.0000
51.4000 27.1342 1.0000
51.5000 20.2113 1.0000
51.6000 22.6227 1.0000
51.7000 21.5133 1.0000
51.8000 22.2518 1.0000
51.9000 26.9446 1.0000
52.0000 15.0501 1.0000
52.1000 25.7732 1.0000
52.2000 33.4389 1.0000
52.3000 19.1839 1.0000
52.4000 26.0512 1.0000
52.5000 24.0199 1.0000
52.6000 26.0719 1.0000
52.7000 33.4736 1.0000
52.8000 25.5648 1.0000
52.9000 27.0396 1.0000
53.0000 15.6133 1.0000
53.1000 27.2254 1.0000
53.2000 26.3213 1.0000
53.3000 14.2128 1.0000
53.4000 21.7836 1.0000
53.5000 30.9194 1.0000
53.6000 23.1191 1.0000
53.7000 20.7588 1.0000
53.8000 26.5044 1.0000
53.9000 25.0472 1.0000
54.0000 28.3964 1.0000
54.1000 21.8561 1.0000
54.2000 29.3285 1.0000
54.3000 23.5491 1.0000
54.4000 27.1833 1.0000
54.5000 23.9591 1.0000
54.6000 21.9226 1.0000
54.7000 23.5348 1.0000
54.8000 22.1043 1.0000
54.9000 29.4481 1.0000
55.0000 31.7683 1.0000
55.1000 17.3091 1.0000
55.2000 21.4390 1.0000
55.3000 28.9530 1.0000
55.4000 26.9510 1.0000
55.5000 17.4764 1.0000
55.6000 30.7823 1.0000
55.7000 28.8087 1.0000
55.8000 23.6764 1.0000
55.9000 26.2809 1.0000
56.0000 21.7174 1.0000
56.1000 18.9749 1.0000
56.2000 26.3045 1.0000
56.3000 24.4742 1.0000
56.4000 14.8843 1.0000
56.5000 22.8555 1.0000
56.6000 20.7389 1.0000
56.7000 22.6231 1.0000
56.8000 16.0585 1.0000
56.9000 33.1277 1.0000
57.0000 21.9473 1.0000
57.1000 13.7374 1.0000
57.2000 13.5832 1.0000
57.3000 26.7726 1.0000
57.4000 23.8377 1.0000
57.5000 14.5411 1.0000
57.6000 18.7167 1.0000
57.7000 29.8465 1.0000
57.8000 21.7190 1.0000
57.9000 25.0049 1.0000
58.0000 21.1949 1.0000
58.1000 26.5549 1.0000
58.2000 18.9909 1.0000
58.3000 25.9647 1.0000
58.4000 24.3203 1.0000
58.5000 19.7670 1.0000
58.6000 25.5419 1.0000
58.7000 28.7913 1.0000
58.8000 25.5958 1.0000
58.9000 21.7951 1.0000
59.0000 18.1450 1.0000
59.1000 17.6981 1.0000
59.2000 22.9642 1.0000
59.3000 20.8641 1.0000
59.4000 20.2388 1.0000
59.5000 23.5827 1.0000
59.6000 21.2399 1.0000
59.7000 15.3067 1.0000
59.8000 22.7659 1.0000
59.9000 19.2447 1.0000
60.0000 27.0024 1.0000
60.1000 22.9198 1.0000
60.2000 16.6223 1.0000
60.3000 25.2392 1.0000
60.4000 22.1634 1.0000
60.5000 20.0366 1.0000
60.6000 25.7414 1.0000
60.7000 25.9410 1.0000
60.8000 22.1310 1.0000
60.9000 21.0173 1.0000
61.0000 20.8704 1.0000
61.1000 23.2338 1.0000
61.2000 16.0645 1.0000
61.3000 17.4373 1.0000
61.4000 21.1309 1.0000
61.5000 18.4517 1.0000
61.6000 24.1354 1.0000
61.7000 25.1177 1.0000
61.8000 23.2298 1.0000
61.9000 14.0907 1.0000
62.0000 30.3868 1.0000
62.1000 20.1264 1.0000
62.2000 26.5708 1.0000
62.3000 27.0708 1.0000
62.4000 31.6548 1.0000
62.5000 24.5632 1.0000
62.6000 29.2235 1.0000
62.7000 15.3679 1.0000
62.8000 21.8398 1.0000
62.9000 22.5611 1.0000
63.0000 19.5192 1.0000
63.1000 32.2154 1.0000
63.2000 23.0865 1.0000
63.3000 24.4136 1.0000
63.4000 19.2090 1.0000
63.5000 19.1461 1.0000
63.6000 18.3585 1.0000
63.7000 28.4239 1.0000
63.8000 26.5463 1.0000
63.9000 21.3823 1.0000
64.0000 23.2173 1.0000
64.1000 19.0655 1.0000
64.2000 21.0436 1.0000
64.3000 23.8681 1.0000
64.4000 27.5094 1.0000
64.5000 18.0646 1.0000
64.6000 42.9201 1.0000
64.7000 54.1075 1.0000
64.8000 65.4659 1.0000
64.9000 57.7057 1.0000
65.0000 40.2475 1.0000
65.1000 31.4274 1.0000
65.2000 21.2090 1.0000
65.3000 22.3342 1.0000
65.4000 33.3149 1.0000
65.5000 21.4292 1.0000
65.6000 24.9771 1.0000
65.7000 27.9998 1.0000
65.8000 16.2983 1.0000
65.9000 19.4601 1.0000
66.0000 27.0509 1.0000
66.1000 19.1774 1.0000
66.2000 16.1070 1.0000
66.3000 20.8917 1.0000
66.4000 28.8563 1.0000
66.5000 28.0907 1.0000
66.6000 20.0686 1.0000
66.7000 26.9833 1.0000
66.8000 16.7958 1.0000
66.9000 15.7048 1.0000
67.0000 15.6665 1.0000
67.1000 25.0298 1.0000
67.2000 17.7840 1.0000
67.3000 14.7955 1.0000
67.4000 30.6689 1.0000
67.5000 32.4760 1.0000
67.6000 16.7528 1.0000
67.7000 23.5540 1.0000
67.8000 28.1706 1.0000
67.9000 24.8609 1.0000
68.0000 17.8644 1.0000
68.1000 19.6982 1.0000
68.2000 27.2905 1.0000
68.3000 19.8783 1.0000
68.4000 19.6851 1.0000
68.5000 20.2100 1.0000
68.6000 22.5489 1.0000
68.7000 15.5597 1.0000
68.8000 23.3304 1.0000
68.9000 28.7178 1.0000
69.0000 23.1598 1.0000
69.1000 18.8064 1.0000
69.2000 22.6796 1.0000
69.3000 22.3938 1.0000
69.4000 21.8645 1.0000
69.5000 20.1131 1.0000
69.6000 21.0595 1.0000
69.7000 24.8937 1.0000
69.8000 24.9984 1.0000
69.9000 26.6527 1.0000
70.0000 27.7253 1.0000
70.1000 34.1700 1.0000
70.2000 21.2555 1.0000
70.3000 24.5623 1.0000
70.4000 20.6563 1.0000
70.5000 30.5266 1.0000
70.6000 23.6726 1.0000
70.7000 19.6781 1.0000
70.8000 20.2169 1.0000
70.9000 28.0538 1.0000
71.0000 25.5080 1.0000
71.1000 19.2755 1.0000
71.2000 19.5710 1.0000
71.3000 22.2486 1.0000
71.4000 24.6336 1.0000
71.5000 23.7910 1.0000
71.6000 22.0821 1.0000
71.7000 20.8627 1.0000
71.8000 25.8866 1.0000
71.9000 21.4043 1.0000
72.0000 19.7576 1.0000
72.1000 15.6764 1.0000
72.2000 29.3577 1.0000
72.3000 20.8893 1.0000
72.4000 25.6189 1.0000
72.5000 21.9009 1.0000
72.6000 20.7843 1.0000
72.7000 17.5781 1.0000
72.8000 18.8478 1.0000
72.9000 19.5873 1.0000
73.0000 20.6373 1.0000
73.1000 18.2926 1.0000
73.2000 15.5109 1.0000
73.3000 23.4179 1.0000
73.4000 22.0513 1.0000
73.5000 26.1586 1.0000
73.6000 33.2818 1.0000
73.7000 29.0797 1.0000
73.8000 14.5669 1.0000
73.9000 21.4812 1.0000
74.0000 20.6574 1.0000
74.1000 24.3173 1.0000
74.2000 22.0726 1.0000
74.3000 24.9852 1.0000
74.4000 19.5624 1.0000
74.5000 29.5579 1.0000
74.6000 23.5621 1.0000
74.7000 19.9906 1.0000
74.8000 29.4337 1.0000
74.9000 21.5820 1.0000
75.0000 27.0458 1.0000
75.1000 23.1994 1.0000
75.2000 26.4770 1.0000
75.3000 17.5903 1.0000
75.4000 20.6072 1.0000
75.5000 29.3673 1.0000
75.6000 27.6876 1.0000
75.7000 20.9177 1.0000
75.8000 21.6386 1.0000
75.9000 32.0072 1.0000
76.0000 29.1539 1.0000
76.1000 22.3413 1.0000
76.2000 28.6967 1.0000
76.3000 15.8065 1.0000
76.4000 27.8374 1.0000
76.5000 35.7140 1.0000
76.6000 23.9160 1.0000
76.7000 27.9377 1.0000
76.8000 21.8428 1.0000
76.9000 22.8824 1.0000
77.0000 25.3343 1.0000
77.1000 23.4767 1.0000
77.2000 14.4456 1.0000
77.3000 25.2188 1.0000
77.4000 24.7898 1.0000
77.5000 18.4514 1.0000
77.6000 28.6745 1.0000
77.7000 26.9600 1.0000
77.8000 16.7510 1.0000
77.9000 13.3523 1.0000
78.0000 23.5839 1.0000
78.1000 29.7767 1.0000
78.2000 13.1478 1.0000
78.3000 23.2074 1.0000
78.4000 16.2428 1.0000
78.5000 26.1583 1.0000
78.6000 23.6307 1.0000
78.7000 13.9186 1.0000
78.8000 17.4247 1.0000
78.9000 18.8137 1.0000
79.0000 26.5219 1.0000
79.1000 20.1901 1.0000
79.2000 24.4731 1.0000
79.3000 27.0482 1.0000
79.4000 11.4555 1.0000
79.5000 21.3982 1.0000
79.6000 17.0083 1.0000
79.7000 13.1547 1.0000
79.8000 17.8189 1.0000
79.9000 17.4288 1.0000
80.0000 24.1047 1.0000
80.1000 26.8466 1.0000
80.2000 13.5552 1.0000
80.3000 19.9429 1.0000
80.4000 20.6676 1.0000
80.5000 15.9734 1.0000
80.6000 27.3853 1.0000
80.7000 20.1154 1.0000
80.8000 21.6893 1.0000
80.9000 22.9365 1.0000
81.0000 20.1364 1.0000
81.1000 29.5231 1.0000
81.2000 35.3756 1.0000
81.3000 25.2035 1.0000
81.4000 26.4171 1.0000
81.5000 30.6740 1.0000
81.6000 26.5913 1.0000
81.7000 31.0628 1.0000
81.8000 42.7601 1.0000
81.9000 59.4478 1.0000
82.0000 151.8299 1.0000
82.1000 159.4681 1.0000
82.2000 96.0532 1.0000
82.3000 41.8291 1.0000
82.4000 30.0812 1.0000
82.5000 21.3660 1.0000
82.6000 27.2558 1.0000
82.7000 19.8611 1.0000
82.8000 12.4609 1.0000
82.9000 17.8628 1.0000
83.0000 20.3575 1.0000
83.1000 17.9560 1.0000
83.2000 22.1828 1.0000
83.3000 17.0572 1.0000
83.4000 30.8150 1.0000
83.5000 30.5558 1.0000
83.6000 21.8372 1.0000
83.7000 25.4791 1.0000
83.8000 21.5364 1.0000
83.9000 22.9211 1.0000
84.0000 20.2050 1.0000
84.1000 28.6003 1.0000
84.2000 18.7705 1.0000
84.3000 20.0542 1.0000
84.4000 19.9987 1.0000
84.5000 24.7118 1.0000
84.6000 23.5140 1.0000
84.7000 25.8942 1.0000
84.8000 27.8410 1.0000
84.9000 18.3195 1.0000
85.0000 22.6551 1.0000
85.1000 13.7406 1.0000
85.2000 27.8162 1.0000
85.3000 29.9763 1.0000
85.4000 25.8225 1.0000
85.5000 28.0517 1.0000
85.6000 27.8961 1.0000
85.7000 17.2064 1.0000
85.8000 18.4636 1.0000
85.9000 23.3135 1.0000
86.0000 23.8060 1.0000
86.1000 22.2608 1.0000
86.2000 24.8607 1.0000
86.3000 24.1932 1.0000
86.4000 19.0651 1.0000
86.5000 26.2741 1.0000
86.6000 20.4637 1.0000
86.7000 20.4551 1.0000
86.8000 25.2526 1.0000
86.9000 28.0760 1.0000
87.0000 21.3682 1.0000
87.1000 10.6727 1.0000
87.2000 26.9021 1.0000
87.3000 32.7968 1.0000
87.4000 21.4199 1.0000
87.5000 25.7244 1.0000
87.6000 21.9210 1.0000
87.7000 25.9637 1.0000
87.8000 26.5324 1.0000
87.9000 18.6879 1.0000
88.0000 24.6152 1.0000
88.1000 19.9220 1.0000
88.2000 19.6330 1.0000
88.3000 18.9547 1.0000
88.4000 16.9380 1.0000
88.5000 20.4455 1.0000
88.6000 28.6187 1.0000
88.7000 16.1779 1.0000
88.8000 24.6119 1.0000
88.9000 19.3400 1.0000
89.0000 25.7730 1.0000
89.1000 27.9562 1.0000
89.2000 24.2939 1.0000
89.3000 26.4932 1.0000
89.4000 25.2637 1.0000
89.5000 14.5199 1.0000
89.6000 16.1637 1.0000
89.7000 18.5936 1.0000
89.8000 18.3198 1.0000
89.9000 21.1217 1.0000
90.0000 17.1651 1.0000
90.1000 23.4373 1.0000
90.2000 22.4153 1.0000
90.3000 24.1716 1.0000
90.4000 14.3506 1.0000
90.5000 22.7995 1.0000
90.6000 19.9649 1.0000
90.7000 24.3720 1.0000
90.8000 22.2831 1.0000
90.9000 27.1697 1.0000
91.0000 20.6164 1.0000
91.1000 17.7853 1.0000
91.2000 26.6138 1.0000
91.3000 24.4858 1.0000
91.4000 20.6271 1.0000
91.5000 27.5211 1.0000
91.6000 22.3070 1.0000
91.7000 19.4553 1.0000
91.8000 15.5367 1.0000
91.9000 19.6260 1.0000
92.0000 26.4469 1.0000
92.1000 27.7752 1.0000
92.2000 23.3554 1.0000
92.3000 22.6155 1.0000
92.4000 20.3142 1.0000
92.5000 16.9342 1.0000
92.6000 17.1009 1.0000
92.7000 19.4914 1.0000
92.8000 20.4056 1.0000
92.9000 22.2906 1.0000
93.0000 16.7228 1.0000
93.1000 20.2134 1.0000
93.2000 26.5533 1.0000
93.3000 19.7559 1.0000
93.4000 27.8006 1.0000
93.5000 12.8073 1.0000
93.6000 17.5248 1.0000
93.7000 33.2413 1.0000
93.8000 27.9589 1.0000
93.9000 29.1407 1.0000
94.0000 19.8153 1.0000
94.1000 23.1493 1.0000
94.2000 17.2251 1.0000
94.3000 15.9643 1.0000
94.4000 23.2601 1.0000
94.5000 26.0699 1.0000
94.6000 14.6517 1.0000
94.7000 28.6774 1.0000
94.8000 22.7010 1.0000
94.9000 20.8500 1.0000
95.0000 30.8716 1.0000
95.1000 26.5743 1.0000
95.2000 20.3276 1.0000
95.3000 29.5231 1.0000
95.4000 24.0443 1.0000
95.5000 14.8237 1.0000
95.6000 26.5312 1.0000
95.7000 23.2776 1.0000
95.8000 27.4690 1.0000
95.9000 22.5553 1.0000
96.0000 34.5427 1.0000
96.1000 15.0648 1.0000
96.2000 25.2676 1.0000
96.3000 14.5719 1.0000
96.4000 15.0566 1.0000
96.5000 19.8880 1.0000
96.6000 15.3466 1.0000
96.7000 21.2316 1.0000
96.8000 22.1595 1.0000
96.9000 16.6145 1.0000
97.0000 22.0258 1.0000
97.1000 28.1612 1.0000
97.2000 20.1184 1.0000
97.3000 27.3663 1.0000
97.4000 21.0856 1.0000
97.5000 22.5529 1.0000
97.6000 22.5050 1.0000
97.7000 31.4452 1.0000
97.8000 17.3521 1.0000
97.9000 18.3197 1.0000
98.0000 26.5796 1.0000
98.1000 24.9755 1.0000
98.2000 26.9661 1.0000
98.3000 40.7071 1.0000
98.4000 59.7141 1.0000
98.5000 104.4047 1.0000
98.6000 134.6636 1.0000
98.7000 84.2320 1.0000
98.8000 43.5962 1.0000
98.9000 42.8817 1.0000
99.0000 28.0884 1.0000
99.1000 28.1968 1.0000
99.2000 24.6767 1.0000
99.3000 26.5132 1.0000
99.4000 19.1801 1.0000
99.5000 22.5026 1.0000
99.6000 16.9077 1.0000
99.7000 21.9512 1.0000
99.8000 16.9137 1.0000
99.9000 23.8049 1.0000
100.0000 20.6877 1.0000
100.1000 17.8434 1.0000
100.2000 18.1723 1.0000
100.3000 24.1052 1.0000
100.4000 20.7785 1.0000
100.5000 25.3166 1.0000
100.6000 26.8074 1.0000
100.7000 29.2228 1.0000
100.8000 26.1262 1.0000
100.9000 21.6536 1.0000
101.0000 25.2676 1.0000
101.1000 26.1269 1.0000
101.2000 25.0578 1.0000
101.3000 21.9607 1.0000
101.4000 15.2355 1.0000
101.5000 25.6231 1.0000
101.6000 20.7035 1.0000
101.7000 22.2793 1.0000
101.8000 14.3505 1.0000
101.9000 26.4545 1.0000
102.0000 22.9653 1.0000
102.1000 23.0833 1.0000
102.2000 19.6955 1.0000
102.3000 23.0502 1.0000
102.4000 17.7763 1.0000
102.5000 20.7804 1.0000
102.6000 21.4514 1.0000
102.7000 23.7824 1.0000
102.8000 19.3156 1.0000
102.9000 24.3221 1.0000
103.0000 22.4861 1.0000
103.1000 21.2883 1.0000
103.2000 11.7281 1.0000
103.3000 19.5522 1.0000
103.4000 19.5667 1.0000
103.5000 19.7580 1.0000
103.6000 19.8536 1.0000
103.7000 19.4631 1.0000
103.8000 21.8394 1.0000
103.9000 23.3280 1.0000
104.0000 16.1600 1.0000
104.1000 19.0935 1.0000
104.2000 25.1867 1.0000
104.3000 17.0778 1.0000
104.4000 19.6140 1.0000
104.5000 20.3934 1.0000
104.6000 26.3792 1.0000
104.7000 15.8484 1.0000
104.8000 19.9628 1.0000
104.9000 20.9568 1.0000
105.0000 22.5492 1.0000
105.1000 15.0723 1.0000
105.2000 30.2095 1.0000
105.3000 17.9959 1.0000
105.4000 19.4911 1.0000
105.5000 19.2464 1.0000
105.6000 21.7320 1.0000
105.7000 21.1987 1.0000
105.8000 19.9534 1.0000
105.9000 26.2258 1.0000
106.0000 27.3172 1.0000
106.1000 17.6705 1.0000
106.2000 26.5695 1.0000
106.3000 27.1486 1.0000
106.4000 24.4137 1.0000
106.5000 25.9383 1.0000
106.6000 22.3223 1.0000
106.7000 17.3128 1.0000
106.8000 10.6335 1.0000
106.9000 20.2521 1.0000
107.0000 28.0940 1.0000
107.1000 17.0504 1.0000
107.2000 23.8976 1.0000
107.3000 24.5898 1.0000
107.4000 23.3183 1.0000
107.5000 17.9191 1.0000
107.6000 20.0049 1.0000
107.7000 27.4183 1.0000
107.8000 21.3104 1.0000
107.9000 17.7504 1.0000
108.0000 24.2126 1.0000
108.1000 16.7887 1.0000
108.2000 20.4627 1.0000
108.3000 22.2953 1.0000
108.4000 28.6126 1.0000
108.5000 21.9796 1.0000
108.6000 18.5176 1.0000
108.7000 18.1550 1.0000
108.8000 26.5129 1.0000
108.9000 20.0740 1.0000
109.0000 18.4917 1.0000
109.1000 22.9894 1.0000
109.2000 23.1006 1.0000
109.3000 31.4897 1.0000
109.4000 19.0289 1.0000
109.5000 27.4473 1.0000
109.6000 19.9759 1.0000
109.7000 33.7730 1.0000
109.8000 13.2886 1.0000
109.9000 22.4693 1.0000
110.0000 24.3750 1.0000
110.1000 17.7793 1.0000
110.2000 26.8111 1.0000
110.3000 22.4743 1.0000
110.4000 23.5604 1.0000
110.5000 21.6478 1.0000
110.6000 25.7091 1.0000
110.7000 24.5301 1.0000
110.8000 23.2515 1.0000
110.9000 25.8964 1.0000
111.0000 19.7283 1.0000
111.1000 26.4661 1.0000
111.2000 18.4289 1.0000
111.3000 20.7824 1.0000
111.4000 24.4921 1.0000
111.5000 18.2566 1.0000
111.6000 16.9006 1.0000
111.7000 18.5482 1.0000
111.8000 16.5839 1.0000
111.9000 22.5942 1.0000
112.0000 25.1464 1.0000
112.1000 22.4617 1.0000
112.2000 22.7064 1.0000
112.3000 21.3807 1.0000
112.4000 19.5291 1.0000
112.5000 19.2096 1.0000
112.6000 15.5710 1.0000
112.7000 23.4380 1.0000
112.8000 22.6189 1.0000
112.9000 22.3665 1.0000
113.0000 21.3867 1.0000
113.1000 23.9120 1.0000
113.2000 25.4465 1.0000
113.3000 18.7415 1.0000
113.4000 20.6354 1.0000
113.5000 12.3554 1.0000
113.6000 17.2130 1.0000
113.7000 15.7881 1.0000
113.8000 26.4149 1.0000
113.9000 23.9957 1.0000
114.0000 26.2387 1.0000
114.1000 27.5765 1.0000
114.2000 20.9020 1.0000
114.3000 19.4611 1.0000
114.4000 22.8903 1.0000
114.5000 20.6323 1.0000
114.6000 18.5207 1.0000
114.7000 17.7656 1.0000
114.8000 27.5227 1.0000
114.9000 24.0396 1.0000
115.0000 23.7870 1.0000
115.1000 29.4551 1.0000
115.2000 23.2948 1.0000
115.3000 22.4682 1.0000
115.4000 26.9940 1.0000
115.5000 35.9383 1.0000
115.6000 47.9469 1.0000
115.7000 43.2139 1.0000
115.8000 63.9343 1.0000
115.9000 61.4009 1.0000
116.0000 45.1496 1.0000
116.1000 44.6999 1.0000
116.2000 33.7326 1.0000
116.3000 38.0747 1.0000
116.4000 23.3556 1.0000
116.5000 17.0951 1.0000
116.6000 25.7605 1.0000
116.7000 22.6945 1.0000
116.8000 15.4899 1.0000
116.9000 22.6310 1.0000
117.0000 26.9295 1.0000
117.1000 20.6492 1.0000
117.2000 27.2798 1.0000
117.3000 31.3108 1.0000
117.4000 30.1826 1.0000
117.5000 27.9827 1.0000
117.6000 19.7691 1.0000
117.7000 18.5771 1.0000
117.8000 9.5187 1.0000
117.9000 22.5562 1.0000
118.0000 27.9361 1.0000
118.1000 17.2611 1.0000
118.2000 24.8570 1.0000
118.3000 13.6798 1.0000
118.4000 15.9182 1.0000
118.5000 19.4068 1.0000
118.6000 32.0811 1.0000
118.7000 23.4802 1.0000
118.8000 20.7821 1.0000
118.9000 23.1991 1.0000
119.0000 19.2467 1.0000
119.1000 20.9354 1.0000
119.2000 23.3702 1.0000
119.3000 24.4232 1.0000
119.4000 19.2227 1.0000
119.5000 18.3496 1.0000
119.6000 16.5514 1.0000
119.7000 23.3463 1.0000
119.8000 19.9554 1.0000
119.9000 18.7707 1.0000
120.0000 21.5202 1.0000
120.1000 19.4642 1.0000
120.2000 20.6141 1.0000
120.3000 22.8230 1.0000
120.4000 23.6560 1.0000
120.5000 18.3690 1.0000
120.6000 19.3935 1.0000
120.7000 16.2709 1.0000
120.8000 13.2972 1.0000
120.9000 25.5847 1.0000
121.0000 16.0826 1.0000
121.1000 16.8751 1.0000
121.2000 22.1067 1.0000
121.3000 16.8129 1.0000
121.4000 29.3160 1.0000
121.5000 22.7529 1.0000
121.6000 19.8271 1.0000
121.7000 20.6367 1.0000
121.8000 19.9378 1.0000
121.9000 16.2834 1.0000
122.0000 20.6438 1.0000
122.1000 20.5154 1.0000
122.2000 19.3782 1.0000
122.3000 24.3151 1.0000
122.4000 28.4492 1.0000
122.5000 15.0091 1.0000
122.6000 21.1889 1.0000
122.7000 17.6607 1.0000
122.8000 14.5528 1.0000
122.9000 16.4094 1.0000
123.0000 20.6984 1.0000
123.1000 20.2812 1.0000
123.2000 19.5984 1.0000
123.3000 20.1819 1.0000
123.4000 20.8047 1.0000
123.5000 13.8594 1.0000
123.6000 29.9218 1.0000
123.7000 23.4998 1.0000
123.8000 17.3376 1.0000
123.9000 28.0471 1.0000
124.0000 20.9500 1.0000
124.1000 28.3714 1.0000
124.2000 16.3402 1.0000
124.3000 25.6884 1.0000
124.4000 22.6481 1.0000
124.5000 21.6337 1.0000
124.6000 20.5525 1.0000
124.7000 21.0031 1.0000
124.8000 24.9413 1.0000
124.9000 27.1231 1.0000
125.0000 19.7015 1.0000
125.1000 14.4329 1.0000
125.2000 23.5162 1.0000
125.3000 26.2495 1.0000
125.4000 17.7020 1.0000
125.5000 15.2519 1.0000
125.6000 23.3871 1.0000
125.7000 17.2878 1.0000
125.8000 22.2068 1.0000
125.9000 21.7780 1.0000
126.0000 28.6414 1.0000
126.1000 14.8446 1.0000
126.2000 23.3813 1.0000
126.3000 22.3184 1.0000
126.4000 22.9594 1.0000
126.5000 23.6929 1.0000
126.6000 21.7205 1.0000
126.7000 19.4873 1.0000
126.8000 36.0651 1.0000
126.9000 22.9475 1.0000
127.0000 25.6505 1.0000
127.1000 17.2023 1.0000
127.2000 16.1966 1.0000
127.3000 25.7705 1.0000
127.4000 17.4721 1.0000
127.5000 24.8414 1.0000
127.6000 30.2200 1.0000
127.7000 12.3164 1.0000
127.8000 26.0715 1.0000
127.9000 11.9328 1.0000
128.0000 21.4886 1.0000
128.1000 27.7529 1.0000
128.2000 24.0662 1.0000
128.3000 21.5024 1.0000
128.4000 16.8526 1.0000
128.5000 17.4604 1.0000
128.6000 20.4124 1.0000
128.7000 24.1428 1.0000
128.8000 15.3415 1.0000
128.9000 18.6032 1.0000
129.0000 17.2192 1.0000
129.1000 25.1982 1.0000
129.2000 18.6313 1.0000
129.3000 18.2753 1.0000
129.4000 32.8715 1.0000
129.5000 21.0003 1.0000
129.6000 27.5263 1.0000
129.7000 22.0082 1.0000
129.8000 22.7637 1.0000
129.9000 29.3264 1.0000
130.0000 13.5590 1.0000
*RAS_INT_END
*RAS_TEMPERATURE_START
*RAS_TEMPERATURE_END
*RAS_DATA_END