File: XRD/May_2022/EFRW2_Unirradiated_region/PB_Ge220_5SS_500umDS_RS1_Rod_5SS_Hypix1D_EFRW2_HAZ_P-irradiated.ras
*RAS_DATA_START
*RAS_HEADER_START
*DISP_FMT_X "%.3f"
*DISP_FMT_Y "%.0f"
*DISP_FULLSCALE "1100.2051481018"
*DISP_LINE_COLOR "255.0000000000"
*DISP_LINE_STYLE "0.0000000000"
*DISP_LINE_WIDTH "0.2500000000"
*DISP_NOTE "Collected Data-39"
*DISP_OFFSET_Y "0.0000000000"
*DISP_PEAKSEARCH_UNIT_Y "cps"
*DISP_RANGE_BOTTOM "0.0000000000"
*DISP_RANGE_LEFT "40.0000000000"
*DISP_RANGE_LOGCUTOFF "0.0100000000"
*DISP_RANGE_RIGHT "119.9968000000"
*DISP_RANGE_TOP "1100.2051481018"
*DISP_SCALE_MODE_Y "0.0000000000"
*DISP_TAB_NAME "Theta/2-Theta"
*DISP_TITLE_Y "Intensity"
*DISP_UNIT_Y "cps"
*DISP_WINDOW_NAME "MSG_MACROENGINE"
*FILE_COMMENT " "
*FILE_MD5 ""
*FILE_MEMO " "
*FILE_OPERATOR "Administrator"
*FILE_PART_ID "MEAS_KHP2_00061"
*FILE_SAMPLE " "
*FILE_TYPE "RAS_RAW"
*FILE_USERGROUP "System Manager"
*FILE_VERSION "1.0000000000"
*HW_ATTACHMENT_ID "ATT0021"
*HW_ATTACHMENT_NAME "XY-20mm|XY-20mm"
*HW_COUNTER_ID-0 "CUT0041"
*HW_COUNTER_ID-1 "CUT0051"
*HW_COUNTER_ID-2 "CUT0020"
*HW_COUNTER_ID-3 "CSL0021"
*HW_COUNTER_ID-4 "CMC0021"
*HW_COUNTER_NAME-0 "D/teX Ultra 250|D/teX Ultra 250"
*HW_COUNTER_NAME-1 "HyPix 3000(H)|HyPix 3000(H)"
*HW_COUNTER_NAME-2 "None|None"
*HW_COUNTER_NAME-3 "BBM|BBM"
*HW_COUNTER_NAME-4 "検出器モノクロメータ|Detector monochromator"
*HW_COUNTER_SELECT_NAME "HyPix 3000(H)|HyPix 3000(H)"
*HW_GONIOMETER_ID "GON0024"
*HW_GONIOMETER_NAME "SmartLab(In-plane)|SmartLab(In-plane)"
*HW_GONIOMETER_RADIUS-0 "90.0"
*HW_GONIOMETER_RADIUS-1 "114.0"
*HW_GONIOMETER_RADIUS-2 "190.0"
*HW_GONIOMETER_RADIUS-3 "300.0"
*HW_GONIOMETER_RADIUS-4 "187.0"
*HW_GONIOMETER_RADIUS-5 "300.0"
*HW_GONIOMETER_RADIUS-6 "113.0"
*HW_GONIOMETER_RADIUS-7 "331.0"
*HW_I_OPT_ID-0 "CBO0021"
*HW_I_OPT_ID-1 "ICR0021"
*HW_I_OPT_ID-2 "ISL0021"
*HW_I_OPT_ID-3 "ISO0021"
*HW_I_OPT_ID-4 "IAD0021"
*HW_I_OPT_ID-5 "IPR0001"
*HW_I_OPT_NAME-0 "CBOユニット|CBO unit"
*HW_I_OPT_NAME-1 "標準入射光学ユニット|Standard incident optical unit"
*HW_I_OPT_NAME-2 "標準入射スリットボックス|Standard incident slit box"
*HW_I_OPT_NAME-3 "入射平行スリット|Incident parallel slit"
*HW_I_OPT_NAME-4 "長手制限スリット|Length limiting slit"
*HW_I_OPT_NAME-5 "None|None"
*HW_R_ATTENUATER_AUTOMODE "0"
*HW_R_OPT_ID-0 "RSS0022"
*HW_R_OPT_ID-1 "RCR0022"
*HW_R_OPT_ID-2 "RSO0021"
*HW_R_OPT_ID-3 "RRS0022"
*HW_R_OPT_ID-4 "ATN0020"
*HW_R_OPT_ID-5 "RFL0021"
*HW_R_OPT_ID-6 "RAD0021"
*HW_R_OPT_NAME-0 "受光スリットボックス1(Zr軸付)|Receiving slit box # 1 (w/ Zr Axis)"
*HW_R_OPT_NAME-1 "標準受光光学ユニット1|Standard receiving unit # 1"
*HW_R_OPT_NAME-2 "標準受光光学ユニット2|Standard receiving optical unit # 2"
*HW_R_OPT_NAME-3 "仮想受光スリット2|Virtual receiving slit #2"
*HW_R_OPT_NAME-4 "無し|None"
*HW_R_OPT_NAME-5 "Cu Kβ|Cu K-beta"
*HW_R_OPT_NAME-6 "調整用受光スリット|Alignment receiving slit"
*HW_SAMPLE_HOLDER_ID "SMP0021"
*HW_SAMPLE_HOLDER_NAME "χφZクレードル|Chi phi Z cradle"
*HW_XG_CURRENT_MAX "40"
*HW_XG_CURRENT_MIN "2"
*HW_XG_CURRENT_RESOLUTION "1"
*HW_XG_CURRENT_UNIT "mA"
*HW_XG_FOCUS "0.4mm x 8mm"
*HW_XG_FOCUS_TYPE "Fine"
*HW_XG_ID "1200"
*HW_XG_NAME "3kW 封入管(ID:1200)|3kW Sealed tube(ID:1200)"
*HW_XG_TARGET_ATOMIC_NUMBER "29.0000000000"
*HW_XG_TARGET_NAME "Cu"
*HW_XG_TYPE "Hermetic"
*HW_XG_VOLTAGE_MAX "40"
*HW_XG_VOLTAGE_MIN "20"
*HW_XG_VOLTAGE_RESOLUTION "1"
*HW_XG_VOLTAGE_UNIT "kV"
*HW_XG_WATT_MAX "1.500"
*HW_XG_WATT_UNIT "kW"
*HW_XG_WAVE_LENGTH_ALPHA1 "1.540593"
*HW_XG_WAVE_LENGTH_ALPHA2 "1.544414"
*HW_XG_WAVE_LENGTH_BETA "1.392250"
*MEAS_COND_AXIS_NAME-0 "Theta/2-Theta"
*MEAS_COND_AXIS_NAME-1 "2-Theta"
*MEAS_COND_AXIS_NAME-2 "Omega"
*MEAS_COND_AXIS_NAME-3 "Chi"
*MEAS_COND_AXIS_NAME-4 "Phi"
*MEAS_COND_AXIS_NAME-5 "Z"
*MEAS_COND_AXIS_NAME-6 "X"
*MEAS_COND_AXIS_NAME-7 "Y"
*MEAS_COND_AXIS_NAME-8 "2-Theta/Omega"
*MEAS_COND_AXIS_NAME-9 "2-ThetaChi"
*MEAS_COND_AXIS_NAME-10 "2-ThetaChi/Phi"
*MEAS_COND_AXIS_NAME-11 "Alpha"
*MEAS_COND_AXIS_NAME-12 "Beta"
*MEAS_COND_AXIS_NAME-13 "Theta_s"
*MEAS_COND_AXIS_NAME-14 "Theta_d"
*MEAS_COND_AXIS_NAME-15 "Ts"
*MEAS_COND_AXIS_NAME-16 "CBO selection slit"
*MEAS_COND_AXIS_NAME-17 "M"
*MEAS_COND_AXIS_NAME-18 "Incident parallel slit"
*MEAS_COND_AXIS_NAME-19 "Incident slit"
*MEAS_COND_AXIS_NAME-20 ""
*MEAS_COND_AXIS_NAME-21 "Zs"
*MEAS_COND_AXIS_NAME-22 "Incident optical device"
*MEAS_COND_AXIS_NAME-23 "Omega_m"
*MEAS_COND_AXIS_NAME-24 "Length limiting slit"
*MEAS_COND_AXIS_NAME-25 "Center slit"
*MEAS_COND_AXIS_NAME-26 "Filter"
*MEAS_COND_AXIS_NAME-27 "Receiving slit # 1"
*MEAS_COND_AXIS_NAME-28 "Receiving slit # 2"
*MEAS_COND_AXIS_NAME-29 "Receiving optical device"
*MEAS_COND_AXIS_NAME-30 "Receiving parallel slit"
*MEAS_COND_AXIS_NAME-31 "Alignment receiving slit"
*MEAS_COND_AXIS_NAME-32 ""
*MEAS_COND_AXIS_NAME-33 ""
*MEAS_COND_AXIS_NAME-34 "Zd"
*MEAS_COND_AXIS_NAME-35 "Attenuator"
*MEAS_COND_AXIS_NAME-36 "Diffracted beam monochromator"
*MEAS_COND_AXIS_NAME-37 "Monochromator slit"
*MEAS_COND_AXIS_NAME-38 "2-ThetaB"
*MEAS_COND_AXIS_NAME-39 ""
*MEAS_COND_AXIS_NAME-40 ""
*MEAS_COND_AXIS_NAME-41 "Zr"
*MEAS_COND_AXIS_NAME-42 "Primary beam"
*MEAS_COND_AXIS_NAME_INTERNAL-0 "TwoThetaTheta"
*MEAS_COND_AXIS_NAME_INTERNAL-1 "TwoTheta"
*MEAS_COND_AXIS_NAME_INTERNAL-2 "Omega"
*MEAS_COND_AXIS_NAME_INTERNAL-3 "Chi"
*MEAS_COND_AXIS_NAME_INTERNAL-4 "Phi"
*MEAS_COND_AXIS_NAME_INTERNAL-5 "Z"
*MEAS_COND_AXIS_NAME_INTERNAL-6 "X"
*MEAS_COND_AXIS_NAME_INTERNAL-7 "Y"
*MEAS_COND_AXIS_NAME_INTERNAL-8 "TwoThetaOmega"
*MEAS_COND_AXIS_NAME_INTERNAL-9 "TwoThetaChi"
*MEAS_COND_AXIS_NAME_INTERNAL-10 "TwoThetaChiPhi"
*MEAS_COND_AXIS_NAME_INTERNAL-11 "Alpha"
*MEAS_COND_AXIS_NAME_INTERNAL-12 "Beta"
*MEAS_COND_AXIS_NAME_INTERNAL-13 "ThetaS"
*MEAS_COND_AXIS_NAME_INTERNAL-14 "ThetaD"
*MEAS_COND_AXIS_NAME_INTERNAL-15 "Ts"
*MEAS_COND_AXIS_NAME_INTERNAL-16 "CBO"
*MEAS_COND_AXIS_NAME_INTERNAL-17 "CBO-M"
*MEAS_COND_AXIS_NAME_INTERNAL-18 "IncidentSollerSlit"
*MEAS_COND_AXIS_NAME_INTERNAL-19 "IncidentSlitBox"
*MEAS_COND_AXIS_NAME_INTERNAL-20 "IncidentSlitBox-_Axis"
*MEAS_COND_AXIS_NAME_INTERNAL-21 "Zs"
*MEAS_COND_AXIS_NAME_INTERNAL-22 "IncidentMonochromator"
*MEAS_COND_AXIS_NAME_INTERNAL-23 "IncidentMonochromator-OmegaM"
*MEAS_COND_AXIS_NAME_INTERNAL-24 "IncidentAxdSlit"
*MEAS_COND_AXIS_NAME_INTERNAL-25 "CenterSlit"
*MEAS_COND_AXIS_NAME_INTERNAL-26 "Filter"
*MEAS_COND_AXIS_NAME_INTERNAL-27 "ReceivingSlitBox1"
*MEAS_COND_AXIS_NAME_INTERNAL-28 "ReceivingSlitBox2"
*MEAS_COND_AXIS_NAME_INTERNAL-29 "ReceivingOptics"
*MEAS_COND_AXIS_NAME_INTERNAL-30 "ReceivingSollerSlit"
*MEAS_COND_AXIS_NAME_INTERNAL-31 "ReceivingAxdSlit"
*MEAS_COND_AXIS_NAME_INTERNAL-32 "ReceivingSlitBox1-_Axis"
*MEAS_COND_AXIS_NAME_INTERNAL-33 "ReceivingSlitBox2-_Axis"
*MEAS_COND_AXIS_NAME_INTERNAL-34 "ReceivingSlitBox2-Zd"
*MEAS_COND_AXIS_NAME_INTERNAL-35 "Attenuator"
*MEAS_COND_AXIS_NAME_INTERNAL-36 "CounterMonochromator"
*MEAS_COND_AXIS_NAME_INTERNAL-37 "CounterSlit"
*MEAS_COND_AXIS_NAME_INTERNAL-38 "TwoThetaB"
*MEAS_COND_AXIS_NAME_INTERNAL-39 "AlphaR"
*MEAS_COND_AXIS_NAME_INTERNAL-40 "BetaR"
*MEAS_COND_AXIS_NAME_INTERNAL-41 "ReceivingSlitBox1-Zr"
*MEAS_COND_AXIS_NAME_INTERNAL-42 "IncidentPrimary"
*MEAS_COND_AXIS_NAME_MAGICNO-0 "83951616.0000000000"
*MEAS_COND_AXIS_NAME_MAGICNO-1 "268632064.0000000000"
*MEAS_COND_AXIS_NAME_MAGICNO-2 "268500992.0000000000"
*MEAS_COND_AXIS_NAME_MAGICNO-3 "268500992.0000000000"
*MEAS_COND_AXIS_NAME_MAGICNO-4 "268500992.0000000000"
*MEAS_COND_AXIS_NAME_MAGICNO-5 "285278208.0000000000"
*MEAS_COND_AXIS_NAME_MAGICNO-6 "268500992.0000000000"
*MEAS_COND_AXIS_NAME_MAGICNO-7 "268500992.0000000000"
*MEAS_COND_AXIS_NAME_MAGICNO-8 "83951616.0000000000"
*MEAS_COND_AXIS_NAME_MAGICNO-9 "268632064.0000000000"
*MEAS_COND_AXIS_NAME_MAGICNO-10 "83951616.0000000000"
*MEAS_COND_AXIS_NAME_MAGICNO-11 "17039360.0000000000"
*MEAS_COND_AXIS_NAME_MAGICNO-12 "17039360.0000000000"
*MEAS_COND_AXIS_NAME_MAGICNO-13 "131072.0000000000"
*MEAS_COND_AXIS_NAME_MAGICNO-14 "131072.0000000000"
*MEAS_COND_AXIS_NAME_MAGICNO-15 "318898176.0000000000"
*MEAS_COND_AXIS_NAME_MAGICNO-16 "20971521.0000000000"
*MEAS_COND_AXIS_NAME_MAGICNO-17 "285343744.0000000000"
*MEAS_COND_AXIS_NAME_MAGICNO-18 "20971521.0000000000"
*MEAS_COND_AXIS_NAME_MAGICNO-19 "22020097.0000000000"
*MEAS_COND_AXIS_NAME_MAGICNO-20 "25165824.0000000000"
*MEAS_COND_AXIS_NAME_MAGICNO-21 "318898176.0000000000"
*MEAS_COND_AXIS_NAME_MAGICNO-22 "20971521.0000000000"
*MEAS_COND_AXIS_NAME_MAGICNO-23 "285343744.0000000000"
*MEAS_COND_AXIS_NAME_MAGICNO-24 "20971521.0000000000"
*MEAS_COND_AXIS_NAME_MAGICNO-25 "20971521.0000000000"
*MEAS_COND_AXIS_NAME_MAGICNO-26 "20971521.0000000000"
*MEAS_COND_AXIS_NAME_MAGICNO-27 "23068673.0000000000"
*MEAS_COND_AXIS_NAME_MAGICNO-28 "23068673.0000000000"
*MEAS_COND_AXIS_NAME_MAGICNO-29 "20971521.0000000000"
*MEAS_COND_AXIS_NAME_MAGICNO-30 "20971521.0000000000"
*MEAS_COND_AXIS_NAME_MAGICNO-31 "20971521.0000000000"
*MEAS_COND_AXIS_NAME_MAGICNO-32 "25165824.0000000000"
*MEAS_COND_AXIS_NAME_MAGICNO-33 "25165824.0000000000"
*MEAS_COND_AXIS_NAME_MAGICNO-34 "285343744.0000000000"
*MEAS_COND_AXIS_NAME_MAGICNO-35 "0.0000000000"
*MEAS_COND_AXIS_NAME_MAGICNO-36 "20971521.0000000000"
*MEAS_COND_AXIS_NAME_MAGICNO-37 "20971521.0000000000"
*MEAS_COND_AXIS_NAME_MAGICNO-38 "17039360.0000000000"
*MEAS_COND_AXIS_NAME_MAGICNO-39 "8388608.0000000000"
*MEAS_COND_AXIS_NAME_MAGICNO-40 "8388608.0000000000"
*MEAS_COND_AXIS_NAME_MAGICNO-41 "285343744.0000000000"
*MEAS_COND_AXIS_NAME_MAGICNO-42 "20971521.0000000000"
*MEAS_COND_AXIS_OFFSET-0 "-"
*MEAS_COND_AXIS_OFFSET-1 "0.9261000000"
*MEAS_COND_AXIS_OFFSET-2 "1.0829000000"
*MEAS_COND_AXIS_OFFSET-3 "0.0000000000"
*MEAS_COND_AXIS_OFFSET-4 "0.0000000000"
*MEAS_COND_AXIS_OFFSET-5 "-"
*MEAS_COND_AXIS_OFFSET-6 "0.0000000000"
*MEAS_COND_AXIS_OFFSET-7 "0.0000000000"
*MEAS_COND_AXIS_OFFSET-8 "-"
*MEAS_COND_AXIS_OFFSET-9 "0.0000000000"
*MEAS_COND_AXIS_OFFSET-10 "-"
*MEAS_COND_AXIS_OFFSET-11 "-"
*MEAS_COND_AXIS_OFFSET-12 "-"
*MEAS_COND_AXIS_OFFSET-13 "1.0829000000"
*MEAS_COND_AXIS_OFFSET-14 "-0.1568000000"
*MEAS_COND_AXIS_OFFSET-15 "-"
*MEAS_COND_AXIS_OFFSET-16 "-"
*MEAS_COND_AXIS_OFFSET-17 "-"
*MEAS_COND_AXIS_OFFSET-18 "-"
*MEAS_COND_AXIS_OFFSET-19 "-"
*MEAS_COND_AXIS_OFFSET-20 "-"
*MEAS_COND_AXIS_OFFSET-21 "-"
*MEAS_COND_AXIS_OFFSET-22 "-"
*MEAS_COND_AXIS_OFFSET-23 "-"
*MEAS_COND_AXIS_OFFSET-24 "-"
*MEAS_COND_AXIS_OFFSET-25 "-"
*MEAS_COND_AXIS_OFFSET-26 "-"
*MEAS_COND_AXIS_OFFSET-27 "-"
*MEAS_COND_AXIS_OFFSET-28 "-"
*MEAS_COND_AXIS_OFFSET-29 "-"
*MEAS_COND_AXIS_OFFSET-30 "-"
*MEAS_COND_AXIS_OFFSET-31 "-"
*MEAS_COND_AXIS_OFFSET-32 "-"
*MEAS_COND_AXIS_OFFSET-33 "-"
*MEAS_COND_AXIS_OFFSET-34 "-"
*MEAS_COND_AXIS_OFFSET-35 "-"
*MEAS_COND_AXIS_OFFSET-36 "-"
*MEAS_COND_AXIS_OFFSET-37 "-"
*MEAS_COND_AXIS_OFFSET-38 "-"
*MEAS_COND_AXIS_OFFSET-39 "0.0000000000"
*MEAS_COND_AXIS_OFFSET-40 "0.0000000000"
*MEAS_COND_AXIS_OFFSET-41 "-"
*MEAS_COND_AXIS_OFFSET-42 "-"
*MEAS_COND_AXIS_POSITION-0 "40.0000000000"
*MEAS_COND_AXIS_POSITION-1 "40.0000000000"
*MEAS_COND_AXIS_POSITION-2 "20.0000000000"
*MEAS_COND_AXIS_POSITION-3 "0.0000000000"
*MEAS_COND_AXIS_POSITION-4 "0.0000000000"
*MEAS_COND_AXIS_POSITION-5 "-2.0050000000"
*MEAS_COND_AXIS_POSITION-6 "0.5630000000"
*MEAS_COND_AXIS_POSITION-7 "-1.0010000000"
*MEAS_COND_AXIS_POSITION-8 "40.0000000000"
*MEAS_COND_AXIS_POSITION-9 "0.0000000000"
*MEAS_COND_AXIS_POSITION-10 "0.0000000000"
*MEAS_COND_AXIS_POSITION-11 "90.0000000000"
*MEAS_COND_AXIS_POSITION-12 "0.0000000000"
*MEAS_COND_AXIS_POSITION-13 "20.0000000000"
*MEAS_COND_AXIS_POSITION-14 "20.0000000000"
*MEAS_COND_AXIS_POSITION-15 "-5.4951200000"
*MEAS_COND_AXIS_POSITION-16 "PB"
*MEAS_COND_AXIS_POSITION-17 "0.0000000000"
*MEAS_COND_AXIS_POSITION-18 "Soller_slit_5.0deg_s"
*MEAS_COND_AXIS_POSITION-19 "1.000mm"
*MEAS_COND_AXIS_POSITION-20 "1.0000000000"
*MEAS_COND_AXIS_POSITION-21 "-1.2471900000"
*MEAS_COND_AXIS_POSITION-22 "Ge(220)x2"
*MEAS_COND_AXIS_POSITION-23 "0.0000000000"
*MEAS_COND_AXIS_POSITION-24 "0.5mm"
*MEAS_COND_AXIS_POSITION-25 "None"
*MEAS_COND_AXIS_POSITION-26 "None"
*MEAS_COND_AXIS_POSITION-27 "20.000mm"
*MEAS_COND_AXIS_POSITION-28 "38.500mm"
*MEAS_COND_AXIS_POSITION-29 "PSA_open"
*MEAS_COND_AXIS_POSITION-30 "Soller_slit_5.0deg"
*MEAS_COND_AXIS_POSITION-31 "None"
*MEAS_COND_AXIS_POSITION-32 "20.0000000000"
*MEAS_COND_AXIS_POSITION-33 "38.5000000000"
*MEAS_COND_AXIS_POSITION-34 "0.0000000000"
*MEAS_COND_AXIS_POSITION-35 "-"
*MEAS_COND_AXIS_POSITION-36 "No_unit"
*MEAS_COND_AXIS_POSITION-37 "None"
*MEAS_COND_AXIS_POSITION-38 "40.0000000000"
*MEAS_COND_AXIS_POSITION-39 "0.0000000000"
*MEAS_COND_AXIS_POSITION-40 "0.0000000000"
*MEAS_COND_AXIS_POSITION-41 "0.1325000000"
*MEAS_COND_AXIS_POSITION-42 "None"
*MEAS_COND_AXIS_UNIT-0 "deg"
*MEAS_COND_AXIS_UNIT-1 "deg"
*MEAS_COND_AXIS_UNIT-2 "deg"
*MEAS_COND_AXIS_UNIT-3 "deg"
*MEAS_COND_AXIS_UNIT-4 "deg"
*MEAS_COND_AXIS_UNIT-5 "mm"
*MEAS_COND_AXIS_UNIT-6 "mm"
*MEAS_COND_AXIS_UNIT-7 "mm"
*MEAS_COND_AXIS_UNIT-8 "deg"
*MEAS_COND_AXIS_UNIT-9 "deg"
*MEAS_COND_AXIS_UNIT-10 "deg"
*MEAS_COND_AXIS_UNIT-11 "deg"
*MEAS_COND_AXIS_UNIT-12 "deg"
*MEAS_COND_AXIS_UNIT-13 "deg"
*MEAS_COND_AXIS_UNIT-14 "deg"
*MEAS_COND_AXIS_UNIT-15 "mm"
*MEAS_COND_AXIS_UNIT-16 ""
*MEAS_COND_AXIS_UNIT-17 "pulse"
*MEAS_COND_AXIS_UNIT-18 ""
*MEAS_COND_AXIS_UNIT-19 ""
*MEAS_COND_AXIS_UNIT-20 "mm"
*MEAS_COND_AXIS_UNIT-21 "mm"
*MEAS_COND_AXIS_UNIT-22 ""
*MEAS_COND_AXIS_UNIT-23 "pulse"
*MEAS_COND_AXIS_UNIT-24 ""
*MEAS_COND_AXIS_UNIT-25 ""
*MEAS_COND_AXIS_UNIT-26 ""
*MEAS_COND_AXIS_UNIT-27 ""
*MEAS_COND_AXIS_UNIT-28 ""
*MEAS_COND_AXIS_UNIT-29 ""
*MEAS_COND_AXIS_UNIT-30 ""
*MEAS_COND_AXIS_UNIT-31 ""
*MEAS_COND_AXIS_UNIT-32 "mm"
*MEAS_COND_AXIS_UNIT-33 "mm"
*MEAS_COND_AXIS_UNIT-34 "mm"
*MEAS_COND_AXIS_UNIT-35 ""
*MEAS_COND_AXIS_UNIT-36 ""
*MEAS_COND_AXIS_UNIT-37 ""
*MEAS_COND_AXIS_UNIT-38 "deg"
*MEAS_COND_AXIS_UNIT-39 "deg"
*MEAS_COND_AXIS_UNIT-40 "deg"
*MEAS_COND_AXIS_UNIT-41 "mm"
*MEAS_COND_AXIS_UNIT-42 ""
*MEAS_COND_COUNTER_CNTLOSS_CORR "0.0000000000"
*MEAS_COND_COUNTER_TAUDIFF "0.0000000000"
*MEAS_COND_COUNTER_TAUINT "0.0000000000"
*MEAS_COND_COUNTER_TEMP_CONDITION "NORMAL"
*MEAS_COND_IRRADIATION_MODE "OFF"
*MEAS_COND_IRRADIATION_WIDTH ""
*MEAS_COND_OPT_ATTR "High resolution parallel beam Ge(220)x2/RS"
*MEAS_COND_OPT_NAME "@High resolution PB-Ge(220)x2"
*MEAS_COND_UNSYMMETRIC_MODE "OFF"
*MEAS_COND_XG_CURRENT "30.0000000000"
*MEAS_COND_XG_VOLTAGE "40.0000000000"
*MEAS_COND_XG_WAVE_TYPE "Ka1"
*MEAS_DATA_COUNT "8000.0000000000"
*MEAS_SCAN_AXIS_X "Theta/2-Theta"
*MEAS_SCAN_AXIS_X_INTERNAL "TwoThetaTheta"
*MEAS_SCAN_END_TIME "04/15/22 12:39:16"
*MEAS_SCAN_MODE "CONTINUOUS"
*MEAS_SCAN_MONITOR "0"
*MEAS_SCAN_RESOLUTION_X "0.0002"
*MEAS_SCAN_SPEED "0.503240"
*MEAS_SCAN_SPEED_UNIT "deg/min"
*MEAS_SCAN_SPEED_USER "0.5"
*MEAS_SCAN_START "40.0000000000"
*MEAS_SCAN_START_TIME "04/15/22 09:44:27"
*MEAS_SCAN_STEP "0.0100000000"
*MEAS_SCAN_STOP "119.9900000000"
*MEAS_SCAN_UNIT_X "deg"
*MEAS_SCAN_UNIT_Y "counts"
*RAS_HEADER_END
*RAS_INT_START
40.0000 27.7659 1.0000
40.0600 13.3598 1.0000
40.1200 18.7327 1.0000
40.1800 15.4643 1.0000
40.2400 19.7548 1.0000
40.3000 21.0009 1.0000
40.3600 22.5316 1.0000
40.4200 19.2638 1.0000
40.4800 20.1288 1.0000
40.5400 25.5833 1.0000
40.6000 22.7377 1.0000
40.6600 27.4575 1.0000
40.7200 20.8823 1.0000
40.7800 32.0476 1.0000
40.8400 23.9420 1.0000
40.9000 17.3479 1.0000
40.9600 21.0246 1.0000
41.0200 23.8531 1.0000
41.0800 25.0030 1.0000
41.1400 22.2814 1.0000
41.2000 19.8016 1.0000
41.2600 14.3795 1.0000
41.3200 19.2118 1.0000
41.3800 16.3994 1.0000
41.4400 19.9503 1.0000
41.5000 25.4524 1.0000
41.5600 20.7449 1.0000
41.6200 21.4383 1.0000
41.6800 21.0470 1.0000
41.7400 27.5039 1.0000
41.8000 26.7377 1.0000
41.8600 30.6821 1.0000
41.9200 20.2644 1.0000
41.9800 24.4483 1.0000
42.0400 22.1441 1.0000
42.1000 20.5639 1.0000
42.1600 17.0210 1.0000
42.2200 20.9693 1.0000
42.2800 18.4691 1.0000
42.3400 21.7423 1.0000
42.4000 16.5278 1.0000
42.4600 25.9105 1.0000
42.5200 29.2879 1.0000
42.5800 21.0175 1.0000
42.6400 20.3197 1.0000
42.7000 29.5167 1.0000
42.7600 24.7392 1.0000
42.8200 24.5371 1.0000
42.8800 16.9931 1.0000
42.9400 18.1320 1.0000
43.0000 23.1406 1.0000
43.0600 20.7946 1.0000
43.1200 14.1759 1.0000
43.1800 18.4152 1.0000
43.2400 25.6960 1.0000
43.3000 28.4981 1.0000
43.3600 31.5081 1.0000
43.4200 24.6973 1.0000
43.4800 26.5323 1.0000
43.5400 25.8694 1.0000
43.6000 16.1297 1.0000
43.6600 25.3722 1.0000
43.7200 21.1631 1.0000
43.7800 19.0583 1.0000
43.8400 23.2065 1.0000
43.9000 24.3239 1.0000
43.9600 21.9250 1.0000
44.0200 22.3143 1.0000
44.0800 25.9541 1.0000
44.1400 38.8154 1.0000
44.2000 36.8836 1.0000
44.2600 68.7068 1.0000
44.3200 97.4362 1.0000
44.3800 218.8893 1.0000
44.4400 583.6759 1.0000
44.5000 955.9677 1.0000
44.5600 955.6586 1.0000
44.6200 451.5359 1.0000
44.6800 146.1456 1.0000
44.7400 66.0739 1.0000
44.8000 49.3050 1.0000
44.8600 33.2813 1.0000
44.9200 24.1049 1.0000
44.9800 30.1948 1.0000
45.0400 31.7334 1.0000
45.1000 24.4036 1.0000
45.1600 21.7678 1.0000
45.2200 26.2146 1.0000
45.2800 18.4708 1.0000
45.3400 17.2504 1.0000
45.4000 30.5742 1.0000
45.4600 28.6244 1.0000
45.5200 21.8499 1.0000
45.5800 20.9223 1.0000
45.6400 26.2379 1.0000
45.7000 12.9059 1.0000
45.7600 14.9045 1.0000
45.8200 20.4377 1.0000
45.8800 23.7126 1.0000
45.9400 12.6471 1.0000
46.0000 18.0791 1.0000
46.0600 15.9314 1.0000
46.1200 26.1712 1.0000
46.1800 14.5504 1.0000
46.2400 23.7835 1.0000
46.3000 20.8506 1.0000
46.3600 18.7051 1.0000
46.4200 19.9339 1.0000
46.4800 18.5045 1.0000
46.5400 26.8965 1.0000
46.6000 24.9249 1.0000
46.6600 21.0981 1.0000
46.7200 15.4712 1.0000
46.7800 15.3297 1.0000
46.8400 17.6277 1.0000
46.9000 23.0550 1.0000
46.9600 24.2382 1.0000
47.0200 18.3178 1.0000
47.0800 14.2918 1.0000
47.1400 18.6581 1.0000
47.2000 18.4769 1.0000
47.2600 26.0909 1.0000
47.3200 23.4269 1.0000
47.3800 13.6792 1.0000
47.4400 21.6696 1.0000
47.5000 31.5521 1.0000
47.5600 20.6246 1.0000
47.6200 19.6415 1.0000
47.6800 13.8345 1.0000
47.7400 14.8618 1.0000
47.8000 13.7203 1.0000
47.8600 22.1498 1.0000
47.9200 27.0882 1.0000
47.9800 19.8587 1.0000
48.0400 17.4602 1.0000
48.1000 15.4916 1.0000
48.1600 18.7838 1.0000
48.2200 17.2155 1.0000
48.2800 23.1353 1.0000
48.3400 16.7813 1.0000
48.4000 21.9493 1.0000
48.4600 16.5003 1.0000
48.5200 22.9915 1.0000
48.5800 12.2787 1.0000
48.6400 24.1276 1.0000
48.7000 21.5133 1.0000
48.7600 21.3588 1.0000
48.8200 18.3758 1.0000
48.8800 21.0437 1.0000
48.9400 21.5578 1.0000
49.0000 19.2570 1.0000
49.0600 20.8434 1.0000
49.1200 24.0674 1.0000
49.1800 25.5962 1.0000
49.2400 21.8959 1.0000
49.3000 18.4002 1.0000
49.3600 16.8514 1.0000
49.4200 14.8091 1.0000
49.4800 19.9139 1.0000
49.5400 16.1812 1.0000
49.6000 20.9645 1.0000
49.6600 15.4586 1.0000
49.7200 20.3687 1.0000
49.7800 25.3619 1.0000
49.8400 20.9208 1.0000
49.9000 22.8325 1.0000
49.9600 18.8212 1.0000
50.0200 19.1846 1.0000
50.0800 20.3325 1.0000
50.1400 15.2304 1.0000
50.2000 17.0492 1.0000
50.2600 20.5001 1.0000
50.3200 19.1004 1.0000
50.3800 18.8042 1.0000
50.4400 24.4811 1.0000
50.5000 16.0379 1.0000
50.5600 15.8079 1.0000
50.6200 8.3215 1.0000
50.6800 20.2127 1.0000
50.7400 24.1396 1.0000
50.8000 16.3510 1.0000
50.8600 24.8406 1.0000
50.9200 21.0873 1.0000
50.9800 16.3979 1.0000
51.0400 22.5080 1.0000
51.1000 24.8891 1.0000
51.1600 24.8486 1.0000
51.2200 12.5845 1.0000
51.2800 22.5435 1.0000
51.3400 22.8261 1.0000
51.4000 16.8326 1.0000
51.4600 13.7715 1.0000
51.5200 17.2589 1.0000
51.5800 28.0182 1.0000
51.6400 18.2106 1.0000
51.7000 22.9453 1.0000
51.7600 15.5651 1.0000
51.8200 15.9242 1.0000
51.8800 16.0422 1.0000
51.9400 11.5627 1.0000
52.0000 14.7363 1.0000
52.0600 17.1155 1.0000
52.1200 18.0743 1.0000
52.1800 18.0632 1.0000
52.2400 16.2516 1.0000
52.3000 23.9369 1.0000
52.3600 18.2466 1.0000
52.4200 18.3509 1.0000
52.4800 17.7791 1.0000
52.5400 18.6628 1.0000
52.6000 15.7142 1.0000
52.6600 16.9292 1.0000
52.7200 21.3742 1.0000
52.7800 20.5260 1.0000
52.8400 16.3140 1.0000
52.9000 20.2163 1.0000
52.9600 15.5275 1.0000
53.0200 17.6953 1.0000
53.0800 13.2249 1.0000
53.1400 17.2771 1.0000
53.2000 25.8695 1.0000
53.2600 24.9961 1.0000
53.3200 28.7315 1.0000
53.3800 21.2954 1.0000
53.4400 21.7469 1.0000
53.5000 9.1240 1.0000
53.5600 13.6567 1.0000
53.6200 12.8659 1.0000
53.6800 15.2594 1.0000
53.7400 23.6000 1.0000
53.8000 19.2152 1.0000
53.8600 16.0022 1.0000
53.9200 22.1091 1.0000
53.9800 19.3475 1.0000
54.0400 15.2929 1.0000
54.1000 16.5815 1.0000
54.1600 16.7564 1.0000
54.2200 21.5102 1.0000
54.2800 13.9972 1.0000
54.3400 19.8634 1.0000
54.4000 13.5324 1.0000
54.4600 21.0903 1.0000
54.5200 30.2596 1.0000
54.5800 27.4485 1.0000
54.6400 23.6559 1.0000
54.7000 14.6710 1.0000
54.7600 10.3838 1.0000
54.8200 17.2341 1.0000
54.8800 21.8642 1.0000
54.9400 16.3088 1.0000
55.0000 18.7519 1.0000
55.0600 23.6652 1.0000
55.1200 21.3721 1.0000
55.1800 24.4600 1.0000
55.2400 22.6654 1.0000
55.3000 20.0056 1.0000
55.3600 14.8176 1.0000
55.4200 12.7675 1.0000
55.4800 19.9614 1.0000
55.5400 19.7513 1.0000
55.6000 14.4549 1.0000
55.6600 17.5038 1.0000
55.7200 27.6014 1.0000
55.7800 20.8447 1.0000
55.8400 16.7705 1.0000
55.9000 11.4815 1.0000
55.9600 15.0099 1.0000
56.0200 15.2605 1.0000
56.0800 16.3969 1.0000
56.1400 21.4884 1.0000
56.2000 15.3560 1.0000
56.2600 15.3631 1.0000
56.3200 21.0399 1.0000
56.3800 18.1115 1.0000
56.4400 20.8248 1.0000
56.5000 19.1802 1.0000
56.5600 18.9755 1.0000
56.6200 21.0299 1.0000
56.6800 23.7820 1.0000
56.7400 21.3460 1.0000
56.8000 22.8708 1.0000
56.8600 19.1718 1.0000
56.9200 17.2841 1.0000
56.9800 18.8828 1.0000
57.0400 24.7022 1.0000
57.1000 17.9834 1.0000
57.1600 19.5208 1.0000
57.2200 20.4994 1.0000
57.2800 24.5762 1.0000
57.3400 20.3758 1.0000
57.4000 22.8404 1.0000
57.4600 16.7319 1.0000
57.5200 12.5823 1.0000
57.5800 16.2004 1.0000
57.6400 23.3327 1.0000
57.7000 24.1094 1.0000
57.7600 12.1343 1.0000
57.8200 14.3357 1.0000
57.8800 16.8983 1.0000
57.9400 20.2469 1.0000
58.0000 11.8409 1.0000
58.0600 23.2185 1.0000
58.1200 19.0438 1.0000
58.1800 12.5913 1.0000
58.2400 18.6515 1.0000
58.3000 19.1191 1.0000
58.3600 14.4622 1.0000
58.4200 23.0293 1.0000
58.4800 22.1948 1.0000
58.5400 19.2065 1.0000
58.6000 18.2676 1.0000
58.6600 15.5701 1.0000
58.7200 20.1556 1.0000
58.7800 16.5688 1.0000
58.8400 14.5989 1.0000
58.9000 14.7131 1.0000
58.9600 12.4329 1.0000
59.0200 16.1720 1.0000
59.0800 20.4286 1.0000
59.1400 20.3042 1.0000
59.2000 18.1212 1.0000
59.2600 14.2714 1.0000
59.3200 18.0485 1.0000
59.3800 14.4893 1.0000
59.4400 16.9440 1.0000
59.5000 20.6637 1.0000
59.5600 13.4004 1.0000
59.6200 17.2978 1.0000
59.6800 13.7909 1.0000
59.7400 16.6193 1.0000
59.8000 16.3480 1.0000
59.8600 12.8831 1.0000
59.9200 23.6523 1.0000
59.9800 13.2995 1.0000
60.0400 20.3045 1.0000
60.1000 18.3307 1.0000
60.1600 11.9712 1.0000
60.2200 16.0040 1.0000
60.2800 21.0678 1.0000
60.3400 19.4685 1.0000
60.4000 22.5691 1.0000
60.4600 20.2597 1.0000
60.5200 18.7652 1.0000
60.5800 14.3399 1.0000
60.6400 17.8200 1.0000
60.7000 28.0100 1.0000
60.7600 16.1439 1.0000
60.8200 16.5964 1.0000
60.8800 12.4495 1.0000
60.9400 11.5061 1.0000
61.0000 24.5252 1.0000
61.0600 19.6289 1.0000
61.1200 18.8752 1.0000
61.1800 13.9374 1.0000
61.2400 22.9860 1.0000
61.3000 17.6006 1.0000
61.3600 18.7383 1.0000
61.4200 15.5493 1.0000
61.4800 14.1542 1.0000
61.5400 14.0055 1.0000
61.6000 15.5299 1.0000
61.6600 15.8239 1.0000
61.7200 22.1725 1.0000
61.7800 29.9515 1.0000
61.8400 19.3943 1.0000
61.9000 21.9082 1.0000
61.9600 17.0450 1.0000
62.0200 18.8711 1.0000
62.0800 16.8387 1.0000
62.1400 11.0751 1.0000
62.2000 18.7363 1.0000
62.2600 23.0936 1.0000
62.3200 21.8237 1.0000
62.3800 30.0574 1.0000
62.4400 19.6775 1.0000
62.5000 18.8788 1.0000
62.5600 18.4158 1.0000
62.6200 21.9433 1.0000
62.6800 13.0127 1.0000
62.7400 12.0516 1.0000
62.8000 20.8997 1.0000
62.8600 14.0050 1.0000
62.9200 11.0449 1.0000
62.9800 11.5451 1.0000
63.0400 20.3441 1.0000
63.1000 12.6573 1.0000
63.1600 11.3814 1.0000
63.2200 14.3800 1.0000
63.2800 13.3383 1.0000
63.3400 20.7283 1.0000
63.4000 20.5506 1.0000
63.4600 18.7779 1.0000
63.5200 12.3629 1.0000
63.5800 14.8400 1.0000
63.6400 21.7475 1.0000
63.7000 22.7812 1.0000
63.7600 16.5935 1.0000
63.8200 25.1581 1.0000
63.8800 25.7002 1.0000
63.9400 17.5673 1.0000
64.0000 13.5116 1.0000
64.0600 17.1728 1.0000
64.1200 23.5372 1.0000
64.1800 18.6309 1.0000
64.2400 19.0154 1.0000
64.3000 16.5527 1.0000
64.3600 17.4201 1.0000
64.4200 22.8811 1.0000
64.4800 17.5424 1.0000
64.5400 22.6107 1.0000
64.6000 28.1085 1.0000
64.6600 31.1805 1.0000
64.7200 57.5221 1.0000
64.7800 56.3906 1.0000
64.8400 45.1644 1.0000
64.9000 42.6050 1.0000
64.9600 28.7229 1.0000
65.0200 34.2925 1.0000
65.0800 21.5702 1.0000
65.1400 17.4055 1.0000
65.2000 19.3041 1.0000
65.2600 17.6109 1.0000
65.3200 24.3965 1.0000
65.3800 18.7451 1.0000
65.4400 22.7596 1.0000
65.5000 19.5536 1.0000
65.5600 25.4612 1.0000
65.6200 13.9506 1.0000
65.6800 15.6777 1.0000
65.7400 22.3062 1.0000
65.8000 23.8261 1.0000
65.8600 11.8345 1.0000
65.9200 17.7639 1.0000
65.9800 26.6822 1.0000
66.0400 18.7255 1.0000
66.1000 18.0496 1.0000
66.1600 28.9932 1.0000
66.2200 14.7686 1.0000
66.2800 18.6348 1.0000
66.3400 19.6789 1.0000
66.4000 19.6759 1.0000
66.4600 18.0126 1.0000
66.5200 20.9365 1.0000
66.5800 18.7158 1.0000
66.6400 18.3537 1.0000
66.7000 18.1467 1.0000
66.7600 15.8681 1.0000
66.8200 17.2371 1.0000
66.8800 22.3933 1.0000
66.9400 19.0484 1.0000
67.0000 19.1490 1.0000
67.0600 21.0368 1.0000
67.1200 22.7913 1.0000
67.1800 20.3718 1.0000
67.2400 13.7949 1.0000
67.3000 19.8144 1.0000
67.3600 16.6229 1.0000
67.4200 15.8131 1.0000
67.4800 14.4111 1.0000
67.5400 12.8005 1.0000
67.6000 17.1518 1.0000
67.6600 19.9374 1.0000
67.7200 23.3995 1.0000
67.7800 20.0726 1.0000
67.8400 12.5525 1.0000
67.9000 18.8428 1.0000
67.9600 18.5292 1.0000
68.0200 15.0784 1.0000
68.0800 16.0340 1.0000
68.1400 15.4282 1.0000
68.2000 14.1846 1.0000
68.2600 21.2771 1.0000
68.3200 12.7223 1.0000
68.3800 16.5652 1.0000
68.4400 17.5883 1.0000
68.5000 21.1317 1.0000
68.5600 17.3896 1.0000
68.6200 18.5089 1.0000
68.6800 21.2395 1.0000
68.7400 12.9483 1.0000
68.8000 16.6265 1.0000
68.8600 20.3737 1.0000
68.9200 19.5910 1.0000
68.9800 9.1994 1.0000
69.0400 23.2980 1.0000
69.1000 14.2723 1.0000
69.1600 16.0874 1.0000
69.2200 13.2828 1.0000
69.2800 16.1024 1.0000
69.3400 24.1438 1.0000
69.4000 28.4874 1.0000
69.4600 19.1932 1.0000
69.5200 15.9971 1.0000
69.5800 18.8158 1.0000
69.6400 18.0630 1.0000
69.7000 13.1083 1.0000
69.7600 6.5942 1.0000
69.8200 11.6946 1.0000
69.8800 14.3511 1.0000
69.9400 17.0726 1.0000
70.0000 28.1770 1.0000
70.0600 20.3167 1.0000
70.1200 20.9907 1.0000
70.1800 15.7801 1.0000
70.2400 22.8707 1.0000
70.3000 19.5486 1.0000
70.3600 18.3471 1.0000
70.4200 16.3048 1.0000
70.4800 15.8623 1.0000
70.5400 18.8655 1.0000
70.6000 17.7841 1.0000
70.6600 16.3178 1.0000
70.7200 16.7519 1.0000
70.7800 16.7796 1.0000
70.8400 22.6069 1.0000
70.9000 15.5423 1.0000
70.9600 18.2260 1.0000
71.0200 26.1739 1.0000
71.0800 11.4395 1.0000
71.1400 16.1042 1.0000
71.2000 21.3744 1.0000
71.2600 14.0801 1.0000
71.3200 10.3838 1.0000
71.3800 21.4218 1.0000
71.4400 10.3495 1.0000
71.5000 19.3065 1.0000
71.5600 17.2946 1.0000
71.6200 16.3160 1.0000
71.6800 19.2355 1.0000
71.7400 13.9604 1.0000
71.8000 29.1927 1.0000
71.8600 10.0108 1.0000
71.9200 20.4497 1.0000
71.9800 17.0537 1.0000
72.0400 15.8187 1.0000
72.1000 15.6132 1.0000
72.1600 24.4463 1.0000
72.2200 17.1219 1.0000
72.2800 5.1098 1.0000
72.3400 10.2286 1.0000
72.4000 16.9811 1.0000
72.4600 13.6585 1.0000
72.5200 20.4650 1.0000
72.5800 19.8373 1.0000
72.6400 18.3389 1.0000
72.7000 16.4804 1.0000
72.7600 15.2860 1.0000
72.8200 23.8320 1.0000
72.8800 17.1283 1.0000
72.9400 20.4787 1.0000
73.0000 13.2378 1.0000
73.0600 23.3405 1.0000
73.1200 13.7100 1.0000
73.1800 24.4566 1.0000
73.2400 15.5280 1.0000
73.3000 23.2416 1.0000
73.3600 14.0572 1.0000
73.4200 13.7913 1.0000
73.4800 16.6759 1.0000
73.5400 17.5713 1.0000
73.6000 14.5307 1.0000
73.6600 18.2649 1.0000
73.7200 15.4445 1.0000
73.7800 15.2956 1.0000
73.8400 16.2540 1.0000
73.9000 19.5647 1.0000
73.9600 16.0349 1.0000
74.0200 18.5121 1.0000
74.0800 15.5184 1.0000
74.1400 20.9004 1.0000
74.2000 12.5574 1.0000
74.2600 16.9062 1.0000
74.3200 20.4750 1.0000
74.3800 17.5498 1.0000
74.4400 10.8323 1.0000
74.5000 18.7742 1.0000
74.5600 16.2705 1.0000
74.6200 12.1620 1.0000
74.6800 20.9148 1.0000
74.7400 18.9106 1.0000
74.8000 13.6418 1.0000
74.8600 11.4763 1.0000
74.9200 12.6996 1.0000
74.9800 13.8507 1.0000
75.0400 21.5140 1.0000
75.1000 17.8116 1.0000
75.1600 12.3487 1.0000
75.2200 18.5744 1.0000
75.2800 12.2202 1.0000
75.3400 19.9533 1.0000
75.4000 13.8280 1.0000
75.4600 17.1801 1.0000
75.5200 15.0361 1.0000
75.5800 20.7318 1.0000
75.6400 13.9085 1.0000
75.7000 9.9683 1.0000
75.7600 16.2242 1.0000
75.8200 15.5713 1.0000
75.8800 17.8058 1.0000
75.9400 22.7217 1.0000
76.0000 18.2640 1.0000
76.0600 15.9470 1.0000
76.1200 18.4747 1.0000
76.1800 22.5833 1.0000
76.2400 18.1674 1.0000
76.3000 11.0099 1.0000
76.3600 15.9433 1.0000
76.4200 17.7279 1.0000
76.4800 14.7846 1.0000
76.5400 16.6479 1.0000
76.6000 19.6420 1.0000
76.6600 16.5268 1.0000
76.7200 22.1551 1.0000
76.7800 20.4760 1.0000
76.8400 26.4542 1.0000
76.9000 16.1889 1.0000
76.9600 11.5176 1.0000
77.0200 12.2815 1.0000
77.0800 17.2819 1.0000
77.1400 23.9088 1.0000
77.2000 17.8864 1.0000
77.2600 16.0452 1.0000
77.3200 22.6118 1.0000
77.3800 16.3318 1.0000
77.4400 21.3282 1.0000
77.5000 16.4879 1.0000
77.5600 22.5802 1.0000
77.6200 21.8913 1.0000
77.6800 20.2496 1.0000
77.7400 22.4367 1.0000
77.8000 14.9965 1.0000
77.8600 9.1647 1.0000
77.9200 23.9767 1.0000
77.9800 21.6433 1.0000
78.0400 15.5478 1.0000
78.1000 21.4078 1.0000
78.1600 18.8290 1.0000
78.2200 14.1881 1.0000
78.2800 16.7654 1.0000
78.3400 15.0894 1.0000
78.4000 13.7350 1.0000
78.4600 15.5736 1.0000
78.5200 19.1689 1.0000
78.5800 12.0524 1.0000
78.6400 26.6365 1.0000
78.7000 20.4211 1.0000
78.7600 20.3082 1.0000
78.8200 17.5792 1.0000
78.8800 19.5698 1.0000
78.9400 11.4157 1.0000
79.0000 19.8866 1.0000
79.0600 20.5109 1.0000
79.1200 12.9407 1.0000
79.1800 22.9897 1.0000
79.2400 15.8191 1.0000
79.3000 29.1008 1.0000
79.3600 12.1905 1.0000
79.4200 15.0492 1.0000
79.4800 20.7981 1.0000
79.5400 14.9901 1.0000
79.6000 19.7579 1.0000
79.6600 12.7585 1.0000
79.7200 18.6226 1.0000
79.7800 19.7765 1.0000
79.8400 17.7251 1.0000
79.9000 10.3131 1.0000
79.9600 16.1404 1.0000
80.0200 22.3690 1.0000
80.0800 20.2525 1.0000
80.1400 18.4074 1.0000
80.2000 23.2865 1.0000
80.2600 15.2176 1.0000
80.3200 18.6966 1.0000
80.3800 20.6493 1.0000
80.4400 11.0796 1.0000
80.5000 13.2519 1.0000
80.5600 15.8902 1.0000
80.6200 11.5639 1.0000
80.6800 18.7896 1.0000
80.7400 10.3484 1.0000
80.8000 20.2806 1.0000
80.8600 15.0474 1.0000
80.9200 22.9507 1.0000
80.9800 9.1984 1.0000
81.0400 15.6609 1.0000
81.1000 14.6619 1.0000
81.1600 18.5436 1.0000
81.2200 21.3674 1.0000
81.2800 23.2513 1.0000
81.3400 20.3859 1.0000
81.4000 21.4104 1.0000
81.4600 17.3905 1.0000
81.5200 20.1917 1.0000
81.5800 16.9434 1.0000
81.6400 18.5594 1.0000
81.7000 23.1744 1.0000
81.7600 25.9754 1.0000
81.8200 40.4636 1.0000
81.8800 45.7518 1.0000
81.9400 47.4168 1.0000
82.0000 64.0005 1.0000
82.0600 71.5505 1.0000
82.1200 89.9748 1.0000
82.1800 59.6593 1.0000
82.2400 47.1016 1.0000
82.3000 37.0623 1.0000
82.3600 29.8354 1.0000
82.4200 22.0926 1.0000
82.4800 26.6889 1.0000
82.5400 22.0694 1.0000
82.6000 17.4933 1.0000
82.6600 18.7794 1.0000
82.7200 21.8514 1.0000
82.7800 22.4519 1.0000
82.8400 16.0383 1.0000
82.9000 14.3921 1.0000
82.9600 15.6710 1.0000
83.0200 12.4886 1.0000
83.0800 17.5772 1.0000
83.1400 22.7360 1.0000
83.2000 23.5732 1.0000
83.2600 9.9360 1.0000
83.3200 18.0100 1.0000
83.3800 21.4565 1.0000
83.4400 23.0684 1.0000
83.5000 18.1677 1.0000
83.5600 11.3415 1.0000
83.6200 19.2301 1.0000
83.6800 19.4371 1.0000
83.7400 19.0228 1.0000
83.8000 17.1741 1.0000
83.8600 20.4878 1.0000
83.9200 21.4228 1.0000
83.9800 27.2893 1.0000
84.0400 17.7176 1.0000
84.1000 13.5250 1.0000
84.1600 18.0214 1.0000
84.2200 24.3854 1.0000
84.2800 14.7407 1.0000
84.3400 23.8357 1.0000
84.4000 18.0007 1.0000
84.4600 10.6166 1.0000
84.5200 8.8301 1.0000
84.5800 19.0922 1.0000
84.6400 17.4443 1.0000
84.7000 13.2777 1.0000
84.7600 18.5974 1.0000
84.8200 16.5533 1.0000
84.8800 19.6215 1.0000
84.9400 15.7765 1.0000
85.0000 16.1975 1.0000
85.0600 14.0196 1.0000
85.1200 9.8610 1.0000
85.1800 21.5029 1.0000
85.2400 14.2648 1.0000
85.3000 10.7333 1.0000
85.3600 14.9066 1.0000
85.4200 16.2531 1.0000
85.4800 13.2946 1.0000
85.5400 14.0237 1.0000
85.6000 16.7459 1.0000
85.6600 14.8248 1.0000
85.7200 17.9645 1.0000
85.7800 13.9164 1.0000
85.8400 18.7274 1.0000
85.9000 16.7825 1.0000
85.9600 19.9990 1.0000
86.0200 15.2687 1.0000
86.0800 17.5063 1.0000
86.1400 23.3601 1.0000
86.2000 13.7876 1.0000
86.2600 10.2898 1.0000
86.3200 16.4601 1.0000
86.3800 18.5040 1.0000
86.4400 18.4775 1.0000
86.5000 22.1143 1.0000
86.5600 17.7152 1.0000
86.6200 14.9993 1.0000
86.6800 15.0183 1.0000
86.7400 16.5461 1.0000
86.8000 27.5735 1.0000
86.8600 12.3938 1.0000
86.9200 20.5142 1.0000
86.9800 14.6368 1.0000
87.0400 15.5363 1.0000
87.1000 16.9442 1.0000
87.1600 15.3285 1.0000
87.2200 20.5007 1.0000
87.2800 10.4315 1.0000
87.3400 24.2144 1.0000
87.4000 23.9519 1.0000
87.4600 19.6946 1.0000
87.5200 15.9131 1.0000
87.5800 10.0978 1.0000
87.6400 19.3379 1.0000
87.7000 16.2545 1.0000
87.7600 16.6205 1.0000
87.8200 17.1733 1.0000
87.8800 20.2713 1.0000
87.9400 13.9366 1.0000
88.0000 19.3668 1.0000
88.0600 24.6769 1.0000
88.1200 14.2133 1.0000
88.1800 16.5135 1.0000
88.2400 19.2593 1.0000
88.3000 19.0637 1.0000
88.3600 19.7841 1.0000
88.4200 16.1835 1.0000
88.4800 16.0651 1.0000
88.5400 16.4304 1.0000
88.6000 12.2691 1.0000
88.6600 12.5039 1.0000
88.7200 16.9696 1.0000
88.7800 19.4435 1.0000
88.8400 17.8320 1.0000
88.9000 22.9840 1.0000
88.9600 14.3725 1.0000
89.0200 17.3594 1.0000
89.0800 23.1633 1.0000
89.1400 10.1311 1.0000
89.2000 18.1025 1.0000
89.2600 18.7870 1.0000
89.3200 13.5540 1.0000
89.3800 12.7065 1.0000
89.4400 19.4517 1.0000
89.5000 16.8068 1.0000
89.5600 19.0911 1.0000
89.6200 17.1719 1.0000
89.6800 11.6156 1.0000
89.7400 15.0971 1.0000
89.8000 12.0871 1.0000
89.8600 14.6024 1.0000
89.9200 21.4071 1.0000
89.9800 17.0279 1.0000
90.0400 27.4308 1.0000
90.1000 18.8335 1.0000
90.1600 20.1611 1.0000
90.2200 17.6528 1.0000
90.2800 16.7650 1.0000
90.3400 18.1891 1.0000
90.4000 26.1495 1.0000
90.4600 15.6809 1.0000
90.5200 16.4596 1.0000
90.5800 13.1309 1.0000
90.6400 16.4081 1.0000
90.7000 22.1433 1.0000
90.7600 15.0838 1.0000
90.8200 16.2937 1.0000
90.8800 20.6272 1.0000
90.9400 12.9488 1.0000
91.0000 12.8512 1.0000
91.0600 16.3893 1.0000
91.1200 16.5790 1.0000
91.1800 25.7675 1.0000
91.2400 21.6401 1.0000
91.3000 17.9292 1.0000
91.3600 19.9286 1.0000
91.4200 13.2154 1.0000
91.4800 19.0455 1.0000
91.5400 18.5983 1.0000
91.6000 18.8705 1.0000
91.6600 18.6554 1.0000
91.7200 22.1005 1.0000
91.7800 13.4526 1.0000
91.8400 24.7662 1.0000
91.9000 14.2273 1.0000
91.9600 17.6700 1.0000
92.0200 19.1663 1.0000
92.0800 14.2397 1.0000
92.1400 22.5370 1.0000
92.2000 20.6108 1.0000
92.2600 11.8941 1.0000
92.3200 17.1347 1.0000
92.3800 15.7617 1.0000
92.4400 18.7008 1.0000
92.5000 18.5092 1.0000
92.5600 23.8054 1.0000
92.6200 19.3807 1.0000
92.6800 21.2154 1.0000
92.7400 17.8167 1.0000
92.8000 23.8319 1.0000
92.8600 16.8933 1.0000
92.9200 17.7662 1.0000
92.9800 18.2617 1.0000
93.0400 12.4703 1.0000
93.1000 16.5599 1.0000
93.1600 23.0455 1.0000
93.2200 17.5308 1.0000
93.2800 12.2420 1.0000
93.3400 16.9436 1.0000
93.4000 19.6806 1.0000
93.4600 20.8740 1.0000
93.5200 13.4937 1.0000
93.5800 11.3489 1.0000
93.6400 15.7313 1.0000
93.7000 18.0433 1.0000
93.7600 18.7591 1.0000
93.8200 20.5796 1.0000
93.8800 17.8198 1.0000
93.9400 15.5599 1.0000
94.0000 12.2017 1.0000
94.0600 20.8320 1.0000
94.1200 20.3723 1.0000
94.1800 15.6363 1.0000
94.2400 15.8727 1.0000
94.3000 16.3100 1.0000
94.3600 12.9379 1.0000
94.4200 11.1998 1.0000
94.4800 18.5608 1.0000
94.5400 16.1836 1.0000
94.6000 16.3313 1.0000
94.6600 16.9725 1.0000
94.7200 14.5522 1.0000
94.7800 20.2242 1.0000
94.8400 15.8292 1.0000
94.9000 15.5889 1.0000
94.9600 17.1412 1.0000
95.0200 22.8500 1.0000
95.0800 16.9566 1.0000
95.1400 12.2293 1.0000
95.2000 15.9486 1.0000
95.2600 24.1316 1.0000
95.3200 16.2571 1.0000
95.3800 11.9353 1.0000
95.4400 17.6333 1.0000
95.5000 23.9869 1.0000
95.5600 15.4721 1.0000
95.6200 15.7581 1.0000
95.6800 17.1138 1.0000
95.7400 17.0270 1.0000
95.8000 20.4960 1.0000
95.8600 14.9486 1.0000
95.9200 14.7481 1.0000
95.9800 20.1675 1.0000
96.0400 11.0025 1.0000
96.1000 21.4321 1.0000
96.1600 16.5430 1.0000
96.2200 22.4678 1.0000
96.2800 17.6232 1.0000
96.3400 13.2845 1.0000
96.4000 12.3086 1.0000
96.4600 18.1812 1.0000
96.5200 18.1716 1.0000
96.5800 18.4543 1.0000
96.6400 17.8925 1.0000
96.7000 20.1355 1.0000
96.7600 11.7025 1.0000
96.8200 13.8392 1.0000
96.8800 16.7739 1.0000
96.9400 11.6264 1.0000
97.0000 14.0915 1.0000
97.0600 14.7689 1.0000
97.1200 19.6742 1.0000
97.1800 13.1171 1.0000
97.2400 17.8055 1.0000
97.3000 17.8326 1.0000
97.3600 16.2822 1.0000
97.4200 22.3391 1.0000
97.4800 20.3877 1.0000
97.5400 17.7595 1.0000
97.6000 10.1921 1.0000
97.6600 21.8039 1.0000
97.7200 23.2010 1.0000
97.7800 14.3533 1.0000
97.8400 17.6809 1.0000
97.9000 15.1499 1.0000
97.9600 23.6593 1.0000
98.0200 25.5645 1.0000
98.0800 27.3318 1.0000
98.1400 20.7109 1.0000
98.2000 22.7736 1.0000
98.2600 19.6204 1.0000
98.3200 33.1202 1.0000
98.3800 27.9792 1.0000
98.4400 43.3272 1.0000
98.5000 48.7699 1.0000
98.5600 60.7047 1.0000
98.6200 59.1877 1.0000
98.6800 72.4490 1.0000
98.7400 60.8946 1.0000
98.8000 43.1750 1.0000
98.8600 49.6542 1.0000
98.9200 27.3212 1.0000
98.9800 31.3606 1.0000
99.0400 17.3654 1.0000
99.1000 16.9027 1.0000
99.1600 15.0556 1.0000
99.2200 15.4023 1.0000
99.2800 16.6970 1.0000
99.3400 13.8610 1.0000
99.4000 15.0949 1.0000
99.4600 12.8489 1.0000
99.5200 15.7609 1.0000
99.5800 12.1206 1.0000
99.6400 21.2518 1.0000
99.7000 16.8239 1.0000
99.7600 21.1925 1.0000
99.8200 16.2883 1.0000
99.8800 17.6722 1.0000
99.9400 16.7053 1.0000
100.0000 27.3085 1.0000
100.0600 21.6715 1.0000
100.1200 20.0149 1.0000
100.1800 21.1333 1.0000
100.2400 25.7914 1.0000
100.3000 18.8439 1.0000
100.3600 17.6773 1.0000
100.4200 14.3715 1.0000
100.4800 33.5255 1.0000
100.5400 11.6700 1.0000
100.6000 15.4376 1.0000
100.6600 15.1317 1.0000
100.7200 15.4323 1.0000
100.7800 15.6981 1.0000
100.8400 13.7642 1.0000
100.9000 18.3266 1.0000
100.9600 16.2181 1.0000
101.0200 18.0842 1.0000
101.0800 15.2167 1.0000
101.1400 20.7310 1.0000
101.2000 15.1533 1.0000
101.2600 15.9570 1.0000
101.3200 23.8770 1.0000
101.3800 21.6961 1.0000
101.4400 15.7861 1.0000
101.5000 19.9883 1.0000
101.5600 13.2624 1.0000
101.6200 22.5986 1.0000
101.6800 16.4391 1.0000
101.7400 17.4320 1.0000
101.8000 12.3488 1.0000
101.8600 21.0648 1.0000
101.9200 13.8707 1.0000
101.9800 15.2987 1.0000
102.0400 25.3831 1.0000
102.1000 16.6021 1.0000
102.1600 15.1081 1.0000
102.2200 11.5693 1.0000
102.2800 23.2077 1.0000
102.3400 11.7031 1.0000
102.4000 20.8596 1.0000
102.4600 13.9499 1.0000
102.5200 17.3370 1.0000
102.5800 16.4552 1.0000
102.6400 16.4721 1.0000
102.7000 17.0349 1.0000
102.7600 24.0870 1.0000
102.8200 16.4880 1.0000
102.8800 10.8837 1.0000
102.9400 16.1020 1.0000
103.0000 7.2733 1.0000
103.0600 13.5825 1.0000
103.1200 11.1989 1.0000
103.1800 22.3119 1.0000
103.2400 23.7579 1.0000
103.3000 17.9437 1.0000
103.3600 20.6817 1.0000
103.4200 22.1669 1.0000
103.4800 16.2761 1.0000
103.5400 17.2938 1.0000
103.6000 22.1159 1.0000
103.6600 15.8111 1.0000
103.7200 19.7114 1.0000
103.7800 18.7086 1.0000
103.8400 23.4401 1.0000
103.9000 26.6327 1.0000
103.9600 23.1433 1.0000
104.0200 21.5130 1.0000
104.0800 16.7455 1.0000
104.1400 20.5031 1.0000
104.2000 14.4079 1.0000
104.2600 13.5838 1.0000
104.3200 18.3998 1.0000
104.3800 15.1529 1.0000
104.4400 13.8136 1.0000
104.5000 20.3381 1.0000
104.5600 18.4115 1.0000
104.6200 17.6456 1.0000
104.6800 13.5712 1.0000
104.7400 26.2069 1.0000
104.8000 9.9190 1.0000
104.8600 13.3943 1.0000
104.9200 15.4389 1.0000
104.9800 15.8177 1.0000
105.0400 21.1053 1.0000
105.1000 9.3443 1.0000
105.1600 20.7918 1.0000
105.2200 17.0151 1.0000
105.2800 14.0201 1.0000
105.3400 21.1859 1.0000
105.4000 17.3171 1.0000
105.4600 18.7629 1.0000
105.5200 27.5320 1.0000
105.5800 19.0611 1.0000
105.6400 21.4647 1.0000
105.7000 20.3699 1.0000
105.7600 11.5048 1.0000
105.8200 12.6581 1.0000
[...]
68.9800 29.3885 1.0000
69.0400 19.2420 1.0000
69.1000 18.7269 1.0000
69.1600 18.0719 1.0000
69.2200 10.5525 1.0000
69.2800 11.7500 1.0000
69.3400 24.8235 1.0000
69.4000 18.5809 1.0000
69.4600 10.6813 1.0000
69.5200 23.3492 1.0000
69.5800 12.7659 1.0000
69.6400 15.5691 1.0000
69.7000 16.9756 1.0000
69.7600 14.8259 1.0000
69.8200 18.8780 1.0000
69.8800 23.9030 1.0000
69.9400 16.8849 1.0000
70.0000 19.1958 1.0000
70.0600 21.3660 1.0000
70.1200 17.3677 1.0000
70.1800 17.1562 1.0000
70.2400 15.5061 1.0000
70.3000 10.8573 1.0000
70.3600 14.2861 1.0000
70.4200 14.4068 1.0000
70.4800 17.2122 1.0000
70.5400 13.4800 1.0000
70.6000 16.4431 1.0000
70.6600 18.4979 1.0000
70.7200 15.1397 1.0000
70.7800 14.6636 1.0000
70.8400 19.8498 1.0000
70.9000 16.5503 1.0000
70.9600 15.9713 1.0000
71.0200 18.9835 1.0000
71.0800 15.5368 1.0000
71.1400 19.3732 1.0000
71.2000 26.5949 1.0000
71.2600 12.5640 1.0000
71.3200 14.2627 1.0000
71.3800 23.0706 1.0000
71.4400 18.3796 1.0000
71.5000 10.3991 1.0000
71.5600 8.6054 1.0000
71.6200 14.1365 1.0000
71.6800 13.5498 1.0000
71.7400 13.2720 1.0000
71.8000 16.0535 1.0000
71.8600 13.8606 1.0000
71.9200 27.1019 1.0000
71.9800 21.4584 1.0000
72.0400 14.9353 1.0000
72.1000 16.4907 1.0000
72.1600 14.6764 1.0000
72.2200 12.4104 1.0000
72.2800 16.5803 1.0000
72.3400 20.7562 1.0000
72.4000 18.9935 1.0000
72.4600 10.3714 1.0000
72.5200 11.6435 1.0000
72.5800 19.8343 1.0000
72.6400 19.4750 1.0000
72.7000 14.4410 1.0000
72.7600 25.1857 1.0000
72.8200 17.9140 1.0000
72.8800 12.8571 1.0000
72.9400 14.0766 1.0000
73.0000 21.0118 1.0000
73.0600 12.2243 1.0000
73.1200 20.0872 1.0000
73.1800 16.5535 1.0000
73.2400 14.5588 1.0000
73.3000 21.6464 1.0000
73.3600 19.0192 1.0000
73.4200 11.9847 1.0000
73.4800 21.5200 1.0000
73.5400 17.1547 1.0000
73.6000 14.3114 1.0000
73.6600 19.4051 1.0000
73.7200 23.1316 1.0000
73.7800 21.6502 1.0000
73.8400 22.6381 1.0000
73.9000 8.4576 1.0000
73.9600 12.3010 1.0000
74.0200 12.0808 1.0000
74.0800 20.4910 1.0000
74.1400 19.5838 1.0000
74.2000 22.0855 1.0000
74.2600 12.9443 1.0000
74.3200 8.7760 1.0000
74.3800 19.4874 1.0000
74.4400 13.7524 1.0000
74.5000 18.4086 1.0000
74.5600 17.7657 1.0000
74.6200 14.4517 1.0000
74.6800 24.8575 1.0000
74.7400 21.4056 1.0000
74.8000 15.9507 1.0000
74.8600 19.1269 1.0000
74.9200 21.9474 1.0000
74.9800 22.4751 1.0000
75.0400 17.8207 1.0000
75.1000 14.1011 1.0000
75.1600 19.1999 1.0000
75.2200 23.0983 1.0000
75.2800 19.2176 1.0000
75.3400 22.3410 1.0000
75.4000 19.2210 1.0000
75.4600 17.4599 1.0000
75.5200 17.4477 1.0000
75.5800 17.8715 1.0000
75.6400 23.1067 1.0000
75.7000 16.1539 1.0000
75.7600 13.6406 1.0000
75.8200 12.2506 1.0000
75.8800 14.9408 1.0000
75.9400 15.9204 1.0000
76.0000 12.5406 1.0000
76.0600 14.2712 1.0000
76.1200 19.1945 1.0000
76.1800 13.9339 1.0000
76.2400 16.7652 1.0000
76.3000 14.5290 1.0000
76.3600 17.5166 1.0000
76.4200 20.7562 1.0000
76.4800 17.8608 1.0000
76.5400 20.4112 1.0000
76.6000 10.3446 1.0000
76.6600 14.3100 1.0000
76.7200 10.9698 1.0000
76.7800 16.8050 1.0000
76.8400 17.0250 1.0000
76.9000 14.8839 1.0000
76.9600 22.5793 1.0000
77.0200 17.4399 1.0000
77.0800 14.6434 1.0000
77.1400 18.6028 1.0000
77.2000 14.4957 1.0000
77.2600 13.2844 1.0000
77.3200 13.0815 1.0000
77.3800 14.7338 1.0000
77.4400 15.7580 1.0000
77.5000 11.8592 1.0000
77.5600 22.6581 1.0000
77.6200 21.6362 1.0000
77.6800 16.6822 1.0000
77.7400 20.0050 1.0000
77.8000 15.3336 1.0000
77.8600 13.3810 1.0000
77.9200 13.2967 1.0000
77.9800 18.9223 1.0000
78.0400 15.8450 1.0000
78.1000 19.1645 1.0000
78.1600 17.6693 1.0000
78.2200 25.2897 1.0000
78.2800 13.7655 1.0000
78.3400 14.0353 1.0000
78.4000 19.8860 1.0000
78.4600 17.2128 1.0000
78.5200 16.7336 1.0000
78.5800 23.3651 1.0000
78.6400 14.5454 1.0000
78.7000 10.9537 1.0000
78.7600 18.6297 1.0000
78.8200 19.1059 1.0000
78.8800 20.9672 1.0000
78.9400 21.6504 1.0000
79.0000 15.5498 1.0000
79.0600 14.0563 1.0000
79.1200 20.5760 1.0000
79.1800 15.3642 1.0000
79.2400 26.0095 1.0000
79.3000 12.8917 1.0000
79.3600 5.5874 1.0000
79.4200 16.8603 1.0000
79.4800 12.2857 1.0000
79.5400 17.3446 1.0000
79.6000 13.7271 1.0000
79.6600 21.9700 1.0000
79.7200 12.5773 1.0000
79.7800 14.4832 1.0000
79.8400 15.5352 1.0000
79.9000 13.0604 1.0000
79.9600 25.7282 1.0000
80.0200 18.3736 1.0000
80.0800 11.5182 1.0000
80.1400 16.5137 1.0000
80.2000 18.0924 1.0000
80.2600 20.6651 1.0000
80.3200 17.0455 1.0000
80.3800 14.9079 1.0000
80.4400 16.6976 1.0000
80.5000 13.8371 1.0000
80.5600 24.9931 1.0000
80.6200 12.0713 1.0000
80.6800 14.6838 1.0000
80.7400 19.7922 1.0000
80.8000 21.2592 1.0000
80.8600 15.9101 1.0000
80.9200 8.3564 1.0000
80.9800 16.3017 1.0000
81.0400 17.8177 1.0000
81.1000 18.1227 1.0000
81.1600 13.0254 1.0000
81.2200 18.0219 1.0000
81.2800 22.9757 1.0000
81.3400 13.0776 1.0000
81.4000 18.1267 1.0000
81.4600 17.7196 1.0000
81.5200 23.7427 1.0000
81.5800 22.6924 1.0000
81.6400 17.4158 1.0000
81.7000 28.6551 1.0000
81.7600 20.2515 1.0000
81.8200 22.4227 1.0000
81.8800 36.0044 1.0000
81.9400 50.9354 1.0000
82.0000 61.1222 1.0000
82.0600 82.9596 1.0000
82.1200 91.1528 1.0000
82.1800 61.5549 1.0000
82.2400 39.1577 1.0000
82.3000 27.8257 1.0000
82.3600 33.5029 1.0000
82.4200 24.8480 1.0000
82.4800 21.0975 1.0000
82.5400 8.6358 1.0000
82.6000 19.7773 1.0000
82.6600 14.6072 1.0000
82.7200 18.1523 1.0000
82.7800 12.3802 1.0000
82.8400 18.0777 1.0000
82.9000 14.3198 1.0000
82.9600 16.0592 1.0000
83.0200 14.3008 1.0000
83.0800 17.1426 1.0000
83.1400 15.9848 1.0000
83.2000 25.1124 1.0000
83.2600 13.7512 1.0000
83.3200 21.1869 1.0000
83.3800 21.5950 1.0000
83.4400 22.5070 1.0000
83.5000 24.1319 1.0000
83.5600 17.4407 1.0000
83.6200 23.8259 1.0000
83.6800 20.7071 1.0000
83.7400 12.6778 1.0000
83.8000 21.5002 1.0000
83.8600 11.6928 1.0000
83.9200 19.9912 1.0000
83.9800 15.3822 1.0000
84.0400 14.9807 1.0000
84.1000 18.5510 1.0000
84.1600 16.4620 1.0000
84.2200 14.8535 1.0000
84.2800 18.1589 1.0000
84.3400 17.5261 1.0000
84.4000 17.1135 1.0000
84.4600 16.2491 1.0000
84.5200 16.9001 1.0000
84.5800 17.9204 1.0000
84.6400 14.8848 1.0000
84.7000 13.7785 1.0000
84.7600 22.4934 1.0000
84.8200 16.1579 1.0000
84.8800 18.3286 1.0000
84.9400 20.6062 1.0000
85.0000 17.1353 1.0000
85.0600 10.9038 1.0000
85.1200 12.2562 1.0000
85.1800 15.1748 1.0000
85.2400 14.7628 1.0000
85.3000 23.9731 1.0000
85.3600 20.0499 1.0000
85.4200 24.9650 1.0000
85.4800 15.5910 1.0000
85.5400 19.4209 1.0000
85.6000 22.8805 1.0000
85.6600 11.9661 1.0000
85.7200 16.6653 1.0000
85.7800 13.6618 1.0000
85.8400 17.6387 1.0000
85.9000 19.0445 1.0000
85.9600 13.6447 1.0000
86.0200 10.3937 1.0000
86.0800 27.9100 1.0000
86.1400 13.7195 1.0000
86.2000 10.0723 1.0000
86.2600 12.5015 1.0000
86.3200 16.0212 1.0000
86.3800 19.6780 1.0000
86.4400 13.2385 1.0000
86.5000 19.8140 1.0000
86.5600 24.0644 1.0000
86.6200 17.9270 1.0000
86.6800 16.3845 1.0000
86.7400 11.4222 1.0000
86.8000 19.4266 1.0000
86.8600 18.4186 1.0000
86.9200 24.0338 1.0000
86.9800 9.8413 1.0000
87.0400 21.3856 1.0000
87.1000 11.8371 1.0000
87.1600 22.7156 1.0000
87.2200 15.4097 1.0000
87.2800 17.4146 1.0000
87.3400 20.6668 1.0000
87.4000 15.9627 1.0000
87.4600 14.3122 1.0000
87.5200 12.9287 1.0000
87.5800 16.0157 1.0000
87.6400 12.0133 1.0000
87.7000 19.6796 1.0000
87.7600 14.3558 1.0000
87.8200 18.4086 1.0000
87.8800 19.5627 1.0000
87.9400 14.5018 1.0000
88.0000 21.9367 1.0000
88.0600 17.4007 1.0000
88.1200 15.9907 1.0000
88.1800 17.0786 1.0000
88.2400 15.2727 1.0000
88.3000 16.0997 1.0000
88.3600 15.4325 1.0000
88.4200 19.9720 1.0000
88.4800 17.0498 1.0000
88.5400 9.2324 1.0000
88.6000 15.1178 1.0000
88.6600 23.2764 1.0000
88.7200 17.9072 1.0000
88.7800 16.7670 1.0000
88.8400 15.0053 1.0000
88.9000 27.1665 1.0000
88.9600 16.5907 1.0000
89.0200 12.7179 1.0000
89.0800 17.5377 1.0000
89.1400 16.5267 1.0000
89.2000 20.0463 1.0000
89.2600 14.2293 1.0000
89.3200 19.7188 1.0000
89.3800 22.0849 1.0000
89.4400 14.7140 1.0000
89.5000 19.4606 1.0000
89.5600 9.5656 1.0000
89.6200 13.8168 1.0000
89.6800 16.0391 1.0000
89.7400 23.5064 1.0000
89.8000 12.1426 1.0000
89.8600 14.7079 1.0000
89.9200 18.1500 1.0000
89.9800 15.5709 1.0000
90.0400 10.6130 1.0000
90.1000 11.3535 1.0000
90.1600 12.6844 1.0000
90.2200 18.8139 1.0000
90.2800 18.2446 1.0000
90.3400 17.9117 1.0000
90.4000 11.5640 1.0000
90.4600 11.2353 1.0000
90.5200 13.1568 1.0000
90.5800 13.3562 1.0000
90.6400 21.0437 1.0000
90.7000 20.0984 1.0000
90.7600 15.8046 1.0000
90.8200 16.5027 1.0000
90.8800 21.8338 1.0000
90.9400 15.1812 1.0000
91.0000 15.2409 1.0000
91.0600 15.9548 1.0000
91.1200 17.1228 1.0000
91.1800 14.5843 1.0000
91.2400 9.2151 1.0000
91.3000 18.8379 1.0000
91.3600 17.2590 1.0000
91.4200 12.7332 1.0000
91.4800 15.3629 1.0000
91.5400 18.7817 1.0000
91.6000 18.4270 1.0000
91.6600 18.2449 1.0000
91.7200 18.0278 1.0000
91.7800 20.4642 1.0000
91.8400 15.7248 1.0000
91.9000 14.4964 1.0000
91.9600 16.4003 1.0000
92.0200 16.3731 1.0000
92.0800 12.4342 1.0000
92.1400 28.5189 1.0000
92.2000 11.9155 1.0000
92.2600 20.8076 1.0000
92.3200 17.4480 1.0000
92.3800 16.3410 1.0000
92.4400 15.7445 1.0000
92.5000 10.6387 1.0000
92.5600 13.6377 1.0000
92.6200 19.9857 1.0000
92.6800 12.4297 1.0000
92.7400 19.3636 1.0000
92.8000 16.3898 1.0000
92.8600 15.0988 1.0000
92.9200 20.3359 1.0000
92.9800 19.9774 1.0000
93.0400 18.9850 1.0000
93.1000 16.2510 1.0000
93.1600 17.4358 1.0000
93.2200 17.4070 1.0000
93.2800 15.6331 1.0000
93.3400 13.8089 1.0000
93.4000 17.7784 1.0000
93.4600 17.3710 1.0000
93.5200 17.0277 1.0000
93.5800 18.2645 1.0000
93.6400 12.1116 1.0000
93.7000 16.4562 1.0000
93.7600 16.7537 1.0000
93.8200 11.2771 1.0000
93.8800 16.8209 1.0000
93.9400 21.0510 1.0000
94.0000 12.9952 1.0000
94.0600 17.6919 1.0000
94.1200 13.4676 1.0000
94.1800 16.7987 1.0000
94.2400 17.9421 1.0000
94.3000 18.0820 1.0000
94.3600 8.9436 1.0000
94.4200 18.6050 1.0000
94.4800 20.5988 1.0000
94.5400 26.3779 1.0000
94.6000 11.9782 1.0000
94.6600 13.2921 1.0000
94.7200 18.8476 1.0000
94.7800 17.5646 1.0000
94.8400 21.5834 1.0000
94.9000 15.0929 1.0000
94.9600 21.0133 1.0000
95.0200 25.2796 1.0000
95.0800 15.9872 1.0000
95.1400 15.2468 1.0000
95.2000 18.1780 1.0000
95.2600 15.0170 1.0000
95.3200 18.2357 1.0000
95.3800 25.3429 1.0000
95.4400 21.7471 1.0000
95.5000 19.8489 1.0000
95.5600 11.7133 1.0000
95.6200 17.2352 1.0000
95.6800 14.2181 1.0000
95.7400 13.4369 1.0000
95.8000 18.8138 1.0000
95.8600 21.7797 1.0000
95.9200 18.1827 1.0000
95.9800 23.2066 1.0000
96.0400 21.2478 1.0000
96.1000 20.1413 1.0000
96.1600 16.8403 1.0000
96.2200 15.4642 1.0000
96.2800 15.5908 1.0000
96.3400 21.3383 1.0000
96.4000 21.1858 1.0000
96.4600 17.2826 1.0000
96.5200 18.0782 1.0000
96.5800 13.4317 1.0000
96.6400 18.9758 1.0000
96.7000 24.6383 1.0000
96.7600 20.8352 1.0000
96.8200 17.1214 1.0000
96.8800 15.7630 1.0000
96.9400 17.9432 1.0000
97.0000 18.3127 1.0000
97.0600 18.3687 1.0000
97.1200 19.1207 1.0000
97.1800 12.3753 1.0000
97.2400 20.9327 1.0000
97.3000 17.0404 1.0000
97.3600 23.1609 1.0000
97.4200 13.6068 1.0000
97.4800 7.5678 1.0000
97.5400 16.9496 1.0000
97.6000 18.6855 1.0000
97.6600 18.8908 1.0000
97.7200 13.5337 1.0000
97.7800 19.3807 1.0000
97.8400 25.2090 1.0000
97.9000 11.3116 1.0000
97.9600 27.6944 1.0000
98.0200 24.2733 1.0000
98.0800 21.6843 1.0000
98.1400 23.2469 1.0000
98.2000 18.1800 1.0000
98.2600 24.4253 1.0000
98.3200 30.4368 1.0000
98.3800 31.5845 1.0000
98.4400 30.6691 1.0000
98.5000 40.5288 1.0000
98.5600 63.6370 1.0000
98.6200 61.3582 1.0000
98.6800 50.3780 1.0000
98.7400 49.3644 1.0000
98.8000 49.6951 1.0000
98.8600 42.9039 1.0000
98.9200 25.8404 1.0000
98.9800 12.8674 1.0000
99.0400 22.7775 1.0000
99.1000 21.3049 1.0000
99.1600 22.2451 1.0000
99.2200 16.4663 1.0000
99.2800 13.2968 1.0000
99.3400 12.7862 1.0000
99.4000 16.6996 1.0000
99.4600 26.8356 1.0000
99.5200 18.8748 1.0000
99.5800 16.7274 1.0000
99.6400 14.1845 1.0000
99.7000 14.2926 1.0000
99.7600 17.0908 1.0000
99.8200 19.0219 1.0000
99.8800 13.3565 1.0000
99.9400 13.7347 1.0000
100.0000 21.6135 1.0000
100.0600 19.1597 1.0000
100.1200 13.6542 1.0000
100.1800 14.7266 1.0000
100.2400 11.2062 1.0000
100.3000 14.3878 1.0000
100.3600 16.6369 1.0000
100.4200 21.4999 1.0000
100.4800 23.8186 1.0000
100.5400 13.7680 1.0000
100.6000 15.6799 1.0000
100.6600 15.4679 1.0000
100.7200 17.8632 1.0000
100.7800 13.1745 1.0000
100.8400 19.5933 1.0000
100.9000 17.8532 1.0000
100.9600 13.0140 1.0000
101.0200 16.6396 1.0000
101.0800 23.1654 1.0000
101.1400 16.3027 1.0000
101.2000 22.9275 1.0000
101.2600 14.1391 1.0000
101.3200 10.7021 1.0000
101.3800 16.4896 1.0000
101.4400 17.9716 1.0000
101.5000 16.9874 1.0000
101.5600 8.7569 1.0000
101.6200 19.2719 1.0000
101.6800 12.8687 1.0000
101.7400 15.6716 1.0000
101.8000 18.3409 1.0000
101.8600 14.7267 1.0000
101.9200 14.4032 1.0000
101.9800 16.4678 1.0000
102.0400 28.2671 1.0000
102.1000 17.0208 1.0000
102.1600 14.5071 1.0000
102.2200 17.3745 1.0000
102.2800 16.0814 1.0000
102.3400 8.8708 1.0000
102.4000 13.3149 1.0000
102.4600 16.1922 1.0000
102.5200 19.7343 1.0000
102.5800 14.3969 1.0000
102.6400 15.4057 1.0000
102.7000 19.4859 1.0000
102.7600 11.3665 1.0000
102.8200 23.9606 1.0000
102.8800 16.7657 1.0000
102.9400 22.5003 1.0000
103.0000 19.9050 1.0000
103.0600 18.6580 1.0000
103.1200 14.4862 1.0000
103.1800 20.1064 1.0000
103.2400 19.7035 1.0000
103.3000 17.5261 1.0000
103.3600 17.7808 1.0000
103.4200 18.6357 1.0000
103.4800 17.3729 1.0000
103.5400 31.6658 1.0000
103.6000 17.2993 1.0000
103.6600 13.0526 1.0000
103.7200 17.5778 1.0000
103.7800 15.2399 1.0000
103.8400 17.0541 1.0000
103.9000 14.7313 1.0000
103.9600 19.1089 1.0000
104.0200 19.4935 1.0000
104.0800 11.0094 1.0000
104.1400 20.3480 1.0000
104.2000 19.4600 1.0000
104.2600 15.5615 1.0000
104.3200 15.2105 1.0000
104.3800 14.9982 1.0000
104.4400 18.2981 1.0000
104.5000 8.4182 1.0000
104.5600 18.2331 1.0000
104.6200 17.9579 1.0000
104.6800 19.5921 1.0000
104.7400 21.6572 1.0000
104.8000 23.1403 1.0000
104.8600 13.1581 1.0000
104.9200 14.7205 1.0000
104.9800 21.0938 1.0000
105.0400 14.7747 1.0000
105.1000 20.6861 1.0000
105.1600 15.5870 1.0000
105.2200 12.9412 1.0000
105.2800 10.9497 1.0000
105.3400 23.0352 1.0000
105.4000 19.9359 1.0000
105.4600 13.9397 1.0000
105.5200 18.0126 1.0000
105.5800 16.4887 1.0000
105.6400 11.4250 1.0000
105.7000 17.0036 1.0000
105.7600 22.2022 1.0000
105.8200 12.1060 1.0000
105.8800 9.6466 1.0000
105.9400 15.1509 1.0000
106.0000 12.5031 1.0000
106.0600 20.8911 1.0000
106.1200 17.2395 1.0000
106.1800 13.7543 1.0000
106.2400 10.6819 1.0000
106.3000 13.3777 1.0000
106.3600 20.4821 1.0000
106.4200 17.1137 1.0000
106.4800 19.7792 1.0000
106.5400 15.3135 1.0000
106.6000 35.0551 1.0000
106.6600 16.8311 1.0000
106.7200 20.1397 1.0000
106.7800 17.6136 1.0000
106.8400 23.4050 1.0000
106.9000 18.5999 1.0000
106.9600 19.6764 1.0000
107.0200 14.2663 1.0000
107.0800 11.1728 1.0000
107.1400 15.4373 1.0000
107.2000 21.0427 1.0000
107.2600 20.3324 1.0000
107.3200 14.8264 1.0000
107.3800 17.1695 1.0000
107.4400 19.7910 1.0000
107.5000 10.9016 1.0000
107.5600 11.0315 1.0000
107.6200 10.2303 1.0000
107.6800 17.0298 1.0000
107.7400 10.2473 1.0000
107.8000 22.3150 1.0000
107.8600 14.0576 1.0000
107.9200 10.7181 1.0000
107.9800 20.6560 1.0000
108.0400 12.9310 1.0000
108.1000 16.4980 1.0000
108.1600 18.5702 1.0000
108.2200 12.6751 1.0000
108.2800 22.8003 1.0000
108.3400 11.6614 1.0000
108.4000 12.8394 1.0000
108.4600 12.0508 1.0000
108.5200 17.1030 1.0000
108.5800 28.5987 1.0000
108.6400 12.6081 1.0000
108.7000 19.4512 1.0000
108.7600 14.1002 1.0000
108.8200 8.3669 1.0000
108.8800 25.3924 1.0000
108.9400 16.6980 1.0000
109.0000 12.8507 1.0000
109.0600 19.6206 1.0000
109.1200 24.3026 1.0000
109.1800 18.9529 1.0000
109.2400 18.7862 1.0000
109.3000 14.1789 1.0000
109.3600 19.5733 1.0000
109.4200 17.7718 1.0000
109.4800 13.3699 1.0000
109.5400 15.5832 1.0000
109.6000 17.8137 1.0000
109.6600 14.9955 1.0000
109.7200 20.4092 1.0000
109.7800 20.1267 1.0000
109.8400 14.0708 1.0000
109.9000 17.0103 1.0000
109.9600 16.9363 1.0000
110.0200 17.9911 1.0000
110.0800 12.4230 1.0000
110.1400 14.9666 1.0000
110.2000 15.8686 1.0000
110.2600 14.5207 1.0000
110.3200 21.9948 1.0000
110.3800 15.7427 1.0000
110.4400 19.4170 1.0000
110.5000 17.1056 1.0000
110.5600 18.2720 1.0000
110.6200 13.6668 1.0000
110.6800 15.0307 1.0000
110.7400 12.0495 1.0000
110.8000 17.4956 1.0000
110.8600 20.9642 1.0000
110.9200 21.9610 1.0000
110.9800 14.7739 1.0000
111.0400 12.9098 1.0000
111.1000 16.4930 1.0000
111.1600 11.4969 1.0000
111.2200 25.0134 1.0000
111.2800 17.2885 1.0000
111.3400 15.6965 1.0000
111.4000 17.1366 1.0000
111.4600 15.7284 1.0000
111.5200 18.8219 1.0000
111.5800 17.4387 1.0000
111.6400 15.2351 1.0000
111.7000 19.7891 1.0000
111.7600 13.7840 1.0000
111.8200 22.1380 1.0000
111.8800 15.8086 1.0000
111.9400 13.3743 1.0000
112.0000 19.1275 1.0000
112.0600 18.9107 1.0000
112.1200 11.6678 1.0000
112.1800 12.0374 1.0000
112.2400 16.7201 1.0000
112.3000 20.3411 1.0000
112.3600 21.2742 1.0000
112.4200 14.4733 1.0000
112.4800 17.2847 1.0000
112.5400 13.3098 1.0000
112.6000 24.8181 1.0000
112.6600 18.3279 1.0000
112.7200 18.1991 1.0000
112.7800 22.3260 1.0000
112.8400 18.9595 1.0000
112.9000 21.1093 1.0000
112.9600 12.9448 1.0000
113.0200 15.0482 1.0000
113.0800 17.1637 1.0000
113.1400 17.2260 1.0000
113.2000 18.7184 1.0000
113.2600 16.3456 1.0000
113.3200 16.2222 1.0000
113.3800 12.3088 1.0000
113.4400 20.6223 1.0000
113.5000 19.7539 1.0000
113.5600 19.8678 1.0000
113.6200 10.9515 1.0000
113.6800 24.9979 1.0000
113.7400 27.0346 1.0000
113.8000 16.9995 1.0000
113.8600 20.4865 1.0000
113.9200 16.1085 1.0000
113.9800 22.9806 1.0000
114.0400 18.5213 1.0000
114.1000 25.6304 1.0000
114.1600 19.9198 1.0000
114.2200 12.6518 1.0000
114.2800 16.1174 1.0000
114.3400 13.7009 1.0000
114.4000 16.4647 1.0000
114.4600 14.1026 1.0000
114.5200 17.5432 1.0000
114.5800 19.4063 1.0000
114.6400 19.1989 1.0000
114.7000 20.3402 1.0000
114.7600 16.2887 1.0000
114.8200 15.4151 1.0000
114.8800 18.0036 1.0000
114.9400 31.0949 1.0000
115.0000 18.5061 1.0000
115.0600 13.5624 1.0000
115.1200 19.3497 1.0000
115.1800 22.0156 1.0000
115.2400 16.4330 1.0000
115.3000 21.2194 1.0000
115.3600 20.4321 1.0000
115.4200 28.3762 1.0000
115.4800 35.3596 1.0000
115.5400 34.5776 1.0000
115.6000 34.9449 1.0000
115.6600 41.3185 1.0000
115.7200 33.8965 1.0000
115.7800 45.3952 1.0000
115.8400 55.9368 1.0000
115.9000 56.3434 1.0000
115.9600 43.3838 1.0000
116.0200 48.1070 1.0000
116.0800 40.4861 1.0000
116.1400 46.3666 1.0000
116.2000 28.5808 1.0000
116.2600 31.2333 1.0000
116.3200 30.4712 1.0000
116.3800 27.2966 1.0000
116.4400 30.8101 1.0000
116.5000 15.4835 1.0000
116.5600 21.9308 1.0000
116.6200 19.8586 1.0000
116.6800 20.4648 1.0000
116.7400 8.3248 1.0000
116.8000 14.7059 1.0000
116.8600 17.2792 1.0000
116.9200 17.1502 1.0000
116.9800 24.4614 1.0000
117.0400 26.0192 1.0000
117.1000 23.4480 1.0000
117.1600 25.6318 1.0000
117.2200 15.8873 1.0000
117.2800 23.7808 1.0000
117.3400 14.7278 1.0000
117.4000 16.5292 1.0000
117.4600 21.2702 1.0000
117.5200 23.1539 1.0000
117.5800 16.7804 1.0000
117.6400 17.8791 1.0000
117.7000 11.8725 1.0000
117.7600 25.2455 1.0000
117.8200 23.0241 1.0000
117.8800 24.4613 1.0000
117.9400 11.6074 1.0000
118.0000 19.7894 1.0000
118.0600 14.8141 1.0000
118.1200 19.8137 1.0000
118.1800 28.5133 1.0000
118.2400 19.1869 1.0000
118.3000 17.8036 1.0000
118.3600 23.0776 1.0000
118.4200 17.4142 1.0000
118.4800 13.7937 1.0000
118.5400 14.4301 1.0000
118.6000 10.6468 1.0000
118.6600 20.6821 1.0000
118.7200 16.9124 1.0000
118.7800 22.3426 1.0000
118.8400 11.6928 1.0000
118.9000 11.0834 1.0000
118.9600 17.3224 1.0000
119.0200 8.9364 1.0000
119.0800 17.2556 1.0000
119.1400 15.7603 1.0000
119.2000 18.3409 1.0000
119.2600 15.7088 1.0000
119.3200 19.4486 1.0000
119.3800 18.3899 1.0000
119.4400 14.0592 1.0000
119.5000 17.5970 1.0000
119.5600 16.5650 1.0000
119.6200 19.6298 1.0000
119.6800 24.5143 1.0000
119.7400 11.8798 1.0000
119.8000 25.8243 1.0000
119.8600 18.1241 1.0000
119.9200 12.5502 1.0000
119.9800 18.6420 1.0000
119.9900 15.8166 1.0000
*RAS_INT_END
*RAS_TEMPERATURE_START
*RAS_TEMPERATURE_END
*RAS_DATA_END