File: XRD/May_2022/EFRW4_Unirradiated_regions/PB_Ge220_5SS_500umDS_RS1_Rod_5SS_Hypix1D_EFRW4_r3_FZ_P-irradiated.ras
*RAS_DATA_START
*RAS_HEADER_START
*DISP_FMT_X "%.3f"
*DISP_FMT_Y "%.0f"
*DISP_FULLSCALE "110.7032878456"
*DISP_LINE_COLOR "255.0000000000"
*DISP_LINE_STYLE "0.0000000000"
*DISP_LINE_WIDTH "0.2500000000"
*DISP_NOTE "Collected Data-106"
*DISP_OFFSET_Y "0.0000000000"
*DISP_PEAKSEARCH_UNIT_Y "cps"
*DISP_RANGE_BOTTOM "0.0000000000"
*DISP_RANGE_LEFT "40.0000000000"
*DISP_RANGE_LOGCUTOFF "0.0100000000"
*DISP_RANGE_RIGHT "119.9968000000"
*DISP_RANGE_TOP "110.7032878456"
*DISP_SCALE_MODE_Y "0.0000000000"
*DISP_TAB_NAME "Theta/2-Theta"
*DISP_TITLE_Y "Intensity"
*DISP_UNIT_Y "cps"
*DISP_WINDOW_NAME "MSG_MACROENGINE"
*FILE_COMMENT " "
*FILE_MD5 ""
*FILE_MEMO " "
*FILE_OPERATOR "Administrator"
*FILE_PART_ID "MEAS_KHP2_00061"
*FILE_SAMPLE " "
*FILE_TYPE "RAS_RAW"
*FILE_USERGROUP "System Manager"
*FILE_VERSION "1.0000000000"
*HW_ATTACHMENT_ID "ATT0021"
*HW_ATTACHMENT_NAME "XY-20mm|XY-20mm"
*HW_COUNTER_ID-0 "CUT0041"
*HW_COUNTER_ID-1 "CUT0052"
*HW_COUNTER_ID-2 "CUT0020"
*HW_COUNTER_ID-3 "CSL0021"
*HW_COUNTER_ID-4 "CMC0021"
*HW_COUNTER_NAME-0 "D/teX Ultra 250|D/teX Ultra 250"
*HW_COUNTER_NAME-1 "HyPix 3000(V)|HyPix 3000(V)"
*HW_COUNTER_NAME-2 "None|None"
*HW_COUNTER_NAME-3 "BBM|BBM"
*HW_COUNTER_NAME-4 "検出器モノクロメータ|Detector monochromator"
*HW_COUNTER_SELECT_NAME "HyPix 3000(V)|HyPix 3000(V)"
*HW_GONIOMETER_ID "GON0024"
*HW_GONIOMETER_NAME "SmartLab(In-plane)|SmartLab(In-plane)"
*HW_GONIOMETER_RADIUS-0 "90.0"
*HW_GONIOMETER_RADIUS-1 "114.0"
*HW_GONIOMETER_RADIUS-2 "190.0"
*HW_GONIOMETER_RADIUS-3 "300.0"
*HW_GONIOMETER_RADIUS-4 "187.0"
*HW_GONIOMETER_RADIUS-5 "300.0"
*HW_GONIOMETER_RADIUS-6 "113.0"
*HW_GONIOMETER_RADIUS-7 "331.0"
*HW_I_OPT_ID-0 "CBO0021"
*HW_I_OPT_ID-1 "ICR0021"
*HW_I_OPT_ID-2 "ISL0021"
*HW_I_OPT_ID-3 "ISO0021"
*HW_I_OPT_ID-4 "IAD0021"
*HW_I_OPT_ID-5 "IPR0001"
*HW_I_OPT_NAME-0 "CBOユニット|CBO unit"
*HW_I_OPT_NAME-1 "標準入射光学ユニット|Standard incident optical unit"
*HW_I_OPT_NAME-2 "標準入射スリットボックス|Standard incident slit box"
*HW_I_OPT_NAME-3 "入射平行スリット|Incident parallel slit"
*HW_I_OPT_NAME-4 "長手制限スリット|Length limiting slit"
*HW_I_OPT_NAME-5 "None|None"
*HW_R_ATTENUATER_AUTOMODE "0"
*HW_R_OPT_ID-0 "RSS0022"
*HW_R_OPT_ID-1 "RCR0022"
*HW_R_OPT_ID-2 "RSO0021"
*HW_R_OPT_ID-3 "RRS0022"
*HW_R_OPT_ID-4 "ATN0020"
*HW_R_OPT_ID-5 "RFL0021"
*HW_R_OPT_ID-6 "RAD0021"
*HW_R_OPT_NAME-0 "受光スリットボックス1(Zr軸付)|Receiving slit box # 1 (w/ Zr Axis)"
*HW_R_OPT_NAME-1 "標準受光光学ユニット1|Standard receiving unit # 1"
*HW_R_OPT_NAME-2 "標準受光光学ユニット2|Standard receiving optical unit # 2"
*HW_R_OPT_NAME-3 "仮想受光スリット2|Virtual receiving slit #2"
*HW_R_OPT_NAME-4 "無し|None"
*HW_R_OPT_NAME-5 "Cu Kβ|Cu K-beta"
*HW_R_OPT_NAME-6 "調整用受光スリット|Alignment receiving slit"
*HW_SAMPLE_HOLDER_ID "SMP0021"
*HW_SAMPLE_HOLDER_NAME "χφZクレードル|Chi phi Z cradle"
*HW_XG_CURRENT_MAX "40"
*HW_XG_CURRENT_MIN "2"
*HW_XG_CURRENT_RESOLUTION "1"
*HW_XG_CURRENT_UNIT "mA"
*HW_XG_FOCUS "0.4mm x 8mm"
*HW_XG_FOCUS_TYPE "Fine"
*HW_XG_ID "1200"
*HW_XG_NAME "3kW 封入管(ID:1200)|3kW Sealed tube(ID:1200)"
*HW_XG_TARGET_ATOMIC_NUMBER "29.0000000000"
*HW_XG_TARGET_NAME "Cu"
*HW_XG_TYPE "Hermetic"
*HW_XG_VOLTAGE_MAX "40"
*HW_XG_VOLTAGE_MIN "20"
*HW_XG_VOLTAGE_RESOLUTION "1"
*HW_XG_VOLTAGE_UNIT "kV"
*HW_XG_WATT_MAX "1.500"
*HW_XG_WATT_UNIT "kW"
*HW_XG_WAVE_LENGTH_ALPHA1 "1.540593"
*HW_XG_WAVE_LENGTH_ALPHA2 "1.544414"
*HW_XG_WAVE_LENGTH_BETA "1.392250"
*MEAS_COND_AXIS_NAME-0 "Theta/2-Theta"
*MEAS_COND_AXIS_NAME-1 "2-Theta"
*MEAS_COND_AXIS_NAME-2 "Omega"
*MEAS_COND_AXIS_NAME-3 "Chi"
*MEAS_COND_AXIS_NAME-4 "Phi"
*MEAS_COND_AXIS_NAME-5 "Z"
*MEAS_COND_AXIS_NAME-6 "X"
*MEAS_COND_AXIS_NAME-7 "Y"
*MEAS_COND_AXIS_NAME-8 "2-Theta/Omega"
*MEAS_COND_AXIS_NAME-9 "2-ThetaChi"
*MEAS_COND_AXIS_NAME-10 "2-ThetaChi/Phi"
*MEAS_COND_AXIS_NAME-11 "Alpha"
*MEAS_COND_AXIS_NAME-12 "Beta"
*MEAS_COND_AXIS_NAME-13 "Theta_s"
*MEAS_COND_AXIS_NAME-14 "Theta_d"
*MEAS_COND_AXIS_NAME-15 "Ts"
*MEAS_COND_AXIS_NAME-16 "CBO selection slit"
*MEAS_COND_AXIS_NAME-17 "M"
*MEAS_COND_AXIS_NAME-18 "Incident parallel slit"
*MEAS_COND_AXIS_NAME-19 "Incident slit"
*MEAS_COND_AXIS_NAME-20 ""
*MEAS_COND_AXIS_NAME-21 "Zs"
*MEAS_COND_AXIS_NAME-22 "Incident optical device"
*MEAS_COND_AXIS_NAME-23 "Omega_m"
*MEAS_COND_AXIS_NAME-24 "Length limiting slit"
*MEAS_COND_AXIS_NAME-25 "Center slit"
*MEAS_COND_AXIS_NAME-26 "Filter"
*MEAS_COND_AXIS_NAME-27 "Receiving slit # 1"
*MEAS_COND_AXIS_NAME-28 "Receiving slit # 2"
*MEAS_COND_AXIS_NAME-29 "Receiving optical device"
*MEAS_COND_AXIS_NAME-30 "Receiving parallel slit"
*MEAS_COND_AXIS_NAME-31 "Alignment receiving slit"
*MEAS_COND_AXIS_NAME-32 ""
*MEAS_COND_AXIS_NAME-33 ""
*MEAS_COND_AXIS_NAME-34 "Zd"
*MEAS_COND_AXIS_NAME-35 "Attenuator"
*MEAS_COND_AXIS_NAME-36 "Diffracted beam monochromator"
*MEAS_COND_AXIS_NAME-37 "Monochromator slit"
*MEAS_COND_AXIS_NAME-38 "2-ThetaB"
*MEAS_COND_AXIS_NAME-39 ""
*MEAS_COND_AXIS_NAME-40 ""
*MEAS_COND_AXIS_NAME-41 "Zr"
*MEAS_COND_AXIS_NAME-42 "Primary beam"
*MEAS_COND_AXIS_NAME_INTERNAL-0 "TwoThetaTheta"
*MEAS_COND_AXIS_NAME_INTERNAL-1 "TwoTheta"
*MEAS_COND_AXIS_NAME_INTERNAL-2 "Omega"
*MEAS_COND_AXIS_NAME_INTERNAL-3 "Chi"
*MEAS_COND_AXIS_NAME_INTERNAL-4 "Phi"
*MEAS_COND_AXIS_NAME_INTERNAL-5 "Z"
*MEAS_COND_AXIS_NAME_INTERNAL-6 "X"
*MEAS_COND_AXIS_NAME_INTERNAL-7 "Y"
*MEAS_COND_AXIS_NAME_INTERNAL-8 "TwoThetaOmega"
*MEAS_COND_AXIS_NAME_INTERNAL-9 "TwoThetaChi"
*MEAS_COND_AXIS_NAME_INTERNAL-10 "TwoThetaChiPhi"
*MEAS_COND_AXIS_NAME_INTERNAL-11 "Alpha"
*MEAS_COND_AXIS_NAME_INTERNAL-12 "Beta"
*MEAS_COND_AXIS_NAME_INTERNAL-13 "ThetaS"
*MEAS_COND_AXIS_NAME_INTERNAL-14 "ThetaD"
*MEAS_COND_AXIS_NAME_INTERNAL-15 "Ts"
*MEAS_COND_AXIS_NAME_INTERNAL-16 "CBO"
*MEAS_COND_AXIS_NAME_INTERNAL-17 "CBO-M"
*MEAS_COND_AXIS_NAME_INTERNAL-18 "IncidentSollerSlit"
*MEAS_COND_AXIS_NAME_INTERNAL-19 "IncidentSlitBox"
*MEAS_COND_AXIS_NAME_INTERNAL-20 "IncidentSlitBox-_Axis"
*MEAS_COND_AXIS_NAME_INTERNAL-21 "Zs"
*MEAS_COND_AXIS_NAME_INTERNAL-22 "IncidentMonochromator"
*MEAS_COND_AXIS_NAME_INTERNAL-23 "IncidentMonochromator-OmegaM"
*MEAS_COND_AXIS_NAME_INTERNAL-24 "IncidentAxdSlit"
*MEAS_COND_AXIS_NAME_INTERNAL-25 "CenterSlit"
*MEAS_COND_AXIS_NAME_INTERNAL-26 "Filter"
*MEAS_COND_AXIS_NAME_INTERNAL-27 "ReceivingSlitBox1"
*MEAS_COND_AXIS_NAME_INTERNAL-28 "ReceivingSlitBox2"
*MEAS_COND_AXIS_NAME_INTERNAL-29 "ReceivingOptics"
*MEAS_COND_AXIS_NAME_INTERNAL-30 "ReceivingSollerSlit"
*MEAS_COND_AXIS_NAME_INTERNAL-31 "ReceivingAxdSlit"
*MEAS_COND_AXIS_NAME_INTERNAL-32 "ReceivingSlitBox1-_Axis"
*MEAS_COND_AXIS_NAME_INTERNAL-33 "ReceivingSlitBox2-_Axis"
*MEAS_COND_AXIS_NAME_INTERNAL-34 "ReceivingSlitBox2-Zd"
*MEAS_COND_AXIS_NAME_INTERNAL-35 "Attenuator"
*MEAS_COND_AXIS_NAME_INTERNAL-36 "CounterMonochromator"
*MEAS_COND_AXIS_NAME_INTERNAL-37 "CounterSlit"
*MEAS_COND_AXIS_NAME_INTERNAL-38 "TwoThetaB"
*MEAS_COND_AXIS_NAME_INTERNAL-39 "AlphaR"
*MEAS_COND_AXIS_NAME_INTERNAL-40 "BetaR"
*MEAS_COND_AXIS_NAME_INTERNAL-41 "ReceivingSlitBox1-Zr"
*MEAS_COND_AXIS_NAME_INTERNAL-42 "IncidentPrimary"
*MEAS_COND_AXIS_NAME_MAGICNO-0 "83951616.0000000000"
*MEAS_COND_AXIS_NAME_MAGICNO-1 "268632064.0000000000"
*MEAS_COND_AXIS_NAME_MAGICNO-2 "268500992.0000000000"
*MEAS_COND_AXIS_NAME_MAGICNO-3 "268500992.0000000000"
*MEAS_COND_AXIS_NAME_MAGICNO-4 "268500992.0000000000"
*MEAS_COND_AXIS_NAME_MAGICNO-5 "285278208.0000000000"
*MEAS_COND_AXIS_NAME_MAGICNO-6 "268500992.0000000000"
*MEAS_COND_AXIS_NAME_MAGICNO-7 "268500992.0000000000"
*MEAS_COND_AXIS_NAME_MAGICNO-8 "83951616.0000000000"
*MEAS_COND_AXIS_NAME_MAGICNO-9 "268632064.0000000000"
*MEAS_COND_AXIS_NAME_MAGICNO-10 "83951616.0000000000"
*MEAS_COND_AXIS_NAME_MAGICNO-11 "17039360.0000000000"
*MEAS_COND_AXIS_NAME_MAGICNO-12 "17039360.0000000000"
*MEAS_COND_AXIS_NAME_MAGICNO-13 "131072.0000000000"
*MEAS_COND_AXIS_NAME_MAGICNO-14 "131072.0000000000"
*MEAS_COND_AXIS_NAME_MAGICNO-15 "318898176.0000000000"
*MEAS_COND_AXIS_NAME_MAGICNO-16 "20971521.0000000000"
*MEAS_COND_AXIS_NAME_MAGICNO-17 "285343744.0000000000"
*MEAS_COND_AXIS_NAME_MAGICNO-18 "20971521.0000000000"
*MEAS_COND_AXIS_NAME_MAGICNO-19 "22020097.0000000000"
*MEAS_COND_AXIS_NAME_MAGICNO-20 "25165824.0000000000"
*MEAS_COND_AXIS_NAME_MAGICNO-21 "318898176.0000000000"
*MEAS_COND_AXIS_NAME_MAGICNO-22 "20971521.0000000000"
*MEAS_COND_AXIS_NAME_MAGICNO-23 "285343744.0000000000"
*MEAS_COND_AXIS_NAME_MAGICNO-24 "20971521.0000000000"
*MEAS_COND_AXIS_NAME_MAGICNO-25 "20971521.0000000000"
*MEAS_COND_AXIS_NAME_MAGICNO-26 "20971521.0000000000"
*MEAS_COND_AXIS_NAME_MAGICNO-27 "23068673.0000000000"
*MEAS_COND_AXIS_NAME_MAGICNO-28 "23068673.0000000000"
*MEAS_COND_AXIS_NAME_MAGICNO-29 "20971521.0000000000"
*MEAS_COND_AXIS_NAME_MAGICNO-30 "20971521.0000000000"
*MEAS_COND_AXIS_NAME_MAGICNO-31 "20971521.0000000000"
*MEAS_COND_AXIS_NAME_MAGICNO-32 "25165824.0000000000"
*MEAS_COND_AXIS_NAME_MAGICNO-33 "25165824.0000000000"
*MEAS_COND_AXIS_NAME_MAGICNO-34 "285343744.0000000000"
*MEAS_COND_AXIS_NAME_MAGICNO-35 "0.0000000000"
*MEAS_COND_AXIS_NAME_MAGICNO-36 "20971521.0000000000"
*MEAS_COND_AXIS_NAME_MAGICNO-37 "20971521.0000000000"
*MEAS_COND_AXIS_NAME_MAGICNO-38 "17039360.0000000000"
*MEAS_COND_AXIS_NAME_MAGICNO-39 "8388608.0000000000"
*MEAS_COND_AXIS_NAME_MAGICNO-40 "8388608.0000000000"
*MEAS_COND_AXIS_NAME_MAGICNO-41 "285343744.0000000000"
*MEAS_COND_AXIS_NAME_MAGICNO-42 "20971521.0000000000"
*MEAS_COND_AXIS_OFFSET-0 "-"
*MEAS_COND_AXIS_OFFSET-1 "0.8642000000"
*MEAS_COND_AXIS_OFFSET-2 "0.9822000000"
*MEAS_COND_AXIS_OFFSET-3 "0.0000000000"
*MEAS_COND_AXIS_OFFSET-4 "0.0000000000"
*MEAS_COND_AXIS_OFFSET-5 "-"
*MEAS_COND_AXIS_OFFSET-6 "0.0000000000"
*MEAS_COND_AXIS_OFFSET-7 "0.0000000000"
*MEAS_COND_AXIS_OFFSET-8 "-"
*MEAS_COND_AXIS_OFFSET-9 "0.0000000000"
*MEAS_COND_AXIS_OFFSET-10 "-"
*MEAS_COND_AXIS_OFFSET-11 "-"
*MEAS_COND_AXIS_OFFSET-12 "-"
*MEAS_COND_AXIS_OFFSET-13 "0.9822000000"
*MEAS_COND_AXIS_OFFSET-14 "-0.1180000000"
*MEAS_COND_AXIS_OFFSET-15 "-"
*MEAS_COND_AXIS_OFFSET-16 "-"
*MEAS_COND_AXIS_OFFSET-17 "-"
*MEAS_COND_AXIS_OFFSET-18 "-"
*MEAS_COND_AXIS_OFFSET-19 "-"
*MEAS_COND_AXIS_OFFSET-20 "-"
*MEAS_COND_AXIS_OFFSET-21 "-"
*MEAS_COND_AXIS_OFFSET-22 "-"
*MEAS_COND_AXIS_OFFSET-23 "-"
*MEAS_COND_AXIS_OFFSET-24 "-"
*MEAS_COND_AXIS_OFFSET-25 "-"
*MEAS_COND_AXIS_OFFSET-26 "-"
*MEAS_COND_AXIS_OFFSET-27 "-"
*MEAS_COND_AXIS_OFFSET-28 "-"
*MEAS_COND_AXIS_OFFSET-29 "-"
*MEAS_COND_AXIS_OFFSET-30 "-"
*MEAS_COND_AXIS_OFFSET-31 "-"
*MEAS_COND_AXIS_OFFSET-32 "-"
*MEAS_COND_AXIS_OFFSET-33 "-"
*MEAS_COND_AXIS_OFFSET-34 "-"
*MEAS_COND_AXIS_OFFSET-35 "-"
*MEAS_COND_AXIS_OFFSET-36 "-"
*MEAS_COND_AXIS_OFFSET-37 "-"
*MEAS_COND_AXIS_OFFSET-38 "-"
*MEAS_COND_AXIS_OFFSET-39 "0.0000000000"
*MEAS_COND_AXIS_OFFSET-40 "0.0000000000"
*MEAS_COND_AXIS_OFFSET-41 "-"
*MEAS_COND_AXIS_OFFSET-42 "-"
*MEAS_COND_AXIS_POSITION-0 "40.0000000000"
*MEAS_COND_AXIS_POSITION-1 "40.0000000000"
*MEAS_COND_AXIS_POSITION-2 "20.0000000000"
*MEAS_COND_AXIS_POSITION-3 "0.0000000000"
*MEAS_COND_AXIS_POSITION-4 "0.0000000000"
*MEAS_COND_AXIS_POSITION-5 "0.6389000000"
*MEAS_COND_AXIS_POSITION-6 "1.9630000000"
*MEAS_COND_AXIS_POSITION-7 "0.2050000000"
*MEAS_COND_AXIS_POSITION-8 "40.0000000000"
*MEAS_COND_AXIS_POSITION-9 "0.0000000000"
*MEAS_COND_AXIS_POSITION-10 "0.0000000000"
*MEAS_COND_AXIS_POSITION-11 "90.0000000000"
*MEAS_COND_AXIS_POSITION-12 "0.0000000000"
*MEAS_COND_AXIS_POSITION-13 "20.0000000000"
*MEAS_COND_AXIS_POSITION-14 "20.0000000000"
*MEAS_COND_AXIS_POSITION-15 "-5.4426900000"
*MEAS_COND_AXIS_POSITION-16 "PB"
*MEAS_COND_AXIS_POSITION-17 "0.0000000000"
*MEAS_COND_AXIS_POSITION-18 "Soller_slit_5.0deg_s"
*MEAS_COND_AXIS_POSITION-19 "1.000mm"
*MEAS_COND_AXIS_POSITION-20 "1.0000000000"
*MEAS_COND_AXIS_POSITION-21 "-1.3487500000"
*MEAS_COND_AXIS_POSITION-22 "Ge(220)x2"
*MEAS_COND_AXIS_POSITION-23 "0.0000000000"
*MEAS_COND_AXIS_POSITION-24 "0.5mm"
*MEAS_COND_AXIS_POSITION-25 "None"
*MEAS_COND_AXIS_POSITION-26 "None"
*MEAS_COND_AXIS_POSITION-27 "20.000mm"
*MEAS_COND_AXIS_POSITION-28 "38.500mm"
*MEAS_COND_AXIS_POSITION-29 "PSA_open"
*MEAS_COND_AXIS_POSITION-30 "Soller_slit_5.0deg"
*MEAS_COND_AXIS_POSITION-31 "None"
*MEAS_COND_AXIS_POSITION-32 "20.0000000000"
*MEAS_COND_AXIS_POSITION-33 "38.5000000000"
*MEAS_COND_AXIS_POSITION-34 "0.0000000000"
*MEAS_COND_AXIS_POSITION-35 "-"
*MEAS_COND_AXIS_POSITION-36 "No_unit"
*MEAS_COND_AXIS_POSITION-37 "None"
*MEAS_COND_AXIS_POSITION-38 "40.0000000000"
*MEAS_COND_AXIS_POSITION-39 "0.0000000000"
*MEAS_COND_AXIS_POSITION-40 "0.0000000000"
*MEAS_COND_AXIS_POSITION-41 "0.2584400000"
*MEAS_COND_AXIS_POSITION-42 "None"
*MEAS_COND_AXIS_UNIT-0 "deg"
*MEAS_COND_AXIS_UNIT-1 "deg"
*MEAS_COND_AXIS_UNIT-2 "deg"
*MEAS_COND_AXIS_UNIT-3 "deg"
*MEAS_COND_AXIS_UNIT-4 "deg"
*MEAS_COND_AXIS_UNIT-5 "mm"
*MEAS_COND_AXIS_UNIT-6 "mm"
*MEAS_COND_AXIS_UNIT-7 "mm"
*MEAS_COND_AXIS_UNIT-8 "deg"
*MEAS_COND_AXIS_UNIT-9 "deg"
*MEAS_COND_AXIS_UNIT-10 "deg"
*MEAS_COND_AXIS_UNIT-11 "deg"
*MEAS_COND_AXIS_UNIT-12 "deg"
*MEAS_COND_AXIS_UNIT-13 "deg"
*MEAS_COND_AXIS_UNIT-14 "deg"
*MEAS_COND_AXIS_UNIT-15 "mm"
*MEAS_COND_AXIS_UNIT-16 ""
*MEAS_COND_AXIS_UNIT-17 "pulse"
*MEAS_COND_AXIS_UNIT-18 ""
*MEAS_COND_AXIS_UNIT-19 ""
*MEAS_COND_AXIS_UNIT-20 "mm"
*MEAS_COND_AXIS_UNIT-21 "mm"
*MEAS_COND_AXIS_UNIT-22 ""
*MEAS_COND_AXIS_UNIT-23 "pulse"
*MEAS_COND_AXIS_UNIT-24 ""
*MEAS_COND_AXIS_UNIT-25 ""
*MEAS_COND_AXIS_UNIT-26 ""
*MEAS_COND_AXIS_UNIT-27 ""
*MEAS_COND_AXIS_UNIT-28 ""
*MEAS_COND_AXIS_UNIT-29 ""
*MEAS_COND_AXIS_UNIT-30 ""
*MEAS_COND_AXIS_UNIT-31 ""
*MEAS_COND_AXIS_UNIT-32 "mm"
*MEAS_COND_AXIS_UNIT-33 "mm"
*MEAS_COND_AXIS_UNIT-34 "mm"
*MEAS_COND_AXIS_UNIT-35 ""
*MEAS_COND_AXIS_UNIT-36 ""
*MEAS_COND_AXIS_UNIT-37 ""
*MEAS_COND_AXIS_UNIT-38 "deg"
*MEAS_COND_AXIS_UNIT-39 "deg"
*MEAS_COND_AXIS_UNIT-40 "deg"
*MEAS_COND_AXIS_UNIT-41 "mm"
*MEAS_COND_AXIS_UNIT-42 ""
*MEAS_COND_COUNTER_CNTLOSS_CORR "0.0000000000"
*MEAS_COND_COUNTER_TAUDIFF "0.0000000000"
*MEAS_COND_COUNTER_TAUINT "0.0000000000"
*MEAS_COND_COUNTER_TEMP_CONDITION "NORMAL"
*MEAS_COND_IRRADIATION_MODE "OFF"
*MEAS_COND_IRRADIATION_WIDTH ""
*MEAS_COND_OPT_ATTR "High resolution parallel beam Ge(220)x2/RS"
*MEAS_COND_OPT_NAME "@High resolution PB-Ge(220)x2"
*MEAS_COND_UNSYMMETRIC_MODE "OFF"
*MEAS_COND_XG_CURRENT "30.0000000000"
*MEAS_COND_XG_VOLTAGE "40.0000000000"
*MEAS_COND_XG_WAVE_TYPE "Ka1"
*MEAS_DATA_COUNT "8000.0000000000"
*MEAS_SCAN_AXIS_X "Theta/2-Theta"
*MEAS_SCAN_AXIS_X_INTERNAL "TwoThetaTheta"
*MEAS_SCAN_END_TIME "05/23/22 14:58:45"
*MEAS_SCAN_MODE "CONTINUOUS"
*MEAS_SCAN_MONITOR "0"
*MEAS_SCAN_RESOLUTION_X "0.0002"
*MEAS_SCAN_SPEED "0.503240"
*MEAS_SCAN_SPEED_UNIT "deg/min"
*MEAS_SCAN_SPEED_USER "0.5"
*MEAS_SCAN_START "40.0000000000"
*MEAS_SCAN_START_TIME "05/23/22 12:03:43"
*MEAS_SCAN_STEP "0.0100000000"
*MEAS_SCAN_STOP "119.9900000000"
*MEAS_SCAN_UNIT_X "deg"
*MEAS_SCAN_UNIT_Y "counts"
*RAS_HEADER_END
*RAS_INT_START
40.0000 40.3078 1.0000
40.0600 48.2735 1.0000
40.1200 50.3148 1.0000
40.1800 41.9041 1.0000
40.2400 34.9734 1.0000
40.3000 44.8258 1.0000
40.3600 50.4198 1.0000
40.4200 65.4883 1.0000
40.4800 58.3627 1.0000
40.5400 43.1691 1.0000
40.6000 42.9898 1.0000
40.6600 58.4463 1.0000
40.7200 41.7457 1.0000
40.7800 60.2906 1.0000
40.8400 44.3920 1.0000
40.9000 54.0272 1.0000
40.9600 55.0229 1.0000
41.0200 49.0648 1.0000
41.0800 48.7118 1.0000
41.1400 51.8191 1.0000
41.2000 57.4490 1.0000
41.2600 42.4844 1.0000
41.3200 67.8899 1.0000
41.3800 59.5836 1.0000
41.4400 45.4459 1.0000
41.5000 55.6527 1.0000
41.5600 53.8408 1.0000
41.6200 40.0206 1.0000
41.6800 54.3588 1.0000
41.7400 60.1526 1.0000
41.8000 45.6938 1.0000
41.8600 66.5899 1.0000
41.9200 58.7726 1.0000
41.9800 61.4681 1.0000
42.0400 59.4480 1.0000
42.1000 66.7639 1.0000
42.1600 58.8795 1.0000
42.2200 58.7305 1.0000
42.2800 62.3188 1.0000
42.3400 58.9046 1.0000
42.4000 72.5191 1.0000
42.4600 63.1108 1.0000
42.5200 60.7923 1.0000
42.5800 65.9504 1.0000
42.6400 78.6874 1.0000
42.7000 58.5643 1.0000
42.7600 70.9879 1.0000
42.8200 61.4701 1.0000
42.8800 69.2654 1.0000
42.9400 66.8650 1.0000
43.0000 64.0915 1.0000
43.0600 68.1999 1.0000
43.1200 61.2829 1.0000
43.1800 59.0427 1.0000
43.2400 65.3744 1.0000
43.3000 77.5604 1.0000
43.3600 69.4760 1.0000
43.4200 83.9291 1.0000
43.4800 82.8605 1.0000
43.5400 82.7706 1.0000
43.6000 70.0716 1.0000
43.6600 71.4156 1.0000
43.7200 81.2738 1.0000
43.7800 80.2141 1.0000
43.8400 84.4967 1.0000
43.9000 58.8074 1.0000
43.9600 54.6375 1.0000
44.0200 67.8398 1.0000
44.0800 77.6981 1.0000
44.1400 63.5004 1.0000
44.2000 75.4075 1.0000
44.2600 85.3407 1.0000
44.3200 69.5413 1.0000
44.3800 76.0830 1.0000
44.4400 86.4839 1.0000
44.5000 56.2464 1.0000
44.5600 78.2776 1.0000
44.6200 77.8284 1.0000
44.6800 79.8182 1.0000
44.7400 64.3128 1.0000
44.8000 78.6034 1.0000
44.8600 63.0520 1.0000
44.9200 67.5465 1.0000
44.9800 66.4712 1.0000
45.0400 64.9493 1.0000
45.1000 75.9740 1.0000
45.1600 74.0285 1.0000
45.2200 85.8800 1.0000
45.2800 82.8223 1.0000
45.3400 62.6406 1.0000
45.4000 72.0307 1.0000
45.4600 71.4072 1.0000
45.5200 77.8772 1.0000
45.5800 62.7440 1.0000
45.6400 59.2527 1.0000
45.7000 63.0165 1.0000
45.7600 44.7229 1.0000
45.8200 61.5447 1.0000
45.8800 53.8280 1.0000
45.9400 61.1153 1.0000
46.0000 54.4831 1.0000
46.0600 62.5749 1.0000
46.1200 68.6371 1.0000
46.1800 77.2115 1.0000
46.2400 64.4508 1.0000
46.3000 53.9691 1.0000
46.3600 69.1909 1.0000
46.4200 64.5073 1.0000
46.4800 62.3975 1.0000
46.5400 55.0377 1.0000
46.6000 54.4716 1.0000
46.6600 60.6130 1.0000
46.7200 65.2301 1.0000
46.7800 55.1784 1.0000
46.8400 53.9243 1.0000
46.9000 56.5675 1.0000
46.9600 57.5043 1.0000
47.0200 44.3725 1.0000
47.0800 47.7787 1.0000
47.1400 45.1646 1.0000
47.2000 52.4937 1.0000
47.2600 49.1848 1.0000
47.3200 51.7825 1.0000
47.3800 45.5914 1.0000
47.4400 43.6239 1.0000
47.5000 56.3856 1.0000
47.5600 52.5726 1.0000
47.6200 56.1896 1.0000
47.6800 47.4360 1.0000
47.7400 62.7636 1.0000
47.8000 53.8435 1.0000
47.8600 44.7051 1.0000
47.9200 53.7382 1.0000
47.9800 44.7674 1.0000
48.0400 46.1634 1.0000
48.1000 64.4548 1.0000
48.1600 37.9206 1.0000
48.2200 50.1218 1.0000
48.2800 61.6977 1.0000
48.3400 44.7176 1.0000
48.4000 52.3694 1.0000
48.4600 47.4648 1.0000
48.5200 45.4299 1.0000
48.5800 51.4393 1.0000
48.6400 51.0428 1.0000
48.7000 52.9697 1.0000
48.7600 54.0324 1.0000
48.8200 55.3276 1.0000
48.8800 56.5382 1.0000
48.9400 45.1353 1.0000
49.0000 49.6660 1.0000
49.0600 49.0670 1.0000
49.1200 46.7980 1.0000
49.1800 45.5828 1.0000
49.2400 45.2429 1.0000
49.3000 46.3792 1.0000
49.3600 34.0947 1.0000
49.4200 49.2043 1.0000
49.4800 45.2706 1.0000
49.5400 53.5501 1.0000
49.6000 37.1218 1.0000
49.6600 44.8069 1.0000
49.7200 44.6276 1.0000
49.7800 47.6693 1.0000
49.8400 53.6032 1.0000
49.9000 62.7650 1.0000
49.9600 46.3117 1.0000
50.0200 52.2664 1.0000
50.0800 45.1716 1.0000
50.1400 39.6260 1.0000
50.2000 49.3782 1.0000
50.2600 48.6458 1.0000
50.3200 55.5128 1.0000
50.3800 51.1549 1.0000
50.4400 50.3384 1.0000
50.5000 49.7024 1.0000
50.5600 58.7189 1.0000
50.6200 62.9707 1.0000
50.6800 50.9216 1.0000
50.7400 43.7170 1.0000
50.8000 45.8714 1.0000
50.8600 50.2064 1.0000
50.9200 47.1936 1.0000
50.9800 50.8259 1.0000
51.0400 44.5865 1.0000
51.1000 38.9417 1.0000
51.1600 40.0678 1.0000
51.2200 52.1384 1.0000
51.2800 46.9070 1.0000
51.3400 45.1017 1.0000
51.4000 53.1731 1.0000
51.4600 44.8271 1.0000
51.5200 47.6997 1.0000
51.5800 44.2353 1.0000
51.6400 54.5418 1.0000
51.7000 41.4515 1.0000
51.7600 45.4877 1.0000
51.8200 42.4292 1.0000
51.8800 43.5161 1.0000
51.9400 41.1728 1.0000
52.0000 49.3834 1.0000
52.0600 50.8394 1.0000
52.1200 45.9067 1.0000
52.1800 43.0190 1.0000
52.2400 56.8436 1.0000
52.3000 47.6351 1.0000
52.3600 44.1886 1.0000
52.4200 43.9977 1.0000
52.4800 33.5615 1.0000
52.5400 46.2680 1.0000
52.6000 53.4973 1.0000
52.6600 56.8564 1.0000
52.7200 52.4080 1.0000
52.7800 33.5360 1.0000
52.8400 48.4939 1.0000
52.9000 50.3368 1.0000
52.9600 55.0718 1.0000
53.0200 45.8383 1.0000
53.0800 48.2890 1.0000
53.1400 48.1110 1.0000
53.2000 47.8857 1.0000
53.2600 48.9032 1.0000
53.3200 41.1331 1.0000
53.3800 45.8260 1.0000
53.4400 47.8596 1.0000
53.5000 51.2348 1.0000
53.5600 53.1775 1.0000
53.6200 44.6811 1.0000
53.6800 42.5460 1.0000
53.7400 45.8486 1.0000
53.8000 52.7242 1.0000
53.8600 47.3041 1.0000
53.9200 51.4280 1.0000
53.9800 42.1486 1.0000
54.0400 51.6716 1.0000
54.1000 47.2558 1.0000
54.1600 47.0110 1.0000
54.2200 42.8183 1.0000
54.2800 42.6638 1.0000
54.3400 41.4047 1.0000
54.4000 35.7313 1.0000
54.4600 47.8575 1.0000
54.5200 45.2555 1.0000
54.5800 51.2657 1.0000
54.6400 53.2377 1.0000
54.7000 49.3880 1.0000
54.7600 44.9973 1.0000
54.8200 57.1135 1.0000
54.8800 41.9228 1.0000
54.9400 41.4592 1.0000
55.0000 50.5951 1.0000
55.0600 48.3706 1.0000
55.1200 41.8012 1.0000
55.1800 49.3335 1.0000
55.2400 57.4255 1.0000
55.3000 45.1117 1.0000
55.3600 47.7640 1.0000
55.4200 41.3183 1.0000
55.4800 39.3834 1.0000
55.5400 49.4361 1.0000
55.6000 36.4418 1.0000
55.6600 47.7049 1.0000
55.7200 46.8882 1.0000
55.7800 51.8171 1.0000
55.8400 47.1179 1.0000
55.9000 48.1871 1.0000
55.9600 56.3670 1.0000
56.0200 49.2441 1.0000
56.0800 44.5931 1.0000
56.1400 33.2157 1.0000
56.2000 45.5419 1.0000
56.2600 44.0537 1.0000
56.3200 49.3183 1.0000
56.3800 46.3091 1.0000
56.4400 43.2337 1.0000
56.5000 43.0999 1.0000
56.5600 47.1844 1.0000
56.6200 49.5489 1.0000
56.6800 56.9368 1.0000
56.7400 43.1168 1.0000
56.8000 58.2065 1.0000
56.8600 44.6316 1.0000
56.9200 53.3993 1.0000
56.9800 38.9680 1.0000
57.0400 52.5177 1.0000
57.1000 40.7509 1.0000
57.1600 39.2188 1.0000
57.2200 55.0742 1.0000
57.2800 39.2690 1.0000
57.3400 38.7283 1.0000
57.4000 53.0923 1.0000
57.4600 43.3272 1.0000
57.5200 49.7644 1.0000
57.5800 45.8908 1.0000
57.6400 41.9329 1.0000
57.7000 40.5633 1.0000
57.7600 42.1345 1.0000
57.8200 53.1181 1.0000
57.8800 42.4955 1.0000
57.9400 54.7206 1.0000
58.0000 47.5668 1.0000
58.0600 48.7412 1.0000
58.1200 45.5190 1.0000
58.1800 50.6292 1.0000
58.2400 45.5431 1.0000
58.3000 45.6732 1.0000
58.3600 57.3375 1.0000
58.4200 42.7912 1.0000
58.4800 57.3051 1.0000
58.5400 42.3330 1.0000
58.6000 54.3089 1.0000
58.6600 48.2362 1.0000
58.7200 43.9496 1.0000
58.7800 52.8149 1.0000
58.8400 45.8635 1.0000
58.9000 39.0336 1.0000
58.9600 47.0461 1.0000
59.0200 43.5577 1.0000
59.0800 42.3543 1.0000
59.1400 44.5602 1.0000
59.2000 43.7610 1.0000
59.2600 43.2711 1.0000
59.3200 48.8987 1.0000
59.3800 48.7652 1.0000
59.4400 45.3048 1.0000
59.5000 41.4459 1.0000
59.5600 40.2108 1.0000
59.6200 39.9313 1.0000
59.6800 43.0484 1.0000
59.7400 44.1823 1.0000
59.8000 44.1674 1.0000
59.8600 43.6358 1.0000
59.9200 51.4433 1.0000
59.9800 47.2895 1.0000
60.0400 48.3483 1.0000
60.1000 40.1271 1.0000
60.1600 40.6366 1.0000
60.2200 42.4812 1.0000
60.2800 49.4663 1.0000
60.3400 55.4791 1.0000
60.4000 49.6957 1.0000
60.4600 40.0635 1.0000
60.5200 40.3477 1.0000
60.5800 39.2748 1.0000
60.6400 55.8048 1.0000
60.7000 53.2168 1.0000
60.7600 59.5597 1.0000
60.8200 54.2267 1.0000
60.8800 44.8777 1.0000
60.9400 34.3877 1.0000
61.0000 51.2502 1.0000
61.0600 46.8809 1.0000
61.1200 36.5580 1.0000
61.1800 53.6063 1.0000
61.2400 42.7099 1.0000
61.3000 46.7484 1.0000
61.3600 41.9489 1.0000
61.4200 45.4466 1.0000
61.4800 45.2262 1.0000
61.5400 46.8607 1.0000
61.6000 54.5859 1.0000
61.6600 36.5153 1.0000
61.7200 45.7802 1.0000
61.7800 51.5273 1.0000
61.8400 50.0705 1.0000
61.9000 56.4281 1.0000
61.9600 53.6128 1.0000
62.0200 49.1166 1.0000
62.0800 50.6885 1.0000
62.1400 47.0380 1.0000
62.2000 56.2256 1.0000
62.2600 49.2547 1.0000
62.3200 51.2936 1.0000
62.3800 54.8666 1.0000
62.4400 51.1686 1.0000
62.5000 57.5815 1.0000
62.5600 51.2898 1.0000
62.6200 42.5470 1.0000
62.6800 47.5683 1.0000
62.7400 46.5641 1.0000
62.8000 46.4626 1.0000
62.8600 57.9464 1.0000
62.9200 52.4185 1.0000
62.9800 49.9303 1.0000
63.0400 58.8531 1.0000
63.1000 55.0304 1.0000
63.1600 58.9675 1.0000
63.2200 48.8807 1.0000
63.2800 50.1959 1.0000
63.3400 44.8095 1.0000
63.4000 53.2788 1.0000
63.4600 47.7785 1.0000
63.5200 50.1309 1.0000
63.5800 54.5483 1.0000
63.6400 48.2648 1.0000
63.7000 45.6216 1.0000
63.7600 54.2856 1.0000
63.8200 43.1798 1.0000
63.8800 55.1832 1.0000
63.9400 51.4067 1.0000
64.0000 47.9775 1.0000
64.0600 44.2679 1.0000
64.1200 56.5463 1.0000
64.1800 55.3599 1.0000
64.2400 40.2696 1.0000
64.3000 52.5598 1.0000
64.3600 42.2345 1.0000
64.4200 50.0313 1.0000
64.4800 50.6503 1.0000
64.5400 42.9781 1.0000
64.6000 48.8278 1.0000
64.6600 55.7039 1.0000
64.7200 39.4163 1.0000
64.7800 49.5118 1.0000
64.8400 48.5921 1.0000
64.9000 46.1736 1.0000
64.9600 55.3332 1.0000
65.0200 50.7002 1.0000
65.0800 46.2875 1.0000
65.1400 57.0267 1.0000
65.2000 67.8911 1.0000
65.2600 49.9459 1.0000
65.3200 48.8562 1.0000
65.3800 42.5555 1.0000
65.4400 49.2357 1.0000
65.5000 51.3606 1.0000
65.5600 42.1946 1.0000
65.6200 54.4968 1.0000
65.6800 57.4699 1.0000
65.7400 44.1306 1.0000
65.8000 46.4722 1.0000
65.8600 62.5783 1.0000
65.9200 41.5358 1.0000
65.9800 52.3606 1.0000
66.0400 44.6439 1.0000
66.1000 39.2184 1.0000
66.1600 60.4126 1.0000
66.2200 54.3435 1.0000
66.2800 55.6060 1.0000
66.3400 50.3724 1.0000
66.4000 48.2458 1.0000
66.4600 47.4757 1.0000
66.5200 46.0564 1.0000
66.5800 50.7386 1.0000
66.6400 48.3442 1.0000
66.7000 50.2078 1.0000
66.7600 58.3049 1.0000
66.8200 47.2755 1.0000
66.8800 47.5446 1.0000
66.9400 44.7511 1.0000
67.0000 57.1446 1.0000
67.0600 48.8696 1.0000
67.1200 54.4742 1.0000
67.1800 50.0225 1.0000
67.2400 48.8494 1.0000
67.3000 43.9479 1.0000
67.3600 47.7025 1.0000
67.4200 44.3139 1.0000
67.4800 51.9555 1.0000
67.5400 44.7797 1.0000
67.6000 49.8009 1.0000
67.6600 42.7339 1.0000
67.7200 47.3257 1.0000
67.7800 39.7872 1.0000
67.8400 54.8754 1.0000
67.9000 43.5444 1.0000
67.9600 48.4728 1.0000
68.0200 36.6602 1.0000
68.0800 48.4907 1.0000
68.1400 50.4804 1.0000
68.2000 44.4270 1.0000
68.2600 44.7397 1.0000
68.3200 55.7717 1.0000
68.3800 39.1951 1.0000
68.4400 52.1778 1.0000
68.5000 59.1408 1.0000
68.5600 41.1615 1.0000
68.6200 48.7281 1.0000
68.6800 43.8712 1.0000
68.7400 56.4045 1.0000
68.8000 42.7628 1.0000
68.8600 49.3439 1.0000
68.9200 48.9373 1.0000
68.9800 31.3778 1.0000
69.0400 47.3835 1.0000
69.1000 51.0850 1.0000
69.1600 50.9937 1.0000
69.2200 45.1988 1.0000
69.2800 49.5540 1.0000
69.3400 48.0403 1.0000
69.4000 41.4899 1.0000
69.4600 49.0570 1.0000
69.5200 56.4116 1.0000
69.5800 52.0221 1.0000
69.6400 59.3349 1.0000
69.7000 58.5661 1.0000
69.7600 45.1556 1.0000
69.8200 48.7803 1.0000
69.8800 42.7699 1.0000
69.9400 48.9162 1.0000
70.0000 52.1195 1.0000
70.0600 40.6241 1.0000
70.1200 50.6764 1.0000
70.1800 39.2683 1.0000
70.2400 54.0477 1.0000
70.3000 59.5048 1.0000
70.3600 50.3624 1.0000
70.4200 43.7089 1.0000
70.4800 48.0293 1.0000
70.5400 44.4270 1.0000
70.6000 51.6724 1.0000
70.6600 42.0297 1.0000
70.7200 42.3981 1.0000
70.7800 58.8710 1.0000
70.8400 44.6932 1.0000
70.9000 52.3493 1.0000
70.9600 42.6310 1.0000
71.0200 50.1390 1.0000
71.0800 37.3839 1.0000
71.1400 50.8177 1.0000
71.2000 41.3916 1.0000
71.2600 51.0417 1.0000
71.3200 49.4986 1.0000
71.3800 43.2518 1.0000
71.4400 50.1261 1.0000
71.5000 53.1739 1.0000
71.5600 44.4041 1.0000
71.6200 37.6501 1.0000
71.6800 39.9290 1.0000
71.7400 47.1336 1.0000
71.8000 48.9858 1.0000
71.8600 66.1348 1.0000
71.9200 49.9976 1.0000
71.9800 45.7529 1.0000
72.0400 39.8128 1.0000
72.1000 51.6854 1.0000
72.1600 40.6682 1.0000
72.2200 39.2570 1.0000
72.2800 46.5883 1.0000
72.3400 40.8250 1.0000
72.4000 46.3260 1.0000
72.4600 40.1384 1.0000
72.5200 49.5514 1.0000
72.5800 38.0868 1.0000
72.6400 48.8960 1.0000
72.7000 38.8744 1.0000
72.7600 47.6073 1.0000
72.8200 52.9255 1.0000
72.8800 55.0923 1.0000
72.9400 36.2743 1.0000
73.0000 61.3724 1.0000
73.0600 43.5426 1.0000
73.1200 42.4680 1.0000
73.1800 50.5860 1.0000
73.2400 45.2737 1.0000
73.3000 51.9863 1.0000
73.3600 51.2923 1.0000
73.4200 54.6232 1.0000
73.4800 43.9943 1.0000
73.5400 45.6607 1.0000
73.6000 43.4861 1.0000
73.6600 44.0691 1.0000
73.7200 40.7967 1.0000
73.7800 44.1129 1.0000
73.8400 39.4429 1.0000
73.9000 45.8472 1.0000
73.9600 46.9563 1.0000
74.0200 36.5669 1.0000
74.0800 45.7729 1.0000
74.1400 46.1966 1.0000
74.2000 52.5244 1.0000
74.2600 61.1203 1.0000
74.3200 52.3482 1.0000
74.3800 54.5922 1.0000
74.4400 61.0826 1.0000
74.5000 38.0847 1.0000
74.5600 36.3791 1.0000
74.6200 51.8015 1.0000
74.6800 53.4619 1.0000
74.7400 36.5586 1.0000
74.8000 55.7420 1.0000
74.8600 43.5001 1.0000
74.9200 35.2536 1.0000
74.9800 59.3122 1.0000
75.0400 56.4633 1.0000
75.1000 51.1280 1.0000
75.1600 37.8426 1.0000
75.2200 45.8259 1.0000
75.2800 49.4636 1.0000
75.3400 44.9862 1.0000
75.4000 58.4655 1.0000
75.4600 54.8530 1.0000
75.5200 40.7993 1.0000
75.5800 38.7636 1.0000
75.6400 55.5988 1.0000
75.7000 59.9053 1.0000
75.7600 43.4942 1.0000
75.8200 57.6877 1.0000
75.8800 56.4417 1.0000
75.9400 48.4710 1.0000
76.0000 56.9452 1.0000
76.0600 61.6827 1.0000
76.1200 46.9641 1.0000
76.1800 44.6732 1.0000
76.2400 50.0531 1.0000
76.3000 38.9725 1.0000
76.3600 50.7370 1.0000
76.4200 54.9788 1.0000
76.4800 59.5638 1.0000
76.5400 45.7348 1.0000
76.6000 45.0114 1.0000
76.6600 53.9701 1.0000
76.7200 53.2407 1.0000
76.7800 44.6540 1.0000
76.8400 57.2038 1.0000
76.9000 43.7015 1.0000
76.9600 42.0955 1.0000
77.0200 42.0883 1.0000
77.0800 53.9728 1.0000
77.1400 51.0049 1.0000
77.2000 42.4987 1.0000
77.2600 56.9351 1.0000
77.3200 49.2257 1.0000
77.3800 52.9810 1.0000
77.4400 50.1567 1.0000
77.5000 60.6324 1.0000
77.5600 47.9964 1.0000
77.6200 48.1530 1.0000
77.6800 48.9969 1.0000
77.7400 49.2055 1.0000
77.8000 53.2698 1.0000
77.8600 49.1336 1.0000
77.9200 40.6193 1.0000
77.9800 59.3788 1.0000
78.0400 47.4994 1.0000
78.1000 51.2444 1.0000
78.1600 43.3433 1.0000
78.2200 46.1968 1.0000
78.2800 44.4198 1.0000
78.3400 48.6623 1.0000
78.4000 38.4439 1.0000
78.4600 53.9800 1.0000
78.5200 39.1916 1.0000
78.5800 35.4140 1.0000
78.6400 45.9583 1.0000
78.7000 52.0587 1.0000
78.7600 51.5190 1.0000
78.8200 46.0960 1.0000
78.8800 54.3824 1.0000
78.9400 39.0993 1.0000
79.0000 53.6731 1.0000
79.0600 45.6131 1.0000
79.1200 47.4682 1.0000
79.1800 50.4415 1.0000
79.2400 46.8901 1.0000
79.3000 46.8220 1.0000
79.3600 41.2441 1.0000
79.4200 48.3203 1.0000
79.4800 50.9590 1.0000
79.5400 50.1332 1.0000
79.6000 40.5335 1.0000
79.6600 48.4314 1.0000
79.7200 54.0610 1.0000
79.7800 56.8927 1.0000
79.8400 45.9384 1.0000
79.9000 41.9401 1.0000
79.9600 51.2377 1.0000
80.0200 40.1690 1.0000
80.0800 59.2231 1.0000
80.1400 54.0800 1.0000
80.2000 56.0135 1.0000
80.2600 56.7712 1.0000
80.3200 56.8519 1.0000
80.3800 54.1716 1.0000
80.4400 53.4321 1.0000
80.5000 44.6757 1.0000
80.5600 45.3394 1.0000
80.6200 51.0859 1.0000
80.6800 53.4096 1.0000
80.7400 65.6583 1.0000
80.8000 52.2087 1.0000
80.8600 46.1872 1.0000
80.9200 43.6797 1.0000
80.9800 53.9743 1.0000
81.0400 63.9644 1.0000
81.1000 53.6868 1.0000
81.1600 51.2397 1.0000
81.2200 40.6272 1.0000
81.2800 54.5557 1.0000
81.3400 53.7699 1.0000
81.4000 53.7826 1.0000
81.4600 43.8456 1.0000
81.5200 42.2110 1.0000
81.5800 42.0507 1.0000
81.6400 44.6737 1.0000
81.7000 47.2735 1.0000
81.7600 49.6126 1.0000
81.8200 50.1805 1.0000
81.8800 44.8421 1.0000
81.9400 47.2598 1.0000
82.0000 55.3799 1.0000
82.0600 51.0892 1.0000
82.1200 46.0188 1.0000
82.1800 60.3199 1.0000
82.2400 44.5146 1.0000
82.3000 41.1454 1.0000
82.3600 54.8877 1.0000
82.4200 56.7378 1.0000
82.4800 48.6046 1.0000
82.5400 62.4723 1.0000
82.6000 42.3799 1.0000
82.6600 48.5353 1.0000
82.7200 58.9519 1.0000
82.7800 54.2239 1.0000
82.8400 48.6234 1.0000
82.9000 51.9416 1.0000
82.9600 53.5900 1.0000
83.0200 48.9306 1.0000
83.0800 37.4707 1.0000
83.1400 51.0525 1.0000
83.2000 61.5834 1.0000
83.2600 47.0283 1.0000
83.3200 48.2106 1.0000
83.3800 41.1259 1.0000
83.4400 48.5445 1.0000
83.5000 42.3766 1.0000
83.5600 54.8143 1.0000
83.6200 43.1663 1.0000
83.6800 56.5882 1.0000
83.7400 47.5445 1.0000
83.8000 48.1294 1.0000
83.8600 54.7833 1.0000
83.9200 53.8337 1.0000
83.9800 47.5172 1.0000
84.0400 58.2921 1.0000
84.1000 51.2414 1.0000
84.1600 54.1133 1.0000
84.2200 55.2357 1.0000
84.2800 55.6921 1.0000
84.3400 43.2924 1.0000
84.4000 60.1994 1.0000
84.4600 54.7739 1.0000
84.5200 54.5052 1.0000
84.5800 44.5069 1.0000
84.6400 36.1144 1.0000
84.7000 48.5835 1.0000
84.7600 52.7526 1.0000
84.8200 57.3971 1.0000
84.8800 44.4298 1.0000
84.9400 46.6882 1.0000
85.0000 41.1827 1.0000
85.0600 47.7128 1.0000
85.1200 46.0058 1.0000
85.1800 38.7209 1.0000
85.2400 49.9158 1.0000
85.3000 51.5057 1.0000
85.3600 44.7425 1.0000
85.4200 42.6339 1.0000
85.4800 43.5684 1.0000
85.5400 51.7203 1.0000
85.6000 52.8303 1.0000
85.6600 48.8534 1.0000
85.7200 52.3936 1.0000
85.7800 42.1610 1.0000
85.8400 44.1345 1.0000
85.9000 52.1436 1.0000
85.9600 44.0615 1.0000
86.0200 52.7208 1.0000
86.0800 51.9571 1.0000
86.1400 51.7242 1.0000
86.2000 50.9335 1.0000
86.2600 51.5470 1.0000
86.3200 41.8037 1.0000
86.3800 50.4425 1.0000
86.4400 52.0154 1.0000
86.5000 47.8101 1.0000
86.5600 46.3402 1.0000
86.6200 46.1915 1.0000
86.6800 39.4758 1.0000
86.7400 52.7851 1.0000
86.8000 43.5876 1.0000
86.8600 45.3329 1.0000
86.9200 46.2845 1.0000
86.9800 44.9800 1.0000
87.0400 56.8346 1.0000
87.1000 47.0476 1.0000
87.1600 53.2574 1.0000
87.2200 53.5852 1.0000
87.2800 51.8646 1.0000
87.3400 45.8620 1.0000
87.4000 57.7865 1.0000
87.4600 44.9635 1.0000
87.5200 53.5781 1.0000
87.5800 45.1440 1.0000
87.6400 52.9512 1.0000
87.7000 53.6752 1.0000
87.7600 65.2031 1.0000
87.8200 54.0845 1.0000
87.8800 47.1695 1.0000
87.9400 61.8536 1.0000
88.0000 46.9652 1.0000
88.0600 56.9865 1.0000
88.1200 50.2993 1.0000
88.1800 45.3040 1.0000
88.2400 48.9585 1.0000
88.3000 49.0969 1.0000
88.3600 48.2060 1.0000
88.4200 47.3995 1.0000
88.4800 50.2826 1.0000
88.5400 53.1334 1.0000
88.6000 42.4336 1.0000
88.6600 42.2912 1.0000
88.7200 38.0622 1.0000
88.7800 56.3563 1.0000
88.8400 41.0785 1.0000
88.9000 50.5284 1.0000
88.9600 50.7626 1.0000
89.0200 56.4758 1.0000
89.0800 51.0008 1.0000
89.1400 42.0205 1.0000
89.2000 46.4954 1.0000
89.2600 61.6236 1.0000
89.3200 48.1933 1.0000
89.3800 47.9849 1.0000
89.4400 53.4977 1.0000
89.5000 49.4460 1.0000
89.5600 42.1214 1.0000
89.6200 50.6880 1.0000
89.6800 48.1415 1.0000
89.7400 43.2854 1.0000
89.8000 58.1237 1.0000
89.8600 55.9375 1.0000
89.9200 55.0592 1.0000
89.9800 40.3107 1.0000
90.0400 44.2028 1.0000
90.1000 53.0225 1.0000
90.1600 43.3826 1.0000
90.2200 40.7467 1.0000
90.2800 46.0368 1.0000
90.3400 50.7294 1.0000
90.4000 43.8992 1.0000
90.4600 46.6497 1.0000
90.5200 52.9944 1.0000
90.5800 59.4085 1.0000
90.6400 46.8880 1.0000
90.7000 65.5639 1.0000
90.7600 48.5927 1.0000
90.8200 60.7437 1.0000
90.8800 56.0269 1.0000
90.9400 48.2533 1.0000
91.0000 42.7154 1.0000
91.0600 53.0291 1.0000
91.1200 40.6446 1.0000
91.1800 46.6157 1.0000
91.2400 48.8250 1.0000
91.3000 41.4069 1.0000
91.3600 44.6306 1.0000
91.4200 55.1004 1.0000
91.4800 42.3734 1.0000
91.5400 67.8869 1.0000
91.6000 62.4088 1.0000
91.6600 43.1797 1.0000
91.7200 57.9816 1.0000
91.7800 49.7295 1.0000
91.8400 54.5826 1.0000
91.9000 56.9438 1.0000
91.9600 59.9313 1.0000
92.0200 45.8320 1.0000
92.0800 52.4184 1.0000
92.1400 55.7358 1.0000
92.2000 67.1755 1.0000
92.2600 44.9836 1.0000
92.3200 56.5799 1.0000
92.3800 58.6520 1.0000
92.4400 54.6389 1.0000
92.5000 49.3035 1.0000
92.5600 57.6814 1.0000
92.6200 55.7398 1.0000
92.6800 50.0204 1.0000
92.7400 45.2257 1.0000
92.8000 55.7079 1.0000
92.8600 42.4170 1.0000
92.9200 53.6172 1.0000
92.9800 44.1768 1.0000
93.0400 46.3821 1.0000
93.1000 49.3200 1.0000
93.1600 57.1015 1.0000
93.2200 47.0076 1.0000
93.2800 50.0870 1.0000
93.3400 50.6120 1.0000
93.4000 42.7167 1.0000
93.4600 46.4722 1.0000
93.5200 47.1216 1.0000
93.5800 37.5078 1.0000
93.6400 33.8399 1.0000
93.7000 55.6413 1.0000
93.7600 36.7358 1.0000
93.8200 44.3735 1.0000
93.8800 50.2768 1.0000
93.9400 52.0276 1.0000
94.0000 45.5770 1.0000
94.0600 57.4461 1.0000
94.1200 49.9013 1.0000
94.1800 41.0433 1.0000
94.2400 44.1483 1.0000
94.3000 55.6407 1.0000
94.3600 36.8097 1.0000
94.4200 44.3117 1.0000
94.4800 53.0455 1.0000
94.5400 51.0575 1.0000
94.6000 41.0315 1.0000
94.6600 49.7744 1.0000
94.7200 46.3451 1.0000
94.7800 53.0379 1.0000
94.8400 50.6625 1.0000
94.9000 41.7752 1.0000
94.9600 43.1354 1.0000
95.0200 48.4940 1.0000
95.0800 52.6679 1.0000
95.1400 64.9695 1.0000
95.2000 44.9513 1.0000
95.2600 45.1357 1.0000
95.3200 40.1336 1.0000
95.3800 62.3455 1.0000
95.4400 38.7846 1.0000
95.5000 55.1598 1.0000
95.5600 52.1139 1.0000
95.6200 46.3145 1.0000
95.6800 42.7585 1.0000
95.7400 56.0776 1.0000
95.8000 44.7298 1.0000
95.8600 46.5604 1.0000
95.9200 50.8089 1.0000
95.9800 52.1315 1.0000
96.0400 56.4596 1.0000
96.1000 41.1501 1.0000
96.1600 42.3311 1.0000
96.2200 46.4948 1.0000
96.2800 57.8610 1.0000
96.3400 44.5551 1.0000
96.4000 45.4310 1.0000
96.4600 50.3965 1.0000
96.5200 45.9321 1.0000
96.5800 48.2555 1.0000
96.6400 58.5977 1.0000
96.7000 50.7546 1.0000
96.7600 45.4056 1.0000
96.8200 56.2623 1.0000
96.8800 51.8281 1.0000
96.9400 53.7360 1.0000
97.0000 57.4533 1.0000
97.0600 48.0494 1.0000
97.1200 44.1744 1.0000
97.1800 50.5501 1.0000
97.2400 49.4931 1.0000
97.3000 59.1053 1.0000
97.3600 50.7874 1.0000
97.4200 58.0996 1.0000
97.4800 51.1059 1.0000
97.5400 50.2913 1.0000
97.6000 52.7268 1.0000
97.6600 53.6787 1.0000
97.7200 61.7707 1.0000
97.7800 60.6883 1.0000
97.8400 57.7589 1.0000
97.9000 44.0355 1.0000
97.9600 56.3923 1.0000
98.0200 48.7163 1.0000
98.0800 53.0449 1.0000
98.1400 51.6030 1.0000
98.2000 49.1002 1.0000
98.2600 53.2640 1.0000
98.3200 56.8763 1.0000
98.3800 58.9471 1.0000
98.4400 44.8623 1.0000
98.5000 53.7434 1.0000
98.5600 54.4903 1.0000
98.6200 44.8474 1.0000
98.6800 49.1848 1.0000
98.7400 53.7753 1.0000
98.8000 55.4474 1.0000
98.8600 56.6295 1.0000
98.9200 51.1009 1.0000
98.9800 58.3419 1.0000
99.0400 50.5645 1.0000
99.1000 59.0346 1.0000
99.1600 57.8230 1.0000
99.2200 47.5679 1.0000
99.2800 51.8954 1.0000
99.3400 48.5802 1.0000
99.4000 61.6627 1.0000
99.4600 44.0984 1.0000
99.5200 51.1576 1.0000
99.5800 53.9712 1.0000
99.6400 52.5647 1.0000
99.7000 51.9634 1.0000
99.7600 55.1553 1.0000
99.8200 44.6514 1.0000
99.8800 46.7698 1.0000
99.9400 45.9331 1.0000
100.0000 48.0311 1.0000
100.0600 44.8353 1.0000
100.1200 50.8092 1.0000
100.1800 49.0472 1.0000
100.2400 53.5420 1.0000
100.3000 57.4742 1.0000
100.3600 50.4940 1.0000
100.4200 51.3696 1.0000
100.4800 56.6130 1.0000
100.5400 37.0194 1.0000
100.6000 62.8868 1.0000
100.6600 47.3057 1.0000
100.7200 50.7494 1.0000
100.7800 46.0615 1.0000
100.8400 47.2097 1.0000
100.9000 50.0741 1.0000
100.9600 55.2943 1.0000
101.0200 45.9348 1.0000
101.0800 49.6395 1.0000
101.1400 48.7185 1.0000
101.2000 40.0254 1.0000
101.2600 43.8890 1.0000
101.3200 54.2332 1.0000
101.3800 38.3019 1.0000
101.4400 45.4832 1.0000
101.5000 39.5906 1.0000
101.5600 42.0600 1.0000
101.6200 56.5937 1.0000
101.6800 48.5269 1.0000
101.7400 58.8306 1.0000
101.8000 47.4905 1.0000
101.8600 46.1506 1.0000
101.9200 62.2246 1.0000
101.9800 50.9192 1.0000
102.0400 61.2044 1.0000
102.1000 43.4835 1.0000
102.1600 51.9270 1.0000
102.2200 63.2222 1.0000
102.2800 49.8186 1.0000
102.3400 46.2334 1.0000
102.4000 47.5812 1.0000
102.4600 48.3234 1.0000
102.5200 57.1661 1.0000
102.5800 44.6825 1.0000
102.6400 50.7794 1.0000
102.7000 43.0109 1.0000
102.7600 44.2990 1.0000
102.8200 54.0469 1.0000
102.8800 50.6029 1.0000
102.9400 52.0420 1.0000
103.0000 48.3817 1.0000
103.0600 53.5169 1.0000
103.1200 39.8907 1.0000
103.1800 47.1512 1.0000
103.2400 48.5578 1.0000
103.3000 57.6002 1.0000
103.3600 56.9145 1.0000
103.4200 49.4520 1.0000
103.4800 44.0145 1.0000
103.5400 63.5700 1.0000
103.6000 65.2567 1.0000
103.6600 56.9929 1.0000
103.7200 45.7853 1.0000
103.7800 47.4389 1.0000
103.8400 41.3619 1.0000
103.9000 43.7254 1.0000
103.9600 46.3219 1.0000
104.0200 49.8014 1.0000
104.0800 60.2479 1.0000
104.1400 44.2664 1.0000
104.2000 48.3667 1.0000
104.2600 43.7182 1.0000
104.3200 51.4586 1.0000
104.3800 56.9757 1.0000
104.4400 51.9697 1.0000
104.5000 51.5195 1.0000
104.5600 37.7995 1.0000
104.6200 43.7506 1.0000
104.6800 60.4282 1.0000
104.7400 47.4193 1.0000
104.8000 52.7557 1.0000
104.8600 52.4627 1.0000
104.9200 61.1219 1.0000
104.9800 49.0657 1.0000
105.0400 47.7897 1.0000
105.1000 46.3324 1.0000
105.1600 46.3817 1.0000
105.2200 51.0615 1.0000
105.2800 55.1422 1.0000
105.3400 50.7892 1.0000
105.4000 44.0151 1.0000
105.4600 46.6971 1.0000
105.5200 43.4207 1.0000
105.5800 53.3265 1.0000
105.6400 46.0003 1.0000
105.7000 39.6004 1.0000
105.7600 45.3871 1.0000
105.8200 53.4348 1.0000
[...]
69.0400 47.7710 1.0000
69.1000 54.4628 1.0000
69.1600 46.7376 1.0000
69.2200 48.7690 1.0000
69.2800 50.7210 1.0000
69.3400 65.0286 1.0000
69.4000 44.6996 1.0000
69.4600 51.9592 1.0000
69.5200 50.2821 1.0000
69.5800 46.7472 1.0000
69.6400 62.0392 1.0000
69.7000 47.0528 1.0000
69.7600 43.3406 1.0000
69.8200 54.1884 1.0000
69.8800 40.9962 1.0000
69.9400 41.8373 1.0000
70.0000 54.8929 1.0000
70.0600 42.8118 1.0000
70.1200 50.1080 1.0000
70.1800 37.7036 1.0000
70.2400 48.4383 1.0000
70.3000 36.5109 1.0000
70.3600 50.3722 1.0000
70.4200 45.6239 1.0000
70.4800 51.5078 1.0000
70.5400 40.7083 1.0000
70.6000 52.7936 1.0000
70.6600 60.5680 1.0000
70.7200 48.5811 1.0000
70.7800 50.2386 1.0000
70.8400 48.8701 1.0000
70.9000 47.0438 1.0000
70.9600 37.8198 1.0000
71.0200 50.4405 1.0000
71.0800 48.4165 1.0000
71.1400 41.8166 1.0000
71.2000 53.0084 1.0000
71.2600 59.7869 1.0000
71.3200 39.0146 1.0000
71.3800 58.9525 1.0000
71.4400 52.9984 1.0000
71.5000 48.4420 1.0000
71.5600 52.2982 1.0000
71.6200 48.0602 1.0000
71.6800 52.2803 1.0000
71.7400 49.9930 1.0000
71.8000 52.6755 1.0000
71.8600 56.4548 1.0000
71.9200 44.6470 1.0000
71.9800 39.1941 1.0000
72.0400 52.6545 1.0000
72.1000 44.5187 1.0000
72.1600 52.8178 1.0000
72.2200 35.4718 1.0000
72.2800 40.7442 1.0000
72.3400 52.1719 1.0000
72.4000 54.8040 1.0000
72.4600 43.7462 1.0000
72.5200 47.8509 1.0000
72.5800 51.2155 1.0000
72.6400 40.7849 1.0000
72.7000 42.4031 1.0000
72.7600 49.8985 1.0000
72.8200 51.0839 1.0000
72.8800 43.7384 1.0000
72.9400 37.9867 1.0000
73.0000 45.3878 1.0000
73.0600 37.1209 1.0000
73.1200 41.2572 1.0000
73.1800 40.9922 1.0000
73.2400 37.5905 1.0000
73.3000 52.7020 1.0000
73.3600 44.0251 1.0000
73.4200 65.0793 1.0000
73.4800 56.2929 1.0000
73.5400 61.1146 1.0000
73.6000 58.6469 1.0000
73.6600 41.7575 1.0000
73.7200 48.8424 1.0000
73.7800 57.4796 1.0000
73.8400 47.1120 1.0000
73.9000 53.8749 1.0000
73.9600 46.0184 1.0000
74.0200 61.2994 1.0000
74.0800 40.7620 1.0000
74.1400 48.9515 1.0000
74.2000 48.6839 1.0000
74.2600 52.4215 1.0000
74.3200 44.7713 1.0000
74.3800 47.0585 1.0000
74.4400 56.7644 1.0000
74.5000 49.8244 1.0000
74.5600 49.2208 1.0000
74.6200 49.1924 1.0000
74.6800 43.9947 1.0000
74.7400 51.2139 1.0000
74.8000 45.6054 1.0000
74.8600 41.3562 1.0000
74.9200 44.7794 1.0000
74.9800 44.1024 1.0000
75.0400 56.4068 1.0000
75.1000 52.3633 1.0000
75.1600 64.7892 1.0000
75.2200 41.7329 1.0000
75.2800 50.4166 1.0000
75.3400 57.2687 1.0000
75.4000 53.5958 1.0000
75.4600 48.2973 1.0000
75.5200 47.4449 1.0000
75.5800 54.3353 1.0000
75.6400 53.6835 1.0000
75.7000 45.3093 1.0000
75.7600 50.6858 1.0000
75.8200 35.6084 1.0000
75.8800 51.1492 1.0000
75.9400 51.2568 1.0000
76.0000 39.5326 1.0000
76.0600 52.5489 1.0000
76.1200 52.3742 1.0000
76.1800 42.8027 1.0000
76.2400 61.1336 1.0000
76.3000 43.6264 1.0000
76.3600 40.2835 1.0000
76.4200 37.0567 1.0000
76.4800 53.8263 1.0000
76.5400 37.3084 1.0000
76.6000 52.3844 1.0000
76.6600 45.2684 1.0000
76.7200 53.9452 1.0000
76.7800 50.4169 1.0000
76.8400 44.2147 1.0000
76.9000 45.8591 1.0000
76.9600 43.8589 1.0000
77.0200 60.3118 1.0000
77.0800 46.2569 1.0000
77.1400 48.2762 1.0000
77.2000 40.9591 1.0000
77.2600 56.1263 1.0000
77.3200 43.8673 1.0000
77.3800 48.7172 1.0000
77.4400 49.5424 1.0000
77.5000 39.6490 1.0000
77.5600 51.7463 1.0000
77.6200 46.9140 1.0000
77.6800 55.5452 1.0000
77.7400 52.4155 1.0000
77.8000 52.5615 1.0000
77.8600 50.8345 1.0000
77.9200 56.4267 1.0000
77.9800 48.4011 1.0000
78.0400 55.1722 1.0000
78.1000 64.6644 1.0000
78.1600 54.3961 1.0000
78.2200 50.2260 1.0000
78.2800 39.4422 1.0000
78.3400 41.2729 1.0000
78.4000 40.1400 1.0000
78.4600 48.0634 1.0000
78.5200 50.2734 1.0000
78.5800 59.2823 1.0000
78.6400 41.8815 1.0000
78.7000 59.4792 1.0000
78.7600 50.7969 1.0000
78.8200 61.1257 1.0000
78.8800 48.9029 1.0000
78.9400 50.2124 1.0000
79.0000 53.7156 1.0000
79.0600 55.8169 1.0000
79.1200 50.9959 1.0000
79.1800 59.4457 1.0000
79.2400 46.4003 1.0000
79.3000 45.7431 1.0000
79.3600 50.4898 1.0000
79.4200 55.3625 1.0000
79.4800 55.1415 1.0000
79.5400 47.8600 1.0000
79.6000 46.9584 1.0000
79.6600 55.7843 1.0000
79.7200 50.9558 1.0000
79.7800 40.8317 1.0000
79.8400 51.0573 1.0000
79.9000 44.4815 1.0000
79.9600 40.1228 1.0000
80.0200 44.5790 1.0000
80.0800 48.6032 1.0000
80.1400 41.2182 1.0000
80.2000 54.7433 1.0000
80.2600 46.4946 1.0000
80.3200 53.2373 1.0000
80.3800 43.8827 1.0000
80.4400 52.8451 1.0000
80.5000 51.2561 1.0000
80.5600 47.0678 1.0000
80.6200 70.2946 1.0000
80.6800 55.2506 1.0000
80.7400 55.0461 1.0000
80.8000 52.9823 1.0000
80.8600 53.1365 1.0000
80.9200 59.7169 1.0000
80.9800 58.1307 1.0000
81.0400 58.4243 1.0000
81.1000 51.0659 1.0000
81.1600 52.2464 1.0000
81.2200 39.9301 1.0000
81.2800 43.4112 1.0000
81.3400 53.4264 1.0000
81.4000 60.5180 1.0000
81.4600 49.8376 1.0000
81.5200 61.3574 1.0000
81.5800 54.2862 1.0000
81.6400 58.3704 1.0000
81.7000 49.2643 1.0000
81.7600 65.4646 1.0000
81.8200 61.7366 1.0000
81.8800 61.2200 1.0000
81.9400 48.3520 1.0000
82.0000 68.5157 1.0000
82.0600 52.7347 1.0000
82.1200 50.0126 1.0000
82.1800 55.1443 1.0000
82.2400 54.8115 1.0000
82.3000 48.6127 1.0000
82.3600 44.3842 1.0000
82.4200 52.1248 1.0000
82.4800 54.7900 1.0000
82.5400 49.5691 1.0000
82.6000 48.5894 1.0000
82.6600 46.9802 1.0000
82.7200 49.7121 1.0000
82.7800 61.4624 1.0000
82.8400 39.2924 1.0000
82.9000 49.7425 1.0000
82.9600 59.0665 1.0000
83.0200 50.0601 1.0000
83.0800 60.1304 1.0000
83.1400 50.8020 1.0000
83.2000 50.8374 1.0000
83.2600 40.8032 1.0000
83.3200 49.3520 1.0000
83.3800 54.8133 1.0000
83.4400 54.2333 1.0000
83.5000 42.4392 1.0000
83.5600 47.1449 1.0000
83.6200 52.9932 1.0000
83.6800 55.6469 1.0000
83.7400 48.8496 1.0000
83.8000 57.4760 1.0000
83.8600 63.4762 1.0000
83.9200 50.2720 1.0000
83.9800 50.4391 1.0000
84.0400 51.5211 1.0000
84.1000 55.7471 1.0000
84.1600 54.4087 1.0000
84.2200 46.9152 1.0000
84.2800 52.9444 1.0000
84.3400 47.5909 1.0000
84.4000 54.5928 1.0000
84.4600 52.2099 1.0000
84.5200 60.1912 1.0000
84.5800 57.1411 1.0000
84.6400 49.9837 1.0000
84.7000 39.4650 1.0000
84.7600 49.3335 1.0000
84.8200 46.4192 1.0000
84.8800 50.3533 1.0000
84.9400 58.4454 1.0000
85.0000 47.3653 1.0000
85.0600 43.3627 1.0000
85.1200 52.4241 1.0000
85.1800 48.2843 1.0000
85.2400 56.4549 1.0000
85.3000 56.9975 1.0000
85.3600 54.4446 1.0000
85.4200 58.2232 1.0000
85.4800 50.4381 1.0000
85.5400 41.6378 1.0000
85.6000 63.3042 1.0000
85.6600 50.2802 1.0000
85.7200 48.5647 1.0000
85.7800 48.2750 1.0000
85.8400 41.1497 1.0000
85.9000 51.8424 1.0000
85.9600 51.3985 1.0000
86.0200 50.2009 1.0000
86.0800 49.4975 1.0000
86.1400 47.2653 1.0000
86.2000 61.7688 1.0000
86.2600 49.5975 1.0000
86.3200 41.3852 1.0000
86.3800 48.9485 1.0000
86.4400 52.5289 1.0000
86.5000 54.8062 1.0000
86.5600 41.0537 1.0000
86.6200 43.7569 1.0000
86.6800 43.1865 1.0000
86.7400 51.2295 1.0000
86.8000 51.5652 1.0000
86.8600 64.2192 1.0000
86.9200 52.0181 1.0000
86.9800 50.5374 1.0000
87.0400 43.0314 1.0000
87.1000 36.6658 1.0000
87.1600 55.3935 1.0000
87.2200 44.1090 1.0000
87.2800 52.3417 1.0000
87.3400 49.3586 1.0000
87.4000 47.6856 1.0000
87.4600 53.7967 1.0000
87.5200 45.6070 1.0000
87.5800 46.0652 1.0000
87.6400 37.2611 1.0000
87.7000 55.6905 1.0000
87.7600 50.9014 1.0000
87.8200 56.2631 1.0000
87.8800 52.3639 1.0000
87.9400 49.8541 1.0000
88.0000 58.1716 1.0000
88.0600 46.9362 1.0000
88.1200 47.3134 1.0000
88.1800 63.3467 1.0000
88.2400 43.6594 1.0000
88.3000 54.3666 1.0000
88.3600 51.2259 1.0000
88.4200 46.8012 1.0000
88.4800 40.1588 1.0000
88.5400 55.4486 1.0000
88.6000 42.1077 1.0000
88.6600 58.1586 1.0000
88.7200 44.7181 1.0000
88.7800 62.3648 1.0000
88.8400 47.0719 1.0000
88.9000 55.7430 1.0000
88.9600 40.6663 1.0000
89.0200 63.8782 1.0000
89.0800 56.3407 1.0000
89.1400 52.1206 1.0000
89.2000 56.0197 1.0000
89.2600 41.9028 1.0000
89.3200 56.1515 1.0000
89.3800 49.5818 1.0000
89.4400 45.2941 1.0000
89.5000 45.8218 1.0000
89.5600 40.8832 1.0000
89.6200 50.1978 1.0000
89.6800 53.1630 1.0000
89.7400 42.2774 1.0000
89.8000 51.4217 1.0000
89.8600 50.2638 1.0000
89.9200 49.3221 1.0000
89.9800 46.4176 1.0000
90.0400 40.3441 1.0000
90.1000 58.6193 1.0000
90.1600 47.6742 1.0000
90.2200 49.5933 1.0000
90.2800 52.2295 1.0000
90.3400 53.7526 1.0000
90.4000 56.2143 1.0000
90.4600 58.4457 1.0000
90.5200 44.0133 1.0000
90.5800 56.9424 1.0000
90.6400 57.5029 1.0000
90.7000 43.1833 1.0000
90.7600 57.0430 1.0000
90.8200 58.6592 1.0000
90.8800 44.7929 1.0000
90.9400 46.4953 1.0000
91.0000 53.2846 1.0000
91.0600 43.6955 1.0000
91.1200 50.3464 1.0000
91.1800 51.5158 1.0000
91.2400 50.1578 1.0000
91.3000 46.6308 1.0000
91.3600 49.1319 1.0000
91.4200 47.9113 1.0000
91.4800 41.7436 1.0000
91.5400 51.4839 1.0000
91.6000 46.3480 1.0000
91.6600 40.7810 1.0000
91.7200 49.4184 1.0000
91.7800 49.0717 1.0000
91.8400 45.7786 1.0000
91.9000 43.7496 1.0000
91.9600 39.8913 1.0000
92.0200 50.2142 1.0000
92.0800 45.4462 1.0000
92.1400 51.7842 1.0000
92.2000 50.8264 1.0000
92.2600 45.0193 1.0000
92.3200 45.8043 1.0000
92.3800 47.5975 1.0000
92.4400 47.6555 1.0000
92.5000 46.7839 1.0000
92.5600 43.6934 1.0000
92.6200 50.7767 1.0000
92.6800 40.9832 1.0000
92.7400 48.3067 1.0000
92.8000 49.1508 1.0000
92.8600 43.8993 1.0000
92.9200 50.5601 1.0000
92.9800 48.7324 1.0000
93.0400 49.3559 1.0000
93.1000 54.8686 1.0000
93.1600 39.4696 1.0000
93.2200 43.4280 1.0000
93.2800 47.6736 1.0000
93.3400 51.0599 1.0000
93.4000 63.4449 1.0000
93.4600 54.8421 1.0000
93.5200 43.0221 1.0000
93.5800 49.0590 1.0000
93.6400 37.4540 1.0000
93.7000 48.5847 1.0000
93.7600 54.1953 1.0000
93.8200 54.0699 1.0000
93.8800 45.3850 1.0000
93.9400 53.0391 1.0000
94.0000 62.2822 1.0000
94.0600 49.0158 1.0000
94.1200 51.7503 1.0000
94.1800 39.4131 1.0000
94.2400 44.3684 1.0000
94.3000 44.2982 1.0000
94.3600 46.5640 1.0000
94.4200 49.0973 1.0000
94.4800 47.6482 1.0000
94.5400 50.8584 1.0000
94.6000 49.6623 1.0000
94.6600 36.3900 1.0000
94.7200 56.7197 1.0000
94.7800 49.1191 1.0000
94.8400 39.9161 1.0000
94.9000 39.8636 1.0000
94.9600 51.3667 1.0000
95.0200 52.4500 1.0000
95.0800 40.3112 1.0000
95.1400 53.9864 1.0000
95.2000 55.3432 1.0000
95.2600 42.5478 1.0000
95.3200 47.3808 1.0000
95.3800 45.8556 1.0000
95.4400 63.3033 1.0000
95.5000 49.7759 1.0000
95.5600 47.5739 1.0000
95.6200 53.0258 1.0000
95.6800 48.5771 1.0000
95.7400 54.8306 1.0000
95.8000 50.5273 1.0000
95.8600 54.3502 1.0000
95.9200 50.9245 1.0000
95.9800 43.9520 1.0000
96.0400 52.3308 1.0000
96.1000 58.7710 1.0000
96.1600 46.8883 1.0000
96.2200 53.1546 1.0000
96.2800 47.2738 1.0000
96.3400 48.7827 1.0000
96.4000 61.7897 1.0000
96.4600 51.3407 1.0000
96.5200 48.2180 1.0000
96.5800 46.2810 1.0000
96.6400 45.1485 1.0000
96.7000 48.2797 1.0000
96.7600 53.3933 1.0000
96.8200 67.5240 1.0000
96.8800 54.2167 1.0000
96.9400 49.4203 1.0000
97.0000 62.5162 1.0000
97.0600 60.0847 1.0000
97.1200 53.6493 1.0000
97.1800 48.3201 1.0000
97.2400 61.1631 1.0000
97.3000 60.0157 1.0000
97.3600 48.2423 1.0000
97.4200 51.2530 1.0000
97.4800 54.3560 1.0000
97.5400 55.4348 1.0000
97.6000 46.6674 1.0000
97.6600 55.3810 1.0000
97.7200 44.9263 1.0000
97.7800 51.3254 1.0000
97.8400 57.4976 1.0000
97.9000 50.1210 1.0000
97.9600 60.4407 1.0000
98.0200 56.3552 1.0000
98.0800 55.9835 1.0000
98.1400 48.2859 1.0000
98.2000 55.4331 1.0000
98.2600 53.9803 1.0000
98.3200 54.8815 1.0000
98.3800 59.6905 1.0000
98.4400 47.2353 1.0000
98.5000 42.8202 1.0000
98.5600 51.7361 1.0000
98.6200 62.7328 1.0000
98.6800 49.6067 1.0000
98.7400 59.4858 1.0000
98.8000 59.3517 1.0000
98.8600 58.8763 1.0000
98.9200 55.6312 1.0000
98.9800 54.5996 1.0000
99.0400 55.3696 1.0000
99.1000 53.9189 1.0000
99.1600 39.6520 1.0000
99.2200 61.8793 1.0000
99.2800 50.4710 1.0000
99.3400 52.7149 1.0000
99.4000 50.8343 1.0000
99.4600 51.6784 1.0000
99.5200 53.6757 1.0000
99.5800 40.6143 1.0000
99.6400 54.3870 1.0000
99.7000 50.6851 1.0000
99.7600 42.3748 1.0000
99.8200 52.9024 1.0000
99.8800 48.1211 1.0000
99.9400 44.7818 1.0000
100.0000 61.2681 1.0000
100.0600 48.4653 1.0000
100.1200 49.0295 1.0000
100.1800 51.6927 1.0000
100.2400 57.7885 1.0000
100.3000 52.6075 1.0000
100.3600 41.3791 1.0000
100.4200 47.5704 1.0000
100.4800 45.6544 1.0000
100.5400 55.5602 1.0000
100.6000 48.6860 1.0000
100.6600 59.2623 1.0000
100.7200 58.8147 1.0000
100.7800 49.7827 1.0000
100.8400 69.9143 1.0000
100.9000 59.1080 1.0000
100.9600 48.7782 1.0000
101.0200 51.8982 1.0000
101.0800 40.0140 1.0000
101.1400 57.3951 1.0000
101.2000 50.3084 1.0000
101.2600 46.4361 1.0000
101.3200 51.0462 1.0000
101.3800 41.0429 1.0000
101.4400 54.2124 1.0000
101.5000 37.3532 1.0000
101.5600 59.4397 1.0000
101.6200 49.9378 1.0000
101.6800 45.2993 1.0000
101.7400 61.0986 1.0000
101.8000 43.4237 1.0000
101.8600 53.9133 1.0000
101.9200 53.5198 1.0000
101.9800 40.9997 1.0000
102.0400 63.1183 1.0000
102.1000 54.7662 1.0000
102.1600 53.1588 1.0000
102.2200 54.4441 1.0000
102.2800 48.7886 1.0000
102.3400 51.0453 1.0000
102.4000 50.2870 1.0000
102.4600 63.0689 1.0000
102.5200 54.0207 1.0000
102.5800 50.1104 1.0000
102.6400 54.5099 1.0000
102.7000 42.1847 1.0000
102.7600 50.1002 1.0000
102.8200 42.0421 1.0000
102.8800 44.3535 1.0000
102.9400 55.5472 1.0000
103.0000 55.6858 1.0000
103.0600 59.7008 1.0000
103.1200 38.8737 1.0000
103.1800 36.1741 1.0000
103.2400 59.8606 1.0000
103.3000 49.5358 1.0000
103.3600 46.0498 1.0000
103.4200 57.7867 1.0000
103.4800 60.8072 1.0000
103.5400 59.2505 1.0000
103.6000 58.6137 1.0000
103.6600 62.2193 1.0000
103.7200 45.5087 1.0000
103.7800 49.3727 1.0000
103.8400 57.3614 1.0000
103.9000 49.0388 1.0000
103.9600 33.9600 1.0000
104.0200 51.8265 1.0000
104.0800 52.2556 1.0000
104.1400 51.8527 1.0000
104.2000 54.4038 1.0000
104.2600 51.1753 1.0000
104.3200 51.5344 1.0000
104.3800 62.7894 1.0000
104.4400 53.9006 1.0000
104.5000 58.1610 1.0000
104.5600 48.8960 1.0000
104.6200 49.6778 1.0000
104.6800 49.5822 1.0000
104.7400 49.6536 1.0000
104.8000 40.2907 1.0000
104.8600 49.2237 1.0000
104.9200 42.8218 1.0000
104.9800 43.3258 1.0000
105.0400 50.5290 1.0000
105.1000 33.9031 1.0000
105.1600 46.3418 1.0000
105.2200 52.4047 1.0000
105.2800 49.5710 1.0000
105.3400 52.9583 1.0000
105.4000 47.4323 1.0000
105.4600 45.5148 1.0000
105.5200 46.1126 1.0000
105.5800 57.4367 1.0000
105.6400 51.8272 1.0000
105.7000 51.8547 1.0000
105.7600 43.1846 1.0000
105.8200 52.1342 1.0000
105.8800 56.4489 1.0000
105.9400 55.0510 1.0000
106.0000 43.6284 1.0000
106.0600 51.2430 1.0000
106.1200 47.6494 1.0000
106.1800 53.2436 1.0000
106.2400 55.6378 1.0000
106.3000 61.8792 1.0000
106.3600 64.9581 1.0000
106.4200 58.2340 1.0000
106.4800 52.2402 1.0000
106.5400 52.3259 1.0000
106.6000 57.2322 1.0000
106.6600 59.9385 1.0000
106.7200 54.4428 1.0000
106.7800 40.4067 1.0000
106.8400 46.2040 1.0000
106.9000 37.1511 1.0000
106.9600 48.8954 1.0000
107.0200 56.3045 1.0000
107.0800 49.7938 1.0000
107.1400 55.2321 1.0000
107.2000 47.8162 1.0000
107.2600 55.9620 1.0000
107.3200 61.8960 1.0000
107.3800 39.7476 1.0000
107.4400 52.7229 1.0000
107.5000 55.7071 1.0000
107.5600 44.8761 1.0000
107.6200 51.8499 1.0000
107.6800 58.4640 1.0000
107.7400 44.0382 1.0000
107.8000 39.9388 1.0000
107.8600 39.6992 1.0000
107.9200 43.3630 1.0000
107.9800 52.5544 1.0000
108.0400 37.5923 1.0000
108.1000 56.7356 1.0000
108.1600 47.2841 1.0000
108.2200 58.9585 1.0000
108.2800 46.0326 1.0000
108.3400 42.7056 1.0000
108.4000 48.5937 1.0000
108.4600 48.0846 1.0000
108.5200 50.8162 1.0000
108.5800 44.1193 1.0000
108.6400 44.3294 1.0000
108.7000 53.5210 1.0000
108.7600 49.4923 1.0000
108.8200 53.1026 1.0000
108.8800 56.5098 1.0000
108.9400 49.4637 1.0000
109.0000 49.8487 1.0000
109.0600 58.8809 1.0000
109.1200 59.4541 1.0000
109.1800 41.3393 1.0000
109.2400 45.5123 1.0000
109.3000 50.5929 1.0000
109.3600 52.5181 1.0000
109.4200 53.3240 1.0000
109.4800 40.2065 1.0000
109.5400 52.2578 1.0000
109.6000 39.8381 1.0000
109.6600 57.7568 1.0000
109.7200 44.8008 1.0000
109.7800 53.3871 1.0000
109.8400 54.0214 1.0000
109.9000 52.6708 1.0000
109.9600 46.4017 1.0000
110.0200 38.9472 1.0000
110.0800 54.6715 1.0000
110.1400 58.7383 1.0000
110.2000 54.1140 1.0000
110.2600 44.7294 1.0000
110.3200 44.8391 1.0000
110.3800 59.0215 1.0000
110.4400 54.5200 1.0000
110.5000 55.1215 1.0000
110.5600 43.1112 1.0000
110.6200 53.8144 1.0000
110.6800 50.0687 1.0000
110.7400 41.8281 1.0000
110.8000 49.7782 1.0000
110.8600 42.2461 1.0000
110.9200 44.7302 1.0000
110.9800 60.3936 1.0000
111.0400 41.6443 1.0000
111.1000 52.2326 1.0000
111.1600 49.7504 1.0000
111.2200 55.5718 1.0000
111.2800 55.0158 1.0000
111.3400 52.7629 1.0000
111.4000 55.3352 1.0000
111.4600 28.1784 1.0000
111.5200 41.4392 1.0000
111.5800 40.9862 1.0000
111.6400 43.3261 1.0000
111.7000 43.9671 1.0000
111.7600 48.8194 1.0000
111.8200 61.5582 1.0000
111.8800 38.9709 1.0000
111.9400 59.8345 1.0000
112.0000 50.8456 1.0000
112.0600 53.4235 1.0000
112.1200 54.0636 1.0000
112.1800 50.3394 1.0000
112.2400 52.9266 1.0000
112.3000 50.4780 1.0000
112.3600 45.9380 1.0000
112.4200 43.9025 1.0000
112.4800 48.5401 1.0000
112.5400 46.8950 1.0000
112.6000 48.2462 1.0000
112.6600 55.4037 1.0000
112.7200 47.3640 1.0000
112.7800 71.8535 1.0000
112.8400 54.2468 1.0000
112.9000 61.1731 1.0000
112.9600 49.8604 1.0000
113.0200 47.1601 1.0000
113.0800 41.1303 1.0000
113.1400 56.8667 1.0000
113.2000 52.4199 1.0000
113.2600 68.4067 1.0000
113.3200 58.5360 1.0000
113.3800 44.2839 1.0000
113.4400 49.1740 1.0000
113.5000 39.3456 1.0000
113.5600 45.8277 1.0000
113.6200 54.7827 1.0000
113.6800 58.7175 1.0000
113.7400 45.5127 1.0000
113.8000 51.5608 1.0000
113.8600 40.8547 1.0000
113.9200 56.5516 1.0000
113.9800 42.9661 1.0000
114.0400 42.3071 1.0000
114.1000 49.2953 1.0000
114.1600 52.2379 1.0000
114.2200 54.4428 1.0000
114.2800 43.4350 1.0000
114.3400 49.1865 1.0000
114.4000 61.1900 1.0000
114.4600 48.0478 1.0000
114.5200 53.4397 1.0000
114.5800 60.0446 1.0000
114.6400 58.2854 1.0000
114.7000 52.5172 1.0000
114.7600 47.6779 1.0000
114.8200 61.3024 1.0000
114.8800 43.4194 1.0000
114.9400 55.0868 1.0000
115.0000 63.1872 1.0000
115.0600 53.6643 1.0000
115.1200 51.4857 1.0000
115.1800 47.9259 1.0000
115.2400 56.9955 1.0000
115.3000 64.0462 1.0000
115.3600 53.1708 1.0000
115.4200 61.8748 1.0000
115.4800 53.8376 1.0000
115.5400 45.5538 1.0000
115.6000 43.7728 1.0000
115.6600 45.3272 1.0000
115.7200 49.7148 1.0000
115.7800 58.0651 1.0000
115.8400 51.8406 1.0000
115.9000 58.3524 1.0000
115.9600 54.3796 1.0000
116.0200 55.9774 1.0000
116.0800 44.1901 1.0000
116.1400 62.1064 1.0000
116.2000 54.8378 1.0000
116.2600 45.6415 1.0000
116.3200 47.7190 1.0000
116.3800 45.9842 1.0000
116.4400 43.7666 1.0000
116.5000 53.5668 1.0000
116.5600 61.2112 1.0000
116.6200 55.6481 1.0000
116.6800 54.0019 1.0000
116.7400 57.1654 1.0000
116.8000 49.1465 1.0000
116.8600 56.3956 1.0000
116.9200 58.0140 1.0000
116.9800 62.6390 1.0000
117.0400 50.3528 1.0000
117.1000 43.9813 1.0000
117.1600 51.9187 1.0000
117.2200 58.4678 1.0000
117.2800 48.6284 1.0000
117.3400 46.4321 1.0000
117.4000 64.0162 1.0000
117.4600 47.7346 1.0000
117.5200 44.0215 1.0000
117.5800 60.2207 1.0000
117.6400 53.7343 1.0000
117.7000 47.7117 1.0000
117.7600 44.4022 1.0000
117.8200 63.6185 1.0000
117.8800 56.5730 1.0000
117.9400 57.1006 1.0000
118.0000 58.1997 1.0000
118.0600 52.4443 1.0000
118.1200 59.0866 1.0000
118.1800 47.2578 1.0000
118.2400 56.0414 1.0000
118.3000 50.5081 1.0000
118.3600 55.5805 1.0000
118.4200 53.0677 1.0000
118.4800 64.0295 1.0000
118.5400 51.6487 1.0000
118.6000 55.4850 1.0000
118.6600 55.1779 1.0000
118.7200 49.5527 1.0000
118.7800 66.7065 1.0000
118.8400 57.1400 1.0000
118.9000 53.7083 1.0000
118.9600 64.6764 1.0000
119.0200 46.5519 1.0000
119.0800 51.9464 1.0000
119.1400 57.0413 1.0000
119.2000 60.3994 1.0000
119.2600 65.8891 1.0000
119.3200 60.2471 1.0000
119.3800 50.2543 1.0000
119.4400 63.0921 1.0000
119.5000 69.8688 1.0000
119.5600 56.8263 1.0000
119.6200 70.8027 1.0000
119.6800 49.8692 1.0000
119.7400 54.2797 1.0000
119.8000 39.9814 1.0000
119.8600 40.8132 1.0000
119.9200 60.6776 1.0000
119.9800 41.4743 1.0000
119.9900 77.8990 1.0000
*RAS_INT_END
*RAS_TEMPERATURE_START
*RAS_TEMPERATURE_END
*RAS_DATA_END