File: XRD/May_2022/EFRW4_Unirradiated_regions/PB_Ge220_5SS_500umDS_RS1_Rod_5SS_Hypix1D_EFRW4_FZ_P-irradiated.ras
*RAS_DATA_START
*RAS_HEADER_START
*DISP_FMT_X "%.3f"
*DISP_FMT_Y "%.0f"
*DISP_FULLSCALE "704.8288834890"
*DISP_LINE_COLOR "255.0000000000"
*DISP_LINE_STYLE "0.0000000000"
*DISP_LINE_WIDTH "0.2500000000"
*DISP_NOTE "Collected Data-17"
*DISP_OFFSET_Y "0.0000000000"
*DISP_PEAKSEARCH_UNIT_Y "cps"
*DISP_RANGE_BOTTOM "0.0000000000"
*DISP_RANGE_LEFT "40.0000000000"
*DISP_RANGE_LOGCUTOFF "0.0100000000"
*DISP_RANGE_RIGHT "119.9968000000"
*DISP_RANGE_TOP "704.8288834890"
*DISP_SCALE_MODE_Y "0.0000000000"
*DISP_TAB_NAME "Theta/2-Theta"
*DISP_TITLE_Y "Intensity"
*DISP_UNIT_Y "cps"
*DISP_WINDOW_NAME "MSG_MACROENGINE"
*FILE_COMMENT " "
*FILE_MD5 ""
*FILE_MEMO " "
*FILE_OPERATOR "Administrator"
*FILE_PART_ID "MEAS_KHP2_00061"
*FILE_SAMPLE " "
*FILE_TYPE "RAS_RAW"
*FILE_USERGROUP "System Manager"
*FILE_VERSION "1.0000000000"
*HW_ATTACHMENT_ID "ATT0021"
*HW_ATTACHMENT_NAME "XY-20mm|XY-20mm"
*HW_COUNTER_ID-0 "CUT0041"
*HW_COUNTER_ID-1 "CUT0051"
*HW_COUNTER_ID-2 "CUT0020"
*HW_COUNTER_ID-3 "CSL0021"
*HW_COUNTER_ID-4 "CMC0021"
*HW_COUNTER_NAME-0 "D/teX Ultra 250|D/teX Ultra 250"
*HW_COUNTER_NAME-1 "HyPix 3000(H)|HyPix 3000(H)"
*HW_COUNTER_NAME-2 "None|None"
*HW_COUNTER_NAME-3 "BBM|BBM"
*HW_COUNTER_NAME-4 "検出器モノクロメータ|Detector monochromator"
*HW_COUNTER_SELECT_NAME "HyPix 3000(H)|HyPix 3000(H)"
*HW_GONIOMETER_ID "GON0024"
*HW_GONIOMETER_NAME "SmartLab(In-plane)|SmartLab(In-plane)"
*HW_GONIOMETER_RADIUS-0 "90.0"
*HW_GONIOMETER_RADIUS-1 "114.0"
*HW_GONIOMETER_RADIUS-2 "190.0"
*HW_GONIOMETER_RADIUS-3 "300.0"
*HW_GONIOMETER_RADIUS-4 "187.0"
*HW_GONIOMETER_RADIUS-5 "300.0"
*HW_GONIOMETER_RADIUS-6 "113.0"
*HW_GONIOMETER_RADIUS-7 "331.0"
*HW_I_OPT_ID-0 "CBO0021"
*HW_I_OPT_ID-1 "ICR0021"
*HW_I_OPT_ID-2 "ISL0021"
*HW_I_OPT_ID-3 "ISO0021"
*HW_I_OPT_ID-4 "IAD0021"
*HW_I_OPT_ID-5 "IPR0001"
*HW_I_OPT_NAME-0 "CBOユニット|CBO unit"
*HW_I_OPT_NAME-1 "標準入射光学ユニット|Standard incident optical unit"
*HW_I_OPT_NAME-2 "標準入射スリットボックス|Standard incident slit box"
*HW_I_OPT_NAME-3 "入射平行スリット|Incident parallel slit"
*HW_I_OPT_NAME-4 "長手制限スリット|Length limiting slit"
*HW_I_OPT_NAME-5 "None|None"
*HW_R_ATTENUATER_AUTOMODE "0"
*HW_R_OPT_ID-0 "RSS0022"
*HW_R_OPT_ID-1 "RCR0022"
*HW_R_OPT_ID-2 "RSO0021"
*HW_R_OPT_ID-3 "RRS0022"
*HW_R_OPT_ID-4 "ATN0020"
*HW_R_OPT_ID-5 "RFL0021"
*HW_R_OPT_ID-6 "RAD0021"
*HW_R_OPT_NAME-0 "受光スリットボックス1(Zr軸付)|Receiving slit box # 1 (w/ Zr Axis)"
*HW_R_OPT_NAME-1 "標準受光光学ユニット1|Standard receiving unit # 1"
*HW_R_OPT_NAME-2 "標準受光光学ユニット2|Standard receiving optical unit # 2"
*HW_R_OPT_NAME-3 "仮想受光スリット2|Virtual receiving slit #2"
*HW_R_OPT_NAME-4 "無し|None"
*HW_R_OPT_NAME-5 "Cu Kβ|Cu K-beta"
*HW_R_OPT_NAME-6 "調整用受光スリット|Alignment receiving slit"
*HW_SAMPLE_HOLDER_ID "SMP0021"
*HW_SAMPLE_HOLDER_NAME "χφZクレードル|Chi phi Z cradle"
*HW_XG_CURRENT_MAX "40"
*HW_XG_CURRENT_MIN "2"
*HW_XG_CURRENT_RESOLUTION "1"
*HW_XG_CURRENT_UNIT "mA"
*HW_XG_FOCUS "0.4mm x 8mm"
*HW_XG_FOCUS_TYPE "Fine"
*HW_XG_ID "1200"
*HW_XG_NAME "3kW 封入管(ID:1200)|3kW Sealed tube(ID:1200)"
*HW_XG_TARGET_ATOMIC_NUMBER "29.0000000000"
*HW_XG_TARGET_NAME "Cu"
*HW_XG_TYPE "Hermetic"
*HW_XG_VOLTAGE_MAX "40"
*HW_XG_VOLTAGE_MIN "20"
*HW_XG_VOLTAGE_RESOLUTION "1"
*HW_XG_VOLTAGE_UNIT "kV"
*HW_XG_WATT_MAX "1.500"
*HW_XG_WATT_UNIT "kW"
*HW_XG_WAVE_LENGTH_ALPHA1 "1.540593"
*HW_XG_WAVE_LENGTH_ALPHA2 "1.544414"
*HW_XG_WAVE_LENGTH_BETA "1.392250"
*MEAS_COND_AXIS_NAME-0 "Theta/2-Theta"
*MEAS_COND_AXIS_NAME-1 "2-Theta"
*MEAS_COND_AXIS_NAME-2 "Omega"
*MEAS_COND_AXIS_NAME-3 "Chi"
*MEAS_COND_AXIS_NAME-4 "Phi"
*MEAS_COND_AXIS_NAME-5 "Z"
*MEAS_COND_AXIS_NAME-6 "X"
*MEAS_COND_AXIS_NAME-7 "Y"
*MEAS_COND_AXIS_NAME-8 "2-Theta/Omega"
*MEAS_COND_AXIS_NAME-9 "2-ThetaChi"
*MEAS_COND_AXIS_NAME-10 "2-ThetaChi/Phi"
*MEAS_COND_AXIS_NAME-11 "Alpha"
*MEAS_COND_AXIS_NAME-12 "Beta"
*MEAS_COND_AXIS_NAME-13 "Theta_s"
*MEAS_COND_AXIS_NAME-14 "Theta_d"
*MEAS_COND_AXIS_NAME-15 "Ts"
*MEAS_COND_AXIS_NAME-16 "CBO selection slit"
*MEAS_COND_AXIS_NAME-17 "M"
*MEAS_COND_AXIS_NAME-18 "Incident parallel slit"
*MEAS_COND_AXIS_NAME-19 "Incident slit"
*MEAS_COND_AXIS_NAME-20 ""
*MEAS_COND_AXIS_NAME-21 "Zs"
*MEAS_COND_AXIS_NAME-22 "Incident optical device"
*MEAS_COND_AXIS_NAME-23 "Omega_m"
*MEAS_COND_AXIS_NAME-24 "Length limiting slit"
*MEAS_COND_AXIS_NAME-25 "Center slit"
*MEAS_COND_AXIS_NAME-26 "Filter"
*MEAS_COND_AXIS_NAME-27 "Receiving slit # 1"
*MEAS_COND_AXIS_NAME-28 "Receiving slit # 2"
*MEAS_COND_AXIS_NAME-29 "Receiving optical device"
*MEAS_COND_AXIS_NAME-30 "Receiving parallel slit"
*MEAS_COND_AXIS_NAME-31 "Alignment receiving slit"
*MEAS_COND_AXIS_NAME-32 ""
*MEAS_COND_AXIS_NAME-33 ""
*MEAS_COND_AXIS_NAME-34 "Zd"
*MEAS_COND_AXIS_NAME-35 "Attenuator"
*MEAS_COND_AXIS_NAME-36 "Diffracted beam monochromator"
*MEAS_COND_AXIS_NAME-37 "Monochromator slit"
*MEAS_COND_AXIS_NAME-38 "2-ThetaB"
*MEAS_COND_AXIS_NAME-39 ""
*MEAS_COND_AXIS_NAME-40 ""
*MEAS_COND_AXIS_NAME-41 "Zr"
*MEAS_COND_AXIS_NAME-42 "Primary beam"
*MEAS_COND_AXIS_NAME_INTERNAL-0 "TwoThetaTheta"
*MEAS_COND_AXIS_NAME_INTERNAL-1 "TwoTheta"
*MEAS_COND_AXIS_NAME_INTERNAL-2 "Omega"
*MEAS_COND_AXIS_NAME_INTERNAL-3 "Chi"
*MEAS_COND_AXIS_NAME_INTERNAL-4 "Phi"
*MEAS_COND_AXIS_NAME_INTERNAL-5 "Z"
*MEAS_COND_AXIS_NAME_INTERNAL-6 "X"
*MEAS_COND_AXIS_NAME_INTERNAL-7 "Y"
*MEAS_COND_AXIS_NAME_INTERNAL-8 "TwoThetaOmega"
*MEAS_COND_AXIS_NAME_INTERNAL-9 "TwoThetaChi"
*MEAS_COND_AXIS_NAME_INTERNAL-10 "TwoThetaChiPhi"
*MEAS_COND_AXIS_NAME_INTERNAL-11 "Alpha"
*MEAS_COND_AXIS_NAME_INTERNAL-12 "Beta"
*MEAS_COND_AXIS_NAME_INTERNAL-13 "ThetaS"
*MEAS_COND_AXIS_NAME_INTERNAL-14 "ThetaD"
*MEAS_COND_AXIS_NAME_INTERNAL-15 "Ts"
*MEAS_COND_AXIS_NAME_INTERNAL-16 "CBO"
*MEAS_COND_AXIS_NAME_INTERNAL-17 "CBO-M"
*MEAS_COND_AXIS_NAME_INTERNAL-18 "IncidentSollerSlit"
*MEAS_COND_AXIS_NAME_INTERNAL-19 "IncidentSlitBox"
*MEAS_COND_AXIS_NAME_INTERNAL-20 "IncidentSlitBox-_Axis"
*MEAS_COND_AXIS_NAME_INTERNAL-21 "Zs"
*MEAS_COND_AXIS_NAME_INTERNAL-22 "IncidentMonochromator"
*MEAS_COND_AXIS_NAME_INTERNAL-23 "IncidentMonochromator-OmegaM"
*MEAS_COND_AXIS_NAME_INTERNAL-24 "IncidentAxdSlit"
*MEAS_COND_AXIS_NAME_INTERNAL-25 "CenterSlit"
*MEAS_COND_AXIS_NAME_INTERNAL-26 "Filter"
*MEAS_COND_AXIS_NAME_INTERNAL-27 "ReceivingSlitBox1"
*MEAS_COND_AXIS_NAME_INTERNAL-28 "ReceivingSlitBox2"
*MEAS_COND_AXIS_NAME_INTERNAL-29 "ReceivingOptics"
*MEAS_COND_AXIS_NAME_INTERNAL-30 "ReceivingSollerSlit"
*MEAS_COND_AXIS_NAME_INTERNAL-31 "ReceivingAxdSlit"
*MEAS_COND_AXIS_NAME_INTERNAL-32 "ReceivingSlitBox1-_Axis"
*MEAS_COND_AXIS_NAME_INTERNAL-33 "ReceivingSlitBox2-_Axis"
*MEAS_COND_AXIS_NAME_INTERNAL-34 "ReceivingSlitBox2-Zd"
*MEAS_COND_AXIS_NAME_INTERNAL-35 "Attenuator"
*MEAS_COND_AXIS_NAME_INTERNAL-36 "CounterMonochromator"
*MEAS_COND_AXIS_NAME_INTERNAL-37 "CounterSlit"
*MEAS_COND_AXIS_NAME_INTERNAL-38 "TwoThetaB"
*MEAS_COND_AXIS_NAME_INTERNAL-39 "AlphaR"
*MEAS_COND_AXIS_NAME_INTERNAL-40 "BetaR"
*MEAS_COND_AXIS_NAME_INTERNAL-41 "ReceivingSlitBox1-Zr"
*MEAS_COND_AXIS_NAME_INTERNAL-42 "IncidentPrimary"
*MEAS_COND_AXIS_NAME_MAGICNO-0 "83951616.0000000000"
*MEAS_COND_AXIS_NAME_MAGICNO-1 "268632064.0000000000"
*MEAS_COND_AXIS_NAME_MAGICNO-2 "268500992.0000000000"
*MEAS_COND_AXIS_NAME_MAGICNO-3 "268500992.0000000000"
*MEAS_COND_AXIS_NAME_MAGICNO-4 "268500992.0000000000"
*MEAS_COND_AXIS_NAME_MAGICNO-5 "285278208.0000000000"
*MEAS_COND_AXIS_NAME_MAGICNO-6 "268500992.0000000000"
*MEAS_COND_AXIS_NAME_MAGICNO-7 "268500992.0000000000"
*MEAS_COND_AXIS_NAME_MAGICNO-8 "83951616.0000000000"
*MEAS_COND_AXIS_NAME_MAGICNO-9 "268632064.0000000000"
*MEAS_COND_AXIS_NAME_MAGICNO-10 "83951616.0000000000"
*MEAS_COND_AXIS_NAME_MAGICNO-11 "17039360.0000000000"
*MEAS_COND_AXIS_NAME_MAGICNO-12 "17039360.0000000000"
*MEAS_COND_AXIS_NAME_MAGICNO-13 "131072.0000000000"
*MEAS_COND_AXIS_NAME_MAGICNO-14 "131072.0000000000"
*MEAS_COND_AXIS_NAME_MAGICNO-15 "318898176.0000000000"
*MEAS_COND_AXIS_NAME_MAGICNO-16 "20971521.0000000000"
*MEAS_COND_AXIS_NAME_MAGICNO-17 "285343744.0000000000"
*MEAS_COND_AXIS_NAME_MAGICNO-18 "20971521.0000000000"
*MEAS_COND_AXIS_NAME_MAGICNO-19 "22020097.0000000000"
*MEAS_COND_AXIS_NAME_MAGICNO-20 "25165824.0000000000"
*MEAS_COND_AXIS_NAME_MAGICNO-21 "318898176.0000000000"
*MEAS_COND_AXIS_NAME_MAGICNO-22 "20971521.0000000000"
*MEAS_COND_AXIS_NAME_MAGICNO-23 "285343744.0000000000"
*MEAS_COND_AXIS_NAME_MAGICNO-24 "20971521.0000000000"
*MEAS_COND_AXIS_NAME_MAGICNO-25 "20971521.0000000000"
*MEAS_COND_AXIS_NAME_MAGICNO-26 "20971521.0000000000"
*MEAS_COND_AXIS_NAME_MAGICNO-27 "23068673.0000000000"
*MEAS_COND_AXIS_NAME_MAGICNO-28 "23068673.0000000000"
*MEAS_COND_AXIS_NAME_MAGICNO-29 "20971521.0000000000"
*MEAS_COND_AXIS_NAME_MAGICNO-30 "20971521.0000000000"
*MEAS_COND_AXIS_NAME_MAGICNO-31 "20971521.0000000000"
*MEAS_COND_AXIS_NAME_MAGICNO-32 "25165824.0000000000"
*MEAS_COND_AXIS_NAME_MAGICNO-33 "25165824.0000000000"
*MEAS_COND_AXIS_NAME_MAGICNO-34 "285343744.0000000000"
*MEAS_COND_AXIS_NAME_MAGICNO-35 "0.0000000000"
*MEAS_COND_AXIS_NAME_MAGICNO-36 "20971521.0000000000"
*MEAS_COND_AXIS_NAME_MAGICNO-37 "20971521.0000000000"
*MEAS_COND_AXIS_NAME_MAGICNO-38 "17039360.0000000000"
*MEAS_COND_AXIS_NAME_MAGICNO-39 "8388608.0000000000"
*MEAS_COND_AXIS_NAME_MAGICNO-40 "8388608.0000000000"
*MEAS_COND_AXIS_NAME_MAGICNO-41 "285343744.0000000000"
*MEAS_COND_AXIS_NAME_MAGICNO-42 "20971521.0000000000"
*MEAS_COND_AXIS_OFFSET-0 "-"
*MEAS_COND_AXIS_OFFSET-1 "0.0000000000"
*MEAS_COND_AXIS_OFFSET-2 "0.0000000000"
*MEAS_COND_AXIS_OFFSET-3 "0.0000000000"
*MEAS_COND_AXIS_OFFSET-4 "0.0000000000"
*MEAS_COND_AXIS_OFFSET-5 "-"
*MEAS_COND_AXIS_OFFSET-6 "0.0000000000"
*MEAS_COND_AXIS_OFFSET-7 "0.0000000000"
*MEAS_COND_AXIS_OFFSET-8 "-"
*MEAS_COND_AXIS_OFFSET-9 "0.0000000000"
*MEAS_COND_AXIS_OFFSET-10 "-"
*MEAS_COND_AXIS_OFFSET-11 "-"
*MEAS_COND_AXIS_OFFSET-12 "-"
*MEAS_COND_AXIS_OFFSET-13 "0.0000000000"
*MEAS_COND_AXIS_OFFSET-14 "0.0000000000"
*MEAS_COND_AXIS_OFFSET-15 "-"
*MEAS_COND_AXIS_OFFSET-16 "-"
*MEAS_COND_AXIS_OFFSET-17 "-"
*MEAS_COND_AXIS_OFFSET-18 "-"
*MEAS_COND_AXIS_OFFSET-19 "-"
*MEAS_COND_AXIS_OFFSET-20 "-"
*MEAS_COND_AXIS_OFFSET-21 "-"
*MEAS_COND_AXIS_OFFSET-22 "-"
*MEAS_COND_AXIS_OFFSET-23 "-"
*MEAS_COND_AXIS_OFFSET-24 "-"
*MEAS_COND_AXIS_OFFSET-25 "-"
*MEAS_COND_AXIS_OFFSET-26 "-"
*MEAS_COND_AXIS_OFFSET-27 "-"
*MEAS_COND_AXIS_OFFSET-28 "-"
*MEAS_COND_AXIS_OFFSET-29 "-"
*MEAS_COND_AXIS_OFFSET-30 "-"
*MEAS_COND_AXIS_OFFSET-31 "-"
*MEAS_COND_AXIS_OFFSET-32 "-"
*MEAS_COND_AXIS_OFFSET-33 "-"
*MEAS_COND_AXIS_OFFSET-34 "-"
*MEAS_COND_AXIS_OFFSET-35 "-"
*MEAS_COND_AXIS_OFFSET-36 "-"
*MEAS_COND_AXIS_OFFSET-37 "-"
*MEAS_COND_AXIS_OFFSET-38 "-"
*MEAS_COND_AXIS_OFFSET-39 "0.0000000000"
*MEAS_COND_AXIS_OFFSET-40 "0.0000000000"
*MEAS_COND_AXIS_OFFSET-41 "-"
*MEAS_COND_AXIS_OFFSET-42 "-"
*MEAS_COND_AXIS_POSITION-0 "40.0000000000"
*MEAS_COND_AXIS_POSITION-1 "40.0000000000"
*MEAS_COND_AXIS_POSITION-2 "20.0000000000"
*MEAS_COND_AXIS_POSITION-3 "0.0000000000"
*MEAS_COND_AXIS_POSITION-4 "0.0000000000"
*MEAS_COND_AXIS_POSITION-5 "-2.1742000000"
*MEAS_COND_AXIS_POSITION-6 "3.4515000000"
*MEAS_COND_AXIS_POSITION-7 "1.4865000000"
*MEAS_COND_AXIS_POSITION-8 "40.0000000000"
*MEAS_COND_AXIS_POSITION-9 "0.0000000000"
*MEAS_COND_AXIS_POSITION-10 "0.0000000000"
*MEAS_COND_AXIS_POSITION-11 "90.0000000000"
*MEAS_COND_AXIS_POSITION-12 "0.0000000000"
*MEAS_COND_AXIS_POSITION-13 "20.0000000000"
*MEAS_COND_AXIS_POSITION-14 "20.0000000000"
*MEAS_COND_AXIS_POSITION-15 "-5.5000000000"
*MEAS_COND_AXIS_POSITION-16 "PB"
*MEAS_COND_AXIS_POSITION-17 "0.0000000000"
*MEAS_COND_AXIS_POSITION-18 "Soller_slit_5.0deg_s"
*MEAS_COND_AXIS_POSITION-19 "1.000mm"
*MEAS_COND_AXIS_POSITION-20 "1.0000000000"
*MEAS_COND_AXIS_POSITION-21 "-1.5000000000"
*MEAS_COND_AXIS_POSITION-22 "Ge(220)x2"
*MEAS_COND_AXIS_POSITION-23 "0.0000000000"
*MEAS_COND_AXIS_POSITION-24 "0.5mm"
*MEAS_COND_AXIS_POSITION-25 "None"
*MEAS_COND_AXIS_POSITION-26 "None"
*MEAS_COND_AXIS_POSITION-27 "20.000mm"
*MEAS_COND_AXIS_POSITION-28 "38.500mm"
*MEAS_COND_AXIS_POSITION-29 "PSA_open"
*MEAS_COND_AXIS_POSITION-30 "Soller_slit_5.0deg"
*MEAS_COND_AXIS_POSITION-31 "None"
*MEAS_COND_AXIS_POSITION-32 "20.0000000000"
*MEAS_COND_AXIS_POSITION-33 "38.5000000000"
*MEAS_COND_AXIS_POSITION-34 "0.0000000000"
*MEAS_COND_AXIS_POSITION-35 "-"
*MEAS_COND_AXIS_POSITION-36 "No_unit"
*MEAS_COND_AXIS_POSITION-37 "None"
*MEAS_COND_AXIS_POSITION-38 "40.0000000000"
*MEAS_COND_AXIS_POSITION-39 "0.0000000000"
*MEAS_COND_AXIS_POSITION-40 "0.0000000000"
*MEAS_COND_AXIS_POSITION-41 "0.0000000000"
*MEAS_COND_AXIS_POSITION-42 "None"
*MEAS_COND_AXIS_UNIT-0 "deg"
*MEAS_COND_AXIS_UNIT-1 "deg"
*MEAS_COND_AXIS_UNIT-2 "deg"
*MEAS_COND_AXIS_UNIT-3 "deg"
*MEAS_COND_AXIS_UNIT-4 "deg"
*MEAS_COND_AXIS_UNIT-5 "mm"
*MEAS_COND_AXIS_UNIT-6 "mm"
*MEAS_COND_AXIS_UNIT-7 "mm"
*MEAS_COND_AXIS_UNIT-8 "deg"
*MEAS_COND_AXIS_UNIT-9 "deg"
*MEAS_COND_AXIS_UNIT-10 "deg"
*MEAS_COND_AXIS_UNIT-11 "deg"
*MEAS_COND_AXIS_UNIT-12 "deg"
*MEAS_COND_AXIS_UNIT-13 "deg"
*MEAS_COND_AXIS_UNIT-14 "deg"
*MEAS_COND_AXIS_UNIT-15 "mm"
*MEAS_COND_AXIS_UNIT-16 ""
*MEAS_COND_AXIS_UNIT-17 "pulse"
*MEAS_COND_AXIS_UNIT-18 ""
*MEAS_COND_AXIS_UNIT-19 ""
*MEAS_COND_AXIS_UNIT-20 "mm"
*MEAS_COND_AXIS_UNIT-21 "mm"
*MEAS_COND_AXIS_UNIT-22 ""
*MEAS_COND_AXIS_UNIT-23 "pulse"
*MEAS_COND_AXIS_UNIT-24 ""
*MEAS_COND_AXIS_UNIT-25 ""
*MEAS_COND_AXIS_UNIT-26 ""
*MEAS_COND_AXIS_UNIT-27 ""
*MEAS_COND_AXIS_UNIT-28 ""
*MEAS_COND_AXIS_UNIT-29 ""
*MEAS_COND_AXIS_UNIT-30 ""
*MEAS_COND_AXIS_UNIT-31 ""
*MEAS_COND_AXIS_UNIT-32 "mm"
*MEAS_COND_AXIS_UNIT-33 "mm"
*MEAS_COND_AXIS_UNIT-34 "mm"
*MEAS_COND_AXIS_UNIT-35 ""
*MEAS_COND_AXIS_UNIT-36 ""
*MEAS_COND_AXIS_UNIT-37 ""
*MEAS_COND_AXIS_UNIT-38 "deg"
*MEAS_COND_AXIS_UNIT-39 "deg"
*MEAS_COND_AXIS_UNIT-40 "deg"
*MEAS_COND_AXIS_UNIT-41 "mm"
*MEAS_COND_AXIS_UNIT-42 ""
*MEAS_COND_COUNTER_CNTLOSS_CORR "0.0000000000"
*MEAS_COND_COUNTER_TAUDIFF "0.0000000000"
*MEAS_COND_COUNTER_TAUINT "0.0000000000"
*MEAS_COND_COUNTER_TEMP_CONDITION "NORMAL"
*MEAS_COND_IRRADIATION_MODE "OFF"
*MEAS_COND_IRRADIATION_WIDTH ""
*MEAS_COND_OPT_ATTR "High resolution parallel beam Ge(220)x2/RS"
*MEAS_COND_OPT_NAME "@High resolution PB-Ge(220)x2"
*MEAS_COND_UNSYMMETRIC_MODE "OFF"
*MEAS_COND_XG_CURRENT "30.0000000000"
*MEAS_COND_XG_VOLTAGE "40.0000000000"
*MEAS_COND_XG_WAVE_TYPE "Ka1"
*MEAS_DATA_COUNT "8000.0000000000"
*MEAS_SCAN_AXIS_X "Theta/2-Theta"
*MEAS_SCAN_AXIS_X_INTERNAL "TwoThetaTheta"
*MEAS_SCAN_END_TIME "04/29/22 14:56:27"
*MEAS_SCAN_MODE "CONTINUOUS"
*MEAS_SCAN_MONITOR "0"
*MEAS_SCAN_RESOLUTION_X "0.0002"
*MEAS_SCAN_SPEED "0.503240"
*MEAS_SCAN_SPEED_UNIT "deg/min"
*MEAS_SCAN_SPEED_USER "0.5"
*MEAS_SCAN_START "40.0000000000"
*MEAS_SCAN_START_TIME "04/29/22 12:01:37"
*MEAS_SCAN_STEP "0.0100000000"
*MEAS_SCAN_STOP "119.9900000000"
*MEAS_SCAN_UNIT_X "deg"
*MEAS_SCAN_UNIT_Y "counts"
*RAS_HEADER_END
*RAS_INT_START
40.0000 8.6750 1.0000
40.0600 13.3804 1.0000
40.1200 5.5301 1.0000
40.1800 6.2394 1.0000
40.2400 12.7900 1.0000
40.3000 11.7552 1.0000
40.3600 8.6893 1.0000
40.4200 13.0464 1.0000
40.4800 14.7510 1.0000
40.5400 12.1281 1.0000
40.6000 12.1384 1.0000
40.6600 7.5871 1.0000
40.7200 9.0974 1.0000
40.7800 6.9465 1.0000
40.8400 7.1643 1.0000
40.9000 8.3257 1.0000
40.9600 13.5578 1.0000
41.0200 5.7027 1.0000
41.0800 11.7957 1.0000
41.1400 11.0819 1.0000
41.2000 7.7789 1.0000
41.2600 9.1257 1.0000
41.3200 10.5380 1.0000
41.3800 10.5808 1.0000
41.4400 11.0712 1.0000
41.5000 7.9022 1.0000
41.5600 9.3834 1.0000
41.6200 10.5573 1.0000
41.6800 11.7343 1.0000
41.7400 12.4019 1.0000
41.8000 9.1371 1.0000
41.8600 7.5654 1.0000
41.9200 5.5800 1.0000
41.9800 10.1674 1.0000
42.0400 11.9618 1.0000
42.1000 6.1025 1.0000
42.1600 10.2325 1.0000
42.2200 16.1455 1.0000
42.2800 7.7087 1.0000
42.3400 7.8433 1.0000
42.4000 12.2381 1.0000
42.4600 5.1874 1.0000
42.5200 7.4866 1.0000
42.5800 11.3515 1.0000
42.6400 11.1873 1.0000
42.7000 8.5891 1.0000
42.7600 7.6030 1.0000
42.8200 7.5298 1.0000
42.8800 3.6097 1.0000
42.9400 9.0313 1.0000
43.0000 14.8718 1.0000
43.0600 12.2129 1.0000
43.1200 9.1532 1.0000
43.1800 8.9089 1.0000
43.2400 12.3959 1.0000
43.3000 12.2650 1.0000
43.3600 14.2926 1.0000
43.4200 9.3860 1.0000
43.4800 11.4946 1.0000
43.5400 12.1443 1.0000
43.6000 9.8961 1.0000
43.6600 7.7736 1.0000
43.7200 8.6752 1.0000
43.7800 8.6062 1.0000
43.8400 8.2315 1.0000
43.9000 10.4120 1.0000
43.9600 12.9826 1.0000
44.0200 8.9026 1.0000
44.0800 10.0139 1.0000
44.1400 11.1610 1.0000
44.2000 4.0111 1.0000
44.2600 5.1257 1.0000
44.3200 8.7821 1.0000
44.3800 10.6493 1.0000
44.4400 10.0684 1.0000
44.5000 5.9479 1.0000
44.5600 12.3027 1.0000
44.6200 11.9854 1.0000
44.6800 8.5582 1.0000
44.7400 7.1974 1.0000
44.8000 13.9860 1.0000
44.8600 17.1517 1.0000
44.9200 10.2175 1.0000
44.9800 9.0772 1.0000
45.0400 11.1397 1.0000
45.1000 6.5849 1.0000
45.1600 15.6018 1.0000
45.2200 14.4309 1.0000
45.2800 21.5923 1.0000
45.3400 22.0281 1.0000
45.4000 66.2683 1.0000
45.4600 260.9359 1.0000
45.5200 615.8953 1.0000
45.5800 453.9673 1.0000
45.6400 136.7016 1.0000
45.7000 36.7739 1.0000
45.7600 24.4127 1.0000
45.8200 14.3807 1.0000
45.8800 13.1899 1.0000
45.9400 13.2698 1.0000
46.0000 8.0780 1.0000
46.0600 9.7983 1.0000
46.1200 11.6653 1.0000
46.1800 7.9404 1.0000
46.2400 6.8985 1.0000
46.3000 10.3146 1.0000
46.3600 12.2303 1.0000
46.4200 7.5569 1.0000
46.4800 6.4491 1.0000
46.5400 13.5683 1.0000
46.6000 9.1628 1.0000
46.6600 7.0596 1.0000
46.7200 5.9713 1.0000
46.7800 7.6486 1.0000
46.8400 9.5752 1.0000
46.9000 14.8849 1.0000
46.9600 8.5721 1.0000
47.0200 3.5438 1.0000
47.0800 12.5078 1.0000
47.1400 11.9205 1.0000
47.2000 10.2290 1.0000
47.2600 13.2815 1.0000
47.3200 8.8395 1.0000
47.3800 17.1140 1.0000
47.4400 11.6794 1.0000
47.5000 7.7284 1.0000
47.5600 9.5159 1.0000
47.6200 6.7020 1.0000
47.6800 14.4192 1.0000
47.7400 10.1587 1.0000
47.8000 8.1725 1.0000
47.8600 8.0436 1.0000
47.9200 8.1343 1.0000
47.9800 7.0584 1.0000
48.0400 4.9507 1.0000
48.1000 9.0528 1.0000
48.1600 7.8001 1.0000
48.2200 7.7973 1.0000
48.2800 8.2395 1.0000
48.3400 10.6327 1.0000
48.4000 13.1614 1.0000
48.4600 6.7436 1.0000
48.5200 11.5324 1.0000
48.5800 12.6545 1.0000
48.6400 3.8689 1.0000
48.7000 12.6320 1.0000
48.7600 13.3845 1.0000
48.8200 6.2891 1.0000
48.8800 9.9784 1.0000
48.9400 9.6899 1.0000
49.0000 14.4411 1.0000
49.0600 11.5035 1.0000
49.1200 9.5787 1.0000
49.1800 11.3175 1.0000
49.2400 11.7069 1.0000
49.3000 10.4857 1.0000
49.3600 5.5919 1.0000
49.4200 11.0618 1.0000
49.4800 9.3369 1.0000
49.5400 13.7994 1.0000
49.6000 11.1914 1.0000
49.6600 6.0235 1.0000
49.7200 8.6030 1.0000
49.7800 12.9745 1.0000
49.8400 8.4530 1.0000
49.9000 10.0826 1.0000
49.9600 6.9732 1.0000
50.0200 12.0053 1.0000
50.0800 3.9461 1.0000
50.1400 13.9393 1.0000
50.2000 7.9051 1.0000
50.2600 5.1992 1.0000
50.3200 5.1158 1.0000
50.3800 7.9470 1.0000
50.4400 8.0179 1.0000
50.5000 12.3874 1.0000
50.5600 12.8326 1.0000
50.6200 8.8260 1.0000
50.6800 11.0456 1.0000
50.7400 20.4621 1.0000
50.8000 11.6392 1.0000
50.8600 8.0909 1.0000
50.9200 4.8097 1.0000
50.9800 8.0568 1.0000
51.0400 11.2044 1.0000
51.1000 14.3152 1.0000
51.1600 8.5965 1.0000
51.2200 8.7995 1.0000
51.2800 9.2821 1.0000
51.3400 8.6531 1.0000
51.4000 3.5382 1.0000
51.4600 9.6873 1.0000
51.5200 10.6688 1.0000
51.5800 12.5806 1.0000
51.6400 10.5144 1.0000
51.7000 18.0827 1.0000
51.7600 13.5570 1.0000
51.8200 6.6498 1.0000
51.8800 11.8816 1.0000
51.9400 5.8220 1.0000
52.0000 7.0531 1.0000
52.0600 6.6959 1.0000
52.1200 7.2302 1.0000
52.1800 5.3804 1.0000
52.2400 11.5273 1.0000
52.3000 10.9183 1.0000
52.3600 5.2538 1.0000
52.4200 5.1665 1.0000
52.4800 6.5761 1.0000
52.5400 5.5363 1.0000
52.6000 6.9560 1.0000
52.6600 9.7698 1.0000
52.7200 7.6132 1.0000
52.7800 6.8538 1.0000
52.8400 9.1175 1.0000
52.9000 12.3723 1.0000
52.9600 4.4028 1.0000
53.0200 10.5517 1.0000
53.0800 11.1258 1.0000
53.1400 7.6030 1.0000
53.2000 11.6247 1.0000
53.2600 6.2701 1.0000
53.3200 6.7224 1.0000
53.3800 4.2483 1.0000
53.4400 8.5633 1.0000
53.5000 6.0681 1.0000
53.5600 8.8770 1.0000
53.6200 10.4001 1.0000
53.6800 10.4144 1.0000
53.7400 9.3326 1.0000
53.8000 10.5525 1.0000
53.8600 4.6859 1.0000
53.9200 9.6184 1.0000
53.9800 10.0906 1.0000
54.0400 5.4583 1.0000
54.1000 12.5195 1.0000
54.1600 6.7442 1.0000
54.2200 10.9481 1.0000
54.2800 5.8869 1.0000
54.3400 13.2138 1.0000
54.4000 6.2356 1.0000
54.4600 12.0683 1.0000
54.5200 11.8588 1.0000
54.5800 4.9782 1.0000
54.6400 7.2780 1.0000
54.7000 6.4430 1.0000
54.7600 6.8663 1.0000
54.8200 9.7016 1.0000
54.8800 10.0380 1.0000
54.9400 9.7270 1.0000
55.0000 7.3855 1.0000
55.0600 13.0194 1.0000
55.1200 7.4539 1.0000
55.1800 8.5066 1.0000
55.2400 4.4047 1.0000
55.3000 14.3687 1.0000
55.3600 8.1683 1.0000
55.4200 2.6583 1.0000
55.4800 13.2877 1.0000
55.5400 12.8694 1.0000
55.6000 12.1324 1.0000
55.6600 7.6600 1.0000
55.7200 9.8410 1.0000
55.7800 7.0438 1.0000
55.8400 7.3043 1.0000
55.9000 8.9061 1.0000
55.9600 8.8781 1.0000
56.0200 9.2577 1.0000
56.0800 12.4366 1.0000
56.1400 16.4951 1.0000
56.2000 8.4327 1.0000
56.2600 6.0645 1.0000
56.3200 12.2616 1.0000
56.3800 9.9263 1.0000
56.4400 6.1665 1.0000
56.5000 7.3628 1.0000
56.5600 5.4911 1.0000
56.6200 4.8313 1.0000
56.6800 11.3362 1.0000
56.7400 11.7190 1.0000
56.8000 2.3435 1.0000
56.8600 10.0110 1.0000
56.9200 3.5152 1.0000
56.9800 7.4663 1.0000
57.0400 6.0190 1.0000
57.1000 6.3140 1.0000
57.1600 8.0096 1.0000
57.2200 14.8837 1.0000
57.2800 10.8064 1.0000
57.3400 6.5839 1.0000
57.4000 6.5112 1.0000
57.4600 9.9559 1.0000
57.5200 13.6184 1.0000
57.5800 11.0798 1.0000
57.6400 6.3935 1.0000
57.7000 8.9072 1.0000
57.7600 15.3229 1.0000
57.8200 8.5623 1.0000
57.8800 9.1037 1.0000
57.9400 18.3138 1.0000
58.0000 11.7337 1.0000
58.0600 8.3557 1.0000
58.1200 10.3070 1.0000
58.1800 6.1782 1.0000
58.2400 3.7432 1.0000
58.3000 8.2611 1.0000
58.3600 15.8837 1.0000
58.4200 11.9826 1.0000
58.4800 5.6143 1.0000
58.5400 5.4060 1.0000
58.6000 8.0742 1.0000
58.6600 7.9597 1.0000
58.7200 4.0400 1.0000
58.7800 12.3746 1.0000
58.8400 5.6271 1.0000
58.9000 13.2494 1.0000
58.9600 3.6108 1.0000
59.0200 9.4962 1.0000
59.0800 8.8074 1.0000
59.1400 2.3526 1.0000
59.2000 8.7477 1.0000
59.2600 7.4725 1.0000
59.3200 11.1300 1.0000
59.3800 10.2007 1.0000
59.4400 9.2186 1.0000
59.5000 8.3773 1.0000
59.5600 5.8828 1.0000
59.6200 5.1019 1.0000
59.6800 13.1093 1.0000
59.7400 6.1147 1.0000
59.8000 8.5494 1.0000
59.8600 4.2701 1.0000
59.9200 3.7213 1.0000
59.9800 6.9169 1.0000
60.0400 6.9753 1.0000
60.1000 1.4046 1.0000
60.1600 5.9225 1.0000
60.2200 9.5870 1.0000
60.2800 11.8419 1.0000
60.3400 11.5406 1.0000
60.4000 12.0363 1.0000
60.4600 11.7390 1.0000
60.5200 15.3067 1.0000
60.5800 12.5751 1.0000
60.6400 4.6929 1.0000
60.7000 8.5141 1.0000
60.7600 5.6312 1.0000
60.8200 5.6665 1.0000
60.8800 5.4694 1.0000
60.9400 14.0837 1.0000
61.0000 11.7820 1.0000
61.0600 13.1733 1.0000
61.1200 10.2815 1.0000
61.1800 8.7196 1.0000
61.2400 11.2458 1.0000
61.3000 6.2969 1.0000
61.3600 8.1821 1.0000
61.4200 12.6450 1.0000
61.4800 5.9345 1.0000
61.5400 13.0430 1.0000
61.6000 6.9621 1.0000
61.6600 4.4626 1.0000
61.7200 10.3912 1.0000
61.7800 10.2758 1.0000
61.8400 7.9573 1.0000
61.9000 8.9878 1.0000
61.9600 4.8802 1.0000
62.0200 7.4273 1.0000
62.0800 11.0448 1.0000
62.1400 9.9856 1.0000
62.2000 12.1857 1.0000
62.2600 10.1216 1.0000
62.3200 6.2772 1.0000
62.3800 3.9855 1.0000
62.4400 15.9997 1.0000
62.5000 8.1071 1.0000
62.5600 3.7094 1.0000
62.6200 11.1300 1.0000
62.6800 9.9173 1.0000
62.7400 10.5844 1.0000
62.8000 8.9744 1.0000
62.8600 8.3288 1.0000
62.9200 9.9992 1.0000
62.9800 8.5660 1.0000
63.0400 8.6682 1.0000
63.1000 15.1903 1.0000
63.1600 7.0814 1.0000
63.2200 10.0987 1.0000
63.2800 5.4921 1.0000
63.3400 4.4827 1.0000
63.4000 3.8558 1.0000
63.4600 3.1908 1.0000
63.5200 7.9655 1.0000
63.5800 12.7616 1.0000
63.6400 13.8768 1.0000
63.7000 8.4619 1.0000
63.7600 4.4580 1.0000
63.8200 4.2969 1.0000
63.8800 10.4699 1.0000
63.9400 4.6921 1.0000
64.0000 9.2545 1.0000
64.0600 7.5611 1.0000
64.1200 9.7127 1.0000
64.1800 6.6596 1.0000
64.2400 8.0094 1.0000
64.3000 8.3947 1.0000
64.3600 11.2253 1.0000
64.4200 6.4365 1.0000
64.4800 9.1185 1.0000
64.5400 10.0458 1.0000
64.6000 1.3813 1.0000
64.6600 6.0065 1.0000
64.7200 5.8731 1.0000
64.7800 10.3097 1.0000
64.8400 7.1955 1.0000
64.9000 6.5695 1.0000
64.9600 4.5603 1.0000
65.0200 10.0433 1.0000
65.0800 4.8243 1.0000
65.1400 4.2693 1.0000
65.2000 8.0342 1.0000
65.2600 7.3640 1.0000
65.3200 2.3621 1.0000
65.3800 7.5478 1.0000
65.4400 7.2418 1.0000
65.5000 13.9889 1.0000
65.5600 12.5535 1.0000
65.6200 11.0064 1.0000
65.6800 25.6824 1.0000
65.7400 22.9606 1.0000
65.8000 38.2509 1.0000
65.8600 26.8933 1.0000
65.9200 15.7856 1.0000
65.9800 16.2568 1.0000
66.0400 6.6620 1.0000
66.1000 16.8757 1.0000
66.1600 9.7386 1.0000
66.2200 11.7376 1.0000
66.2800 9.5081 1.0000
66.3400 5.8479 1.0000
66.4000 8.5715 1.0000
66.4600 10.5305 1.0000
66.5200 6.2413 1.0000
66.5800 8.5156 1.0000
66.6400 8.1365 1.0000
66.7000 4.5389 1.0000
66.7600 10.1331 1.0000
66.8200 9.1899 1.0000
66.8800 8.5511 1.0000
66.9400 11.1804 1.0000
67.0000 10.7050 1.0000
67.0600 6.0839 1.0000
67.1200 5.2267 1.0000
67.1800 6.3421 1.0000
67.2400 7.7775 1.0000
67.3000 6.1953 1.0000
67.3600 3.8181 1.0000
67.4200 7.7892 1.0000
67.4800 10.9610 1.0000
67.5400 9.1639 1.0000
67.6000 16.2044 1.0000
67.6600 5.0584 1.0000
67.7200 7.9371 1.0000
67.7800 9.0840 1.0000
67.8400 9.0051 1.0000
67.9000 4.4758 1.0000
67.9600 5.9369 1.0000
68.0200 7.2462 1.0000
68.0800 5.6896 1.0000
68.1400 4.3477 1.0000
68.2000 7.9048 1.0000
68.2600 6.4673 1.0000
68.3200 5.9891 1.0000
68.3800 5.9555 1.0000
68.4400 8.2875 1.0000
68.5000 8.5352 1.0000
68.5600 6.9964 1.0000
68.6200 11.1835 1.0000
68.6800 3.3022 1.0000
68.7400 7.4792 1.0000
68.8000 3.2066 1.0000
68.8600 2.5400 1.0000
68.9200 8.1511 1.0000
68.9800 9.3242 1.0000
69.0400 1.5312 1.0000
69.1000 11.0617 1.0000
69.1600 7.7000 1.0000
69.2200 11.9084 1.0000
69.2800 8.2305 1.0000
69.3400 11.0579 1.0000
69.4000 4.1823 1.0000
69.4600 6.3346 1.0000
69.5200 7.6407 1.0000
69.5800 10.3108 1.0000
69.6400 6.2635 1.0000
69.7000 10.0912 1.0000
69.7600 9.4490 1.0000
69.8200 6.3504 1.0000
69.8800 9.9615 1.0000
69.9400 9.2425 1.0000
70.0000 5.5565 1.0000
70.0600 8.2612 1.0000
70.1200 7.4771 1.0000
70.1800 5.1213 1.0000
70.2400 11.0006 1.0000
70.3000 10.7739 1.0000
70.3600 8.9916 1.0000
70.4200 7.2337 1.0000
70.4800 7.4124 1.0000
70.5400 10.6209 1.0000
70.6000 6.9311 1.0000
70.6600 2.4105 1.0000
70.7200 7.3488 1.0000
70.7800 5.5390 1.0000
70.8400 14.1809 1.0000
70.9000 6.2557 1.0000
70.9600 11.4185 1.0000
71.0200 6.6601 1.0000
71.0800 12.4990 1.0000
71.1400 9.5640 1.0000
71.2000 8.1200 1.0000
71.2600 7.9074 1.0000
71.3200 4.1459 1.0000
71.3800 4.9577 1.0000
71.4400 9.8411 1.0000
71.5000 10.8096 1.0000
71.5600 8.7646 1.0000
71.6200 9.3386 1.0000
71.6800 5.6248 1.0000
71.7400 7.0340 1.0000
71.8000 5.2455 1.0000
71.8600 5.5474 1.0000
71.9200 6.5488 1.0000
71.9800 5.9862 1.0000
72.0400 14.2521 1.0000
72.1000 7.1850 1.0000
72.1600 9.4040 1.0000
72.2200 5.8439 1.0000
72.2800 7.6439 1.0000
72.3400 12.4251 1.0000
72.4000 9.1585 1.0000
72.4600 11.6312 1.0000
72.5200 13.3613 1.0000
72.5800 3.5834 1.0000
72.6400 9.5890 1.0000
72.7000 5.3344 1.0000
72.7600 5.7982 1.0000
72.8200 4.4618 1.0000
72.8800 5.9352 1.0000
72.9400 4.2492 1.0000
73.0000 10.5365 1.0000
73.0600 9.8169 1.0000
73.1200 7.1193 1.0000
73.1800 3.7644 1.0000
73.2400 13.7839 1.0000
73.3000 4.3494 1.0000
73.3600 7.9451 1.0000
73.4200 12.2910 1.0000
73.4800 6.7554 1.0000
73.5400 5.7226 1.0000
73.6000 12.6557 1.0000
73.6600 8.0731 1.0000
73.7200 6.4001 1.0000
73.7800 8.2795 1.0000
73.8400 7.9444 1.0000
73.9000 5.9980 1.0000
73.9600 6.6505 1.0000
74.0200 7.9333 1.0000
74.0800 6.7062 1.0000
74.1400 9.2721 1.0000
74.2000 9.3761 1.0000
74.2600 12.0121 1.0000
74.3200 2.0873 1.0000
74.3800 9.4064 1.0000
74.4400 8.4973 1.0000
74.5000 12.4736 1.0000
74.5600 10.1630 1.0000
74.6200 10.5615 1.0000
74.6800 9.9048 1.0000
74.7400 13.5899 1.0000
74.8000 4.1800 1.0000
74.8600 7.3075 1.0000
74.9200 8.9065 1.0000
74.9800 9.5879 1.0000
75.0400 5.7031 1.0000
75.1000 2.7704 1.0000
75.1600 6.3734 1.0000
75.2200 4.2935 1.0000
75.2800 4.9575 1.0000
75.3400 6.6301 1.0000
75.4000 3.6950 1.0000
75.4600 8.2672 1.0000
75.5200 5.3927 1.0000
75.5800 4.1607 1.0000
75.6400 9.8919 1.0000
75.7000 6.8667 1.0000
75.7600 9.2197 1.0000
75.8200 8.4568 1.0000
75.8800 4.9666 1.0000
75.9400 10.4928 1.0000
76.0000 5.6673 1.0000
76.0600 8.0671 1.0000
76.1200 4.5346 1.0000
76.1800 10.4947 1.0000
76.2400 8.0070 1.0000
76.3000 8.5171 1.0000
76.3600 7.1005 1.0000
76.4200 8.2304 1.0000
76.4800 8.1016 1.0000
76.5400 2.6214 1.0000
76.6000 4.5084 1.0000
76.6600 14.2233 1.0000
76.7200 10.6607 1.0000
76.7800 11.7054 1.0000
76.8400 5.9011 1.0000
76.9000 6.5386 1.0000
76.9600 11.8247 1.0000
77.0200 4.4310 1.0000
77.0800 7.5333 1.0000
77.1400 8.3554 1.0000
77.2000 11.5924 1.0000
77.2600 5.9575 1.0000
77.3200 6.9854 1.0000
77.3800 4.5067 1.0000
77.4400 7.2397 1.0000
77.5000 4.0942 1.0000
77.5600 6.1898 1.0000
77.6200 6.9978 1.0000
77.6800 3.8836 1.0000
77.7400 11.9991 1.0000
77.8000 8.7877 1.0000
77.8600 4.5212 1.0000
77.9200 9.8039 1.0000
77.9800 6.8147 1.0000
78.0400 4.3849 1.0000
78.1000 6.0840 1.0000
78.1600 7.4980 1.0000
78.2200 12.6284 1.0000
78.2800 3.5855 1.0000
78.3400 3.5975 1.0000
78.4000 8.9649 1.0000
78.4600 14.7048 1.0000
78.5200 12.4668 1.0000
78.5800 8.2650 1.0000
78.6400 5.8000 1.0000
78.7000 8.0292 1.0000
78.7600 11.3598 1.0000
78.8200 2.5388 1.0000
78.8800 7.2190 1.0000
78.9400 4.9972 1.0000
79.0000 6.9510 1.0000
79.0600 6.5199 1.0000
79.1200 4.6762 1.0000
79.1800 5.4779 1.0000
79.2400 7.3230 1.0000
79.3000 8.1534 1.0000
79.3600 11.3778 1.0000
79.4200 10.5313 1.0000
79.4800 10.6537 1.0000
79.5400 9.2295 1.0000
79.6000 6.5622 1.0000
79.6600 8.7463 1.0000
79.7200 11.0768 1.0000
79.7800 12.8604 1.0000
79.8400 8.4831 1.0000
79.9000 7.2988 1.0000
79.9600 11.0830 1.0000
80.0200 8.1180 1.0000
80.0800 8.1800 1.0000
80.1400 9.2698 1.0000
80.2000 11.8796 1.0000
80.2600 10.2460 1.0000
80.3200 9.8479 1.0000
80.3800 2.8917 1.0000
80.4400 5.4267 1.0000
80.5000 8.0437 1.0000
80.5600 8.8514 1.0000
80.6200 8.4618 1.0000
80.6800 6.6152 1.0000
80.7400 7.0783 1.0000
80.8000 6.9869 1.0000
80.8600 14.1561 1.0000
80.9200 8.0496 1.0000
80.9800 4.8439 1.0000
81.0400 9.5613 1.0000
81.1000 6.5562 1.0000
81.1600 15.3458 1.0000
81.2200 9.6110 1.0000
81.2800 12.8162 1.0000
81.3400 10.2673 1.0000
81.4000 8.2192 1.0000
81.4600 4.2946 1.0000
81.5200 4.6689 1.0000
81.5800 7.4057 1.0000
81.6400 8.1945 1.0000
81.7000 8.3638 1.0000
81.7600 7.9709 1.0000
81.8200 10.6293 1.0000
81.8800 7.9365 1.0000
81.9400 4.3288 1.0000
82.0000 5.2357 1.0000
82.0600 7.2946 1.0000
82.1200 5.8062 1.0000
82.1800 12.5971 1.0000
82.2400 8.3921 1.0000
82.3000 7.2914 1.0000
82.3600 13.8606 1.0000
82.4200 11.3016 1.0000
82.4800 14.0396 1.0000
82.5400 7.4608 1.0000
82.6000 9.3041 1.0000
82.6600 13.8975 1.0000
82.7200 6.6381 1.0000
82.7800 10.4152 1.0000
82.8400 12.8603 1.0000
82.9000 29.0101 1.0000
82.9600 39.1161 1.0000
83.0200 54.1984 1.0000
83.0800 84.5049 1.0000
83.1400 42.3902 1.0000
83.2000 20.3493 1.0000
83.2600 8.2535 1.0000
83.3200 10.1998 1.0000
83.3800 10.4905 1.0000
83.4400 8.3010 1.0000
83.5000 7.8459 1.0000
83.5600 9.5528 1.0000
83.6200 9.2334 1.0000
83.6800 7.0375 1.0000
83.7400 13.6484 1.0000
83.8000 10.1679 1.0000
83.8600 14.0872 1.0000
83.9200 4.2831 1.0000
83.9800 8.4269 1.0000
84.0400 8.0145 1.0000
84.1000 6.9110 1.0000
84.1600 11.5628 1.0000
84.2200 3.2488 1.0000
84.2800 7.6013 1.0000
84.3400 7.1729 1.0000
84.4000 8.6898 1.0000
84.4600 9.0221 1.0000
84.5200 9.7230 1.0000
84.5800 8.0451 1.0000
84.6400 15.4523 1.0000
84.7000 6.7230 1.0000
84.7600 3.2772 1.0000
84.8200 13.6518 1.0000
84.8800 7.4419 1.0000
84.9400 9.2644 1.0000
85.0000 8.4704 1.0000
85.0600 7.4306 1.0000
85.1200 10.2155 1.0000
85.1800 10.6687 1.0000
85.2400 7.4542 1.0000
85.3000 6.1451 1.0000
85.3600 7.7581 1.0000
85.4200 7.7213 1.0000
85.4800 5.5821 1.0000
85.5400 6.1728 1.0000
85.6000 8.9110 1.0000
85.6600 6.7316 1.0000
85.7200 11.5289 1.0000
85.7800 9.3691 1.0000
85.8400 10.0730 1.0000
85.9000 5.1863 1.0000
85.9600 11.2019 1.0000
86.0200 13.0436 1.0000
86.0800 11.8877 1.0000
86.1400 9.4680 1.0000
86.2000 7.3227 1.0000
86.2600 9.1552 1.0000
86.3200 3.4914 1.0000
86.3800 9.1219 1.0000
86.4400 15.3814 1.0000
86.5000 6.4621 1.0000
86.5600 3.5151 1.0000
86.6200 8.6313 1.0000
86.6800 9.9595 1.0000
86.7400 12.3041 1.0000
86.8000 9.5969 1.0000
86.8600 9.2491 1.0000
86.9200 9.2745 1.0000
86.9800 15.1586 1.0000
87.0400 8.9769 1.0000
87.1000 6.4591 1.0000
87.1600 6.3926 1.0000
87.2200 11.7948 1.0000
87.2800 9.1875 1.0000
87.3400 7.3124 1.0000
87.4000 8.2836 1.0000
87.4600 5.6972 1.0000
87.5200 11.2021 1.0000
87.5800 11.8396 1.0000
87.6400 9.1899 1.0000
87.7000 6.6771 1.0000
87.7600 8.2414 1.0000
87.8200 6.2879 1.0000
87.8800 8.6284 1.0000
87.9400 12.3978 1.0000
88.0000 9.2943 1.0000
88.0600 7.1799 1.0000
88.1200 8.0579 1.0000
88.1800 6.5278 1.0000
88.2400 8.7832 1.0000
88.3000 5.2125 1.0000
88.3600 10.0920 1.0000
88.4200 7.4826 1.0000
88.4800 17.1878 1.0000
88.5400 6.2585 1.0000
88.6000 7.9782 1.0000
88.6600 13.3758 1.0000
88.7200 12.1681 1.0000
88.7800 12.0361 1.0000
88.8400 4.2704 1.0000
88.9000 13.6893 1.0000
88.9600 10.8909 1.0000
89.0200 7.8688 1.0000
89.0800 4.8233 1.0000
89.1400 4.9053 1.0000
89.2000 4.2655 1.0000
89.2600 11.5550 1.0000
89.3200 5.2540 1.0000
89.3800 6.4025 1.0000
89.4400 9.7581 1.0000
89.5000 2.9301 1.0000
89.5600 6.5280 1.0000
89.6200 12.6182 1.0000
89.6800 7.0820 1.0000
89.7400 12.0091 1.0000
89.8000 7.3326 1.0000
89.8600 7.0766 1.0000
89.9200 5.6494 1.0000
89.9800 3.2420 1.0000
90.0400 10.5724 1.0000
90.1000 6.3769 1.0000
90.1600 10.4733 1.0000
90.2200 8.5227 1.0000
90.2800 2.8595 1.0000
90.3400 14.5068 1.0000
90.4000 8.6948 1.0000
90.4600 6.0879 1.0000
90.5200 5.6575 1.0000
90.5800 6.0915 1.0000
90.6400 6.5426 1.0000
90.7000 7.0214 1.0000
90.7600 4.6294 1.0000
90.8200 8.6966 1.0000
90.8800 5.5678 1.0000
90.9400 2.6679 1.0000
91.0000 7.2485 1.0000
91.0600 4.2475 1.0000
91.1200 7.6560 1.0000
91.1800 5.0703 1.0000
91.2400 13.4006 1.0000
91.3000 10.1030 1.0000
91.3600 9.9802 1.0000
91.4200 5.9938 1.0000
91.4800 16.2848 1.0000
91.5400 9.5918 1.0000
91.6000 7.8682 1.0000
91.6600 11.2787 1.0000
91.7200 7.6530 1.0000
91.7800 6.9464 1.0000
91.8400 6.9415 1.0000
91.9000 5.3493 1.0000
91.9600 7.2632 1.0000
92.0200 6.0431 1.0000
92.0800 7.6711 1.0000
92.1400 14.2392 1.0000
92.2000 8.2433 1.0000
92.2600 7.0319 1.0000
92.3200 4.5737 1.0000
92.3800 7.1415 1.0000
92.4400 9.4273 1.0000
92.5000 10.3937 1.0000
92.5600 4.7590 1.0000
92.6200 11.6177 1.0000
92.6800 6.2501 1.0000
92.7400 9.1355 1.0000
92.8000 8.8162 1.0000
92.8600 8.3096 1.0000
92.9200 6.4463 1.0000
92.9800 7.5452 1.0000
93.0400 6.3938 1.0000
93.1000 7.8792 1.0000
93.1600 7.0315 1.0000
93.2200 6.8743 1.0000
93.2800 9.7053 1.0000
93.3400 6.1597 1.0000
93.4000 10.8110 1.0000
93.4600 11.2231 1.0000
93.5200 10.2135 1.0000
93.5800 4.3151 1.0000
93.6400 7.5388 1.0000
93.7000 4.9166 1.0000
93.7600 10.9513 1.0000
93.8200 6.1524 1.0000
93.8800 7.4387 1.0000
93.9400 7.2569 1.0000
94.0000 7.8992 1.0000
94.0600 9.7675 1.0000
94.1200 8.5173 1.0000
94.1800 3.6067 1.0000
94.2400 4.2874 1.0000
94.3000 10.1030 1.0000
94.3600 4.6496 1.0000
94.4200 6.5992 1.0000
94.4800 11.8392 1.0000
94.5400 4.8852 1.0000
94.6000 7.0990 1.0000
94.6600 9.4613 1.0000
94.7200 3.1285 1.0000
94.7800 7.8501 1.0000
94.8400 6.6408 1.0000
94.9000 5.6414 1.0000
94.9600 8.0835 1.0000
95.0200 7.2786 1.0000
95.0800 5.2373 1.0000
95.1400 6.2257 1.0000
95.2000 5.5456 1.0000
95.2600 6.9423 1.0000
95.3200 6.4575 1.0000
95.3800 8.8536 1.0000
95.4400 6.2432 1.0000
95.5000 12.8431 1.0000
95.5600 8.3754 1.0000
95.6200 13.4412 1.0000
95.6800 16.4281 1.0000
95.7400 11.1930 1.0000
95.8000 8.2792 1.0000
95.8600 7.0987 1.0000
95.9200 7.5939 1.0000
95.9800 11.2340 1.0000
96.0400 6.4220 1.0000
96.1000 6.9240 1.0000
96.1600 7.7451 1.0000
96.2200 5.1001 1.0000
96.2800 9.5015 1.0000
96.3400 6.3499 1.0000
96.4000 4.9984 1.0000
96.4600 9.3927 1.0000
96.5200 11.2149 1.0000
96.5800 7.3874 1.0000
96.6400 12.0512 1.0000
96.7000 11.8740 1.0000
96.7600 5.2974 1.0000
96.8200 5.7191 1.0000
96.8800 6.4857 1.0000
96.9400 5.2763 1.0000
97.0000 6.4978 1.0000
97.0600 2.2978 1.0000
97.1200 6.2528 1.0000
97.1800 14.0981 1.0000
97.2400 9.5879 1.0000
97.3000 9.9273 1.0000
97.3600 2.1688 1.0000
97.4200 4.4885 1.0000
97.4800 12.9523 1.0000
97.5400 7.0130 1.0000
97.6000 5.3492 1.0000
97.6600 4.5981 1.0000
97.7200 10.3120 1.0000
97.7800 4.1065 1.0000
97.8400 7.3367 1.0000
97.9000 8.4128 1.0000
97.9600 8.2087 1.0000
98.0200 3.8094 1.0000
98.0800 9.3210 1.0000
98.1400 9.0886 1.0000
98.2000 13.7645 1.0000
98.2600 8.3759 1.0000
98.3200 8.7617 1.0000
98.3800 4.1125 1.0000
98.4400 1.5837 1.0000
98.5000 10.2605 1.0000
98.5600 9.1853 1.0000
98.6200 6.9163 1.0000
98.6800 7.4246 1.0000
98.7400 4.3147 1.0000
98.8000 6.3979 1.0000
98.8600 10.5502 1.0000
98.9200 7.8354 1.0000
98.9800 8.9953 1.0000
99.0400 11.2118 1.0000
99.1000 7.0658 1.0000
99.1600 10.0973 1.0000
99.2200 7.2350 1.0000
99.2800 6.9742 1.0000
99.3400 11.0889 1.0000
99.4000 17.1042 1.0000
99.4600 18.3809 1.0000
99.5200 32.4020 1.0000
99.5800 39.1170 1.0000
99.6400 42.9803 1.0000
99.7000 31.6425 1.0000
99.7600 12.2688 1.0000
99.8200 11.0706 1.0000
99.8800 6.8272 1.0000
99.9400 12.4344 1.0000
100.0000 8.6510 1.0000
100.0600 10.9320 1.0000
100.1200 12.5747 1.0000
100.1800 8.2010 1.0000
100.2400 9.8213 1.0000
100.3000 14.3460 1.0000
100.3600 5.2359 1.0000
100.4200 6.5819 1.0000
100.4800 8.7406 1.0000
100.5400 9.1105 1.0000
100.6000 8.2552 1.0000
100.6600 7.2086 1.0000
100.7200 6.0139 1.0000
100.7800 4.7705 1.0000
100.8400 6.8787 1.0000
100.9000 7.8930 1.0000
100.9600 7.0519 1.0000
101.0200 6.3432 1.0000
101.0800 8.1926 1.0000
101.1400 7.9381 1.0000
101.2000 9.5474 1.0000
101.2600 5.6459 1.0000
101.3200 7.5232 1.0000
101.3800 9.2160 1.0000
101.4400 9.7572 1.0000
101.5000 4.3395 1.0000
101.5600 6.4712 1.0000
101.6200 10.1595 1.0000
101.6800 4.6126 1.0000
101.7400 11.2335 1.0000
101.8000 3.0267 1.0000
101.8600 5.2118 1.0000
101.9200 8.6106 1.0000
101.9800 8.9803 1.0000
102.0400 7.1397 1.0000
102.1000 3.6086 1.0000
102.1600 12.7845 1.0000
102.2200 8.0217 1.0000
102.2800 9.7287 1.0000
102.3400 3.0891 1.0000
102.4000 7.4907 1.0000
102.4600 9.4367 1.0000
102.5200 5.4556 1.0000
102.5800 9.5855 1.0000
102.6400 6.0819 1.0000
102.7000 10.1790 1.0000
102.7600 9.3927 1.0000
102.8200 2.4421 1.0000
102.8800 12.1454 1.0000
102.9400 10.9637 1.0000
103.0000 3.0827 1.0000
103.0600 7.4718 1.0000
103.1200 12.2154 1.0000
103.1800 8.4253 1.0000
103.2400 6.0519 1.0000
103.3000 10.2326 1.0000
103.3600 3.9088 1.0000
103.4200 5.0531 1.0000
103.4800 6.3777 1.0000
103.5400 5.3975 1.0000
103.6000 11.1375 1.0000
103.6600 8.5542 1.0000
103.7200 11.1738 1.0000
103.7800 6.0311 1.0000
103.8400 10.1448 1.0000
103.9000 8.1400 1.0000
103.9600 5.1741 1.0000
104.0200 5.6669 1.0000
104.0800 7.8115 1.0000
104.1400 3.0926 1.0000
104.2000 6.3279 1.0000
104.2600 7.3145 1.0000
104.3200 10.7777 1.0000
104.3800 7.3932 1.0000
104.4400 4.0785 1.0000
104.5000 10.4622 1.0000
104.5600 5.2240 1.0000
104.6200 5.9514 1.0000
104.6800 8.8560 1.0000
104.7400 6.2338 1.0000
104.8000 4.7896 1.0000
104.8600 6.2397 1.0000
104.9200 9.2265 1.0000
104.9800 3.9589 1.0000
105.0400 7.1507 1.0000
105.1000 11.3886 1.0000
105.1600 7.9600 1.0000
105.2200 8.9791 1.0000
105.2800 2.1124 1.0000
105.3400 3.5845 1.0000
105.4000 6.2230 1.0000
105.4600 8.5900 1.0000
105.5200 6.1103 1.0000
105.5800 8.4025 1.0000
105.6400 9.4714 1.0000
105.7000 7.2350 1.0000
105.7600 2.9927 1.0000
105.8200 7.5909 1.0000
105.8800 5.7433 1.0000
105.9400 7.2329 1.0000
106.0000 6.2019 1.0000
106.0600 10.3436 1.0000
106.1200 5.4454 1.0000
106.1800 5.9798 1.0000
106.2400 4.2964 1.0000
106.3000 7.2413 1.0000
106.3600 7.0196 1.0000
106.4200 7.3220 1.0000
106.4800 5.4435 1.0000
106.5400 8.5850 1.0000
106.6000 7.1221 1.0000
106.6600 7.7785 1.0000
106.7200 3.4452 1.0000
106.7800 7.2730 1.0000
106.8400 3.4143 1.0000
106.9000 12.5043 1.0000
106.9600 6.4380 1.0000
107.0200 4.5490 1.0000
107.0800 8.7682 1.0000
107.1400 8.6766 1.0000
107.2000 4.5827 1.0000
107.2600 8.4638 1.0000
107.3200 11.1798 1.0000
107.3800 7.8805 1.0000
107.4400 7.4763 1.0000
107.5000 3.5478 1.0000
107.5600 14.3310 1.0000
107.6200 7.2904 1.0000
107.6800 4.3710 1.0000
107.7400 19.5348 1.0000
[...]
67.3000 6.5598 1.0000
67.3600 8.4714 1.0000
67.4200 5.5605 1.0000
67.4800 4.8300 1.0000
67.5400 7.1859 1.0000
67.6000 8.2955 1.0000
67.6600 14.4012 1.0000
67.7200 5.4728 1.0000
67.7800 7.7167 1.0000
67.8400 10.0958 1.0000
67.9000 3.6683 1.0000
67.9600 8.8811 1.0000
68.0200 9.3554 1.0000
68.0800 8.5806 1.0000
68.1400 4.7851 1.0000
68.2000 5.5983 1.0000
68.2600 8.3828 1.0000
68.3200 5.2590 1.0000
68.3800 5.6297 1.0000
68.4400 7.5096 1.0000
68.5000 17.3540 1.0000
68.5600 11.1120 1.0000
68.6200 11.0232 1.0000
68.6800 18.0665 1.0000
68.7400 11.4827 1.0000
68.8000 7.4675 1.0000
68.8600 5.7174 1.0000
68.9200 6.6348 1.0000
68.9800 9.9489 1.0000
69.0400 4.8145 1.0000
69.1000 6.8605 1.0000
69.1600 5.8154 1.0000
69.2200 11.1565 1.0000
69.2800 8.9518 1.0000
69.3400 5.2754 1.0000
69.4000 5.4164 1.0000
69.4600 9.7586 1.0000
69.5200 10.8851 1.0000
69.5800 7.7154 1.0000
69.6400 12.8303 1.0000
69.7000 7.2922 1.0000
69.7600 9.9564 1.0000
69.8200 10.0508 1.0000
69.8800 8.7120 1.0000
69.9400 7.2208 1.0000
70.0000 11.2568 1.0000
70.0600 11.0755 1.0000
70.1200 5.3759 1.0000
70.1800 5.2730 1.0000
70.2400 5.0746 1.0000
70.3000 8.0561 1.0000
70.3600 11.7327 1.0000
70.4200 5.1213 1.0000
70.4800 7.7013 1.0000
70.5400 7.0008 1.0000
70.6000 11.3013 1.0000
70.6600 14.2292 1.0000
70.7200 7.9490 1.0000
70.7800 7.1554 1.0000
70.8400 6.1804 1.0000
70.9000 9.3279 1.0000
70.9600 10.6303 1.0000
71.0200 5.2580 1.0000
71.0800 6.9038 1.0000
71.1400 6.2278 1.0000
71.2000 8.3132 1.0000
71.2600 10.5122 1.0000
71.3200 17.1981 1.0000
71.3800 6.9215 1.0000
71.4400 8.6432 1.0000
71.5000 14.2684 1.0000
71.5600 13.2627 1.0000
71.6200 10.5972 1.0000
71.6800 9.5309 1.0000
71.7400 11.2731 1.0000
71.8000 6.6122 1.0000
71.8600 11.0933 1.0000
71.9200 2.9175 1.0000
71.9800 10.0721 1.0000
72.0400 9.7506 1.0000
72.1000 7.1368 1.0000
72.1600 6.3732 1.0000
72.2200 7.7429 1.0000
72.2800 10.0629 1.0000
72.3400 5.4069 1.0000
72.4000 10.9216 1.0000
72.4600 8.8844 1.0000
72.5200 9.2366 1.0000
72.5800 6.1886 1.0000
72.6400 5.2864 1.0000
72.7000 7.7135 1.0000
72.7600 7.9439 1.0000
72.8200 8.9322 1.0000
72.8800 9.5870 1.0000
72.9400 3.8810 1.0000
73.0000 11.3221 1.0000
73.0600 9.0154 1.0000
73.1200 14.7129 1.0000
73.1800 8.9247 1.0000
73.2400 5.3790 1.0000
73.3000 11.9097 1.0000
73.3600 10.3482 1.0000
73.4200 3.2480 1.0000
73.4800 8.0469 1.0000
73.5400 5.2775 1.0000
73.6000 9.0146 1.0000
73.6600 8.2368 1.0000
73.7200 7.9661 1.0000
73.7800 12.6967 1.0000
73.8400 8.2442 1.0000
73.9000 9.0354 1.0000
73.9600 8.0577 1.0000
74.0200 7.3962 1.0000
74.0800 6.9682 1.0000
74.1400 15.7609 1.0000
74.2000 4.8528 1.0000
74.2600 9.1020 1.0000
74.3200 5.8927 1.0000
74.3800 7.5688 1.0000
74.4400 7.7804 1.0000
74.5000 7.4232 1.0000
74.5600 7.8439 1.0000
74.6200 10.1633 1.0000
74.6800 6.9358 1.0000
74.7400 13.5177 1.0000
74.8000 14.4507 1.0000
74.8600 14.4117 1.0000
74.9200 9.8810 1.0000
74.9800 6.6359 1.0000
75.0400 8.4367 1.0000
75.1000 7.0289 1.0000
75.1600 7.8826 1.0000
75.2200 2.2719 1.0000
75.2800 10.5172 1.0000
75.3400 7.4377 1.0000
75.4000 7.1216 1.0000
75.4600 7.5409 1.0000
75.5200 12.5094 1.0000
75.5800 11.2501 1.0000
75.6400 8.7838 1.0000
75.7000 4.1454 1.0000
75.7600 6.1194 1.0000
75.8200 12.4376 1.0000
75.8800 6.4186 1.0000
75.9400 6.3613 1.0000
76.0000 7.0104 1.0000
76.0600 11.7457 1.0000
76.1200 9.5357 1.0000
76.1800 8.1842 1.0000
76.2400 5.6187 1.0000
76.3000 4.1461 1.0000
76.3600 6.4192 1.0000
76.4200 8.5380 1.0000
76.4800 4.9737 1.0000
76.5400 7.9944 1.0000
76.6000 10.1989 1.0000
76.6600 7.0247 1.0000
76.7200 7.8208 1.0000
76.7800 8.9052 1.0000
76.8400 7.2658 1.0000
76.9000 7.4360 1.0000
76.9600 12.4523 1.0000
77.0200 7.3001 1.0000
77.0800 9.8877 1.0000
77.1400 9.2967 1.0000
77.2000 8.6976 1.0000
77.2600 8.4985 1.0000
77.3200 7.4956 1.0000
77.3800 9.3139 1.0000
77.4400 7.6078 1.0000
77.5000 4.6440 1.0000
77.5600 6.0949 1.0000
77.6200 3.4391 1.0000
77.6800 5.0083 1.0000
77.7400 3.3070 1.0000
77.8000 5.9372 1.0000
77.8600 18.0289 1.0000
77.9200 20.4901 1.0000
77.9800 3.3437 1.0000
78.0400 10.6285 1.0000
78.1000 12.0983 1.0000
78.1600 3.0606 1.0000
78.2200 6.3887 1.0000
78.2800 2.0370 1.0000
78.3400 12.2430 1.0000
78.4000 19.0246 1.0000
78.4600 9.8329 1.0000
78.5200 8.1845 1.0000
78.5800 8.4180 1.0000
78.6400 11.2140 1.0000
78.7000 4.5879 1.0000
78.7600 6.6281 1.0000
78.8200 7.5230 1.0000
78.8800 13.2202 1.0000
78.9400 7.1082 1.0000
79.0000 6.2960 1.0000
79.0600 7.1117 1.0000
79.1200 6.2961 1.0000
79.1800 9.9805 1.0000
79.2400 1.4933 1.0000
79.3000 10.9066 1.0000
79.3600 8.3076 1.0000
79.4200 15.6625 1.0000
79.4800 5.7045 1.0000
79.5400 11.0735 1.0000
79.6000 5.6343 1.0000
79.6600 8.3238 1.0000
79.7200 11.9013 1.0000
79.7800 9.3445 1.0000
79.8400 6.4448 1.0000
79.9000 8.0664 1.0000
79.9600 5.3796 1.0000
80.0200 6.2522 1.0000
80.0800 5.8998 1.0000
80.1400 7.4059 1.0000
80.2000 5.4317 1.0000
80.2600 4.7318 1.0000
80.3200 8.3134 1.0000
80.3800 7.6097 1.0000
80.4400 7.1382 1.0000
80.5000 7.1961 1.0000
80.5600 9.0895 1.0000
80.6200 5.3563 1.0000
80.6800 5.6544 1.0000
80.7400 8.4102 1.0000
80.8000 7.9458 1.0000
80.8600 7.5503 1.0000
80.9200 10.8563 1.0000
80.9800 12.1369 1.0000
81.0400 9.1524 1.0000
81.1000 2.5205 1.0000
81.1600 3.3128 1.0000
81.2200 9.5212 1.0000
81.2800 6.1985 1.0000
81.3400 10.7731 1.0000
81.4000 9.0236 1.0000
81.4600 3.5921 1.0000
81.5200 7.3098 1.0000
81.5800 12.4444 1.0000
81.6400 7.1158 1.0000
81.7000 5.6362 1.0000
81.7600 10.7261 1.0000
81.8200 6.4762 1.0000
81.8800 7.1126 1.0000
81.9400 5.7862 1.0000
82.0000 19.6890 1.0000
82.0600 11.9605 1.0000
82.1200 5.5371 1.0000
82.1800 8.2734 1.0000
82.2400 6.2248 1.0000
82.3000 9.9781 1.0000
82.3600 3.5952 1.0000
82.4200 8.7938 1.0000
82.4800 6.8595 1.0000
82.5400 4.5552 1.0000
82.6000 9.4881 1.0000
82.6600 5.6381 1.0000
82.7200 12.3158 1.0000
82.7800 13.8728 1.0000
82.8400 17.8532 1.0000
82.9000 18.6622 1.0000
82.9600 40.2540 1.0000
83.0200 60.1555 1.0000
83.0800 73.6353 1.0000
83.1400 39.4189 1.0000
83.2000 24.7382 1.0000
83.2600 12.9354 1.0000
83.3200 14.1764 1.0000
83.3800 13.5382 1.0000
83.4400 12.3510 1.0000
83.5000 7.3376 1.0000
83.5600 4.1755 1.0000
83.6200 8.3289 1.0000
83.6800 5.4490 1.0000
83.7400 7.6212 1.0000
83.8000 13.0672 1.0000
83.8600 15.9414 1.0000
83.9200 6.9167 1.0000
83.9800 11.1644 1.0000
84.0400 7.7507 1.0000
84.1000 7.5277 1.0000
84.1600 7.5039 1.0000
84.2200 7.8157 1.0000
84.2800 5.7740 1.0000
84.3400 14.2890 1.0000
84.4000 12.1027 1.0000
84.4600 7.1731 1.0000
84.5200 6.4148 1.0000
84.5800 6.7057 1.0000
84.6400 6.5094 1.0000
84.7000 9.1059 1.0000
84.7600 10.5412 1.0000
84.8200 6.0607 1.0000
84.8800 10.0075 1.0000
84.9400 8.5585 1.0000
85.0000 3.5190 1.0000
85.0600 11.5695 1.0000
85.1200 3.5709 1.0000
85.1800 6.3701 1.0000
85.2400 11.6444 1.0000
85.3000 9.8898 1.0000
85.3600 10.0805 1.0000
85.4200 9.4064 1.0000
85.4800 1.8225 1.0000
85.5400 4.8155 1.0000
85.6000 6.1487 1.0000
85.6600 3.6650 1.0000
85.7200 10.4543 1.0000
85.7800 6.8204 1.0000
85.8400 8.4917 1.0000
85.9000 7.0585 1.0000
85.9600 7.8843 1.0000
86.0200 7.2140 1.0000
86.0800 11.7797 1.0000
86.1400 8.4699 1.0000
86.2000 6.9489 1.0000
86.2600 3.6520 1.0000
86.3200 5.8892 1.0000
86.3800 2.3930 1.0000
86.4400 13.8234 1.0000
86.5000 7.7245 1.0000
86.5600 10.5092 1.0000
86.6200 8.9288 1.0000
86.6800 19.0910 1.0000
86.7400 4.4257 1.0000
86.8000 9.6449 1.0000
86.8600 4.9537 1.0000
86.9200 6.4259 1.0000
86.9800 6.8380 1.0000
87.0400 5.7040 1.0000
87.1000 11.8357 1.0000
87.1600 5.4766 1.0000
87.2200 7.7799 1.0000
87.2800 12.6533 1.0000
87.3400 5.2544 1.0000
87.4000 10.2033 1.0000
87.4600 9.6251 1.0000
87.5200 10.4494 1.0000
87.5800 12.1864 1.0000
87.6400 4.3646 1.0000
87.7000 6.6905 1.0000
87.7600 4.9160 1.0000
87.8200 7.6854 1.0000
87.8800 4.9893 1.0000
87.9400 12.0795 1.0000
88.0000 7.2252 1.0000
88.0600 4.8072 1.0000
88.1200 7.4254 1.0000
88.1800 8.8941 1.0000
88.2400 8.1266 1.0000
88.3000 10.9500 1.0000
88.3600 4.5618 1.0000
88.4200 14.9636 1.0000
88.4800 4.0319 1.0000
88.5400 4.0920 1.0000
88.6000 6.9292 1.0000
88.6600 8.6012 1.0000
88.7200 8.5514 1.0000
88.7800 5.6271 1.0000
88.8400 9.1038 1.0000
88.9000 10.9366 1.0000
88.9600 10.7766 1.0000
89.0200 4.6857 1.0000
89.0800 5.8736 1.0000
89.1400 6.9158 1.0000
89.2000 7.0404 1.0000
89.2600 6.7421 1.0000
89.3200 8.7231 1.0000
89.3800 2.3531 1.0000
89.4400 7.7769 1.0000
89.5000 10.4768 1.0000
89.5600 6.4950 1.0000
89.6200 5.7082 1.0000
89.6800 10.9305 1.0000
89.7400 1.3281 1.0000
89.8000 4.8341 1.0000
89.8600 6.6179 1.0000
89.9200 10.1688 1.0000
89.9800 7.7131 1.0000
90.0400 7.6516 1.0000
90.1000 8.4992 1.0000
90.1600 3.1494 1.0000
90.2200 5.0663 1.0000
90.2800 8.8163 1.0000
90.3400 3.9088 1.0000
90.4000 10.7067 1.0000
90.4600 8.1938 1.0000
90.5200 5.9213 1.0000
90.5800 10.6438 1.0000
90.6400 8.0826 1.0000
90.7000 9.5923 1.0000
90.7600 3.6146 1.0000
90.8200 4.6756 1.0000
90.8800 6.1148 1.0000
90.9400 7.0881 1.0000
91.0000 7.4400 1.0000
91.0600 3.7037 1.0000
91.1200 11.5426 1.0000
91.1800 8.9125 1.0000
91.2400 6.4963 1.0000
91.3000 10.7777 1.0000
91.3600 4.7317 1.0000
91.4200 9.3636 1.0000
91.4800 5.6979 1.0000
91.5400 8.0041 1.0000
91.6000 4.4865 1.0000
91.6600 13.1359 1.0000
91.7200 4.0435 1.0000
91.7800 10.4803 1.0000
91.8400 7.7430 1.0000
91.9000 5.7479 1.0000
91.9600 12.4571 1.0000
92.0200 2.8320 1.0000
92.0800 5.4538 1.0000
92.1400 10.4516 1.0000
92.2000 6.5403 1.0000
92.2600 11.5723 1.0000
92.3200 7.5910 1.0000
92.3800 5.3045 1.0000
92.4400 4.7918 1.0000
92.5000 13.2739 1.0000
92.5600 9.4179 1.0000
92.6200 12.0182 1.0000
92.6800 9.1850 1.0000
92.7400 11.5689 1.0000
92.8000 3.9635 1.0000
92.8600 10.2541 1.0000
92.9200 11.4503 1.0000
92.9800 4.3633 1.0000
93.0400 14.7310 1.0000
93.1000 10.6584 1.0000
93.1600 7.6197 1.0000
93.2200 4.0564 1.0000
93.2800 6.7019 1.0000
93.3400 8.4363 1.0000
93.4000 9.0923 1.0000
93.4600 10.5111 1.0000
93.5200 11.2240 1.0000
93.5800 3.9555 1.0000
93.6400 3.9068 1.0000
93.7000 7.5267 1.0000
93.7600 9.5155 1.0000
93.8200 9.8046 1.0000
93.8800 7.3756 1.0000
93.9400 7.3228 1.0000
94.0000 6.8611 1.0000
94.0600 7.3937 1.0000
94.1200 9.4782 1.0000
94.1800 7.0663 1.0000
94.2400 9.2230 1.0000
94.3000 9.2438 1.0000
94.3600 10.9908 1.0000
94.4200 3.2097 1.0000
94.4800 11.3773 1.0000
94.5400 8.8026 1.0000
94.6000 7.5417 1.0000
94.6600 11.5791 1.0000
94.7200 10.6741 1.0000
94.7800 7.3402 1.0000
94.8400 5.1896 1.0000
94.9000 3.9637 1.0000
94.9600 7.0199 1.0000
95.0200 6.3282 1.0000
95.0800 5.1036 1.0000
95.1400 6.8950 1.0000
95.2000 13.2399 1.0000
95.2600 11.8961 1.0000
95.3200 7.3956 1.0000
95.3800 17.5644 1.0000
95.4400 9.9676 1.0000
95.5000 5.6718 1.0000
95.5600 11.5396 1.0000
95.6200 4.3272 1.0000
95.6800 9.2132 1.0000
95.7400 9.3095 1.0000
95.8000 11.2951 1.0000
95.8600 5.2312 1.0000
95.9200 6.5389 1.0000
95.9800 4.5498 1.0000
96.0400 10.0944 1.0000
96.1000 7.0169 1.0000
96.1600 4.1997 1.0000
96.2200 7.8393 1.0000
96.2800 4.1163 1.0000
96.3400 14.0112 1.0000
96.4000 9.7018 1.0000
96.4600 9.9641 1.0000
96.5200 5.1993 1.0000
96.5800 6.4224 1.0000
96.6400 10.1413 1.0000
96.7000 9.1912 1.0000
96.7600 4.2960 1.0000
96.8200 8.0603 1.0000
96.8800 6.8973 1.0000
96.9400 5.3268 1.0000
97.0000 11.3908 1.0000
97.0600 8.1446 1.0000
97.1200 7.9411 1.0000
97.1800 8.0108 1.0000
97.2400 10.3965 1.0000
97.3000 5.9568 1.0000
97.3600 5.9212 1.0000
97.4200 6.9675 1.0000
97.4800 6.4060 1.0000
97.5400 6.7529 1.0000
97.6000 8.4012 1.0000
97.6600 4.8990 1.0000
97.7200 5.1195 1.0000
97.7800 3.3397 1.0000
97.8400 6.7341 1.0000
97.9000 7.0491 1.0000
97.9600 7.6193 1.0000
98.0200 7.8960 1.0000
98.0800 8.6480 1.0000
98.1400 11.4473 1.0000
98.2000 7.9490 1.0000
98.2600 3.6399 1.0000
98.3200 15.5875 1.0000
98.3800 8.9805 1.0000
98.4400 6.9070 1.0000
98.5000 3.3529 1.0000
98.5600 4.8774 1.0000
98.6200 9.7224 1.0000
98.6800 2.3592 1.0000
98.7400 10.4331 1.0000
98.8000 4.2722 1.0000
98.8600 8.4386 1.0000
98.9200 8.7823 1.0000
98.9800 11.5432 1.0000
99.0400 3.4276 1.0000
99.1000 2.9540 1.0000
99.1600 9.6254 1.0000
99.2200 6.3502 1.0000
99.2800 8.4248 1.0000
99.3400 8.1754 1.0000
99.4000 18.1383 1.0000
99.4600 17.7857 1.0000
99.5200 33.1815 1.0000
99.5800 40.5765 1.0000
99.6400 42.2709 1.0000
99.7000 24.0107 1.0000
99.7600 18.1138 1.0000
99.8200 15.4912 1.0000
99.8800 11.2028 1.0000
99.9400 12.7679 1.0000
100.0000 5.9028 1.0000
100.0600 7.9849 1.0000
100.1200 19.1965 1.0000
100.1800 10.1111 1.0000
100.2400 9.5791 1.0000
100.3000 8.6649 1.0000
100.3600 9.3424 1.0000
100.4200 5.3210 1.0000
100.4800 11.3397 1.0000
100.5400 5.6461 1.0000
100.6000 4.9001 1.0000
100.6600 3.5043 1.0000
100.7200 11.0158 1.0000
100.7800 6.8705 1.0000
100.8400 17.8236 1.0000
100.9000 6.0959 1.0000
100.9600 14.9800 1.0000
101.0200 4.2031 1.0000
101.0800 4.7338 1.0000
101.1400 8.0395 1.0000
101.2000 5.0285 1.0000
101.2600 8.2643 1.0000
101.3200 12.2094 1.0000
101.3800 5.3944 1.0000
101.4400 8.8690 1.0000
101.5000 6.2643 1.0000
101.5600 6.8126 1.0000
101.6200 5.7689 1.0000
101.6800 10.1038 1.0000
101.7400 10.0490 1.0000
101.8000 6.8961 1.0000
101.8600 6.6585 1.0000
101.9200 7.2899 1.0000
101.9800 8.3323 1.0000
102.0400 10.5351 1.0000
102.1000 14.0644 1.0000
102.1600 8.4739 1.0000
102.2200 12.0312 1.0000
102.2800 7.8539 1.0000
102.3400 6.0672 1.0000
102.4000 7.5106 1.0000
102.4600 8.7956 1.0000
102.5200 9.8624 1.0000
102.5800 8.5431 1.0000
102.6400 5.7842 1.0000
102.7000 10.4254 1.0000
102.7600 4.1945 1.0000
102.8200 9.1195 1.0000
102.8800 15.3122 1.0000
102.9400 4.8317 1.0000
103.0000 7.7069 1.0000
103.0600 8.8184 1.0000
103.1200 5.2535 1.0000
103.1800 4.4578 1.0000
103.2400 3.6611 1.0000
103.3000 6.2207 1.0000
103.3600 11.3313 1.0000
103.4200 9.4109 1.0000
103.4800 9.2505 1.0000
103.5400 8.3663 1.0000
103.6000 5.5062 1.0000
103.6600 11.6026 1.0000
103.7200 8.2851 1.0000
103.7800 6.9459 1.0000
103.8400 9.9584 1.0000
103.9000 12.8593 1.0000
103.9600 6.8542 1.0000
104.0200 9.6812 1.0000
104.0800 7.9078 1.0000
104.1400 7.9736 1.0000
104.2000 7.6720 1.0000
104.2600 3.4245 1.0000
104.3200 8.6512 1.0000
104.3800 10.7040 1.0000
104.4400 13.4022 1.0000
104.5000 8.6919 1.0000
104.5600 9.9795 1.0000
104.6200 4.2097 1.0000
104.6800 7.5308 1.0000
104.7400 13.8919 1.0000
104.8000 7.7664 1.0000
104.8600 13.1820 1.0000
104.9200 6.2598 1.0000
104.9800 6.4472 1.0000
105.0400 4.2426 1.0000
105.1000 6.7241 1.0000
105.1600 11.8169 1.0000
105.2200 8.8543 1.0000
105.2800 8.6330 1.0000
105.3400 4.0675 1.0000
105.4000 6.0928 1.0000
105.4600 10.8813 1.0000
105.5200 9.8169 1.0000
105.5800 7.2836 1.0000
105.6400 6.2929 1.0000
105.7000 9.8853 1.0000
105.7600 6.2198 1.0000
105.8200 7.6288 1.0000
105.8800 11.3216 1.0000
105.9400 13.8264 1.0000
106.0000 10.1889 1.0000
106.0600 9.7147 1.0000
106.1200 10.7736 1.0000
106.1800 8.5524 1.0000
106.2400 9.1868 1.0000
106.3000 7.6747 1.0000
106.3600 7.3584 1.0000
106.4200 6.0246 1.0000
106.4800 10.3406 1.0000
106.5400 15.2492 1.0000
106.6000 8.6451 1.0000
106.6600 5.4806 1.0000
106.7200 7.4737 1.0000
106.7800 11.2811 1.0000
106.8400 6.1811 1.0000
106.9000 9.2685 1.0000
106.9600 6.8728 1.0000
107.0200 8.1847 1.0000
107.0800 6.5202 1.0000
107.1400 15.6153 1.0000
107.2000 7.3951 1.0000
107.2600 8.7824 1.0000
107.3200 6.2669 1.0000
107.3800 13.0681 1.0000
107.4400 4.4933 1.0000
107.5000 4.6978 1.0000
107.5600 7.0783 1.0000
107.6200 5.0417 1.0000
107.6800 7.2264 1.0000
107.7400 8.0944 1.0000
107.8000 7.6269 1.0000
107.8600 10.1468 1.0000
107.9200 7.5550 1.0000
107.9800 5.0010 1.0000
108.0400 6.5568 1.0000
108.1000 9.3499 1.0000
108.1600 8.1591 1.0000
108.2200 5.5919 1.0000
108.2800 10.8525 1.0000
108.3400 6.6612 1.0000
108.4000 8.3490 1.0000
108.4600 4.6177 1.0000
108.5200 7.4144 1.0000
108.5800 2.4190 1.0000
108.6400 10.6109 1.0000
108.7000 9.5934 1.0000
108.7600 11.6855 1.0000
108.8200 10.2606 1.0000
108.8800 7.2092 1.0000
108.9400 4.3978 1.0000
109.0000 5.0532 1.0000
109.0600 4.6635 1.0000
109.1200 4.4222 1.0000
109.1800 1.6569 1.0000
109.2400 8.5582 1.0000
109.3000 9.5963 1.0000
109.3600 9.3687 1.0000
109.4200 4.3078 1.0000
109.4800 6.7659 1.0000
109.5400 6.3517 1.0000
109.6000 7.4845 1.0000
109.6600 6.1331 1.0000
109.7200 8.8828 1.0000
109.7800 11.9321 1.0000
109.8400 6.5499 1.0000
109.9000 7.4321 1.0000
109.9600 7.4492 1.0000
110.0200 4.6734 1.0000
110.0800 3.3740 1.0000
110.1400 10.3683 1.0000
110.2000 6.8497 1.0000
110.2600 6.1756 1.0000
110.3200 10.2325 1.0000
110.3800 8.2427 1.0000
110.4400 6.2883 1.0000
110.5000 9.2263 1.0000
110.5600 8.5936 1.0000
110.6200 6.5562 1.0000
110.6800 8.2713 1.0000
110.7400 8.1496 1.0000
110.8000 6.9623 1.0000
110.8600 6.5312 1.0000
110.9200 8.1619 1.0000
110.9800 11.2765 1.0000
111.0400 6.5541 1.0000
111.1000 10.9216 1.0000
111.1600 4.2292 1.0000
111.2200 6.7170 1.0000
111.2800 9.8496 1.0000
111.3400 9.3805 1.0000
111.4000 8.8927 1.0000
111.4600 7.7117 1.0000
111.5200 8.0110 1.0000
111.5800 10.9521 1.0000
111.6400 10.4476 1.0000
111.7000 5.7465 1.0000
111.7600 12.2449 1.0000
111.8200 8.1794 1.0000
111.8800 5.2795 1.0000
111.9400 5.2077 1.0000
112.0000 6.6756 1.0000
112.0600 6.2850 1.0000
112.1200 8.9461 1.0000
112.1800 8.7435 1.0000
112.2400 6.1269 1.0000
112.3000 7.2369 1.0000
112.3600 8.9180 1.0000
112.4200 3.3926 1.0000
112.4800 4.4647 1.0000
112.5400 7.3862 1.0000
112.6000 10.1450 1.0000
112.6600 9.7806 1.0000
112.7200 13.6335 1.0000
112.7800 11.0320 1.0000
112.8400 11.3062 1.0000
112.9000 2.9755 1.0000
112.9600 9.3298 1.0000
113.0200 8.2162 1.0000
113.0800 7.4869 1.0000
113.1400 8.1502 1.0000
113.2000 4.5594 1.0000
113.2600 2.2907 1.0000
113.3200 9.2719 1.0000
113.3800 3.7524 1.0000
113.4400 16.5613 1.0000
113.5000 7.3773 1.0000
113.5600 5.1367 1.0000
113.6200 9.1369 1.0000
113.6800 10.8968 1.0000
113.7400 9.6145 1.0000
113.8000 14.1132 1.0000
113.8600 11.1287 1.0000
113.9200 9.8978 1.0000
113.9800 6.8516 1.0000
114.0400 5.6669 1.0000
114.1000 12.3060 1.0000
114.1600 15.5339 1.0000
114.2200 8.4133 1.0000
114.2800 7.1992 1.0000
114.3400 6.9788 1.0000
114.4000 8.7077 1.0000
114.4600 6.4371 1.0000
114.5200 4.0099 1.0000
114.5800 13.3507 1.0000
114.6400 7.4412 1.0000
114.7000 12.8739 1.0000
114.7600 5.6983 1.0000
114.8200 9.4713 1.0000
114.8800 6.8115 1.0000
114.9400 5.6685 1.0000
115.0000 8.7560 1.0000
115.0600 9.5360 1.0000
115.1200 4.9022 1.0000
115.1800 7.5208 1.0000
115.2400 5.4766 1.0000
115.3000 5.6518 1.0000
115.3600 8.1686 1.0000
115.4200 7.7437 1.0000
115.4800 9.5972 1.0000
115.5400 8.2329 1.0000
115.6000 6.4406 1.0000
115.6600 13.5589 1.0000
115.7200 7.7740 1.0000
115.7800 6.2974 1.0000
115.8400 6.1746 1.0000
115.9000 3.1444 1.0000
115.9600 7.2620 1.0000
116.0200 6.6872 1.0000
116.0800 6.2141 1.0000
116.1400 6.7464 1.0000
116.2000 9.6003 1.0000
116.2600 8.5764 1.0000
116.3200 11.3090 1.0000
116.3800 9.2784 1.0000
116.4400 10.0137 1.0000
116.5000 13.3788 1.0000
116.5600 12.8447 1.0000
116.6200 11.3697 1.0000
116.6800 10.9740 1.0000
116.7400 18.3252 1.0000
116.8000 25.8540 1.0000
116.8600 26.8558 1.0000
116.9200 19.2812 1.0000
116.9800 27.4703 1.0000
117.0400 16.1125 1.0000
117.1000 11.7110 1.0000
117.1600 11.9838 1.0000
117.2200 12.9467 1.0000
117.2800 5.5184 1.0000
117.3400 4.2081 1.0000
117.4000 10.6977 1.0000
117.4600 6.6937 1.0000
117.5200 6.1985 1.0000
117.5800 4.2299 1.0000
117.6400 8.3135 1.0000
117.7000 7.2828 1.0000
117.7600 6.9540 1.0000
117.8200 7.5312 1.0000
117.8800 3.3450 1.0000
117.9400 9.6642 1.0000
118.0000 9.6066 1.0000
118.0600 3.0704 1.0000
118.1200 7.3142 1.0000
118.1800 6.5849 1.0000
118.2400 12.7002 1.0000
118.3000 10.0868 1.0000
118.3600 7.6258 1.0000
118.4200 7.2737 1.0000
118.4800 8.6561 1.0000
118.5400 3.9815 1.0000
118.6000 9.4666 1.0000
118.6600 7.2992 1.0000
118.7200 8.5084 1.0000
118.7800 4.0264 1.0000
118.8400 4.1332 1.0000
118.9000 13.0947 1.0000
118.9600 7.3394 1.0000
119.0200 4.7431 1.0000
119.0800 11.1188 1.0000
119.1400 4.7591 1.0000
119.2000 13.0601 1.0000
119.2600 10.6373 1.0000
119.3200 15.0333 1.0000
119.3800 3.9592 1.0000
119.4400 8.5830 1.0000
119.5000 10.4337 1.0000
119.5600 9.8677 1.0000
119.6200 9.2837 1.0000
119.6800 8.3659 1.0000
119.7400 7.2666 1.0000
119.8000 10.0093 1.0000
119.8600 6.5964 1.0000
119.9200 6.2932 1.0000
119.9800 10.7184 1.0000
119.9900 8.3198 1.0000
*RAS_INT_END
*RAS_TEMPERATURE_START
*RAS_TEMPERATURE_END
*RAS_DATA_END