File: XRD/May_2022/EFRW1_Unirradiated_region/PB_Ge220_2.5SS_500umDS_RS1_Rod_2.5SS_Hypix1D_EFRW1_Weld_Centre_Unirradiated.ras
*RAS_DATA_START
*RAS_HEADER_START
*DISP_FMT_X "%.3f"
*DISP_FMT_Y "%.0f"
*DISP_FULLSCALE "241.9350078786"
*DISP_LINE_COLOR "255.0000000000"
*DISP_LINE_STYLE "0.0000000000"
*DISP_LINE_WIDTH "0.2500000000"
*DISP_NOTE "Collected Data-224"
*DISP_OFFSET_Y "0.0000000000"
*DISP_PEAKSEARCH_UNIT_Y "cps"
*DISP_RANGE_BOTTOM "0.0000000000"
*DISP_RANGE_LEFT "40.0000000000"
*DISP_RANGE_LOGCUTOFF "0.0100000000"
*DISP_RANGE_RIGHT "119.9968000000"
*DISP_RANGE_TOP "241.9350078786"
*DISP_SCALE_MODE_Y "0.0000000000"
*DISP_TAB_NAME "Theta/2-Theta"
*DISP_TITLE_Y "Intensity"
*DISP_UNIT_Y "cps"
*DISP_WINDOW_NAME "MSG_MACROENGINE"
*FILE_COMMENT " "
*FILE_MD5 ""
*FILE_MEMO " "
*FILE_OPERATOR "Administrator"
*FILE_PART_ID "MEAS_KHP2_00061"
*FILE_SAMPLE " "
*FILE_TYPE "RAS_RAW"
*FILE_USERGROUP "System Manager"
*FILE_VERSION "1.0000000000"
*HW_ATTACHMENT_ID "ATT0021"
*HW_ATTACHMENT_NAME "XY-20mm|XY-20mm"
*HW_COUNTER_ID-0 "CUT0041"
*HW_COUNTER_ID-1 "CUT0051"
*HW_COUNTER_ID-2 "CUT0020"
*HW_COUNTER_ID-3 "CSL0021"
*HW_COUNTER_ID-4 "CMC0021"
*HW_COUNTER_NAME-0 "D/teX Ultra 250|D/teX Ultra 250"
*HW_COUNTER_NAME-1 "HyPix 3000(H)|HyPix 3000(H)"
*HW_COUNTER_NAME-2 "None|None"
*HW_COUNTER_NAME-3 "BBM|BBM"
*HW_COUNTER_NAME-4 "検出器モノクロメータ|Detector monochromator"
*HW_COUNTER_SELECT_NAME "HyPix 3000(H)|HyPix 3000(H)"
*HW_GONIOMETER_ID "GON0024"
*HW_GONIOMETER_NAME "SmartLab(In-plane)|SmartLab(In-plane)"
*HW_GONIOMETER_RADIUS-0 "90.0"
*HW_GONIOMETER_RADIUS-1 "114.0"
*HW_GONIOMETER_RADIUS-2 "190.0"
*HW_GONIOMETER_RADIUS-3 "300.0"
*HW_GONIOMETER_RADIUS-4 "187.0"
*HW_GONIOMETER_RADIUS-5 "300.0"
*HW_GONIOMETER_RADIUS-6 "113.0"
*HW_GONIOMETER_RADIUS-7 "331.0"
*HW_I_OPT_ID-0 "CBO0021"
*HW_I_OPT_ID-1 "ICR0021"
*HW_I_OPT_ID-2 "ISL0021"
*HW_I_OPT_ID-3 "ISO0021"
*HW_I_OPT_ID-4 "IAD0021"
*HW_I_OPT_ID-5 "IPR0001"
*HW_I_OPT_NAME-0 "CBOユニット|CBO unit"
*HW_I_OPT_NAME-1 "標準入射光学ユニット|Standard incident optical unit"
*HW_I_OPT_NAME-2 "標準入射スリットボックス|Standard incident slit box"
*HW_I_OPT_NAME-3 "入射平行スリット|Incident parallel slit"
*HW_I_OPT_NAME-4 "長手制限スリット|Length limiting slit"
*HW_I_OPT_NAME-5 "None|None"
*HW_R_ATTENUATER_AUTOMODE "0"
*HW_R_OPT_ID-0 "RSS0022"
*HW_R_OPT_ID-1 "RCR0022"
*HW_R_OPT_ID-2 "RSO0021"
*HW_R_OPT_ID-3 "RRS0022"
*HW_R_OPT_ID-4 "ATN0020"
*HW_R_OPT_ID-5 "RFL0021"
*HW_R_OPT_ID-6 "RAD0021"
*HW_R_OPT_NAME-0 "受光スリットボックス1(Zr軸付)|Receiving slit box # 1 (w/ Zr Axis)"
*HW_R_OPT_NAME-1 "標準受光光学ユニット1|Standard receiving unit # 1"
*HW_R_OPT_NAME-2 "標準受光光学ユニット2|Standard receiving optical unit # 2"
*HW_R_OPT_NAME-3 "仮想受光スリット2|Virtual receiving slit #2"
*HW_R_OPT_NAME-4 "無し|None"
*HW_R_OPT_NAME-5 "Cu Kβ|Cu K-beta"
*HW_R_OPT_NAME-6 "調整用受光スリット|Alignment receiving slit"
*HW_SAMPLE_HOLDER_ID "SMP0021"
*HW_SAMPLE_HOLDER_NAME "χφZクレードル|Chi phi Z cradle"
*HW_XG_CURRENT_MAX "40"
*HW_XG_CURRENT_MIN "2"
*HW_XG_CURRENT_RESOLUTION "1"
*HW_XG_CURRENT_UNIT "mA"
*HW_XG_FOCUS "0.4mm x 8mm"
*HW_XG_FOCUS_TYPE "Fine"
*HW_XG_ID "1200"
*HW_XG_NAME "3kW 封入管(ID:1200)|3kW Sealed tube(ID:1200)"
*HW_XG_TARGET_ATOMIC_NUMBER "29.0000000000"
*HW_XG_TARGET_NAME "Cu"
*HW_XG_TYPE "Hermetic"
*HW_XG_VOLTAGE_MAX "40"
*HW_XG_VOLTAGE_MIN "20"
*HW_XG_VOLTAGE_RESOLUTION "1"
*HW_XG_VOLTAGE_UNIT "kV"
*HW_XG_WATT_MAX "1.500"
*HW_XG_WATT_UNIT "kW"
*HW_XG_WAVE_LENGTH_ALPHA1 "1.540593"
*HW_XG_WAVE_LENGTH_ALPHA2 "1.544414"
*HW_XG_WAVE_LENGTH_BETA "1.392250"
*MEAS_COND_AXIS_NAME-0 "Theta/2-Theta"
*MEAS_COND_AXIS_NAME-1 "2-Theta"
*MEAS_COND_AXIS_NAME-2 "Omega"
*MEAS_COND_AXIS_NAME-3 "Chi"
*MEAS_COND_AXIS_NAME-4 "Phi"
*MEAS_COND_AXIS_NAME-5 "Z"
*MEAS_COND_AXIS_NAME-6 "X"
*MEAS_COND_AXIS_NAME-7 "Y"
*MEAS_COND_AXIS_NAME-8 "2-Theta/Omega"
*MEAS_COND_AXIS_NAME-9 "2-ThetaChi"
*MEAS_COND_AXIS_NAME-10 "2-ThetaChi/Phi"
*MEAS_COND_AXIS_NAME-11 "Alpha"
*MEAS_COND_AXIS_NAME-12 "Beta"
*MEAS_COND_AXIS_NAME-13 "Theta_s"
*MEAS_COND_AXIS_NAME-14 "Theta_d"
*MEAS_COND_AXIS_NAME-15 "Ts"
*MEAS_COND_AXIS_NAME-16 "CBO selection slit"
*MEAS_COND_AXIS_NAME-17 "M"
*MEAS_COND_AXIS_NAME-18 "Incident parallel slit"
*MEAS_COND_AXIS_NAME-19 "Incident slit"
*MEAS_COND_AXIS_NAME-20 ""
*MEAS_COND_AXIS_NAME-21 "Zs"
*MEAS_COND_AXIS_NAME-22 "Incident optical device"
*MEAS_COND_AXIS_NAME-23 "Omega_m"
*MEAS_COND_AXIS_NAME-24 "Length limiting slit"
*MEAS_COND_AXIS_NAME-25 "Center slit"
*MEAS_COND_AXIS_NAME-26 "Filter"
*MEAS_COND_AXIS_NAME-27 "Receiving slit # 1"
*MEAS_COND_AXIS_NAME-28 "Receiving slit # 2"
*MEAS_COND_AXIS_NAME-29 "Receiving optical device"
*MEAS_COND_AXIS_NAME-30 "Receiving parallel slit"
*MEAS_COND_AXIS_NAME-31 "Alignment receiving slit"
*MEAS_COND_AXIS_NAME-32 ""
*MEAS_COND_AXIS_NAME-33 ""
*MEAS_COND_AXIS_NAME-34 "Zd"
*MEAS_COND_AXIS_NAME-35 "Attenuator"
*MEAS_COND_AXIS_NAME-36 "Diffracted beam monochromator"
*MEAS_COND_AXIS_NAME-37 "Monochromator slit"
*MEAS_COND_AXIS_NAME-38 "2-ThetaB"
*MEAS_COND_AXIS_NAME-39 ""
*MEAS_COND_AXIS_NAME-40 ""
*MEAS_COND_AXIS_NAME-41 "Zr"
*MEAS_COND_AXIS_NAME-42 "Primary beam"
*MEAS_COND_AXIS_NAME_INTERNAL-0 "TwoThetaTheta"
*MEAS_COND_AXIS_NAME_INTERNAL-1 "TwoTheta"
*MEAS_COND_AXIS_NAME_INTERNAL-2 "Omega"
*MEAS_COND_AXIS_NAME_INTERNAL-3 "Chi"
*MEAS_COND_AXIS_NAME_INTERNAL-4 "Phi"
*MEAS_COND_AXIS_NAME_INTERNAL-5 "Z"
*MEAS_COND_AXIS_NAME_INTERNAL-6 "X"
*MEAS_COND_AXIS_NAME_INTERNAL-7 "Y"
*MEAS_COND_AXIS_NAME_INTERNAL-8 "TwoThetaOmega"
*MEAS_COND_AXIS_NAME_INTERNAL-9 "TwoThetaChi"
*MEAS_COND_AXIS_NAME_INTERNAL-10 "TwoThetaChiPhi"
*MEAS_COND_AXIS_NAME_INTERNAL-11 "Alpha"
*MEAS_COND_AXIS_NAME_INTERNAL-12 "Beta"
*MEAS_COND_AXIS_NAME_INTERNAL-13 "ThetaS"
*MEAS_COND_AXIS_NAME_INTERNAL-14 "ThetaD"
*MEAS_COND_AXIS_NAME_INTERNAL-15 "Ts"
*MEAS_COND_AXIS_NAME_INTERNAL-16 "CBO"
*MEAS_COND_AXIS_NAME_INTERNAL-17 "CBO-M"
*MEAS_COND_AXIS_NAME_INTERNAL-18 "IncidentSollerSlit"
*MEAS_COND_AXIS_NAME_INTERNAL-19 "IncidentSlitBox"
*MEAS_COND_AXIS_NAME_INTERNAL-20 "IncidentSlitBox-_Axis"
*MEAS_COND_AXIS_NAME_INTERNAL-21 "Zs"
*MEAS_COND_AXIS_NAME_INTERNAL-22 "IncidentMonochromator"
*MEAS_COND_AXIS_NAME_INTERNAL-23 "IncidentMonochromator-OmegaM"
*MEAS_COND_AXIS_NAME_INTERNAL-24 "IncidentAxdSlit"
*MEAS_COND_AXIS_NAME_INTERNAL-25 "CenterSlit"
*MEAS_COND_AXIS_NAME_INTERNAL-26 "Filter"
*MEAS_COND_AXIS_NAME_INTERNAL-27 "ReceivingSlitBox1"
*MEAS_COND_AXIS_NAME_INTERNAL-28 "ReceivingSlitBox2"
*MEAS_COND_AXIS_NAME_INTERNAL-29 "ReceivingOptics"
*MEAS_COND_AXIS_NAME_INTERNAL-30 "ReceivingSollerSlit"
*MEAS_COND_AXIS_NAME_INTERNAL-31 "ReceivingAxdSlit"
*MEAS_COND_AXIS_NAME_INTERNAL-32 "ReceivingSlitBox1-_Axis"
*MEAS_COND_AXIS_NAME_INTERNAL-33 "ReceivingSlitBox2-_Axis"
*MEAS_COND_AXIS_NAME_INTERNAL-34 "ReceivingSlitBox2-Zd"
*MEAS_COND_AXIS_NAME_INTERNAL-35 "Attenuator"
*MEAS_COND_AXIS_NAME_INTERNAL-36 "CounterMonochromator"
*MEAS_COND_AXIS_NAME_INTERNAL-37 "CounterSlit"
*MEAS_COND_AXIS_NAME_INTERNAL-38 "TwoThetaB"
*MEAS_COND_AXIS_NAME_INTERNAL-39 "AlphaR"
*MEAS_COND_AXIS_NAME_INTERNAL-40 "BetaR"
*MEAS_COND_AXIS_NAME_INTERNAL-41 "ReceivingSlitBox1-Zr"
*MEAS_COND_AXIS_NAME_INTERNAL-42 "IncidentPrimary"
*MEAS_COND_AXIS_NAME_MAGICNO-0 "83951616.0000000000"
*MEAS_COND_AXIS_NAME_MAGICNO-1 "268632064.0000000000"
*MEAS_COND_AXIS_NAME_MAGICNO-2 "268500992.0000000000"
*MEAS_COND_AXIS_NAME_MAGICNO-3 "268500992.0000000000"
*MEAS_COND_AXIS_NAME_MAGICNO-4 "268500992.0000000000"
*MEAS_COND_AXIS_NAME_MAGICNO-5 "285278208.0000000000"
*MEAS_COND_AXIS_NAME_MAGICNO-6 "268500992.0000000000"
*MEAS_COND_AXIS_NAME_MAGICNO-7 "268500992.0000000000"
*MEAS_COND_AXIS_NAME_MAGICNO-8 "83951616.0000000000"
*MEAS_COND_AXIS_NAME_MAGICNO-9 "268632064.0000000000"
*MEAS_COND_AXIS_NAME_MAGICNO-10 "83951616.0000000000"
*MEAS_COND_AXIS_NAME_MAGICNO-11 "17039360.0000000000"
*MEAS_COND_AXIS_NAME_MAGICNO-12 "17039360.0000000000"
*MEAS_COND_AXIS_NAME_MAGICNO-13 "131072.0000000000"
*MEAS_COND_AXIS_NAME_MAGICNO-14 "131072.0000000000"
*MEAS_COND_AXIS_NAME_MAGICNO-15 "318898176.0000000000"
*MEAS_COND_AXIS_NAME_MAGICNO-16 "20971521.0000000000"
*MEAS_COND_AXIS_NAME_MAGICNO-17 "285343744.0000000000"
*MEAS_COND_AXIS_NAME_MAGICNO-18 "20971521.0000000000"
*MEAS_COND_AXIS_NAME_MAGICNO-19 "22020097.0000000000"
*MEAS_COND_AXIS_NAME_MAGICNO-20 "25165824.0000000000"
*MEAS_COND_AXIS_NAME_MAGICNO-21 "318898176.0000000000"
*MEAS_COND_AXIS_NAME_MAGICNO-22 "20971521.0000000000"
*MEAS_COND_AXIS_NAME_MAGICNO-23 "285343744.0000000000"
*MEAS_COND_AXIS_NAME_MAGICNO-24 "20971521.0000000000"
*MEAS_COND_AXIS_NAME_MAGICNO-25 "20971521.0000000000"
*MEAS_COND_AXIS_NAME_MAGICNO-26 "20971521.0000000000"
*MEAS_COND_AXIS_NAME_MAGICNO-27 "23068673.0000000000"
*MEAS_COND_AXIS_NAME_MAGICNO-28 "23068673.0000000000"
*MEAS_COND_AXIS_NAME_MAGICNO-29 "20971521.0000000000"
*MEAS_COND_AXIS_NAME_MAGICNO-30 "20971521.0000000000"
*MEAS_COND_AXIS_NAME_MAGICNO-31 "20971521.0000000000"
*MEAS_COND_AXIS_NAME_MAGICNO-32 "25165824.0000000000"
*MEAS_COND_AXIS_NAME_MAGICNO-33 "25165824.0000000000"
*MEAS_COND_AXIS_NAME_MAGICNO-34 "285343744.0000000000"
*MEAS_COND_AXIS_NAME_MAGICNO-35 "0.0000000000"
*MEAS_COND_AXIS_NAME_MAGICNO-36 "20971521.0000000000"
*MEAS_COND_AXIS_NAME_MAGICNO-37 "20971521.0000000000"
*MEAS_COND_AXIS_NAME_MAGICNO-38 "17039360.0000000000"
*MEAS_COND_AXIS_NAME_MAGICNO-39 "8388608.0000000000"
*MEAS_COND_AXIS_NAME_MAGICNO-40 "8388608.0000000000"
*MEAS_COND_AXIS_NAME_MAGICNO-41 "285343744.0000000000"
*MEAS_COND_AXIS_NAME_MAGICNO-42 "20971521.0000000000"
*MEAS_COND_AXIS_OFFSET-0 "-"
*MEAS_COND_AXIS_OFFSET-1 "0.9151000000"
*MEAS_COND_AXIS_OFFSET-2 "-0.1071000000"
*MEAS_COND_AXIS_OFFSET-3 "0.0000000000"
*MEAS_COND_AXIS_OFFSET-4 "0.0000000000"
*MEAS_COND_AXIS_OFFSET-5 "-"
*MEAS_COND_AXIS_OFFSET-6 "0.0000000000"
*MEAS_COND_AXIS_OFFSET-7 "0.0000000000"
*MEAS_COND_AXIS_OFFSET-8 "-"
*MEAS_COND_AXIS_OFFSET-9 "0.0000000000"
*MEAS_COND_AXIS_OFFSET-10 "-"
*MEAS_COND_AXIS_OFFSET-11 "-"
*MEAS_COND_AXIS_OFFSET-12 "-"
*MEAS_COND_AXIS_OFFSET-13 "-0.1071000000"
*MEAS_COND_AXIS_OFFSET-14 "1.0222000000"
*MEAS_COND_AXIS_OFFSET-15 "-"
*MEAS_COND_AXIS_OFFSET-16 "-"
*MEAS_COND_AXIS_OFFSET-17 "-"
*MEAS_COND_AXIS_OFFSET-18 "-"
*MEAS_COND_AXIS_OFFSET-19 "-"
*MEAS_COND_AXIS_OFFSET-20 "-"
*MEAS_COND_AXIS_OFFSET-21 "-"
*MEAS_COND_AXIS_OFFSET-22 "-"
*MEAS_COND_AXIS_OFFSET-23 "-"
*MEAS_COND_AXIS_OFFSET-24 "-"
*MEAS_COND_AXIS_OFFSET-25 "-"
*MEAS_COND_AXIS_OFFSET-26 "-"
*MEAS_COND_AXIS_OFFSET-27 "-"
*MEAS_COND_AXIS_OFFSET-28 "-"
*MEAS_COND_AXIS_OFFSET-29 "-"
*MEAS_COND_AXIS_OFFSET-30 "-"
*MEAS_COND_AXIS_OFFSET-31 "-"
*MEAS_COND_AXIS_OFFSET-32 "-"
*MEAS_COND_AXIS_OFFSET-33 "-"
*MEAS_COND_AXIS_OFFSET-34 "-"
*MEAS_COND_AXIS_OFFSET-35 "-"
*MEAS_COND_AXIS_OFFSET-36 "-"
*MEAS_COND_AXIS_OFFSET-37 "-"
*MEAS_COND_AXIS_OFFSET-38 "-"
*MEAS_COND_AXIS_OFFSET-39 "0.0000000000"
*MEAS_COND_AXIS_OFFSET-40 "0.0000000000"
*MEAS_COND_AXIS_OFFSET-41 "-"
*MEAS_COND_AXIS_OFFSET-42 "-"
*MEAS_COND_AXIS_POSITION-0 "40.0000000000"
*MEAS_COND_AXIS_POSITION-1 "40.0000000000"
*MEAS_COND_AXIS_POSITION-2 "20.0000000000"
*MEAS_COND_AXIS_POSITION-3 "0.0000000000"
*MEAS_COND_AXIS_POSITION-4 "0.0000000000"
*MEAS_COND_AXIS_POSITION-5 "-3.5486000000"
*MEAS_COND_AXIS_POSITION-6 "1.3645000000"
*MEAS_COND_AXIS_POSITION-7 "0.0000000000"
*MEAS_COND_AXIS_POSITION-8 "40.0000000000"
*MEAS_COND_AXIS_POSITION-9 "0.0000000000"
*MEAS_COND_AXIS_POSITION-10 "0.0000000000"
*MEAS_COND_AXIS_POSITION-11 "90.0000000000"
*MEAS_COND_AXIS_POSITION-12 "0.0000000000"
*MEAS_COND_AXIS_POSITION-13 "20.0000000000"
*MEAS_COND_AXIS_POSITION-14 "20.0000000000"
*MEAS_COND_AXIS_POSITION-15 "-5.5036300000"
*MEAS_COND_AXIS_POSITION-16 "PB"
*MEAS_COND_AXIS_POSITION-17 "0.0000000000"
*MEAS_COND_AXIS_POSITION-18 "Soller_slit_2.5deg_s"
*MEAS_COND_AXIS_POSITION-19 "1.000mm"
*MEAS_COND_AXIS_POSITION-20 "1.0000000000"
*MEAS_COND_AXIS_POSITION-21 "-1.0678100000"
*MEAS_COND_AXIS_POSITION-22 "Ge(220)x2"
*MEAS_COND_AXIS_POSITION-23 "0.0000000000"
*MEAS_COND_AXIS_POSITION-24 "0.5mm"
*MEAS_COND_AXIS_POSITION-25 "None"
*MEAS_COND_AXIS_POSITION-26 "None"
*MEAS_COND_AXIS_POSITION-27 "20.000mm"
*MEAS_COND_AXIS_POSITION-28 "38.500mm"
*MEAS_COND_AXIS_POSITION-29 "PSA_open"
*MEAS_COND_AXIS_POSITION-30 "Soller_slit_2.5deg"
*MEAS_COND_AXIS_POSITION-31 "None"
*MEAS_COND_AXIS_POSITION-32 "20.0000000000"
*MEAS_COND_AXIS_POSITION-33 "38.5000000000"
*MEAS_COND_AXIS_POSITION-34 "0.0000000000"
*MEAS_COND_AXIS_POSITION-35 "-"
*MEAS_COND_AXIS_POSITION-36 "No_unit"
*MEAS_COND_AXIS_POSITION-37 "None"
*MEAS_COND_AXIS_POSITION-38 "40.0000000000"
*MEAS_COND_AXIS_POSITION-39 "0.0000000000"
*MEAS_COND_AXIS_POSITION-40 "0.0000000000"
*MEAS_COND_AXIS_POSITION-41 "0.1412500000"
*MEAS_COND_AXIS_POSITION-42 "None"
*MEAS_COND_AXIS_UNIT-0 "deg"
*MEAS_COND_AXIS_UNIT-1 "deg"
*MEAS_COND_AXIS_UNIT-2 "deg"
*MEAS_COND_AXIS_UNIT-3 "deg"
*MEAS_COND_AXIS_UNIT-4 "deg"
*MEAS_COND_AXIS_UNIT-5 "mm"
*MEAS_COND_AXIS_UNIT-6 "mm"
*MEAS_COND_AXIS_UNIT-7 "mm"
*MEAS_COND_AXIS_UNIT-8 "deg"
*MEAS_COND_AXIS_UNIT-9 "deg"
*MEAS_COND_AXIS_UNIT-10 "deg"
*MEAS_COND_AXIS_UNIT-11 "deg"
*MEAS_COND_AXIS_UNIT-12 "deg"
*MEAS_COND_AXIS_UNIT-13 "deg"
*MEAS_COND_AXIS_UNIT-14 "deg"
*MEAS_COND_AXIS_UNIT-15 "mm"
*MEAS_COND_AXIS_UNIT-16 ""
*MEAS_COND_AXIS_UNIT-17 "pulse"
*MEAS_COND_AXIS_UNIT-18 ""
*MEAS_COND_AXIS_UNIT-19 ""
*MEAS_COND_AXIS_UNIT-20 "mm"
*MEAS_COND_AXIS_UNIT-21 "mm"
*MEAS_COND_AXIS_UNIT-22 ""
*MEAS_COND_AXIS_UNIT-23 "pulse"
*MEAS_COND_AXIS_UNIT-24 ""
*MEAS_COND_AXIS_UNIT-25 ""
*MEAS_COND_AXIS_UNIT-26 ""
*MEAS_COND_AXIS_UNIT-27 ""
*MEAS_COND_AXIS_UNIT-28 ""
*MEAS_COND_AXIS_UNIT-29 ""
*MEAS_COND_AXIS_UNIT-30 ""
*MEAS_COND_AXIS_UNIT-31 ""
*MEAS_COND_AXIS_UNIT-32 "mm"
*MEAS_COND_AXIS_UNIT-33 "mm"
*MEAS_COND_AXIS_UNIT-34 "mm"
*MEAS_COND_AXIS_UNIT-35 ""
*MEAS_COND_AXIS_UNIT-36 ""
*MEAS_COND_AXIS_UNIT-37 ""
*MEAS_COND_AXIS_UNIT-38 "deg"
*MEAS_COND_AXIS_UNIT-39 "deg"
*MEAS_COND_AXIS_UNIT-40 "deg"
*MEAS_COND_AXIS_UNIT-41 "mm"
*MEAS_COND_AXIS_UNIT-42 ""
*MEAS_COND_COUNTER_CNTLOSS_CORR "0.0000000000"
*MEAS_COND_COUNTER_TAUDIFF "0.0000000000"
*MEAS_COND_COUNTER_TAUINT "0.0000000000"
*MEAS_COND_COUNTER_TEMP_CONDITION "NORMAL"
*MEAS_COND_IRRADIATION_MODE "OFF"
*MEAS_COND_IRRADIATION_WIDTH ""
*MEAS_COND_OPT_ATTR "High resolution parallel beam Ge(220)x2/RS"
*MEAS_COND_OPT_NAME "@High resolution PB-Ge(220)x2"
*MEAS_COND_UNSYMMETRIC_MODE "OFF"
*MEAS_COND_XG_CURRENT "30.0000000000"
*MEAS_COND_XG_VOLTAGE "40.0000000000"
*MEAS_COND_XG_WAVE_TYPE "Ka1"
*MEAS_DATA_COUNT "8000.0000000000"
*MEAS_SCAN_AXIS_X "Theta/2-Theta"
*MEAS_SCAN_AXIS_X_INTERNAL "TwoThetaTheta"
*MEAS_SCAN_END_TIME "03/29/22 15:12:43"
*MEAS_SCAN_MODE "CONTINUOUS"
*MEAS_SCAN_MONITOR "0"
*MEAS_SCAN_RESOLUTION_X "0.0002"
*MEAS_SCAN_SPEED "0.503240"
*MEAS_SCAN_SPEED_UNIT "deg/min"
*MEAS_SCAN_SPEED_USER "0.5"
*MEAS_SCAN_START "40.0000000000"
*MEAS_SCAN_START_TIME "03/29/22 12:17:53"
*MEAS_SCAN_STEP "0.0100000000"
*MEAS_SCAN_STOP "119.9900000000"
*MEAS_SCAN_UNIT_X "deg"
*MEAS_SCAN_UNIT_Y "counts"
*RAS_HEADER_END
*RAS_INT_START
40.0000 3.4834 1.0000
40.0600 5.9801 1.0000
40.1200 4.1586 1.0000
40.1800 10.4452 1.0000
40.2400 4.5206 1.0000
40.3000 4.8092 1.0000
40.3600 8.2075 1.0000
40.4200 6.0054 1.0000
40.4800 6.0056 1.0000
40.5400 3.1833 1.0000
40.6000 5.1100 1.0000
40.6600 2.7239 1.0000
40.7200 2.4611 1.0000
40.7800 3.7759 1.0000
40.8400 8.7815 1.0000
40.9000 3.2039 1.0000
40.9600 8.3384 1.0000
41.0200 7.2672 1.0000
41.0800 3.7841 1.0000
41.1400 8.2536 1.0000
41.2000 3.4643 1.0000
41.2600 6.4124 1.0000
41.3200 6.3044 1.0000
41.3800 3.5807 1.0000
41.4400 4.0856 1.0000
41.5000 4.1024 1.0000
41.5600 8.2272 1.0000
41.6200 5.6431 1.0000
41.6800 5.5062 1.0000
41.7400 6.9929 1.0000
41.8000 4.2497 1.0000
41.8600 9.0886 1.0000
41.9200 2.7731 1.0000
41.9800 6.2172 1.0000
42.0400 9.1638 1.0000
42.1000 3.6172 1.0000
42.1600 5.2245 1.0000
42.2200 3.6824 1.0000
42.2800 6.2839 1.0000
42.3400 6.5951 1.0000
42.4000 4.4191 1.0000
42.4600 4.4306 1.0000
42.5200 3.9989 1.0000
42.5800 5.2164 1.0000
42.6400 7.1033 1.0000
42.7000 6.1402 1.0000
42.7600 10.0119 1.0000
42.8200 3.4520 1.0000
42.8800 5.5383 1.0000
42.9400 2.7465 1.0000
43.0000 3.5321 1.0000
43.0600 5.7615 1.0000
43.1200 5.7460 1.0000
43.1800 4.8507 1.0000
43.2400 4.4937 1.0000
43.3000 3.2014 1.0000
43.3600 8.1681 1.0000
43.4200 6.0880 1.0000
43.4800 6.3160 1.0000
43.5400 3.1125 1.0000
43.6000 5.0935 1.0000
43.6600 8.1002 1.0000
43.7200 5.3356 1.0000
43.7800 2.2823 1.0000
43.8400 3.1753 1.0000
43.9000 6.2311 1.0000
43.9600 6.2775 1.0000
44.0200 4.0497 1.0000
44.0800 4.1806 1.0000
44.1400 7.7710 1.0000
44.2000 12.1382 1.0000
44.2600 8.4717 1.0000
44.3200 15.6537 1.0000
44.3800 34.3991 1.0000
44.4400 61.5862 1.0000
44.5000 105.1902 1.0000
44.5600 175.4608 1.0000
44.6200 208.3529 1.0000
44.6800 139.2661 1.0000
44.7400 73.6413 1.0000
44.8000 21.9316 1.0000
44.8600 9.8181 1.0000
44.9200 11.1159 1.0000
44.9800 4.7013 1.0000
45.0400 7.2451 1.0000
45.1000 6.3049 1.0000
45.1600 3.9782 1.0000
45.2200 4.9293 1.0000
45.2800 5.4100 1.0000
45.3400 4.5309 1.0000
45.4000 5.6053 1.0000
45.4600 6.2741 1.0000
45.5200 5.6733 1.0000
45.5800 3.0438 1.0000
45.6400 2.1807 1.0000
45.7000 3.7489 1.0000
45.7600 3.5374 1.0000
45.8200 8.0513 1.0000
45.8800 3.2721 1.0000
45.9400 2.2138 1.0000
46.0000 3.6182 1.0000
46.0600 4.3619 1.0000
46.1200 3.2582 1.0000
46.1800 8.1971 1.0000
46.2400 2.4760 1.0000
46.3000 6.2766 1.0000
46.3600 7.7972 1.0000
46.4200 0.4454 1.0000
46.4800 4.9253 1.0000
46.5400 7.6780 1.0000
46.6000 4.7256 1.0000
46.6600 5.9648 1.0000
46.7200 2.2287 1.0000
46.7800 4.6030 1.0000
46.8400 4.3986 1.0000
46.9000 7.0474 1.0000
46.9600 3.9571 1.0000
47.0200 6.2855 1.0000
47.0800 3.1895 1.0000
47.1400 3.2023 1.0000
47.2000 2.9892 1.0000
47.2600 13.2659 1.0000
47.3200 4.1140 1.0000
47.3800 4.6186 1.0000
47.4400 10.7559 1.0000
47.5000 10.8248 1.0000
47.5600 7.0803 1.0000
47.6200 3.4173 1.0000
47.6800 4.1452 1.0000
47.7400 4.4993 1.0000
47.8000 6.7180 1.0000
47.8600 3.7335 1.0000
47.9200 7.7345 1.0000
47.9800 5.3154 1.0000
48.0400 4.0713 1.0000
48.1000 3.2539 1.0000
48.1600 2.1010 1.0000
48.2200 3.1571 1.0000
48.2800 4.6195 1.0000
48.3400 1.2818 1.0000
48.4000 4.7491 1.0000
48.4600 4.0536 1.0000
48.5200 4.0952 1.0000
48.5800 6.2438 1.0000
48.6400 8.9072 1.0000
48.7000 8.3652 1.0000
48.7600 5.4944 1.0000
48.8200 7.2665 1.0000
48.8800 8.7897 1.0000
48.9400 8.0155 1.0000
49.0000 1.9888 1.0000
49.0600 3.1688 1.0000
49.1200 5.7885 1.0000
49.1800 3.1462 1.0000
49.2400 4.0137 1.0000
49.3000 5.3283 1.0000
49.3600 7.8227 1.0000
49.4200 7.1584 1.0000
49.4800 4.2571 1.0000
49.5400 3.5559 1.0000
49.6000 5.4318 1.0000
49.6600 6.3220 1.0000
49.7200 5.1051 1.0000
49.7800 6.1888 1.0000
49.8400 3.3712 1.0000
49.9000 6.8234 1.0000
49.9600 5.7828 1.0000
50.0200 9.2249 1.0000
50.0800 4.4329 1.0000
50.1400 5.1705 1.0000
50.2000 5.6114 1.0000
50.2600 1.4004 1.0000
50.3200 3.3902 1.0000
50.3800 1.6256 1.0000
50.4400 3.1705 1.0000
50.5000 7.1183 1.0000
50.5600 7.9742 1.0000
50.6200 4.7743 1.0000
50.6800 2.8730 1.0000
50.7400 12.8342 1.0000
50.8000 6.3063 1.0000
50.8600 3.3062 1.0000
50.9200 5.0482 1.0000
50.9800 5.9730 1.0000
51.0400 4.7507 1.0000
51.1000 2.4825 1.0000
51.1600 3.1670 1.0000
51.2200 5.1384 1.0000
51.2800 5.1098 1.0000
51.3400 5.0071 1.0000
51.4000 3.5487 1.0000
51.4600 8.8807 1.0000
51.5200 3.1428 1.0000
51.5800 7.4747 1.0000
51.6400 7.5125 1.0000
51.7000 6.0502 1.0000
51.7600 4.6253 1.0000
51.8200 5.4439 1.0000
51.8800 5.1333 1.0000
51.9400 5.5237 1.0000
52.0000 6.2166 1.0000
52.0600 4.7755 1.0000
52.1200 6.8342 1.0000
52.1800 5.8523 1.0000
52.2400 3.7801 1.0000
52.3000 4.9939 1.0000
52.3600 4.9745 1.0000
52.4200 3.2445 1.0000
52.4800 4.0072 1.0000
52.5400 2.5229 1.0000
52.6000 7.1584 1.0000
52.6600 1.2972 1.0000
52.7200 3.9417 1.0000
52.7800 4.9905 1.0000
52.8400 4.0991 1.0000
52.9000 6.7132 1.0000
52.9600 3.9730 1.0000
53.0200 2.4371 1.0000
53.0800 2.7215 1.0000
53.1400 6.1324 1.0000
53.2000 4.3708 1.0000
53.2600 4.1903 1.0000
53.3200 2.7099 1.0000
53.3800 5.2424 1.0000
53.4400 6.1506 1.0000
53.5000 3.1376 1.0000
53.5600 5.1294 1.0000
53.6200 3.4068 1.0000
53.6800 4.2449 1.0000
53.7400 2.7726 1.0000
53.8000 3.9194 1.0000
53.8600 5.4402 1.0000
53.9200 2.4550 1.0000
53.9800 4.8342 1.0000
54.0400 6.3157 1.0000
54.1000 4.9200 1.0000
54.1600 4.9332 1.0000
54.2200 5.6190 1.0000
54.2800 2.1543 1.0000
54.3400 4.1210 1.0000
54.4000 3.6749 1.0000
54.4600 5.1836 1.0000
54.5200 4.1659 1.0000
54.5800 4.8967 1.0000
54.6400 3.3249 1.0000
54.7000 1.9023 1.0000
54.7600 2.1056 1.0000
54.8200 4.0963 1.0000
54.8800 6.2239 1.0000
54.9400 6.3680 1.0000
55.0000 2.1951 1.0000
55.0600 7.4128 1.0000
55.1200 3.7552 1.0000
55.1800 2.3306 1.0000
55.2400 6.2564 1.0000
55.3000 3.2346 1.0000
55.3600 5.0718 1.0000
55.4200 5.8449 1.0000
55.4800 3.7101 1.0000
55.5400 2.3253 1.0000
55.6000 4.7973 1.0000
55.6600 6.2316 1.0000
55.7200 1.0928 1.0000
55.7800 3.5865 1.0000
55.8400 5.4575 1.0000
55.9000 3.3421 1.0000
55.9600 3.2322 1.0000
56.0200 5.4595 1.0000
56.0800 4.1876 1.0000
56.1400 5.8243 1.0000
56.2000 4.4340 1.0000
56.2600 2.0268 1.0000
56.3200 5.2736 1.0000
56.3800 1.9287 1.0000
56.4400 5.7243 1.0000
56.5000 4.0277 1.0000
56.5600 7.0695 1.0000
56.6200 2.4668 1.0000
56.6800 3.0765 1.0000
56.7400 6.7002 1.0000
56.8000 3.1624 1.0000
56.8600 4.6193 1.0000
56.9200 3.2326 1.0000
56.9800 8.4495 1.0000
57.0400 3.1584 1.0000
57.1000 2.3921 1.0000
57.1600 3.2327 1.0000
57.2200 1.3328 1.0000
57.2800 5.0713 1.0000
57.3400 3.6122 1.0000
57.4000 3.3471 1.0000
57.4600 4.8788 1.0000
57.5200 4.4859 1.0000
57.5800 1.6594 1.0000
57.6400 7.4699 1.0000
57.7000 1.6671 1.0000
57.7600 3.1558 1.0000
57.8200 3.7568 1.0000
57.8800 3.9956 1.0000
57.9400 2.1189 1.0000
58.0000 2.4293 1.0000
58.0600 4.6093 1.0000
58.1200 5.1797 1.0000
58.1800 5.3685 1.0000
58.2400 3.4036 1.0000
58.3000 3.9012 1.0000
58.3600 4.2057 1.0000
58.4200 1.7758 1.0000
58.4800 3.3050 1.0000
58.5400 8.6513 1.0000
58.6000 4.2519 1.0000
58.6600 4.2765 1.0000
58.7200 2.4442 1.0000
58.7800 4.2532 1.0000
58.8400 2.8858 1.0000
58.9000 3.2492 1.0000
58.9600 3.9771 1.0000
59.0200 5.2784 1.0000
59.0800 3.0811 1.0000
59.1400 4.4288 1.0000
59.2000 4.6042 1.0000
59.2600 4.7720 1.0000
59.3200 3.9728 1.0000
59.3800 4.4546 1.0000
59.4400 5.3189 1.0000
59.5000 2.6247 1.0000
59.5600 6.7545 1.0000
59.6200 6.8560 1.0000
59.6800 5.1925 1.0000
59.7400 5.3395 1.0000
59.8000 3.2538 1.0000
59.8600 4.1203 1.0000
59.9200 3.7466 1.0000
59.9800 3.4766 1.0000
60.0400 4.9721 1.0000
60.1000 3.4301 1.0000
60.1600 2.7475 1.0000
60.2200 8.0301 1.0000
60.2800 4.0629 1.0000
60.3400 4.7233 1.0000
60.4000 4.0698 1.0000
60.4600 8.7280 1.0000
60.5200 4.8405 1.0000
60.5800 2.7411 1.0000
60.6400 3.9170 1.0000
60.7000 5.4182 1.0000
60.7600 4.2817 1.0000
60.8200 8.0014 1.0000
60.8800 2.7583 1.0000
60.9400 4.7310 1.0000
61.0000 4.8358 1.0000
61.0600 3.3646 1.0000
61.1200 4.0846 1.0000
61.1800 3.2903 1.0000
61.2400 2.1270 1.0000
61.3000 5.2520 1.0000
61.3600 5.1745 1.0000
61.4200 2.7644 1.0000
61.4800 2.7146 1.0000
61.5400 2.7004 1.0000
61.6000 5.0443 1.0000
61.6600 4.2174 1.0000
61.7200 4.3814 1.0000
61.7800 4.6965 1.0000
61.8400 3.0807 1.0000
61.9000 4.2022 1.0000
61.9600 6.4184 1.0000
62.0200 3.1114 1.0000
62.0800 2.0412 1.0000
62.1400 4.2748 1.0000
62.2000 5.9191 1.0000
62.2600 5.8829 1.0000
62.3200 6.7700 1.0000
62.3800 4.8335 1.0000
62.4400 4.7803 1.0000
62.5000 2.9011 1.0000
62.5600 2.5071 1.0000
62.6200 5.3421 1.0000
62.6800 3.4099 1.0000
62.7400 5.4923 1.0000
62.8000 3.3536 1.0000
62.8600 3.5737 1.0000
62.9200 2.7172 1.0000
62.9800 5.6422 1.0000
63.0400 7.5429 1.0000
63.1000 3.6755 1.0000
63.1600 6.0762 1.0000
63.2200 4.1467 1.0000
63.2800 6.0221 1.0000
63.3400 5.7893 1.0000
63.4000 2.5692 1.0000
63.4600 2.0659 1.0000
63.5200 4.6402 1.0000
63.5800 2.0260 1.0000
63.6400 7.4099 1.0000
63.7000 3.6491 1.0000
63.7600 3.0303 1.0000
63.8200 3.2226 1.0000
63.8800 1.4514 1.0000
63.9400 2.5014 1.0000
64.0000 2.0692 1.0000
64.0600 6.1283 1.0000
64.1200 8.1918 1.0000
64.1800 6.0329 1.0000
64.2400 4.8691 1.0000
64.3000 2.4802 1.0000
64.3600 7.1470 1.0000
64.4200 5.9869 1.0000
64.4800 5.5958 1.0000
64.5400 7.2021 1.0000
64.6000 9.6552 1.0000
64.6600 10.1085 1.0000
64.7200 8.5622 1.0000
64.7800 22.5152 1.0000
64.8400 30.3392 1.0000
64.9000 30.4659 1.0000
64.9600 25.8443 1.0000
65.0200 28.5727 1.0000
65.0800 14.0905 1.0000
65.1400 17.1551 1.0000
65.2000 6.0451 1.0000
65.2600 4.1894 1.0000
65.3200 7.2601 1.0000
65.3800 6.0024 1.0000
65.4400 4.1816 1.0000
65.5000 3.4424 1.0000
65.5600 4.8124 1.0000
65.6200 4.2912 1.0000
65.6800 2.2147 1.0000
65.7400 2.6360 1.0000
65.8000 6.2072 1.0000
65.8600 5.4308 1.0000
65.9200 5.0249 1.0000
65.9800 3.9151 1.0000
66.0400 4.8203 1.0000
66.1000 2.2205 1.0000
66.1600 4.1171 1.0000
66.2200 3.3219 1.0000
66.2800 2.9324 1.0000
66.3400 4.3458 1.0000
66.4000 6.1994 1.0000
66.4600 4.6055 1.0000
66.5200 2.5103 1.0000
66.5800 5.7050 1.0000
66.6400 6.8764 1.0000
66.7000 5.7132 1.0000
66.7600 2.5340 1.0000
66.8200 2.6725 1.0000
66.8800 5.4156 1.0000
66.9400 4.6541 1.0000
67.0000 5.0122 1.0000
67.0600 3.3480 1.0000
67.1200 2.5795 1.0000
67.1800 8.3276 1.0000
67.2400 2.0392 1.0000
67.3000 3.7641 1.0000
67.3600 2.0469 1.0000
67.4200 4.3014 1.0000
67.4800 4.9377 1.0000
67.5400 4.8479 1.0000
67.6000 6.2530 1.0000
67.6600 6.3012 1.0000
67.7200 4.9703 1.0000
67.7800 3.5856 1.0000
67.8400 3.2010 1.0000
67.9000 4.5756 1.0000
67.9600 3.9140 1.0000
68.0200 8.1806 1.0000
68.0800 4.5545 1.0000
68.1400 5.9518 1.0000
68.2000 9.0499 1.0000
68.2600 5.0470 1.0000
68.3200 3.7933 1.0000
68.3800 1.2773 1.0000
68.4400 2.3793 1.0000
68.5000 1.4579 1.0000
68.5600 8.5003 1.0000
68.6200 6.3380 1.0000
68.6800 5.0036 1.0000
68.7400 3.7179 1.0000
68.8000 8.4992 1.0000
68.8600 5.3420 1.0000
68.9200 3.2722 1.0000
68.9800 5.9690 1.0000
69.0400 5.7196 1.0000
69.1000 3.9780 1.0000
69.1600 2.8708 1.0000
69.2200 4.9853 1.0000
69.2800 6.8171 1.0000
69.3400 9.7708 1.0000
69.4000 3.6271 1.0000
69.4600 2.6320 1.0000
69.5200 4.1828 1.0000
69.5800 4.8506 1.0000
69.6400 6.7241 1.0000
69.7000 4.6975 1.0000
69.7600 2.0590 1.0000
69.8200 5.9839 1.0000
69.8800 8.6615 1.0000
69.9400 4.3247 1.0000
70.0000 5.2556 1.0000
70.0600 7.7381 1.0000
70.1200 4.5609 1.0000
70.1800 5.4973 1.0000
70.2400 4.3077 1.0000
70.3000 5.7269 1.0000
70.3600 6.2050 1.0000
70.4200 4.4800 1.0000
70.4800 4.1944 1.0000
70.5400 3.2431 1.0000
70.6000 3.9614 1.0000
70.6600 5.5878 1.0000
70.7200 2.5362 1.0000
70.7800 2.5242 1.0000
70.8400 5.7656 1.0000
70.9000 8.3288 1.0000
70.9600 6.4358 1.0000
71.0200 9.1907 1.0000
71.0800 2.4989 1.0000
71.1400 4.9201 1.0000
71.2000 7.0335 1.0000
71.2600 2.7849 1.0000
71.3200 6.4146 1.0000
71.3800 1.8565 1.0000
71.4400 2.5218 1.0000
71.5000 6.5951 1.0000
71.5600 4.3496 1.0000
71.6200 4.2968 1.0000
71.6800 2.2017 1.0000
71.7400 6.9168 1.0000
71.8000 4.4445 1.0000
71.8600 2.0379 1.0000
71.9200 4.6589 1.0000
71.9800 4.0396 1.0000
72.0400 4.2982 1.0000
72.1000 6.9319 1.0000
72.1600 6.3825 1.0000
72.2200 4.5058 1.0000
72.2800 4.4205 1.0000
72.3400 8.0707 1.0000
72.4000 2.7524 1.0000
72.4600 2.2886 1.0000
72.5200 3.6618 1.0000
72.5800 2.6912 1.0000
72.6400 0.5082 1.0000
72.7000 4.3349 1.0000
72.7600 3.2651 1.0000
72.8200 4.7495 1.0000
72.8800 4.1612 1.0000
72.9400 4.7116 1.0000
73.0000 2.2562 1.0000
73.0600 1.5917 1.0000
73.1200 4.4065 1.0000
73.1800 4.3020 1.0000
73.2400 3.9839 1.0000
73.3000 6.2642 1.0000
73.3600 3.1408 1.0000
73.4200 0.9969 1.0000
73.4800 4.7173 1.0000
73.5400 9.0504 1.0000
73.6000 3.5263 1.0000
73.6600 1.6269 1.0000
73.7200 2.1730 1.0000
73.7800 5.8152 1.0000
73.8400 2.3931 1.0000
73.9000 3.6678 1.0000
73.9600 0.2277 1.0000
74.0200 5.7621 1.0000
74.0800 3.8722 1.0000
74.1400 2.4864 1.0000
74.2000 7.3049 1.0000
74.2600 4.1376 1.0000
74.3200 4.7628 1.0000
74.3800 3.9246 1.0000
74.4400 2.8377 1.0000
74.5000 4.8095 1.0000
74.5600 4.2330 1.0000
74.6200 2.9840 1.0000
74.6800 4.8191 1.0000
74.7400 3.6755 1.0000
74.8000 4.0284 1.0000
74.8600 3.6744 1.0000
74.9200 6.6215 1.0000
74.9800 1.3430 1.0000
75.0400 2.2588 1.0000
75.1000 4.6323 1.0000
75.1600 4.2490 1.0000
75.2200 8.2297 1.0000
75.2800 6.3190 1.0000
75.3400 6.0578 1.0000
75.4000 6.1210 1.0000
75.4600 4.0658 1.0000
75.5200 2.3300 1.0000
75.5800 3.6919 1.0000
75.6400 2.0566 1.0000
75.7000 7.3815 1.0000
75.7600 4.0971 1.0000
75.8200 4.7549 1.0000
75.8800 8.1128 1.0000
75.9400 5.5205 1.0000
76.0000 6.9964 1.0000
76.0600 3.6562 1.0000
76.1200 2.2091 1.0000
76.1800 0.1932 1.0000
76.2400 1.7043 1.0000
76.3000 1.3493 1.0000
76.3600 5.5109 1.0000
76.4200 4.9482 1.0000
76.4800 2.1696 1.0000
76.5400 5.6379 1.0000
76.6000 3.2473 1.0000
76.6600 2.0610 1.0000
76.7200 3.7915 1.0000
76.7800 4.3206 1.0000
76.8400 6.0405 1.0000
76.9000 8.9640 1.0000
76.9600 5.2766 1.0000
77.0200 4.1769 1.0000
77.0800 2.0442 1.0000
77.1400 6.2668 1.0000
77.2000 4.8840 1.0000
77.2600 3.1267 1.0000
77.3200 5.0592 1.0000
77.3800 4.1824 1.0000
77.4400 4.8925 1.0000
77.5000 4.9653 1.0000
77.5600 3.0864 1.0000
77.6200 3.1141 1.0000
77.6800 7.3950 1.0000
77.7400 3.6022 1.0000
77.8000 7.9448 1.0000
77.8600 5.2421 1.0000
77.9200 4.4117 1.0000
77.9800 5.2297 1.0000
78.0400 2.5536 1.0000
78.1000 3.4810 1.0000
78.1600 5.4511 1.0000
78.2200 4.2574 1.0000
78.2800 3.1471 1.0000
78.3400 7.0531 1.0000
78.4000 7.2753 1.0000
78.4600 5.3371 1.0000
78.5200 9.1058 1.0000
78.5800 6.5835 1.0000
78.6400 4.4184 1.0000
78.7000 6.2972 1.0000
78.7600 3.8145 1.0000
78.8200 3.1706 1.0000
78.8800 8.4939 1.0000
78.9400 2.4974 1.0000
79.0000 2.0682 1.0000
79.0600 5.6006 1.0000
79.1200 5.2542 1.0000
79.1800 1.9418 1.0000
79.2400 7.7388 1.0000
79.3000 1.6277 1.0000
79.3600 4.4266 1.0000
79.4200 4.1017 1.0000
79.4800 3.0082 1.0000
79.5400 7.2385 1.0000
79.6000 7.7323 1.0000
79.6600 5.9444 1.0000
79.7200 2.7985 1.0000
79.7800 2.1466 1.0000
79.8400 2.3187 1.0000
79.9000 6.0492 1.0000
79.9600 5.8241 1.0000
80.0200 6.5367 1.0000
80.0800 4.3035 1.0000
80.1400 1.9403 1.0000
80.2000 2.0450 1.0000
80.2600 5.2067 1.0000
80.3200 5.2475 1.0000
80.3800 2.7030 1.0000
80.4400 5.5041 1.0000
80.5000 5.6151 1.0000
80.5600 4.3880 1.0000
80.6200 5.2908 1.0000
80.6800 2.6001 1.0000
80.7400 3.9346 1.0000
80.8000 4.5176 1.0000
80.8600 2.9414 1.0000
80.9200 6.2025 1.0000
80.9800 5.9079 1.0000
81.0400 3.3953 1.0000
81.1000 3.6239 1.0000
81.1600 5.2724 1.0000
81.2200 3.4449 1.0000
81.2800 3.5927 1.0000
81.3400 2.6622 1.0000
81.4000 4.8266 1.0000
81.4600 3.2332 1.0000
81.5200 7.3880 1.0000
81.5800 5.3257 1.0000
81.6400 4.6841 1.0000
81.7000 5.3571 1.0000
81.7600 7.4099 1.0000
81.8200 5.6511 1.0000
81.8800 9.4309 1.0000
81.9400 13.9274 1.0000
82.0000 16.3711 1.0000
82.0600 18.4607 1.0000
82.1200 19.7124 1.0000
82.1800 23.7980 1.0000
82.2400 21.3295 1.0000
82.3000 12.3696 1.0000
82.3600 12.3173 1.0000
82.4200 10.5094 1.0000
82.4800 5.6731 1.0000
82.5400 1.2209 1.0000
82.6000 4.0271 1.0000
82.6600 0.4582 1.0000
82.7200 7.2202 1.0000
82.7800 3.4980 1.0000
82.8400 6.0767 1.0000
82.9000 5.9776 1.0000
82.9600 3.0897 1.0000
83.0200 3.1836 1.0000
83.0800 3.2663 1.0000
83.1400 2.1071 1.0000
83.2000 4.8198 1.0000
83.2600 3.6766 1.0000
83.3200 5.2579 1.0000
83.3800 3.0494 1.0000
83.4400 3.9935 1.0000
83.5000 4.0925 1.0000
83.5600 4.6818 1.0000
83.6200 3.8743 1.0000
83.6800 5.0889 1.0000
83.7400 2.9948 1.0000
83.8000 1.2149 1.0000
83.8600 5.6936 1.0000
83.9200 5.4788 1.0000
83.9800 3.2097 1.0000
84.0400 3.0998 1.0000
84.1000 5.8495 1.0000
84.1600 3.0995 1.0000
84.2200 5.0901 1.0000
84.2800 3.7309 1.0000
84.3400 3.1546 1.0000
84.4000 5.4707 1.0000
84.4600 4.5094 1.0000
84.5200 3.4843 1.0000
84.5800 4.2107 1.0000
84.6400 5.2805 1.0000
84.7000 3.0284 1.0000
84.7600 5.1567 1.0000
84.8200 4.9283 1.0000
84.8800 4.1564 1.0000
84.9400 5.0739 1.0000
85.0000 3.4460 1.0000
85.0600 3.0619 1.0000
85.1200 6.4062 1.0000
85.1800 4.4113 1.0000
85.2400 4.7302 1.0000
85.3000 8.2538 1.0000
85.3600 3.1579 1.0000
85.4200 2.6223 1.0000
85.4800 2.7879 1.0000
85.5400 2.4696 1.0000
85.6000 0.9402 1.0000
85.6600 6.6796 1.0000
85.7200 8.4432 1.0000
85.7800 8.1773 1.0000
85.8400 1.2040 1.0000
85.9000 2.8120 1.0000
85.9600 1.4707 1.0000
86.0200 4.0562 1.0000
86.0800 3.1615 1.0000
86.1400 4.2422 1.0000
86.2000 4.1783 1.0000
86.2600 5.3128 1.0000
86.3200 4.3616 1.0000
86.3800 3.0560 1.0000
86.4400 2.0812 1.0000
86.5000 3.3080 1.0000
86.5600 3.3890 1.0000
86.6200 4.0107 1.0000
86.6800 3.7937 1.0000
86.7400 5.2127 1.0000
86.8000 5.1385 1.0000
86.8600 7.9131 1.0000
86.9200 4.6064 1.0000
86.9800 5.5137 1.0000
87.0400 2.0416 1.0000
87.1000 6.1882 1.0000
87.1600 3.3638 1.0000
87.2200 3.8093 1.0000
87.2800 2.8910 1.0000
87.3400 5.9469 1.0000
87.4000 6.0143 1.0000
87.4600 3.2439 1.0000
87.5200 10.0821 1.0000
87.5800 5.4479 1.0000
87.6400 5.3323 1.0000
87.7000 2.0645 1.0000
87.7600 6.3166 1.0000
87.8200 0.1575 1.0000
87.8800 2.2909 1.0000
87.9400 5.3353 1.0000
88.0000 3.8431 1.0000
88.0600 0.9747 1.0000
88.1200 5.1920 1.0000
88.1800 4.0184 1.0000
88.2400 3.3405 1.0000
88.3000 6.9790 1.0000
88.3600 5.1079 1.0000
88.4200 5.5016 1.0000
88.4800 2.0508 1.0000
88.5400 3.8112 1.0000
88.6000 3.9629 1.0000
88.6600 4.1923 1.0000
88.7200 5.6383 1.0000
88.7800 9.4027 1.0000
88.8400 6.4325 1.0000
88.9000 2.3332 1.0000
88.9600 3.3177 1.0000
89.0200 1.3873 1.0000
89.0800 4.5538 1.0000
89.1400 1.3400 1.0000
89.2000 2.2266 1.0000
89.2600 1.9614 1.0000
89.3200 3.0356 1.0000
89.3800 6.3355 1.0000
89.4400 3.1715 1.0000
89.5000 3.6873 1.0000
89.5600 4.5381 1.0000
89.6200 7.3806 1.0000
89.6800 1.6299 1.0000
89.7400 3.3912 1.0000
89.8000 5.9451 1.0000
89.8600 3.2596 1.0000
89.9200 5.1036 1.0000
89.9800 1.0838 1.0000
90.0400 1.5456 1.0000
90.1000 5.9487 1.0000
90.1600 5.6156 1.0000
90.2200 3.5435 1.0000
90.2800 2.4029 1.0000
90.3400 6.4362 1.0000
90.4000 2.8058 1.0000
90.4600 7.4927 1.0000
90.5200 3.4634 1.0000
90.5800 2.2931 1.0000
90.6400 2.1421 1.0000
90.7000 3.7313 1.0000
90.7600 6.3464 1.0000
90.8200 3.2268 1.0000
90.8800 3.3428 1.0000
90.9400 5.6985 1.0000
91.0000 5.0653 1.0000
91.0600 5.2642 1.0000
91.1200 5.0428 1.0000
91.1800 6.1677 1.0000
91.2400 3.9362 1.0000
91.3000 7.5741 1.0000
91.3600 5.3797 1.0000
91.4200 5.9544 1.0000
91.4800 4.0284 1.0000
91.5400 1.2702 1.0000
91.6000 3.3438 1.0000
91.6600 8.0853 1.0000
91.7200 3.8801 1.0000
91.7800 2.2578 1.0000
91.8400 3.8740 1.0000
91.9000 6.3177 1.0000
91.9600 5.2237 1.0000
92.0200 3.5282 1.0000
92.0800 7.2183 1.0000
92.1400 2.1900 1.0000
92.2000 3.9088 1.0000
92.2600 6.8947 1.0000
92.3200 5.8095 1.0000
92.3800 3.0755 1.0000
92.4400 7.5647 1.0000
92.5000 5.9167 1.0000
92.5600 2.7960 1.0000
92.6200 7.6713 1.0000
92.6800 5.3998 1.0000
92.7400 0.3840 1.0000
92.8000 2.0381 1.0000
92.8600 1.5840 1.0000
92.9200 3.4558 1.0000
92.9800 2.9048 1.0000
93.0400 6.5451 1.0000
93.1000 4.5740 1.0000
93.1600 9.3047 1.0000
93.2200 6.5380 1.0000
93.2800 1.9123 1.0000
93.3400 2.0598 1.0000
93.4000 4.8483 1.0000
93.4600 1.0841 1.0000
93.5200 3.9639 1.0000
93.5800 3.1103 1.0000
93.6400 4.8338 1.0000
93.7000 3.1472 1.0000
93.7600 6.2696 1.0000
93.8200 3.1165 1.0000
93.8800 3.4774 1.0000
93.9400 5.7686 1.0000
94.0000 4.7054 1.0000
94.0600 3.4538 1.0000
94.1200 4.5757 1.0000
94.1800 3.4190 1.0000
94.2400 3.8363 1.0000
94.3000 6.0840 1.0000
94.3600 2.7864 1.0000
94.4200 3.4242 1.0000
94.4800 1.8312 1.0000
94.5400 6.0749 1.0000
94.6000 4.7244 1.0000
94.6600 4.6204 1.0000
94.7200 4.9255 1.0000
94.7800 4.6208 1.0000
94.8400 3.3808 1.0000
94.9000 3.8723 1.0000
94.9600 4.0722 1.0000
95.0200 4.0392 1.0000
95.0800 3.2786 1.0000
95.1400 6.6921 1.0000
95.2000 2.1201 1.0000
95.2600 6.1175 1.0000
95.3200 5.0323 1.0000
95.3800 1.6933 1.0000
95.4400 5.6499 1.0000
95.5000 2.3277 1.0000
95.5600 6.4418 1.0000
95.6200 7.1546 1.0000
95.6800 7.2761 1.0000
95.7400 2.9189 1.0000
95.8000 4.8243 1.0000
95.8600 3.4624 1.0000
95.9200 4.4879 1.0000
95.9800 4.9845 1.0000
96.0400 4.2581 1.0000
96.1000 3.3323 1.0000
96.1600 3.6883 1.0000
96.2200 3.4006 1.0000
96.2800 2.9524 1.0000
96.3400 8.6143 1.0000
96.4000 7.3638 1.0000
96.4600 6.3225 1.0000
96.5200 4.3217 1.0000
96.5800 3.8316 1.0000
96.6400 2.9463 1.0000
96.7000 3.8928 1.0000
96.7600 4.6651 1.0000
96.8200 4.9816 1.0000
96.8800 5.0421 1.0000
96.9400 5.7127 1.0000
97.0000 7.5824 1.0000
97.0600 3.4889 1.0000
97.1200 4.5850 1.0000
97.1800 3.8685 1.0000
97.2400 3.9792 1.0000
97.3000 4.5567 1.0000
97.3600 4.1019 1.0000
97.4200 7.7417 1.0000
97.4800 4.4803 1.0000
97.5400 4.2377 1.0000
97.6000 4.5242 1.0000
97.6600 6.1486 1.0000
97.7200 1.9025 1.0000
97.7800 7.5371 1.0000
97.8400 5.8764 1.0000
97.9000 2.2186 1.0000
97.9600 4.5767 1.0000
98.0200 2.5698 1.0000
98.0800 8.0852 1.0000
98.1400 4.8158 1.0000
98.2000 6.3215 1.0000
98.2600 5.0280 1.0000
98.3200 6.3941 1.0000
98.3800 4.7057 1.0000
98.4400 5.5426 1.0000
98.5000 4.7690 1.0000
98.5600 7.5096 1.0000
98.6200 11.6662 1.0000
98.6800 9.0203 1.0000
98.7400 18.4003 1.0000
98.8000 14.0150 1.0000
98.8600 10.0710 1.0000
98.9200 13.0840 1.0000
98.9800 6.2777 1.0000
99.0400 8.5820 1.0000
99.1000 4.4227 1.0000
99.1600 5.4992 1.0000
99.2200 6.2170 1.0000
99.2800 5.8924 1.0000
99.3400 7.0043 1.0000
99.4000 6.3990 1.0000
99.4600 4.0544 1.0000
99.5200 4.5432 1.0000
99.5800 4.8764 1.0000
99.6400 4.4651 1.0000
99.7000 6.1494 1.0000
99.7600 1.7059 1.0000
99.8200 4.4146 1.0000
99.8800 3.5487 1.0000
99.9400 5.3976 1.0000
100.0000 2.1356 1.0000
100.0600 2.0727 1.0000
100.1200 5.3096 1.0000
100.1800 1.6926 1.0000
100.2400 5.0296 1.0000
100.3000 4.5246 1.0000
100.3600 5.7355 1.0000
100.4200 0.0000 1.0000
100.4800 5.0087 1.0000
100.5400 3.4070 1.0000
100.6000 5.8625 1.0000
100.6600 7.3196 1.0000
100.7200 4.1256 1.0000
100.7800 1.2786 1.0000
100.8400 2.2899 1.0000
100.9000 4.8261 1.0000
100.9600 4.9844 1.0000
101.0200 5.4221 1.0000
101.0800 1.3295 1.0000
101.1400 4.6523 1.0000
101.2000 1.5508 1.0000
101.2600 4.4656 1.0000
101.3200 5.1154 1.0000
101.3800 4.9059 1.0000
101.4400 4.7039 1.0000
101.5000 4.2888 1.0000
101.5600 8.8883 1.0000
101.6200 3.3396 1.0000
101.6800 6.0486 1.0000
101.7400 4.3107 1.0000
101.8000 3.9598 1.0000
101.8600 1.4368 1.0000
101.9200 3.0603 1.0000
101.9800 2.6894 1.0000
102.0400 4.9236 1.0000
102.1000 3.4337 1.0000
102.1600 6.2978 1.0000
102.2200 4.5553 1.0000
102.2800 3.9789 1.0000
102.3400 7.1611 1.0000
102.4000 3.5091 1.0000
102.4600 8.2911 1.0000
102.5200 3.9857 1.0000
102.5800 5.4158 1.0000
102.6400 7.4036 1.0000
102.7000 4.8406 1.0000
102.7600 2.0427 1.0000
102.8200 1.9845 1.0000
102.8800 2.1454 1.0000
102.9400 5.3939 1.0000
103.0000 2.0511 1.0000
103.0600 2.9317 1.0000
103.1200 6.6236 1.0000
103.1800 1.8731 1.0000
103.2400 5.9898 1.0000
103.3000 0.3083 1.0000
103.3600 6.8789 1.0000
103.4200 3.1085 1.0000
103.4800 5.3672 1.0000
103.5400 6.1631 1.0000
103.6000 3.2622 1.0000
103.6600 2.6178 1.0000
103.7200 5.2357 1.0000
103.7800 4.5824 1.0000
103.8400 2.3446 1.0000
103.9000 2.5466 1.0000
103.9600 9.4577 1.0000
104.0200 6.8712 1.0000
104.0800 4.2389 1.0000
104.1400 3.1514 1.0000
104.2000 3.3679 1.0000
104.2600 4.3960 1.0000
104.3200 4.7803 1.0000
104.3800 2.9883 1.0000
104.4400 2.5068 1.0000
104.5000 7.4204 1.0000
104.5600 8.0474 1.0000
104.6200 1.5144 1.0000
104.6800 7.1371 1.0000
104.7400 3.1610 1.0000
104.8000 7.9802 1.0000
104.8600 5.7839 1.0000
104.9200 7.0558 1.0000
104.9800 9.6237 1.0000
105.0400 5.6291 1.0000
105.1000 4.3254 1.0000
105.1600 4.7159 1.0000
105.2200 3.0643 1.0000
105.2800 1.9093 1.0000
105.3400 8.0519 1.0000
105.4000 6.5595 1.0000
105.4600 9.4248 1.0000
105.5200 3.9545 1.0000
105.5800 2.1101 1.0000
105.6400 6.2925 1.0000
105.7000 4.1838 1.0000
105.7600 1.7997 1.0000
105.8200 4.8526 1.0000
105.8800 4.1401 1.0000
105.9400 3.1334 1.0000
106.0000 7.4845 1.0000
106.0600 7.0834 1.0000
106.1200 5.0688 1.0000
106.1800 3.6200 1.0000
106.2400 8.7331 1.0000
106.3000 6.6250 1.0000
106.3600 1.2345 1.0000
106.4200 7.6376 1.0000
106.4800 4.3645 1.0000
106.5400 4.9213 1.0000
106.6000 4.6532 1.0000
106.6600 7.4701 1.0000
106.7200 3.8605 1.0000
106.7800 4.5971 1.0000
106.8400 4.5672 1.0000
106.9000 6.1791 1.0000
106.9600 5.2953 1.0000
107.0200 5.8567 1.0000
107.0800 4.7178 1.0000
107.1400 2.1302 1.0000
107.2000 2.1513 1.0000
107.2600 6.9209 1.0000
107.3200 5.4911 1.0000
107.3800 6.2188 1.0000
107.4400 7.8110 1.0000
107.5000 2.8318 1.0000
107.5600 5.9622 1.0000
107.6200 2.8406 1.0000
107.6800 2.0052 1.0000
107.7400 4.9903 1.0000
107.8000 6.1682 1.0000
107.8600 5.1069 1.0000
107.9200 1.2823 1.0000
107.9800 5.5021 1.0000
108.0400 4.3601 1.0000
108.1000 6.1783 1.0000
108.1600 5.8395 1.0000
108.2200 5.8845 1.0000
108.2800 6.1462 1.0000
108.3400 5.2476 1.0000
108.4000 5.7313 1.0000
108.4600 5.4158 1.0000
108.5200 5.0814 1.0000
108.5800 5.2573 1.0000
[...]
66.7600 3.0280 1.0000
66.8200 7.6857 1.0000
66.8800 6.1199 1.0000
66.9400 4.6262 1.0000
67.0000 5.0091 1.0000
67.0600 1.0923 1.0000
67.1200 2.6732 1.0000
67.1800 2.0367 1.0000
67.2400 7.9250 1.0000
67.3000 9.0865 1.0000
67.3600 5.3986 1.0000
67.4200 7.0829 1.0000
67.4800 6.5676 1.0000
67.5400 10.9579 1.0000
67.6000 7.6329 1.0000
67.6600 4.0121 1.0000
67.7200 3.0909 1.0000
67.7800 5.3696 1.0000
67.8400 4.2602 1.0000
67.9000 4.7220 1.0000
67.9600 3.7978 1.0000
68.0200 4.0900 1.0000
68.0800 6.6814 1.0000
68.1400 5.2772 1.0000
68.2000 3.5289 1.0000
68.2600 2.6769 1.0000
68.3200 7.3920 1.0000
68.3800 3.6485 1.0000
68.4400 1.3892 1.0000
68.5000 6.1068 1.0000
68.5600 4.8605 1.0000
68.6200 4.3238 1.0000
68.6800 1.9559 1.0000
68.7400 0.7590 1.0000
68.8000 3.8656 1.0000
68.8600 1.0798 1.0000
68.9200 1.6455 1.0000
68.9800 5.1387 1.0000
69.0400 6.5755 1.0000
69.1000 2.1991 1.0000
69.1600 2.6343 1.0000
69.2200 6.2783 1.0000
69.2800 5.0584 1.0000
69.3400 4.4780 1.0000
69.4000 5.5747 1.0000
69.4600 2.0918 1.0000
69.5200 2.6858 1.0000
69.5800 4.0444 1.0000
69.6400 3.9792 1.0000
69.7000 4.0923 1.0000
69.7600 6.0781 1.0000
69.8200 7.3647 1.0000
69.8800 6.6295 1.0000
69.9400 3.8924 1.0000
70.0000 5.1357 1.0000
70.0600 3.4736 1.0000
70.1200 5.7217 1.0000
70.1800 3.5146 1.0000
70.2400 1.3795 1.0000
70.3000 3.5169 1.0000
70.3600 5.0653 1.0000
70.4200 2.5209 1.0000
70.4800 3.9380 1.0000
70.5400 3.0306 1.0000
70.6000 4.1749 1.0000
70.6600 3.8965 1.0000
70.7200 7.8803 1.0000
70.7800 5.1334 1.0000
70.8400 5.5129 1.0000
70.9000 2.9710 1.0000
70.9600 4.7445 1.0000
71.0200 4.5361 1.0000
71.0800 3.4450 1.0000
71.1400 3.0904 1.0000
71.2000 5.0691 1.0000
71.2600 3.6158 1.0000
71.3200 5.3001 1.0000
71.3800 3.5639 1.0000
71.4400 4.6656 1.0000
71.5000 6.8624 1.0000
71.5600 2.7604 1.0000
71.6200 4.2181 1.0000
71.6800 1.4885 1.0000
71.7400 1.7390 1.0000
71.8000 0.7738 1.0000
71.8600 4.4544 1.0000
71.9200 3.4520 1.0000
71.9800 2.7131 1.0000
72.0400 6.3788 1.0000
72.1000 2.6752 1.0000
72.1600 3.1282 1.0000
72.2200 3.3506 1.0000
72.2800 3.5504 1.0000
72.3400 1.6385 1.0000
72.4000 3.7966 1.0000
72.4600 6.2968 1.0000
72.5200 2.1356 1.0000
72.5800 1.2000 1.0000
72.6400 3.7484 1.0000
72.7000 2.2731 1.0000
72.7600 3.0446 1.0000
72.8200 1.2877 1.0000
72.8800 3.4076 1.0000
72.9400 6.8893 1.0000
73.0000 7.0710 1.0000
73.0600 4.4564 1.0000
73.1200 3.8099 1.0000
73.1800 3.7626 1.0000
73.2400 3.5597 1.0000
73.3000 4.2534 1.0000
73.3600 4.7361 1.0000
73.4200 6.1640 1.0000
73.4800 5.3901 1.0000
73.5400 5.0041 1.0000
73.6000 5.5593 1.0000
73.6600 9.0300 1.0000
73.7200 2.6407 1.0000
73.7800 6.5522 1.0000
73.8400 0.3527 1.0000
73.9000 2.3395 1.0000
73.9600 4.3745 1.0000
74.0200 4.3641 1.0000
74.0800 4.9973 1.0000
74.1400 2.8479 1.0000
74.2000 2.0830 1.0000
74.2600 3.4783 1.0000
74.3200 1.0669 1.0000
74.3800 2.0601 1.0000
74.4400 6.6981 1.0000
74.5000 1.3050 1.0000
74.5600 2.7774 1.0000
74.6200 3.6691 1.0000
74.6800 6.0116 1.0000
74.7400 5.6220 1.0000
74.8000 3.9389 1.0000
74.8600 3.8402 1.0000
74.9200 3.1210 1.0000
74.9800 1.5088 1.0000
75.0400 6.2791 1.0000
75.1000 5.7526 1.0000
75.1600 5.3336 1.0000
75.2200 1.2785 1.0000
75.2800 3.2053 1.0000
75.3400 5.1817 1.0000
75.4000 4.3451 1.0000
75.4600 2.6971 1.0000
75.5200 7.0942 1.0000
75.5800 3.1655 1.0000
75.6400 5.1558 1.0000
75.7000 7.3696 1.0000
75.7600 5.8472 1.0000
75.8200 1.4036 1.0000
75.8800 6.6879 1.0000
75.9400 6.1589 1.0000
76.0000 1.7454 1.0000
76.0600 5.9693 1.0000
76.1200 5.3115 1.0000
76.1800 5.6951 1.0000
76.2400 2.6058 1.0000
76.3000 4.0679 1.0000
76.3600 4.2413 1.0000
76.4200 2.5456 1.0000
76.4800 4.5623 1.0000
76.5400 4.4951 1.0000
76.6000 5.2720 1.0000
76.6600 7.3833 1.0000
76.7200 6.7292 1.0000
76.7800 3.5218 1.0000
76.8400 1.2751 1.0000
76.9000 6.3302 1.0000
76.9600 4.7112 1.0000
77.0200 6.0692 1.0000
77.0800 4.5733 1.0000
77.1400 5.1250 1.0000
77.2000 1.9061 1.0000
77.2600 4.9526 1.0000
77.3200 1.2783 1.0000
77.3800 4.6719 1.0000
77.4400 5.0611 1.0000
77.5000 3.3146 1.0000
77.5600 5.0686 1.0000
77.6200 3.4956 1.0000
77.6800 3.0014 1.0000
77.7400 1.6901 1.0000
77.8000 2.8170 1.0000
77.8600 3.0817 1.0000
77.9200 3.7028 1.0000
77.9800 1.1133 1.0000
78.0400 4.3062 1.0000
78.1000 6.7969 1.0000
78.1600 10.5613 1.0000
78.2200 4.7237 1.0000
78.2800 3.6717 1.0000
78.3400 4.6360 1.0000
78.4000 3.2966 1.0000
78.4600 4.7235 1.0000
78.5200 1.7609 1.0000
78.5800 5.0557 1.0000
78.6400 3.0168 1.0000
78.7000 4.4611 1.0000
78.7600 3.6185 1.0000
78.8200 3.4746 1.0000
78.8800 4.1773 1.0000
78.9400 2.8253 1.0000
79.0000 3.1406 1.0000
79.0600 4.1042 1.0000
79.1200 5.7330 1.0000
79.1800 2.3444 1.0000
79.2400 4.2840 1.0000
79.3000 3.5161 1.0000
79.3600 4.2758 1.0000
79.4200 3.9450 1.0000
79.4800 2.7701 1.0000
79.5400 0.0000 1.0000
79.6000 1.6698 1.0000
79.6600 2.9554 1.0000
79.7200 4.0429 1.0000
79.7800 1.4366 1.0000
79.8400 3.9467 1.0000
79.9000 3.9771 1.0000
79.9600 6.4933 1.0000
80.0200 4.1621 1.0000
80.0800 7.4609 1.0000
80.1400 6.8879 1.0000
80.2000 1.0737 1.0000
80.2600 6.2215 1.0000
80.3200 4.8253 1.0000
80.3800 2.8687 1.0000
80.4400 1.3387 1.0000
80.5000 3.8674 1.0000
80.5600 5.7432 1.0000
80.6200 2.5315 1.0000
80.6800 1.6982 1.0000
80.7400 4.1173 1.0000
80.8000 7.4927 1.0000
80.8600 3.9205 1.0000
80.9200 4.5199 1.0000
80.9800 6.7593 1.0000
81.0400 3.7495 1.0000
81.1000 1.6208 1.0000
81.1600 4.1050 1.0000
81.2200 7.1146 1.0000
81.2800 3.1815 1.0000
81.3400 2.0250 1.0000
81.4000 6.6592 1.0000
81.4600 5.5178 1.0000
81.5200 5.1716 1.0000
81.5800 6.1342 1.0000
81.6400 2.5242 1.0000
81.7000 5.1030 1.0000
81.7600 6.2212 1.0000
81.8200 11.5756 1.0000
81.8800 6.0036 1.0000
81.9400 10.7319 1.0000
82.0000 10.6923 1.0000
82.0600 15.8389 1.0000
82.1200 19.2998 1.0000
82.1800 19.9325 1.0000
82.2400 16.5068 1.0000
82.3000 16.1064 1.0000
82.3600 19.9786 1.0000
82.4200 2.9542 1.0000
82.4800 6.7040 1.0000
82.5400 6.0812 1.0000
82.6000 5.3502 1.0000
82.6600 4.6887 1.0000
82.7200 2.4200 1.0000
82.7800 4.0762 1.0000
82.8400 5.8803 1.0000
82.9000 3.9187 1.0000
82.9600 3.1739 1.0000
83.0200 4.7749 1.0000
83.0800 2.3189 1.0000
83.1400 5.3022 1.0000
83.2000 5.0419 1.0000
83.2600 4.4801 1.0000
83.3200 2.0843 1.0000
83.3800 1.1593 1.0000
83.4400 1.6594 1.0000
83.5000 1.9348 1.0000
83.5600 2.8438 1.0000
83.6200 2.6342 1.0000
83.6800 4.6843 1.0000
83.7400 7.2291 1.0000
83.8000 4.0502 1.0000
83.8600 5.7305 1.0000
83.9200 4.2764 1.0000
83.9800 7.9903 1.0000
84.0400 5.4607 1.0000
84.1000 5.8314 1.0000
84.1600 4.4969 1.0000
84.2200 6.4173 1.0000
84.2800 3.5097 1.0000
84.3400 2.2999 1.0000
84.4000 2.9642 1.0000
84.4600 4.4117 1.0000
84.5200 3.7120 1.0000
84.5800 1.1576 1.0000
84.6400 7.0791 1.0000
84.7000 3.6425 1.0000
84.7600 5.3349 1.0000
84.8200 7.0665 1.0000
84.8800 4.9197 1.0000
84.9400 3.2781 1.0000
85.0000 3.1624 1.0000
85.0600 5.6805 1.0000
85.1200 4.0515 1.0000
85.1800 2.2568 1.0000
85.2400 3.5537 1.0000
85.3000 5.9196 1.0000
85.3600 4.7444 1.0000
85.4200 6.8032 1.0000
85.4800 6.1648 1.0000
85.5400 4.0808 1.0000
85.6000 2.1992 1.0000
85.6600 3.6488 1.0000
85.7200 1.5002 1.0000
85.7800 8.3877 1.0000
85.8400 3.8026 1.0000
85.9000 3.8267 1.0000
85.9600 3.2751 1.0000
86.0200 6.1733 1.0000
86.0800 2.0306 1.0000
86.1400 3.0410 1.0000
86.2000 1.9298 1.0000
86.2600 3.0049 1.0000
86.3200 3.2988 1.0000
86.3800 1.7226 1.0000
86.4400 1.1234 1.0000
86.5000 5.0911 1.0000
86.5600 3.4958 1.0000
86.6200 5.8651 1.0000
86.6800 6.2724 1.0000
86.7400 3.7219 1.0000
86.8000 2.8665 1.0000
86.8600 7.7543 1.0000
86.9200 2.8853 1.0000
86.9800 7.0518 1.0000
87.0400 3.2807 1.0000
87.1000 2.0698 1.0000
87.1600 4.4907 1.0000
87.2200 1.3217 1.0000
87.2800 1.2672 1.0000
87.3400 3.7072 1.0000
87.4000 2.1872 1.0000
87.4600 1.6319 1.0000
87.5200 3.3619 1.0000
87.5800 2.7883 1.0000
87.6400 2.7771 1.0000
87.7000 5.6486 1.0000
87.7600 4.9039 1.0000
87.8200 3.3308 1.0000
87.8800 7.6554 1.0000
87.9400 5.1607 1.0000
88.0000 3.1842 1.0000
88.0600 1.9373 1.0000
88.1200 6.4458 1.0000
88.1800 1.7311 1.0000
88.2400 4.1198 1.0000
88.3000 5.9165 1.0000
88.3600 4.0768 1.0000
88.4200 5.5817 1.0000
88.4800 6.5806 1.0000
88.5400 7.0486 1.0000
88.6000 7.8716 1.0000
88.6600 6.1244 1.0000
88.7200 5.1673 1.0000
88.7800 3.0517 1.0000
88.8400 5.2016 1.0000
88.9000 4.2492 1.0000
88.9600 1.7914 1.0000
89.0200 4.4917 1.0000
89.0800 3.9404 1.0000
89.1400 1.5621 1.0000
89.2000 3.0379 1.0000
89.2600 0.8727 1.0000
89.3200 6.1799 1.0000
89.3800 5.1382 1.0000
89.4400 6.1404 1.0000
89.5000 2.9113 1.0000
89.5600 2.7972 1.0000
89.6200 4.2783 1.0000
89.6800 7.4152 1.0000
89.7400 5.9316 1.0000
89.8000 4.4740 1.0000
89.8600 4.9520 1.0000
89.9200 4.5656 1.0000
89.9800 4.8202 1.0000
90.0400 5.6180 1.0000
90.1000 2.2244 1.0000
90.1600 2.1200 1.0000
90.2200 3.9319 1.0000
90.2800 3.0173 1.0000
90.3400 4.2434 1.0000
90.4000 5.3159 1.0000
90.4600 5.1225 1.0000
90.5200 5.3453 1.0000
90.5800 5.0988 1.0000
90.6400 2.0261 1.0000
90.7000 1.1626 1.0000
90.7600 1.1287 1.0000
90.8200 3.1545 1.0000
90.8800 0.2496 1.0000
90.9400 3.1099 1.0000
91.0000 4.2103 1.0000
91.0600 7.7131 1.0000
91.1200 3.3907 1.0000
91.1800 3.7126 1.0000
91.2400 3.2840 1.0000
91.3000 4.4870 1.0000
91.3600 5.6968 1.0000
91.4200 5.1902 1.0000
91.4800 3.2710 1.0000
91.5400 6.5273 1.0000
91.6000 9.1309 1.0000
91.6600 2.5030 1.0000
91.7200 5.3869 1.0000
91.7800 2.0247 1.0000
91.8400 4.2885 1.0000
91.9000 3.9367 1.0000
91.9600 1.5263 1.0000
92.0200 5.5138 1.0000
92.0800 1.7940 1.0000
92.1400 3.1354 1.0000
92.2000 4.4293 1.0000
92.2600 6.6477 1.0000
92.3200 3.1246 1.0000
92.3800 2.1817 1.0000
92.4400 2.3626 1.0000
92.5000 2.9166 1.0000
92.5600 3.7997 1.0000
92.6200 8.1397 1.0000
92.6800 7.6957 1.0000
92.7400 7.4605 1.0000
92.8000 7.4762 1.0000
92.8600 4.4249 1.0000
92.9200 3.1193 1.0000
92.9800 1.1072 1.0000
93.0400 4.2917 1.0000
93.1000 2.3747 1.0000
93.1600 5.3341 1.0000
93.2200 3.2401 1.0000
93.2800 4.7099 1.0000
93.3400 5.0724 1.0000
93.4000 5.5959 1.0000
93.4600 6.2722 1.0000
93.5200 5.2805 1.0000
93.5800 2.9423 1.0000
93.6400 4.0569 1.0000
93.7000 5.8826 1.0000
93.7600 5.1461 1.0000
93.8200 1.5505 1.0000
93.8800 8.2748 1.0000
93.9400 1.7401 1.0000
94.0000 3.6899 1.0000
94.0600 4.5581 1.0000
94.1200 4.1578 1.0000
94.1800 3.9837 1.0000
94.2400 4.2454 1.0000
94.3000 1.0876 1.0000
94.3600 6.2369 1.0000
94.4200 1.6401 1.0000
94.4800 6.0752 1.0000
94.5400 6.4675 1.0000
94.6000 3.3329 1.0000
94.6600 5.3019 1.0000
94.7200 2.9738 1.0000
94.7800 6.2692 1.0000
94.8400 5.2579 1.0000
94.9000 1.4573 1.0000
94.9600 5.5904 1.0000
95.0200 5.7375 1.0000
95.0800 4.3221 1.0000
95.1400 6.0126 1.0000
95.2000 1.6422 1.0000
95.2600 5.0827 1.0000
95.3200 2.1703 1.0000
95.3800 3.4631 1.0000
95.4400 5.1132 1.0000
95.5000 5.0517 1.0000
95.5600 7.0571 1.0000
95.6200 4.0460 1.0000
95.6800 2.0283 1.0000
95.7400 2.7618 1.0000
95.8000 2.9445 1.0000
95.8600 3.5553 1.0000
95.9200 1.7600 1.0000
95.9800 8.5720 1.0000
96.0400 3.0739 1.0000
96.1000 4.1130 1.0000
96.1600 2.6869 1.0000
96.2200 3.7423 1.0000
96.2800 5.2257 1.0000
96.3400 4.1593 1.0000
96.4000 2.9543 1.0000
96.4600 6.2125 1.0000
96.5200 7.2742 1.0000
96.5800 2.5230 1.0000
96.6400 5.8202 1.0000
96.7000 5.6856 1.0000
96.7600 3.1280 1.0000
96.8200 4.8288 1.0000
96.8800 6.1684 1.0000
96.9400 4.3247 1.0000
97.0000 5.6061 1.0000
97.0600 6.8554 1.0000
97.1200 6.1590 1.0000
97.1800 5.0444 1.0000
97.2400 7.3233 1.0000
97.3000 5.8540 1.0000
97.3600 1.3141 1.0000
97.4200 6.3913 1.0000
97.4800 5.9417 1.0000
97.5400 4.7878 1.0000
97.6000 4.5028 1.0000
97.6600 3.7986 1.0000
97.7200 6.1856 1.0000
97.7800 5.9841 1.0000
97.8400 2.8422 1.0000
97.9000 3.1359 1.0000
97.9600 5.3974 1.0000
98.0200 2.9135 1.0000
98.0800 3.8420 1.0000
98.1400 6.2018 1.0000
98.2000 7.0311 1.0000
98.2600 8.5714 1.0000
98.3200 6.5812 1.0000
98.3800 6.6985 1.0000
98.4400 6.4608 1.0000
98.5000 9.8243 1.0000
98.5600 8.8161 1.0000
98.6200 14.1864 1.0000
98.6800 11.9200 1.0000
98.7400 11.7498 1.0000
98.8000 12.5228 1.0000
98.8600 12.4048 1.0000
98.9200 11.1377 1.0000
98.9800 9.2311 1.0000
99.0400 6.4051 1.0000
99.1000 5.0835 1.0000
99.1600 3.0312 1.0000
99.2200 4.0444 1.0000
99.2800 4.3981 1.0000
99.3400 3.9586 1.0000
99.4000 2.4916 1.0000
99.4600 3.0998 1.0000
99.5200 2.7873 1.0000
99.5800 1.2973 1.0000
99.6400 2.6941 1.0000
99.7000 4.0211 1.0000
99.7600 4.8852 1.0000
99.8200 8.7628 1.0000
99.8800 4.9920 1.0000
99.9400 7.5163 1.0000
100.0000 6.4210 1.0000
100.0600 4.5839 1.0000
100.1200 2.3093 1.0000
100.1800 5.7322 1.0000
100.2400 3.3316 1.0000
100.3000 1.7621 1.0000
100.3600 3.7633 1.0000
100.4200 9.0310 1.0000
100.4800 4.8388 1.0000
100.5400 3.3270 1.0000
100.6000 6.3187 1.0000
100.6600 1.5135 1.0000
100.7200 0.0000 1.0000
100.7800 3.3473 1.0000
100.8400 6.5019 1.0000
100.9000 1.6588 1.0000
100.9600 2.8176 1.0000
101.0200 4.5086 1.0000
101.0800 0.0000 1.0000
101.1400 1.8299 1.0000
101.2000 5.9551 1.0000
101.2600 3.9447 1.0000
101.3200 4.2061 1.0000
101.3800 4.2800 1.0000
101.4400 4.7642 1.0000
101.5000 2.4196 1.0000
101.5600 2.6818 1.0000
101.6200 5.1596 1.0000
101.6800 8.9173 1.0000
101.7400 4.3993 1.0000
101.8000 3.2585 1.0000
101.8600 5.7793 1.0000
101.9200 3.3617 1.0000
101.9800 3.1910 1.0000
102.0400 3.6475 1.0000
102.1000 7.5064 1.0000
102.1600 1.5791 1.0000
102.2200 2.4732 1.0000
102.2800 5.4118 1.0000
102.3400 6.4381 1.0000
102.4000 1.6553 1.0000
102.4600 3.5516 1.0000
102.5200 5.1726 1.0000
102.5800 4.3564 1.0000
102.6400 2.6624 1.0000
102.7000 5.1875 1.0000
102.7600 5.8805 1.0000
102.8200 1.4972 1.0000
102.8800 3.1525 1.0000
102.9400 5.6216 1.0000
103.0000 3.8310 1.0000
103.0600 6.6402 1.0000
103.1200 3.5299 1.0000
103.1800 1.0327 1.0000
103.2400 3.0032 1.0000
103.3000 1.3444 1.0000
103.3600 2.0674 1.0000
103.4200 4.3577 1.0000
103.4800 2.8402 1.0000
103.5400 4.7248 1.0000
103.6000 4.1659 1.0000
103.6600 4.7596 1.0000
103.7200 2.1140 1.0000
103.7800 4.6294 1.0000
103.8400 3.3197 1.0000
103.9000 1.8061 1.0000
103.9600 2.2341 1.0000
104.0200 4.9939 1.0000
104.0800 4.6061 1.0000
104.1400 5.2027 1.0000
104.2000 3.5720 1.0000
104.2600 6.0816 1.0000
104.3200 1.5696 1.0000
104.3800 4.6470 1.0000
104.4400 6.4906 1.0000
104.5000 5.1051 1.0000
104.5600 4.0911 1.0000
104.6200 5.0684 1.0000
104.6800 1.0986 1.0000
104.7400 4.0251 1.0000
104.8000 1.4460 1.0000
104.8600 2.8864 1.0000
104.9200 2.5980 1.0000
104.9800 3.9257 1.0000
105.0400 0.5169 1.0000
105.1000 8.5917 1.0000
105.1600 5.9314 1.0000
105.2200 4.6320 1.0000
105.2800 5.8069 1.0000
105.3400 4.8455 1.0000
105.4000 2.7940 1.0000
105.4600 3.9554 1.0000
105.5200 7.0738 1.0000
105.5800 6.7861 1.0000
105.6400 7.2917 1.0000
105.7000 3.1222 1.0000
105.7600 3.9772 1.0000
105.8200 2.0664 1.0000
105.8800 2.9119 1.0000
105.9400 3.2946 1.0000
106.0000 3.1477 1.0000
106.0600 4.3408 1.0000
106.1200 2.1104 1.0000
106.1800 11.1552 1.0000
106.2400 6.0420 1.0000
106.3000 3.2063 1.0000
106.3600 4.9530 1.0000
106.4200 6.2132 1.0000
106.4800 3.3127 1.0000
106.5400 5.1726 1.0000
106.6000 5.1679 1.0000
106.6600 6.2628 1.0000
106.7200 4.7877 1.0000
106.7800 3.7068 1.0000
106.8400 4.1565 1.0000
106.9000 6.1865 1.0000
106.9600 5.4077 1.0000
107.0200 5.1373 1.0000
107.0800 2.7475 1.0000
107.1400 5.8623 1.0000
107.2000 4.2032 1.0000
107.2600 2.1997 1.0000
107.3200 9.0265 1.0000
107.3800 7.3534 1.0000
107.4400 6.4396 1.0000
107.5000 4.9285 1.0000
107.5600 1.8292 1.0000
107.6200 5.1876 1.0000
107.6800 4.1583 1.0000
107.7400 6.0260 1.0000
107.8000 6.9843 1.0000
107.8600 4.6964 1.0000
107.9200 2.2133 1.0000
107.9800 0.8470 1.0000
108.0400 5.8440 1.0000
108.1000 0.7014 1.0000
108.1600 2.3613 1.0000
108.2200 3.0704 1.0000
108.2800 5.2207 1.0000
108.3400 7.0655 1.0000
108.4000 4.6352 1.0000
108.4600 6.9068 1.0000
108.5200 4.3704 1.0000
108.5800 7.2585 1.0000
108.6400 4.3270 1.0000
108.7000 3.2429 1.0000
108.7600 3.6327 1.0000
108.8200 3.9759 1.0000
108.8800 6.3947 1.0000
108.9400 2.2324 1.0000
109.0000 5.6356 1.0000
109.0600 3.0876 1.0000
109.1200 2.1964 1.0000
109.1800 3.3649 1.0000
109.2400 1.6386 1.0000
109.3000 6.6812 1.0000
109.3600 3.2216 1.0000
109.4200 2.4310 1.0000
109.4800 3.4946 1.0000
109.5400 4.2566 1.0000
109.6000 4.5397 1.0000
109.6600 8.2751 1.0000
109.7200 5.6507 1.0000
109.7800 6.9180 1.0000
109.8400 4.5915 1.0000
109.9000 3.4884 1.0000
109.9600 4.3143 1.0000
110.0200 5.9393 1.0000
110.0800 5.4814 1.0000
110.1400 2.7133 1.0000
110.2000 5.0677 1.0000
110.2600 4.3519 1.0000
110.3200 6.0564 1.0000
110.3800 4.6253 1.0000
110.4400 0.4448 1.0000
110.5000 2.1921 1.0000
110.5600 3.1902 1.0000
110.6200 2.5241 1.0000
110.6800 4.0666 1.0000
110.7400 1.4304 1.0000
110.8000 7.0571 1.0000
110.8600 4.1928 1.0000
110.9200 4.3110 1.0000
110.9800 4.3295 1.0000
111.0400 3.0701 1.0000
111.1000 6.7915 1.0000
111.1600 3.5371 1.0000
111.2200 6.3366 1.0000
111.2800 8.3050 1.0000
111.3400 5.9578 1.0000
111.4000 2.6923 1.0000
111.4600 5.0180 1.0000
111.5200 5.2025 1.0000
111.5800 3.1909 1.0000
111.6400 2.6049 1.0000
111.7000 3.1637 1.0000
111.7600 4.4237 1.0000
111.8200 3.9036 1.0000
111.8800 5.0819 1.0000
111.9400 5.2441 1.0000
112.0000 4.1875 1.0000
112.0600 5.4563 1.0000
112.1200 5.3628 1.0000
112.1800 5.9747 1.0000
112.2400 6.0856 1.0000
112.3000 4.2514 1.0000
112.3600 3.5184 1.0000
112.4200 4.3907 1.0000
112.4800 6.4244 1.0000
112.5400 4.0912 1.0000
112.6000 2.6537 1.0000
112.6600 6.1564 1.0000
112.7200 6.3737 1.0000
112.7800 7.3740 1.0000
112.8400 4.0133 1.0000
112.9000 4.4769 1.0000
112.9600 1.2494 1.0000
113.0200 5.4110 1.0000
113.0800 4.7442 1.0000
113.1400 2.1974 1.0000
113.2000 1.9618 1.0000
113.2600 3.4847 1.0000
113.3200 5.0754 1.0000
113.3800 3.9158 1.0000
113.4400 6.5898 1.0000
113.5000 6.9673 1.0000
113.5600 1.9145 1.0000
113.6200 2.9635 1.0000
113.6800 3.2393 1.0000
113.7400 2.6401 1.0000
113.8000 2.6711 1.0000
113.8600 2.3062 1.0000
113.9200 2.8456 1.0000
113.9800 4.3627 1.0000
114.0400 2.1724 1.0000
114.1000 4.0090 1.0000
114.1600 3.6881 1.0000
114.2200 3.8274 1.0000
114.2800 4.3033 1.0000
114.3400 1.9707 1.0000
114.4000 4.0927 1.0000
114.4600 3.0140 1.0000
114.5200 6.0214 1.0000
114.5800 2.2169 1.0000
114.6400 9.2911 1.0000
114.7000 3.4390 1.0000
114.7600 4.9456 1.0000
114.8200 4.1435 1.0000
114.8800 2.8862 1.0000
114.9400 2.0170 1.0000
115.0000 10.3872 1.0000
115.0600 4.0788 1.0000
115.1200 5.3722 1.0000
115.1800 3.8774 1.0000
115.2400 7.7715 1.0000
115.3000 6.5882 1.0000
115.3600 2.7877 1.0000
115.4200 8.7876 1.0000
115.4800 10.2522 1.0000
115.5400 6.5827 1.0000
115.6000 6.2081 1.0000
115.6600 8.4874 1.0000
115.7200 8.7866 1.0000
115.7800 5.8441 1.0000
115.8400 11.9092 1.0000
115.9000 8.2403 1.0000
115.9600 5.5330 1.0000
116.0200 13.4133 1.0000
116.0800 10.4738 1.0000
116.1400 8.9541 1.0000
116.2000 7.9845 1.0000
116.2600 13.5472 1.0000
116.3200 8.5431 1.0000
116.3800 12.0632 1.0000
116.4400 8.4667 1.0000
116.5000 7.1248 1.0000
116.5600 9.9565 1.0000
116.6200 4.6002 1.0000
116.6800 5.7496 1.0000
116.7400 7.4784 1.0000
116.8000 4.5567 1.0000
116.8600 6.2123 1.0000
116.9200 4.1905 1.0000
116.9800 6.4848 1.0000
117.0400 2.1785 1.0000
117.1000 3.7184 1.0000
117.1600 6.1562 1.0000
117.2200 2.9993 1.0000
117.2800 2.4090 1.0000
117.3400 3.3946 1.0000
117.4000 4.3551 1.0000
117.4600 3.1072 1.0000
117.5200 2.3829 1.0000
117.5800 2.3065 1.0000
117.6400 3.7612 1.0000
117.7000 6.0778 1.0000
117.7600 7.2854 1.0000
117.8200 4.0233 1.0000
117.8800 5.4126 1.0000
117.9400 1.3523 1.0000
118.0000 3.0711 1.0000
118.0600 4.7244 1.0000
118.1200 5.6283 1.0000
118.1800 3.2683 1.0000
118.2400 4.5023 1.0000
118.3000 4.7641 1.0000
118.3600 3.6619 1.0000
118.4200 1.7606 1.0000
118.4800 2.6625 1.0000
118.5400 9.0160 1.0000
118.6000 4.6859 1.0000
118.6600 5.0525 1.0000
118.7200 7.3659 1.0000
118.7800 4.2075 1.0000
118.8400 6.8147 1.0000
118.9000 4.6613 1.0000
118.9600 3.5472 1.0000
119.0200 5.4771 1.0000
119.0800 4.2764 1.0000
119.1400 7.0222 1.0000
119.2000 3.1820 1.0000
119.2600 6.8296 1.0000
119.3200 3.4515 1.0000
119.3800 4.9384 1.0000
119.4400 0.0000 1.0000
119.5000 6.3530 1.0000
119.5600 4.6211 1.0000
119.6200 6.2193 1.0000
119.6800 4.0818 1.0000
119.7400 7.4353 1.0000
119.8000 3.4583 1.0000
119.8600 3.6729 1.0000
119.9200 3.1750 1.0000
119.9800 3.7983 1.0000
119.9900 9.4447 1.0000
*RAS_INT_END
*RAS_TEMPERATURE_START
*RAS_TEMPERATURE_END
*RAS_DATA_END