File: XRD/February 2021/PB_Ge220_2.5SS_5DS_RS1_Rod_2.5SS_Hypix1D_P91__3_Parent_5mmRHS_18hrs.ras
*RAS_DATA_START
*RAS_HEADER_START
*DISP_FMT_X "%.3f"
*DISP_FMT_Y "%.0f"
*DISP_FULLSCALE "5295.9404975000"
*DISP_LINE_COLOR "255.0000000000"
*DISP_LINE_STYLE "0.0000000000"
*DISP_LINE_WIDTH "0.2500000000"
*DISP_NOTE "Collected Data-192"
*DISP_OFFSET_Y "0.0000000000"
*DISP_PEAKSEARCH_UNIT_Y "cps"
*DISP_RANGE_BOTTOM "0.0000000000"
*DISP_RANGE_LEFT "40.0000000000"
*DISP_RANGE_LOGCUTOFF "0.0100000000"
*DISP_RANGE_RIGHT "130.0000000000"
*DISP_RANGE_TOP "5295.9404975000"
*DISP_SCALE_MODE_Y "0.0000000000"
*DISP_TAB_NAME "Theta/2-Theta"
*DISP_TITLE_Y "Intensity"
*DISP_UNIT_Y "cps"
*DISP_WINDOW_NAME "MSG_MACROENGINE"
*FILE_COMMENT " "
*FILE_MD5 ""
*FILE_MEMO " "
*FILE_OPERATOR "Administrator"
*FILE_PART_ID "MEAS_KHP2_00061"
*FILE_SAMPLE " "
*FILE_TYPE "RAS_RAW"
*FILE_USERGROUP "System Manager"
*FILE_VERSION "1.0000000000"
*HW_ATTACHMENT_ID "ATT0021"
*HW_ATTACHMENT_NAME "XY-20mm|XY-20mm"
*HW_COUNTER_ID-0 "CUT0041"
*HW_COUNTER_ID-1 "CUT0051"
*HW_COUNTER_ID-2 "CUT0020"
*HW_COUNTER_ID-3 "CSL0021"
*HW_COUNTER_ID-4 "CMC0021"
*HW_COUNTER_NAME-0 "D/teX Ultra 250|D/teX Ultra 250"
*HW_COUNTER_NAME-1 "HyPix 3000(H)|HyPix 3000(H)"
*HW_COUNTER_NAME-2 "None|None"
*HW_COUNTER_NAME-3 "BBM|BBM"
*HW_COUNTER_NAME-4 "検出器モノクロメータ|Detector monochromator"
*HW_COUNTER_SELECT_NAME "HyPix 3000(H)|HyPix 3000(H)"
*HW_GONIOMETER_ID "GON0024"
*HW_GONIOMETER_NAME "SmartLab(In-plane)|SmartLab(In-plane)"
*HW_GONIOMETER_RADIUS-0 "90.0"
*HW_GONIOMETER_RADIUS-1 "114.0"
*HW_GONIOMETER_RADIUS-2 "190.0"
*HW_GONIOMETER_RADIUS-3 "300.0"
*HW_GONIOMETER_RADIUS-4 "187.0"
*HW_GONIOMETER_RADIUS-5 "300.0"
*HW_GONIOMETER_RADIUS-6 "113.0"
*HW_GONIOMETER_RADIUS-7 "331.0"
*HW_I_OPT_ID-0 "CBO0021"
*HW_I_OPT_ID-1 "ICR0021"
*HW_I_OPT_ID-2 "ISL0021"
*HW_I_OPT_ID-3 "ISO0021"
*HW_I_OPT_ID-4 "IAD0021"
*HW_I_OPT_ID-5 "IPR0001"
*HW_I_OPT_NAME-0 "CBOユニット|CBO unit"
*HW_I_OPT_NAME-1 "標準入射光学ユニット|Standard incident optical unit"
*HW_I_OPT_NAME-2 "標準入射スリットボックス|Standard incident slit box"
*HW_I_OPT_NAME-3 "入射平行スリット|Incident parallel slit"
*HW_I_OPT_NAME-4 "長手制限スリット|Length limiting slit"
*HW_I_OPT_NAME-5 "None|None"
*HW_R_ATTENUATER_AUTOMODE "0"
*HW_R_OPT_ID-0 "RSS0022"
*HW_R_OPT_ID-1 "RCR0022"
*HW_R_OPT_ID-2 "RSO0021"
*HW_R_OPT_ID-3 "RRS0022"
*HW_R_OPT_ID-4 "ATN0020"
*HW_R_OPT_ID-5 "RFL0021"
*HW_R_OPT_ID-6 "RAD0021"
*HW_R_OPT_NAME-0 "受光スリットボックス1(Zr軸付)|Receiving slit box # 1 (w/ Zr Axis)"
*HW_R_OPT_NAME-1 "標準受光光学ユニット1|Standard receiving unit # 1"
*HW_R_OPT_NAME-2 "標準受光光学ユニット2|Standard receiving optical unit # 2"
*HW_R_OPT_NAME-3 "仮想受光スリット2|Virtual receiving slit #2"
*HW_R_OPT_NAME-4 "無し|None"
*HW_R_OPT_NAME-5 "Cu Kβ|Cu K-beta"
*HW_R_OPT_NAME-6 "調整用受光スリット|Alignment receiving slit"
*HW_SAMPLE_HOLDER_ID "SMP0021"
*HW_SAMPLE_HOLDER_NAME "χφZクレードル|Chi phi Z cradle"
*HW_XG_CURRENT_MAX "40"
*HW_XG_CURRENT_MIN "2"
*HW_XG_CURRENT_RESOLUTION "1"
*HW_XG_CURRENT_UNIT "mA"
*HW_XG_FOCUS "0.4mm x 8mm"
*HW_XG_FOCUS_TYPE "Fine"
*HW_XG_ID "1200"
*HW_XG_NAME "3kW 封入管(ID:1200)|3kW Sealed tube(ID:1200)"
*HW_XG_TARGET_ATOMIC_NUMBER "29.0000000000"
*HW_XG_TARGET_NAME "Cu"
*HW_XG_TYPE "Hermetic"
*HW_XG_VOLTAGE_MAX "40"
*HW_XG_VOLTAGE_MIN "20"
*HW_XG_VOLTAGE_RESOLUTION "1"
*HW_XG_VOLTAGE_UNIT "kV"
*HW_XG_WATT_MAX "1.500"
*HW_XG_WATT_UNIT "kW"
*HW_XG_WAVE_LENGTH_ALPHA1 "1.540593"
*HW_XG_WAVE_LENGTH_ALPHA2 "1.544414"
*HW_XG_WAVE_LENGTH_BETA "1.392250"
*MEAS_COND_AXIS_NAME-0 "Theta/2-Theta"
*MEAS_COND_AXIS_NAME-1 "2-Theta"
*MEAS_COND_AXIS_NAME-2 "Omega"
*MEAS_COND_AXIS_NAME-3 "Chi"
*MEAS_COND_AXIS_NAME-4 "Phi"
*MEAS_COND_AXIS_NAME-5 "Z"
*MEAS_COND_AXIS_NAME-6 "X"
*MEAS_COND_AXIS_NAME-7 "Y"
*MEAS_COND_AXIS_NAME-8 "2-Theta/Omega"
*MEAS_COND_AXIS_NAME-9 "2-ThetaChi"
*MEAS_COND_AXIS_NAME-10 "2-ThetaChi/Phi"
*MEAS_COND_AXIS_NAME-11 "Alpha"
*MEAS_COND_AXIS_NAME-12 "Beta"
*MEAS_COND_AXIS_NAME-13 "Theta_s"
*MEAS_COND_AXIS_NAME-14 "Theta_d"
*MEAS_COND_AXIS_NAME-15 "Ts"
*MEAS_COND_AXIS_NAME-16 "CBO selection slit"
*MEAS_COND_AXIS_NAME-17 "M"
*MEAS_COND_AXIS_NAME-18 "Incident parallel slit"
*MEAS_COND_AXIS_NAME-19 "Incident slit"
*MEAS_COND_AXIS_NAME-20 ""
*MEAS_COND_AXIS_NAME-21 "Zs"
*MEAS_COND_AXIS_NAME-22 "Incident optical device"
*MEAS_COND_AXIS_NAME-23 "Omega_m"
*MEAS_COND_AXIS_NAME-24 "Length limiting slit"
*MEAS_COND_AXIS_NAME-25 "Center slit"
*MEAS_COND_AXIS_NAME-26 "Filter"
*MEAS_COND_AXIS_NAME-27 "Receiving slit # 1"
*MEAS_COND_AXIS_NAME-28 "Receiving slit # 2"
*MEAS_COND_AXIS_NAME-29 "Receiving optical device"
*MEAS_COND_AXIS_NAME-30 "Receiving parallel slit"
*MEAS_COND_AXIS_NAME-31 "Alignment receiving slit"
*MEAS_COND_AXIS_NAME-32 ""
*MEAS_COND_AXIS_NAME-33 ""
*MEAS_COND_AXIS_NAME-34 "Zd"
*MEAS_COND_AXIS_NAME-35 "Attenuator"
*MEAS_COND_AXIS_NAME-36 "Diffracted beam monochromator"
*MEAS_COND_AXIS_NAME-37 "Monochromator slit"
*MEAS_COND_AXIS_NAME-38 "2-ThetaB"
*MEAS_COND_AXIS_NAME-39 ""
*MEAS_COND_AXIS_NAME-40 ""
*MEAS_COND_AXIS_NAME-41 "Zr"
*MEAS_COND_AXIS_NAME-42 "Primary beam"
*MEAS_COND_AXIS_NAME_INTERNAL-0 "TwoThetaTheta"
*MEAS_COND_AXIS_NAME_INTERNAL-1 "TwoTheta"
*MEAS_COND_AXIS_NAME_INTERNAL-2 "Omega"
*MEAS_COND_AXIS_NAME_INTERNAL-3 "Chi"
*MEAS_COND_AXIS_NAME_INTERNAL-4 "Phi"
*MEAS_COND_AXIS_NAME_INTERNAL-5 "Z"
*MEAS_COND_AXIS_NAME_INTERNAL-6 "X"
*MEAS_COND_AXIS_NAME_INTERNAL-7 "Y"
*MEAS_COND_AXIS_NAME_INTERNAL-8 "TwoThetaOmega"
*MEAS_COND_AXIS_NAME_INTERNAL-9 "TwoThetaChi"
*MEAS_COND_AXIS_NAME_INTERNAL-10 "TwoThetaChiPhi"
*MEAS_COND_AXIS_NAME_INTERNAL-11 "Alpha"
*MEAS_COND_AXIS_NAME_INTERNAL-12 "Beta"
*MEAS_COND_AXIS_NAME_INTERNAL-13 "ThetaS"
*MEAS_COND_AXIS_NAME_INTERNAL-14 "ThetaD"
*MEAS_COND_AXIS_NAME_INTERNAL-15 "Ts"
*MEAS_COND_AXIS_NAME_INTERNAL-16 "CBO"
*MEAS_COND_AXIS_NAME_INTERNAL-17 "CBO-M"
*MEAS_COND_AXIS_NAME_INTERNAL-18 "IncidentSollerSlit"
*MEAS_COND_AXIS_NAME_INTERNAL-19 "IncidentSlitBox"
*MEAS_COND_AXIS_NAME_INTERNAL-20 "IncidentSlitBox-_Axis"
*MEAS_COND_AXIS_NAME_INTERNAL-21 "Zs"
*MEAS_COND_AXIS_NAME_INTERNAL-22 "IncidentMonochromator"
*MEAS_COND_AXIS_NAME_INTERNAL-23 "IncidentMonochromator-OmegaM"
*MEAS_COND_AXIS_NAME_INTERNAL-24 "IncidentAxdSlit"
*MEAS_COND_AXIS_NAME_INTERNAL-25 "CenterSlit"
*MEAS_COND_AXIS_NAME_INTERNAL-26 "Filter"
*MEAS_COND_AXIS_NAME_INTERNAL-27 "ReceivingSlitBox1"
*MEAS_COND_AXIS_NAME_INTERNAL-28 "ReceivingSlitBox2"
*MEAS_COND_AXIS_NAME_INTERNAL-29 "ReceivingOptics"
*MEAS_COND_AXIS_NAME_INTERNAL-30 "ReceivingSollerSlit"
*MEAS_COND_AXIS_NAME_INTERNAL-31 "ReceivingAxdSlit"
*MEAS_COND_AXIS_NAME_INTERNAL-32 "ReceivingSlitBox1-_Axis"
*MEAS_COND_AXIS_NAME_INTERNAL-33 "ReceivingSlitBox2-_Axis"
*MEAS_COND_AXIS_NAME_INTERNAL-34 "ReceivingSlitBox2-Zd"
*MEAS_COND_AXIS_NAME_INTERNAL-35 "Attenuator"
*MEAS_COND_AXIS_NAME_INTERNAL-36 "CounterMonochromator"
*MEAS_COND_AXIS_NAME_INTERNAL-37 "CounterSlit"
*MEAS_COND_AXIS_NAME_INTERNAL-38 "TwoThetaB"
*MEAS_COND_AXIS_NAME_INTERNAL-39 "AlphaR"
*MEAS_COND_AXIS_NAME_INTERNAL-40 "BetaR"
*MEAS_COND_AXIS_NAME_INTERNAL-41 "ReceivingSlitBox1-Zr"
*MEAS_COND_AXIS_NAME_INTERNAL-42 "IncidentPrimary"
*MEAS_COND_AXIS_NAME_MAGICNO-0 "83951616.0000000000"
*MEAS_COND_AXIS_NAME_MAGICNO-1 "268632064.0000000000"
*MEAS_COND_AXIS_NAME_MAGICNO-2 "268500992.0000000000"
*MEAS_COND_AXIS_NAME_MAGICNO-3 "268500992.0000000000"
*MEAS_COND_AXIS_NAME_MAGICNO-4 "268500992.0000000000"
*MEAS_COND_AXIS_NAME_MAGICNO-5 "285278208.0000000000"
*MEAS_COND_AXIS_NAME_MAGICNO-6 "268500992.0000000000"
*MEAS_COND_AXIS_NAME_MAGICNO-7 "268500992.0000000000"
*MEAS_COND_AXIS_NAME_MAGICNO-8 "83951616.0000000000"
*MEAS_COND_AXIS_NAME_MAGICNO-9 "268632064.0000000000"
*MEAS_COND_AXIS_NAME_MAGICNO-10 "83951616.0000000000"
*MEAS_COND_AXIS_NAME_MAGICNO-11 "17039360.0000000000"
*MEAS_COND_AXIS_NAME_MAGICNO-12 "17039360.0000000000"
*MEAS_COND_AXIS_NAME_MAGICNO-13 "131072.0000000000"
*MEAS_COND_AXIS_NAME_MAGICNO-14 "131072.0000000000"
*MEAS_COND_AXIS_NAME_MAGICNO-15 "318898176.0000000000"
*MEAS_COND_AXIS_NAME_MAGICNO-16 "20971521.0000000000"
*MEAS_COND_AXIS_NAME_MAGICNO-17 "285343744.0000000000"
*MEAS_COND_AXIS_NAME_MAGICNO-18 "20971521.0000000000"
*MEAS_COND_AXIS_NAME_MAGICNO-19 "22020097.0000000000"
*MEAS_COND_AXIS_NAME_MAGICNO-20 "25165824.0000000000"
*MEAS_COND_AXIS_NAME_MAGICNO-21 "318898176.0000000000"
*MEAS_COND_AXIS_NAME_MAGICNO-22 "20971521.0000000000"
*MEAS_COND_AXIS_NAME_MAGICNO-23 "285343744.0000000000"
*MEAS_COND_AXIS_NAME_MAGICNO-24 "20971521.0000000000"
*MEAS_COND_AXIS_NAME_MAGICNO-25 "20971521.0000000000"
*MEAS_COND_AXIS_NAME_MAGICNO-26 "20971521.0000000000"
*MEAS_COND_AXIS_NAME_MAGICNO-27 "23068673.0000000000"
*MEAS_COND_AXIS_NAME_MAGICNO-28 "23068673.0000000000"
*MEAS_COND_AXIS_NAME_MAGICNO-29 "20971521.0000000000"
*MEAS_COND_AXIS_NAME_MAGICNO-30 "20971521.0000000000"
*MEAS_COND_AXIS_NAME_MAGICNO-31 "20971521.0000000000"
*MEAS_COND_AXIS_NAME_MAGICNO-32 "25165824.0000000000"
*MEAS_COND_AXIS_NAME_MAGICNO-33 "25165824.0000000000"
*MEAS_COND_AXIS_NAME_MAGICNO-34 "285343744.0000000000"
*MEAS_COND_AXIS_NAME_MAGICNO-35 "0.0000000000"
*MEAS_COND_AXIS_NAME_MAGICNO-36 "20971521.0000000000"
*MEAS_COND_AXIS_NAME_MAGICNO-37 "20971521.0000000000"
*MEAS_COND_AXIS_NAME_MAGICNO-38 "17039360.0000000000"
*MEAS_COND_AXIS_NAME_MAGICNO-39 "8388608.0000000000"
*MEAS_COND_AXIS_NAME_MAGICNO-40 "8388608.0000000000"
*MEAS_COND_AXIS_NAME_MAGICNO-41 "285343744.0000000000"
*MEAS_COND_AXIS_NAME_MAGICNO-42 "20971521.0000000000"
*MEAS_COND_AXIS_OFFSET-0 "-"
*MEAS_COND_AXIS_OFFSET-1 "0.9377000000"
*MEAS_COND_AXIS_OFFSET-2 "1.5052000000"
*MEAS_COND_AXIS_OFFSET-3 "0.0000000000"
*MEAS_COND_AXIS_OFFSET-4 "0.0000000000"
*MEAS_COND_AXIS_OFFSET-5 "-"
*MEAS_COND_AXIS_OFFSET-6 "0.0000000000"
*MEAS_COND_AXIS_OFFSET-7 "0.0000000000"
*MEAS_COND_AXIS_OFFSET-8 "-"
*MEAS_COND_AXIS_OFFSET-9 "0.0000000000"
*MEAS_COND_AXIS_OFFSET-10 "-"
*MEAS_COND_AXIS_OFFSET-11 "-"
*MEAS_COND_AXIS_OFFSET-12 "-"
*MEAS_COND_AXIS_OFFSET-13 "1.5052000000"
*MEAS_COND_AXIS_OFFSET-14 "-0.5675000000"
*MEAS_COND_AXIS_OFFSET-15 "-"
*MEAS_COND_AXIS_OFFSET-16 "-"
*MEAS_COND_AXIS_OFFSET-17 "-"
*MEAS_COND_AXIS_OFFSET-18 "-"
*MEAS_COND_AXIS_OFFSET-19 "-"
*MEAS_COND_AXIS_OFFSET-20 "-"
*MEAS_COND_AXIS_OFFSET-21 "-"
*MEAS_COND_AXIS_OFFSET-22 "-"
*MEAS_COND_AXIS_OFFSET-23 "-"
*MEAS_COND_AXIS_OFFSET-24 "-"
*MEAS_COND_AXIS_OFFSET-25 "-"
*MEAS_COND_AXIS_OFFSET-26 "-"
*MEAS_COND_AXIS_OFFSET-27 "-"
*MEAS_COND_AXIS_OFFSET-28 "-"
*MEAS_COND_AXIS_OFFSET-29 "-"
*MEAS_COND_AXIS_OFFSET-30 "-"
*MEAS_COND_AXIS_OFFSET-31 "-"
*MEAS_COND_AXIS_OFFSET-32 "-"
*MEAS_COND_AXIS_OFFSET-33 "-"
*MEAS_COND_AXIS_OFFSET-34 "-"
*MEAS_COND_AXIS_OFFSET-35 "-"
*MEAS_COND_AXIS_OFFSET-36 "-"
*MEAS_COND_AXIS_OFFSET-37 "-"
*MEAS_COND_AXIS_OFFSET-38 "-"
*MEAS_COND_AXIS_OFFSET-39 "0.0000000000"
*MEAS_COND_AXIS_OFFSET-40 "0.0000000000"
*MEAS_COND_AXIS_OFFSET-41 "-"
*MEAS_COND_AXIS_OFFSET-42 "-"
*MEAS_COND_AXIS_POSITION-0 "40.0000000000"
*MEAS_COND_AXIS_POSITION-1 "40.0000000000"
*MEAS_COND_AXIS_POSITION-2 "20.0000000000"
*MEAS_COND_AXIS_POSITION-3 "0.0000000000"
*MEAS_COND_AXIS_POSITION-4 "0.0000000000"
*MEAS_COND_AXIS_POSITION-5 "-1.6476000000"
*MEAS_COND_AXIS_POSITION-6 "0.0000000000"
*MEAS_COND_AXIS_POSITION-7 "0.0000000000"
*MEAS_COND_AXIS_POSITION-8 "40.0000000000"
*MEAS_COND_AXIS_POSITION-9 "0.0000000000"
*MEAS_COND_AXIS_POSITION-10 "0.0000000000"
*MEAS_COND_AXIS_POSITION-11 "90.0000000000"
*MEAS_COND_AXIS_POSITION-12 "0.0000000000"
*MEAS_COND_AXIS_POSITION-13 "20.0000000000"
*MEAS_COND_AXIS_POSITION-14 "20.0000000000"
*MEAS_COND_AXIS_POSITION-15 "-5.5290600000"
*MEAS_COND_AXIS_POSITION-16 "PB"
*MEAS_COND_AXIS_POSITION-17 "0.0000000000"
*MEAS_COND_AXIS_POSITION-18 "Soller_slit_2.5deg_s"
*MEAS_COND_AXIS_POSITION-19 "1.000mm"
*MEAS_COND_AXIS_POSITION-20 "1.0000000000"
*MEAS_COND_AXIS_POSITION-21 "-1.4025000000"
*MEAS_COND_AXIS_POSITION-22 "Ge(220)x2"
*MEAS_COND_AXIS_POSITION-23 "0.0000000000"
*MEAS_COND_AXIS_POSITION-24 "5.0mm"
*MEAS_COND_AXIS_POSITION-25 "None"
*MEAS_COND_AXIS_POSITION-26 "None"
*MEAS_COND_AXIS_POSITION-27 "20.000mm"
*MEAS_COND_AXIS_POSITION-28 "38.500mm"
*MEAS_COND_AXIS_POSITION-29 "PSA_open"
*MEAS_COND_AXIS_POSITION-30 "Soller_slit_2.5deg"
*MEAS_COND_AXIS_POSITION-31 "None"
*MEAS_COND_AXIS_POSITION-32 "20.0000000000"
*MEAS_COND_AXIS_POSITION-33 "38.5000000000"
*MEAS_COND_AXIS_POSITION-34 "0.0000000000"
*MEAS_COND_AXIS_POSITION-35 "-"
*MEAS_COND_AXIS_POSITION-36 "No_unit"
*MEAS_COND_AXIS_POSITION-37 "None"
*MEAS_COND_AXIS_POSITION-38 "40.0000000000"
*MEAS_COND_AXIS_POSITION-39 "0.0000000000"
*MEAS_COND_AXIS_POSITION-40 "0.0000000000"
*MEAS_COND_AXIS_POSITION-41 "0.1125000000"
*MEAS_COND_AXIS_POSITION-42 "None"
*MEAS_COND_AXIS_UNIT-0 "deg"
*MEAS_COND_AXIS_UNIT-1 "deg"
*MEAS_COND_AXIS_UNIT-2 "deg"
*MEAS_COND_AXIS_UNIT-3 "deg"
*MEAS_COND_AXIS_UNIT-4 "deg"
*MEAS_COND_AXIS_UNIT-5 "mm"
*MEAS_COND_AXIS_UNIT-6 "mm"
*MEAS_COND_AXIS_UNIT-7 "mm"
*MEAS_COND_AXIS_UNIT-8 "deg"
*MEAS_COND_AXIS_UNIT-9 "deg"
*MEAS_COND_AXIS_UNIT-10 "deg"
*MEAS_COND_AXIS_UNIT-11 "deg"
*MEAS_COND_AXIS_UNIT-12 "deg"
*MEAS_COND_AXIS_UNIT-13 "deg"
*MEAS_COND_AXIS_UNIT-14 "deg"
*MEAS_COND_AXIS_UNIT-15 "mm"
*MEAS_COND_AXIS_UNIT-16 ""
*MEAS_COND_AXIS_UNIT-17 "pulse"
*MEAS_COND_AXIS_UNIT-18 ""
*MEAS_COND_AXIS_UNIT-19 ""
*MEAS_COND_AXIS_UNIT-20 "mm"
*MEAS_COND_AXIS_UNIT-21 "mm"
*MEAS_COND_AXIS_UNIT-22 ""
*MEAS_COND_AXIS_UNIT-23 "pulse"
*MEAS_COND_AXIS_UNIT-24 ""
*MEAS_COND_AXIS_UNIT-25 ""
*MEAS_COND_AXIS_UNIT-26 ""
*MEAS_COND_AXIS_UNIT-27 ""
*MEAS_COND_AXIS_UNIT-28 ""
*MEAS_COND_AXIS_UNIT-29 ""
*MEAS_COND_AXIS_UNIT-30 ""
*MEAS_COND_AXIS_UNIT-31 ""
*MEAS_COND_AXIS_UNIT-32 "mm"
*MEAS_COND_AXIS_UNIT-33 "mm"
*MEAS_COND_AXIS_UNIT-34 "mm"
*MEAS_COND_AXIS_UNIT-35 ""
*MEAS_COND_AXIS_UNIT-36 ""
*MEAS_COND_AXIS_UNIT-37 ""
*MEAS_COND_AXIS_UNIT-38 "deg"
*MEAS_COND_AXIS_UNIT-39 "deg"
*MEAS_COND_AXIS_UNIT-40 "deg"
*MEAS_COND_AXIS_UNIT-41 "mm"
*MEAS_COND_AXIS_UNIT-42 ""
*MEAS_COND_COUNTER_CNTLOSS_CORR "0.0000000000"
*MEAS_COND_COUNTER_TAUDIFF "0.0000000000"
*MEAS_COND_COUNTER_TAUINT "0.0000000000"
*MEAS_COND_COUNTER_TEMP_CONDITION "NORMAL"
*MEAS_COND_IRRADIATION_MODE "OFF"
*MEAS_COND_IRRADIATION_WIDTH ""
*MEAS_COND_OPT_ATTR "High resolution parallel beam Ge(220)x2/RS"
*MEAS_COND_OPT_NAME "@High resolution PB-Ge(220)x2"
*MEAS_COND_UNSYMMETRIC_MODE "OFF"
*MEAS_COND_XG_CURRENT "30.0000000000"
*MEAS_COND_XG_VOLTAGE "40.0000000000"
*MEAS_COND_XG_WAVE_TYPE "Ka1"
*MEAS_DATA_COUNT "9001.0000000000"
*MEAS_SCAN_AXIS_X "Theta/2-Theta"
*MEAS_SCAN_AXIS_X_INTERNAL "TwoThetaTheta"
*MEAS_SCAN_END_TIME "03/01/21 20:03:04"
*MEAS_SCAN_MODE "CONTINUOUS"
*MEAS_SCAN_MONITOR "0"
*MEAS_SCAN_RESOLUTION_X "0.0002"
*MEAS_SCAN_SPEED "0.503240"
*MEAS_SCAN_SPEED_UNIT "deg/min"
*MEAS_SCAN_SPEED_USER "0.5"
*MEAS_SCAN_START "40.0000000000"
*MEAS_SCAN_START_TIME "03/01/21 16:48:15"
*MEAS_SCAN_STEP "0.0100000000"
*MEAS_SCAN_STOP "130.0000000000"
*MEAS_SCAN_UNIT_X "deg"
*MEAS_SCAN_UNIT_Y "counts"
*RAS_HEADER_END
*RAS_INT_START
40.0000 82.0474 1.0000
40.0700 67.7639 1.0000
40.1400 70.0953 1.0000
40.2100 70.8464 1.0000
40.2800 66.9794 1.0000
40.3500 66.4129 1.0000
40.4200 75.5639 1.0000
40.4900 74.9804 1.0000
40.5600 60.9516 1.0000
40.6300 66.9735 1.0000
40.7000 66.5814 1.0000
40.7700 76.1951 1.0000
40.8400 88.8144 1.0000
40.9100 62.9717 1.0000
40.9800 68.2408 1.0000
41.0500 65.0168 1.0000
41.1200 71.3922 1.0000
41.1900 59.7544 1.0000
41.2600 70.1746 1.0000
41.3300 72.0341 1.0000
41.4000 70.8796 1.0000
41.4700 65.8754 1.0000
41.5400 73.1794 1.0000
41.6100 73.5817 1.0000
41.6800 76.9488 1.0000
41.7500 58.0770 1.0000
41.8200 68.4785 1.0000
41.8900 73.5545 1.0000
41.9600 58.6055 1.0000
42.0300 69.5975 1.0000
42.1000 62.1484 1.0000
42.1700 76.1080 1.0000
42.2400 77.8326 1.0000
42.3100 77.7760 1.0000
42.3800 72.5937 1.0000
42.4500 75.5917 1.0000
42.5200 65.7407 1.0000
42.5900 70.8995 1.0000
42.6600 70.8343 1.0000
42.7300 62.2106 1.0000
42.8000 62.1627 1.0000
42.8700 68.4936 1.0000
42.9400 64.8796 1.0000
43.0100 68.0384 1.0000
43.0800 72.1595 1.0000
43.1500 49.8462 1.0000
43.2200 73.9831 1.0000
43.2900 60.4259 1.0000
43.3600 67.6893 1.0000
43.4300 76.1818 1.0000
43.5000 70.3123 1.0000
43.5700 88.9793 1.0000
43.6400 68.7704 1.0000
43.7100 73.0886 1.0000
43.7800 76.3347 1.0000
43.8500 83.1296 1.0000
43.9200 63.8133 1.0000
43.9900 82.3184 1.0000
44.0600 110.2254 1.0000
44.1300 123.7166 1.0000
44.2000 149.0320 1.0000
44.2700 200.5838 1.0000
44.3400 356.3119 1.0000
44.4100 948.2002 1.0000
44.4800 3412.5947 1.0000
44.5500 5200.7080 1.0000
44.6200 3323.8032 1.0000
44.6900 959.9587 1.0000
44.7600 332.5063 1.0000
44.8300 203.9321 1.0000
44.9000 124.0362 1.0000
44.9700 97.1716 1.0000
45.0400 85.8986 1.0000
45.1100 87.9589 1.0000
45.1800 79.4661 1.0000
45.2500 63.4467 1.0000
45.3200 71.1037 1.0000
45.3900 56.7442 1.0000
45.4600 74.5049 1.0000
45.5300 84.3772 1.0000
45.6000 60.9639 1.0000
45.6700 66.8791 1.0000
45.7400 62.9613 1.0000
45.8100 69.7424 1.0000
45.8800 60.2600 1.0000
45.9500 68.9230 1.0000
46.0200 69.3018 1.0000
46.0900 58.4664 1.0000
46.1600 76.4406 1.0000
46.2300 70.4130 1.0000
46.3000 58.0116 1.0000
46.3700 73.8724 1.0000
46.4400 62.7837 1.0000
46.5100 61.5148 1.0000
46.5800 69.1001 1.0000
46.6500 61.6622 1.0000
46.7200 63.0733 1.0000
46.7900 72.4370 1.0000
46.8600 53.1270 1.0000
46.9300 53.9403 1.0000
47.0000 71.2718 1.0000
47.0700 66.3103 1.0000
47.1400 55.4381 1.0000
47.2100 63.9453 1.0000
47.2800 60.1022 1.0000
47.3500 69.2539 1.0000
47.4200 61.2128 1.0000
47.4900 56.6874 1.0000
47.5600 52.5036 1.0000
47.6300 75.3546 1.0000
47.7000 63.0866 1.0000
47.7700 57.6883 1.0000
47.8400 59.9859 1.0000
47.9100 66.6606 1.0000
47.9800 62.7507 1.0000
48.0500 58.7820 1.0000
48.1200 41.6774 1.0000
48.1900 51.4740 1.0000
48.2600 62.2312 1.0000
48.3300 48.4300 1.0000
48.4000 67.3891 1.0000
48.4700 59.5596 1.0000
48.5400 72.7832 1.0000
48.6100 57.3234 1.0000
48.6800 57.2069 1.0000
48.7500 57.3580 1.0000
48.8200 76.6180 1.0000
48.8900 68.2954 1.0000
48.9600 59.0530 1.0000
49.0300 71.1950 1.0000
49.1000 59.4608 1.0000
49.1700 59.2111 1.0000
49.2400 59.8134 1.0000
49.3100 43.9796 1.0000
49.3800 58.9299 1.0000
49.4500 74.6869 1.0000
49.5200 60.3822 1.0000
49.5900 66.1141 1.0000
49.6600 57.4078 1.0000
49.7300 60.8845 1.0000
49.8000 61.1001 1.0000
49.8700 55.4506 1.0000
49.9400 51.8088 1.0000
50.0100 58.2989 1.0000
50.0800 70.9537 1.0000
50.1500 74.5183 1.0000
50.2200 73.9682 1.0000
50.2900 51.8915 1.0000
50.3600 71.4970 1.0000
50.4300 59.2468 1.0000
50.5000 61.1866 1.0000
50.5700 64.1226 1.0000
50.6400 68.9643 1.0000
50.7100 56.1563 1.0000
50.7800 59.2994 1.0000
50.8500 62.9411 1.0000
50.9200 66.0328 1.0000
50.9900 60.0992 1.0000
51.0600 52.7912 1.0000
51.1300 60.8791 1.0000
51.2000 64.0884 1.0000
51.2700 59.5944 1.0000
51.3400 59.8914 1.0000
51.4100 61.7447 1.0000
51.4800 61.5582 1.0000
51.5500 65.1328 1.0000
51.6200 61.6439 1.0000
51.6900 58.6391 1.0000
51.7600 51.3981 1.0000
51.8300 51.8765 1.0000
51.9000 57.0026 1.0000
51.9700 61.6134 1.0000
52.0400 66.0171 1.0000
52.1100 62.5976 1.0000
52.1800 65.1521 1.0000
52.2500 49.5329 1.0000
52.3200 63.4799 1.0000
52.3900 54.9353 1.0000
52.4600 68.7300 1.0000
52.5300 59.8997 1.0000
52.6000 63.5764 1.0000
52.6700 58.8428 1.0000
52.7400 66.5055 1.0000
52.8100 61.4447 1.0000
52.8800 61.8336 1.0000
52.9500 65.5802 1.0000
53.0200 65.2644 1.0000
53.0900 56.3348 1.0000
53.1600 50.5129 1.0000
53.2300 50.2296 1.0000
53.3000 73.1217 1.0000
53.3700 48.8075 1.0000
53.4400 62.9435 1.0000
53.5100 60.3513 1.0000
53.5800 58.7387 1.0000
53.6500 46.1193 1.0000
53.7200 50.4262 1.0000
53.7900 72.1764 1.0000
53.8600 54.0869 1.0000
53.9300 58.5801 1.0000
54.0000 57.9634 1.0000
54.0700 52.2350 1.0000
54.1400 55.2730 1.0000
54.2100 58.6217 1.0000
54.2800 56.6315 1.0000
54.3500 63.0552 1.0000
54.4200 59.4815 1.0000
54.4900 57.7366 1.0000
54.5600 56.1376 1.0000
54.6300 49.9874 1.0000
54.7000 78.7995 1.0000
54.7700 67.1597 1.0000
54.8400 60.3118 1.0000
54.9100 65.8666 1.0000
54.9800 54.7749 1.0000
55.0500 48.5399 1.0000
55.1200 59.3665 1.0000
55.1900 67.4731 1.0000
55.2600 58.3741 1.0000
55.3300 48.9787 1.0000
55.4000 66.2919 1.0000
55.4700 59.9238 1.0000
55.5400 59.2562 1.0000
55.6100 54.5242 1.0000
55.6800 60.1471 1.0000
55.7500 62.4234 1.0000
55.8200 66.5630 1.0000
55.8900 74.4643 1.0000
55.9600 65.6802 1.0000
56.0300 50.1744 1.0000
56.1000 63.0806 1.0000
56.1700 60.6539 1.0000
56.2400 55.3441 1.0000
56.3100 54.0011 1.0000
56.3800 52.7075 1.0000
56.4500 63.5952 1.0000
56.5200 51.1001 1.0000
56.5900 58.0185 1.0000
56.6600 46.6937 1.0000
56.7300 51.5620 1.0000
56.8000 53.5928 1.0000
56.8700 65.4699 1.0000
56.9400 51.3749 1.0000
57.0100 50.1751 1.0000
57.0800 46.1568 1.0000
57.1500 48.9220 1.0000
57.2200 58.7604 1.0000
57.2900 53.8896 1.0000
57.3600 60.8474 1.0000
57.4300 66.5776 1.0000
57.5000 70.4658 1.0000
57.5700 60.1722 1.0000
57.6400 57.3765 1.0000
57.7100 62.1999 1.0000
57.7800 50.1926 1.0000
57.8500 66.7624 1.0000
57.9200 56.1620 1.0000
57.9900 61.0418 1.0000
58.0600 65.1228 1.0000
58.1300 52.9778 1.0000
58.2000 51.1113 1.0000
58.2700 48.9803 1.0000
58.3400 60.2808 1.0000
58.4100 48.6551 1.0000
58.4800 60.1653 1.0000
58.5500 47.1109 1.0000
58.6200 64.6511 1.0000
58.6900 67.3399 1.0000
58.7600 61.5676 1.0000
58.8300 51.6918 1.0000
58.9000 65.2982 1.0000
58.9700 53.9792 1.0000
59.0400 53.7509 1.0000
59.1100 52.0304 1.0000
59.1800 41.6247 1.0000
59.2500 48.2730 1.0000
59.3200 50.5986 1.0000
59.3900 50.5056 1.0000
59.4600 48.6244 1.0000
59.5300 61.9906 1.0000
59.6000 58.1018 1.0000
59.6700 44.2694 1.0000
59.7400 62.7782 1.0000
59.8100 58.5582 1.0000
59.8800 67.5880 1.0000
59.9500 49.4681 1.0000
60.0200 53.2020 1.0000
60.0900 54.9449 1.0000
60.1600 49.2905 1.0000
60.2300 61.0753 1.0000
60.3000 55.9481 1.0000
60.3700 54.4144 1.0000
60.4400 58.0553 1.0000
60.5100 52.7491 1.0000
60.5800 65.3808 1.0000
60.6500 52.0935 1.0000
60.7200 63.4334 1.0000
60.7900 57.4979 1.0000
60.8600 56.0896 1.0000
60.9300 41.7598 1.0000
61.0000 62.9904 1.0000
61.0700 63.2367 1.0000
61.1400 54.8889 1.0000
61.2100 36.8695 1.0000
61.2800 59.6324 1.0000
61.3500 51.0386 1.0000
61.4200 57.0287 1.0000
61.4900 51.8737 1.0000
61.5600 49.7654 1.0000
61.6300 57.2831 1.0000
61.7000 59.2393 1.0000
61.7700 57.2202 1.0000
61.8400 51.7510 1.0000
61.9100 48.4290 1.0000
61.9800 54.4559 1.0000
62.0500 56.8378 1.0000
62.1200 47.4348 1.0000
62.1900 45.1020 1.0000
62.2600 54.7992 1.0000
62.3300 47.0110 1.0000
62.4000 51.6718 1.0000
62.4700 48.3665 1.0000
62.5400 51.5120 1.0000
62.6100 54.8700 1.0000
62.6800 55.9486 1.0000
62.7500 48.3466 1.0000
62.8200 56.2424 1.0000
62.8900 54.6353 1.0000
62.9600 55.6393 1.0000
63.0300 57.0935 1.0000
63.1000 52.5337 1.0000
63.1700 57.7097 1.0000
63.2400 71.0700 1.0000
63.3100 63.7099 1.0000
63.3800 53.9131 1.0000
63.4500 47.9952 1.0000
63.5200 61.4324 1.0000
63.5900 69.3121 1.0000
63.6600 46.6142 1.0000
63.7300 54.6973 1.0000
63.8000 48.8667 1.0000
63.8700 46.3771 1.0000
63.9400 65.9163 1.0000
64.0100 62.3073 1.0000
64.0800 61.0121 1.0000
64.1500 67.9210 1.0000
64.2200 62.6063 1.0000
64.2900 66.0350 1.0000
64.3600 53.0982 1.0000
64.4300 51.9401 1.0000
64.5000 79.2617 1.0000
64.5700 84.7975 1.0000
64.6400 116.1539 1.0000
64.7100 177.8696 1.0000
64.7800 192.6754 1.0000
64.8500 177.1048 1.0000
64.9200 113.4524 1.0000
64.9900 99.3466 1.0000
65.0600 55.6486 1.0000
65.1300 57.7546 1.0000
65.2000 62.0386 1.0000
65.2700 61.4408 1.0000
65.3400 57.0488 1.0000
65.4100 50.4561 1.0000
65.4800 49.3740 1.0000
65.5500 66.2629 1.0000
65.6200 56.0587 1.0000
65.6900 52.7491 1.0000
65.7600 57.1884 1.0000
65.8300 60.3934 1.0000
65.9000 71.4704 1.0000
65.9700 65.3329 1.0000
66.0400 54.9222 1.0000
66.1100 53.2801 1.0000
66.1800 40.0694 1.0000
66.2500 58.2381 1.0000
66.3200 63.2346 1.0000
66.3900 51.5224 1.0000
66.4600 52.8690 1.0000
66.5300 62.3896 1.0000
66.6000 58.4307 1.0000
66.6700 52.9977 1.0000
66.7400 44.1866 1.0000
66.8100 53.9326 1.0000
66.8800 64.2926 1.0000
66.9500 56.2230 1.0000
67.0200 56.2225 1.0000
67.0900 50.9200 1.0000
67.1600 58.3594 1.0000
67.2300 59.8347 1.0000
67.3000 64.7694 1.0000
67.3700 47.7644 1.0000
67.4400 50.6000 1.0000
67.5100 50.3293 1.0000
67.5800 57.4179 1.0000
67.6500 59.9147 1.0000
67.7200 46.3820 1.0000
67.7900 42.8124 1.0000
67.8600 53.6992 1.0000
67.9300 42.6952 1.0000
68.0000 58.6451 1.0000
68.0700 60.5112 1.0000
68.1400 47.7654 1.0000
68.2100 63.0598 1.0000
68.2800 61.5741 1.0000
68.3500 52.7496 1.0000
68.4200 67.0186 1.0000
68.4900 56.2493 1.0000
68.5600 62.0499 1.0000
68.6300 59.7605 1.0000
68.7000 58.4568 1.0000
68.7700 47.1778 1.0000
68.8400 53.1246 1.0000
68.9100 48.2184 1.0000
68.9800 41.6352 1.0000
69.0500 58.3446 1.0000
69.1200 54.5867 1.0000
69.1900 40.5424 1.0000
69.2600 43.5645 1.0000
69.3300 49.2938 1.0000
69.4000 57.7616 1.0000
69.4700 55.6682 1.0000
69.5400 50.4047 1.0000
69.6100 58.0888 1.0000
69.6800 52.7260 1.0000
69.7500 49.2144 1.0000
69.8200 62.2414 1.0000
69.8900 47.9265 1.0000
69.9600 50.9983 1.0000
70.0300 46.0187 1.0000
70.1000 66.8938 1.0000
70.1700 58.5538 1.0000
70.2400 34.9359 1.0000
70.3100 48.0698 1.0000
70.3800 54.5884 1.0000
70.4500 54.6393 1.0000
70.5200 51.9148 1.0000
70.5900 55.2996 1.0000
70.6600 53.4070 1.0000
70.7300 51.5930 1.0000
70.8000 52.5751 1.0000
70.8700 59.3035 1.0000
70.9400 70.4368 1.0000
71.0100 53.6904 1.0000
71.0800 45.8526 1.0000
71.1500 50.5426 1.0000
71.2200 50.7003 1.0000
71.2900 50.1760 1.0000
71.3600 54.1882 1.0000
71.4300 50.8399 1.0000
71.5000 56.8561 1.0000
71.5700 48.8806 1.0000
71.6400 53.2749 1.0000
71.7100 48.8996 1.0000
71.7800 56.7655 1.0000
71.8500 48.8970 1.0000
71.9200 61.1510 1.0000
71.9900 48.6866 1.0000
72.0600 52.9675 1.0000
72.1300 62.5641 1.0000
72.2000 55.4800 1.0000
72.2700 50.8320 1.0000
72.3400 44.3514 1.0000
72.4100 62.3476 1.0000
72.4800 50.4724 1.0000
72.5500 51.7101 1.0000
72.6200 50.7849 1.0000
72.6900 45.4467 1.0000
72.7600 44.0942 1.0000
72.8300 55.5739 1.0000
72.9000 52.8400 1.0000
72.9700 59.2493 1.0000
73.0400 55.1597 1.0000
73.1100 71.8964 1.0000
73.1800 51.6768 1.0000
73.2500 65.4826 1.0000
73.3200 49.8471 1.0000
73.3900 51.2034 1.0000
73.4600 45.6877 1.0000
73.5300 45.8041 1.0000
73.6000 51.2704 1.0000
73.6700 63.4006 1.0000
73.7400 61.6168 1.0000
73.8100 49.8102 1.0000
73.8800 52.3461 1.0000
73.9500 46.8055 1.0000
74.0200 52.2872 1.0000
74.0900 45.6999 1.0000
74.1600 49.7524 1.0000
74.2300 61.7563 1.0000
74.3000 56.3289 1.0000
74.3700 47.9122 1.0000
74.4400 52.3631 1.0000
74.5100 44.6777 1.0000
74.5800 57.0574 1.0000
74.6500 56.5614 1.0000
74.7200 45.5662 1.0000
74.7900 43.9316 1.0000
74.8600 55.6050 1.0000
74.9300 55.1570 1.0000
75.0000 58.8020 1.0000
75.0700 56.0755 1.0000
75.1400 49.4360 1.0000
75.2100 54.5722 1.0000
75.2800 50.7836 1.0000
75.3500 49.4701 1.0000
75.4200 52.1689 1.0000
75.4900 49.2768 1.0000
75.5600 49.1413 1.0000
75.6300 47.7129 1.0000
75.7000 43.4757 1.0000
75.7700 54.7636 1.0000
75.8400 45.9746 1.0000
75.9100 46.7429 1.0000
75.9800 59.3570 1.0000
76.0500 58.0596 1.0000
76.1200 59.7377 1.0000
76.1900 57.5868 1.0000
76.2600 61.8843 1.0000
76.3300 67.4015 1.0000
76.4000 55.4518 1.0000
76.4700 53.3549 1.0000
76.5400 43.6693 1.0000
76.6100 57.8093 1.0000
76.6800 57.6684 1.0000
76.7500 61.6163 1.0000
76.8200 62.9344 1.0000
76.8900 47.9719 1.0000
76.9600 50.4236 1.0000
77.0300 44.0387 1.0000
77.1000 46.2757 1.0000
77.1700 40.7148 1.0000
77.2400 43.3330 1.0000
77.3100 47.4490 1.0000
77.3800 55.7538 1.0000
77.4500 49.6623 1.0000
77.5200 50.8286 1.0000
77.5900 54.6436 1.0000
77.6600 55.7250 1.0000
77.7300 60.3308 1.0000
77.8000 55.7704 1.0000
77.8700 49.0106 1.0000
77.9400 62.5392 1.0000
78.0100 48.5230 1.0000
78.0800 58.8281 1.0000
78.1500 46.1512 1.0000
78.2200 48.2754 1.0000
78.2900 44.3188 1.0000
78.3600 48.1115 1.0000
78.4300 45.7844 1.0000
78.5000 50.1462 1.0000
78.5700 51.3110 1.0000
78.6400 43.0914 1.0000
78.7100 50.9789 1.0000
78.7800 60.3841 1.0000
78.8500 47.8233 1.0000
78.9200 56.8168 1.0000
78.9900 48.4654 1.0000
79.0600 45.4727 1.0000
79.1300 45.2771 1.0000
79.2000 57.3310 1.0000
79.2700 51.2576 1.0000
79.3400 58.1215 1.0000
79.4100 48.7968 1.0000
79.4800 54.0855 1.0000
79.5500 51.1047 1.0000
79.6200 58.7196 1.0000
79.6900 51.5421 1.0000
79.7600 54.3411 1.0000
79.8300 62.0901 1.0000
79.9000 57.3389 1.0000
79.9700 52.8938 1.0000
80.0400 49.1190 1.0000
80.1100 55.3892 1.0000
80.1800 49.4779 1.0000
80.2500 50.3553 1.0000
80.3200 58.6028 1.0000
80.3900 55.8242 1.0000
80.4600 55.8642 1.0000
80.5300 56.1264 1.0000
80.6000 57.2198 1.0000
80.6700 53.8622 1.0000
80.7400 43.5246 1.0000
80.8100 53.1047 1.0000
80.8800 54.6870 1.0000
80.9500 55.9965 1.0000
81.0200 47.3308 1.0000
81.0900 70.4549 1.0000
81.1600 58.6078 1.0000
81.2300 61.6525 1.0000
81.3000 53.8403 1.0000
81.3700 58.4982 1.0000
81.4400 64.2995 1.0000
81.5100 58.6491 1.0000
81.5800 62.4251 1.0000
81.6500 68.9307 1.0000
81.7200 84.8248 1.0000
81.7900 84.5639 1.0000
81.8600 142.3800 1.0000
81.9300 215.0458 1.0000
82.0000 362.3953 1.0000
82.0700 422.1465 1.0000
82.1400 314.3915 1.0000
82.2100 180.5318 1.0000
82.2800 85.6343 1.0000
82.3500 71.4444 1.0000
82.4200 65.0291 1.0000
82.4900 60.6306 1.0000
82.5600 62.9040 1.0000
82.6300 59.8884 1.0000
82.7000 51.5247 1.0000
82.7700 45.9445 1.0000
82.8400 63.3640 1.0000
82.9100 48.9260 1.0000
82.9800 64.2150 1.0000
83.0500 58.2264 1.0000
83.1200 53.3352 1.0000
83.1900 53.2758 1.0000
83.2600 50.8377 1.0000
83.3300 43.3573 1.0000
83.4000 57.2286 1.0000
83.4700 53.6865 1.0000
83.5400 58.6982 1.0000
83.6100 55.8708 1.0000
83.6800 45.3169 1.0000
83.7500 60.1871 1.0000
83.8200 57.7575 1.0000
83.8900 60.1453 1.0000
83.9600 53.1758 1.0000
84.0300 56.2389 1.0000
84.1000 46.1347 1.0000
84.1700 52.0220 1.0000
84.2400 56.7968 1.0000
84.3100 44.3674 1.0000
84.3800 58.6064 1.0000
84.4500 59.6240 1.0000
84.5200 51.8283 1.0000
84.5900 62.9934 1.0000
84.6600 44.0949 1.0000
84.7300 46.7651 1.0000
84.8000 52.3431 1.0000
84.8700 45.9306 1.0000
84.9400 45.5908 1.0000
85.0100 47.7528 1.0000
85.0800 45.2961 1.0000
85.1500 53.1099 1.0000
85.2200 53.1093 1.0000
85.2900 54.1365 1.0000
85.3600 52.6608 1.0000
85.4300 33.2784 1.0000
85.5000 55.8396 1.0000
85.5700 47.4802 1.0000
85.6400 56.2554 1.0000
85.7100 46.2676 1.0000
85.7800 56.0442 1.0000
85.8500 54.1657 1.0000
85.9200 54.1581 1.0000
85.9900 47.6263 1.0000
86.0600 44.4670 1.0000
86.1300 55.3271 1.0000
86.2000 46.5816 1.0000
86.2700 47.5992 1.0000
86.3400 45.0133 1.0000
86.4100 52.0626 1.0000
86.4800 57.4596 1.0000
86.5500 29.7111 1.0000
86.6200 60.2194 1.0000
86.6900 49.2396 1.0000
86.7600 44.4647 1.0000
86.8300 53.0203 1.0000
86.9000 48.8127 1.0000
86.9700 49.0620 1.0000
87.0400 65.0386 1.0000
87.1100 57.2654 1.0000
87.1800 45.2581 1.0000
87.2500 52.9278 1.0000
87.3200 53.1275 1.0000
87.3900 49.7489 1.0000
87.4600 52.2951 1.0000
87.5300 58.6633 1.0000
87.6000 43.2218 1.0000
87.6700 40.1749 1.0000
87.7400 51.3232 1.0000
87.8100 65.0751 1.0000
87.8800 54.5210 1.0000
87.9500 64.6094 1.0000
88.0200 46.0032 1.0000
88.0900 52.0600 1.0000
88.1600 48.4598 1.0000
88.2300 60.6039 1.0000
88.3000 51.3220 1.0000
88.3700 55.8462 1.0000
88.4400 62.3731 1.0000
88.5100 52.8190 1.0000
88.5800 55.7327 1.0000
88.6500 50.7709 1.0000
88.7200 53.6565 1.0000
88.7900 62.0279 1.0000
88.8600 57.8834 1.0000
88.9300 51.8362 1.0000
89.0000 62.6411 1.0000
89.0700 50.5270 1.0000
89.1400 58.9819 1.0000
89.2100 50.7253 1.0000
89.2800 57.6315 1.0000
89.3500 63.0515 1.0000
89.4200 48.3774 1.0000
89.4900 47.0459 1.0000
89.5600 45.7848 1.0000
89.6300 56.5661 1.0000
89.7000 60.5175 1.0000
89.7700 44.4185 1.0000
89.8400 67.1482 1.0000
89.9100 47.8867 1.0000
89.9800 50.4256 1.0000
90.0500 49.8320 1.0000
90.1200 49.8457 1.0000
90.1900 42.0602 1.0000
90.2600 57.5453 1.0000
90.3300 53.1302 1.0000
90.4000 50.5380 1.0000
90.4700 41.4166 1.0000
90.5400 48.9744 1.0000
90.6100 57.5153 1.0000
90.6800 41.8086 1.0000
90.7500 53.5806 1.0000
90.8200 51.3140 1.0000
90.8900 51.2859 1.0000
90.9600 44.3165 1.0000
91.0300 52.8780 1.0000
91.1000 41.1107 1.0000
91.1700 44.7243 1.0000
91.2400 39.8924 1.0000
91.3100 43.8565 1.0000
91.3800 53.9696 1.0000
91.4500 40.0776 1.0000
91.5200 52.9759 1.0000
91.5900 49.2965 1.0000
91.6600 47.9117 1.0000
91.7300 47.3890 1.0000
91.8000 56.2142 1.0000
91.8700 57.3246 1.0000
91.9400 44.1745 1.0000
92.0100 51.2140 1.0000
92.0800 48.9197 1.0000
92.1500 61.1680 1.0000
92.2200 51.5422 1.0000
92.2900 54.5581 1.0000
92.3600 43.5933 1.0000
92.4300 48.0216 1.0000
92.5000 64.1943 1.0000
92.5700 68.6713 1.0000
92.6400 65.7314 1.0000
92.7100 65.6048 1.0000
92.7800 47.4851 1.0000
92.8500 42.9558 1.0000
92.9200 43.9159 1.0000
92.9900 58.7401 1.0000
93.0600 50.8822 1.0000
93.1300 56.8665 1.0000
93.2000 52.3084 1.0000
93.2700 47.8343 1.0000
93.3400 58.2299 1.0000
93.4100 50.9630 1.0000
93.4800 48.2280 1.0000
93.5500 61.9045 1.0000
93.6200 44.6860 1.0000
93.6900 57.9021 1.0000
93.7600 64.7921 1.0000
93.8300 44.3189 1.0000
93.9000 50.7713 1.0000
93.9700 50.4292 1.0000
94.0400 44.4396 1.0000
94.1100 46.5063 1.0000
94.1800 56.7104 1.0000
94.2500 60.8243 1.0000
94.3200 40.3654 1.0000
94.3900 55.8582 1.0000
94.4600 52.3146 1.0000
94.5300 55.9151 1.0000
94.6000 65.7758 1.0000
94.6700 52.5898 1.0000
94.7400 53.1924 1.0000
94.8100 52.2487 1.0000
94.8800 39.5407 1.0000
94.9500 44.7265 1.0000
95.0200 42.4845 1.0000
95.0900 54.3447 1.0000
95.1600 55.4555 1.0000
95.2300 45.8487 1.0000
95.3000 52.1366 1.0000
95.3700 52.3497 1.0000
95.4400 48.9725 1.0000
95.5100 57.3925 1.0000
95.5800 36.2779 1.0000
95.6500 49.7217 1.0000
95.7200 58.7904 1.0000
95.7900 49.1274 1.0000
95.8600 48.0011 1.0000
95.9300 51.9621 1.0000
96.0000 53.0940 1.0000
96.0700 61.1972 1.0000
96.1400 55.5229 1.0000
96.2100 57.0431 1.0000
96.2800 50.3314 1.0000
96.3500 59.4420 1.0000
96.4200 61.9163 1.0000
96.4900 62.5184 1.0000
96.5600 55.3173 1.0000
96.6300 54.8180 1.0000
96.7000 61.3689 1.0000
96.7700 48.4053 1.0000
96.8400 41.1584 1.0000
96.9100 48.0451 1.0000
96.9800 51.4519 1.0000
97.0500 52.3354 1.0000
97.1200 33.6605 1.0000
97.1900 52.8866 1.0000
97.2600 57.7546 1.0000
97.3300 57.6993 1.0000
97.4000 44.3890 1.0000
97.4700 59.9409 1.0000
97.5400 48.3854 1.0000
97.6100 52.5007 1.0000
97.6800 55.3303 1.0000
97.7500 58.0915 1.0000
97.8200 51.7734 1.0000
97.8900 58.6688 1.0000
97.9600 61.5274 1.0000
98.0300 67.9825 1.0000
98.1000 64.0670 1.0000
98.1700 61.2180 1.0000
98.2400 78.5458 1.0000
98.3100 76.1088 1.0000
98.3800 121.0067 1.0000
98.4500 177.6856 1.0000
98.5200 298.0643 1.0000
98.5900 329.1385 1.0000
98.6600 295.1046 1.0000
98.7300 192.7722 1.0000
98.8000 122.2424 1.0000
98.8700 93.0322 1.0000
98.9400 67.1284 1.0000
99.0100 57.3082 1.0000
99.0800 59.2408 1.0000
99.1500 62.2692 1.0000
99.2200 56.4320 1.0000
99.2900 63.3075 1.0000
99.3600 58.6562 1.0000
99.4300 60.4469 1.0000
99.5000 55.7549 1.0000
99.5700 45.9092 1.0000
99.6400 58.8134 1.0000
99.7100 48.3161 1.0000
99.7800 60.6874 1.0000
99.8500 61.0136 1.0000
99.9200 49.8118 1.0000
99.9900 49.1126 1.0000
100.0600 53.3036 1.0000
100.1300 46.7490 1.0000
100.2000 46.9736 1.0000
100.2700 46.4048 1.0000
100.3400 56.4400 1.0000
100.4100 46.3863 1.0000
100.4800 45.8881 1.0000
100.5500 51.7662 1.0000
100.6200 50.9642 1.0000
100.6900 45.0397 1.0000
100.7600 51.0553 1.0000
100.8300 44.8197 1.0000
100.9000 48.1762 1.0000
100.9700 52.5302 1.0000
101.0400 35.6705 1.0000
101.1100 50.3164 1.0000
101.1800 39.6322 1.0000
101.2500 52.8510 1.0000
101.3200 48.4811 1.0000
101.3900 64.6131 1.0000
101.4600 50.8558 1.0000
101.5300 51.3796 1.0000
101.6000 52.3746 1.0000
101.6700 52.9489 1.0000
101.7400 50.7699 1.0000
101.8100 63.9536 1.0000
101.8800 63.4239 1.0000
101.9500 40.9911 1.0000
102.0200 55.7487 1.0000
102.0900 57.5773 1.0000
102.1600 58.6134 1.0000
102.2300 50.5074 1.0000
102.3000 45.9462 1.0000
102.3700 50.0525 1.0000
102.4400 44.3566 1.0000
102.5100 58.2829 1.0000
102.5800 59.7137 1.0000
102.6500 48.3511 1.0000
102.7200 63.8858 1.0000
102.7900 57.5573 1.0000
102.8600 43.2348 1.0000
102.9300 42.8388 1.0000
103.0000 53.3680 1.0000
103.0700 47.6714 1.0000
103.1400 50.7852 1.0000
103.2100 60.0349 1.0000
103.2800 46.2613 1.0000
103.3500 36.9063 1.0000
103.4200 54.5536 1.0000
103.4900 44.3960 1.0000
103.5600 66.1330 1.0000
103.6300 51.4156 1.0000
103.7000 56.0561 1.0000
103.7700 47.3656 1.0000
103.8400 50.3727 1.0000
103.9100 53.3664 1.0000
103.9800 53.3760 1.0000
104.0500 47.6308 1.0000
104.1200 61.1201 1.0000
104.1900 42.7284 1.0000
104.2600 55.3595 1.0000
104.3300 47.9781 1.0000
104.4000 50.9661 1.0000
104.4700 51.7298 1.0000
104.5400 41.9523 1.0000
104.6100 45.6683 1.0000
104.6800 56.9905 1.0000
104.7500 51.1703 1.0000
104.8200 56.2268 1.0000
104.8900 66.1398 1.0000
104.9600 54.8102 1.0000
105.0300 57.1486 1.0000
105.1000 53.9993 1.0000
105.1700 61.5841 1.0000
105.2400 46.4244 1.0000
105.3100 55.3753 1.0000
105.3800 48.9094 1.0000
105.4500 50.8278 1.0000
105.5200 51.5448 1.0000
105.5900 41.4738 1.0000
105.6600 67.1342 1.0000
105.7300 49.0085 1.0000
105.8000 41.0247 1.0000
105.8700 41.3809 1.0000
105.9400 56.6006 1.0000
106.0100 56.6864 1.0000
106.0800 47.4255 1.0000
106.1500 67.0055 1.0000
106.2200 52.4161 1.0000
106.2900 47.1414 1.0000
106.3600 51.8688 1.0000
106.4300 49.4963 1.0000
106.5000 56.1517 1.0000
106.5700 52.5478 1.0000
106.6400 44.0896 1.0000
106.7100 51.8621 1.0000
106.7800 48.8295 1.0000
106.8500 46.1485 1.0000
106.9200 56.4273 1.0000
106.9900 48.7332 1.0000
107.0600 45.9049 1.0000
107.1300 41.7572 1.0000
107.2000 50.6412 1.0000
107.2700 50.7818 1.0000
107.3400 41.6242 1.0000
107.4100 63.3397 1.0000
107.4800 52.9061 1.0000
107.5500 53.2296 1.0000
107.6200 49.9250 1.0000
107.6900 47.3791 1.0000
107.7600 49.4715 1.0000
107.8300 53.5649 1.0000
107.9000 62.0141 1.0000
107.9700 62.1049 1.0000
108.0400 60.1861 1.0000
108.1100 60.6839 1.0000
108.1800 38.9707 1.0000
108.2500 57.8756 1.0000
108.3200 59.8044 1.0000
108.3900 55.6046 1.0000
108.4600 48.5164 1.0000
108.5300 62.1334 1.0000
108.6000 53.1788 1.0000
108.6700 55.5936 1.0000
108.7400 51.4586 1.0000
108.8100 48.3101 1.0000
108.8800 58.6829 1.0000
108.9500 59.5247 1.0000
109.0200 53.6460 1.0000
109.0900 47.9183 1.0000
109.1600 54.8611 1.0000
109.2300 42.4325 1.0000
109.3000 54.6950 1.0000
109.3700 48.8204 1.0000
109.4400 44.9422 1.0000
109.5100 58.3260 1.0000
109.5800 45.6366 1.0000
109.6500 50.2787 1.0000
109.7200 48.1485 1.0000
109.7900 53.3130 1.0000
109.8600 52.1895 1.0000
109.9300 45.5492 1.0000
110.0000 61.3510 1.0000
110.0700 49.8505 1.0000
110.1400 57.6600 1.0000
110.2100 34.6919 1.0000
110.2800 64.0522 1.0000
110.3500 50.9291 1.0000
110.4200 42.9637 1.0000
110.4900 58.3942 1.0000
110.5600 64.1325 1.0000
110.6300 53.0200 1.0000
110.7000 55.5778 1.0000
110.7700 50.4080 1.0000
110.8400 48.5948 1.0000
110.9100 43.0276 1.0000
110.9800 37.2311 1.0000
111.0500 52.2945 1.0000
111.1200 55.4141 1.0000
111.1900 53.6881 1.0000
111.2600 46.7994 1.0000
111.3300 46.1238 1.0000
111.4000 52.1628 1.0000
111.4700 52.6588 1.0000
111.5400 52.1595 1.0000
111.6100 45.7715 1.0000
111.6800 40.0294 1.0000
111.7500 47.3485 1.0000
111.8200 70.7593 1.0000
111.8900 60.6636 1.0000
111.9600 51.7919 1.0000
112.0300 51.6522 1.0000
112.1000 42.7190 1.0000
112.1700 50.6555 1.0000
112.2400 51.2859 1.0000
112.3100 51.4259 1.0000
112.3800 49.6939 1.0000
112.4500 46.9307 1.0000
112.5200 54.9032 1.0000
112.5900 58.5757 1.0000
112.6600 50.7966 1.0000
112.7300 52.3347 1.0000
112.8000 52.7212 1.0000
112.8700 44.3046 1.0000
112.9400 44.7245 1.0000
113.0100 48.2935 1.0000
113.0800 45.5249 1.0000
113.1500 57.4993 1.0000
113.2200 41.4614 1.0000
113.2900 53.7039 1.0000
113.3600 47.4316 1.0000
113.4300 45.7637 1.0000
113.5000 54.9098 1.0000
113.5700 40.4289 1.0000
113.6400 51.5771 1.0000
113.7100 52.0146 1.0000
113.7800 55.6723 1.0000
113.8500 62.8344 1.0000
113.9200 56.0942 1.0000
113.9900 58.8288 1.0000
114.0600 48.5384 1.0000
114.1300 45.2933 1.0000
114.2000 34.7857 1.0000
114.2700 49.7327 1.0000
114.3400 41.2753 1.0000
114.4100 51.7402 1.0000
114.4800 53.4997 1.0000
114.5500 52.1853 1.0000
114.6200 51.3209 1.0000
114.6900 66.7070 1.0000
114.7600 61.1971 1.0000
114.8300 43.2752 1.0000
114.9000 54.2150 1.0000
114.9700 54.0460 1.0000
115.0400 57.0683 1.0000
115.1100 65.2985 1.0000
115.1800 65.1037 1.0000
115.2500 55.1809 1.0000
115.3200 70.0701 1.0000
115.3900 71.8421 1.0000
115.4600 90.4191 1.0000
115.5300 88.4252 1.0000
115.6000 107.0652 1.0000
115.6700 132.6479 1.0000
115.7400 139.3816 1.0000
115.8100 149.8204 1.0000
115.8800 146.2379 1.0000
115.9500 117.9478 1.0000
116.0200 101.3070 1.0000
116.0900 89.3705 1.0000
116.1600 75.0610 1.0000
116.2300 71.9834 1.0000
[...]
70.8000 59.9454 1.0000
70.8700 39.5089 1.0000
70.9400 52.5497 1.0000
71.0100 52.5619 1.0000
71.0800 61.9846 1.0000
71.1500 50.6593 1.0000
71.2200 57.4376 1.0000
71.2900 63.7953 1.0000
71.3600 42.0021 1.0000
71.4300 51.8226 1.0000
71.5000 68.9435 1.0000
71.5700 55.4906 1.0000
71.6400 48.0277 1.0000
71.7100 50.6380 1.0000
71.7800 59.4735 1.0000
71.8500 51.3962 1.0000
71.9200 58.1855 1.0000
71.9900 52.9275 1.0000
72.0600 63.2250 1.0000
72.1300 51.4862 1.0000
72.2000 44.7252 1.0000
72.2700 48.6280 1.0000
72.3400 50.5558 1.0000
72.4100 50.7381 1.0000
72.4800 48.7955 1.0000
72.5500 51.1106 1.0000
72.6200 53.2634 1.0000
72.6900 58.8931 1.0000
72.7600 51.8012 1.0000
72.8300 61.6130 1.0000
72.9000 55.9409 1.0000
72.9700 56.1767 1.0000
73.0400 50.0740 1.0000
73.1100 46.9583 1.0000
73.1800 53.5286 1.0000
73.2500 62.0966 1.0000
73.3200 45.4371 1.0000
73.3900 57.8843 1.0000
73.4600 58.7470 1.0000
73.5300 44.5869 1.0000
73.6000 53.1637 1.0000
73.6700 48.8241 1.0000
73.7400 68.0829 1.0000
73.8100 62.9176 1.0000
73.8800 62.8018 1.0000
73.9500 62.4600 1.0000
74.0200 65.0862 1.0000
74.0900 59.0374 1.0000
74.1600 55.3969 1.0000
74.2300 52.1899 1.0000
74.3000 52.2802 1.0000
74.3700 52.0938 1.0000
74.4400 53.4240 1.0000
74.5100 56.1018 1.0000
74.5800 54.3490 1.0000
74.6500 57.3912 1.0000
74.7200 42.4943 1.0000
74.7900 36.7895 1.0000
74.8600 63.1466 1.0000
74.9300 53.1570 1.0000
75.0000 62.3038 1.0000
75.0700 53.4213 1.0000
75.1400 49.5765 1.0000
75.2100 49.0935 1.0000
75.2800 54.6953 1.0000
75.3500 46.7266 1.0000
75.4200 45.4012 1.0000
75.4900 58.8264 1.0000
75.5600 60.1071 1.0000
75.6300 61.4640 1.0000
75.7000 55.8371 1.0000
75.7700 57.6124 1.0000
75.8400 58.6989 1.0000
75.9100 43.8523 1.0000
75.9800 42.0955 1.0000
76.0500 52.2426 1.0000
76.1200 54.0506 1.0000
76.1900 50.2545 1.0000
76.2600 38.6449 1.0000
76.3300 47.2758 1.0000
76.4000 56.6409 1.0000
76.4700 51.6078 1.0000
76.5400 60.5121 1.0000
76.6100 51.5922 1.0000
76.6800 55.1514 1.0000
76.7500 59.5515 1.0000
76.8200 59.1191 1.0000
76.8900 48.5670 1.0000
76.9600 56.9435 1.0000
77.0300 49.1330 1.0000
77.1000 48.4062 1.0000
77.1700 48.8328 1.0000
77.2400 61.3258 1.0000
77.3100 57.3116 1.0000
77.3800 50.6468 1.0000
77.4500 57.6550 1.0000
77.5200 52.7592 1.0000
77.5900 57.2693 1.0000
77.6600 63.0127 1.0000
77.7300 43.7088 1.0000
77.8000 38.8473 1.0000
77.8700 53.5800 1.0000
77.9400 55.3098 1.0000
78.0100 60.6559 1.0000
78.0800 55.1973 1.0000
78.1500 56.4597 1.0000
78.2200 40.6311 1.0000
78.2900 49.9583 1.0000
78.3600 44.6777 1.0000
78.4300 54.7422 1.0000
78.5000 45.2119 1.0000
78.5700 62.7437 1.0000
78.6400 61.2409 1.0000
78.7100 39.8193 1.0000
78.7800 45.3232 1.0000
78.8500 48.9242 1.0000
78.9200 36.7539 1.0000
78.9900 52.8272 1.0000
79.0600 49.2568 1.0000
79.1300 59.5156 1.0000
79.2000 41.9124 1.0000
79.2700 51.5112 1.0000
79.3400 58.3770 1.0000
79.4100 54.5710 1.0000
79.4800 51.3448 1.0000
79.5500 38.4266 1.0000
79.6200 62.6725 1.0000
79.6900 56.9789 1.0000
79.7600 50.3327 1.0000
79.8300 39.5676 1.0000
79.9000 50.6243 1.0000
79.9700 38.7594 1.0000
80.0400 54.2033 1.0000
80.1100 47.2532 1.0000
80.1800 62.2017 1.0000
80.2500 47.5870 1.0000
80.3200 55.8077 1.0000
80.3900 48.2410 1.0000
80.4600 40.0504 1.0000
80.5300 49.4713 1.0000
80.6000 62.5936 1.0000
80.6700 50.9788 1.0000
80.7400 55.7929 1.0000
80.8100 60.0251 1.0000
80.8800 61.2256 1.0000
80.9500 49.1165 1.0000
81.0200 46.1132 1.0000
81.0900 57.0620 1.0000
81.1600 54.9074 1.0000
81.2300 51.1624 1.0000
81.3000 50.9728 1.0000
81.3700 54.0501 1.0000
81.4400 55.5157 1.0000
81.5100 57.0009 1.0000
81.5800 71.0227 1.0000
81.6500 64.5229 1.0000
81.7200 80.1185 1.0000
81.7900 93.7430 1.0000
81.8600 147.3976 1.0000
81.9300 224.4941 1.0000
82.0000 359.8022 1.0000
82.0700 389.9403 1.0000
82.1400 324.5867 1.0000
82.2100 199.9381 1.0000
82.2800 96.4498 1.0000
82.3500 70.5968 1.0000
82.4200 75.3841 1.0000
82.4900 71.3873 1.0000
82.5600 55.7903 1.0000
82.6300 61.4064 1.0000
82.7000 58.2969 1.0000
82.7700 59.5861 1.0000
82.8400 59.7232 1.0000
82.9100 55.4911 1.0000
82.9800 64.2027 1.0000
83.0500 53.7884 1.0000
83.1200 65.7835 1.0000
83.1900 57.2924 1.0000
83.2600 40.2377 1.0000
83.3300 45.6820 1.0000
83.4000 49.2593 1.0000
83.4700 55.5148 1.0000
83.5400 51.8648 1.0000
83.6100 60.1229 1.0000
83.6800 63.8542 1.0000
83.7500 48.7626 1.0000
83.8200 63.4921 1.0000
83.8900 52.4603 1.0000
83.9600 50.9697 1.0000
84.0300 59.0197 1.0000
84.1000 54.2401 1.0000
84.1700 50.0831 1.0000
84.2400 54.6649 1.0000
84.3100 50.9603 1.0000
84.3800 53.3812 1.0000
84.4500 51.6321 1.0000
84.5200 56.7397 1.0000
84.5900 52.0971 1.0000
84.6600 56.9619 1.0000
84.7300 46.0061 1.0000
84.8000 48.5481 1.0000
84.8700 56.4691 1.0000
84.9400 52.8381 1.0000
85.0100 59.5548 1.0000
85.0800 65.3290 1.0000
85.1500 53.2495 1.0000
85.2200 45.5418 1.0000
85.2900 45.4301 1.0000
85.3600 47.6237 1.0000
85.4300 39.5562 1.0000
85.5000 48.0910 1.0000
85.5700 47.7838 1.0000
85.6400 57.3812 1.0000
85.7100 54.5506 1.0000
85.7800 52.5726 1.0000
85.8500 49.5713 1.0000
85.9200 47.2672 1.0000
85.9900 59.9970 1.0000
86.0600 46.2871 1.0000
86.1300 48.1054 1.0000
86.2000 53.5110 1.0000
86.2700 53.3887 1.0000
86.3400 58.4895 1.0000
86.4100 55.1374 1.0000
86.4800 53.6180 1.0000
86.5500 55.9370 1.0000
86.6200 44.0740 1.0000
86.6900 51.3313 1.0000
86.7600 59.0521 1.0000
86.8300 48.9683 1.0000
86.9000 54.9386 1.0000
86.9700 57.1930 1.0000
87.0400 42.2964 1.0000
87.1100 47.8797 1.0000
87.1800 61.3042 1.0000
87.2500 49.9498 1.0000
87.3200 52.2836 1.0000
87.3900 42.6732 1.0000
87.4600 54.2057 1.0000
87.5300 51.9969 1.0000
87.6000 49.9433 1.0000
87.6700 39.1393 1.0000
87.7400 50.7925 1.0000
87.8100 39.9635 1.0000
87.8800 60.5636 1.0000
87.9500 55.1878 1.0000
88.0200 60.8106 1.0000
88.0900 59.3309 1.0000
88.1600 54.3677 1.0000
88.2300 58.1285 1.0000
88.3000 46.1930 1.0000
88.3700 57.5945 1.0000
88.4400 52.0903 1.0000
88.5100 51.5200 1.0000
88.5800 48.5202 1.0000
88.6500 57.7640 1.0000
88.7200 37.2265 1.0000
88.7900 56.6404 1.0000
88.8600 49.7348 1.0000
88.9300 39.6627 1.0000
89.0000 55.3848 1.0000
89.0700 57.4029 1.0000
89.1400 52.4212 1.0000
89.2100 54.2303 1.0000
89.2800 46.6505 1.0000
89.3500 50.0354 1.0000
89.4200 51.8504 1.0000
89.4900 49.3043 1.0000
89.5600 49.7802 1.0000
89.6300 43.9113 1.0000
89.7000 58.9162 1.0000
89.7700 58.8307 1.0000
89.8400 55.0304 1.0000
89.9100 42.1532 1.0000
89.9800 60.8155 1.0000
90.0500 57.0104 1.0000
90.1200 49.8539 1.0000
90.1900 53.5038 1.0000
90.2600 50.0783 1.0000
90.3300 54.9860 1.0000
90.4000 49.5553 1.0000
90.4700 50.0285 1.0000
90.5400 44.8197 1.0000
90.6100 53.6736 1.0000
90.6800 57.3720 1.0000
90.7500 51.6071 1.0000
90.8200 56.0690 1.0000
90.8900 64.1961 1.0000
90.9600 46.5672 1.0000
91.0300 50.6978 1.0000
91.1000 50.2726 1.0000
91.1700 48.9791 1.0000
91.2400 51.2554 1.0000
91.3100 55.5564 1.0000
91.3800 51.3991 1.0000
91.4500 72.3061 1.0000
91.5200 49.3179 1.0000
91.5900 45.0616 1.0000
91.6600 51.8574 1.0000
91.7300 54.5274 1.0000
91.8000 47.8337 1.0000
91.8700 45.8562 1.0000
91.9400 43.2143 1.0000
92.0100 46.7982 1.0000
92.0800 58.1655 1.0000
92.1500 59.1856 1.0000
92.2200 48.3403 1.0000
92.2900 42.5412 1.0000
92.3600 61.5288 1.0000
92.4300 55.7103 1.0000
92.5000 40.0698 1.0000
92.5700 59.9642 1.0000
92.6400 46.4562 1.0000
92.7100 37.0248 1.0000
92.7800 57.3160 1.0000
92.8500 47.5654 1.0000
92.9200 47.8738 1.0000
92.9900 50.7566 1.0000
93.0600 52.3153 1.0000
93.1300 48.6584 1.0000
93.2000 47.7892 1.0000
93.2700 64.0806 1.0000
93.3400 71.5145 1.0000
93.4100 42.8502 1.0000
93.4800 41.5360 1.0000
93.5500 42.7313 1.0000
93.6200 41.1733 1.0000
93.6900 57.7438 1.0000
93.7600 53.9854 1.0000
93.8300 40.5018 1.0000
93.9000 44.8099 1.0000
93.9700 52.5600 1.0000
94.0400 60.1296 1.0000
94.1100 44.1893 1.0000
94.1800 50.4663 1.0000
94.2500 55.2612 1.0000
94.3200 54.8799 1.0000
94.3900 53.2912 1.0000
94.4600 56.9298 1.0000
94.5300 46.9760 1.0000
94.6000 52.8632 1.0000
94.6700 54.7161 1.0000
94.7400 49.1149 1.0000
94.8100 54.3959 1.0000
94.8800 53.7983 1.0000
94.9500 37.8822 1.0000
95.0200 37.5949 1.0000
95.0900 50.2632 1.0000
95.1600 42.5861 1.0000
95.2300 63.5786 1.0000
95.3000 46.6886 1.0000
95.3700 55.7188 1.0000
95.4400 54.3813 1.0000
95.5100 55.7105 1.0000
95.5800 54.3223 1.0000
95.6500 55.9706 1.0000
95.7200 46.6995 1.0000
95.7900 45.2325 1.0000
95.8600 48.4158 1.0000
95.9300 46.3869 1.0000
96.0000 48.4185 1.0000
96.0700 51.8904 1.0000
96.1400 50.4097 1.0000
96.2100 69.4035 1.0000
96.2800 51.8198 1.0000
96.3500 57.1040 1.0000
96.4200 53.8880 1.0000
96.4900 49.9516 1.0000
96.5600 49.7076 1.0000
96.6300 54.9295 1.0000
96.7000 42.1762 1.0000
96.7700 44.9429 1.0000
96.8400 49.3556 1.0000
96.9100 54.5757 1.0000
96.9800 34.9925 1.0000
97.0500 68.5534 1.0000
97.1200 63.2749 1.0000
97.1900 41.5944 1.0000
97.2600 56.3537 1.0000
97.3300 42.9652 1.0000
97.4000 59.6490 1.0000
97.4700 43.6922 1.0000
97.5400 44.9264 1.0000
97.6100 55.6385 1.0000
97.6800 51.8035 1.0000
97.7500 52.6426 1.0000
97.8200 53.9495 1.0000
97.8900 61.4425 1.0000
97.9600 56.0198 1.0000
98.0300 69.2394 1.0000
98.1000 52.5556 1.0000
98.1700 69.4102 1.0000
98.2400 85.5129 1.0000
98.3100 95.5477 1.0000
98.3800 118.6584 1.0000
98.4500 175.7659 1.0000
98.5200 271.0883 1.0000
98.5900 342.4517 1.0000
98.6600 274.3104 1.0000
98.7300 191.1742 1.0000
98.8000 126.8376 1.0000
98.8700 92.6816 1.0000
98.9400 81.1629 1.0000
99.0100 61.4737 1.0000
99.0800 53.3074 1.0000
99.1500 49.8371 1.0000
99.2200 62.9663 1.0000
99.2900 54.7564 1.0000
99.3600 56.9510 1.0000
99.4300 51.4618 1.0000
99.5000 50.6112 1.0000
99.5700 47.8666 1.0000
99.6400 57.8648 1.0000
99.7100 59.7731 1.0000
99.7800 49.7266 1.0000
99.8500 49.2436 1.0000
99.9200 50.6788 1.0000
99.9900 62.5531 1.0000
100.0600 55.7626 1.0000
100.1300 44.4210 1.0000
100.2000 48.2434 1.0000
100.2700 45.3643 1.0000
100.3400 47.0505 1.0000
100.4100 50.0364 1.0000
100.4800 41.1109 1.0000
100.5500 48.5833 1.0000
100.6200 53.9799 1.0000
100.6900 40.2916 1.0000
100.7600 46.5785 1.0000
100.8300 45.5011 1.0000
100.9000 48.5820 1.0000
100.9700 59.2557 1.0000
101.0400 49.4169 1.0000
101.1100 46.1983 1.0000
101.1800 47.4500 1.0000
101.2500 55.0948 1.0000
101.3200 47.7388 1.0000
101.3900 48.3646 1.0000
101.4600 63.7886 1.0000
101.5300 55.0750 1.0000
101.6000 54.8723 1.0000
101.6700 43.4509 1.0000
101.7400 48.9193 1.0000
101.8100 44.2271 1.0000
101.8800 55.6648 1.0000
101.9500 53.0498 1.0000
102.0200 52.1725 1.0000
102.0900 60.6578 1.0000
102.1600 47.2643 1.0000
102.2300 44.0830 1.0000
102.3000 53.2577 1.0000
102.3700 65.6950 1.0000
102.4400 55.8245 1.0000
102.5100 37.9097 1.0000
102.5800 44.7829 1.0000
102.6500 48.2884 1.0000
102.7200 50.1657 1.0000
102.7900 52.8550 1.0000
102.8600 42.8096 1.0000
102.9300 61.3075 1.0000
103.0000 47.0561 1.0000
103.0700 57.7388 1.0000
103.1400 56.6443 1.0000
103.2100 53.3500 1.0000
103.2800 55.6350 1.0000
103.3500 45.6106 1.0000
103.4200 51.5939 1.0000
103.4900 65.5597 1.0000
103.5600 42.0244 1.0000
103.6300 48.1769 1.0000
103.7000 49.6373 1.0000
103.7700 47.0789 1.0000
103.8400 49.1142 1.0000
103.9100 45.3136 1.0000
103.9800 35.7339 1.0000
104.0500 49.3913 1.0000
104.1200 57.3868 1.0000
104.1900 47.2690 1.0000
104.2600 66.0412 1.0000
104.3300 47.6969 1.0000
104.4000 52.1298 1.0000
104.4700 52.3774 1.0000
104.5400 59.9679 1.0000
104.6100 54.0294 1.0000
104.6800 46.4953 1.0000
104.7500 50.1855 1.0000
104.8200 53.7206 1.0000
104.8900 58.5738 1.0000
104.9600 39.9959 1.0000
105.0300 54.2075 1.0000
105.1000 53.5316 1.0000
105.1700 52.9124 1.0000
105.2400 54.9444 1.0000
105.3100 53.2572 1.0000
105.3800 52.6080 1.0000
105.4500 52.6311 1.0000
105.5200 45.9372 1.0000
105.5900 56.2218 1.0000
105.6600 55.8818 1.0000
105.7300 50.7661 1.0000
105.8000 42.0910 1.0000
105.8700 53.7724 1.0000
105.9400 50.4370 1.0000
106.0100 50.2734 1.0000
106.0800 45.6661 1.0000
106.1500 48.4550 1.0000
106.2200 47.6413 1.0000
106.2900 46.0956 1.0000
106.3600 52.2194 1.0000
106.4300 42.6295 1.0000
106.5000 51.5976 1.0000
106.5700 55.4536 1.0000
106.6400 60.5877 1.0000
106.7100 48.8253 1.0000
106.7800 49.7938 1.0000
106.8500 48.3410 1.0000
106.9200 51.2853 1.0000
106.9900 51.6565 1.0000
107.0600 47.0807 1.0000
107.1300 45.5843 1.0000
107.2000 54.2857 1.0000
107.2700 52.6233 1.0000
107.3400 48.2470 1.0000
107.4100 52.4987 1.0000
107.4800 57.3069 1.0000
107.5500 34.3455 1.0000
107.6200 47.0483 1.0000
107.6900 41.7344 1.0000
107.7600 43.6771 1.0000
107.8300 53.3211 1.0000
107.9000 64.5254 1.0000
107.9700 51.7512 1.0000
108.0400 58.5719 1.0000
108.1100 45.0672 1.0000
108.1800 53.7613 1.0000
108.2500 55.4950 1.0000
108.3200 55.0686 1.0000
108.3900 49.8201 1.0000
108.4600 48.5027 1.0000
108.5300 61.2142 1.0000
108.6000 50.1659 1.0000
108.6700 46.5459 1.0000
108.7400 54.9928 1.0000
108.8100 43.6492 1.0000
108.8800 39.8416 1.0000
108.9500 45.4544 1.0000
109.0200 55.6143 1.0000
109.0900 52.9511 1.0000
109.1600 60.7604 1.0000
109.2300 42.4804 1.0000
109.3000 57.8872 1.0000
109.3700 48.8459 1.0000
109.4400 52.6517 1.0000
109.5100 51.2106 1.0000
109.5800 50.4548 1.0000
109.6500 56.8988 1.0000
109.7200 44.4906 1.0000
109.7900 52.8362 1.0000
109.8600 46.0343 1.0000
109.9300 42.8407 1.0000
110.0000 47.6343 1.0000
110.0700 46.7693 1.0000
110.1400 48.6805 1.0000
110.2100 54.5034 1.0000
110.2800 51.0291 1.0000
110.3500 46.6916 1.0000
110.4200 53.2018 1.0000
110.4900 48.1416 1.0000
110.5600 55.0512 1.0000
110.6300 47.8722 1.0000
110.7000 37.5584 1.0000
110.7700 52.4429 1.0000
110.8400 56.7553 1.0000
110.9100 58.4902 1.0000
110.9800 50.7714 1.0000
111.0500 50.7911 1.0000
111.1200 61.0945 1.0000
111.1900 51.4371 1.0000
111.2600 54.3154 1.0000
111.3300 58.4799 1.0000
111.4000 56.7204 1.0000
111.4700 45.6175 1.0000
111.5400 44.4445 1.0000
111.6100 50.6218 1.0000
111.6800 58.4942 1.0000
111.7500 47.8056 1.0000
111.8200 47.9169 1.0000
111.8900 58.4398 1.0000
111.9600 53.9194 1.0000
112.0300 57.6846 1.0000
112.1000 59.2089 1.0000
112.1700 51.5644 1.0000
112.2400 50.9039 1.0000
112.3100 71.3238 1.0000
112.3800 56.6688 1.0000
112.4500 59.1088 1.0000
112.5200 42.7971 1.0000
112.5900 50.9095 1.0000
112.6600 64.2498 1.0000
112.7300 47.0531 1.0000
112.8000 52.5960 1.0000
112.8700 47.2382 1.0000
112.9400 49.9485 1.0000
113.0100 39.0319 1.0000
113.0800 65.3460 1.0000
113.1500 44.1775 1.0000
113.2200 61.2280 1.0000
113.2900 43.8484 1.0000
113.3600 57.0155 1.0000
113.4300 43.6083 1.0000
113.5000 56.2041 1.0000
113.5700 56.8082 1.0000
113.6400 50.5368 1.0000
113.7100 51.3270 1.0000
113.7800 61.2304 1.0000
113.8500 43.4979 1.0000
113.9200 43.0034 1.0000
113.9900 52.8518 1.0000
114.0600 50.2566 1.0000
114.1300 50.8857 1.0000
114.2000 48.0135 1.0000
114.2700 58.2217 1.0000
114.3400 53.2239 1.0000
114.4100 73.4845 1.0000
114.4800 46.5445 1.0000
114.5500 61.8875 1.0000
114.6200 43.9348 1.0000
114.6900 51.6841 1.0000
114.7600 49.4589 1.0000
114.8300 69.7304 1.0000
114.9000 54.9247 1.0000
114.9700 62.6853 1.0000
115.0400 60.9031 1.0000
115.1100 55.3110 1.0000
115.1800 68.3153 1.0000
115.2500 64.3444 1.0000
115.3200 57.8542 1.0000
115.3900 72.9146 1.0000
115.4600 73.2501 1.0000
115.5300 85.3861 1.0000
115.6000 91.9850 1.0000
115.6700 108.8567 1.0000
115.7400 154.6992 1.0000
115.8100 155.8185 1.0000
115.8800 141.0405 1.0000
115.9500 118.2583 1.0000
116.0200 118.3884 1.0000
116.0900 79.0230 1.0000
116.1600 81.6509 1.0000
116.2300 61.6111 1.0000
116.3000 68.2780 1.0000
116.3700 47.2954 1.0000
116.4400 66.0586 1.0000
116.5100 67.9755 1.0000
116.5800 48.9833 1.0000
116.6500 53.2503 1.0000
116.7200 49.2297 1.0000
116.7900 55.2256 1.0000
116.8600 50.6931 1.0000
116.9300 38.3140 1.0000
117.0000 53.3079 1.0000
117.0700 44.7753 1.0000
117.1400 52.8402 1.0000
117.2100 60.5539 1.0000
117.2800 41.3797 1.0000
117.3500 52.8849 1.0000
117.4200 47.7019 1.0000
117.4900 55.0717 1.0000
117.5600 50.0211 1.0000
117.6300 50.7776 1.0000
117.7000 59.5141 1.0000
117.7700 67.7340 1.0000
117.8400 55.6964 1.0000
117.9100 54.4795 1.0000
117.9800 58.7649 1.0000
118.0500 55.2792 1.0000
118.1200 41.4901 1.0000
118.1900 56.2375 1.0000
118.2600 54.2675 1.0000
118.3300 48.7605 1.0000
118.4000 40.8265 1.0000
118.4700 53.7468 1.0000
118.5400 44.1325 1.0000
118.6100 45.7606 1.0000
118.6800 44.3032 1.0000
118.7500 45.5302 1.0000
118.8200 43.2586 1.0000
118.8900 53.2855 1.0000
118.9600 40.4611 1.0000
119.0300 43.2234 1.0000
119.1000 48.0375 1.0000
119.1700 44.5080 1.0000
119.2400 41.5873 1.0000
119.3100 60.5335 1.0000
119.3800 42.6477 1.0000
119.4500 60.8469 1.0000
119.5200 58.9516 1.0000
119.5900 45.4549 1.0000
119.6600 51.6575 1.0000
119.7300 44.9881 1.0000
119.8000 62.9853 1.0000
119.8700 49.9705 1.0000
119.9400 47.0326 1.0000
120.0100 50.5875 1.0000
120.0800 53.6079 1.0000
120.1500 45.2690 1.0000
120.2200 48.8568 1.0000
120.2900 49.3413 1.0000
120.3600 39.8094 1.0000
120.4300 43.7315 1.0000
120.5000 54.8474 1.0000
120.5700 45.0905 1.0000
120.6400 47.9374 1.0000
120.7100 54.9846 1.0000
120.7800 37.4334 1.0000
120.8500 49.2387 1.0000
120.9200 47.9188 1.0000
120.9900 58.1225 1.0000
121.0600 59.4293 1.0000
121.1300 52.6716 1.0000
121.2000 46.8266 1.0000
121.2700 46.0923 1.0000
121.3400 56.6631 1.0000
121.4100 46.3003 1.0000
121.4800 56.8947 1.0000
121.5500 49.3669 1.0000
121.6200 56.7229 1.0000
121.6900 55.0262 1.0000
121.7600 54.3885 1.0000
121.8300 43.8521 1.0000
121.9000 52.7449 1.0000
121.9700 58.0763 1.0000
122.0400 41.6195 1.0000
122.1100 48.9328 1.0000
122.1800 55.8743 1.0000
122.2500 51.7648 1.0000
122.3200 51.8167 1.0000
122.3900 47.4958 1.0000
122.4600 44.1441 1.0000
122.5300 66.7866 1.0000
122.6000 52.2833 1.0000
122.6700 42.5454 1.0000
122.7400 63.4427 1.0000
122.8100 55.8678 1.0000
122.8800 42.9202 1.0000
122.9500 50.4988 1.0000
123.0200 54.3190 1.0000
123.0900 62.3240 1.0000
123.1600 50.8299 1.0000
123.2300 42.3289 1.0000
123.3000 53.9173 1.0000
123.3700 43.5458 1.0000
123.4400 58.7417 1.0000
123.5100 57.7391 1.0000
123.5800 46.1926 1.0000
123.6500 61.9994 1.0000
123.7200 52.1193 1.0000
123.7900 47.9377 1.0000
123.8600 56.3340 1.0000
123.9300 48.5868 1.0000
124.0000 45.9865 1.0000
124.0700 43.8157 1.0000
124.1400 40.8835 1.0000
124.2100 56.7249 1.0000
124.2800 58.8158 1.0000
124.3500 61.7683 1.0000
124.4200 48.8762 1.0000
124.4900 47.2715 1.0000
124.5600 44.0981 1.0000
124.6300 51.3084 1.0000
124.7000 38.2754 1.0000
124.7700 57.6478 1.0000
124.8400 53.6485 1.0000
124.9100 44.6314 1.0000
124.9800 39.1670 1.0000
125.0500 51.4327 1.0000
125.1200 56.4394 1.0000
125.1900 64.8882 1.0000
125.2600 57.3605 1.0000
125.3300 55.4600 1.0000
125.4000 43.1022 1.0000
125.4700 53.4092 1.0000
125.5400 59.1925 1.0000
125.6100 51.5869 1.0000
125.6800 55.7001 1.0000
125.7500 52.9611 1.0000
125.8200 46.3312 1.0000
125.8900 35.8379 1.0000
125.9600 54.5918 1.0000
126.0300 42.4938 1.0000
126.1000 52.9035 1.0000
126.1700 55.1374 1.0000
126.2400 45.4175 1.0000
126.3100 52.1990 1.0000
126.3800 52.1072 1.0000
126.4500 51.3123 1.0000
126.5200 53.4155 1.0000
126.5900 44.5859 1.0000
126.6600 41.4686 1.0000
126.7300 56.1552 1.0000
126.8000 45.3645 1.0000
126.8700 53.1207 1.0000
126.9400 63.6571 1.0000
127.0100 46.9424 1.0000
127.0800 51.3373 1.0000
127.1500 48.4707 1.0000
127.2200 49.4478 1.0000
127.2900 46.4328 1.0000
127.3600 50.0006 1.0000
127.4300 41.2775 1.0000
127.5000 42.0604 1.0000
127.5700 41.9787 1.0000
127.6400 47.4591 1.0000
127.7100 49.1280 1.0000
127.7800 50.5280 1.0000
127.8500 44.7878 1.0000
127.9200 51.4528 1.0000
127.9900 53.3578 1.0000
128.0600 49.8025 1.0000
128.1300 49.3974 1.0000
128.2000 68.2824 1.0000
128.2700 51.5049 1.0000
128.3400 58.8769 1.0000
128.4100 50.5283 1.0000
128.4800 44.7421 1.0000
128.5500 43.9043 1.0000
128.6200 53.9355 1.0000
128.6900 39.4505 1.0000
128.7600 53.1709 1.0000
128.8300 45.2480 1.0000
128.9000 58.3985 1.0000
128.9700 59.9101 1.0000
129.0400 52.7191 1.0000
129.1100 58.4399 1.0000
129.1800 54.5609 1.0000
129.2500 65.5984 1.0000
129.3200 42.1206 1.0000
129.3900 42.7107 1.0000
129.4600 43.9836 1.0000
129.5300 53.1151 1.0000
129.6000 46.1915 1.0000
129.6700 56.9297 1.0000
129.7400 49.2683 1.0000
129.8100 60.4061 1.0000
129.8800 48.1153 1.0000
129.9500 50.9996 1.0000
130.0000 71.3866 1.0000
*RAS_INT_END
*RAS_TEMPERATURE_START
*RAS_TEMPERATURE_END
*RAS_DATA_END