File: XRD/February 2021/PB_Ge220_2.5SS_500umDS_RS1_Rod_2.5SS_Hypix1D_Test_Weld_Centre.ras
*RAS_DATA_START
*RAS_HEADER_START
*DISP_FMT_X "%.3f"
*DISP_FMT_Y "%.0f"
*DISP_FULLSCALE "220.6410321309"
*DISP_LINE_COLOR "255.0000000000"
*DISP_LINE_STYLE "0.0000000000"
*DISP_LINE_WIDTH "0.2500000000"
*DISP_NOTE "Collected Data-197"
*DISP_OFFSET_Y "0.0000000000"
*DISP_PEAKSEARCH_UNIT_Y "cps"
*DISP_RANGE_BOTTOM "0.0000000000"
*DISP_RANGE_LEFT "44.0000000000"
*DISP_RANGE_LOGCUTOFF "0.0100000000"
*DISP_RANGE_RIGHT "45.0000000000"
*DISP_RANGE_TOP "220.6410321309"
*DISP_SCALE_MODE_Y "0.0000000000"
*DISP_TAB_NAME "Theta/2-Theta"
*DISP_TITLE_Y "Intensity"
*DISP_UNIT_Y "cps"
*DISP_WINDOW_NAME "MSG_MACROENGINE"
*FILE_COMMENT " "
*FILE_MD5 ""
*FILE_MEMO " "
*FILE_OPERATOR "Administrator"
*FILE_PART_ID "MEAS_KHP2_00061"
*FILE_SAMPLE " "
*FILE_TYPE "RAS_RAW"
*FILE_USERGROUP "System Manager"
*FILE_VERSION "1.0000000000"
*HW_ATTACHMENT_ID "ATT0021"
*HW_ATTACHMENT_NAME "XY-20mm|XY-20mm"
*HW_COUNTER_ID-0 "CUT0041"
*HW_COUNTER_ID-1 "CUT0051"
*HW_COUNTER_ID-2 "CUT0020"
*HW_COUNTER_ID-3 "CSL0021"
*HW_COUNTER_ID-4 "CMC0021"
*HW_COUNTER_NAME-0 "D/teX Ultra 250|D/teX Ultra 250"
*HW_COUNTER_NAME-1 "HyPix 3000(H)|HyPix 3000(H)"
*HW_COUNTER_NAME-2 "None|None"
*HW_COUNTER_NAME-3 "BBM|BBM"
*HW_COUNTER_NAME-4 "検出器モノクロメータ|Detector monochromator"
*HW_COUNTER_SELECT_NAME "HyPix 3000(H)|HyPix 3000(H)"
*HW_GONIOMETER_ID "GON0024"
*HW_GONIOMETER_NAME "SmartLab(In-plane)|SmartLab(In-plane)"
*HW_GONIOMETER_RADIUS-0 "90.0"
*HW_GONIOMETER_RADIUS-1 "114.0"
*HW_GONIOMETER_RADIUS-2 "190.0"
*HW_GONIOMETER_RADIUS-3 "300.0"
*HW_GONIOMETER_RADIUS-4 "187.0"
*HW_GONIOMETER_RADIUS-5 "300.0"
*HW_GONIOMETER_RADIUS-6 "113.0"
*HW_GONIOMETER_RADIUS-7 "331.0"
*HW_I_OPT_ID-0 "CBO0021"
*HW_I_OPT_ID-1 "ICR0021"
*HW_I_OPT_ID-2 "ISL0021"
*HW_I_OPT_ID-3 "ISO0021"
*HW_I_OPT_ID-4 "IAD0021"
*HW_I_OPT_ID-5 "IPR0001"
*HW_I_OPT_NAME-0 "CBOユニット|CBO unit"
*HW_I_OPT_NAME-1 "標準入射光学ユニット|Standard incident optical unit"
*HW_I_OPT_NAME-2 "標準入射スリットボックス|Standard incident slit box"
*HW_I_OPT_NAME-3 "入射平行スリット|Incident parallel slit"
*HW_I_OPT_NAME-4 "長手制限スリット|Length limiting slit"
*HW_I_OPT_NAME-5 "None|None"
*HW_R_ATTENUATER_AUTOMODE "0"
*HW_R_OPT_ID-0 "RSS0022"
*HW_R_OPT_ID-1 "RCR0022"
*HW_R_OPT_ID-2 "RSO0021"
*HW_R_OPT_ID-3 "RRS0022"
*HW_R_OPT_ID-4 "ATN0020"
*HW_R_OPT_ID-5 "RFL0021"
*HW_R_OPT_ID-6 "RAD0021"
*HW_R_OPT_NAME-0 "受光スリットボックス1(Zr軸付)|Receiving slit box # 1 (w/ Zr Axis)"
*HW_R_OPT_NAME-1 "標準受光光学ユニット1|Standard receiving unit # 1"
*HW_R_OPT_NAME-2 "標準受光光学ユニット2|Standard receiving optical unit # 2"
*HW_R_OPT_NAME-3 "仮想受光スリット2|Virtual receiving slit #2"
*HW_R_OPT_NAME-4 "無し|None"
*HW_R_OPT_NAME-5 "Cu Kβ|Cu K-beta"
*HW_R_OPT_NAME-6 "調整用受光スリット|Alignment receiving slit"
*HW_SAMPLE_HOLDER_ID "SMP0021"
*HW_SAMPLE_HOLDER_NAME "χφZクレードル|Chi phi Z cradle"
*HW_XG_CURRENT_MAX "40"
*HW_XG_CURRENT_MIN "2"
*HW_XG_CURRENT_RESOLUTION "1"
*HW_XG_CURRENT_UNIT "mA"
*HW_XG_FOCUS "0.4mm x 8mm"
*HW_XG_FOCUS_TYPE "Fine"
*HW_XG_ID "1200"
*HW_XG_NAME "3kW 封入管(ID:1200)|3kW Sealed tube(ID:1200)"
*HW_XG_TARGET_ATOMIC_NUMBER "29.0000000000"
*HW_XG_TARGET_NAME "Cu"
*HW_XG_TYPE "Hermetic"
*HW_XG_VOLTAGE_MAX "40"
*HW_XG_VOLTAGE_MIN "20"
*HW_XG_VOLTAGE_RESOLUTION "1"
*HW_XG_VOLTAGE_UNIT "kV"
*HW_XG_WATT_MAX "1.500"
*HW_XG_WATT_UNIT "kW"
*HW_XG_WAVE_LENGTH_ALPHA1 "1.540593"
*HW_XG_WAVE_LENGTH_ALPHA2 "1.544414"
*HW_XG_WAVE_LENGTH_BETA "1.392250"
*MEAS_COND_AXIS_NAME-0 "Theta/2-Theta"
*MEAS_COND_AXIS_NAME-1 "2-Theta"
*MEAS_COND_AXIS_NAME-2 "Omega"
*MEAS_COND_AXIS_NAME-3 "Chi"
*MEAS_COND_AXIS_NAME-4 "Phi"
*MEAS_COND_AXIS_NAME-5 "Z"
*MEAS_COND_AXIS_NAME-6 "X"
*MEAS_COND_AXIS_NAME-7 "Y"
*MEAS_COND_AXIS_NAME-8 "2-Theta/Omega"
*MEAS_COND_AXIS_NAME-9 "2-ThetaChi"
*MEAS_COND_AXIS_NAME-10 "2-ThetaChi/Phi"
*MEAS_COND_AXIS_NAME-11 "Alpha"
*MEAS_COND_AXIS_NAME-12 "Beta"
*MEAS_COND_AXIS_NAME-13 "Theta_s"
*MEAS_COND_AXIS_NAME-14 "Theta_d"
*MEAS_COND_AXIS_NAME-15 "Ts"
*MEAS_COND_AXIS_NAME-16 "CBO selection slit"
*MEAS_COND_AXIS_NAME-17 "M"
*MEAS_COND_AXIS_NAME-18 "Incident parallel slit"
*MEAS_COND_AXIS_NAME-19 "Incident slit"
*MEAS_COND_AXIS_NAME-20 ""
*MEAS_COND_AXIS_NAME-21 "Zs"
*MEAS_COND_AXIS_NAME-22 "Incident optical device"
*MEAS_COND_AXIS_NAME-23 "Omega_m"
*MEAS_COND_AXIS_NAME-24 "Length limiting slit"
*MEAS_COND_AXIS_NAME-25 "Center slit"
*MEAS_COND_AXIS_NAME-26 "Filter"
*MEAS_COND_AXIS_NAME-27 "Receiving slit # 1"
*MEAS_COND_AXIS_NAME-28 "Receiving slit # 2"
*MEAS_COND_AXIS_NAME-29 "Receiving optical device"
*MEAS_COND_AXIS_NAME-30 "Receiving parallel slit"
*MEAS_COND_AXIS_NAME-31 "Alignment receiving slit"
*MEAS_COND_AXIS_NAME-32 ""
*MEAS_COND_AXIS_NAME-33 ""
*MEAS_COND_AXIS_NAME-34 "Zd"
*MEAS_COND_AXIS_NAME-35 "Attenuator"
*MEAS_COND_AXIS_NAME-36 "Diffracted beam monochromator"
*MEAS_COND_AXIS_NAME-37 "Monochromator slit"
*MEAS_COND_AXIS_NAME-38 "2-ThetaB"
*MEAS_COND_AXIS_NAME-39 ""
*MEAS_COND_AXIS_NAME-40 ""
*MEAS_COND_AXIS_NAME-41 "Zr"
*MEAS_COND_AXIS_NAME-42 "Primary beam"
*MEAS_COND_AXIS_NAME_INTERNAL-0 "TwoThetaTheta"
*MEAS_COND_AXIS_NAME_INTERNAL-1 "TwoTheta"
*MEAS_COND_AXIS_NAME_INTERNAL-2 "Omega"
*MEAS_COND_AXIS_NAME_INTERNAL-3 "Chi"
*MEAS_COND_AXIS_NAME_INTERNAL-4 "Phi"
*MEAS_COND_AXIS_NAME_INTERNAL-5 "Z"
*MEAS_COND_AXIS_NAME_INTERNAL-6 "X"
*MEAS_COND_AXIS_NAME_INTERNAL-7 "Y"
*MEAS_COND_AXIS_NAME_INTERNAL-8 "TwoThetaOmega"
*MEAS_COND_AXIS_NAME_INTERNAL-9 "TwoThetaChi"
*MEAS_COND_AXIS_NAME_INTERNAL-10 "TwoThetaChiPhi"
*MEAS_COND_AXIS_NAME_INTERNAL-11 "Alpha"
*MEAS_COND_AXIS_NAME_INTERNAL-12 "Beta"
*MEAS_COND_AXIS_NAME_INTERNAL-13 "ThetaS"
*MEAS_COND_AXIS_NAME_INTERNAL-14 "ThetaD"
*MEAS_COND_AXIS_NAME_INTERNAL-15 "Ts"
*MEAS_COND_AXIS_NAME_INTERNAL-16 "CBO"
*MEAS_COND_AXIS_NAME_INTERNAL-17 "CBO-M"
*MEAS_COND_AXIS_NAME_INTERNAL-18 "IncidentSollerSlit"
*MEAS_COND_AXIS_NAME_INTERNAL-19 "IncidentSlitBox"
*MEAS_COND_AXIS_NAME_INTERNAL-20 "IncidentSlitBox-_Axis"
*MEAS_COND_AXIS_NAME_INTERNAL-21 "Zs"
*MEAS_COND_AXIS_NAME_INTERNAL-22 "IncidentMonochromator"
*MEAS_COND_AXIS_NAME_INTERNAL-23 "IncidentMonochromator-OmegaM"
*MEAS_COND_AXIS_NAME_INTERNAL-24 "IncidentAxdSlit"
*MEAS_COND_AXIS_NAME_INTERNAL-25 "CenterSlit"
*MEAS_COND_AXIS_NAME_INTERNAL-26 "Filter"
*MEAS_COND_AXIS_NAME_INTERNAL-27 "ReceivingSlitBox1"
*MEAS_COND_AXIS_NAME_INTERNAL-28 "ReceivingSlitBox2"
*MEAS_COND_AXIS_NAME_INTERNAL-29 "ReceivingOptics"
*MEAS_COND_AXIS_NAME_INTERNAL-30 "ReceivingSollerSlit"
*MEAS_COND_AXIS_NAME_INTERNAL-31 "ReceivingAxdSlit"
*MEAS_COND_AXIS_NAME_INTERNAL-32 "ReceivingSlitBox1-_Axis"
*MEAS_COND_AXIS_NAME_INTERNAL-33 "ReceivingSlitBox2-_Axis"
*MEAS_COND_AXIS_NAME_INTERNAL-34 "ReceivingSlitBox2-Zd"
*MEAS_COND_AXIS_NAME_INTERNAL-35 "Attenuator"
*MEAS_COND_AXIS_NAME_INTERNAL-36 "CounterMonochromator"
*MEAS_COND_AXIS_NAME_INTERNAL-37 "CounterSlit"
*MEAS_COND_AXIS_NAME_INTERNAL-38 "TwoThetaB"
*MEAS_COND_AXIS_NAME_INTERNAL-39 "AlphaR"
*MEAS_COND_AXIS_NAME_INTERNAL-40 "BetaR"
*MEAS_COND_AXIS_NAME_INTERNAL-41 "ReceivingSlitBox1-Zr"
*MEAS_COND_AXIS_NAME_INTERNAL-42 "IncidentPrimary"
*MEAS_COND_AXIS_NAME_MAGICNO-0 "83951616.0000000000"
*MEAS_COND_AXIS_NAME_MAGICNO-1 "268632064.0000000000"
*MEAS_COND_AXIS_NAME_MAGICNO-2 "268500992.0000000000"
*MEAS_COND_AXIS_NAME_MAGICNO-3 "268500992.0000000000"
*MEAS_COND_AXIS_NAME_MAGICNO-4 "268500992.0000000000"
*MEAS_COND_AXIS_NAME_MAGICNO-5 "285278208.0000000000"
*MEAS_COND_AXIS_NAME_MAGICNO-6 "268500992.0000000000"
*MEAS_COND_AXIS_NAME_MAGICNO-7 "268500992.0000000000"
*MEAS_COND_AXIS_NAME_MAGICNO-8 "83951616.0000000000"
*MEAS_COND_AXIS_NAME_MAGICNO-9 "268632064.0000000000"
*MEAS_COND_AXIS_NAME_MAGICNO-10 "83951616.0000000000"
*MEAS_COND_AXIS_NAME_MAGICNO-11 "17039360.0000000000"
*MEAS_COND_AXIS_NAME_MAGICNO-12 "17039360.0000000000"
*MEAS_COND_AXIS_NAME_MAGICNO-13 "131072.0000000000"
*MEAS_COND_AXIS_NAME_MAGICNO-14 "131072.0000000000"
*MEAS_COND_AXIS_NAME_MAGICNO-15 "318898176.0000000000"
*MEAS_COND_AXIS_NAME_MAGICNO-16 "20971521.0000000000"
*MEAS_COND_AXIS_NAME_MAGICNO-17 "285343744.0000000000"
*MEAS_COND_AXIS_NAME_MAGICNO-18 "20971521.0000000000"
*MEAS_COND_AXIS_NAME_MAGICNO-19 "22020097.0000000000"
*MEAS_COND_AXIS_NAME_MAGICNO-20 "25165824.0000000000"
*MEAS_COND_AXIS_NAME_MAGICNO-21 "318898176.0000000000"
*MEAS_COND_AXIS_NAME_MAGICNO-22 "20971521.0000000000"
*MEAS_COND_AXIS_NAME_MAGICNO-23 "285343744.0000000000"
*MEAS_COND_AXIS_NAME_MAGICNO-24 "20971521.0000000000"
*MEAS_COND_AXIS_NAME_MAGICNO-25 "20971521.0000000000"
*MEAS_COND_AXIS_NAME_MAGICNO-26 "20971521.0000000000"
*MEAS_COND_AXIS_NAME_MAGICNO-27 "23068673.0000000000"
*MEAS_COND_AXIS_NAME_MAGICNO-28 "23068673.0000000000"
*MEAS_COND_AXIS_NAME_MAGICNO-29 "20971521.0000000000"
*MEAS_COND_AXIS_NAME_MAGICNO-30 "20971521.0000000000"
*MEAS_COND_AXIS_NAME_MAGICNO-31 "20971521.0000000000"
*MEAS_COND_AXIS_NAME_MAGICNO-32 "25165824.0000000000"
*MEAS_COND_AXIS_NAME_MAGICNO-33 "25165824.0000000000"
*MEAS_COND_AXIS_NAME_MAGICNO-34 "285343744.0000000000"
*MEAS_COND_AXIS_NAME_MAGICNO-35 "0.0000000000"
*MEAS_COND_AXIS_NAME_MAGICNO-36 "20971521.0000000000"
*MEAS_COND_AXIS_NAME_MAGICNO-37 "20971521.0000000000"
*MEAS_COND_AXIS_NAME_MAGICNO-38 "17039360.0000000000"
*MEAS_COND_AXIS_NAME_MAGICNO-39 "8388608.0000000000"
*MEAS_COND_AXIS_NAME_MAGICNO-40 "8388608.0000000000"
*MEAS_COND_AXIS_NAME_MAGICNO-41 "285343744.0000000000"
*MEAS_COND_AXIS_NAME_MAGICNO-42 "20971521.0000000000"
*MEAS_COND_AXIS_OFFSET-0 "-"
*MEAS_COND_AXIS_OFFSET-1 "0.9377000000"
*MEAS_COND_AXIS_OFFSET-2 "1.5052000000"
*MEAS_COND_AXIS_OFFSET-3 "0.0000000000"
*MEAS_COND_AXIS_OFFSET-4 "0.0000000000"
*MEAS_COND_AXIS_OFFSET-5 "-"
*MEAS_COND_AXIS_OFFSET-6 "0.0000000000"
*MEAS_COND_AXIS_OFFSET-7 "0.0000000000"
*MEAS_COND_AXIS_OFFSET-8 "-"
*MEAS_COND_AXIS_OFFSET-9 "0.0000000000"
*MEAS_COND_AXIS_OFFSET-10 "-"
*MEAS_COND_AXIS_OFFSET-11 "-"
*MEAS_COND_AXIS_OFFSET-12 "-"
*MEAS_COND_AXIS_OFFSET-13 "1.5052000000"
*MEAS_COND_AXIS_OFFSET-14 "-0.5675000000"
*MEAS_COND_AXIS_OFFSET-15 "-"
*MEAS_COND_AXIS_OFFSET-16 "-"
*MEAS_COND_AXIS_OFFSET-17 "-"
*MEAS_COND_AXIS_OFFSET-18 "-"
*MEAS_COND_AXIS_OFFSET-19 "-"
*MEAS_COND_AXIS_OFFSET-20 "-"
*MEAS_COND_AXIS_OFFSET-21 "-"
*MEAS_COND_AXIS_OFFSET-22 "-"
*MEAS_COND_AXIS_OFFSET-23 "-"
*MEAS_COND_AXIS_OFFSET-24 "-"
*MEAS_COND_AXIS_OFFSET-25 "-"
*MEAS_COND_AXIS_OFFSET-26 "-"
*MEAS_COND_AXIS_OFFSET-27 "-"
*MEAS_COND_AXIS_OFFSET-28 "-"
*MEAS_COND_AXIS_OFFSET-29 "-"
*MEAS_COND_AXIS_OFFSET-30 "-"
*MEAS_COND_AXIS_OFFSET-31 "-"
*MEAS_COND_AXIS_OFFSET-32 "-"
*MEAS_COND_AXIS_OFFSET-33 "-"
*MEAS_COND_AXIS_OFFSET-34 "-"
*MEAS_COND_AXIS_OFFSET-35 "-"
*MEAS_COND_AXIS_OFFSET-36 "-"
*MEAS_COND_AXIS_OFFSET-37 "-"
*MEAS_COND_AXIS_OFFSET-38 "-"
*MEAS_COND_AXIS_OFFSET-39 "0.0000000000"
*MEAS_COND_AXIS_OFFSET-40 "0.0000000000"
*MEAS_COND_AXIS_OFFSET-41 "-"
*MEAS_COND_AXIS_OFFSET-42 "-"
*MEAS_COND_AXIS_POSITION-0 "44.0000000000"
*MEAS_COND_AXIS_POSITION-1 "44.0000000000"
*MEAS_COND_AXIS_POSITION-2 "22.0000000000"
*MEAS_COND_AXIS_POSITION-3 "0.0000000000"
*MEAS_COND_AXIS_POSITION-4 "0.0000000000"
*MEAS_COND_AXIS_POSITION-5 "-1.6509000000"
*MEAS_COND_AXIS_POSITION-6 "1.1950000000"
*MEAS_COND_AXIS_POSITION-7 "0.0000000000"
*MEAS_COND_AXIS_POSITION-8 "44.0000000000"
*MEAS_COND_AXIS_POSITION-9 "0.0000000000"
*MEAS_COND_AXIS_POSITION-10 "0.0000000000"
*MEAS_COND_AXIS_POSITION-11 "90.0000000000"
*MEAS_COND_AXIS_POSITION-12 "0.0000000000"
*MEAS_COND_AXIS_POSITION-13 "22.0000000000"
*MEAS_COND_AXIS_POSITION-14 "22.0000000000"
*MEAS_COND_AXIS_POSITION-15 "-5.5290600000"
*MEAS_COND_AXIS_POSITION-16 "PB"
*MEAS_COND_AXIS_POSITION-17 "0.0000000000"
*MEAS_COND_AXIS_POSITION-18 "Soller_slit_2.5deg_s"
*MEAS_COND_AXIS_POSITION-19 "1.000mm"
*MEAS_COND_AXIS_POSITION-20 "1.0000000000"
*MEAS_COND_AXIS_POSITION-21 "-1.4025000000"
*MEAS_COND_AXIS_POSITION-22 "Ge(220)x2"
*MEAS_COND_AXIS_POSITION-23 "0.0000000000"
*MEAS_COND_AXIS_POSITION-24 "0.5mm"
*MEAS_COND_AXIS_POSITION-25 "None"
*MEAS_COND_AXIS_POSITION-26 "None"
*MEAS_COND_AXIS_POSITION-27 "20.000mm"
*MEAS_COND_AXIS_POSITION-28 "38.500mm"
*MEAS_COND_AXIS_POSITION-29 "PSA_open"
*MEAS_COND_AXIS_POSITION-30 "Soller_slit_2.5deg"
*MEAS_COND_AXIS_POSITION-31 "None"
*MEAS_COND_AXIS_POSITION-32 "20.0000000000"
*MEAS_COND_AXIS_POSITION-33 "38.5000000000"
*MEAS_COND_AXIS_POSITION-34 "0.0000000000"
*MEAS_COND_AXIS_POSITION-35 "-"
*MEAS_COND_AXIS_POSITION-36 "No_unit"
*MEAS_COND_AXIS_POSITION-37 "None"
*MEAS_COND_AXIS_POSITION-38 "44.0000000000"
*MEAS_COND_AXIS_POSITION-39 "0.0000000000"
*MEAS_COND_AXIS_POSITION-40 "0.0000000000"
*MEAS_COND_AXIS_POSITION-41 "0.1125000000"
*MEAS_COND_AXIS_POSITION-42 "None"
*MEAS_COND_AXIS_UNIT-0 "deg"
*MEAS_COND_AXIS_UNIT-1 "deg"
*MEAS_COND_AXIS_UNIT-2 "deg"
*MEAS_COND_AXIS_UNIT-3 "deg"
*MEAS_COND_AXIS_UNIT-4 "deg"
*MEAS_COND_AXIS_UNIT-5 "mm"
*MEAS_COND_AXIS_UNIT-6 "mm"
*MEAS_COND_AXIS_UNIT-7 "mm"
*MEAS_COND_AXIS_UNIT-8 "deg"
*MEAS_COND_AXIS_UNIT-9 "deg"
*MEAS_COND_AXIS_UNIT-10 "deg"
*MEAS_COND_AXIS_UNIT-11 "deg"
*MEAS_COND_AXIS_UNIT-12 "deg"
*MEAS_COND_AXIS_UNIT-13 "deg"
*MEAS_COND_AXIS_UNIT-14 "deg"
*MEAS_COND_AXIS_UNIT-15 "mm"
*MEAS_COND_AXIS_UNIT-16 ""
*MEAS_COND_AXIS_UNIT-17 "pulse"
*MEAS_COND_AXIS_UNIT-18 ""
*MEAS_COND_AXIS_UNIT-19 ""
*MEAS_COND_AXIS_UNIT-20 "mm"
*MEAS_COND_AXIS_UNIT-21 "mm"
*MEAS_COND_AXIS_UNIT-22 ""
*MEAS_COND_AXIS_UNIT-23 "pulse"
*MEAS_COND_AXIS_UNIT-24 ""
*MEAS_COND_AXIS_UNIT-25 ""
*MEAS_COND_AXIS_UNIT-26 ""
*MEAS_COND_AXIS_UNIT-27 ""
*MEAS_COND_AXIS_UNIT-28 ""
*MEAS_COND_AXIS_UNIT-29 ""
*MEAS_COND_AXIS_UNIT-30 ""
*MEAS_COND_AXIS_UNIT-31 ""
*MEAS_COND_AXIS_UNIT-32 "mm"
*MEAS_COND_AXIS_UNIT-33 "mm"
*MEAS_COND_AXIS_UNIT-34 "mm"
*MEAS_COND_AXIS_UNIT-35 ""
*MEAS_COND_AXIS_UNIT-36 ""
*MEAS_COND_AXIS_UNIT-37 ""
*MEAS_COND_AXIS_UNIT-38 "deg"
*MEAS_COND_AXIS_UNIT-39 "deg"
*MEAS_COND_AXIS_UNIT-40 "deg"
*MEAS_COND_AXIS_UNIT-41 "mm"
*MEAS_COND_AXIS_UNIT-42 ""
*MEAS_COND_COUNTER_CNTLOSS_CORR "0.0000000000"
*MEAS_COND_COUNTER_TAUDIFF "0.0000000000"
*MEAS_COND_COUNTER_TAUINT "0.0000000000"
*MEAS_COND_COUNTER_TEMP_CONDITION "NORMAL"
*MEAS_COND_IRRADIATION_MODE "OFF"
*MEAS_COND_IRRADIATION_WIDTH ""
*MEAS_COND_OPT_ATTR "High resolution parallel beam Ge(220)x2/RS"
*MEAS_COND_OPT_NAME "@High resolution PB-Ge(220)x2"
*MEAS_COND_UNSYMMETRIC_MODE "OFF"
*MEAS_COND_XG_CURRENT "30.0000000000"
*MEAS_COND_XG_VOLTAGE "40.0000000000"
*MEAS_COND_XG_WAVE_TYPE "Ka1"
*MEAS_DATA_COUNT "21.0000000000"
*MEAS_SCAN_AXIS_X "Theta/2-Theta"
*MEAS_SCAN_AXIS_X_INTERNAL "TwoThetaTheta"
*MEAS_SCAN_END_TIME "03/02/21 08:42:10"
*MEAS_SCAN_MODE "CONTINUOUS"
*MEAS_SCAN_MONITOR "0"
*MEAS_SCAN_RESOLUTION_X "0.0002"
*MEAS_SCAN_SPEED "0.503240"
*MEAS_SCAN_SPEED_UNIT "deg/min"
*MEAS_SCAN_SPEED_USER "0.5"
*MEAS_SCAN_START "44.0000000000"
*MEAS_SCAN_START_TIME "03/02/21 08:25:20"
*MEAS_SCAN_STEP "0.0500000000"
*MEAS_SCAN_STOP "45.0000000000"
*MEAS_SCAN_UNIT_X "deg"
*MEAS_SCAN_UNIT_Y "counts"
*RAS_HEADER_END
*RAS_INT_START
44.0000 85.8571 1.0000
44.0500 86.8562 1.0000
44.1000 118.3759 1.0000
44.1500 151.0875 1.0000
44.2000 213.9431 1.0000
44.2500 302.9024 1.0000
44.3000 448.8069 1.0000
44.3500 739.0226 1.0000
44.4000 958.1017 1.0000
44.4500 1096.1024 1.0000
44.5000 1008.2144 1.0000
44.5500 812.2551 1.0000
44.6000 627.3359 1.0000
44.6500 421.6631 1.0000
44.7000 286.9229 1.0000
44.7500 149.2353 1.0000
44.8000 134.0414 1.0000
44.8500 100.9708 1.0000
44.9000 88.9359 1.0000
44.9500 89.1909 1.0000
45.0000 47.9015 1.0000
*RAS_INT_END
*RAS_TEMPERATURE_START
*RAS_TEMPERATURE_END
*RAS_DATA_END