File: XRD/PB_Ge220_2.5SS_500umDS_RS1_Rod_2.5SS_Hypix1D_EFRW3_FZ_P-irradiated.ras
*RAS_DATA_START
*RAS_HEADER_START
*DISP_FMT_X "%.3f"
*DISP_FMT_Y "%.0f"
*DISP_FULLSCALE "199.9012519671"
*DISP_LINE_COLOR "255.0000000000"
*DISP_LINE_STYLE "0.0000000000"
*DISP_LINE_WIDTH "0.2500000000"
*DISP_NOTE "Collected Data-35"
*DISP_OFFSET_Y "0.0000000000"
*DISP_PEAKSEARCH_UNIT_Y "cps"
*DISP_RANGE_BOTTOM "0.0000000000"
*DISP_RANGE_LEFT "40.0000000000"
*DISP_RANGE_LOGCUTOFF "0.0100000000"
*DISP_RANGE_RIGHT "119.9968000000"
*DISP_RANGE_TOP "199.9012519671"
*DISP_SCALE_MODE_Y "0.0000000000"
*DISP_TAB_NAME "Theta/2-Theta"
*DISP_TITLE_Y "Intensity"
*DISP_UNIT_Y "cps"
*DISP_WINDOW_NAME "MSG_MACROENGINE"
*FILE_COMMENT " "
*FILE_MD5 ""
*FILE_MEMO " "
*FILE_OPERATOR "Administrator"
*FILE_PART_ID "MEAS_KHP2_00061"
*FILE_SAMPLE " "
*FILE_TYPE "RAS_RAW"
*FILE_USERGROUP "System Manager"
*FILE_VERSION "1.0000000000"
*HW_ATTACHMENT_ID "ATT0021"
*HW_ATTACHMENT_NAME "XY-20mm|XY-20mm"
*HW_COUNTER_ID-0 "CUT0041"
*HW_COUNTER_ID-1 "CUT0051"
*HW_COUNTER_ID-2 "CUT0020"
*HW_COUNTER_ID-3 "CSL0021"
*HW_COUNTER_ID-4 "CMC0021"
*HW_COUNTER_NAME-0 "D/teX Ultra 250|D/teX Ultra 250"
*HW_COUNTER_NAME-1 "HyPix 3000(H)|HyPix 3000(H)"
*HW_COUNTER_NAME-2 "None|None"
*HW_COUNTER_NAME-3 "BBM|BBM"
*HW_COUNTER_NAME-4 "検出器モノクロメータ|Detector monochromator"
*HW_COUNTER_SELECT_NAME "HyPix 3000(H)|HyPix 3000(H)"
*HW_GONIOMETER_ID "GON0024"
*HW_GONIOMETER_NAME "SmartLab(In-plane)|SmartLab(In-plane)"
*HW_GONIOMETER_RADIUS-0 "90.0"
*HW_GONIOMETER_RADIUS-1 "114.0"
*HW_GONIOMETER_RADIUS-2 "190.0"
*HW_GONIOMETER_RADIUS-3 "300.0"
*HW_GONIOMETER_RADIUS-4 "187.0"
*HW_GONIOMETER_RADIUS-5 "300.0"
*HW_GONIOMETER_RADIUS-6 "113.0"
*HW_GONIOMETER_RADIUS-7 "331.0"
*HW_I_OPT_ID-0 "CBO0021"
*HW_I_OPT_ID-1 "ICR0021"
*HW_I_OPT_ID-2 "ISL0021"
*HW_I_OPT_ID-3 "ISO0021"
*HW_I_OPT_ID-4 "IAD0021"
*HW_I_OPT_ID-5 "IPR0001"
*HW_I_OPT_NAME-0 "CBOユニット|CBO unit"
*HW_I_OPT_NAME-1 "標準入射光学ユニット|Standard incident optical unit"
*HW_I_OPT_NAME-2 "標準入射スリットボックス|Standard incident slit box"
*HW_I_OPT_NAME-3 "入射平行スリット|Incident parallel slit"
*HW_I_OPT_NAME-4 "長手制限スリット|Length limiting slit"
*HW_I_OPT_NAME-5 "None|None"
*HW_R_ATTENUATER_AUTOMODE "0"
*HW_R_OPT_ID-0 "RSS0022"
*HW_R_OPT_ID-1 "RCR0022"
*HW_R_OPT_ID-2 "RSO0021"
*HW_R_OPT_ID-3 "RRS0022"
*HW_R_OPT_ID-4 "ATN0020"
*HW_R_OPT_ID-5 "RFL0021"
*HW_R_OPT_ID-6 "RAD0021"
*HW_R_OPT_NAME-0 "受光スリットボックス1(Zr軸付)|Receiving slit box # 1 (w/ Zr Axis)"
*HW_R_OPT_NAME-1 "標準受光光学ユニット1|Standard receiving unit # 1"
*HW_R_OPT_NAME-2 "標準受光光学ユニット2|Standard receiving optical unit # 2"
*HW_R_OPT_NAME-3 "仮想受光スリット2|Virtual receiving slit #2"
*HW_R_OPT_NAME-4 "無し|None"
*HW_R_OPT_NAME-5 "Cu Kβ|Cu K-beta"
*HW_R_OPT_NAME-6 "調整用受光スリット|Alignment receiving slit"
*HW_SAMPLE_HOLDER_ID "SMP0021"
*HW_SAMPLE_HOLDER_NAME "χφZクレードル|Chi phi Z cradle"
*HW_XG_CURRENT_MAX "40"
*HW_XG_CURRENT_MIN "2"
*HW_XG_CURRENT_RESOLUTION "1"
*HW_XG_CURRENT_UNIT "mA"
*HW_XG_FOCUS "0.4mm x 8mm"
*HW_XG_FOCUS_TYPE "Fine"
*HW_XG_ID "1200"
*HW_XG_NAME "3kW 封入管(ID:1200)|3kW Sealed tube(ID:1200)"
*HW_XG_TARGET_ATOMIC_NUMBER "29.0000000000"
*HW_XG_TARGET_NAME "Cu"
*HW_XG_TYPE "Hermetic"
*HW_XG_VOLTAGE_MAX "40"
*HW_XG_VOLTAGE_MIN "20"
*HW_XG_VOLTAGE_RESOLUTION "1"
*HW_XG_VOLTAGE_UNIT "kV"
*HW_XG_WATT_MAX "1.500"
*HW_XG_WATT_UNIT "kW"
*HW_XG_WAVE_LENGTH_ALPHA1 "1.540593"
*HW_XG_WAVE_LENGTH_ALPHA2 "1.544414"
*HW_XG_WAVE_LENGTH_BETA "1.392250"
*MEAS_COND_AXIS_NAME-0 "Theta/2-Theta"
*MEAS_COND_AXIS_NAME-1 "2-Theta"
*MEAS_COND_AXIS_NAME-2 "Omega"
*MEAS_COND_AXIS_NAME-3 "Chi"
*MEAS_COND_AXIS_NAME-4 "Phi"
*MEAS_COND_AXIS_NAME-5 "Z"
*MEAS_COND_AXIS_NAME-6 "X"
*MEAS_COND_AXIS_NAME-7 "Y"
*MEAS_COND_AXIS_NAME-8 "2-Theta/Omega"
*MEAS_COND_AXIS_NAME-9 "2-ThetaChi"
*MEAS_COND_AXIS_NAME-10 "2-ThetaChi/Phi"
*MEAS_COND_AXIS_NAME-11 "Alpha"
*MEAS_COND_AXIS_NAME-12 "Beta"
*MEAS_COND_AXIS_NAME-13 "Theta_s"
*MEAS_COND_AXIS_NAME-14 "Theta_d"
*MEAS_COND_AXIS_NAME-15 "Ts"
*MEAS_COND_AXIS_NAME-16 "CBO selection slit"
*MEAS_COND_AXIS_NAME-17 "M"
*MEAS_COND_AXIS_NAME-18 "Incident parallel slit"
*MEAS_COND_AXIS_NAME-19 "Incident slit"
*MEAS_COND_AXIS_NAME-20 ""
*MEAS_COND_AXIS_NAME-21 "Zs"
*MEAS_COND_AXIS_NAME-22 "Incident optical device"
*MEAS_COND_AXIS_NAME-23 "Omega_m"
*MEAS_COND_AXIS_NAME-24 "Length limiting slit"
*MEAS_COND_AXIS_NAME-25 "Center slit"
*MEAS_COND_AXIS_NAME-26 "Filter"
*MEAS_COND_AXIS_NAME-27 "Receiving slit # 1"
*MEAS_COND_AXIS_NAME-28 "Receiving slit # 2"
*MEAS_COND_AXIS_NAME-29 "Receiving optical device"
*MEAS_COND_AXIS_NAME-30 "Receiving parallel slit"
*MEAS_COND_AXIS_NAME-31 "Alignment receiving slit"
*MEAS_COND_AXIS_NAME-32 ""
*MEAS_COND_AXIS_NAME-33 ""
*MEAS_COND_AXIS_NAME-34 "Zd"
*MEAS_COND_AXIS_NAME-35 "Attenuator"
*MEAS_COND_AXIS_NAME-36 "Diffracted beam monochromator"
*MEAS_COND_AXIS_NAME-37 "Monochromator slit"
*MEAS_COND_AXIS_NAME-38 "2-ThetaB"
*MEAS_COND_AXIS_NAME-39 ""
*MEAS_COND_AXIS_NAME-40 ""
*MEAS_COND_AXIS_NAME-41 "Zr"
*MEAS_COND_AXIS_NAME-42 "Primary beam"
*MEAS_COND_AXIS_NAME_INTERNAL-0 "TwoThetaTheta"
*MEAS_COND_AXIS_NAME_INTERNAL-1 "TwoTheta"
*MEAS_COND_AXIS_NAME_INTERNAL-2 "Omega"
*MEAS_COND_AXIS_NAME_INTERNAL-3 "Chi"
*MEAS_COND_AXIS_NAME_INTERNAL-4 "Phi"
*MEAS_COND_AXIS_NAME_INTERNAL-5 "Z"
*MEAS_COND_AXIS_NAME_INTERNAL-6 "X"
*MEAS_COND_AXIS_NAME_INTERNAL-7 "Y"
*MEAS_COND_AXIS_NAME_INTERNAL-8 "TwoThetaOmega"
*MEAS_COND_AXIS_NAME_INTERNAL-9 "TwoThetaChi"
*MEAS_COND_AXIS_NAME_INTERNAL-10 "TwoThetaChiPhi"
*MEAS_COND_AXIS_NAME_INTERNAL-11 "Alpha"
*MEAS_COND_AXIS_NAME_INTERNAL-12 "Beta"
*MEAS_COND_AXIS_NAME_INTERNAL-13 "ThetaS"
*MEAS_COND_AXIS_NAME_INTERNAL-14 "ThetaD"
*MEAS_COND_AXIS_NAME_INTERNAL-15 "Ts"
*MEAS_COND_AXIS_NAME_INTERNAL-16 "CBO"
*MEAS_COND_AXIS_NAME_INTERNAL-17 "CBO-M"
*MEAS_COND_AXIS_NAME_INTERNAL-18 "IncidentSollerSlit"
*MEAS_COND_AXIS_NAME_INTERNAL-19 "IncidentSlitBox"
*MEAS_COND_AXIS_NAME_INTERNAL-20 "IncidentSlitBox-_Axis"
*MEAS_COND_AXIS_NAME_INTERNAL-21 "Zs"
*MEAS_COND_AXIS_NAME_INTERNAL-22 "IncidentMonochromator"
*MEAS_COND_AXIS_NAME_INTERNAL-23 "IncidentMonochromator-OmegaM"
*MEAS_COND_AXIS_NAME_INTERNAL-24 "IncidentAxdSlit"
*MEAS_COND_AXIS_NAME_INTERNAL-25 "CenterSlit"
*MEAS_COND_AXIS_NAME_INTERNAL-26 "Filter"
*MEAS_COND_AXIS_NAME_INTERNAL-27 "ReceivingSlitBox1"
*MEAS_COND_AXIS_NAME_INTERNAL-28 "ReceivingSlitBox2"
*MEAS_COND_AXIS_NAME_INTERNAL-29 "ReceivingOptics"
*MEAS_COND_AXIS_NAME_INTERNAL-30 "ReceivingSollerSlit"
*MEAS_COND_AXIS_NAME_INTERNAL-31 "ReceivingAxdSlit"
*MEAS_COND_AXIS_NAME_INTERNAL-32 "ReceivingSlitBox1-_Axis"
*MEAS_COND_AXIS_NAME_INTERNAL-33 "ReceivingSlitBox2-_Axis"
*MEAS_COND_AXIS_NAME_INTERNAL-34 "ReceivingSlitBox2-Zd"
*MEAS_COND_AXIS_NAME_INTERNAL-35 "Attenuator"
*MEAS_COND_AXIS_NAME_INTERNAL-36 "CounterMonochromator"
*MEAS_COND_AXIS_NAME_INTERNAL-37 "CounterSlit"
*MEAS_COND_AXIS_NAME_INTERNAL-38 "TwoThetaB"
*MEAS_COND_AXIS_NAME_INTERNAL-39 "AlphaR"
*MEAS_COND_AXIS_NAME_INTERNAL-40 "BetaR"
*MEAS_COND_AXIS_NAME_INTERNAL-41 "ReceivingSlitBox1-Zr"
*MEAS_COND_AXIS_NAME_INTERNAL-42 "IncidentPrimary"
*MEAS_COND_AXIS_NAME_MAGICNO-0 "83951616.0000000000"
*MEAS_COND_AXIS_NAME_MAGICNO-1 "268632064.0000000000"
*MEAS_COND_AXIS_NAME_MAGICNO-2 "268500992.0000000000"
*MEAS_COND_AXIS_NAME_MAGICNO-3 "268500992.0000000000"
*MEAS_COND_AXIS_NAME_MAGICNO-4 "268500992.0000000000"
*MEAS_COND_AXIS_NAME_MAGICNO-5 "285278208.0000000000"
*MEAS_COND_AXIS_NAME_MAGICNO-6 "268500992.0000000000"
*MEAS_COND_AXIS_NAME_MAGICNO-7 "268500992.0000000000"
*MEAS_COND_AXIS_NAME_MAGICNO-8 "83951616.0000000000"
*MEAS_COND_AXIS_NAME_MAGICNO-9 "268632064.0000000000"
*MEAS_COND_AXIS_NAME_MAGICNO-10 "83951616.0000000000"
*MEAS_COND_AXIS_NAME_MAGICNO-11 "17039360.0000000000"
*MEAS_COND_AXIS_NAME_MAGICNO-12 "17039360.0000000000"
*MEAS_COND_AXIS_NAME_MAGICNO-13 "131072.0000000000"
*MEAS_COND_AXIS_NAME_MAGICNO-14 "131072.0000000000"
*MEAS_COND_AXIS_NAME_MAGICNO-15 "318898176.0000000000"
*MEAS_COND_AXIS_NAME_MAGICNO-16 "20971521.0000000000"
*MEAS_COND_AXIS_NAME_MAGICNO-17 "285343744.0000000000"
*MEAS_COND_AXIS_NAME_MAGICNO-18 "20971521.0000000000"
*MEAS_COND_AXIS_NAME_MAGICNO-19 "22020097.0000000000"
*MEAS_COND_AXIS_NAME_MAGICNO-20 "25165824.0000000000"
*MEAS_COND_AXIS_NAME_MAGICNO-21 "318898176.0000000000"
*MEAS_COND_AXIS_NAME_MAGICNO-22 "20971521.0000000000"
*MEAS_COND_AXIS_NAME_MAGICNO-23 "285343744.0000000000"
*MEAS_COND_AXIS_NAME_MAGICNO-24 "20971521.0000000000"
*MEAS_COND_AXIS_NAME_MAGICNO-25 "20971521.0000000000"
*MEAS_COND_AXIS_NAME_MAGICNO-26 "20971521.0000000000"
*MEAS_COND_AXIS_NAME_MAGICNO-27 "23068673.0000000000"
*MEAS_COND_AXIS_NAME_MAGICNO-28 "23068673.0000000000"
*MEAS_COND_AXIS_NAME_MAGICNO-29 "20971521.0000000000"
*MEAS_COND_AXIS_NAME_MAGICNO-30 "20971521.0000000000"
*MEAS_COND_AXIS_NAME_MAGICNO-31 "20971521.0000000000"
*MEAS_COND_AXIS_NAME_MAGICNO-32 "25165824.0000000000"
*MEAS_COND_AXIS_NAME_MAGICNO-33 "25165824.0000000000"
*MEAS_COND_AXIS_NAME_MAGICNO-34 "285343744.0000000000"
*MEAS_COND_AXIS_NAME_MAGICNO-35 "0.0000000000"
*MEAS_COND_AXIS_NAME_MAGICNO-36 "20971521.0000000000"
*MEAS_COND_AXIS_NAME_MAGICNO-37 "20971521.0000000000"
*MEAS_COND_AXIS_NAME_MAGICNO-38 "17039360.0000000000"
*MEAS_COND_AXIS_NAME_MAGICNO-39 "8388608.0000000000"
*MEAS_COND_AXIS_NAME_MAGICNO-40 "8388608.0000000000"
*MEAS_COND_AXIS_NAME_MAGICNO-41 "285343744.0000000000"
*MEAS_COND_AXIS_NAME_MAGICNO-42 "20971521.0000000000"
*MEAS_COND_AXIS_OFFSET-0 "-"
*MEAS_COND_AXIS_OFFSET-1 "0.8642000000"
*MEAS_COND_AXIS_OFFSET-2 "1.0640000000"
*MEAS_COND_AXIS_OFFSET-3 "0.0000000000"
*MEAS_COND_AXIS_OFFSET-4 "0.0000000000"
*MEAS_COND_AXIS_OFFSET-5 "-"
*MEAS_COND_AXIS_OFFSET-6 "0.0000000000"
*MEAS_COND_AXIS_OFFSET-7 "0.0000000000"
*MEAS_COND_AXIS_OFFSET-8 "-"
*MEAS_COND_AXIS_OFFSET-9 "0.0000000000"
*MEAS_COND_AXIS_OFFSET-10 "-"
*MEAS_COND_AXIS_OFFSET-11 "-"
*MEAS_COND_AXIS_OFFSET-12 "-"
*MEAS_COND_AXIS_OFFSET-13 "1.0640000000"
*MEAS_COND_AXIS_OFFSET-14 "-0.1998000000"
*MEAS_COND_AXIS_OFFSET-15 "-"
*MEAS_COND_AXIS_OFFSET-16 "-"
*MEAS_COND_AXIS_OFFSET-17 "-"
*MEAS_COND_AXIS_OFFSET-18 "-"
*MEAS_COND_AXIS_OFFSET-19 "-"
*MEAS_COND_AXIS_OFFSET-20 "-"
*MEAS_COND_AXIS_OFFSET-21 "-"
*MEAS_COND_AXIS_OFFSET-22 "-"
*MEAS_COND_AXIS_OFFSET-23 "-"
*MEAS_COND_AXIS_OFFSET-24 "-"
*MEAS_COND_AXIS_OFFSET-25 "-"
*MEAS_COND_AXIS_OFFSET-26 "-"
*MEAS_COND_AXIS_OFFSET-27 "-"
*MEAS_COND_AXIS_OFFSET-28 "-"
*MEAS_COND_AXIS_OFFSET-29 "-"
*MEAS_COND_AXIS_OFFSET-30 "-"
*MEAS_COND_AXIS_OFFSET-31 "-"
*MEAS_COND_AXIS_OFFSET-32 "-"
*MEAS_COND_AXIS_OFFSET-33 "-"
*MEAS_COND_AXIS_OFFSET-34 "-"
*MEAS_COND_AXIS_OFFSET-35 "-"
*MEAS_COND_AXIS_OFFSET-36 "-"
*MEAS_COND_AXIS_OFFSET-37 "-"
*MEAS_COND_AXIS_OFFSET-38 "-"
*MEAS_COND_AXIS_OFFSET-39 "0.0000000000"
*MEAS_COND_AXIS_OFFSET-40 "0.0000000000"
*MEAS_COND_AXIS_OFFSET-41 "-"
*MEAS_COND_AXIS_OFFSET-42 "-"
*MEAS_COND_AXIS_POSITION-0 "40.0000000000"
*MEAS_COND_AXIS_POSITION-1 "40.0000000000"
*MEAS_COND_AXIS_POSITION-2 "20.0000000000"
*MEAS_COND_AXIS_POSITION-3 "0.0000000000"
*MEAS_COND_AXIS_POSITION-4 "0.0000000000"
*MEAS_COND_AXIS_POSITION-5 "-1.7645000000"
*MEAS_COND_AXIS_POSITION-6 "-2.2795000000"
*MEAS_COND_AXIS_POSITION-7 "-1.5270000000"
*MEAS_COND_AXIS_POSITION-8 "40.0000000000"
*MEAS_COND_AXIS_POSITION-9 "0.0000000000"
*MEAS_COND_AXIS_POSITION-10 "0.0000000000"
*MEAS_COND_AXIS_POSITION-11 "90.0000000000"
*MEAS_COND_AXIS_POSITION-12 "0.0000000000"
*MEAS_COND_AXIS_POSITION-13 "20.0000000000"
*MEAS_COND_AXIS_POSITION-14 "20.0000000000"
*MEAS_COND_AXIS_POSITION-15 "-5.4426900000"
*MEAS_COND_AXIS_POSITION-16 "PB"
*MEAS_COND_AXIS_POSITION-17 "0.0000000000"
*MEAS_COND_AXIS_POSITION-18 "Soller_slit_5.0deg_s"
*MEAS_COND_AXIS_POSITION-19 "1.000mm"
*MEAS_COND_AXIS_POSITION-20 "1.0000000000"
*MEAS_COND_AXIS_POSITION-21 "-1.3487500000"
*MEAS_COND_AXIS_POSITION-22 "Ge(220)x2"
*MEAS_COND_AXIS_POSITION-23 "0.0000000000"
*MEAS_COND_AXIS_POSITION-24 "0.5mm"
*MEAS_COND_AXIS_POSITION-25 "None"
*MEAS_COND_AXIS_POSITION-26 "None"
*MEAS_COND_AXIS_POSITION-27 "20.000mm"
*MEAS_COND_AXIS_POSITION-28 "38.500mm"
*MEAS_COND_AXIS_POSITION-29 "PSA_open"
*MEAS_COND_AXIS_POSITION-30 "Soller_slit_5.0deg"
*MEAS_COND_AXIS_POSITION-31 "None"
*MEAS_COND_AXIS_POSITION-32 "20.0000000000"
*MEAS_COND_AXIS_POSITION-33 "38.5000000000"
*MEAS_COND_AXIS_POSITION-34 "0.0000000000"
*MEAS_COND_AXIS_POSITION-35 "-"
*MEAS_COND_AXIS_POSITION-36 "No_unit"
*MEAS_COND_AXIS_POSITION-37 "None"
*MEAS_COND_AXIS_POSITION-38 "0.0000000000"
*MEAS_COND_AXIS_POSITION-39 "0.0000000000"
*MEAS_COND_AXIS_POSITION-40 "0.0000000000"
*MEAS_COND_AXIS_POSITION-41 "0.2584400000"
*MEAS_COND_AXIS_POSITION-42 "None"
*MEAS_COND_AXIS_UNIT-0 "deg"
*MEAS_COND_AXIS_UNIT-1 "deg"
*MEAS_COND_AXIS_UNIT-2 "deg"
*MEAS_COND_AXIS_UNIT-3 "deg"
*MEAS_COND_AXIS_UNIT-4 "deg"
*MEAS_COND_AXIS_UNIT-5 "mm"
*MEAS_COND_AXIS_UNIT-6 "mm"
*MEAS_COND_AXIS_UNIT-7 "mm"
*MEAS_COND_AXIS_UNIT-8 "deg"
*MEAS_COND_AXIS_UNIT-9 "deg"
*MEAS_COND_AXIS_UNIT-10 "deg"
*MEAS_COND_AXIS_UNIT-11 "deg"
*MEAS_COND_AXIS_UNIT-12 "deg"
*MEAS_COND_AXIS_UNIT-13 "deg"
*MEAS_COND_AXIS_UNIT-14 "deg"
*MEAS_COND_AXIS_UNIT-15 "mm"
*MEAS_COND_AXIS_UNIT-16 ""
*MEAS_COND_AXIS_UNIT-17 "pulse"
*MEAS_COND_AXIS_UNIT-18 ""
*MEAS_COND_AXIS_UNIT-19 ""
*MEAS_COND_AXIS_UNIT-20 "mm"
*MEAS_COND_AXIS_UNIT-21 "mm"
*MEAS_COND_AXIS_UNIT-22 ""
*MEAS_COND_AXIS_UNIT-23 "pulse"
*MEAS_COND_AXIS_UNIT-24 ""
*MEAS_COND_AXIS_UNIT-25 ""
*MEAS_COND_AXIS_UNIT-26 ""
*MEAS_COND_AXIS_UNIT-27 ""
*MEAS_COND_AXIS_UNIT-28 ""
*MEAS_COND_AXIS_UNIT-29 ""
*MEAS_COND_AXIS_UNIT-30 ""
*MEAS_COND_AXIS_UNIT-31 ""
*MEAS_COND_AXIS_UNIT-32 "mm"
*MEAS_COND_AXIS_UNIT-33 "mm"
*MEAS_COND_AXIS_UNIT-34 "mm"
*MEAS_COND_AXIS_UNIT-35 ""
*MEAS_COND_AXIS_UNIT-36 ""
*MEAS_COND_AXIS_UNIT-37 ""
*MEAS_COND_AXIS_UNIT-38 "deg"
*MEAS_COND_AXIS_UNIT-39 "deg"
*MEAS_COND_AXIS_UNIT-40 "deg"
*MEAS_COND_AXIS_UNIT-41 "mm"
*MEAS_COND_AXIS_UNIT-42 ""
*MEAS_COND_COUNTER_CNTLOSS_CORR "0.0000000000"
*MEAS_COND_COUNTER_TAUDIFF "0.0000000000"
*MEAS_COND_COUNTER_TAUINT "0.0000000000"
*MEAS_COND_COUNTER_TEMP_CONDITION "NORMAL"
*MEAS_COND_IRRADIATION_MODE "OFF"
*MEAS_COND_IRRADIATION_WIDTH ""
*MEAS_COND_OPT_ATTR "High resolution parallel beam Ge(220)x2/RS"
*MEAS_COND_OPT_NAME "@High resolution PB-Ge(220)x2"
*MEAS_COND_UNSYMMETRIC_MODE "OFF"
*MEAS_COND_XG_CURRENT "30.0000000000"
*MEAS_COND_XG_VOLTAGE "40.0000000000"
*MEAS_COND_XG_WAVE_TYPE "Ka1"
*MEAS_DATA_COUNT "8000.0000000000"
*MEAS_SCAN_AXIS_X "Theta/2-Theta"
*MEAS_SCAN_AXIS_X_INTERNAL "TwoThetaTheta"
*MEAS_SCAN_END_TIME "05/16/22 15:31:15"
*MEAS_SCAN_MODE "CONTINUOUS"
*MEAS_SCAN_MONITOR "0"
*MEAS_SCAN_RESOLUTION_X "0.0002"
*MEAS_SCAN_SPEED "0.503240"
*MEAS_SCAN_SPEED_UNIT "deg/min"
*MEAS_SCAN_SPEED_USER "0.5"
*MEAS_SCAN_START "40.0000000000"
*MEAS_SCAN_START_TIME "05/16/22 12:36:25"
*MEAS_SCAN_STEP "0.0100000000"
*MEAS_SCAN_STOP "119.9900000000"
*MEAS_SCAN_UNIT_X "deg"
*MEAS_SCAN_UNIT_Y "counts"
*RAS_HEADER_END
*RAS_INT_START
40.0000 5.2078 1.0000
40.0600 8.3433 1.0000
40.1200 5.4239 1.0000
40.1800 10.7556 1.0000
40.2400 11.9397 1.0000
40.3000 7.0817 1.0000
40.3600 6.5635 1.0000
40.4200 8.3543 1.0000
40.4800 7.2381 1.0000
40.5400 6.1846 1.0000
40.6000 6.7049 1.0000
40.6600 10.9839 1.0000
40.7200 6.6639 1.0000
40.7800 2.6025 1.0000
40.8400 7.0774 1.0000
40.9000 7.8076 1.0000
40.9600 8.3560 1.0000
41.0200 5.5529 1.0000
41.0800 8.5954 1.0000
41.1400 4.2204 1.0000
41.2000 9.1290 1.0000
41.2600 10.5225 1.0000
41.3200 11.1093 1.0000
41.3800 8.5507 1.0000
41.4400 5.7872 1.0000
41.5000 12.4722 1.0000
41.5600 5.6595 1.0000
41.6200 6.9311 1.0000
41.6800 1.9868 1.0000
41.7400 5.5609 1.0000
41.8000 8.6901 1.0000
41.8600 8.6122 1.0000
41.9200 12.0455 1.0000
41.9800 6.4494 1.0000
42.0400 3.9725 1.0000
42.1000 9.2310 1.0000
42.1600 4.8419 1.0000
42.2200 6.2881 1.0000
42.2800 9.6217 1.0000
42.3400 2.4602 1.0000
42.4000 3.9396 1.0000
42.4600 11.1181 1.0000
42.5200 12.0474 1.0000
42.5800 6.7313 1.0000
42.6400 3.4708 1.0000
42.7000 6.4496 1.0000
42.7600 4.6113 1.0000
42.8200 10.6493 1.0000
42.8800 6.9716 1.0000
42.9400 6.6517 1.0000
43.0000 6.2035 1.0000
43.0600 8.6045 1.0000
43.1200 4.1518 1.0000
43.1800 8.4676 1.0000
43.2400 9.2399 1.0000
43.3000 3.4453 1.0000
43.3600 6.5824 1.0000
43.4200 10.0802 1.0000
43.4800 4.4088 1.0000
43.5400 3.2197 1.0000
43.6000 8.1011 1.0000
43.6600 6.2899 1.0000
43.7200 7.0628 1.0000
43.7800 7.9801 1.0000
43.8400 7.7733 1.0000
43.9000 15.3260 1.0000
43.9600 8.6059 1.0000
44.0200 7.8584 1.0000
44.0800 8.3108 1.0000
44.1400 10.6519 1.0000
44.2000 17.5898 1.0000
44.2600 16.2552 1.0000
44.3200 46.4933 1.0000
44.3800 87.3042 1.0000
44.4400 136.9175 1.0000
44.5000 175.7573 1.0000
44.5600 148.6118 1.0000
44.6200 83.8436 1.0000
44.6800 49.9573 1.0000
44.7400 18.6167 1.0000
44.8000 15.3449 1.0000
44.8600 7.8441 1.0000
44.9200 4.2226 1.0000
44.9800 11.7521 1.0000
45.0400 7.0587 1.0000
45.1000 15.3320 1.0000
45.1600 7.9023 1.0000
45.2200 7.6727 1.0000
45.2800 6.2955 1.0000
45.3400 5.6790 1.0000
45.4000 7.3741 1.0000
45.4600 7.1692 1.0000
45.5200 6.3021 1.0000
45.5800 6.5215 1.0000
45.6400 8.4823 1.0000
45.7000 7.3224 1.0000
45.7600 11.2324 1.0000
45.8200 13.9521 1.0000
45.8800 3.2658 1.0000
45.9400 3.2116 1.0000
46.0000 13.4961 1.0000
46.0600 10.6481 1.0000
46.1200 4.8994 1.0000
46.1800 7.0335 1.0000
46.2400 5.5101 1.0000
46.3000 11.6414 1.0000
46.3600 6.8617 1.0000
46.4200 5.2362 1.0000
46.4800 4.5189 1.0000
46.5400 6.6252 1.0000
46.6000 4.5129 1.0000
46.6600 9.5494 1.0000
46.7200 6.8629 1.0000
46.7800 7.1386 1.0000
46.8400 6.1176 1.0000
46.9000 3.2991 1.0000
46.9600 8.0694 1.0000
47.0200 7.0079 1.0000
47.0800 3.8684 1.0000
47.1400 8.4564 1.0000
47.2000 4.1661 1.0000
47.2600 4.0231 1.0000
47.3200 9.5680 1.0000
47.3800 10.3506 1.0000
47.4400 4.4040 1.0000
47.5000 6.5178 1.0000
47.5600 3.4212 1.0000
47.6200 5.1740 1.0000
47.6800 1.2720 1.0000
47.7400 7.2218 1.0000
47.8000 13.1136 1.0000
47.8600 5.9081 1.0000
47.9200 6.5089 1.0000
47.9800 6.1733 1.0000
48.0400 7.3649 1.0000
48.1000 10.3241 1.0000
48.1600 3.1018 1.0000
48.2200 6.0276 1.0000
48.2800 3.3622 1.0000
48.3400 8.5848 1.0000
48.4000 4.2441 1.0000
48.4600 11.0065 1.0000
48.5200 6.3477 1.0000
48.5800 9.0659 1.0000
48.6400 11.1871 1.0000
48.7000 8.1284 1.0000
48.7600 4.6997 1.0000
48.8200 4.8449 1.0000
48.8800 4.9671 1.0000
48.9400 5.5765 1.0000
49.0000 6.2144 1.0000
49.0600 9.9669 1.0000
49.1200 5.0502 1.0000
49.1800 6.7332 1.0000
49.2400 13.1181 1.0000
49.3000 6.5972 1.0000
49.3600 7.7788 1.0000
49.4200 9.6328 1.0000
49.4800 6.5726 1.0000
49.5400 4.4815 1.0000
49.6000 7.8037 1.0000
49.6600 5.7680 1.0000
49.7200 7.9776 1.0000
49.7800 5.0790 1.0000
49.8400 9.0932 1.0000
49.9000 3.9162 1.0000
49.9600 7.2714 1.0000
50.0200 5.2639 1.0000
50.0800 8.8953 1.0000
50.1400 4.2895 1.0000
50.2000 7.2858 1.0000
50.2600 7.8085 1.0000
50.3200 7.8726 1.0000
50.3800 5.9918 1.0000
50.4400 12.1959 1.0000
50.5000 8.7687 1.0000
50.5600 4.5373 1.0000
50.6200 3.3632 1.0000
50.6800 5.0647 1.0000
50.7400 6.0371 1.0000
50.8000 7.5347 1.0000
50.8600 3.9293 1.0000
50.9200 1.4098 1.0000
50.9800 5.0785 1.0000
51.0400 9.3295 1.0000
51.1000 17.5099 1.0000
51.1600 6.7327 1.0000
51.2200 4.3032 1.0000
51.2800 10.0952 1.0000
51.3400 5.7696 1.0000
51.4000 8.0465 1.0000
51.4600 4.3381 1.0000
51.5200 8.0707 1.0000
51.5800 3.7612 1.0000
51.6400 5.8586 1.0000
51.7000 10.2664 1.0000
51.7600 3.7714 1.0000
51.8200 5.0313 1.0000
51.8800 4.8747 1.0000
51.9400 8.7877 1.0000
52.0000 7.0519 1.0000
52.0600 6.7814 1.0000
52.1200 6.9847 1.0000
52.1800 10.5150 1.0000
52.2400 17.6456 1.0000
52.3000 4.2173 1.0000
52.3600 7.2280 1.0000
52.4200 3.7688 1.0000
52.4800 4.3612 1.0000
52.5400 10.7814 1.0000
52.6000 7.8080 1.0000
52.6600 10.3968 1.0000
52.7200 8.5499 1.0000
52.7800 4.3777 1.0000
52.8400 8.6619 1.0000
52.9000 6.2358 1.0000
52.9600 12.6924 1.0000
53.0200 2.8956 1.0000
53.0800 2.2950 1.0000
53.1400 7.6896 1.0000
53.2000 7.9739 1.0000
53.2600 5.4516 1.0000
53.3200 2.2745 1.0000
53.3800 5.6416 1.0000
53.4400 6.1392 1.0000
53.5000 6.5070 1.0000
53.5600 2.5479 1.0000
53.6200 5.0540 1.0000
53.6800 5.2656 1.0000
53.7400 8.1590 1.0000
53.8000 6.3143 1.0000
53.8600 3.8650 1.0000
53.9200 5.0364 1.0000
53.9800 5.1373 1.0000
54.0400 6.1070 1.0000
54.1000 4.7944 1.0000
54.1600 8.4931 1.0000
54.2200 7.5294 1.0000
54.2800 7.7770 1.0000
54.3400 11.1574 1.0000
54.4000 10.2820 1.0000
54.4600 8.1397 1.0000
54.5200 5.5318 1.0000
54.5800 9.0547 1.0000
54.6400 5.0754 1.0000
54.7000 4.4080 1.0000
54.7600 3.8041 1.0000
54.8200 10.1817 1.0000
54.8800 5.5322 1.0000
54.9400 4.2627 1.0000
55.0000 6.4190 1.0000
55.0600 6.5406 1.0000
55.1200 11.1129 1.0000
55.1800 5.9287 1.0000
55.2400 4.4022 1.0000
55.3000 8.7358 1.0000
55.3600 4.5531 1.0000
55.4200 6.1553 1.0000
55.4800 4.5623 1.0000
55.5400 7.3748 1.0000
55.6000 2.4919 1.0000
55.6600 7.4240 1.0000
55.7200 5.2971 1.0000
55.7800 9.0881 1.0000
55.8400 2.0997 1.0000
55.9000 4.9744 1.0000
55.9600 2.7599 1.0000
56.0200 6.4733 1.0000
56.0800 9.8951 1.0000
56.1400 7.5738 1.0000
56.2000 6.7107 1.0000
56.2600 5.3209 1.0000
56.3200 3.9500 1.0000
56.3800 4.1104 1.0000
56.4400 5.6062 1.0000
56.5000 6.8535 1.0000
56.5600 7.8922 1.0000
56.6200 8.4179 1.0000
56.6800 6.3073 1.0000
56.7400 10.5537 1.0000
56.8000 6.1158 1.0000
56.8600 6.5669 1.0000
56.9200 8.8316 1.0000
56.9800 10.0676 1.0000
57.0400 7.4514 1.0000
57.1000 6.2100 1.0000
57.1600 6.7957 1.0000
57.2200 6.2302 1.0000
57.2800 9.7209 1.0000
57.3400 2.2352 1.0000
57.4000 3.7069 1.0000
57.4600 6.5422 1.0000
57.5200 3.5711 1.0000
57.5800 5.7329 1.0000
57.6400 7.0226 1.0000
57.7000 8.1485 1.0000
57.7600 6.1332 1.0000
57.8200 5.5844 1.0000
57.8800 7.5695 1.0000
57.9400 5.5072 1.0000
58.0000 5.1558 1.0000
58.0600 3.1068 1.0000
58.1200 4.7655 1.0000
58.1800 7.8994 1.0000
58.2400 10.6201 1.0000
58.3000 3.3384 1.0000
58.3600 6.0963 1.0000
58.4200 3.8058 1.0000
58.4800 5.7574 1.0000
58.5400 4.0787 1.0000
58.6000 4.9853 1.0000
58.6600 6.2615 1.0000
58.7200 4.8559 1.0000
58.7800 4.0961 1.0000
58.8400 8.4025 1.0000
58.9000 6.4296 1.0000
58.9600 7.7831 1.0000
59.0200 5.1076 1.0000
59.0800 9.9464 1.0000
59.1400 9.7025 1.0000
59.2000 14.2877 1.0000
59.2600 5.8318 1.0000
59.3200 5.1283 1.0000
59.3800 7.4510 1.0000
59.4400 11.1970 1.0000
59.5000 8.4271 1.0000
59.5600 10.6562 1.0000
59.6200 10.4653 1.0000
59.6800 12.4154 1.0000
59.7400 7.4362 1.0000
59.8000 6.1240 1.0000
59.8600 9.4963 1.0000
59.9200 6.5368 1.0000
59.9800 6.9449 1.0000
60.0400 5.9576 1.0000
60.1000 7.3454 1.0000
60.1600 5.0345 1.0000
60.2200 10.2617 1.0000
60.2800 7.5994 1.0000
60.3400 9.0152 1.0000
60.4000 4.2051 1.0000
60.4600 3.6346 1.0000
60.5200 4.3006 1.0000
60.5800 5.0352 1.0000
60.6400 7.1103 1.0000
60.7000 9.0468 1.0000
60.7600 4.8619 1.0000
60.8200 11.7384 1.0000
60.8800 5.2276 1.0000
60.9400 14.7345 1.0000
61.0000 4.3843 1.0000
61.0600 3.3118 1.0000
61.1200 5.1652 1.0000
61.1800 12.0861 1.0000
61.2400 7.4789 1.0000
61.3000 9.0661 1.0000
61.3600 3.7352 1.0000
61.4200 5.3178 1.0000
61.4800 9.0576 1.0000
61.5400 2.8752 1.0000
61.6000 7.5009 1.0000
61.6600 5.0257 1.0000
61.7200 10.4107 1.0000
61.7800 5.8893 1.0000
61.8400 9.2140 1.0000
61.9000 9.4699 1.0000
61.9600 6.3640 1.0000
62.0200 11.8721 1.0000
62.0800 4.0819 1.0000
62.1400 7.8480 1.0000
62.2000 8.3801 1.0000
62.2600 3.4748 1.0000
62.3200 7.9739 1.0000
62.3800 6.5677 1.0000
62.4400 5.5721 1.0000
62.5000 11.6768 1.0000
62.5600 11.9747 1.0000
62.6200 9.0274 1.0000
62.6800 5.8993 1.0000
62.7400 7.7728 1.0000
62.8000 12.1001 1.0000
62.8600 8.4397 1.0000
62.9200 7.0551 1.0000
62.9800 5.7301 1.0000
63.0400 5.2884 1.0000
63.1000 5.7932 1.0000
63.1600 6.1282 1.0000
63.2200 7.2684 1.0000
63.2800 4.9249 1.0000
63.3400 3.8728 1.0000
63.4000 5.8844 1.0000
63.4600 4.1192 1.0000
63.5200 6.2859 1.0000
63.5800 5.3749 1.0000
63.6400 5.0764 1.0000
63.7000 4.5142 1.0000
63.7600 4.2287 1.0000
63.8200 7.4137 1.0000
63.8800 5.4495 1.0000
63.9400 6.6202 1.0000
64.0000 10.3115 1.0000
64.0600 5.8039 1.0000
64.1200 5.7388 1.0000
64.1800 10.3074 1.0000
64.2400 3.0722 1.0000
64.3000 4.6765 1.0000
64.3600 12.6264 1.0000
64.4200 9.2056 1.0000
64.4800 9.6775 1.0000
64.5400 14.9551 1.0000
64.6000 12.1103 1.0000
64.6600 16.6691 1.0000
64.7200 18.5853 1.0000
64.7800 12.5798 1.0000
64.8400 19.4086 1.0000
64.9000 21.4741 1.0000
64.9600 11.0666 1.0000
65.0200 12.0877 1.0000
65.0800 10.2713 1.0000
65.1400 8.2520 1.0000
65.2000 5.1732 1.0000
65.2600 2.2021 1.0000
65.3200 9.2923 1.0000
65.3800 7.9938 1.0000
65.4400 7.4966 1.0000
65.5000 2.8448 1.0000
65.5600 6.3087 1.0000
65.6200 9.3283 1.0000
65.6800 6.0158 1.0000
65.7400 8.1937 1.0000
65.8000 8.1143 1.0000
65.8600 9.4747 1.0000
65.9200 4.6248 1.0000
65.9800 7.4458 1.0000
66.0400 5.7499 1.0000
66.1000 4.7816 1.0000
66.1600 3.6586 1.0000
66.2200 6.1092 1.0000
66.2800 7.8481 1.0000
66.3400 6.4793 1.0000
66.4000 6.0259 1.0000
66.4600 5.4029 1.0000
66.5200 2.2136 1.0000
66.5800 4.2871 1.0000
66.6400 3.2096 1.0000
66.7000 6.3824 1.0000
66.7600 6.7938 1.0000
66.8200 8.7106 1.0000
66.8800 4.9135 1.0000
66.9400 3.6526 1.0000
67.0000 2.4924 1.0000
67.0600 9.6215 1.0000
67.1200 4.0126 1.0000
67.1800 8.0591 1.0000
67.2400 4.0888 1.0000
67.3000 4.8773 1.0000
67.3600 6.7208 1.0000
67.4200 4.2447 1.0000
67.4800 6.9369 1.0000
67.5400 4.5583 1.0000
67.6000 5.2513 1.0000
67.6600 11.4205 1.0000
67.7200 7.7705 1.0000
67.7800 5.7472 1.0000
67.8400 8.4950 1.0000
67.9000 9.1894 1.0000
67.9600 5.1063 1.0000
68.0200 4.1410 1.0000
68.0800 8.2105 1.0000
68.1400 5.9135 1.0000
68.2000 4.5000 1.0000
68.2600 6.4401 1.0000
68.3200 4.4150 1.0000
68.3800 5.1862 1.0000
68.4400 10.2652 1.0000
68.5000 9.3283 1.0000
68.5600 10.9451 1.0000
68.6200 3.4068 1.0000
68.6800 3.6019 1.0000
68.7400 6.9398 1.0000
68.8000 5.1088 1.0000
68.8600 4.7567 1.0000
68.9200 8.5262 1.0000
68.9800 7.1573 1.0000
69.0400 4.4005 1.0000
69.1000 4.1340 1.0000
69.1600 7.0982 1.0000
69.2200 9.6931 1.0000
69.2800 5.8665 1.0000
69.3400 3.5233 1.0000
69.4000 4.9791 1.0000
69.4600 3.3437 1.0000
69.5200 5.5875 1.0000
69.5800 6.8212 1.0000
69.6400 4.4709 1.0000
69.7000 4.1350 1.0000
69.7600 6.0762 1.0000
69.8200 5.1807 1.0000
69.8800 6.6578 1.0000
69.9400 6.9456 1.0000
70.0000 5.0923 1.0000
70.0600 8.6811 1.0000
70.1200 2.5039 1.0000
70.1800 7.7808 1.0000
70.2400 5.2809 1.0000
70.3000 8.3203 1.0000
70.3600 7.9836 1.0000
70.4200 6.2052 1.0000
70.4800 3.5654 1.0000
70.5400 6.5575 1.0000
70.6000 8.4963 1.0000
70.6600 4.1011 1.0000
70.7200 11.5243 1.0000
70.7800 14.6466 1.0000
70.8400 4.5855 1.0000
70.9000 6.6043 1.0000
70.9600 5.0717 1.0000
71.0200 6.5010 1.0000
71.0800 6.7400 1.0000
71.1400 7.1436 1.0000
71.2000 4.6532 1.0000
71.2600 4.7581 1.0000
71.3200 7.8590 1.0000
71.3800 5.5336 1.0000
71.4400 4.7049 1.0000
71.5000 11.4318 1.0000
71.5600 15.5619 1.0000
71.6200 8.8748 1.0000
71.6800 8.3716 1.0000
71.7400 6.2356 1.0000
71.8000 7.8542 1.0000
71.8600 7.0591 1.0000
71.9200 10.0305 1.0000
71.9800 2.9205 1.0000
72.0400 11.3560 1.0000
72.1000 1.5648 1.0000
72.1600 7.6968 1.0000
72.2200 10.7823 1.0000
72.2800 2.0193 1.0000
72.3400 5.3918 1.0000
72.4000 3.4584 1.0000
72.4600 4.6912 1.0000
72.5200 4.8171 1.0000
72.5800 10.6920 1.0000
72.6400 6.4547 1.0000
72.7000 8.2233 1.0000
72.7600 2.1125 1.0000
72.8200 4.6679 1.0000
72.8800 2.8191 1.0000
72.9400 7.5360 1.0000
73.0000 6.3079 1.0000
73.0600 0.9442 1.0000
73.1200 7.5612 1.0000
73.1800 3.8844 1.0000
73.2400 4.5690 1.0000
73.3000 8.7007 1.0000
73.3600 14.9249 1.0000
73.4200 5.2776 1.0000
73.4800 3.6950 1.0000
73.5400 6.5383 1.0000
73.6000 7.5722 1.0000
73.6600 6.1342 1.0000
73.7200 3.2533 1.0000
73.7800 3.4074 1.0000
73.8400 5.4231 1.0000
73.9000 4.7733 1.0000
73.9600 10.0519 1.0000
74.0200 5.7147 1.0000
74.0800 6.5177 1.0000
74.1400 5.5923 1.0000
74.2000 8.6377 1.0000
74.2600 5.0981 1.0000
74.3200 6.4415 1.0000
74.3800 9.1915 1.0000
74.4400 9.0377 1.0000
74.5000 8.6189 1.0000
74.5600 2.4070 1.0000
74.6200 1.8720 1.0000
74.6800 9.7509 1.0000
74.7400 11.1643 1.0000
74.8000 5.2449 1.0000
74.8600 6.7928 1.0000
74.9200 7.9018 1.0000
74.9800 3.9617 1.0000
75.0400 6.0208 1.0000
75.1000 6.8632 1.0000
75.1600 1.5927 1.0000
75.2200 5.0741 1.0000
75.2800 11.3281 1.0000
75.3400 10.8550 1.0000
75.4000 8.9955 1.0000
75.4600 5.9028 1.0000
75.5200 5.0198 1.0000
75.5800 14.2956 1.0000
75.6400 9.7401 1.0000
75.7000 3.9974 1.0000
75.7600 3.3833 1.0000
75.8200 8.2177 1.0000
75.8800 11.9664 1.0000
75.9400 6.6827 1.0000
76.0000 6.6480 1.0000
76.0600 6.1420 1.0000
76.1200 6.4128 1.0000
76.1800 6.3301 1.0000
76.2400 12.1390 1.0000
76.3000 11.3599 1.0000
76.3600 7.2136 1.0000
76.4200 7.8182 1.0000
76.4800 2.0486 1.0000
76.5400 5.8922 1.0000
76.6000 5.2788 1.0000
76.6600 4.1290 1.0000
76.7200 5.9962 1.0000
76.7800 5.4115 1.0000
76.8400 9.1779 1.0000
76.9000 9.7781 1.0000
76.9600 5.4186 1.0000
77.0200 6.1758 1.0000
77.0800 4.1706 1.0000
77.1400 10.1557 1.0000
77.2000 10.9260 1.0000
77.2600 5.0802 1.0000
77.3200 6.7172 1.0000
77.3800 6.0718 1.0000
77.4400 5.5011 1.0000
77.5000 6.3244 1.0000
77.5600 5.3623 1.0000
77.6200 3.0452 1.0000
77.6800 10.6640 1.0000
77.7400 5.0780 1.0000
77.8000 6.6320 1.0000
77.8600 6.2115 1.0000
77.9200 9.6443 1.0000
77.9800 4.4459 1.0000
78.0400 6.1987 1.0000
78.1000 8.0312 1.0000
78.1600 9.7742 1.0000
78.2200 7.7681 1.0000
78.2800 4.5541 1.0000
78.3400 4.0845 1.0000
78.4000 14.1024 1.0000
78.4600 6.7430 1.0000
78.5200 9.3191 1.0000
78.5800 4.5861 1.0000
78.6400 7.8746 1.0000
78.7000 4.3803 1.0000
78.7600 11.4161 1.0000
78.8200 2.1920 1.0000
78.8800 12.9533 1.0000
78.9400 6.6476 1.0000
79.0000 8.2592 1.0000
79.0600 3.5441 1.0000
79.1200 7.2908 1.0000
79.1800 5.6234 1.0000
79.2400 6.6278 1.0000
79.3000 14.8700 1.0000
79.3600 4.2015 1.0000
79.4200 4.5991 1.0000
79.4800 3.1075 1.0000
79.5400 5.2585 1.0000
79.6000 5.1905 1.0000
79.6600 1.2001 1.0000
79.7200 5.0605 1.0000
79.7800 5.6269 1.0000
79.8400 4.8932 1.0000
79.9000 6.6819 1.0000
79.9600 13.9144 1.0000
80.0200 5.8515 1.0000
80.0800 11.9133 1.0000
80.1400 8.9567 1.0000
80.2000 12.2090 1.0000
80.2600 12.5958 1.0000
80.3200 4.5942 1.0000
80.3800 1.6379 1.0000
80.4400 2.6619 1.0000
80.5000 10.1303 1.0000
80.5600 2.4113 1.0000
80.6200 9.2460 1.0000
80.6800 7.6983 1.0000
80.7400 2.4619 1.0000
80.8000 4.8544 1.0000
80.8600 5.2310 1.0000
80.9200 4.8348 1.0000
80.9800 6.0617 1.0000
81.0400 6.2448 1.0000
81.1000 7.0065 1.0000
81.1600 7.2753 1.0000
81.2200 8.1273 1.0000
81.2800 7.0708 1.0000
81.3400 8.9853 1.0000
81.4000 6.3569 1.0000
81.4600 10.1222 1.0000
81.5200 6.7892 1.0000
81.5800 3.0644 1.0000
81.6400 3.7588 1.0000
81.7000 15.3102 1.0000
81.7600 12.1565 1.0000
81.8200 13.2162 1.0000
81.8800 12.9517 1.0000
81.9400 24.5886 1.0000
82.0000 16.7053 1.0000
82.0600 24.7659 1.0000
82.1200 24.4163 1.0000
82.1800 25.2382 1.0000
82.2400 18.0136 1.0000
82.3000 19.5701 1.0000
82.3600 18.0197 1.0000
82.4200 15.2448 1.0000
82.4800 8.3593 1.0000
82.5400 9.0217 1.0000
82.6000 6.7784 1.0000
82.6600 7.4657 1.0000
82.7200 8.1601 1.0000
82.7800 6.2752 1.0000
82.8400 6.7645 1.0000
82.9000 9.9426 1.0000
82.9600 6.1863 1.0000
83.0200 6.0614 1.0000
83.0800 8.8911 1.0000
83.1400 10.3841 1.0000
83.2000 5.4325 1.0000
83.2600 6.6323 1.0000
83.3200 8.1748 1.0000
83.3800 8.4025 1.0000
83.4400 6.8958 1.0000
83.5000 7.4909 1.0000
83.5600 6.7460 1.0000
83.6200 6.6431 1.0000
83.6800 7.1659 1.0000
83.7400 10.7509 1.0000
83.8000 7.4576 1.0000
83.8600 7.3366 1.0000
83.9200 6.2743 1.0000
83.9800 2.9934 1.0000
84.0400 7.0811 1.0000
84.1000 1.9611 1.0000
84.1600 2.8004 1.0000
84.2200 3.2455 1.0000
84.2800 11.3322 1.0000
84.3400 3.2061 1.0000
84.4000 6.9032 1.0000
84.4600 12.4358 1.0000
84.5200 7.5520 1.0000
84.5800 7.6065 1.0000
84.6400 11.2454 1.0000
84.7000 5.6868 1.0000
84.7600 5.1446 1.0000
84.8200 6.0202 1.0000
84.8800 12.6769 1.0000
84.9400 4.7968 1.0000
85.0000 4.0969 1.0000
85.0600 3.0074 1.0000
85.1200 5.1908 1.0000
85.1800 4.3245 1.0000
85.2400 2.6308 1.0000
85.3000 1.9677 1.0000
85.3600 8.4643 1.0000
85.4200 4.7160 1.0000
85.4800 4.8367 1.0000
85.5400 3.6037 1.0000
85.6000 7.9735 1.0000
85.6600 3.9028 1.0000
85.7200 3.4236 1.0000
85.7800 8.3068 1.0000
85.8400 7.7405 1.0000
85.9000 6.9488 1.0000
85.9600 11.5041 1.0000
86.0200 3.1609 1.0000
86.0800 7.6386 1.0000
86.1400 8.1788 1.0000
86.2000 7.2266 1.0000
86.2600 6.8655 1.0000
86.3200 6.5863 1.0000
86.3800 1.0178 1.0000
86.4400 9.8463 1.0000
86.5000 5.8415 1.0000
86.5600 2.2954 1.0000
86.6200 9.0362 1.0000
86.6800 7.3044 1.0000
86.7400 10.9347 1.0000
86.8000 3.2452 1.0000
86.8600 6.5142 1.0000
86.9200 3.6736 1.0000
86.9800 1.4494 1.0000
87.0400 8.5012 1.0000
87.1000 5.0540 1.0000
87.1600 7.4897 1.0000
87.2200 7.9708 1.0000
87.2800 12.2597 1.0000
87.3400 7.5956 1.0000
87.4000 9.1045 1.0000
87.4600 7.7463 1.0000
87.5200 2.5185 1.0000
87.5800 8.3007 1.0000
87.6400 7.0507 1.0000
87.7000 3.2900 1.0000
87.7600 9.6218 1.0000
87.8200 6.1935 1.0000
87.8800 6.4129 1.0000
87.9400 7.5120 1.0000
88.0000 9.8005 1.0000
88.0600 5.2282 1.0000
88.1200 10.4979 1.0000
88.1800 9.0368 1.0000
88.2400 9.3986 1.0000
88.3000 5.1565 1.0000
88.3600 5.4773 1.0000
88.4200 6.0895 1.0000
88.4800 2.8491 1.0000
88.5400 6.8237 1.0000
88.6000 7.2359 1.0000
88.6600 4.6194 1.0000
88.7200 5.0360 1.0000
88.7800 5.2797 1.0000
88.8400 6.2216 1.0000
88.9000 6.3926 1.0000
88.9600 6.2879 1.0000
89.0200 10.4510 1.0000
89.0800 6.2409 1.0000
89.1400 3.1750 1.0000
89.2000 5.3272 1.0000
89.2600 4.6214 1.0000
89.3200 6.4115 1.0000
89.3800 6.7499 1.0000
89.4400 6.5173 1.0000
89.5000 6.0813 1.0000
89.5600 4.5641 1.0000
89.6200 5.2288 1.0000
89.6800 4.3658 1.0000
89.7400 6.5855 1.0000
89.8000 6.0331 1.0000
89.8600 4.7117 1.0000
89.9200 6.3199 1.0000
89.9800 5.0392 1.0000
90.0400 6.0945 1.0000
90.1000 3.7612 1.0000
90.1600 3.1840 1.0000
90.2200 5.6880 1.0000
90.2800 6.0924 1.0000
90.3400 8.5319 1.0000
90.4000 4.6148 1.0000
90.4600 5.7555 1.0000
90.5200 6.5526 1.0000
90.5800 7.4283 1.0000
90.6400 8.0596 1.0000
90.7000 3.2384 1.0000
90.7600 8.7487 1.0000
90.8200 3.8803 1.0000
90.8800 3.8143 1.0000
90.9400 5.0346 1.0000
91.0000 4.9332 1.0000
91.0600 2.1112 1.0000
91.1200 6.3350 1.0000
91.1800 4.8532 1.0000
91.2400 2.5360 1.0000
91.3000 9.5461 1.0000
91.3600 8.9063 1.0000
91.4200 6.5971 1.0000
91.4800 6.9528 1.0000
91.5400 3.2170 1.0000
91.6000 3.5843 1.0000
91.6600 8.2835 1.0000
91.7200 5.6902 1.0000
91.7800 2.0409 1.0000
91.8400 1.9033 1.0000
91.9000 6.6279 1.0000
91.9600 4.4150 1.0000
92.0200 5.2368 1.0000
92.0800 6.3054 1.0000
92.1400 4.3250 1.0000
92.2000 7.7673 1.0000
92.2600 3.0670 1.0000
92.3200 4.0090 1.0000
92.3800 5.3049 1.0000
92.4400 2.0517 1.0000
92.5000 5.5244 1.0000
92.5600 6.2689 1.0000
92.6200 6.1550 1.0000
92.6800 6.0694 1.0000
92.7400 2.4548 1.0000
92.8000 5.7569 1.0000
92.8600 5.7700 1.0000
92.9200 2.2842 1.0000
92.9800 5.3658 1.0000
93.0400 4.1637 1.0000
93.1000 7.5717 1.0000
93.1600 3.7595 1.0000
93.2200 5.6167 1.0000
93.2800 6.7891 1.0000
93.3400 5.2127 1.0000
93.4000 12.2505 1.0000
93.4600 7.3177 1.0000
93.5200 8.1399 1.0000
93.5800 3.6992 1.0000
93.6400 8.8606 1.0000
93.7000 7.3679 1.0000
93.7600 6.1147 1.0000
93.8200 5.2154 1.0000
93.8800 3.7731 1.0000
93.9400 1.3958 1.0000
94.0000 5.7193 1.0000
94.0600 6.8757 1.0000
94.1200 7.2047 1.0000
94.1800 8.2282 1.0000
94.2400 3.5823 1.0000
94.3000 3.2057 1.0000
94.3600 2.6866 1.0000
94.4200 2.2915 1.0000
94.4800 13.2864 1.0000
94.5400 5.5135 1.0000
94.6000 8.0360 1.0000
94.6600 7.3666 1.0000
94.7200 6.3066 1.0000
94.7800 5.4992 1.0000
94.8400 3.9801 1.0000
94.9000 4.4748 1.0000
94.9600 1.9647 1.0000
95.0200 8.1788 1.0000
95.0800 5.8001 1.0000
95.1400 4.0208 1.0000
95.2000 7.3137 1.0000
95.2600 6.3326 1.0000
95.3200 3.9475 1.0000
95.3800 5.4574 1.0000
95.4400 7.9865 1.0000
95.5000 4.5681 1.0000
95.5600 4.9772 1.0000
95.6200 4.7330 1.0000
95.6800 5.3283 1.0000
95.7400 3.1966 1.0000
95.8000 5.7147 1.0000
95.8600 9.2053 1.0000
95.9200 3.0180 1.0000
95.9800 7.1391 1.0000
96.0400 9.7173 1.0000
96.1000 5.8902 1.0000
96.1600 5.1893 1.0000
96.2200 16.9315 1.0000
96.2800 4.8931 1.0000
96.3400 8.3496 1.0000
96.4000 4.0561 1.0000
96.4600 6.5623 1.0000
96.5200 4.2239 1.0000
96.5800 7.2589 1.0000
96.6400 3.9614 1.0000
96.7000 6.5142 1.0000
96.7600 3.7554 1.0000
96.8200 3.7026 1.0000
96.8800 8.1667 1.0000
96.9400 6.0645 1.0000
97.0000 7.8032 1.0000
97.0600 9.2068 1.0000
97.1200 10.0251 1.0000
97.1800 6.2274 1.0000
97.2400 8.0402 1.0000
97.3000 3.8687 1.0000
97.3600 9.3759 1.0000
97.4200 7.1723 1.0000
97.4800 7.4852 1.0000
97.5400 3.5504 1.0000
97.6000 5.1215 1.0000
97.6600 2.9750 1.0000
97.7200 7.6414 1.0000
97.7800 7.7476 1.0000
97.8400 10.2619 1.0000
97.9000 7.0478 1.0000
97.9600 3.3662 1.0000
98.0200 4.7400 1.0000
98.0800 6.9469 1.0000
98.1400 11.8577 1.0000
98.2000 4.8286 1.0000
98.2600 6.6091 1.0000
98.3200 9.4845 1.0000
98.3800 8.2836 1.0000
98.4400 12.4388 1.0000
98.5000 13.1745 1.0000
98.5600 14.4098 1.0000
98.6200 21.9890 1.0000
98.6800 10.3196 1.0000
98.7400 14.8989 1.0000
98.8000 10.8458 1.0000
98.8600 8.8197 1.0000
98.9200 14.2299 1.0000
98.9800 8.2546 1.0000
99.0400 12.1554 1.0000
99.1000 6.4574 1.0000
99.1600 8.3359 1.0000
99.2200 9.8171 1.0000
99.2800 10.5428 1.0000
99.3400 7.3801 1.0000
99.4000 4.2232 1.0000
99.4600 10.1194 1.0000
99.5200 5.4357 1.0000
99.5800 8.3012 1.0000
99.6400 10.1663 1.0000
99.7000 10.4748 1.0000
99.7600 6.5813 1.0000
99.8200 4.7311 1.0000
99.8800 6.8147 1.0000
99.9400 6.4762 1.0000
100.0000 10.3276 1.0000
100.0600 8.3703 1.0000
100.1200 6.7809 1.0000
100.1800 4.3347 1.0000
100.2400 3.8120 1.0000
100.3000 8.1094 1.0000
100.3600 3.0674 1.0000
100.4200 12.4078 1.0000
100.4800 4.8714 1.0000
100.5400 4.1572 1.0000
100.6000 9.4422 1.0000
100.6600 9.4479 1.0000
100.7200 9.6858 1.0000
100.7800 4.8766 1.0000
100.8400 5.2535 1.0000
100.9000 8.8500 1.0000
100.9600 5.1985 1.0000
101.0200 6.7515 1.0000
101.0800 4.4746 1.0000
101.1400 5.7537 1.0000
101.2000 4.3898 1.0000
101.2600 4.9159 1.0000
101.3200 5.2792 1.0000
101.3800 3.4812 1.0000
101.4400 4.7860 1.0000
101.5000 7.2719 1.0000
101.5600 8.2915 1.0000
101.6200 4.8665 1.0000
101.6800 6.2149 1.0000
101.7400 6.3087 1.0000
101.8000 3.2452 1.0000
101.8600 9.5557 1.0000
101.9200 7.2040 1.0000
101.9800 5.2522 1.0000
102.0400 7.9001 1.0000
102.1000 4.2230 1.0000
102.1600 7.8631 1.0000
102.2200 4.3396 1.0000
102.2800 6.4907 1.0000
102.3400 6.0533 1.0000
102.4000 9.1232 1.0000
102.4600 6.7088 1.0000
102.5200 10.0182 1.0000
102.5800 7.0499 1.0000
102.6400 10.3403 1.0000
102.7000 3.7420 1.0000
102.7600 3.5197 1.0000
102.8200 4.3127 1.0000
102.8800 4.3239 1.0000
102.9400 3.7124 1.0000
103.0000 4.4241 1.0000
103.0600 10.4325 1.0000
103.1200 6.6547 1.0000
103.1800 8.1763 1.0000
103.2400 4.6063 1.0000
103.3000 9.2226 1.0000
103.3600 8.0258 1.0000
103.4200 7.4118 1.0000
103.4800 6.8974 1.0000
103.5400 6.9576 1.0000
103.6000 5.0992 1.0000
103.6600 8.1362 1.0000
103.7200 5.1026 1.0000
103.7800 1.6907 1.0000
103.8400 2.9462 1.0000
103.9000 4.3861 1.0000
103.9600 6.7271 1.0000
104.0200 3.3804 1.0000
104.0800 6.4225 1.0000
104.1400 6.2345 1.0000
104.2000 8.1463 1.0000
104.2600 7.1899 1.0000
104.3200 6.1774 1.0000
104.3800 3.7103 1.0000
104.4400 4.9764 1.0000
104.5000 1.3603 1.0000
104.5600 7.6404 1.0000
104.6200 9.7138 1.0000
104.6800 4.1603 1.0000
104.7400 6.2858 1.0000
104.8000 3.2258 1.0000
104.8600 7.1882 1.0000
104.9200 3.0205 1.0000
104.9800 6.0611 1.0000
105.0400 6.7001 1.0000
105.1000 3.1503 1.0000
105.1600 7.8496 1.0000
105.2200 10.2712 1.0000
105.2800 5.6450 1.0000
105.3400 5.7087 1.0000
105.4000 3.6480 1.0000
105.4600 4.7118 1.0000
105.5200 7.3575 1.0000
105.5800 1.0634 1.0000
105.6400 2.2904 1.0000
105.7000 4.4600 1.0000
105.7600 2.6872 1.0000
105.8200 10.2825 1.0000
105.8800 2.3409 1.0000
105.9400 5.1947 1.0000
106.0000 3.2059 1.0000
106.0600 7.6929 1.0000
106.1200 6.2395 1.0000
106.1800 7.3694 1.0000
106.2400 6.9820 1.0000
106.3000 3.1954 1.0000
106.3600 5.9891 1.0000
106.4200 4.0793 1.0000
106.4800 4.5228 1.0000
106.5400 9.0782 1.0000
106.6000 5.9359 1.0000
106.6600 5.1712 1.0000
106.7200 6.5520 1.0000
106.7800 3.9887 1.0000
106.8400 3.0831 1.0000
106.9000 7.4459 1.0000
106.9600 5.6129 1.0000
107.0200 8.1443 1.0000
107.0800 11.8779 1.0000
107.1400 4.7715 1.0000
107.2000 4.1947 1.0000
107.2600 5.9640 1.0000
107.3200 8.2874 1.0000
107.3800 8.2232 1.0000
107.4400 8.6147 1.0000
107.5000 4.2615 1.0000
107.5600 6.0595 1.0000
107.6200 6.6937 1.0000
107.6800 7.6328 1.0000
107.7400 4.0127 1.0000
107.8000 8.7064 1.0000
107.8600 6.0656 1.0000
107.9200 1.3415 1.0000
107.9800 7.6110 1.0000
108.0400 7.7100 1.0000
108.1000 11.0340 1.0000
108.1600 3.6905 1.0000
108.2200 7.1096 1.0000
[...]
67.0000 6.3276 1.0000
67.0600 3.0346 1.0000
67.1200 7.9207 1.0000
67.1800 7.3840 1.0000
67.2400 5.3239 1.0000
67.3000 3.2888 1.0000
67.3600 7.7171 1.0000
67.4200 5.8631 1.0000
67.4800 5.2238 1.0000
67.5400 5.7315 1.0000
67.6000 6.5050 1.0000
67.6600 4.5672 1.0000
67.7200 11.5905 1.0000
67.7800 4.8711 1.0000
67.8400 7.3195 1.0000
67.9000 6.2270 1.0000
67.9600 6.0657 1.0000
68.0200 8.1736 1.0000
68.0800 8.9706 1.0000
68.1400 8.7629 1.0000
68.2000 5.6088 1.0000
68.2600 5.5420 1.0000
68.3200 2.8444 1.0000
68.3800 1.8215 1.0000
68.4400 12.1529 1.0000
68.5000 4.3653 1.0000
68.5600 5.3133 1.0000
68.6200 5.2462 1.0000
68.6800 8.7003 1.0000
68.7400 9.0750 1.0000
68.8000 14.5055 1.0000
68.8600 2.2042 1.0000
68.9200 8.1622 1.0000
68.9800 2.2492 1.0000
69.0400 2.7449 1.0000
69.1000 6.3230 1.0000
69.1600 4.7014 1.0000
69.2200 3.9113 1.0000
69.2800 5.7940 1.0000
69.3400 7.3017 1.0000
69.4000 2.5616 1.0000
69.4600 8.9325 1.0000
69.5200 6.7717 1.0000
69.5800 6.4964 1.0000
69.6400 9.5705 1.0000
69.7000 6.9865 1.0000
69.7600 6.0276 1.0000
69.8200 3.2731 1.0000
69.8800 5.2521 1.0000
69.9400 10.7059 1.0000
70.0000 6.3368 1.0000
70.0600 5.4079 1.0000
70.1200 5.9630 1.0000
70.1800 5.9468 1.0000
70.2400 2.5039 1.0000
70.3000 7.0954 1.0000
70.3600 5.3878 1.0000
70.4200 3.9923 1.0000
70.4800 5.4167 1.0000
70.5400 18.6379 1.0000
70.6000 3.9564 1.0000
70.6600 11.0220 1.0000
70.7200 9.9584 1.0000
70.7800 6.0531 1.0000
70.8400 7.3802 1.0000
70.9000 3.4270 1.0000
70.9600 7.4162 1.0000
71.0200 5.3841 1.0000
71.0800 8.2371 1.0000
71.1400 7.5207 1.0000
71.2000 9.2195 1.0000
71.2600 6.9670 1.0000
71.3200 5.2379 1.0000
71.3800 10.0553 1.0000
71.4400 4.4772 1.0000
71.5000 5.8047 1.0000
71.5600 7.6678 1.0000
71.6200 5.2435 1.0000
71.6800 5.7025 1.0000
71.7400 5.3436 1.0000
71.8000 7.8586 1.0000
71.8600 8.2202 1.0000
71.9200 6.4962 1.0000
71.9800 12.2345 1.0000
72.0400 8.3243 1.0000
72.1000 4.5648 1.0000
72.1600 2.4287 1.0000
72.2200 4.4796 1.0000
72.2800 2.9175 1.0000
72.3400 10.0203 1.0000
72.4000 8.9705 1.0000
72.4600 11.4024 1.0000
72.5200 4.1220 1.0000
72.5800 5.2435 1.0000
72.6400 5.6345 1.0000
72.7000 5.8574 1.0000
72.7600 5.7400 1.0000
72.8200 7.4273 1.0000
72.8800 3.2776 1.0000
72.9400 6.4281 1.0000
73.0000 8.2973 1.0000
73.0600 6.1992 1.0000
73.1200 3.7051 1.0000
73.1800 6.9654 1.0000
73.2400 6.1824 1.0000
73.3000 3.8524 1.0000
73.3600 5.4983 1.0000
73.4200 5.3716 1.0000
73.4800 7.7031 1.0000
73.5400 6.3812 1.0000
73.6000 6.9110 1.0000
73.6600 4.2432 1.0000
73.7200 5.2912 1.0000
73.7800 13.0853 1.0000
73.8400 9.7893 1.0000
73.9000 8.8723 1.0000
73.9600 12.2701 1.0000
74.0200 6.7271 1.0000
74.0800 5.3397 1.0000
74.1400 9.4193 1.0000
74.2000 5.8598 1.0000
74.2600 7.2163 1.0000
74.3200 4.2421 1.0000
74.3800 10.2588 1.0000
74.4400 6.3024 1.0000
74.5000 6.7435 1.0000
74.5600 5.3827 1.0000
74.6200 6.7951 1.0000
74.6800 5.0468 1.0000
74.7400 3.8392 1.0000
74.8000 7.3449 1.0000
74.8600 5.5963 1.0000
74.9200 4.7408 1.0000
74.9800 4.9429 1.0000
75.0400 5.5727 1.0000
75.1000 7.1170 1.0000
75.1600 4.9971 1.0000
75.2200 6.3985 1.0000
75.2800 5.7135 1.0000
75.3400 8.8036 1.0000
75.4000 8.5142 1.0000
75.4600 4.6328 1.0000
75.5200 3.6784 1.0000
75.5800 6.8697 1.0000
75.6400 4.1489 1.0000
75.7000 5.2254 1.0000
75.7600 5.1269 1.0000
75.8200 5.2378 1.0000
75.8800 7.2163 1.0000
75.9400 4.7978 1.0000
76.0000 2.5728 1.0000
76.0600 5.1030 1.0000
76.1200 4.6232 1.0000
76.1800 2.2884 1.0000
76.2400 6.2302 1.0000
76.3000 4.6913 1.0000
76.3600 7.5861 1.0000
76.4200 7.3358 1.0000
76.4800 11.2087 1.0000
76.5400 7.5770 1.0000
76.6000 7.2376 1.0000
76.6600 5.2678 1.0000
76.7200 12.8468 1.0000
76.7800 12.9127 1.0000
76.8400 9.5985 1.0000
76.9000 10.2972 1.0000
76.9600 7.8489 1.0000
77.0200 15.5088 1.0000
77.0800 3.5385 1.0000
77.1400 8.1374 1.0000
77.2000 6.2852 1.0000
77.2600 6.0704 1.0000
77.3200 9.9487 1.0000
77.3800 9.3852 1.0000
77.4400 5.2195 1.0000
77.5000 7.0717 1.0000
77.5600 6.6206 1.0000
77.6200 4.0046 1.0000
77.6800 11.0213 1.0000
77.7400 8.8021 1.0000
77.8000 12.8432 1.0000
77.8600 12.0219 1.0000
77.9200 2.2353 1.0000
77.9800 7.5715 1.0000
78.0400 6.0601 1.0000
78.1000 5.8921 1.0000
78.1600 3.1471 1.0000
78.2200 4.1513 1.0000
78.2800 5.3465 1.0000
78.3400 9.4357 1.0000
78.4000 1.2119 1.0000
78.4600 8.8585 1.0000
78.5200 6.0629 1.0000
78.5800 7.4879 1.0000
78.6400 8.2354 1.0000
78.7000 4.3317 1.0000
78.7600 7.1928 1.0000
78.8200 6.3106 1.0000
78.8800 6.6422 1.0000
78.9400 6.3068 1.0000
79.0000 7.9505 1.0000
79.0600 4.8055 1.0000
79.1200 7.5283 1.0000
79.1800 6.6136 1.0000
79.2400 3.3974 1.0000
79.3000 7.1007 1.0000
79.3600 3.1574 1.0000
79.4200 4.6598 1.0000
79.4800 5.1584 1.0000
79.5400 10.1838 1.0000
79.6000 7.8389 1.0000
79.6600 6.7593 1.0000
79.7200 6.8348 1.0000
79.7800 2.6277 1.0000
79.8400 6.2995 1.0000
79.9000 10.9774 1.0000
79.9600 3.7902 1.0000
80.0200 6.4832 1.0000
80.0800 4.1417 1.0000
80.1400 6.8360 1.0000
80.2000 6.3804 1.0000
80.2600 4.9910 1.0000
80.3200 5.8444 1.0000
80.3800 7.6682 1.0000
80.4400 2.8603 1.0000
80.5000 4.7387 1.0000
80.5600 9.9612 1.0000
80.6200 4.9478 1.0000
80.6800 4.7364 1.0000
80.7400 5.0901 1.0000
80.8000 8.0509 1.0000
80.8600 5.7820 1.0000
80.9200 5.2019 1.0000
80.9800 4.6358 1.0000
81.0400 6.2986 1.0000
81.1000 6.0468 1.0000
81.1600 1.1154 1.0000
81.2200 6.3081 1.0000
81.2800 4.7418 1.0000
81.3400 6.9181 1.0000
81.4000 4.1955 1.0000
81.4600 14.0115 1.0000
81.5200 11.6469 1.0000
81.5800 4.9778 1.0000
81.6400 3.7927 1.0000
81.7000 4.9725 1.0000
81.7600 9.4997 1.0000
81.8200 15.8417 1.0000
81.8800 15.1269 1.0000
81.9400 27.3528 1.0000
82.0000 31.8243 1.0000
82.0600 27.2450 1.0000
82.1200 17.6678 1.0000
82.1800 20.2255 1.0000
82.2400 19.1826 1.0000
82.3000 16.3652 1.0000
82.3600 21.2444 1.0000
82.4200 6.9343 1.0000
82.4800 12.4950 1.0000
82.5400 9.4893 1.0000
82.6000 5.4033 1.0000
82.6600 15.9503 1.0000
82.7200 11.8547 1.0000
82.7800 2.7899 1.0000
82.8400 11.1274 1.0000
82.9000 7.0860 1.0000
82.9600 6.8937 1.0000
83.0200 4.6928 1.0000
83.0800 7.1423 1.0000
83.1400 7.9542 1.0000
83.2000 4.6907 1.0000
83.2600 4.0161 1.0000
83.3200 5.8668 1.0000
83.3800 6.5044 1.0000
83.4400 6.1616 1.0000
83.5000 7.6943 1.0000
83.5600 4.4816 1.0000
83.6200 3.1187 1.0000
83.6800 4.3182 1.0000
83.7400 1.8347 1.0000
83.8000 4.4655 1.0000
83.8600 7.1995 1.0000
83.9200 5.7912 1.0000
83.9800 9.1163 1.0000
84.0400 5.6139 1.0000
84.1000 8.5241 1.0000
84.1600 3.8773 1.0000
84.2200 5.0718 1.0000
84.2800 7.5657 1.0000
84.3400 4.5027 1.0000
84.4000 3.0450 1.0000
84.4600 6.8271 1.0000
84.5200 5.5186 1.0000
84.5800 6.0281 1.0000
84.6400 1.9547 1.0000
84.7000 6.8463 1.0000
84.7600 6.5294 1.0000
84.8200 6.4953 1.0000
84.8800 5.0501 1.0000
84.9400 5.1081 1.0000
85.0000 6.3434 1.0000
85.0600 4.3010 1.0000
85.1200 3.6836 1.0000
85.1800 1.9667 1.0000
85.2400 4.3330 1.0000
85.3000 5.7970 1.0000
85.3600 1.0814 1.0000
85.4200 5.4271 1.0000
85.4800 4.6808 1.0000
85.5400 4.5492 1.0000
85.6000 9.5644 1.0000
85.6600 3.4219 1.0000
85.7200 1.2208 1.0000
85.7800 1.2475 1.0000
85.8400 4.8360 1.0000
85.9000 6.6414 1.0000
85.9600 8.7396 1.0000
86.0200 10.1856 1.0000
86.0800 4.5982 1.0000
86.1400 6.0715 1.0000
86.2000 4.3292 1.0000
86.2600 3.8436 1.0000
86.3200 4.2276 1.0000
86.3800 5.1146 1.0000
86.4400 6.0565 1.0000
86.5000 21.8533 1.0000
86.5600 7.5819 1.0000
86.6200 7.8959 1.0000
86.6800 4.1645 1.0000
86.7400 7.5306 1.0000
86.8000 3.8777 1.0000
86.8600 8.0780 1.0000
86.9200 8.4880 1.0000
86.9800 4.8062 1.0000
87.0400 6.8292 1.0000
87.1000 6.3390 1.0000
87.1600 5.9547 1.0000
87.2200 6.4272 1.0000
87.2800 9.8578 1.0000
87.3400 3.4635 1.0000
87.4000 8.3145 1.0000
87.4600 7.5351 1.0000
87.5200 10.5736 1.0000
87.5800 7.3050 1.0000
87.6400 5.2439 1.0000
87.7000 6.1232 1.0000
87.7600 7.8476 1.0000
87.8200 8.3052 1.0000
87.8800 3.4342 1.0000
87.9400 9.4336 1.0000
88.0000 5.5328 1.0000
88.0600 0.5975 1.0000
88.1200 7.8200 1.0000
88.1800 8.4211 1.0000
88.2400 7.3200 1.0000
88.3000 6.0595 1.0000
88.3600 2.9955 1.0000
88.4200 8.7833 1.0000
88.4800 5.9632 1.0000
88.5400 6.6387 1.0000
88.6000 3.3170 1.0000
88.6600 3.2700 1.0000
88.7200 7.5699 1.0000
88.7800 6.2435 1.0000
88.8400 7.9820 1.0000
88.9000 8.9896 1.0000
88.9600 4.1930 1.0000
89.0200 4.1827 1.0000
89.0800 6.4933 1.0000
89.1400 7.6247 1.0000
89.2000 4.1538 1.0000
89.2600 6.7697 1.0000
89.3200 4.4836 1.0000
89.3800 2.0855 1.0000
89.4400 9.2606 1.0000
89.5000 7.2222 1.0000
89.5600 8.4087 1.0000
89.6200 3.7466 1.0000
89.6800 4.5941 1.0000
89.7400 4.3380 1.0000
89.8000 3.7760 1.0000
89.8600 6.0267 1.0000
89.9200 3.9896 1.0000
89.9800 3.4376 1.0000
90.0400 6.0115 1.0000
90.1000 5.7993 1.0000
90.1600 8.6635 1.0000
90.2200 1.7111 1.0000
90.2800 5.1841 1.0000
90.3400 5.7742 1.0000
90.4000 6.5485 1.0000
90.4600 1.9317 1.0000
90.5200 6.9108 1.0000
90.5800 10.0569 1.0000
90.6400 9.3428 1.0000
90.7000 4.2603 1.0000
90.7600 2.1424 1.0000
90.8200 8.7813 1.0000
90.8800 2.8000 1.0000
90.9400 6.8458 1.0000
91.0000 9.2166 1.0000
91.0600 5.4267 1.0000
91.1200 5.3244 1.0000
91.1800 3.0357 1.0000
91.2400 6.5994 1.0000
91.3000 4.5438 1.0000
91.3600 7.7080 1.0000
91.4200 7.5329 1.0000
91.4800 7.5845 1.0000
91.5400 7.2090 1.0000
91.6000 10.6648 1.0000
91.6600 7.2426 1.0000
91.7200 10.8135 1.0000
91.7800 8.6805 1.0000
91.8400 7.4108 1.0000
91.9000 10.9345 1.0000
91.9600 2.4711 1.0000
92.0200 4.7035 1.0000
92.0800 10.5884 1.0000
92.1400 8.2995 1.0000
92.2000 3.0879 1.0000
92.2600 3.7288 1.0000
92.3200 5.2680 1.0000
92.3800 2.2357 1.0000
92.4400 4.7978 1.0000
92.5000 5.3256 1.0000
92.5600 12.5205 1.0000
92.6200 6.0857 1.0000
92.6800 8.5565 1.0000
92.7400 6.3407 1.0000
92.8000 6.3783 1.0000
92.8600 7.9932 1.0000
92.9200 5.2755 1.0000
92.9800 4.7961 1.0000
93.0400 8.4528 1.0000
93.1000 8.8081 1.0000
93.1600 6.2010 1.0000
93.2200 5.3194 1.0000
93.2800 5.2320 1.0000
93.3400 6.4626 1.0000
93.4000 4.9330 1.0000
93.4600 9.7077 1.0000
93.5200 8.9146 1.0000
93.5800 4.7688 1.0000
93.6400 9.1339 1.0000
93.7000 6.4204 1.0000
93.7600 1.8307 1.0000
93.8200 5.0086 1.0000
93.8800 6.4390 1.0000
93.9400 10.5899 1.0000
94.0000 6.5050 1.0000
94.0600 3.0247 1.0000
94.1200 7.3942 1.0000
94.1800 7.0785 1.0000
94.2400 6.8786 1.0000
94.3000 2.5468 1.0000
94.3600 4.3159 1.0000
94.4200 5.7699 1.0000
94.4800 4.5786 1.0000
94.5400 5.9228 1.0000
94.6000 6.9318 1.0000
94.6600 10.2429 1.0000
94.7200 9.2902 1.0000
94.7800 5.4139 1.0000
94.8400 6.0972 1.0000
94.9000 5.5871 1.0000
94.9600 3.9423 1.0000
95.0200 6.2849 1.0000
95.0800 7.3710 1.0000
95.1400 5.0761 1.0000
95.2000 8.9501 1.0000
95.2600 15.4426 1.0000
95.3200 6.6684 1.0000
95.3800 11.2496 1.0000
95.4400 3.5182 1.0000
95.5000 10.8240 1.0000
95.5600 6.0998 1.0000
95.6200 12.5005 1.0000
95.6800 9.5178 1.0000
95.7400 5.5918 1.0000
95.8000 10.3867 1.0000
95.8600 5.7683 1.0000
95.9200 6.4149 1.0000
95.9800 6.2407 1.0000
96.0400 2.8598 1.0000
96.1000 3.1059 1.0000
96.1600 6.5160 1.0000
96.2200 6.1691 1.0000
96.2800 4.0079 1.0000
96.3400 6.9730 1.0000
96.4000 6.8871 1.0000
96.4600 5.4438 1.0000
96.5200 15.0098 1.0000
96.5800 11.0851 1.0000
96.6400 7.5122 1.0000
96.7000 5.8616 1.0000
96.7600 4.8475 1.0000
96.8200 3.1626 1.0000
96.8800 5.9428 1.0000
96.9400 10.2502 1.0000
97.0000 10.5566 1.0000
97.0600 6.3767 1.0000
97.1200 5.8629 1.0000
97.1800 6.8729 1.0000
97.2400 5.9265 1.0000
97.3000 11.8136 1.0000
97.3600 7.4566 1.0000
97.4200 10.5824 1.0000
97.4800 3.3614 1.0000
97.5400 5.7199 1.0000
97.6000 9.7406 1.0000
97.6600 3.3523 1.0000
97.7200 9.8069 1.0000
97.7800 3.3768 1.0000
97.8400 3.9725 1.0000
97.9000 5.9739 1.0000
97.9600 7.9723 1.0000
98.0200 7.0900 1.0000
98.0800 9.8408 1.0000
98.1400 7.9904 1.0000
98.2000 7.5086 1.0000
98.2600 8.3035 1.0000
98.3200 10.5132 1.0000
98.3800 13.2383 1.0000
98.4400 9.3596 1.0000
98.5000 10.8583 1.0000
98.5600 13.3882 1.0000
98.6200 14.0734 1.0000
98.6800 14.5639 1.0000
98.7400 15.4157 1.0000
98.8000 8.4926 1.0000
98.8600 7.2412 1.0000
98.9200 15.0132 1.0000
98.9800 13.1910 1.0000
99.0400 10.2647 1.0000
99.1000 13.3994 1.0000
99.1600 4.1520 1.0000
99.2200 8.9532 1.0000
99.2800 9.2032 1.0000
99.3400 6.4457 1.0000
99.4000 8.0667 1.0000
99.4600 8.8712 1.0000
99.5200 5.2771 1.0000
99.5800 1.9039 1.0000
99.6400 6.5395 1.0000
99.7000 7.1170 1.0000
99.7600 3.9121 1.0000
99.8200 9.6122 1.0000
99.8800 6.7188 1.0000
99.9400 7.6741 1.0000
100.0000 5.0444 1.0000
100.0600 12.9248 1.0000
100.1200 7.0540 1.0000
100.1800 4.4797 1.0000
100.2400 2.6177 1.0000
100.3000 4.1831 1.0000
100.3600 10.6102 1.0000
100.4200 6.7572 1.0000
100.4800 3.6401 1.0000
100.5400 12.3441 1.0000
100.6000 6.4661 1.0000
100.6600 5.0447 1.0000
100.7200 3.8249 1.0000
100.7800 3.4079 1.0000
100.8400 7.3963 1.0000
100.9000 6.6293 1.0000
100.9600 8.4156 1.0000
101.0200 2.9015 1.0000
101.0800 5.6611 1.0000
101.1400 5.0359 1.0000
101.2000 5.1927 1.0000
101.2600 4.8642 1.0000
101.3200 9.3602 1.0000
101.3800 4.1230 1.0000
101.4400 3.9391 1.0000
101.5000 6.2894 1.0000
101.5600 5.7892 1.0000
101.6200 10.3229 1.0000
101.6800 5.0560 1.0000
101.7400 3.7066 1.0000
101.8000 7.5872 1.0000
101.8600 6.5275 1.0000
101.9200 8.3871 1.0000
101.9800 12.2690 1.0000
102.0400 6.8017 1.0000
102.1000 4.8285 1.0000
102.1600 13.2533 1.0000
102.2200 6.0398 1.0000
102.2800 6.8716 1.0000
102.3400 6.1612 1.0000
102.4000 6.6608 1.0000
102.4600 2.2842 1.0000
102.5200 4.2470 1.0000
102.5800 5.4839 1.0000
102.6400 6.2229 1.0000
102.7000 8.6291 1.0000
102.7600 5.0589 1.0000
102.8200 2.3197 1.0000
102.8800 2.4198 1.0000
102.9400 4.3322 1.0000
103.0000 7.8953 1.0000
103.0600 5.9827 1.0000
103.1200 5.3472 1.0000
103.1800 5.3806 1.0000
103.2400 7.3297 1.0000
103.3000 7.3276 1.0000
103.3600 2.2738 1.0000
103.4200 5.7667 1.0000
103.4800 7.1420 1.0000
103.5400 3.6627 1.0000
103.6000 5.9882 1.0000
103.6600 7.7458 1.0000
103.7200 14.1535 1.0000
103.7800 12.0497 1.0000
103.8400 3.7928 1.0000
103.9000 6.9424 1.0000
103.9600 3.6846 1.0000
104.0200 6.3841 1.0000
104.0800 8.7399 1.0000
104.1400 5.9574 1.0000
104.2000 6.2658 1.0000
104.2600 3.0908 1.0000
104.3200 6.6332 1.0000
104.3800 7.5367 1.0000
104.4400 8.6042 1.0000
104.5000 8.9976 1.0000
104.5600 5.2321 1.0000
104.6200 4.2418 1.0000
104.6800 8.2798 1.0000
104.7400 5.2529 1.0000
104.8000 3.8973 1.0000
104.8600 6.3714 1.0000
104.9200 6.5643 1.0000
104.9800 5.3798 1.0000
105.0400 11.4038 1.0000
105.1000 6.3326 1.0000
105.1600 10.0223 1.0000
105.2200 7.0326 1.0000
105.2800 5.1715 1.0000
105.3400 5.1329 1.0000
105.4000 4.0986 1.0000
105.4600 5.7860 1.0000
105.5200 7.4576 1.0000
105.5800 4.2165 1.0000
105.6400 5.7730 1.0000
105.7000 6.8530 1.0000
105.7600 3.7263 1.0000
105.8200 3.6241 1.0000
105.8800 6.5358 1.0000
105.9400 6.2823 1.0000
106.0000 11.8170 1.0000
106.0600 5.3134 1.0000
106.1200 2.2925 1.0000
106.1800 5.7150 1.0000
106.2400 9.9498 1.0000
106.3000 5.6198 1.0000
106.3600 6.4612 1.0000
106.4200 8.3227 1.0000
106.4800 4.4005 1.0000
106.5400 8.0463 1.0000
106.6000 12.6973 1.0000
106.6600 10.1156 1.0000
106.7200 7.4573 1.0000
106.7800 3.3414 1.0000
106.8400 3.8832 1.0000
106.9000 7.4801 1.0000
106.9600 12.3866 1.0000
107.0200 14.7220 1.0000
107.0800 0.7820 1.0000
107.1400 6.3690 1.0000
107.2000 4.8485 1.0000
107.2600 4.5964 1.0000
107.3200 8.1783 1.0000
107.3800 8.8108 1.0000
107.4400 7.1321 1.0000
107.5000 8.4627 1.0000
107.5600 7.5066 1.0000
107.6200 3.5807 1.0000
107.6800 1.8240 1.0000
107.7400 5.5223 1.0000
107.8000 5.2101 1.0000
107.8600 9.7336 1.0000
107.9200 4.4019 1.0000
107.9800 3.2098 1.0000
108.0400 6.0739 1.0000
108.1000 7.8460 1.0000
108.1600 6.3389 1.0000
108.2200 10.3596 1.0000
108.2800 3.3905 1.0000
108.3400 6.8175 1.0000
108.4000 3.2815 1.0000
108.4600 12.2123 1.0000
108.5200 5.3313 1.0000
108.5800 5.9881 1.0000
108.6400 7.7650 1.0000
108.7000 8.3116 1.0000
108.7600 4.9079 1.0000
108.8200 6.7260 1.0000
108.8800 5.3265 1.0000
108.9400 4.8585 1.0000
109.0000 6.8098 1.0000
109.0600 6.1812 1.0000
109.1200 4.2959 1.0000
109.1800 6.6299 1.0000
109.2400 3.1208 1.0000
109.3000 5.9910 1.0000
109.3600 6.2728 1.0000
109.4200 6.5925 1.0000
109.4800 5.1402 1.0000
109.5400 3.2272 1.0000
109.6000 6.2285 1.0000
109.6600 7.3151 1.0000
109.7200 3.8126 1.0000
109.7800 8.9442 1.0000
109.8400 5.1455 1.0000
109.9000 4.5299 1.0000
109.9600 5.4764 1.0000
110.0200 4.7298 1.0000
110.0800 4.5714 1.0000
110.1400 4.7476 1.0000
110.2000 3.0610 1.0000
110.2600 4.9860 1.0000
110.3200 5.3223 1.0000
110.3800 6.5350 1.0000
110.4400 5.4221 1.0000
110.5000 1.2423 1.0000
110.5600 9.9738 1.0000
110.6200 5.9625 1.0000
110.6800 5.1653 1.0000
110.7400 5.6530 1.0000
110.8000 5.8484 1.0000
110.8600 1.5089 1.0000
110.9200 5.4101 1.0000
110.9800 7.2371 1.0000
111.0400 4.5968 1.0000
111.1000 2.4667 1.0000
111.1600 7.2759 1.0000
111.2200 6.4181 1.0000
111.2800 4.4235 1.0000
111.3400 3.1053 1.0000
111.4000 5.1632 1.0000
111.4600 3.0527 1.0000
111.5200 8.3451 1.0000
111.5800 5.4109 1.0000
111.6400 5.8608 1.0000
111.7000 3.1921 1.0000
111.7600 8.8115 1.0000
111.8200 13.4990 1.0000
111.8800 8.1586 1.0000
111.9400 4.7349 1.0000
112.0000 6.8185 1.0000
112.0600 3.7608 1.0000
112.1200 9.5953 1.0000
112.1800 8.9602 1.0000
112.2400 10.4940 1.0000
112.3000 9.1933 1.0000
112.3600 9.1645 1.0000
112.4200 7.3620 1.0000
112.4800 9.2792 1.0000
112.5400 4.6374 1.0000
112.6000 6.7029 1.0000
112.6600 4.2454 1.0000
112.7200 6.3252 1.0000
112.7800 6.1845 1.0000
112.8400 3.0327 1.0000
112.9000 15.5201 1.0000
112.9600 7.7713 1.0000
113.0200 8.2997 1.0000
113.0800 7.4263 1.0000
113.1400 3.1645 1.0000
113.2000 3.9937 1.0000
113.2600 5.4646 1.0000
113.3200 3.5369 1.0000
113.3800 7.4853 1.0000
113.4400 5.4950 1.0000
113.5000 8.4075 1.0000
113.5600 6.7097 1.0000
113.6200 2.0924 1.0000
113.6800 7.1962 1.0000
113.7400 6.9375 1.0000
113.8000 5.8027 1.0000
113.8600 10.5116 1.0000
113.9200 7.6038 1.0000
113.9800 5.2518 1.0000
114.0400 5.6666 1.0000
114.1000 3.2457 1.0000
114.1600 5.4021 1.0000
114.2200 6.6668 1.0000
114.2800 4.8833 1.0000
114.3400 4.5203 1.0000
114.4000 10.4265 1.0000
114.4600 6.0423 1.0000
114.5200 4.5413 1.0000
114.5800 4.6698 1.0000
114.6400 9.7002 1.0000
114.7000 13.1554 1.0000
114.7600 10.6265 1.0000
114.8200 6.7479 1.0000
114.8800 8.4234 1.0000
114.9400 5.6110 1.0000
115.0000 5.7470 1.0000
115.0600 8.2870 1.0000
115.1200 9.7986 1.0000
115.1800 6.9369 1.0000
115.2400 9.3013 1.0000
115.3000 5.0659 1.0000
115.3600 10.8640 1.0000
115.4200 8.1583 1.0000
115.4800 13.4906 1.0000
115.5400 13.8491 1.0000
115.6000 7.9266 1.0000
115.6600 9.7180 1.0000
115.7200 11.9790 1.0000
115.7800 6.3547 1.0000
115.8400 13.2878 1.0000
115.9000 14.8689 1.0000
115.9600 10.7209 1.0000
116.0200 12.7697 1.0000
116.0800 11.1171 1.0000
116.1400 11.5676 1.0000
116.2000 16.4825 1.0000
116.2600 14.5133 1.0000
116.3200 8.0059 1.0000
116.3800 6.4210 1.0000
116.4400 9.3781 1.0000
116.5000 4.2137 1.0000
116.5600 7.2019 1.0000
116.6200 6.4261 1.0000
116.6800 9.6838 1.0000
116.7400 6.1741 1.0000
116.8000 7.8764 1.0000
116.8600 8.3706 1.0000
116.9200 3.8625 1.0000
116.9800 5.8936 1.0000
117.0400 6.4093 1.0000
117.1000 10.7037 1.0000
117.1600 14.2084 1.0000
117.2200 6.5150 1.0000
117.2800 9.0319 1.0000
117.3400 10.1741 1.0000
117.4000 4.8936 1.0000
117.4600 11.1226 1.0000
117.5200 8.2291 1.0000
117.5800 3.7708 1.0000
117.6400 6.4433 1.0000
117.7000 3.3206 1.0000
117.7600 3.1456 1.0000
117.8200 6.1924 1.0000
117.8800 6.3657 1.0000
117.9400 10.4824 1.0000
118.0000 3.6102 1.0000
118.0600 4.7596 1.0000
118.1200 10.3498 1.0000
118.1800 2.4599 1.0000
118.2400 4.1013 1.0000
118.3000 4.4222 1.0000
118.3600 3.6791 1.0000
118.4200 2.6607 1.0000
118.4800 6.0460 1.0000
118.5400 11.5278 1.0000
118.6000 3.4657 1.0000
118.6600 6.2428 1.0000
118.7200 8.2597 1.0000
118.7800 2.8759 1.0000
118.8400 7.6693 1.0000
118.9000 2.9333 1.0000
118.9600 7.0605 1.0000
119.0200 10.2592 1.0000
119.0800 3.2019 1.0000
119.1400 7.7051 1.0000
119.2000 6.5308 1.0000
119.2600 10.9039 1.0000
119.3200 6.0504 1.0000
119.3800 8.1287 1.0000
119.4400 5.9381 1.0000
119.5000 6.8462 1.0000
119.5600 6.4498 1.0000
119.6200 8.1474 1.0000
119.6800 7.4735 1.0000
119.7400 7.7657 1.0000
119.8000 6.0967 1.0000
119.8600 3.2298 1.0000
119.9200 8.5718 1.0000
119.9800 6.9031 1.0000
119.9900 6.1027 1.0000
*RAS_INT_END
*RAS_TEMPERATURE_START
*RAS_TEMPERATURE_END
*RAS_DATA_END