File: XRD/PB_Ge220_2.5SS_500umDS_RS1_Rod_2.5SS_Hypix1D_EFRW3_HAZ_P-irradiated.ras
*RAS_DATA_START
*RAS_HEADER_START
*DISP_FMT_X "%.3f"
*DISP_FMT_Y "%.0f"
*DISP_FULLSCALE "336.5735851618"
*DISP_LINE_COLOR "255.0000000000"
*DISP_LINE_STYLE "0.0000000000"
*DISP_LINE_WIDTH "0.2500000000"
*DISP_NOTE "Collected Data-41"
*DISP_OFFSET_Y "0.0000000000"
*DISP_PEAKSEARCH_UNIT_Y "cps"
*DISP_RANGE_BOTTOM "0.0000000000"
*DISP_RANGE_LEFT "40.0000000000"
*DISP_RANGE_LOGCUTOFF "0.0100000000"
*DISP_RANGE_RIGHT "119.9968000000"
*DISP_RANGE_TOP "336.5735851618"
*DISP_SCALE_MODE_Y "0.0000000000"
*DISP_TAB_NAME "Theta/2-Theta"
*DISP_TITLE_Y "Intensity"
*DISP_UNIT_Y "cps"
*DISP_WINDOW_NAME "MSG_MACROENGINE"
*FILE_COMMENT " "
*FILE_MD5 ""
*FILE_MEMO " "
*FILE_OPERATOR "Administrator"
*FILE_PART_ID "MEAS_KHP2_00061"
*FILE_SAMPLE " "
*FILE_TYPE "RAS_RAW"
*FILE_USERGROUP "System Manager"
*FILE_VERSION "1.0000000000"
*HW_ATTACHMENT_ID "ATT0021"
*HW_ATTACHMENT_NAME "XY-20mm|XY-20mm"
*HW_COUNTER_ID-0 "CUT0041"
*HW_COUNTER_ID-1 "CUT0051"
*HW_COUNTER_ID-2 "CUT0020"
*HW_COUNTER_ID-3 "CSL0021"
*HW_COUNTER_ID-4 "CMC0021"
*HW_COUNTER_NAME-0 "D/teX Ultra 250|D/teX Ultra 250"
*HW_COUNTER_NAME-1 "HyPix 3000(H)|HyPix 3000(H)"
*HW_COUNTER_NAME-2 "None|None"
*HW_COUNTER_NAME-3 "BBM|BBM"
*HW_COUNTER_NAME-4 "検出器モノクロメータ|Detector monochromator"
*HW_COUNTER_SELECT_NAME "HyPix 3000(H)|HyPix 3000(H)"
*HW_GONIOMETER_ID "GON0024"
*HW_GONIOMETER_NAME "SmartLab(In-plane)|SmartLab(In-plane)"
*HW_GONIOMETER_RADIUS-0 "90.0"
*HW_GONIOMETER_RADIUS-1 "114.0"
*HW_GONIOMETER_RADIUS-2 "190.0"
*HW_GONIOMETER_RADIUS-3 "300.0"
*HW_GONIOMETER_RADIUS-4 "187.0"
*HW_GONIOMETER_RADIUS-5 "300.0"
*HW_GONIOMETER_RADIUS-6 "113.0"
*HW_GONIOMETER_RADIUS-7 "331.0"
*HW_I_OPT_ID-0 "CBO0021"
*HW_I_OPT_ID-1 "ICR0021"
*HW_I_OPT_ID-2 "ISL0021"
*HW_I_OPT_ID-3 "ISO0021"
*HW_I_OPT_ID-4 "IAD0021"
*HW_I_OPT_ID-5 "IPR0001"
*HW_I_OPT_NAME-0 "CBOユニット|CBO unit"
*HW_I_OPT_NAME-1 "標準入射光学ユニット|Standard incident optical unit"
*HW_I_OPT_NAME-2 "標準入射スリットボックス|Standard incident slit box"
*HW_I_OPT_NAME-3 "入射平行スリット|Incident parallel slit"
*HW_I_OPT_NAME-4 "長手制限スリット|Length limiting slit"
*HW_I_OPT_NAME-5 "None|None"
*HW_R_ATTENUATER_AUTOMODE "0"
*HW_R_OPT_ID-0 "RSS0022"
*HW_R_OPT_ID-1 "RCR0022"
*HW_R_OPT_ID-2 "RSO0021"
*HW_R_OPT_ID-3 "RRS0022"
*HW_R_OPT_ID-4 "ATN0020"
*HW_R_OPT_ID-5 "RFL0021"
*HW_R_OPT_ID-6 "RAD0021"
*HW_R_OPT_NAME-0 "受光スリットボックス1(Zr軸付)|Receiving slit box # 1 (w/ Zr Axis)"
*HW_R_OPT_NAME-1 "標準受光光学ユニット1|Standard receiving unit # 1"
*HW_R_OPT_NAME-2 "標準受光光学ユニット2|Standard receiving optical unit # 2"
*HW_R_OPT_NAME-3 "仮想受光スリット2|Virtual receiving slit #2"
*HW_R_OPT_NAME-4 "無し|None"
*HW_R_OPT_NAME-5 "Cu Kβ|Cu K-beta"
*HW_R_OPT_NAME-6 "調整用受光スリット|Alignment receiving slit"
*HW_SAMPLE_HOLDER_ID "SMP0021"
*HW_SAMPLE_HOLDER_NAME "χφZクレードル|Chi phi Z cradle"
*HW_XG_CURRENT_MAX "40"
*HW_XG_CURRENT_MIN "2"
*HW_XG_CURRENT_RESOLUTION "1"
*HW_XG_CURRENT_UNIT "mA"
*HW_XG_FOCUS "0.4mm x 8mm"
*HW_XG_FOCUS_TYPE "Fine"
*HW_XG_ID "1200"
*HW_XG_NAME "3kW 封入管(ID:1200)|3kW Sealed tube(ID:1200)"
*HW_XG_TARGET_ATOMIC_NUMBER "29.0000000000"
*HW_XG_TARGET_NAME "Cu"
*HW_XG_TYPE "Hermetic"
*HW_XG_VOLTAGE_MAX "40"
*HW_XG_VOLTAGE_MIN "20"
*HW_XG_VOLTAGE_RESOLUTION "1"
*HW_XG_VOLTAGE_UNIT "kV"
*HW_XG_WATT_MAX "1.500"
*HW_XG_WATT_UNIT "kW"
*HW_XG_WAVE_LENGTH_ALPHA1 "1.540593"
*HW_XG_WAVE_LENGTH_ALPHA2 "1.544414"
*HW_XG_WAVE_LENGTH_BETA "1.392250"
*MEAS_COND_AXIS_NAME-0 "Theta/2-Theta"
*MEAS_COND_AXIS_NAME-1 "2-Theta"
*MEAS_COND_AXIS_NAME-2 "Omega"
*MEAS_COND_AXIS_NAME-3 "Chi"
*MEAS_COND_AXIS_NAME-4 "Phi"
*MEAS_COND_AXIS_NAME-5 "Z"
*MEAS_COND_AXIS_NAME-6 "X"
*MEAS_COND_AXIS_NAME-7 "Y"
*MEAS_COND_AXIS_NAME-8 "2-Theta/Omega"
*MEAS_COND_AXIS_NAME-9 "2-ThetaChi"
*MEAS_COND_AXIS_NAME-10 "2-ThetaChi/Phi"
*MEAS_COND_AXIS_NAME-11 "Alpha"
*MEAS_COND_AXIS_NAME-12 "Beta"
*MEAS_COND_AXIS_NAME-13 "Theta_s"
*MEAS_COND_AXIS_NAME-14 "Theta_d"
*MEAS_COND_AXIS_NAME-15 "Ts"
*MEAS_COND_AXIS_NAME-16 "CBO selection slit"
*MEAS_COND_AXIS_NAME-17 "M"
*MEAS_COND_AXIS_NAME-18 "Incident parallel slit"
*MEAS_COND_AXIS_NAME-19 "Incident slit"
*MEAS_COND_AXIS_NAME-20 ""
*MEAS_COND_AXIS_NAME-21 "Zs"
*MEAS_COND_AXIS_NAME-22 "Incident optical device"
*MEAS_COND_AXIS_NAME-23 "Omega_m"
*MEAS_COND_AXIS_NAME-24 "Length limiting slit"
*MEAS_COND_AXIS_NAME-25 "Center slit"
*MEAS_COND_AXIS_NAME-26 "Filter"
*MEAS_COND_AXIS_NAME-27 "Receiving slit # 1"
*MEAS_COND_AXIS_NAME-28 "Receiving slit # 2"
*MEAS_COND_AXIS_NAME-29 "Receiving optical device"
*MEAS_COND_AXIS_NAME-30 "Receiving parallel slit"
*MEAS_COND_AXIS_NAME-31 "Alignment receiving slit"
*MEAS_COND_AXIS_NAME-32 ""
*MEAS_COND_AXIS_NAME-33 ""
*MEAS_COND_AXIS_NAME-34 "Zd"
*MEAS_COND_AXIS_NAME-35 "Attenuator"
*MEAS_COND_AXIS_NAME-36 "Diffracted beam monochromator"
*MEAS_COND_AXIS_NAME-37 "Monochromator slit"
*MEAS_COND_AXIS_NAME-38 "2-ThetaB"
*MEAS_COND_AXIS_NAME-39 ""
*MEAS_COND_AXIS_NAME-40 ""
*MEAS_COND_AXIS_NAME-41 "Zr"
*MEAS_COND_AXIS_NAME-42 "Primary beam"
*MEAS_COND_AXIS_NAME_INTERNAL-0 "TwoThetaTheta"
*MEAS_COND_AXIS_NAME_INTERNAL-1 "TwoTheta"
*MEAS_COND_AXIS_NAME_INTERNAL-2 "Omega"
*MEAS_COND_AXIS_NAME_INTERNAL-3 "Chi"
*MEAS_COND_AXIS_NAME_INTERNAL-4 "Phi"
*MEAS_COND_AXIS_NAME_INTERNAL-5 "Z"
*MEAS_COND_AXIS_NAME_INTERNAL-6 "X"
*MEAS_COND_AXIS_NAME_INTERNAL-7 "Y"
*MEAS_COND_AXIS_NAME_INTERNAL-8 "TwoThetaOmega"
*MEAS_COND_AXIS_NAME_INTERNAL-9 "TwoThetaChi"
*MEAS_COND_AXIS_NAME_INTERNAL-10 "TwoThetaChiPhi"
*MEAS_COND_AXIS_NAME_INTERNAL-11 "Alpha"
*MEAS_COND_AXIS_NAME_INTERNAL-12 "Beta"
*MEAS_COND_AXIS_NAME_INTERNAL-13 "ThetaS"
*MEAS_COND_AXIS_NAME_INTERNAL-14 "ThetaD"
*MEAS_COND_AXIS_NAME_INTERNAL-15 "Ts"
*MEAS_COND_AXIS_NAME_INTERNAL-16 "CBO"
*MEAS_COND_AXIS_NAME_INTERNAL-17 "CBO-M"
*MEAS_COND_AXIS_NAME_INTERNAL-18 "IncidentSollerSlit"
*MEAS_COND_AXIS_NAME_INTERNAL-19 "IncidentSlitBox"
*MEAS_COND_AXIS_NAME_INTERNAL-20 "IncidentSlitBox-_Axis"
*MEAS_COND_AXIS_NAME_INTERNAL-21 "Zs"
*MEAS_COND_AXIS_NAME_INTERNAL-22 "IncidentMonochromator"
*MEAS_COND_AXIS_NAME_INTERNAL-23 "IncidentMonochromator-OmegaM"
*MEAS_COND_AXIS_NAME_INTERNAL-24 "IncidentAxdSlit"
*MEAS_COND_AXIS_NAME_INTERNAL-25 "CenterSlit"
*MEAS_COND_AXIS_NAME_INTERNAL-26 "Filter"
*MEAS_COND_AXIS_NAME_INTERNAL-27 "ReceivingSlitBox1"
*MEAS_COND_AXIS_NAME_INTERNAL-28 "ReceivingSlitBox2"
*MEAS_COND_AXIS_NAME_INTERNAL-29 "ReceivingOptics"
*MEAS_COND_AXIS_NAME_INTERNAL-30 "ReceivingSollerSlit"
*MEAS_COND_AXIS_NAME_INTERNAL-31 "ReceivingAxdSlit"
*MEAS_COND_AXIS_NAME_INTERNAL-32 "ReceivingSlitBox1-_Axis"
*MEAS_COND_AXIS_NAME_INTERNAL-33 "ReceivingSlitBox2-_Axis"
*MEAS_COND_AXIS_NAME_INTERNAL-34 "ReceivingSlitBox2-Zd"
*MEAS_COND_AXIS_NAME_INTERNAL-35 "Attenuator"
*MEAS_COND_AXIS_NAME_INTERNAL-36 "CounterMonochromator"
*MEAS_COND_AXIS_NAME_INTERNAL-37 "CounterSlit"
*MEAS_COND_AXIS_NAME_INTERNAL-38 "TwoThetaB"
*MEAS_COND_AXIS_NAME_INTERNAL-39 "AlphaR"
*MEAS_COND_AXIS_NAME_INTERNAL-40 "BetaR"
*MEAS_COND_AXIS_NAME_INTERNAL-41 "ReceivingSlitBox1-Zr"
*MEAS_COND_AXIS_NAME_INTERNAL-42 "IncidentPrimary"
*MEAS_COND_AXIS_NAME_MAGICNO-0 "83951616.0000000000"
*MEAS_COND_AXIS_NAME_MAGICNO-1 "268632064.0000000000"
*MEAS_COND_AXIS_NAME_MAGICNO-2 "268500992.0000000000"
*MEAS_COND_AXIS_NAME_MAGICNO-3 "268500992.0000000000"
*MEAS_COND_AXIS_NAME_MAGICNO-4 "268500992.0000000000"
*MEAS_COND_AXIS_NAME_MAGICNO-5 "285278208.0000000000"
*MEAS_COND_AXIS_NAME_MAGICNO-6 "268500992.0000000000"
*MEAS_COND_AXIS_NAME_MAGICNO-7 "268500992.0000000000"
*MEAS_COND_AXIS_NAME_MAGICNO-8 "83951616.0000000000"
*MEAS_COND_AXIS_NAME_MAGICNO-9 "268632064.0000000000"
*MEAS_COND_AXIS_NAME_MAGICNO-10 "83951616.0000000000"
*MEAS_COND_AXIS_NAME_MAGICNO-11 "17039360.0000000000"
*MEAS_COND_AXIS_NAME_MAGICNO-12 "17039360.0000000000"
*MEAS_COND_AXIS_NAME_MAGICNO-13 "131072.0000000000"
*MEAS_COND_AXIS_NAME_MAGICNO-14 "131072.0000000000"
*MEAS_COND_AXIS_NAME_MAGICNO-15 "318898176.0000000000"
*MEAS_COND_AXIS_NAME_MAGICNO-16 "20971521.0000000000"
*MEAS_COND_AXIS_NAME_MAGICNO-17 "285343744.0000000000"
*MEAS_COND_AXIS_NAME_MAGICNO-18 "20971521.0000000000"
*MEAS_COND_AXIS_NAME_MAGICNO-19 "22020097.0000000000"
*MEAS_COND_AXIS_NAME_MAGICNO-20 "25165824.0000000000"
*MEAS_COND_AXIS_NAME_MAGICNO-21 "318898176.0000000000"
*MEAS_COND_AXIS_NAME_MAGICNO-22 "20971521.0000000000"
*MEAS_COND_AXIS_NAME_MAGICNO-23 "285343744.0000000000"
*MEAS_COND_AXIS_NAME_MAGICNO-24 "20971521.0000000000"
*MEAS_COND_AXIS_NAME_MAGICNO-25 "20971521.0000000000"
*MEAS_COND_AXIS_NAME_MAGICNO-26 "20971521.0000000000"
*MEAS_COND_AXIS_NAME_MAGICNO-27 "23068673.0000000000"
*MEAS_COND_AXIS_NAME_MAGICNO-28 "23068673.0000000000"
*MEAS_COND_AXIS_NAME_MAGICNO-29 "20971521.0000000000"
*MEAS_COND_AXIS_NAME_MAGICNO-30 "20971521.0000000000"
*MEAS_COND_AXIS_NAME_MAGICNO-31 "20971521.0000000000"
*MEAS_COND_AXIS_NAME_MAGICNO-32 "25165824.0000000000"
*MEAS_COND_AXIS_NAME_MAGICNO-33 "25165824.0000000000"
*MEAS_COND_AXIS_NAME_MAGICNO-34 "285343744.0000000000"
*MEAS_COND_AXIS_NAME_MAGICNO-35 "0.0000000000"
*MEAS_COND_AXIS_NAME_MAGICNO-36 "20971521.0000000000"
*MEAS_COND_AXIS_NAME_MAGICNO-37 "20971521.0000000000"
*MEAS_COND_AXIS_NAME_MAGICNO-38 "17039360.0000000000"
*MEAS_COND_AXIS_NAME_MAGICNO-39 "8388608.0000000000"
*MEAS_COND_AXIS_NAME_MAGICNO-40 "8388608.0000000000"
*MEAS_COND_AXIS_NAME_MAGICNO-41 "285343744.0000000000"
*MEAS_COND_AXIS_NAME_MAGICNO-42 "20971521.0000000000"
*MEAS_COND_AXIS_OFFSET-0 "-"
*MEAS_COND_AXIS_OFFSET-1 "0.8642000000"
*MEAS_COND_AXIS_OFFSET-2 "1.0640000000"
*MEAS_COND_AXIS_OFFSET-3 "0.0000000000"
*MEAS_COND_AXIS_OFFSET-4 "0.0000000000"
*MEAS_COND_AXIS_OFFSET-5 "-"
*MEAS_COND_AXIS_OFFSET-6 "0.0000000000"
*MEAS_COND_AXIS_OFFSET-7 "0.0000000000"
*MEAS_COND_AXIS_OFFSET-8 "-"
*MEAS_COND_AXIS_OFFSET-9 "0.0000000000"
*MEAS_COND_AXIS_OFFSET-10 "-"
*MEAS_COND_AXIS_OFFSET-11 "-"
*MEAS_COND_AXIS_OFFSET-12 "-"
*MEAS_COND_AXIS_OFFSET-13 "1.0640000000"
*MEAS_COND_AXIS_OFFSET-14 "-0.1998000000"
*MEAS_COND_AXIS_OFFSET-15 "-"
*MEAS_COND_AXIS_OFFSET-16 "-"
*MEAS_COND_AXIS_OFFSET-17 "-"
*MEAS_COND_AXIS_OFFSET-18 "-"
*MEAS_COND_AXIS_OFFSET-19 "-"
*MEAS_COND_AXIS_OFFSET-20 "-"
*MEAS_COND_AXIS_OFFSET-21 "-"
*MEAS_COND_AXIS_OFFSET-22 "-"
*MEAS_COND_AXIS_OFFSET-23 "-"
*MEAS_COND_AXIS_OFFSET-24 "-"
*MEAS_COND_AXIS_OFFSET-25 "-"
*MEAS_COND_AXIS_OFFSET-26 "-"
*MEAS_COND_AXIS_OFFSET-27 "-"
*MEAS_COND_AXIS_OFFSET-28 "-"
*MEAS_COND_AXIS_OFFSET-29 "-"
*MEAS_COND_AXIS_OFFSET-30 "-"
*MEAS_COND_AXIS_OFFSET-31 "-"
*MEAS_COND_AXIS_OFFSET-32 "-"
*MEAS_COND_AXIS_OFFSET-33 "-"
*MEAS_COND_AXIS_OFFSET-34 "-"
*MEAS_COND_AXIS_OFFSET-35 "-"
*MEAS_COND_AXIS_OFFSET-36 "-"
*MEAS_COND_AXIS_OFFSET-37 "-"
*MEAS_COND_AXIS_OFFSET-38 "-"
*MEAS_COND_AXIS_OFFSET-39 "0.0000000000"
*MEAS_COND_AXIS_OFFSET-40 "0.0000000000"
*MEAS_COND_AXIS_OFFSET-41 "-"
*MEAS_COND_AXIS_OFFSET-42 "-"
*MEAS_COND_AXIS_POSITION-0 "40.0000000000"
*MEAS_COND_AXIS_POSITION-1 "40.0000000000"
*MEAS_COND_AXIS_POSITION-2 "20.0000000000"
*MEAS_COND_AXIS_POSITION-3 "0.0000000000"
*MEAS_COND_AXIS_POSITION-4 "0.0000000000"
*MEAS_COND_AXIS_POSITION-5 "-1.7645000000"
*MEAS_COND_AXIS_POSITION-6 "-0.6530000000"
*MEAS_COND_AXIS_POSITION-7 "-2.6535000000"
*MEAS_COND_AXIS_POSITION-8 "40.0000000000"
*MEAS_COND_AXIS_POSITION-9 "0.0000000000"
*MEAS_COND_AXIS_POSITION-10 "0.0000000000"
*MEAS_COND_AXIS_POSITION-11 "90.0000000000"
*MEAS_COND_AXIS_POSITION-12 "0.0000000000"
*MEAS_COND_AXIS_POSITION-13 "20.0000000000"
*MEAS_COND_AXIS_POSITION-14 "20.0000000000"
*MEAS_COND_AXIS_POSITION-15 "-5.4426900000"
*MEAS_COND_AXIS_POSITION-16 "PB"
*MEAS_COND_AXIS_POSITION-17 "0.0000000000"
*MEAS_COND_AXIS_POSITION-18 "Soller_slit_5.0deg_s"
*MEAS_COND_AXIS_POSITION-19 "1.000mm"
*MEAS_COND_AXIS_POSITION-20 "1.0000000000"
*MEAS_COND_AXIS_POSITION-21 "-1.3487500000"
*MEAS_COND_AXIS_POSITION-22 "Ge(220)x2"
*MEAS_COND_AXIS_POSITION-23 "0.0000000000"
*MEAS_COND_AXIS_POSITION-24 "0.5mm"
*MEAS_COND_AXIS_POSITION-25 "None"
*MEAS_COND_AXIS_POSITION-26 "None"
*MEAS_COND_AXIS_POSITION-27 "20.000mm"
*MEAS_COND_AXIS_POSITION-28 "38.500mm"
*MEAS_COND_AXIS_POSITION-29 "PSA_open"
*MEAS_COND_AXIS_POSITION-30 "Soller_slit_5.0deg"
*MEAS_COND_AXIS_POSITION-31 "None"
*MEAS_COND_AXIS_POSITION-32 "20.0000000000"
*MEAS_COND_AXIS_POSITION-33 "38.5000000000"
*MEAS_COND_AXIS_POSITION-34 "0.0000000000"
*MEAS_COND_AXIS_POSITION-35 "-"
*MEAS_COND_AXIS_POSITION-36 "No_unit"
*MEAS_COND_AXIS_POSITION-37 "None"
*MEAS_COND_AXIS_POSITION-38 "40.0000000000"
*MEAS_COND_AXIS_POSITION-39 "0.0000000000"
*MEAS_COND_AXIS_POSITION-40 "0.0000000000"
*MEAS_COND_AXIS_POSITION-41 "0.2584400000"
*MEAS_COND_AXIS_POSITION-42 "None"
*MEAS_COND_AXIS_UNIT-0 "deg"
*MEAS_COND_AXIS_UNIT-1 "deg"
*MEAS_COND_AXIS_UNIT-2 "deg"
*MEAS_COND_AXIS_UNIT-3 "deg"
*MEAS_COND_AXIS_UNIT-4 "deg"
*MEAS_COND_AXIS_UNIT-5 "mm"
*MEAS_COND_AXIS_UNIT-6 "mm"
*MEAS_COND_AXIS_UNIT-7 "mm"
*MEAS_COND_AXIS_UNIT-8 "deg"
*MEAS_COND_AXIS_UNIT-9 "deg"
*MEAS_COND_AXIS_UNIT-10 "deg"
*MEAS_COND_AXIS_UNIT-11 "deg"
*MEAS_COND_AXIS_UNIT-12 "deg"
*MEAS_COND_AXIS_UNIT-13 "deg"
*MEAS_COND_AXIS_UNIT-14 "deg"
*MEAS_COND_AXIS_UNIT-15 "mm"
*MEAS_COND_AXIS_UNIT-16 ""
*MEAS_COND_AXIS_UNIT-17 "pulse"
*MEAS_COND_AXIS_UNIT-18 ""
*MEAS_COND_AXIS_UNIT-19 ""
*MEAS_COND_AXIS_UNIT-20 "mm"
*MEAS_COND_AXIS_UNIT-21 "mm"
*MEAS_COND_AXIS_UNIT-22 ""
*MEAS_COND_AXIS_UNIT-23 "pulse"
*MEAS_COND_AXIS_UNIT-24 ""
*MEAS_COND_AXIS_UNIT-25 ""
*MEAS_COND_AXIS_UNIT-26 ""
*MEAS_COND_AXIS_UNIT-27 ""
*MEAS_COND_AXIS_UNIT-28 ""
*MEAS_COND_AXIS_UNIT-29 ""
*MEAS_COND_AXIS_UNIT-30 ""
*MEAS_COND_AXIS_UNIT-31 ""
*MEAS_COND_AXIS_UNIT-32 "mm"
*MEAS_COND_AXIS_UNIT-33 "mm"
*MEAS_COND_AXIS_UNIT-34 "mm"
*MEAS_COND_AXIS_UNIT-35 ""
*MEAS_COND_AXIS_UNIT-36 ""
*MEAS_COND_AXIS_UNIT-37 ""
*MEAS_COND_AXIS_UNIT-38 "deg"
*MEAS_COND_AXIS_UNIT-39 "deg"
*MEAS_COND_AXIS_UNIT-40 "deg"
*MEAS_COND_AXIS_UNIT-41 "mm"
*MEAS_COND_AXIS_UNIT-42 ""
*MEAS_COND_COUNTER_CNTLOSS_CORR "0.0000000000"
*MEAS_COND_COUNTER_TAUDIFF "0.0000000000"
*MEAS_COND_COUNTER_TAUINT "0.0000000000"
*MEAS_COND_COUNTER_TEMP_CONDITION "NORMAL"
*MEAS_COND_IRRADIATION_MODE "OFF"
*MEAS_COND_IRRADIATION_WIDTH ""
*MEAS_COND_OPT_ATTR "High resolution parallel beam Ge(220)x2/RS"
*MEAS_COND_OPT_NAME "@High resolution PB-Ge(220)x2"
*MEAS_COND_UNSYMMETRIC_MODE "OFF"
*MEAS_COND_XG_CURRENT "30.0000000000"
*MEAS_COND_XG_VOLTAGE "40.0000000000"
*MEAS_COND_XG_WAVE_TYPE "Ka1"
*MEAS_DATA_COUNT "8000.0000000000"
*MEAS_SCAN_AXIS_X "Theta/2-Theta"
*MEAS_SCAN_AXIS_X_INTERNAL "TwoThetaTheta"
*MEAS_SCAN_END_TIME "05/17/22 09:02:11"
*MEAS_SCAN_MODE "CONTINUOUS"
*MEAS_SCAN_MONITOR "0"
*MEAS_SCAN_RESOLUTION_X "0.0002"
*MEAS_SCAN_SPEED "0.503240"
*MEAS_SCAN_SPEED_UNIT "deg/min"
*MEAS_SCAN_SPEED_USER "0.5"
*MEAS_SCAN_START "40.0000000000"
*MEAS_SCAN_START_TIME "05/17/22 06:07:21"
*MEAS_SCAN_STEP "0.0100000000"
*MEAS_SCAN_STOP "119.9900000000"
*MEAS_SCAN_UNIT_X "deg"
*MEAS_SCAN_UNIT_Y "counts"
*RAS_HEADER_END
*RAS_INT_START
40.0000 9.0026 1.0000
40.0600 5.2020 1.0000
40.1200 10.4819 1.0000
40.1800 8.8969 1.0000
40.2400 6.2560 1.0000
40.3000 5.4456 1.0000
40.3600 9.7012 1.0000
40.4200 8.7075 1.0000
40.4800 6.6523 1.0000
40.5400 6.3934 1.0000
40.6000 6.5594 1.0000
40.6600 9.0561 1.0000
40.7200 9.6082 1.0000
40.7800 3.0348 1.0000
40.8400 8.7806 1.0000
40.9000 4.3428 1.0000
40.9600 6.6413 1.0000
41.0200 7.4178 1.0000
41.0800 14.0323 1.0000
41.1400 12.4429 1.0000
41.2000 5.8401 1.0000
41.2600 9.8614 1.0000
41.3200 6.4319 1.0000
41.3800 6.6617 1.0000
41.4400 6.3238 1.0000
41.5000 14.0029 1.0000
41.5600 6.1061 1.0000
41.6200 7.4408 1.0000
41.6800 8.0716 1.0000
41.7400 6.7100 1.0000
41.8000 7.7232 1.0000
41.8600 5.3573 1.0000
41.9200 2.3691 1.0000
41.9800 6.3953 1.0000
42.0400 7.9116 1.0000
42.1000 14.3262 1.0000
42.1600 3.6805 1.0000
42.2200 8.6858 1.0000
42.2800 8.5630 1.0000
42.3400 5.0097 1.0000
42.4000 4.4871 1.0000
42.4600 6.4478 1.0000
42.5200 6.6536 1.0000
42.5800 3.2928 1.0000
42.6400 3.8862 1.0000
42.7000 7.2000 1.0000
42.7600 4.1396 1.0000
42.8200 5.4078 1.0000
42.8800 5.8588 1.0000
42.9400 10.7977 1.0000
43.0000 6.6441 1.0000
43.0600 6.6655 1.0000
43.1200 6.4100 1.0000
43.1800 9.9945 1.0000
43.2400 7.9442 1.0000
43.3000 10.0794 1.0000
43.3600 4.2090 1.0000
43.4200 11.1829 1.0000
43.4800 13.4804 1.0000
43.5400 5.8328 1.0000
43.6000 4.5573 1.0000
43.6600 7.8775 1.0000
43.7200 12.0201 1.0000
43.7800 5.6866 1.0000
43.8400 2.9214 1.0000
43.9000 11.9344 1.0000
43.9600 13.5167 1.0000
44.0200 13.4229 1.0000
44.0800 7.5057 1.0000
44.1400 6.8172 1.0000
44.2000 13.9204 1.0000
44.2600 20.5808 1.0000
44.3200 30.1845 1.0000
44.3800 66.9150 1.0000
44.4400 161.5496 1.0000
44.5000 255.9615 1.0000
44.5600 261.6912 1.0000
44.6200 145.6472 1.0000
44.6800 56.9099 1.0000
44.7400 30.1492 1.0000
44.8000 15.8955 1.0000
44.8600 11.0417 1.0000
44.9200 2.2618 1.0000
44.9800 7.5389 1.0000
45.0400 11.7706 1.0000
45.1000 6.6136 1.0000
45.1600 8.1886 1.0000
45.2200 5.1208 1.0000
45.2800 8.3189 1.0000
45.3400 6.5577 1.0000
45.4000 8.2612 1.0000
45.4600 7.2584 1.0000
45.5200 6.3684 1.0000
45.5800 7.7581 1.0000
45.6400 7.7338 1.0000
45.7000 3.8184 1.0000
45.7600 7.2015 1.0000
45.8200 6.1245 1.0000
45.8800 5.1575 1.0000
45.9400 6.5791 1.0000
46.0000 4.1404 1.0000
46.0600 5.1026 1.0000
46.1200 4.4374 1.0000
46.1800 9.1266 1.0000
46.2400 8.2776 1.0000
46.3000 2.9522 1.0000
46.3600 6.1486 1.0000
46.4200 1.8341 1.0000
46.4800 3.4283 1.0000
46.5400 10.0195 1.0000
46.6000 8.9152 1.0000
46.6600 7.4436 1.0000
46.7200 4.1812 1.0000
46.7800 10.3274 1.0000
46.8400 6.0062 1.0000
46.9000 3.1328 1.0000
46.9600 5.5548 1.0000
47.0200 9.0262 1.0000
47.0800 6.0786 1.0000
47.1400 4.5120 1.0000
47.2000 5.1718 1.0000
47.2600 7.3129 1.0000
47.3200 4.9709 1.0000
47.3800 7.4183 1.0000
47.4400 7.5927 1.0000
47.5000 6.6767 1.0000
47.5600 5.1375 1.0000
47.6200 6.2719 1.0000
47.6800 3.3655 1.0000
47.7400 6.9520 1.0000
47.8000 4.1378 1.0000
47.8600 8.4807 1.0000
47.9200 3.1992 1.0000
47.9800 4.8924 1.0000
48.0400 5.5520 1.0000
48.1000 5.2312 1.0000
48.1600 6.8447 1.0000
48.2200 3.4191 1.0000
48.2800 7.9983 1.0000
48.3400 7.8838 1.0000
48.4000 7.3390 1.0000
48.4600 9.6679 1.0000
48.5200 8.3036 1.0000
48.5800 3.7178 1.0000
48.6400 4.3610 1.0000
48.7000 5.7581 1.0000
48.7600 4.8105 1.0000
48.8200 5.3612 1.0000
48.8800 10.3191 1.0000
48.9400 8.2456 1.0000
49.0000 6.9421 1.0000
49.0600 5.5793 1.0000
49.1200 13.5997 1.0000
49.1800 6.7898 1.0000
49.2400 7.6638 1.0000
49.3000 8.0461 1.0000
49.3600 9.6184 1.0000
49.4200 5.4654 1.0000
49.4800 3.3996 1.0000
49.5400 5.8073 1.0000
49.6000 13.6456 1.0000
49.6600 3.1224 1.0000
49.7200 11.1237 1.0000
49.7800 12.4682 1.0000
49.8400 9.8722 1.0000
49.9000 6.2432 1.0000
49.9600 6.1844 1.0000
50.0200 7.1740 1.0000
50.0800 5.2923 1.0000
50.1400 6.9694 1.0000
50.2000 4.4716 1.0000
50.2600 5.0674 1.0000
50.3200 8.0838 1.0000
50.3800 8.6926 1.0000
50.4400 6.2139 1.0000
50.5000 4.4345 1.0000
50.5600 4.8165 1.0000
50.6200 8.6449 1.0000
50.6800 4.1439 1.0000
50.7400 3.1379 1.0000
50.8000 5.8609 1.0000
50.8600 9.0298 1.0000
50.9200 9.2761 1.0000
50.9800 4.7420 1.0000
51.0400 6.9585 1.0000
51.1000 4.4965 1.0000
51.1600 5.9100 1.0000
51.2200 10.1424 1.0000
51.2800 10.2309 1.0000
51.3400 7.4286 1.0000
51.4000 4.1453 1.0000
51.4600 5.7847 1.0000
51.5200 4.8828 1.0000
51.5800 4.9474 1.0000
51.6400 6.5630 1.0000
51.7000 10.0284 1.0000
51.7600 8.3586 1.0000
51.8200 4.2166 1.0000
51.8800 3.7213 1.0000
51.9400 2.4518 1.0000
52.0000 4.7663 1.0000
52.0600 1.5560 1.0000
52.1200 5.9844 1.0000
52.1800 4.0540 1.0000
52.2400 9.9826 1.0000
52.3000 5.3147 1.0000
52.3600 8.7205 1.0000
52.4200 1.6963 1.0000
52.4800 1.0080 1.0000
52.5400 9.0502 1.0000
52.6000 4.8615 1.0000
52.6600 7.3781 1.0000
52.7200 3.5290 1.0000
52.7800 13.3039 1.0000
52.8400 5.0564 1.0000
52.9000 10.1480 1.0000
52.9600 6.6327 1.0000
53.0200 7.6382 1.0000
53.0800 4.1778 1.0000
53.1400 9.5403 1.0000
53.2000 9.8106 1.0000
53.2600 3.9286 1.0000
53.3200 6.5561 1.0000
53.3800 8.8241 1.0000
53.4400 9.0029 1.0000
53.5000 7.3220 1.0000
53.5600 7.4439 1.0000
53.6200 7.9697 1.0000
53.6800 7.2019 1.0000
53.7400 6.1947 1.0000
53.8000 7.7875 1.0000
53.8600 5.2258 1.0000
53.9200 6.2946 1.0000
53.9800 3.5098 1.0000
54.0400 11.4924 1.0000
54.1000 7.5832 1.0000
54.1600 5.9854 1.0000
54.2200 8.8198 1.0000
54.2800 3.4193 1.0000
54.3400 4.9976 1.0000
54.4000 7.5090 1.0000
54.4600 6.3370 1.0000
54.5200 6.8896 1.0000
54.5800 5.6700 1.0000
54.6400 5.0635 1.0000
54.7000 4.6147 1.0000
54.7600 4.7387 1.0000
54.8200 9.6131 1.0000
54.8800 7.8853 1.0000
54.9400 10.9882 1.0000
55.0000 8.5900 1.0000
55.0600 7.1472 1.0000
55.1200 13.1212 1.0000
55.1800 5.9808 1.0000
55.2400 3.9472 1.0000
55.3000 9.8922 1.0000
55.3600 6.2278 1.0000
55.4200 5.5947 1.0000
55.4800 6.7059 1.0000
55.5400 7.3098 1.0000
55.6000 6.8274 1.0000
55.6600 7.9757 1.0000
55.7200 8.7177 1.0000
55.7800 8.1741 1.0000
55.8400 4.1441 1.0000
55.9000 8.8173 1.0000
55.9600 4.5079 1.0000
56.0200 6.5629 1.0000
56.0800 3.4537 1.0000
56.1400 4.5219 1.0000
56.2000 7.9778 1.0000
56.2600 12.4338 1.0000
56.3200 4.0239 1.0000
56.3800 11.8030 1.0000
56.4400 8.5572 1.0000
56.5000 6.9980 1.0000
56.5600 7.2013 1.0000
56.6200 9.4752 1.0000
56.6800 5.2972 1.0000
56.7400 5.4632 1.0000
56.8000 3.8912 1.0000
56.8600 7.1972 1.0000
56.9200 8.9976 1.0000
56.9800 5.6151 1.0000
57.0400 6.4610 1.0000
57.1000 12.1514 1.0000
57.1600 15.6033 1.0000
57.2200 16.3093 1.0000
57.2800 5.1815 1.0000
57.3400 2.2110 1.0000
57.4000 5.0734 1.0000
57.4600 3.2097 1.0000
57.5200 6.5350 1.0000
57.5800 2.9930 1.0000
57.6400 6.1307 1.0000
57.7000 4.0680 1.0000
57.7600 10.3655 1.0000
57.8200 5.8869 1.0000
57.8800 4.9588 1.0000
57.9400 7.4084 1.0000
58.0000 4.6811 1.0000
58.0600 11.2529 1.0000
58.1200 4.5739 1.0000
58.1800 7.7513 1.0000
58.2400 11.1147 1.0000
58.3000 9.6567 1.0000
58.3600 9.4360 1.0000
58.4200 6.2232 1.0000
58.4800 11.8902 1.0000
58.5400 9.7381 1.0000
58.6000 11.4825 1.0000
58.6600 4.3261 1.0000
58.7200 5.5886 1.0000
58.7800 6.1369 1.0000
58.8400 5.4051 1.0000
58.9000 8.2999 1.0000
58.9600 14.8158 1.0000
59.0200 7.1671 1.0000
59.0800 8.4814 1.0000
59.1400 9.9452 1.0000
59.2000 5.7728 1.0000
59.2600 6.2016 1.0000
59.3200 9.4433 1.0000
59.3800 10.5141 1.0000
59.4400 7.0625 1.0000
59.5000 4.0947 1.0000
59.5600 6.3217 1.0000
59.6200 6.1961 1.0000
59.6800 10.8848 1.0000
59.7400 9.5726 1.0000
59.8000 6.8521 1.0000
59.8600 8.5363 1.0000
59.9200 8.3550 1.0000
59.9800 3.2794 1.0000
60.0400 4.0952 1.0000
60.1000 7.5736 1.0000
60.1600 14.2519 1.0000
60.2200 14.1737 1.0000
60.2800 5.4195 1.0000
60.3400 2.8039 1.0000
60.4000 12.2346 1.0000
60.4600 8.1216 1.0000
60.5200 4.9097 1.0000
60.5800 1.6216 1.0000
60.6400 3.8475 1.0000
60.7000 2.8788 1.0000
60.7600 8.2684 1.0000
60.8200 9.1725 1.0000
60.8800 8.3653 1.0000
60.9400 3.8768 1.0000
61.0000 7.3073 1.0000
61.0600 2.6581 1.0000
61.1200 9.2757 1.0000
61.1800 3.8129 1.0000
61.2400 6.3293 1.0000
61.3000 6.5683 1.0000
61.3600 4.3687 1.0000
61.4200 8.7830 1.0000
61.4800 3.1616 1.0000
61.5400 11.6549 1.0000
61.6000 4.1527 1.0000
61.6600 7.3825 1.0000
61.7200 1.0443 1.0000
61.7800 3.7849 1.0000
61.8400 9.4887 1.0000
61.9000 4.3774 1.0000
61.9600 6.5661 1.0000
62.0200 7.1694 1.0000
62.0800 6.0036 1.0000
62.1400 3.5170 1.0000
62.2000 2.8450 1.0000
62.2600 3.3370 1.0000
62.3200 5.7213 1.0000
62.3800 3.3819 1.0000
62.4400 7.3692 1.0000
62.5000 3.3613 1.0000
62.5600 6.7935 1.0000
62.6200 6.2901 1.0000
62.6800 10.0725 1.0000
62.7400 9.6420 1.0000
62.8000 5.1286 1.0000
62.8600 4.8284 1.0000
62.9200 5.2630 1.0000
62.9800 7.9834 1.0000
63.0400 9.2716 1.0000
63.1000 6.1988 1.0000
63.1600 4.7222 1.0000
63.2200 7.1243 1.0000
63.2800 8.5902 1.0000
63.3400 3.1044 1.0000
63.4000 6.1233 1.0000
63.4600 10.3222 1.0000
63.5200 7.2145 1.0000
63.5800 6.3222 1.0000
63.6400 6.5581 1.0000
63.7000 3.4890 1.0000
63.7600 3.4178 1.0000
63.8200 1.4624 1.0000
63.8800 4.5891 1.0000
63.9400 8.7949 1.0000
64.0000 7.1415 1.0000
64.0600 5.1121 1.0000
64.1200 11.6710 1.0000
64.1800 9.6796 1.0000
64.2400 7.4471 1.0000
64.3000 2.2975 1.0000
64.3600 4.7126 1.0000
64.4200 11.0990 1.0000
64.4800 7.3099 1.0000
64.5400 15.1470 1.0000
64.6000 10.4447 1.0000
64.6600 11.5964 1.0000
64.7200 15.2817 1.0000
64.7800 15.2761 1.0000
64.8400 22.9783 1.0000
64.9000 18.6460 1.0000
64.9600 15.9339 1.0000
65.0200 14.0921 1.0000
65.0800 7.9066 1.0000
65.1400 5.0503 1.0000
65.2000 6.3008 1.0000
65.2600 3.1628 1.0000
65.3200 8.3771 1.0000
65.3800 7.3559 1.0000
65.4400 2.1720 1.0000
65.5000 7.1276 1.0000
65.5600 4.0030 1.0000
65.6200 9.5703 1.0000
65.6800 4.1520 1.0000
65.7400 3.7301 1.0000
65.8000 3.0606 1.0000
65.8600 5.2686 1.0000
65.9200 3.1644 1.0000
65.9800 7.9102 1.0000
66.0400 4.5601 1.0000
66.1000 6.9237 1.0000
66.1600 3.6778 1.0000
66.2200 7.3931 1.0000
66.2800 7.3116 1.0000
66.3400 3.5061 1.0000
66.4000 8.1884 1.0000
66.4600 4.9067 1.0000
66.5200 6.1653 1.0000
66.5800 3.4184 1.0000
66.6400 12.1454 1.0000
66.7000 3.0943 1.0000
66.7600 7.8630 1.0000
66.8200 9.2801 1.0000
66.8800 6.1516 1.0000
66.9400 8.0415 1.0000
67.0000 10.6453 1.0000
67.0600 7.1557 1.0000
67.1200 8.7138 1.0000
67.1800 7.2243 1.0000
67.2400 5.9292 1.0000
67.3000 5.9984 1.0000
67.3600 12.1532 1.0000
67.4200 9.9430 1.0000
67.4800 13.1955 1.0000
67.5400 4.1203 1.0000
67.6000 9.5334 1.0000
67.6600 5.2435 1.0000
67.7200 7.9689 1.0000
67.7800 9.2698 1.0000
67.8400 10.3781 1.0000
67.9000 8.0963 1.0000
67.9600 11.8342 1.0000
68.0200 1.3402 1.0000
68.0800 6.4087 1.0000
68.1400 4.7239 1.0000
68.2000 11.1557 1.0000
68.2600 8.7975 1.0000
68.3200 8.1090 1.0000
68.3800 9.2210 1.0000
68.4400 5.2195 1.0000
68.5000 2.7150 1.0000
68.5600 9.0059 1.0000
68.6200 9.8810 1.0000
68.6800 15.3176 1.0000
68.7400 11.4234 1.0000
68.8000 4.4636 1.0000
68.8600 8.7355 1.0000
68.9200 6.3919 1.0000
68.9800 2.4342 1.0000
69.0400 4.5750 1.0000
69.1000 8.0340 1.0000
69.1600 8.8380 1.0000
69.2200 4.0168 1.0000
69.2800 8.5573 1.0000
69.3400 11.4740 1.0000
69.4000 6.4688 1.0000
69.4600 12.5958 1.0000
69.5200 3.8289 1.0000
69.5800 5.8737 1.0000
69.6400 5.5740 1.0000
69.7000 3.9501 1.0000
69.7600 5.1534 1.0000
69.8200 6.4211 1.0000
69.8800 7.5136 1.0000
69.9400 8.3803 1.0000
70.0000 6.2160 1.0000
70.0600 8.9623 1.0000
70.1200 5.2840 1.0000
70.1800 7.3253 1.0000
70.2400 4.4317 1.0000
70.3000 8.0661 1.0000
70.3600 2.2979 1.0000
70.4200 3.4039 1.0000
70.4800 10.7955 1.0000
70.5400 2.1110 1.0000
70.6000 4.4182 1.0000
70.6600 5.9186 1.0000
70.7200 7.9035 1.0000
70.7800 10.2220 1.0000
70.8400 5.3386 1.0000
70.9000 6.3427 1.0000
70.9600 2.3707 1.0000
71.0200 7.4262 1.0000
71.0800 7.3390 1.0000
71.1400 4.2799 1.0000
71.2000 6.2401 1.0000
71.2600 5.2459 1.0000
71.3200 8.9454 1.0000
71.3800 7.3329 1.0000
71.4400 7.2859 1.0000
71.5000 13.8972 1.0000
71.5600 1.9654 1.0000
71.6200 8.6724 1.0000
71.6800 2.4444 1.0000
71.7400 5.5349 1.0000
71.8000 3.8362 1.0000
71.8600 6.4639 1.0000
71.9200 7.8588 1.0000
71.9800 13.3527 1.0000
72.0400 4.4175 1.0000
72.1000 6.2739 1.0000
72.1600 6.0452 1.0000
72.2200 6.3713 1.0000
72.2800 10.1703 1.0000
72.3400 5.8361 1.0000
72.4000 7.9982 1.0000
72.4600 12.4848 1.0000
72.5200 6.6831 1.0000
72.5800 4.4292 1.0000
72.6400 9.5154 1.0000
72.7000 7.3572 1.0000
72.7600 11.1768 1.0000
72.8200 6.2531 1.0000
72.8800 0.8712 1.0000
72.9400 5.1912 1.0000
73.0000 6.1583 1.0000
73.0600 9.5584 1.0000
73.1200 5.4350 1.0000
73.1800 7.4542 1.0000
73.2400 3.0360 1.0000
73.3000 2.9696 1.0000
73.3600 3.8809 1.0000
73.4200 7.5185 1.0000
73.4800 5.1141 1.0000
73.5400 3.6648 1.0000
73.6000 7.3211 1.0000
73.6600 4.0323 1.0000
73.7200 8.1812 1.0000
73.7800 8.6133 1.0000
73.8400 4.6627 1.0000
73.9000 7.1551 1.0000
73.9600 5.0336 1.0000
74.0200 3.3742 1.0000
74.0800 3.9453 1.0000
74.1400 4.8057 1.0000
74.2000 5.6230 1.0000
74.2600 10.0994 1.0000
74.3200 8.1235 1.0000
74.3800 8.4598 1.0000
74.4400 7.0305 1.0000
74.5000 6.9256 1.0000
74.5600 4.3890 1.0000
74.6200 6.4482 1.0000
74.6800 4.0152 1.0000
74.7400 6.5954 1.0000
74.8000 2.2832 1.0000
74.8600 6.6839 1.0000
74.9200 7.9647 1.0000
74.9800 5.5698 1.0000
75.0400 2.3840 1.0000
75.1000 3.8116 1.0000
75.1600 7.8604 1.0000
75.2200 7.3278 1.0000
75.2800 4.9237 1.0000
75.3400 5.1320 1.0000
75.4000 5.8138 1.0000
75.4600 6.0177 1.0000
75.5200 10.2077 1.0000
75.5800 8.2422 1.0000
75.6400 13.1474 1.0000
75.7000 14.8920 1.0000
75.7600 3.0866 1.0000
75.8200 8.0295 1.0000
75.8800 11.9240 1.0000
75.9400 5.3274 1.0000
76.0000 2.1517 1.0000
76.0600 9.6366 1.0000
76.1200 6.0197 1.0000
76.1800 5.1330 1.0000
76.2400 10.4605 1.0000
76.3000 2.7567 1.0000
76.3600 7.9666 1.0000
76.4200 4.9601 1.0000
76.4800 8.8271 1.0000
76.5400 4.8382 1.0000
76.6000 7.2298 1.0000
76.6600 8.3650 1.0000
76.7200 6.9751 1.0000
76.7800 8.6810 1.0000
76.8400 5.4287 1.0000
76.9000 10.0772 1.0000
76.9600 11.3075 1.0000
77.0200 9.2699 1.0000
77.0800 7.7864 1.0000
77.1400 8.0861 1.0000
77.2000 3.0396 1.0000
77.2600 6.2253 1.0000
77.3200 6.8105 1.0000
77.3800 13.2446 1.0000
77.4400 8.5183 1.0000
77.5000 9.2398 1.0000
77.5600 6.1646 1.0000
77.6200 5.6295 1.0000
77.6800 3.5081 1.0000
77.7400 11.3963 1.0000
77.8000 7.8311 1.0000
77.8600 6.4991 1.0000
77.9200 4.3406 1.0000
77.9800 12.6469 1.0000
78.0400 9.1563 1.0000
78.1000 11.9887 1.0000
78.1600 12.6853 1.0000
78.2200 4.4581 1.0000
78.2800 17.8128 1.0000
78.3400 9.5719 1.0000
78.4000 7.5218 1.0000
78.4600 4.2255 1.0000
78.5200 6.1860 1.0000
78.5800 8.8831 1.0000
78.6400 4.5966 1.0000
78.7000 5.4871 1.0000
78.7600 7.3060 1.0000
78.8200 6.2296 1.0000
78.8800 5.9880 1.0000
78.9400 6.5347 1.0000
79.0000 1.5060 1.0000
79.0600 7.7225 1.0000
79.1200 4.6329 1.0000
79.1800 12.7561 1.0000
79.2400 6.8464 1.0000
79.3000 1.1374 1.0000
79.3600 5.0785 1.0000
79.4200 3.4816 1.0000
79.4800 7.9266 1.0000
79.5400 10.1279 1.0000
79.6000 6.3081 1.0000
79.6600 8.9011 1.0000
79.7200 8.8145 1.0000
79.7800 14.5398 1.0000
79.8400 9.7750 1.0000
79.9000 10.0196 1.0000
79.9600 4.1669 1.0000
80.0200 3.7378 1.0000
80.0800 5.1340 1.0000
80.1400 4.5462 1.0000
80.2000 5.3044 1.0000
80.2600 9.7694 1.0000
80.3200 6.0139 1.0000
80.3800 4.8884 1.0000
80.4400 7.6432 1.0000
80.5000 12.9033 1.0000
80.5600 3.6470 1.0000
80.6200 3.9900 1.0000
80.6800 7.1856 1.0000
80.7400 5.3684 1.0000
80.8000 7.6753 1.0000
80.8600 4.1753 1.0000
80.9200 9.5257 1.0000
80.9800 7.2255 1.0000
81.0400 7.4420 1.0000
81.1000 4.8045 1.0000
81.1600 7.8596 1.0000
81.2200 5.7920 1.0000
81.2800 6.9625 1.0000
81.3400 8.4545 1.0000
81.4000 8.0019 1.0000
81.4600 5.4147 1.0000
81.5200 8.6401 1.0000
81.5800 10.7530 1.0000
81.6400 13.7767 1.0000
81.7000 4.0496 1.0000
81.7600 5.5673 1.0000
81.8200 5.3588 1.0000
81.8800 11.6209 1.0000
81.9400 19.2829 1.0000
82.0000 34.6036 1.0000
82.0600 44.0734 1.0000
82.1200 35.2713 1.0000
82.1800 27.5206 1.0000
82.2400 20.8563 1.0000
82.3000 16.0643 1.0000
82.3600 7.2822 1.0000
82.4200 11.6731 1.0000
82.4800 11.1069 1.0000
82.5400 9.6100 1.0000
82.6000 8.1258 1.0000
82.6600 4.2077 1.0000
82.7200 10.3284 1.0000
82.7800 4.0156 1.0000
82.8400 13.3560 1.0000
82.9000 7.0544 1.0000
82.9600 4.1907 1.0000
83.0200 3.0936 1.0000
83.0800 10.4308 1.0000
83.1400 5.7972 1.0000
83.2000 6.8424 1.0000
83.2600 6.5160 1.0000
83.3200 4.3948 1.0000
83.3800 6.1619 1.0000
83.4400 6.2778 1.0000
83.5000 7.8297 1.0000
83.5600 6.3991 1.0000
83.6200 6.9707 1.0000
83.6800 3.2583 1.0000
83.7400 10.1523 1.0000
83.8000 2.4141 1.0000
83.8600 4.3173 1.0000
83.9200 7.3132 1.0000
83.9800 3.6081 1.0000
84.0400 4.3995 1.0000
84.1000 6.8252 1.0000
84.1600 2.0785 1.0000
84.2200 5.3464 1.0000
84.2800 4.0771 1.0000
84.3400 5.9482 1.0000
84.4000 5.7742 1.0000
84.4600 7.9152 1.0000
84.5200 9.7996 1.0000
84.5800 3.5442 1.0000
84.6400 6.6287 1.0000
84.7000 4.9289 1.0000
84.7600 6.3613 1.0000
84.8200 9.0566 1.0000
84.8800 10.0495 1.0000
84.9400 6.0451 1.0000
85.0000 3.0963 1.0000
85.0600 6.4432 1.0000
85.1200 7.6520 1.0000
85.1800 8.3765 1.0000
85.2400 6.8981 1.0000
85.3000 8.8176 1.0000
85.3600 5.6771 1.0000
85.4200 7.8398 1.0000
85.4800 10.7473 1.0000
85.5400 9.2447 1.0000
85.6000 4.1221 1.0000
85.6600 8.2117 1.0000
85.7200 5.3278 1.0000
85.7800 4.2211 1.0000
85.8400 9.1303 1.0000
85.9000 5.6761 1.0000
85.9600 6.2684 1.0000
86.0200 6.6217 1.0000
86.0800 6.6994 1.0000
86.1400 8.1973 1.0000
86.2000 2.9332 1.0000
86.2600 7.5458 1.0000
86.3200 4.7735 1.0000
86.3800 7.6850 1.0000
86.4400 7.4088 1.0000
86.5000 2.4547 1.0000
86.5600 3.8428 1.0000
86.6200 2.6302 1.0000
86.6800 3.3757 1.0000
86.7400 2.7395 1.0000
86.8000 7.2689 1.0000
86.8600 12.5701 1.0000
86.9200 7.6386 1.0000
86.9800 6.3126 1.0000
87.0400 4.5601 1.0000
87.1000 2.3067 1.0000
87.1600 8.2451 1.0000
87.2200 8.7012 1.0000
87.2800 4.9103 1.0000
87.3400 8.0284 1.0000
87.4000 12.0804 1.0000
87.4600 7.3507 1.0000
87.5200 8.1585 1.0000
87.5800 11.1724 1.0000
87.6400 4.7335 1.0000
87.7000 12.0701 1.0000
87.7600 12.2657 1.0000
87.8200 3.5999 1.0000
87.8800 7.4087 1.0000
87.9400 3.8766 1.0000
88.0000 2.3671 1.0000
88.0600 5.3682 1.0000
88.1200 5.9989 1.0000
88.1800 5.4646 1.0000
88.2400 6.8373 1.0000
88.3000 4.9848 1.0000
88.3600 4.3129 1.0000
88.4200 7.5937 1.0000
88.4800 4.8444 1.0000
88.5400 5.9994 1.0000
88.6000 4.5412 1.0000
88.6600 2.2446 1.0000
88.7200 10.5971 1.0000
88.7800 3.1938 1.0000
88.8400 5.1535 1.0000
88.9000 1.8936 1.0000
88.9600 7.8631 1.0000
89.0200 2.5376 1.0000
89.0800 4.9949 1.0000
89.1400 6.9019 1.0000
89.2000 6.8347 1.0000
89.2600 7.5508 1.0000
89.3200 13.1819 1.0000
89.3800 7.7793 1.0000
89.4400 6.0494 1.0000
89.5000 3.1495 1.0000
89.5600 3.4891 1.0000
89.6200 7.7593 1.0000
89.6800 4.4949 1.0000
89.7400 7.7718 1.0000
89.8000 6.7292 1.0000
89.8600 5.8303 1.0000
89.9200 5.8713 1.0000
89.9800 3.4554 1.0000
90.0400 1.7789 1.0000
90.1000 9.7865 1.0000
90.1600 4.2957 1.0000
90.2200 5.2334 1.0000
90.2800 7.2836 1.0000
90.3400 5.0479 1.0000
90.4000 8.6249 1.0000
90.4600 6.0200 1.0000
90.5200 4.3162 1.0000
90.5800 7.8471 1.0000
90.6400 5.5123 1.0000
90.7000 6.3116 1.0000
90.7600 6.5596 1.0000
90.8200 6.3955 1.0000
90.8800 5.2535 1.0000
90.9400 11.9145 1.0000
91.0000 8.4558 1.0000
91.0600 1.6743 1.0000
91.1200 5.1884 1.0000
91.1800 4.6890 1.0000
91.2400 2.3392 1.0000
91.3000 8.8474 1.0000
91.3600 7.2943 1.0000
91.4200 7.1358 1.0000
91.4800 8.9076 1.0000
91.5400 7.9582 1.0000
91.6000 6.7378 1.0000
91.6600 3.5053 1.0000
91.7200 2.5008 1.0000
91.7800 3.7947 1.0000
91.8400 6.9041 1.0000
91.9000 6.5094 1.0000
91.9600 3.4254 1.0000
92.0200 8.0402 1.0000
92.0800 8.2529 1.0000
92.1400 4.3556 1.0000
92.2000 2.5400 1.0000
92.2600 9.3116 1.0000
92.3200 3.8955 1.0000
92.3800 9.3378 1.0000
92.4400 4.0689 1.0000
92.5000 4.4713 1.0000
92.5600 5.8486 1.0000
92.6200 4.1826 1.0000
92.6800 6.0908 1.0000
92.7400 9.7586 1.0000
92.8000 2.5505 1.0000
92.8600 4.5169 1.0000
92.9200 6.0728 1.0000
92.9800 8.5388 1.0000
93.0400 8.9205 1.0000
93.1000 5.4460 1.0000
93.1600 5.9138 1.0000
93.2200 4.3444 1.0000
93.2800 7.4972 1.0000
93.3400 10.4913 1.0000
93.4000 3.3715 1.0000
93.4600 1.1632 1.0000
93.5200 5.5668 1.0000
93.5800 10.1668 1.0000
93.6400 6.2264 1.0000
93.7000 5.0784 1.0000
93.7600 4.3091 1.0000
93.8200 9.9399 1.0000
93.8800 3.1687 1.0000
93.9400 6.4428 1.0000
94.0000 6.1109 1.0000
94.0600 3.1979 1.0000
94.1200 5.8825 1.0000
94.1800 7.2874 1.0000
94.2400 7.4681 1.0000
94.3000 5.5339 1.0000
94.3600 10.8720 1.0000
94.4200 11.0759 1.0000
94.4800 1.1050 1.0000
94.5400 9.2675 1.0000
94.6000 5.6844 1.0000
94.6600 8.4650 1.0000
94.7200 4.1470 1.0000
94.7800 8.4501 1.0000
94.8400 5.0380 1.0000
94.9000 5.9858 1.0000
94.9600 6.2355 1.0000
95.0200 3.5138 1.0000
95.0800 4.5040 1.0000
95.1400 9.5788 1.0000
95.2000 7.9020 1.0000
95.2600 10.3651 1.0000
95.3200 9.5653 1.0000
95.3800 8.3788 1.0000
95.4400 7.3779 1.0000
95.5000 10.6353 1.0000
95.5600 1.0694 1.0000
95.6200 9.2328 1.0000
95.6800 10.0233 1.0000
95.7400 6.5146 1.0000
95.8000 3.7430 1.0000
95.8600 9.6306 1.0000
95.9200 9.7613 1.0000
95.9800 4.2998 1.0000
96.0400 9.5535 1.0000
96.1000 11.0942 1.0000
96.1600 6.1642 1.0000
96.2200 6.4459 1.0000
96.2800 5.8102 1.0000
96.3400 8.4361 1.0000
96.4000 4.9586 1.0000
96.4600 3.4865 1.0000
96.5200 11.4759 1.0000
96.5800 9.4663 1.0000
96.6400 7.1267 1.0000
96.7000 5.1010 1.0000
96.7600 13.7136 1.0000
96.8200 7.5674 1.0000
96.8800 9.2158 1.0000
96.9400 10.1071 1.0000
97.0000 8.8042 1.0000
97.0600 7.3919 1.0000
97.1200 8.2550 1.0000
97.1800 6.1947 1.0000
97.2400 8.5981 1.0000
97.3000 1.9688 1.0000
97.3600 5.1337 1.0000
97.4200 9.4331 1.0000
97.4800 1.3496 1.0000
97.5400 7.3426 1.0000
97.6000 10.0190 1.0000
97.6600 8.0210 1.0000
97.7200 6.8104 1.0000
97.7800 9.4558 1.0000
97.8400 6.5646 1.0000
97.9000 6.9558 1.0000
97.9600 8.3122 1.0000
98.0200 10.4726 1.0000
98.0800 8.8665 1.0000
98.1400 8.8602 1.0000
98.2000 8.9799 1.0000
98.2600 12.4893 1.0000
98.3200 15.1091 1.0000
98.3800 11.1118 1.0000
98.4400 14.9412 1.0000
98.5000 19.2544 1.0000
98.5600 17.4080 1.0000
98.6200 25.1394 1.0000
98.6800 23.8428 1.0000
98.7400 25.7123 1.0000
98.8000 13.8496 1.0000
98.8600 16.3631 1.0000
98.9200 7.8997 1.0000
98.9800 5.8559 1.0000
99.0400 8.0455 1.0000
99.1000 6.0993 1.0000
99.1600 9.4739 1.0000
99.2200 8.1517 1.0000
99.2800 8.2570 1.0000
99.3400 6.9036 1.0000
99.4000 8.7698 1.0000
99.4600 7.6703 1.0000
99.5200 7.1899 1.0000
99.5800 4.0180 1.0000
99.6400 7.6146 1.0000
99.7000 11.5170 1.0000
99.7600 3.6657 1.0000
99.8200 3.7981 1.0000
99.8800 7.9753 1.0000
99.9400 4.7124 1.0000
100.0000 5.7950 1.0000
100.0600 3.4081 1.0000
100.1200 13.1514 1.0000
100.1800 13.2539 1.0000
100.2400 5.3717 1.0000
100.3000 3.4261 1.0000
100.3600 2.6930 1.0000
100.4200 6.0328 1.0000
100.4800 3.9248 1.0000
100.5400 5.4027 1.0000
100.6000 7.6406 1.0000
100.6600 7.8346 1.0000
100.7200 6.7155 1.0000
100.7800 3.4792 1.0000
100.8400 2.5813 1.0000
100.9000 6.5348 1.0000
100.9600 4.2011 1.0000
101.0200 9.3804 1.0000
101.0800 3.9727 1.0000
101.1400 5.0361 1.0000
101.2000 4.4406 1.0000
101.2600 3.1641 1.0000
101.3200 4.3544 1.0000
101.3800 8.4780 1.0000
101.4400 11.4611 1.0000
101.5000 11.3851 1.0000
101.5600 10.1506 1.0000
101.6200 7.0904 1.0000
101.6800 3.1326 1.0000
101.7400 6.4108 1.0000
101.8000 8.1555 1.0000
101.8600 12.4324 1.0000
101.9200 11.1915 1.0000
101.9800 3.0845 1.0000
102.0400 6.4383 1.0000
102.1000 7.6624 1.0000
102.1600 14.5241 1.0000
102.2200 4.2021 1.0000
102.2800 4.8098 1.0000
102.3400 4.2624 1.0000
102.4000 5.1994 1.0000
102.4600 1.1902 1.0000
102.5200 9.0162 1.0000
102.5800 6.8199 1.0000
102.6400 6.3059 1.0000
102.7000 8.3206 1.0000
102.7600 6.0434 1.0000
102.8200 5.9252 1.0000
102.8800 6.1486 1.0000
102.9400 3.7554 1.0000
103.0000 5.7121 1.0000
103.0600 6.5411 1.0000
103.1200 9.2202 1.0000
103.1800 4.6118 1.0000
103.2400 8.5274 1.0000
103.3000 2.4145 1.0000
103.3600 5.6580 1.0000
103.4200 4.5283 1.0000
103.4800 4.1210 1.0000
103.5400 13.1099 1.0000
103.6000 3.7121 1.0000
103.6600 9.2168 1.0000
103.7200 3.5164 1.0000
103.7800 6.0966 1.0000
103.8400 7.0914 1.0000
103.9000 5.1519 1.0000
103.9600 8.0534 1.0000
104.0200 6.7702 1.0000
104.0800 6.8784 1.0000
104.1400 8.4191 1.0000
104.2000 6.2949 1.0000
104.2600 3.3930 1.0000
104.3200 5.6918 1.0000
104.3800 6.5757 1.0000
104.4400 6.1225 1.0000
104.5000 3.5587 1.0000
104.5600 9.9522 1.0000
104.6200 2.8967 1.0000
104.6800 4.4825 1.0000
104.7400 3.3123 1.0000
104.8000 4.6763 1.0000
104.8600 3.3867 1.0000
104.9200 6.4028 1.0000
104.9800 6.1761 1.0000
105.0400 3.1927 1.0000
105.1000 8.3933 1.0000
105.1600 2.9141 1.0000
105.2200 4.4617 1.0000
105.2800 7.3098 1.0000
105.3400 3.3260 1.0000
105.4000 10.7830 1.0000
105.4600 6.9348 1.0000
105.5200 5.2493 1.0000
105.5800 5.0989 1.0000
105.6400 5.2797 1.0000
105.7000 5.4221 1.0000
105.7600 10.1964 1.0000
105.8200 2.9350 1.0000
105.8800 4.6416 1.0000
105.9400 7.1006 1.0000
106.0000 3.7806 1.0000
106.0600 10.8647 1.0000
106.1200 2.1757 1.0000
106.1800 5.5934 1.0000
106.2400 4.2304 1.0000
106.3000 8.1429 1.0000
106.3600 6.7475 1.0000
106.4200 5.4036 1.0000
106.4800 5.0154 1.0000
106.5400 2.6142 1.0000
106.6000 3.3311 1.0000
106.6600 9.5524 1.0000
106.7200 4.2172 1.0000
106.7800 5.7292 1.0000
106.8400 11.2572 1.0000
106.9000 14.3488 1.0000
106.9600 9.5635 1.0000
107.0200 8.0145 1.0000
107.0800 9.0635 1.0000
107.1400 4.3878 1.0000
107.2000 9.8766 1.0000
107.2600 8.9166 1.0000
107.3200 6.4960 1.0000
107.3800 9.2932 1.0000
107.4400 6.4044 1.0000
107.5000 7.3841 1.0000
107.5600 8.0801 1.0000
107.6200 7.1467 1.0000
107.6800 5.9283 1.0000
107.7400 10.0463 1.0000
107.8000 10.0242 1.0000
107.8600 7.4953 1.0000
107.9200 6.1305 1.0000
107.9800 6.6573 1.0000
108.0400 6.7314 1.0000
108.1000 8.5647 1.0000
108.1600 9.5926 1.0000
108.2200 10.3791 1.0000
[...]
67.0000 4.0971 1.0000
67.0600 9.4358 1.0000
67.1200 8.8791 1.0000
67.1800 3.2810 1.0000
67.2400 7.2762 1.0000
67.3000 10.0285 1.0000
67.3600 9.7825 1.0000
67.4200 3.2220 1.0000
67.4800 5.9077 1.0000
67.5400 6.8415 1.0000
67.6000 9.5053 1.0000
67.6600 9.7522 1.0000
67.7200 10.5481 1.0000
67.7800 6.5007 1.0000
67.8400 4.8963 1.0000
67.9000 5.8620 1.0000
67.9600 3.5849 1.0000
68.0200 7.0215 1.0000
68.0800 11.5753 1.0000
68.1400 1.2144 1.0000
68.2000 3.9452 1.0000
68.2600 3.5685 1.0000
68.3200 2.2056 1.0000
68.3800 10.2270 1.0000
68.4400 4.7585 1.0000
68.5000 6.9789 1.0000
68.5600 10.1734 1.0000
68.6200 2.7130 1.0000
68.6800 8.2309 1.0000
68.7400 3.7520 1.0000
68.8000 11.1532 1.0000
68.8600 12.0284 1.0000
68.9200 7.6621 1.0000
68.9800 5.4364 1.0000
69.0400 5.6659 1.0000
69.1000 2.9582 1.0000
69.1600 2.9619 1.0000
69.2200 4.0157 1.0000
69.2800 18.0900 1.0000
69.3400 7.4903 1.0000
69.4000 11.1045 1.0000
69.4600 9.2359 1.0000
69.5200 2.0692 1.0000
69.5800 4.3580 1.0000
69.6400 4.8131 1.0000
69.7000 5.4814 1.0000
69.7600 2.4580 1.0000
69.8200 8.3149 1.0000
69.8800 9.9038 1.0000
69.9400 5.3421 1.0000
70.0000 4.1634 1.0000
70.0600 6.8235 1.0000
70.1200 10.7184 1.0000
70.1800 8.3481 1.0000
70.2400 4.3014 1.0000
70.3000 10.4689 1.0000
70.3600 8.1571 1.0000
70.4200 7.9562 1.0000
70.4800 6.4277 1.0000
70.5400 5.7344 1.0000
70.6000 3.2980 1.0000
70.6600 6.3136 1.0000
70.7200 18.3691 1.0000
70.7800 4.3276 1.0000
70.8400 7.0787 1.0000
70.9000 9.3046 1.0000
70.9600 4.9851 1.0000
71.0200 2.4803 1.0000
71.0800 7.2436 1.0000
71.1400 2.1321 1.0000
71.2000 14.9627 1.0000
71.2600 5.6807 1.0000
71.3200 4.1940 1.0000
71.3800 5.7097 1.0000
71.4400 0.6805 1.0000
71.5000 6.5153 1.0000
71.5600 2.9799 1.0000
71.6200 5.2893 1.0000
71.6800 3.6055 1.0000
71.7400 6.1213 1.0000
71.8000 3.4895 1.0000
71.8600 6.8989 1.0000
71.9200 8.0807 1.0000
71.9800 3.8626 1.0000
72.0400 9.2815 1.0000
72.1000 5.4389 1.0000
72.1600 4.3812 1.0000
72.2200 6.5770 1.0000
72.2800 6.8981 1.0000
72.3400 5.1455 1.0000
72.4000 9.2786 1.0000
72.4600 8.2024 1.0000
72.5200 4.8430 1.0000
72.5800 6.0244 1.0000
72.6400 3.2547 1.0000
72.7000 4.2259 1.0000
72.7600 6.8693 1.0000
72.8200 3.4296 1.0000
72.8800 5.1746 1.0000
72.9400 4.6048 1.0000
73.0000 6.4083 1.0000
73.0600 7.2153 1.0000
73.1200 8.0671 1.0000
73.1800 5.1065 1.0000
73.2400 6.8633 1.0000
73.3000 7.4170 1.0000
73.3600 3.4157 1.0000
73.4200 8.0622 1.0000
73.4800 5.7978 1.0000
73.5400 6.5976 1.0000
73.6000 7.0830 1.0000
73.6600 8.4193 1.0000
73.7200 4.8244 1.0000
73.7800 3.3996 1.0000
73.8400 2.9629 1.0000
73.9000 3.6752 1.0000
73.9600 9.2190 1.0000
74.0200 8.3315 1.0000
74.0800 8.0252 1.0000
74.1400 8.1240 1.0000
74.2000 4.9959 1.0000
74.2600 7.2505 1.0000
74.3200 4.2447 1.0000
74.3800 1.3537 1.0000
74.4400 4.7191 1.0000
74.5000 8.4464 1.0000
74.5600 5.2516 1.0000
74.6200 3.6181 1.0000
74.6800 10.9905 1.0000
74.7400 6.5321 1.0000
74.8000 5.2297 1.0000
74.8600 6.6976 1.0000
74.9200 7.0105 1.0000
74.9800 6.8432 1.0000
75.0400 7.0376 1.0000
75.1000 4.8539 1.0000
75.1600 4.1627 1.0000
75.2200 8.5615 1.0000
75.2800 5.3266 1.0000
75.3400 3.5991 1.0000
75.4000 4.5679 1.0000
75.4600 4.5300 1.0000
75.5200 5.9162 1.0000
75.5800 7.0632 1.0000
75.6400 2.8505 1.0000
75.7000 6.7600 1.0000
75.7600 7.2404 1.0000
75.8200 2.2453 1.0000
75.8800 10.3986 1.0000
75.9400 5.2883 1.0000
76.0000 7.7771 1.0000
76.0600 5.8230 1.0000
76.1200 6.1166 1.0000
76.1800 7.9920 1.0000
76.2400 2.4528 1.0000
76.3000 6.5814 1.0000
76.3600 7.9592 1.0000
76.4200 6.8220 1.0000
76.4800 3.2358 1.0000
76.5400 5.1252 1.0000
76.6000 8.2835 1.0000
76.6600 8.0038 1.0000
76.7200 8.0331 1.0000
76.7800 4.7049 1.0000
76.8400 8.4217 1.0000
76.9000 4.0832 1.0000
76.9600 8.3174 1.0000
77.0200 6.0288 1.0000
77.0800 5.7744 1.0000
77.1400 2.9288 1.0000
77.2000 9.6947 1.0000
77.2600 5.3424 1.0000
77.3200 4.5141 1.0000
77.3800 7.1791 1.0000
77.4400 9.4371 1.0000
77.5000 5.5612 1.0000
77.5600 2.1665 1.0000
77.6200 5.0330 1.0000
77.6800 3.9231 1.0000
77.7400 10.4038 1.0000
77.8000 11.9815 1.0000
77.8600 5.7068 1.0000
77.9200 9.8269 1.0000
77.9800 6.2897 1.0000
78.0400 8.6876 1.0000
78.1000 6.7291 1.0000
78.1600 6.2612 1.0000
78.2200 4.5245 1.0000
78.2800 4.6447 1.0000
78.3400 14.2042 1.0000
78.4000 9.2865 1.0000
78.4600 3.9327 1.0000
78.5200 6.3926 1.0000
78.5800 11.0856 1.0000
78.6400 7.6856 1.0000
78.7000 6.2658 1.0000
78.7600 3.8648 1.0000
78.8200 2.1584 1.0000
78.8800 5.5451 1.0000
78.9400 7.6095 1.0000
79.0000 3.1172 1.0000
79.0600 3.7811 1.0000
79.1200 5.3418 1.0000
79.1800 6.6484 1.0000
79.2400 8.8160 1.0000
79.3000 4.4066 1.0000
79.3600 3.3763 1.0000
79.4200 4.6870 1.0000
79.4800 6.5075 1.0000
79.5400 9.2457 1.0000
79.6000 3.8862 1.0000
79.6600 5.4901 1.0000
79.7200 3.8457 1.0000
79.7800 4.2076 1.0000
79.8400 5.1929 1.0000
79.9000 4.5746 1.0000
79.9600 5.2031 1.0000
80.0200 9.8675 1.0000
80.0800 5.9653 1.0000
80.1400 11.2872 1.0000
80.2000 2.4146 1.0000
80.2600 6.3776 1.0000
80.3200 4.5915 1.0000
80.3800 7.7211 1.0000
80.4400 8.0400 1.0000
80.5000 4.5305 1.0000
80.5600 6.4614 1.0000
80.6200 6.0751 1.0000
80.6800 6.3247 1.0000
80.7400 5.2989 1.0000
80.8000 8.7320 1.0000
80.8600 12.3317 1.0000
80.9200 6.2315 1.0000
80.9800 5.7769 1.0000
81.0400 6.0087 1.0000
81.1000 8.9603 1.0000
81.1600 17.0549 1.0000
81.2200 4.9367 1.0000
81.2800 2.2045 1.0000
81.3400 7.2270 1.0000
81.4000 8.3093 1.0000
81.4600 6.0402 1.0000
81.5200 7.3868 1.0000
81.5800 4.2214 1.0000
81.6400 4.1710 1.0000
81.7000 11.3219 1.0000
81.7600 9.5292 1.0000
81.8200 5.7412 1.0000
81.8800 15.1420 1.0000
81.9400 20.7004 1.0000
82.0000 27.0485 1.0000
82.0600 39.4254 1.0000
82.1200 55.9928 1.0000
82.1800 30.5331 1.0000
82.2400 24.5831 1.0000
82.3000 15.0627 1.0000
82.3600 18.0929 1.0000
82.4200 15.6297 1.0000
82.4800 8.9702 1.0000
82.5400 15.1419 1.0000
82.6000 6.0616 1.0000
82.6600 7.2643 1.0000
82.7200 5.6803 1.0000
82.7800 6.1783 1.0000
82.8400 10.7514 1.0000
82.9000 5.1793 1.0000
82.9600 4.1878 1.0000
83.0200 5.7225 1.0000
83.0800 2.4556 1.0000
83.1400 2.3578 1.0000
83.2000 3.8655 1.0000
83.2600 6.8125 1.0000
83.3200 7.3922 1.0000
83.3800 7.2702 1.0000
83.4400 3.1847 1.0000
83.5000 2.4824 1.0000
83.5600 5.6121 1.0000
83.6200 6.9076 1.0000
83.6800 5.3229 1.0000
83.7400 6.4047 1.0000
83.8000 6.1497 1.0000
83.8600 4.5021 1.0000
83.9200 6.8793 1.0000
83.9800 13.0049 1.0000
84.0400 10.6569 1.0000
84.1000 4.8563 1.0000
84.1600 6.0108 1.0000
84.2200 7.9529 1.0000
84.2800 3.1123 1.0000
84.3400 8.9234 1.0000
84.4000 5.5736 1.0000
84.4600 6.2783 1.0000
84.5200 8.6021 1.0000
84.5800 8.6202 1.0000
84.6400 2.3992 1.0000
84.7000 3.6423 1.0000
84.7600 6.3782 1.0000
84.8200 10.0536 1.0000
84.8800 6.8945 1.0000
84.9400 6.9938 1.0000
85.0000 6.4131 1.0000
85.0600 4.3429 1.0000
85.1200 8.4364 1.0000
85.1800 5.3475 1.0000
85.2400 1.5197 1.0000
85.3000 2.3341 1.0000
85.3600 3.4465 1.0000
85.4200 3.0460 1.0000
85.4800 6.1950 1.0000
85.5400 9.7735 1.0000
85.6000 5.0654 1.0000
85.6600 5.4488 1.0000
85.7200 4.9932 1.0000
85.7800 7.2007 1.0000
85.8400 10.1047 1.0000
85.9000 9.6556 1.0000
85.9600 5.7844 1.0000
86.0200 5.4995 1.0000
86.0800 4.3169 1.0000
86.1400 6.1306 1.0000
86.2000 8.6870 1.0000
86.2600 2.1031 1.0000
86.3200 8.4008 1.0000
86.3800 3.9700 1.0000
86.4400 3.7449 1.0000
86.5000 5.3736 1.0000
86.5600 4.9769 1.0000
86.6200 3.9136 1.0000
86.6800 4.1656 1.0000
86.7400 6.9070 1.0000
86.8000 9.7394 1.0000
86.8600 9.0503 1.0000
86.9200 5.8632 1.0000
86.9800 5.2109 1.0000
87.0400 6.1481 1.0000
87.1000 2.2452 1.0000
87.1600 4.5287 1.0000
87.2200 5.5380 1.0000
87.2800 8.1889 1.0000
87.3400 3.0342 1.0000
87.4000 11.0389 1.0000
87.4600 6.2091 1.0000
87.5200 2.2370 1.0000
87.5800 4.5341 1.0000
87.6400 7.4227 1.0000
87.7000 8.6228 1.0000
87.7600 5.1039 1.0000
87.8200 4.1162 1.0000
87.8800 3.8059 1.0000
87.9400 4.2932 1.0000
88.0000 8.8784 1.0000
88.0600 5.9324 1.0000
88.1200 7.5937 1.0000
88.1800 7.2256 1.0000
88.2400 2.8808 1.0000
88.3000 6.0638 1.0000
88.3600 4.3632 1.0000
88.4200 10.1002 1.0000
88.4800 9.6472 1.0000
88.5400 7.0958 1.0000
88.6000 5.8108 1.0000
88.6600 4.6889 1.0000
88.7200 6.7037 1.0000
88.7800 4.3593 1.0000
88.8400 3.6109 1.0000
88.9000 8.1972 1.0000
88.9600 3.7928 1.0000
89.0200 3.0561 1.0000
89.0800 7.3022 1.0000
89.1400 10.3481 1.0000
89.2000 6.1847 1.0000
89.2600 4.0638 1.0000
89.3200 6.1652 1.0000
89.3800 6.8104 1.0000
89.4400 8.1736 1.0000
89.5000 4.5636 1.0000
89.5600 6.4201 1.0000
89.6200 9.3779 1.0000
89.6800 7.8663 1.0000
89.7400 6.2711 1.0000
89.8000 6.5200 1.0000
89.8600 3.4045 1.0000
89.9200 3.5810 1.0000
89.9800 4.2464 1.0000
90.0400 3.1161 1.0000
90.1000 5.1261 1.0000
90.1600 6.1529 1.0000
90.2200 5.9084 1.0000
90.2800 5.0392 1.0000
90.3400 2.3622 1.0000
90.4000 8.6179 1.0000
90.4600 3.0037 1.0000
90.5200 6.1470 1.0000
90.5800 12.1215 1.0000
90.6400 4.8326 1.0000
90.7000 6.9253 1.0000
90.7600 6.2632 1.0000
90.8200 7.9613 1.0000
90.8800 11.5773 1.0000
90.9400 3.0821 1.0000
91.0000 12.2064 1.0000
91.0600 5.9253 1.0000
91.1200 6.4150 1.0000
91.1800 5.0933 1.0000
91.2400 6.4454 1.0000
91.3000 5.6322 1.0000
91.3600 6.1277 1.0000
91.4200 6.1107 1.0000
91.4800 4.2979 1.0000
91.5400 9.2253 1.0000
91.6000 3.3178 1.0000
91.6600 6.6540 1.0000
91.7200 6.3825 1.0000
91.7800 3.8590 1.0000
91.8400 7.4341 1.0000
91.9000 10.3207 1.0000
91.9600 3.1694 1.0000
92.0200 9.9231 1.0000
92.0800 5.1987 1.0000
92.1400 6.0406 1.0000
92.2000 10.7027 1.0000
92.2600 4.3421 1.0000
92.3200 7.4236 1.0000
92.3800 8.2118 1.0000
92.4400 5.3351 1.0000
92.5000 3.0162 1.0000
92.5600 7.3002 1.0000
92.6200 5.3966 1.0000
92.6800 6.2318 1.0000
92.7400 7.4818 1.0000
92.8000 6.3286 1.0000
92.8600 6.8614 1.0000
92.9200 2.8569 1.0000
92.9800 5.8599 1.0000
93.0400 11.8716 1.0000
93.1000 10.0949 1.0000
93.1600 6.2114 1.0000
93.2200 9.9655 1.0000
93.2800 3.7810 1.0000
93.3400 6.1969 1.0000
93.4000 5.0588 1.0000
93.4600 8.5891 1.0000
93.5200 5.8269 1.0000
93.5800 6.7510 1.0000
93.6400 6.5083 1.0000
93.7000 4.3831 1.0000
93.7600 5.3060 1.0000
93.8200 3.8740 1.0000
93.8800 5.5824 1.0000
93.9400 6.6015 1.0000
94.0000 3.9554 1.0000
94.0600 6.4435 1.0000
94.1200 7.9341 1.0000
94.1800 9.5773 1.0000
94.2400 8.3256 1.0000
94.3000 7.3627 1.0000
94.3600 8.8922 1.0000
94.4200 4.5561 1.0000
94.4800 8.5132 1.0000
94.5400 3.6030 1.0000
94.6000 5.0449 1.0000
94.6600 5.7757 1.0000
94.7200 8.8187 1.0000
94.7800 1.4097 1.0000
94.8400 4.0244 1.0000
94.9000 4.1879 1.0000
94.9600 6.7904 1.0000
95.0200 10.8576 1.0000
95.0800 11.2910 1.0000
95.1400 9.5273 1.0000
95.2000 3.5696 1.0000
95.2600 3.1950 1.0000
95.3200 6.2380 1.0000
95.3800 9.2716 1.0000
95.4400 7.7221 1.0000
95.5000 4.4683 1.0000
95.5600 13.1708 1.0000
95.6200 8.0885 1.0000
95.6800 10.7175 1.0000
95.7400 6.6164 1.0000
95.8000 5.0012 1.0000
95.8600 7.2093 1.0000
95.9200 6.2753 1.0000
95.9800 9.9883 1.0000
96.0400 7.3597 1.0000
96.1000 8.3459 1.0000
96.1600 4.8474 1.0000
96.2200 6.1150 1.0000
96.2800 4.6254 1.0000
96.3400 5.3492 1.0000
96.4000 4.6787 1.0000
96.4600 5.2990 1.0000
96.5200 4.1061 1.0000
96.5800 4.0071 1.0000
96.6400 6.0365 1.0000
96.7000 6.9634 1.0000
96.7600 2.3657 1.0000
96.8200 9.6822 1.0000
96.8800 7.4215 1.0000
96.9400 8.0870 1.0000
97.0000 3.1678 1.0000
97.0600 7.2585 1.0000
97.1200 10.6825 1.0000
97.1800 7.0040 1.0000
97.2400 3.0936 1.0000
97.3000 6.6927 1.0000
97.3600 6.0531 1.0000
97.4200 7.3829 1.0000
97.4800 6.2578 1.0000
97.5400 9.9282 1.0000
97.6000 5.5883 1.0000
97.6600 8.4753 1.0000
97.7200 7.7490 1.0000
97.7800 5.3572 1.0000
97.8400 3.1530 1.0000
97.9000 6.3338 1.0000
97.9600 7.1585 1.0000
98.0200 8.7462 1.0000
98.0800 4.4915 1.0000
98.1400 8.1565 1.0000
98.2000 6.0357 1.0000
98.2600 5.3359 1.0000
98.3200 11.1717 1.0000
98.3800 7.4883 1.0000
98.4400 5.8497 1.0000
98.5000 11.7817 1.0000
98.5600 15.6913 1.0000
98.6200 19.7115 1.0000
98.6800 21.6091 1.0000
98.7400 12.3163 1.0000
98.8000 14.1586 1.0000
98.8600 6.0083 1.0000
98.9200 10.6930 1.0000
98.9800 11.2560 1.0000
99.0400 6.0553 1.0000
99.1000 6.6357 1.0000
99.1600 6.0221 1.0000
99.2200 10.0140 1.0000
99.2800 3.2284 1.0000
99.3400 6.7491 1.0000
99.4000 6.3599 1.0000
99.4600 7.0157 1.0000
99.5200 3.8418 1.0000
99.5800 7.2246 1.0000
99.6400 5.8680 1.0000
99.7000 9.5456 1.0000
99.7600 12.1878 1.0000
99.8200 5.1053 1.0000
99.8800 7.5337 1.0000
99.9400 7.3887 1.0000
100.0000 3.4824 1.0000
100.0600 10.6887 1.0000
100.1200 7.2504 1.0000
100.1800 8.4433 1.0000
100.2400 7.1166 1.0000
100.3000 7.8638 1.0000
100.3600 3.3899 1.0000
100.4200 1.5448 1.0000
100.4800 8.9962 1.0000
100.5400 10.1964 1.0000
100.6000 3.2961 1.0000
100.6600 6.6813 1.0000
100.7200 8.1794 1.0000
100.7800 9.3726 1.0000
100.8400 8.0385 1.0000
100.9000 5.1633 1.0000
100.9600 3.1299 1.0000
101.0200 8.7950 1.0000
101.0800 8.4054 1.0000
101.1400 4.9762 1.0000
101.2000 9.1553 1.0000
101.2600 6.3039 1.0000
101.3200 7.0092 1.0000
101.3800 5.3038 1.0000
101.4400 11.5235 1.0000
101.5000 6.1365 1.0000
101.5600 9.5229 1.0000
101.6200 4.5156 1.0000
101.6800 2.3909 1.0000
101.7400 7.3767 1.0000
101.8000 3.0236 1.0000
101.8600 5.9164 1.0000
101.9200 11.4510 1.0000
101.9800 9.2917 1.0000
102.0400 3.3633 1.0000
102.1000 5.9020 1.0000
102.1600 2.9685 1.0000
102.2200 8.8968 1.0000
102.2800 8.0585 1.0000
102.3400 11.0637 1.0000
102.4000 6.9304 1.0000
102.4600 7.9249 1.0000
102.5200 7.1886 1.0000
102.5800 14.5073 1.0000
102.6400 7.8568 1.0000
102.7000 6.2876 1.0000
102.7600 6.0504 1.0000
102.8200 5.5685 1.0000
102.8800 6.7719 1.0000
102.9400 10.9225 1.0000
103.0000 7.8092 1.0000
103.0600 13.1027 1.0000
103.1200 6.3070 1.0000
103.1800 9.8803 1.0000
103.2400 18.5909 1.0000
103.3000 4.4243 1.0000
103.3600 8.5792 1.0000
103.4200 3.4678 1.0000
103.4800 5.9021 1.0000
103.5400 5.1462 1.0000
103.6000 7.1078 1.0000
103.6600 3.6093 1.0000
103.7200 2.2317 1.0000
103.7800 7.6854 1.0000
103.8400 6.9686 1.0000
103.9000 4.8755 1.0000
103.9600 5.1231 1.0000
104.0200 4.8776 1.0000
104.0800 6.7032 1.0000
104.1400 3.9808 1.0000
104.2000 5.4165 1.0000
104.2600 8.3130 1.0000
104.3200 5.4177 1.0000
104.3800 10.6633 1.0000
104.4400 9.4069 1.0000
104.5000 6.7494 1.0000
104.5600 6.0575 1.0000
104.6200 2.1124 1.0000
104.6800 13.0740 1.0000
104.7400 7.6172 1.0000
104.8000 2.8396 1.0000
104.8600 4.7497 1.0000
104.9200 10.4132 1.0000
104.9800 8.0147 1.0000
105.0400 16.0956 1.0000
105.1000 5.1824 1.0000
105.1600 6.6053 1.0000
105.2200 5.9072 1.0000
105.2800 4.0708 1.0000
105.3400 6.8712 1.0000
105.4000 5.1493 1.0000
105.4600 6.3375 1.0000
105.5200 7.3509 1.0000
105.5800 6.1231 1.0000
105.6400 3.2555 1.0000
105.7000 12.9130 1.0000
105.7600 4.2131 1.0000
105.8200 8.4808 1.0000
105.8800 4.1766 1.0000
105.9400 9.3042 1.0000
106.0000 7.4106 1.0000
106.0600 9.2805 1.0000
106.1200 8.3786 1.0000
106.1800 6.4244 1.0000
106.2400 10.3780 1.0000
106.3000 6.1214 1.0000
106.3600 4.6295 1.0000
106.4200 9.6732 1.0000
106.4800 5.3826 1.0000
106.5400 5.7662 1.0000
106.6000 3.3283 1.0000
106.6600 6.9383 1.0000
106.7200 3.0455 1.0000
106.7800 9.5050 1.0000
106.8400 6.8019 1.0000
106.9000 2.6038 1.0000
106.9600 7.2969 1.0000
107.0200 5.0023 1.0000
107.0800 6.7565 1.0000
107.1400 6.3546 1.0000
107.2000 6.7474 1.0000
107.2600 10.7569 1.0000
107.3200 7.2548 1.0000
107.3800 5.7477 1.0000
107.4400 6.8569 1.0000
107.5000 6.3568 1.0000
107.5600 4.5091 1.0000
107.6200 9.1171 1.0000
107.6800 10.4323 1.0000
107.7400 7.1787 1.0000
107.8000 6.8586 1.0000
107.8600 4.3494 1.0000
107.9200 6.2111 1.0000
107.9800 5.5415 1.0000
108.0400 8.6425 1.0000
108.1000 3.9261 1.0000
108.1600 6.8296 1.0000
108.2200 3.0418 1.0000
108.2800 11.1247 1.0000
108.3400 6.9035 1.0000
108.4000 3.5892 1.0000
108.4600 3.6235 1.0000
108.5200 3.7797 1.0000
108.5800 7.4465 1.0000
108.6400 5.2434 1.0000
108.7000 5.1023 1.0000
108.7600 3.9649 1.0000
108.8200 4.0781 1.0000
108.8800 7.8235 1.0000
108.9400 4.5633 1.0000
109.0000 4.9704 1.0000
109.0600 7.2447 1.0000
109.1200 5.2645 1.0000
109.1800 9.0777 1.0000
109.2400 7.5531 1.0000
109.3000 4.0971 1.0000
109.3600 7.9684 1.0000
109.4200 9.1089 1.0000
109.4800 8.1071 1.0000
109.5400 3.6128 1.0000
109.6000 9.3938 1.0000
109.6600 6.0843 1.0000
109.7200 6.5053 1.0000
109.7800 7.0231 1.0000
109.8400 6.9446 1.0000
109.9000 2.5282 1.0000
109.9600 6.8961 1.0000
110.0200 2.6499 1.0000
110.0800 9.2558 1.0000
110.1400 7.4561 1.0000
110.2000 9.0015 1.0000
110.2600 4.2544 1.0000
110.3200 5.3936 1.0000
110.3800 8.0065 1.0000
110.4400 7.3466 1.0000
110.5000 8.3827 1.0000
110.5600 5.3868 1.0000
110.6200 8.7729 1.0000
110.6800 8.2005 1.0000
110.7400 4.7329 1.0000
110.8000 4.2085 1.0000
110.8600 2.5692 1.0000
110.9200 8.6208 1.0000
110.9800 8.6164 1.0000
111.0400 2.3684 1.0000
111.1000 5.3391 1.0000
111.1600 12.9502 1.0000
111.2200 1.8546 1.0000
111.2800 5.9153 1.0000
111.3400 2.5784 1.0000
111.4000 6.2107 1.0000
111.4600 7.8211 1.0000
111.5200 9.2375 1.0000
111.5800 7.4987 1.0000
111.6400 5.1691 1.0000
111.7000 4.0653 1.0000
111.7600 3.8094 1.0000
111.8200 13.4955 1.0000
111.8800 4.7204 1.0000
111.9400 8.2469 1.0000
112.0000 10.0957 1.0000
112.0600 0.3364 1.0000
112.1200 5.0403 1.0000
112.1800 10.5045 1.0000
112.2400 7.4614 1.0000
112.3000 4.0892 1.0000
112.3600 4.9818 1.0000
112.4200 6.7807 1.0000
112.4800 8.0696 1.0000
112.5400 5.7583 1.0000
112.6000 7.7428 1.0000
112.6600 6.4831 1.0000
112.7200 7.3149 1.0000
112.7800 8.1243 1.0000
112.8400 5.0458 1.0000
112.9000 11.9787 1.0000
112.9600 4.3629 1.0000
113.0200 4.7372 1.0000
113.0800 7.3496 1.0000
113.1400 4.9754 1.0000
113.2000 6.5027 1.0000
113.2600 5.3555 1.0000
113.3200 6.1665 1.0000
113.3800 7.0255 1.0000
113.4400 6.4578 1.0000
113.5000 2.2553 1.0000
113.5600 7.2509 1.0000
113.6200 6.5963 1.0000
113.6800 4.1057 1.0000
113.7400 4.9798 1.0000
113.8000 4.8128 1.0000
113.8600 7.1397 1.0000
113.9200 5.5739 1.0000
113.9800 4.2298 1.0000
114.0400 8.2445 1.0000
114.1000 6.1529 1.0000
114.1600 4.2037 1.0000
114.2200 3.5477 1.0000
114.2800 6.9278 1.0000
114.3400 7.5893 1.0000
114.4000 7.8721 1.0000
114.4600 3.3873 1.0000
114.5200 8.1353 1.0000
114.5800 2.6990 1.0000
114.6400 5.3685 1.0000
114.7000 6.6788 1.0000
114.7600 5.6066 1.0000
114.8200 8.8929 1.0000
114.8800 3.4728 1.0000
114.9400 4.7729 1.0000
115.0000 5.9957 1.0000
115.0600 6.3051 1.0000
115.1200 3.5489 1.0000
115.1800 7.0984 1.0000
115.2400 6.2083 1.0000
115.3000 5.3370 1.0000
115.3600 12.1337 1.0000
115.4200 5.8293 1.0000
115.4800 5.1368 1.0000
115.5400 7.7778 1.0000
115.6000 8.1103 1.0000
115.6600 9.1933 1.0000
115.7200 11.2742 1.0000
115.7800 12.1944 1.0000
115.8400 10.4653 1.0000
115.9000 19.0445 1.0000
115.9600 20.5666 1.0000
116.0200 14.7947 1.0000
116.0800 15.6802 1.0000
116.1400 17.0027 1.0000
116.2000 7.0489 1.0000
116.2600 15.1453 1.0000
116.3200 11.6814 1.0000
116.3800 12.0856 1.0000
116.4400 13.6500 1.0000
116.5000 8.9260 1.0000
116.5600 3.3473 1.0000
116.6200 8.1882 1.0000
116.6800 9.0842 1.0000
116.7400 8.5445 1.0000
116.8000 6.0671 1.0000
116.8600 5.1961 1.0000
116.9200 8.4096 1.0000
116.9800 6.2995 1.0000
117.0400 4.2420 1.0000
117.1000 4.9054 1.0000
117.1600 8.5337 1.0000
117.2200 7.8022 1.0000
117.2800 6.5359 1.0000
117.3400 8.0653 1.0000
117.4000 6.5602 1.0000
117.4600 5.2703 1.0000
117.5200 9.4130 1.0000
117.5800 7.8240 1.0000
117.6400 4.0852 1.0000
117.7000 6.6061 1.0000
117.7600 7.1898 1.0000
117.8200 4.5852 1.0000
117.8800 4.7289 1.0000
117.9400 6.9224 1.0000
118.0000 6.7154 1.0000
118.0600 8.8326 1.0000
118.1200 4.2481 1.0000
118.1800 5.1359 1.0000
118.2400 3.9881 1.0000
118.3000 5.5620 1.0000
118.3600 5.9572 1.0000
118.4200 3.8460 1.0000
118.4800 5.8867 1.0000
118.5400 7.1081 1.0000
118.6000 5.5980 1.0000
118.6600 7.1579 1.0000
118.7200 15.8372 1.0000
118.7800 7.3784 1.0000
118.8400 4.2543 1.0000
118.9000 5.2760 1.0000
118.9600 9.2047 1.0000
119.0200 9.5183 1.0000
119.0800 0.4771 1.0000
119.1400 7.9944 1.0000
119.2000 11.2322 1.0000
119.2600 1.9962 1.0000
119.3200 8.4959 1.0000
119.3800 8.9709 1.0000
119.4400 11.2327 1.0000
119.5000 7.0222 1.0000
119.5600 7.0412 1.0000
119.6200 6.1837 1.0000
119.6800 6.4812 1.0000
119.7400 10.0008 1.0000
119.8000 7.8045 1.0000
119.8600 5.5734 1.0000
119.9200 5.4073 1.0000
119.9800 6.3836 1.0000
119.9900 6.7910 1.0000
*RAS_INT_END
*RAS_TEMPERATURE_START
*RAS_TEMPERATURE_END
*RAS_DATA_END