File: XRD/PB_Ge220_5SS_500umDS_RS1_Rod_5SS_Hypix1D_EFRW4_HAZ_P-irradiated.ras
*RAS_DATA_START
*RAS_HEADER_START
*DISP_FMT_X "%.3f"
*DISP_FMT_Y "%.0f"
*DISP_FULLSCALE "708.6323374583"
*DISP_LINE_COLOR "255.0000000000"
*DISP_LINE_STYLE "0.0000000000"
*DISP_LINE_WIDTH "0.2500000000"
*DISP_NOTE "Collected Data-23"
*DISP_OFFSET_Y "0.0000000000"
*DISP_PEAKSEARCH_UNIT_Y "cps"
*DISP_RANGE_BOTTOM "0.0000000000"
*DISP_RANGE_LEFT "40.0000000000"
*DISP_RANGE_LOGCUTOFF "0.0100000000"
*DISP_RANGE_RIGHT "119.9968000000"
*DISP_RANGE_TOP "708.6323374583"
*DISP_SCALE_MODE_Y "0.0000000000"
*DISP_TAB_NAME "Theta/2-Theta"
*DISP_TITLE_Y "Intensity"
*DISP_UNIT_Y "cps"
*DISP_WINDOW_NAME "MSG_MACROENGINE"
*FILE_COMMENT " "
*FILE_MD5 ""
*FILE_MEMO " "
*FILE_OPERATOR "Administrator"
*FILE_PART_ID "MEAS_KHP2_00061"
*FILE_SAMPLE " "
*FILE_TYPE "RAS_RAW"
*FILE_USERGROUP "System Manager"
*FILE_VERSION "1.0000000000"
*HW_ATTACHMENT_ID "ATT0021"
*HW_ATTACHMENT_NAME "XY-20mm|XY-20mm"
*HW_COUNTER_ID-0 "CUT0041"
*HW_COUNTER_ID-1 "CUT0051"
*HW_COUNTER_ID-2 "CUT0020"
*HW_COUNTER_ID-3 "CSL0021"
*HW_COUNTER_ID-4 "CMC0021"
*HW_COUNTER_NAME-0 "D/teX Ultra 250|D/teX Ultra 250"
*HW_COUNTER_NAME-1 "HyPix 3000(H)|HyPix 3000(H)"
*HW_COUNTER_NAME-2 "None|None"
*HW_COUNTER_NAME-3 "BBM|BBM"
*HW_COUNTER_NAME-4 "検出器モノクロメータ|Detector monochromator"
*HW_COUNTER_SELECT_NAME "HyPix 3000(H)|HyPix 3000(H)"
*HW_GONIOMETER_ID "GON0024"
*HW_GONIOMETER_NAME "SmartLab(In-plane)|SmartLab(In-plane)"
*HW_GONIOMETER_RADIUS-0 "90.0"
*HW_GONIOMETER_RADIUS-1 "114.0"
*HW_GONIOMETER_RADIUS-2 "190.0"
*HW_GONIOMETER_RADIUS-3 "300.0"
*HW_GONIOMETER_RADIUS-4 "187.0"
*HW_GONIOMETER_RADIUS-5 "300.0"
*HW_GONIOMETER_RADIUS-6 "113.0"
*HW_GONIOMETER_RADIUS-7 "331.0"
*HW_I_OPT_ID-0 "CBO0021"
*HW_I_OPT_ID-1 "ICR0021"
*HW_I_OPT_ID-2 "ISL0021"
*HW_I_OPT_ID-3 "ISO0021"
*HW_I_OPT_ID-4 "IAD0021"
*HW_I_OPT_ID-5 "IPR0001"
*HW_I_OPT_NAME-0 "CBOユニット|CBO unit"
*HW_I_OPT_NAME-1 "標準入射光学ユニット|Standard incident optical unit"
*HW_I_OPT_NAME-2 "標準入射スリットボックス|Standard incident slit box"
*HW_I_OPT_NAME-3 "入射平行スリット|Incident parallel slit"
*HW_I_OPT_NAME-4 "長手制限スリット|Length limiting slit"
*HW_I_OPT_NAME-5 "None|None"
*HW_R_ATTENUATER_AUTOMODE "0"
*HW_R_OPT_ID-0 "RSS0022"
*HW_R_OPT_ID-1 "RCR0022"
*HW_R_OPT_ID-2 "RSO0021"
*HW_R_OPT_ID-3 "RRS0022"
*HW_R_OPT_ID-4 "ATN0020"
*HW_R_OPT_ID-5 "RFL0021"
*HW_R_OPT_ID-6 "RAD0021"
*HW_R_OPT_NAME-0 "受光スリットボックス1(Zr軸付)|Receiving slit box # 1 (w/ Zr Axis)"
*HW_R_OPT_NAME-1 "標準受光光学ユニット1|Standard receiving unit # 1"
*HW_R_OPT_NAME-2 "標準受光光学ユニット2|Standard receiving optical unit # 2"
*HW_R_OPT_NAME-3 "仮想受光スリット2|Virtual receiving slit #2"
*HW_R_OPT_NAME-4 "無し|None"
*HW_R_OPT_NAME-5 "Cu Kβ|Cu K-beta"
*HW_R_OPT_NAME-6 "調整用受光スリット|Alignment receiving slit"
*HW_SAMPLE_HOLDER_ID "SMP0021"
*HW_SAMPLE_HOLDER_NAME "χφZクレードル|Chi phi Z cradle"
*HW_XG_CURRENT_MAX "40"
*HW_XG_CURRENT_MIN "2"
*HW_XG_CURRENT_RESOLUTION "1"
*HW_XG_CURRENT_UNIT "mA"
*HW_XG_FOCUS "0.4mm x 8mm"
*HW_XG_FOCUS_TYPE "Fine"
*HW_XG_ID "1200"
*HW_XG_NAME "3kW 封入管(ID:1200)|3kW Sealed tube(ID:1200)"
*HW_XG_TARGET_ATOMIC_NUMBER "29.0000000000"
*HW_XG_TARGET_NAME "Cu"
*HW_XG_TYPE "Hermetic"
*HW_XG_VOLTAGE_MAX "40"
*HW_XG_VOLTAGE_MIN "20"
*HW_XG_VOLTAGE_RESOLUTION "1"
*HW_XG_VOLTAGE_UNIT "kV"
*HW_XG_WATT_MAX "1.500"
*HW_XG_WATT_UNIT "kW"
*HW_XG_WAVE_LENGTH_ALPHA1 "1.540593"
*HW_XG_WAVE_LENGTH_ALPHA2 "1.544414"
*HW_XG_WAVE_LENGTH_BETA "1.392250"
*MEAS_COND_AXIS_NAME-0 "Theta/2-Theta"
*MEAS_COND_AXIS_NAME-1 "2-Theta"
*MEAS_COND_AXIS_NAME-2 "Omega"
*MEAS_COND_AXIS_NAME-3 "Chi"
*MEAS_COND_AXIS_NAME-4 "Phi"
*MEAS_COND_AXIS_NAME-5 "Z"
*MEAS_COND_AXIS_NAME-6 "X"
*MEAS_COND_AXIS_NAME-7 "Y"
*MEAS_COND_AXIS_NAME-8 "2-Theta/Omega"
*MEAS_COND_AXIS_NAME-9 "2-ThetaChi"
*MEAS_COND_AXIS_NAME-10 "2-ThetaChi/Phi"
*MEAS_COND_AXIS_NAME-11 "Alpha"
*MEAS_COND_AXIS_NAME-12 "Beta"
*MEAS_COND_AXIS_NAME-13 "Theta_s"
*MEAS_COND_AXIS_NAME-14 "Theta_d"
*MEAS_COND_AXIS_NAME-15 "Ts"
*MEAS_COND_AXIS_NAME-16 "CBO selection slit"
*MEAS_COND_AXIS_NAME-17 "M"
*MEAS_COND_AXIS_NAME-18 "Incident parallel slit"
*MEAS_COND_AXIS_NAME-19 "Incident slit"
*MEAS_COND_AXIS_NAME-20 ""
*MEAS_COND_AXIS_NAME-21 "Zs"
*MEAS_COND_AXIS_NAME-22 "Incident optical device"
*MEAS_COND_AXIS_NAME-23 "Omega_m"
*MEAS_COND_AXIS_NAME-24 "Length limiting slit"
*MEAS_COND_AXIS_NAME-25 "Center slit"
*MEAS_COND_AXIS_NAME-26 "Filter"
*MEAS_COND_AXIS_NAME-27 "Receiving slit # 1"
*MEAS_COND_AXIS_NAME-28 "Receiving slit # 2"
*MEAS_COND_AXIS_NAME-29 "Receiving optical device"
*MEAS_COND_AXIS_NAME-30 "Receiving parallel slit"
*MEAS_COND_AXIS_NAME-31 "Alignment receiving slit"
*MEAS_COND_AXIS_NAME-32 ""
*MEAS_COND_AXIS_NAME-33 ""
*MEAS_COND_AXIS_NAME-34 "Zd"
*MEAS_COND_AXIS_NAME-35 "Attenuator"
*MEAS_COND_AXIS_NAME-36 "Diffracted beam monochromator"
*MEAS_COND_AXIS_NAME-37 "Monochromator slit"
*MEAS_COND_AXIS_NAME-38 "2-ThetaB"
*MEAS_COND_AXIS_NAME-39 ""
*MEAS_COND_AXIS_NAME-40 ""
*MEAS_COND_AXIS_NAME-41 "Zr"
*MEAS_COND_AXIS_NAME-42 "Primary beam"
*MEAS_COND_AXIS_NAME_INTERNAL-0 "TwoThetaTheta"
*MEAS_COND_AXIS_NAME_INTERNAL-1 "TwoTheta"
*MEAS_COND_AXIS_NAME_INTERNAL-2 "Omega"
*MEAS_COND_AXIS_NAME_INTERNAL-3 "Chi"
*MEAS_COND_AXIS_NAME_INTERNAL-4 "Phi"
*MEAS_COND_AXIS_NAME_INTERNAL-5 "Z"
*MEAS_COND_AXIS_NAME_INTERNAL-6 "X"
*MEAS_COND_AXIS_NAME_INTERNAL-7 "Y"
*MEAS_COND_AXIS_NAME_INTERNAL-8 "TwoThetaOmega"
*MEAS_COND_AXIS_NAME_INTERNAL-9 "TwoThetaChi"
*MEAS_COND_AXIS_NAME_INTERNAL-10 "TwoThetaChiPhi"
*MEAS_COND_AXIS_NAME_INTERNAL-11 "Alpha"
*MEAS_COND_AXIS_NAME_INTERNAL-12 "Beta"
*MEAS_COND_AXIS_NAME_INTERNAL-13 "ThetaS"
*MEAS_COND_AXIS_NAME_INTERNAL-14 "ThetaD"
*MEAS_COND_AXIS_NAME_INTERNAL-15 "Ts"
*MEAS_COND_AXIS_NAME_INTERNAL-16 "CBO"
*MEAS_COND_AXIS_NAME_INTERNAL-17 "CBO-M"
*MEAS_COND_AXIS_NAME_INTERNAL-18 "IncidentSollerSlit"
*MEAS_COND_AXIS_NAME_INTERNAL-19 "IncidentSlitBox"
*MEAS_COND_AXIS_NAME_INTERNAL-20 "IncidentSlitBox-_Axis"
*MEAS_COND_AXIS_NAME_INTERNAL-21 "Zs"
*MEAS_COND_AXIS_NAME_INTERNAL-22 "IncidentMonochromator"
*MEAS_COND_AXIS_NAME_INTERNAL-23 "IncidentMonochromator-OmegaM"
*MEAS_COND_AXIS_NAME_INTERNAL-24 "IncidentAxdSlit"
*MEAS_COND_AXIS_NAME_INTERNAL-25 "CenterSlit"
*MEAS_COND_AXIS_NAME_INTERNAL-26 "Filter"
*MEAS_COND_AXIS_NAME_INTERNAL-27 "ReceivingSlitBox1"
*MEAS_COND_AXIS_NAME_INTERNAL-28 "ReceivingSlitBox2"
*MEAS_COND_AXIS_NAME_INTERNAL-29 "ReceivingOptics"
*MEAS_COND_AXIS_NAME_INTERNAL-30 "ReceivingSollerSlit"
*MEAS_COND_AXIS_NAME_INTERNAL-31 "ReceivingAxdSlit"
*MEAS_COND_AXIS_NAME_INTERNAL-32 "ReceivingSlitBox1-_Axis"
*MEAS_COND_AXIS_NAME_INTERNAL-33 "ReceivingSlitBox2-_Axis"
*MEAS_COND_AXIS_NAME_INTERNAL-34 "ReceivingSlitBox2-Zd"
*MEAS_COND_AXIS_NAME_INTERNAL-35 "Attenuator"
*MEAS_COND_AXIS_NAME_INTERNAL-36 "CounterMonochromator"
*MEAS_COND_AXIS_NAME_INTERNAL-37 "CounterSlit"
*MEAS_COND_AXIS_NAME_INTERNAL-38 "TwoThetaB"
*MEAS_COND_AXIS_NAME_INTERNAL-39 "AlphaR"
*MEAS_COND_AXIS_NAME_INTERNAL-40 "BetaR"
*MEAS_COND_AXIS_NAME_INTERNAL-41 "ReceivingSlitBox1-Zr"
*MEAS_COND_AXIS_NAME_INTERNAL-42 "IncidentPrimary"
*MEAS_COND_AXIS_NAME_MAGICNO-0 "83951616.0000000000"
*MEAS_COND_AXIS_NAME_MAGICNO-1 "268632064.0000000000"
*MEAS_COND_AXIS_NAME_MAGICNO-2 "268500992.0000000000"
*MEAS_COND_AXIS_NAME_MAGICNO-3 "268500992.0000000000"
*MEAS_COND_AXIS_NAME_MAGICNO-4 "268500992.0000000000"
*MEAS_COND_AXIS_NAME_MAGICNO-5 "285278208.0000000000"
*MEAS_COND_AXIS_NAME_MAGICNO-6 "268500992.0000000000"
*MEAS_COND_AXIS_NAME_MAGICNO-7 "268500992.0000000000"
*MEAS_COND_AXIS_NAME_MAGICNO-8 "83951616.0000000000"
*MEAS_COND_AXIS_NAME_MAGICNO-9 "268632064.0000000000"
*MEAS_COND_AXIS_NAME_MAGICNO-10 "83951616.0000000000"
*MEAS_COND_AXIS_NAME_MAGICNO-11 "17039360.0000000000"
*MEAS_COND_AXIS_NAME_MAGICNO-12 "17039360.0000000000"
*MEAS_COND_AXIS_NAME_MAGICNO-13 "131072.0000000000"
*MEAS_COND_AXIS_NAME_MAGICNO-14 "131072.0000000000"
*MEAS_COND_AXIS_NAME_MAGICNO-15 "318898176.0000000000"
*MEAS_COND_AXIS_NAME_MAGICNO-16 "20971521.0000000000"
*MEAS_COND_AXIS_NAME_MAGICNO-17 "285343744.0000000000"
*MEAS_COND_AXIS_NAME_MAGICNO-18 "20971521.0000000000"
*MEAS_COND_AXIS_NAME_MAGICNO-19 "22020097.0000000000"
*MEAS_COND_AXIS_NAME_MAGICNO-20 "25165824.0000000000"
*MEAS_COND_AXIS_NAME_MAGICNO-21 "318898176.0000000000"
*MEAS_COND_AXIS_NAME_MAGICNO-22 "20971521.0000000000"
*MEAS_COND_AXIS_NAME_MAGICNO-23 "285343744.0000000000"
*MEAS_COND_AXIS_NAME_MAGICNO-24 "20971521.0000000000"
*MEAS_COND_AXIS_NAME_MAGICNO-25 "20971521.0000000000"
*MEAS_COND_AXIS_NAME_MAGICNO-26 "20971521.0000000000"
*MEAS_COND_AXIS_NAME_MAGICNO-27 "23068673.0000000000"
*MEAS_COND_AXIS_NAME_MAGICNO-28 "23068673.0000000000"
*MEAS_COND_AXIS_NAME_MAGICNO-29 "20971521.0000000000"
*MEAS_COND_AXIS_NAME_MAGICNO-30 "20971521.0000000000"
*MEAS_COND_AXIS_NAME_MAGICNO-31 "20971521.0000000000"
*MEAS_COND_AXIS_NAME_MAGICNO-32 "25165824.0000000000"
*MEAS_COND_AXIS_NAME_MAGICNO-33 "25165824.0000000000"
*MEAS_COND_AXIS_NAME_MAGICNO-34 "285343744.0000000000"
*MEAS_COND_AXIS_NAME_MAGICNO-35 "0.0000000000"
*MEAS_COND_AXIS_NAME_MAGICNO-36 "20971521.0000000000"
*MEAS_COND_AXIS_NAME_MAGICNO-37 "20971521.0000000000"
*MEAS_COND_AXIS_NAME_MAGICNO-38 "17039360.0000000000"
*MEAS_COND_AXIS_NAME_MAGICNO-39 "8388608.0000000000"
*MEAS_COND_AXIS_NAME_MAGICNO-40 "8388608.0000000000"
*MEAS_COND_AXIS_NAME_MAGICNO-41 "285343744.0000000000"
*MEAS_COND_AXIS_NAME_MAGICNO-42 "20971521.0000000000"
*MEAS_COND_AXIS_OFFSET-0 "-"
*MEAS_COND_AXIS_OFFSET-1 "0.0000000000"
*MEAS_COND_AXIS_OFFSET-2 "0.0000000000"
*MEAS_COND_AXIS_OFFSET-3 "0.0000000000"
*MEAS_COND_AXIS_OFFSET-4 "0.0000000000"
*MEAS_COND_AXIS_OFFSET-5 "-"
*MEAS_COND_AXIS_OFFSET-6 "0.0000000000"
*MEAS_COND_AXIS_OFFSET-7 "0.0000000000"
*MEAS_COND_AXIS_OFFSET-8 "-"
*MEAS_COND_AXIS_OFFSET-9 "0.0000000000"
*MEAS_COND_AXIS_OFFSET-10 "-"
*MEAS_COND_AXIS_OFFSET-11 "-"
*MEAS_COND_AXIS_OFFSET-12 "-"
*MEAS_COND_AXIS_OFFSET-13 "0.0000000000"
*MEAS_COND_AXIS_OFFSET-14 "0.0000000000"
*MEAS_COND_AXIS_OFFSET-15 "-"
*MEAS_COND_AXIS_OFFSET-16 "-"
*MEAS_COND_AXIS_OFFSET-17 "-"
*MEAS_COND_AXIS_OFFSET-18 "-"
*MEAS_COND_AXIS_OFFSET-19 "-"
*MEAS_COND_AXIS_OFFSET-20 "-"
*MEAS_COND_AXIS_OFFSET-21 "-"
*MEAS_COND_AXIS_OFFSET-22 "-"
*MEAS_COND_AXIS_OFFSET-23 "-"
*MEAS_COND_AXIS_OFFSET-24 "-"
*MEAS_COND_AXIS_OFFSET-25 "-"
*MEAS_COND_AXIS_OFFSET-26 "-"
*MEAS_COND_AXIS_OFFSET-27 "-"
*MEAS_COND_AXIS_OFFSET-28 "-"
*MEAS_COND_AXIS_OFFSET-29 "-"
*MEAS_COND_AXIS_OFFSET-30 "-"
*MEAS_COND_AXIS_OFFSET-31 "-"
*MEAS_COND_AXIS_OFFSET-32 "-"
*MEAS_COND_AXIS_OFFSET-33 "-"
*MEAS_COND_AXIS_OFFSET-34 "-"
*MEAS_COND_AXIS_OFFSET-35 "-"
*MEAS_COND_AXIS_OFFSET-36 "-"
*MEAS_COND_AXIS_OFFSET-37 "-"
*MEAS_COND_AXIS_OFFSET-38 "-"
*MEAS_COND_AXIS_OFFSET-39 "0.0000000000"
*MEAS_COND_AXIS_OFFSET-40 "0.0000000000"
*MEAS_COND_AXIS_OFFSET-41 "-"
*MEAS_COND_AXIS_OFFSET-42 "-"
*MEAS_COND_AXIS_POSITION-0 "40.0000000000"
*MEAS_COND_AXIS_POSITION-1 "40.0000000000"
*MEAS_COND_AXIS_POSITION-2 "20.0000000000"
*MEAS_COND_AXIS_POSITION-3 "0.0000000000"
*MEAS_COND_AXIS_POSITION-4 "0.0000000000"
*MEAS_COND_AXIS_POSITION-5 "-2.1742000000"
*MEAS_COND_AXIS_POSITION-6 "0.8650000000"
*MEAS_COND_AXIS_POSITION-7 "2.2205000000"
*MEAS_COND_AXIS_POSITION-8 "40.0000000000"
*MEAS_COND_AXIS_POSITION-9 "0.0000000000"
*MEAS_COND_AXIS_POSITION-10 "0.0000000000"
*MEAS_COND_AXIS_POSITION-11 "90.0000000000"
*MEAS_COND_AXIS_POSITION-12 "0.0000000000"
*MEAS_COND_AXIS_POSITION-13 "20.0000000000"
*MEAS_COND_AXIS_POSITION-14 "20.0000000000"
*MEAS_COND_AXIS_POSITION-15 "-5.5000000000"
*MEAS_COND_AXIS_POSITION-16 "PB"
*MEAS_COND_AXIS_POSITION-17 "0.0000000000"
*MEAS_COND_AXIS_POSITION-18 "Soller_slit_5.0deg_s"
*MEAS_COND_AXIS_POSITION-19 "1.000mm"
*MEAS_COND_AXIS_POSITION-20 "1.0000000000"
*MEAS_COND_AXIS_POSITION-21 "-1.5000000000"
*MEAS_COND_AXIS_POSITION-22 "Ge(220)x2"
*MEAS_COND_AXIS_POSITION-23 "0.0000000000"
*MEAS_COND_AXIS_POSITION-24 "0.5mm"
*MEAS_COND_AXIS_POSITION-25 "None"
*MEAS_COND_AXIS_POSITION-26 "None"
*MEAS_COND_AXIS_POSITION-27 "20.000mm"
*MEAS_COND_AXIS_POSITION-28 "38.500mm"
*MEAS_COND_AXIS_POSITION-29 "PSA_open"
*MEAS_COND_AXIS_POSITION-30 "Soller_slit_5.0deg"
*MEAS_COND_AXIS_POSITION-31 "None"
*MEAS_COND_AXIS_POSITION-32 "20.0000000000"
*MEAS_COND_AXIS_POSITION-33 "38.5000000000"
*MEAS_COND_AXIS_POSITION-34 "0.0000000000"
*MEAS_COND_AXIS_POSITION-35 "-"
*MEAS_COND_AXIS_POSITION-36 "No_unit"
*MEAS_COND_AXIS_POSITION-37 "None"
*MEAS_COND_AXIS_POSITION-38 "40.0000000000"
*MEAS_COND_AXIS_POSITION-39 "0.0000000000"
*MEAS_COND_AXIS_POSITION-40 "0.0000000000"
*MEAS_COND_AXIS_POSITION-41 "0.0000000000"
*MEAS_COND_AXIS_POSITION-42 "None"
*MEAS_COND_AXIS_UNIT-0 "deg"
*MEAS_COND_AXIS_UNIT-1 "deg"
*MEAS_COND_AXIS_UNIT-2 "deg"
*MEAS_COND_AXIS_UNIT-3 "deg"
*MEAS_COND_AXIS_UNIT-4 "deg"
*MEAS_COND_AXIS_UNIT-5 "mm"
*MEAS_COND_AXIS_UNIT-6 "mm"
*MEAS_COND_AXIS_UNIT-7 "mm"
*MEAS_COND_AXIS_UNIT-8 "deg"
*MEAS_COND_AXIS_UNIT-9 "deg"
*MEAS_COND_AXIS_UNIT-10 "deg"
*MEAS_COND_AXIS_UNIT-11 "deg"
*MEAS_COND_AXIS_UNIT-12 "deg"
*MEAS_COND_AXIS_UNIT-13 "deg"
*MEAS_COND_AXIS_UNIT-14 "deg"
*MEAS_COND_AXIS_UNIT-15 "mm"
*MEAS_COND_AXIS_UNIT-16 ""
*MEAS_COND_AXIS_UNIT-17 "pulse"
*MEAS_COND_AXIS_UNIT-18 ""
*MEAS_COND_AXIS_UNIT-19 ""
*MEAS_COND_AXIS_UNIT-20 "mm"
*MEAS_COND_AXIS_UNIT-21 "mm"
*MEAS_COND_AXIS_UNIT-22 ""
*MEAS_COND_AXIS_UNIT-23 "pulse"
*MEAS_COND_AXIS_UNIT-24 ""
*MEAS_COND_AXIS_UNIT-25 ""
*MEAS_COND_AXIS_UNIT-26 ""
*MEAS_COND_AXIS_UNIT-27 ""
*MEAS_COND_AXIS_UNIT-28 ""
*MEAS_COND_AXIS_UNIT-29 ""
*MEAS_COND_AXIS_UNIT-30 ""
*MEAS_COND_AXIS_UNIT-31 ""
*MEAS_COND_AXIS_UNIT-32 "mm"
*MEAS_COND_AXIS_UNIT-33 "mm"
*MEAS_COND_AXIS_UNIT-34 "mm"
*MEAS_COND_AXIS_UNIT-35 ""
*MEAS_COND_AXIS_UNIT-36 ""
*MEAS_COND_AXIS_UNIT-37 ""
*MEAS_COND_AXIS_UNIT-38 "deg"
*MEAS_COND_AXIS_UNIT-39 "deg"
*MEAS_COND_AXIS_UNIT-40 "deg"
*MEAS_COND_AXIS_UNIT-41 "mm"
*MEAS_COND_AXIS_UNIT-42 ""
*MEAS_COND_COUNTER_CNTLOSS_CORR "0.0000000000"
*MEAS_COND_COUNTER_TAUDIFF "0.0000000000"
*MEAS_COND_COUNTER_TAUINT "0.0000000000"
*MEAS_COND_COUNTER_TEMP_CONDITION "NORMAL"
*MEAS_COND_IRRADIATION_MODE "OFF"
*MEAS_COND_IRRADIATION_WIDTH ""
*MEAS_COND_OPT_ATTR "High resolution parallel beam Ge(220)x2/RS"
*MEAS_COND_OPT_NAME "@High resolution PB-Ge(220)x2"
*MEAS_COND_UNSYMMETRIC_MODE "OFF"
*MEAS_COND_XG_CURRENT "30.0000000000"
*MEAS_COND_XG_VOLTAGE "40.0000000000"
*MEAS_COND_XG_WAVE_TYPE "Ka1"
*MEAS_DATA_COUNT "8000.0000000000"
*MEAS_SCAN_AXIS_X "Theta/2-Theta"
*MEAS_SCAN_AXIS_X_INTERNAL "TwoThetaTheta"
*MEAS_SCAN_END_TIME "04/30/22 08:27:24"
*MEAS_SCAN_MODE "CONTINUOUS"
*MEAS_SCAN_MONITOR "0"
*MEAS_SCAN_RESOLUTION_X "0.0002"
*MEAS_SCAN_SPEED "0.503240"
*MEAS_SCAN_SPEED_UNIT "deg/min"
*MEAS_SCAN_SPEED_USER "0.5"
*MEAS_SCAN_START "40.0000000000"
*MEAS_SCAN_START_TIME "04/30/22 05:32:35"
*MEAS_SCAN_STEP "0.0100000000"
*MEAS_SCAN_STOP "119.9900000000"
*MEAS_SCAN_UNIT_X "deg"
*MEAS_SCAN_UNIT_Y "counts"
*RAS_HEADER_END
*RAS_INT_START
40.0000 11.4277 1.0000
40.0600 7.1787 1.0000
40.1200 13.8557 1.0000
40.1800 11.3651 1.0000
40.2400 12.6694 1.0000
40.3000 12.6544 1.0000
40.3600 7.0250 1.0000
40.4200 8.7199 1.0000
40.4800 13.4111 1.0000
40.5400 15.2531 1.0000
40.6000 8.4348 1.0000
40.6600 8.2758 1.0000
40.7200 11.6213 1.0000
40.7800 4.7312 1.0000
40.8400 11.9679 1.0000
40.9000 7.5009 1.0000
40.9600 8.7475 1.0000
41.0200 20.8478 1.0000
41.0800 10.0317 1.0000
41.1400 13.8845 1.0000
41.2000 9.9537 1.0000
41.2600 14.2447 1.0000
41.3200 16.3066 1.0000
41.3800 19.4831 1.0000
41.4400 14.2713 1.0000
41.5000 11.6355 1.0000
41.5600 12.4395 1.0000
41.6200 8.5197 1.0000
41.6800 7.0081 1.0000
41.7400 11.3280 1.0000
41.8000 2.5374 1.0000
41.8600 9.3507 1.0000
41.9200 6.1075 1.0000
41.9800 9.2914 1.0000
42.0400 8.8405 1.0000
42.1000 10.9535 1.0000
42.1600 11.1878 1.0000
42.2200 9.7766 1.0000
42.2800 6.4030 1.0000
42.3400 8.2140 1.0000
42.4000 11.1182 1.0000
42.4600 11.3521 1.0000
42.5200 11.3300 1.0000
42.5800 16.4966 1.0000
42.6400 18.9832 1.0000
42.7000 11.6672 1.0000
42.7600 13.8422 1.0000
42.8200 7.7072 1.0000
42.8800 8.1894 1.0000
42.9400 9.1837 1.0000
43.0000 7.8111 1.0000
43.0600 14.5742 1.0000
43.1200 4.6495 1.0000
43.1800 12.2665 1.0000
43.2400 9.5104 1.0000
43.3000 7.4485 1.0000
43.3600 16.9986 1.0000
43.4200 10.0056 1.0000
43.4800 16.0148 1.0000
43.5400 13.5604 1.0000
43.6000 11.4339 1.0000
43.6600 16.0504 1.0000
43.7200 13.1513 1.0000
43.7800 10.0500 1.0000
43.8400 9.5400 1.0000
43.9000 8.3241 1.0000
43.9600 7.5235 1.0000
44.0200 11.6243 1.0000
44.0800 10.5548 1.0000
44.1400 16.0084 1.0000
44.2000 13.7906 1.0000
44.2600 10.0591 1.0000
44.3200 13.5434 1.0000
44.3800 10.8940 1.0000
44.4400 11.1586 1.0000
44.5000 13.2819 1.0000
44.5600 17.4419 1.0000
44.6200 8.0746 1.0000
44.6800 11.4148 1.0000
44.7400 11.8380 1.0000
44.8000 13.4024 1.0000
44.8600 11.6967 1.0000
44.9200 7.4875 1.0000
44.9800 7.8361 1.0000
45.0400 11.3883 1.0000
45.1000 9.4166 1.0000
45.1600 9.4568 1.0000
45.2200 19.1342 1.0000
45.2800 20.8915 1.0000
45.3400 37.3600 1.0000
45.4000 96.9555 1.0000
45.4600 389.1736 1.0000
45.5200 649.7037 1.0000
45.5800 486.1970 1.0000
45.6400 101.2492 1.0000
45.7000 31.5461 1.0000
45.7600 16.6861 1.0000
45.8200 10.4550 1.0000
45.8800 19.8346 1.0000
45.9400 21.0805 1.0000
46.0000 17.7186 1.0000
46.0600 13.8547 1.0000
46.1200 8.6123 1.0000
46.1800 15.6571 1.0000
46.2400 10.0376 1.0000
46.3000 7.8806 1.0000
46.3600 15.3075 1.0000
46.4200 7.6036 1.0000
46.4800 11.2054 1.0000
46.5400 10.5092 1.0000
46.6000 12.0427 1.0000
46.6600 11.7444 1.0000
46.7200 12.5807 1.0000
46.7800 10.2467 1.0000
46.8400 9.9174 1.0000
46.9000 7.7210 1.0000
46.9600 14.8740 1.0000
47.0200 5.7274 1.0000
47.0800 11.6564 1.0000
47.1400 8.4811 1.0000
47.2000 8.8348 1.0000
47.2600 9.2308 1.0000
47.3200 11.1488 1.0000
47.3800 6.4279 1.0000
47.4400 8.7727 1.0000
47.5000 9.5985 1.0000
47.5600 18.4283 1.0000
47.6200 7.6003 1.0000
47.6800 3.4489 1.0000
47.7400 8.9581 1.0000
47.8000 8.2392 1.0000
47.8600 6.8633 1.0000
47.9200 19.7632 1.0000
47.9800 10.0441 1.0000
48.0400 5.9559 1.0000
48.1000 6.9748 1.0000
48.1600 8.2712 1.0000
48.2200 8.9041 1.0000
48.2800 8.4938 1.0000
48.3400 8.5216 1.0000
48.4000 5.8617 1.0000
48.4600 14.3361 1.0000
48.5200 20.1067 1.0000
48.5800 9.1373 1.0000
48.6400 14.5988 1.0000
48.7000 15.3160 1.0000
48.7600 7.4839 1.0000
48.8200 11.7807 1.0000
48.8800 6.9506 1.0000
48.9400 7.8111 1.0000
49.0000 6.1787 1.0000
49.0600 5.2055 1.0000
49.1200 14.0522 1.0000
49.1800 12.5894 1.0000
49.2400 13.7157 1.0000
49.3000 4.8607 1.0000
49.3600 7.7994 1.0000
49.4200 7.5315 1.0000
49.4800 13.5755 1.0000
49.5400 14.6679 1.0000
49.6000 10.3884 1.0000
49.6600 9.1306 1.0000
49.7200 4.3761 1.0000
49.7800 8.0746 1.0000
49.8400 6.2927 1.0000
49.9000 7.2062 1.0000
49.9600 15.9854 1.0000
50.0200 15.8608 1.0000
50.0800 7.7918 1.0000
50.1400 5.3308 1.0000
50.2000 6.6988 1.0000
50.2600 6.8479 1.0000
50.3200 15.6776 1.0000
50.3800 11.4768 1.0000
50.4400 12.5228 1.0000
50.5000 6.9677 1.0000
50.5600 10.5242 1.0000
50.6200 7.5280 1.0000
50.6800 6.2337 1.0000
50.7400 7.2279 1.0000
50.8000 10.9945 1.0000
50.8600 13.6634 1.0000
50.9200 8.1506 1.0000
50.9800 13.4570 1.0000
51.0400 8.0655 1.0000
51.1000 8.7904 1.0000
51.1600 9.9478 1.0000
51.2200 10.2449 1.0000
51.2800 6.5914 1.0000
51.3400 6.1639 1.0000
51.4000 9.2021 1.0000
51.4600 10.5740 1.0000
51.5200 10.1011 1.0000
51.5800 8.4692 1.0000
51.6400 17.9404 1.0000
51.7000 10.9314 1.0000
51.7600 7.9462 1.0000
51.8200 13.9405 1.0000
51.8800 7.2097 1.0000
51.9400 5.8792 1.0000
52.0000 5.0760 1.0000
52.0600 10.4000 1.0000
52.1200 10.4481 1.0000
52.1800 6.1297 1.0000
52.2400 16.4474 1.0000
52.3000 10.0601 1.0000
52.3600 8.4911 1.0000
52.4200 10.4565 1.0000
52.4800 10.9802 1.0000
52.5400 7.8058 1.0000
52.6000 12.6400 1.0000
52.6600 17.7053 1.0000
52.7200 9.9188 1.0000
52.7800 15.0642 1.0000
52.8400 14.0877 1.0000
52.9000 6.4889 1.0000
52.9600 11.2356 1.0000
53.0200 8.5420 1.0000
53.0800 8.4089 1.0000
53.1400 5.6442 1.0000
53.2000 5.0034 1.0000
53.2600 8.9275 1.0000
53.3200 8.4155 1.0000
53.3800 6.1759 1.0000
53.4400 12.3049 1.0000
53.5000 7.2484 1.0000
53.5600 12.1310 1.0000
53.6200 11.2079 1.0000
53.6800 14.1264 1.0000
53.7400 6.0303 1.0000
53.8000 13.9059 1.0000
53.8600 9.2537 1.0000
53.9200 11.4895 1.0000
53.9800 16.2170 1.0000
54.0400 12.9118 1.0000
54.1000 7.2842 1.0000
54.1600 12.0605 1.0000
54.2200 11.9702 1.0000
54.2800 6.7370 1.0000
54.3400 8.2348 1.0000
54.4000 10.5446 1.0000
54.4600 11.2208 1.0000
54.5200 9.7821 1.0000
54.5800 8.1378 1.0000
54.6400 6.9495 1.0000
54.7000 4.3082 1.0000
54.7600 6.0807 1.0000
54.8200 12.2379 1.0000
54.8800 5.1667 1.0000
54.9400 6.7568 1.0000
55.0000 5.6721 1.0000
55.0600 8.0315 1.0000
55.1200 9.0776 1.0000
55.1800 12.0240 1.0000
55.2400 7.0219 1.0000
55.3000 9.3943 1.0000
55.3600 8.9262 1.0000
55.4200 9.1177 1.0000
55.4800 5.8679 1.0000
55.5400 9.6368 1.0000
55.6000 11.3737 1.0000
55.6600 7.1520 1.0000
55.7200 8.9191 1.0000
55.7800 7.7394 1.0000
55.8400 9.8823 1.0000
55.9000 14.7160 1.0000
55.9600 8.5546 1.0000
56.0200 11.1238 1.0000
56.0800 10.5758 1.0000
56.1400 12.3838 1.0000
56.2000 5.0269 1.0000
56.2600 3.6762 1.0000
56.3200 8.7277 1.0000
56.3800 9.1188 1.0000
56.4400 11.6146 1.0000
56.5000 10.4550 1.0000
56.5600 8.0110 1.0000
56.6200 3.7367 1.0000
56.6800 11.5408 1.0000
56.7400 10.7359 1.0000
56.8000 6.9134 1.0000
56.8600 4.2240 1.0000
56.9200 10.2206 1.0000
56.9800 6.5550 1.0000
57.0400 15.4107 1.0000
57.1000 8.0774 1.0000
57.1600 5.9525 1.0000
57.2200 6.3521 1.0000
57.2800 11.9707 1.0000
57.3400 7.5054 1.0000
57.4000 11.2600 1.0000
57.4600 10.2580 1.0000
57.5200 12.7213 1.0000
57.5800 9.6423 1.0000
57.6400 4.3715 1.0000
57.7000 8.1450 1.0000
57.7600 19.4420 1.0000
57.8200 10.9989 1.0000
57.8800 6.1972 1.0000
57.9400 9.4606 1.0000
58.0000 18.7550 1.0000
58.0600 13.5357 1.0000
58.1200 9.5504 1.0000
58.1800 12.6913 1.0000
58.2400 9.0515 1.0000
58.3000 7.6485 1.0000
58.3600 15.1150 1.0000
58.4200 9.3261 1.0000
58.4800 11.0222 1.0000
58.5400 11.8664 1.0000
58.6000 18.0954 1.0000
58.6600 15.4438 1.0000
58.7200 7.5940 1.0000
58.7800 8.6564 1.0000
58.8400 9.8771 1.0000
58.9000 12.6109 1.0000
58.9600 5.7882 1.0000
59.0200 5.2788 1.0000
59.0800 4.8600 1.0000
59.1400 14.6797 1.0000
59.2000 8.3123 1.0000
59.2600 9.1268 1.0000
59.3200 3.0734 1.0000
59.3800 5.2471 1.0000
59.4400 6.3277 1.0000
59.5000 8.0985 1.0000
59.5600 18.3465 1.0000
59.6200 5.7718 1.0000
59.6800 11.1228 1.0000
59.7400 13.6263 1.0000
59.8000 5.8954 1.0000
59.8600 13.0256 1.0000
59.9200 9.4234 1.0000
59.9800 7.4222 1.0000
60.0400 6.5891 1.0000
60.1000 8.5420 1.0000
60.1600 6.0460 1.0000
60.2200 7.1333 1.0000
60.2800 5.4101 1.0000
60.3400 5.4869 1.0000
60.4000 3.3467 1.0000
60.4600 7.4305 1.0000
60.5200 9.1663 1.0000
60.5800 9.7337 1.0000
60.6400 7.9741 1.0000
60.7000 11.9012 1.0000
60.7600 6.4720 1.0000
60.8200 13.4189 1.0000
60.8800 6.4694 1.0000
60.9400 8.9946 1.0000
61.0000 9.3456 1.0000
61.0600 9.1848 1.0000
61.1200 7.2887 1.0000
61.1800 5.0833 1.0000
61.2400 10.3361 1.0000
61.3000 7.0261 1.0000
61.3600 16.6084 1.0000
61.4200 5.9148 1.0000
61.4800 11.7615 1.0000
61.5400 6.6560 1.0000
61.6000 13.8051 1.0000
61.6600 9.4480 1.0000
61.7200 8.5733 1.0000
61.7800 5.3600 1.0000
61.8400 6.1659 1.0000
61.9000 6.4439 1.0000
61.9600 4.0619 1.0000
62.0200 9.0170 1.0000
62.0800 12.5743 1.0000
62.1400 11.9401 1.0000
62.2000 10.2623 1.0000
62.2600 9.2214 1.0000
62.3200 10.7903 1.0000
62.3800 11.1080 1.0000
62.4400 6.9935 1.0000
62.5000 7.6192 1.0000
62.5600 8.1989 1.0000
62.6200 6.0193 1.0000
62.6800 8.6132 1.0000
62.7400 8.9165 1.0000
62.8000 6.5379 1.0000
62.8600 11.1690 1.0000
62.9200 9.9710 1.0000
62.9800 6.2468 1.0000
63.0400 9.1565 1.0000
63.1000 7.6019 1.0000
63.1600 5.2900 1.0000
63.2200 2.3985 1.0000
63.2800 8.2202 1.0000
63.3400 19.4134 1.0000
63.4000 6.1988 1.0000
63.4600 10.8351 1.0000
63.5200 5.8548 1.0000
63.5800 4.2872 1.0000
63.6400 6.5760 1.0000
63.7000 6.9055 1.0000
63.7600 10.8419 1.0000
63.8200 7.7078 1.0000
63.8800 3.7221 1.0000
63.9400 7.6584 1.0000
64.0000 5.1231 1.0000
64.0600 5.7949 1.0000
64.1200 11.1094 1.0000
64.1800 6.8422 1.0000
64.2400 12.4071 1.0000
64.3000 11.6796 1.0000
64.3600 7.9936 1.0000
64.4200 4.2801 1.0000
64.4800 9.1652 1.0000
64.5400 6.2676 1.0000
64.6000 2.7545 1.0000
64.6600 10.4049 1.0000
64.7200 10.2757 1.0000
64.7800 7.4448 1.0000
64.8400 9.5876 1.0000
64.9000 12.4124 1.0000
64.9600 9.4953 1.0000
65.0200 17.2363 1.0000
65.0800 9.3515 1.0000
65.1400 7.3620 1.0000
65.2000 6.4715 1.0000
65.2600 10.2525 1.0000
65.3200 14.8003 1.0000
65.3800 6.6367 1.0000
65.4400 8.8934 1.0000
65.5000 14.2471 1.0000
65.5600 9.6479 1.0000
65.6200 14.6626 1.0000
65.6800 23.6667 1.0000
65.7400 41.0916 1.0000
65.8000 33.7781 1.0000
65.8600 32.1399 1.0000
65.9200 22.0482 1.0000
65.9800 9.3771 1.0000
66.0400 10.1211 1.0000
66.1000 7.4736 1.0000
66.1600 10.7623 1.0000
66.2200 7.3742 1.0000
66.2800 10.6026 1.0000
66.3400 16.1026 1.0000
66.4000 3.9813 1.0000
66.4600 7.7950 1.0000
66.5200 13.6935 1.0000
66.5800 9.0926 1.0000
66.6400 18.1209 1.0000
66.7000 12.7782 1.0000
66.7600 8.9582 1.0000
66.8200 6.9376 1.0000
66.8800 6.9331 1.0000
66.9400 9.4270 1.0000
67.0000 3.2754 1.0000
67.0600 3.9112 1.0000
67.1200 6.1512 1.0000
67.1800 16.0993 1.0000
67.2400 5.0086 1.0000
67.3000 11.7329 1.0000
67.3600 7.9774 1.0000
67.4200 10.3113 1.0000
67.4800 8.0063 1.0000
67.5400 12.8094 1.0000
67.6000 10.2082 1.0000
67.6600 8.0564 1.0000
67.7200 11.2699 1.0000
67.7800 3.8621 1.0000
67.8400 8.6064 1.0000
67.9000 6.1047 1.0000
67.9600 6.4249 1.0000
68.0200 4.7943 1.0000
68.0800 9.7872 1.0000
68.1400 7.5051 1.0000
68.2000 9.4024 1.0000
68.2600 2.5940 1.0000
68.3200 11.8863 1.0000
68.3800 7.7754 1.0000
68.4400 8.7778 1.0000
68.5000 10.1135 1.0000
68.5600 19.7130 1.0000
68.6200 8.8373 1.0000
68.6800 5.7077 1.0000
68.7400 4.5653 1.0000
68.8000 8.8828 1.0000
68.8600 7.4092 1.0000
68.9200 9.1595 1.0000
68.9800 11.1928 1.0000
69.0400 8.2624 1.0000
69.1000 8.1506 1.0000
69.1600 9.2912 1.0000
69.2200 8.8269 1.0000
69.2800 6.3381 1.0000
69.3400 6.9531 1.0000
69.4000 9.1858 1.0000
69.4600 7.6419 1.0000
69.5200 8.7833 1.0000
69.5800 6.7292 1.0000
69.6400 10.9974 1.0000
69.7000 8.6848 1.0000
69.7600 10.7759 1.0000
69.8200 10.1086 1.0000
69.8800 20.8745 1.0000
69.9400 7.1036 1.0000
70.0000 5.5101 1.0000
70.0600 10.7309 1.0000
70.1200 6.4300 1.0000
70.1800 6.2639 1.0000
70.2400 12.9819 1.0000
70.3000 7.0526 1.0000
70.3600 8.0109 1.0000
70.4200 8.6604 1.0000
70.4800 9.0932 1.0000
70.5400 11.6359 1.0000
70.6000 11.5558 1.0000
70.6600 8.8757 1.0000
70.7200 7.3295 1.0000
70.7800 8.0705 1.0000
70.8400 10.2709 1.0000
70.9000 14.0262 1.0000
70.9600 7.3698 1.0000
71.0200 7.2376 1.0000
71.0800 10.8039 1.0000
71.1400 6.5376 1.0000
71.2000 7.5590 1.0000
71.2600 11.0448 1.0000
71.3200 8.3565 1.0000
71.3800 3.9117 1.0000
71.4400 7.3977 1.0000
71.5000 3.9792 1.0000
71.5600 8.3722 1.0000
71.6200 7.2671 1.0000
71.6800 6.7962 1.0000
71.7400 7.2695 1.0000
71.8000 13.1734 1.0000
71.8600 8.2498 1.0000
71.9200 2.8780 1.0000
71.9800 8.5239 1.0000
72.0400 6.5476 1.0000
72.1000 4.7988 1.0000
72.1600 4.3656 1.0000
72.2200 3.5132 1.0000
72.2800 6.2957 1.0000
72.3400 10.1019 1.0000
72.4000 6.5010 1.0000
72.4600 5.2517 1.0000
72.5200 11.0713 1.0000
72.5800 5.3393 1.0000
72.6400 6.8699 1.0000
72.7000 10.4429 1.0000
72.7600 2.8826 1.0000
72.8200 8.1790 1.0000
72.8800 10.2859 1.0000
72.9400 7.0916 1.0000
73.0000 6.4736 1.0000
73.0600 9.8772 1.0000
73.1200 6.5262 1.0000
73.1800 9.1539 1.0000
73.2400 10.5093 1.0000
73.3000 3.7733 1.0000
73.3600 4.8299 1.0000
73.4200 5.7675 1.0000
73.4800 5.5473 1.0000
73.5400 9.6907 1.0000
73.6000 7.7121 1.0000
73.6600 6.9555 1.0000
73.7200 8.4062 1.0000
73.7800 6.1303 1.0000
73.8400 9.2930 1.0000
73.9000 11.5451 1.0000
73.9600 7.6481 1.0000
74.0200 7.1039 1.0000
74.0800 6.3064 1.0000
74.1400 9.0893 1.0000
74.2000 6.0605 1.0000
74.2600 11.0170 1.0000
74.3200 9.6848 1.0000
74.3800 8.3976 1.0000
74.4400 11.2420 1.0000
74.5000 8.5161 1.0000
74.5600 5.6362 1.0000
74.6200 8.0142 1.0000
74.6800 9.9596 1.0000
74.7400 6.6701 1.0000
74.8000 7.5842 1.0000
74.8600 7.8288 1.0000
74.9200 5.7519 1.0000
74.9800 4.1833 1.0000
75.0400 8.6842 1.0000
75.1000 9.3111 1.0000
75.1600 12.0099 1.0000
75.2200 15.4789 1.0000
75.2800 7.7102 1.0000
75.3400 5.2329 1.0000
75.4000 9.3018 1.0000
75.4600 6.7359 1.0000
75.5200 8.2902 1.0000
75.5800 3.0174 1.0000
75.6400 7.5023 1.0000
75.7000 3.2172 1.0000
75.7600 12.3780 1.0000
75.8200 7.2171 1.0000
75.8800 5.9394 1.0000
75.9400 8.1057 1.0000
76.0000 13.1755 1.0000
76.0600 7.2559 1.0000
76.1200 9.3625 1.0000
76.1800 10.9183 1.0000
76.2400 4.9862 1.0000
76.3000 7.9279 1.0000
76.3600 6.5943 1.0000
76.4200 9.1376 1.0000
76.4800 3.4460 1.0000
76.5400 4.7939 1.0000
76.6000 2.2626 1.0000
76.6600 5.4979 1.0000
76.7200 9.1650 1.0000
76.7800 4.3261 1.0000
76.8400 4.0816 1.0000
76.9000 3.3162 1.0000
76.9600 8.8776 1.0000
77.0200 3.4777 1.0000
77.0800 7.8129 1.0000
77.1400 6.1631 1.0000
77.2000 6.0730 1.0000
77.2600 10.6411 1.0000
77.3200 7.3440 1.0000
77.3800 8.4577 1.0000
77.4400 9.0970 1.0000
77.5000 19.5709 1.0000
77.5600 9.1778 1.0000
77.6200 3.3828 1.0000
77.6800 7.5560 1.0000
77.7400 7.3515 1.0000
77.8000 5.5563 1.0000
77.8600 13.4578 1.0000
77.9200 1.5958 1.0000
77.9800 3.3798 1.0000
78.0400 7.5780 1.0000
78.1000 8.6525 1.0000
78.1600 11.6348 1.0000
78.2200 17.2510 1.0000
78.2800 4.6441 1.0000
78.3400 6.8070 1.0000
78.4000 7.0370 1.0000
78.4600 9.2680 1.0000
78.5200 8.8896 1.0000
78.5800 10.0906 1.0000
78.6400 7.1552 1.0000
78.7000 6.3963 1.0000
78.7600 11.1285 1.0000
78.8200 7.3382 1.0000
78.8800 8.3553 1.0000
78.9400 14.6047 1.0000
79.0000 11.5796 1.0000
79.0600 7.1486 1.0000
79.1200 7.6233 1.0000
79.1800 5.6293 1.0000
79.2400 8.1597 1.0000
79.3000 9.7565 1.0000
79.3600 7.1881 1.0000
79.4200 6.8824 1.0000
79.4800 7.5678 1.0000
79.5400 10.4577 1.0000
79.6000 9.9058 1.0000
79.6600 8.2797 1.0000
79.7200 11.7268 1.0000
79.7800 13.1249 1.0000
79.8400 8.2283 1.0000
79.9000 5.9824 1.0000
79.9600 12.7677 1.0000
80.0200 8.7660 1.0000
80.0800 7.5603 1.0000
80.1400 6.3195 1.0000
80.2000 9.1778 1.0000
80.2600 10.1763 1.0000
80.3200 6.4269 1.0000
80.3800 6.0602 1.0000
80.4400 9.2363 1.0000
80.5000 7.5103 1.0000
80.5600 12.1806 1.0000
80.6200 8.3149 1.0000
80.6800 10.5985 1.0000
80.7400 7.2109 1.0000
80.8000 8.0370 1.0000
80.8600 8.2119 1.0000
80.9200 11.6688 1.0000
80.9800 6.1027 1.0000
81.0400 11.5677 1.0000
81.1000 8.3207 1.0000
81.1600 7.3275 1.0000
81.2200 5.2365 1.0000
81.2800 6.7335 1.0000
81.3400 11.7036 1.0000
81.4000 8.4135 1.0000
81.4600 8.1463 1.0000
81.5200 2.6802 1.0000
81.5800 14.2678 1.0000
81.6400 11.8816 1.0000
81.7000 8.2272 1.0000
81.7600 12.5678 1.0000
81.8200 6.9636 1.0000
81.8800 5.2214 1.0000
81.9400 1.2478 1.0000
82.0000 5.3289 1.0000
82.0600 7.7981 1.0000
82.1200 7.8844 1.0000
82.1800 7.1507 1.0000
82.2400 13.1558 1.0000
82.3000 12.7312 1.0000
82.3600 13.4794 1.0000
82.4200 6.2554 1.0000
82.4800 8.3223 1.0000
82.5400 16.5325 1.0000
82.6000 16.4915 1.0000
82.6600 12.0076 1.0000
82.7200 4.3049 1.0000
82.7800 11.7439 1.0000
82.8400 8.6548 1.0000
82.9000 21.1756 1.0000
82.9600 41.0236 1.0000
83.0200 65.4434 1.0000
83.0800 76.2600 1.0000
83.1400 39.2170 1.0000
83.2000 22.2218 1.0000
83.2600 11.8630 1.0000
83.3200 8.4223 1.0000
83.3800 18.2359 1.0000
83.4400 5.0911 1.0000
83.5000 5.4417 1.0000
83.5600 6.7203 1.0000
83.6200 3.9450 1.0000
83.6800 10.2049 1.0000
83.7400 6.3602 1.0000
83.8000 5.3804 1.0000
83.8600 5.0933 1.0000
83.9200 3.8640 1.0000
83.9800 6.0652 1.0000
84.0400 7.2727 1.0000
84.1000 8.9136 1.0000
84.1600 12.0687 1.0000
84.2200 2.4614 1.0000
84.2800 11.5646 1.0000
84.3400 10.6486 1.0000
84.4000 12.7287 1.0000
84.4600 5.1521 1.0000
84.5200 6.5473 1.0000
84.5800 7.4593 1.0000
84.6400 10.2344 1.0000
84.7000 4.4048 1.0000
84.7600 5.3630 1.0000
84.8200 6.8775 1.0000
84.8800 7.0981 1.0000
84.9400 6.9069 1.0000
85.0000 6.3176 1.0000
85.0600 1.4201 1.0000
85.1200 6.2133 1.0000
85.1800 9.1236 1.0000
85.2400 9.8303 1.0000
85.3000 9.4412 1.0000
85.3600 7.5136 1.0000
85.4200 4.4886 1.0000
85.4800 7.3738 1.0000
85.5400 8.2960 1.0000
85.6000 10.5716 1.0000
85.6600 7.4698 1.0000
85.7200 10.3513 1.0000
85.7800 4.1535 1.0000
85.8400 6.9931 1.0000
85.9000 6.1184 1.0000
85.9600 9.0598 1.0000
86.0200 4.5587 1.0000
86.0800 6.5506 1.0000
86.1400 2.5781 1.0000
86.2000 12.1687 1.0000
86.2600 14.9834 1.0000
86.3200 5.5502 1.0000
86.3800 8.5613 1.0000
86.4400 9.9591 1.0000
86.5000 11.8063 1.0000
86.5600 6.6775 1.0000
86.6200 12.1459 1.0000
86.6800 5.5450 1.0000
86.7400 10.9404 1.0000
86.8000 6.7196 1.0000
86.8600 11.3796 1.0000
86.9200 8.3785 1.0000
86.9800 3.9204 1.0000
87.0400 6.6910 1.0000
87.1000 8.1443 1.0000
87.1600 11.5981 1.0000
87.2200 11.9034 1.0000
87.2800 11.1386 1.0000
87.3400 7.6473 1.0000
87.4000 4.3181 1.0000
87.4600 9.9448 1.0000
87.5200 13.0331 1.0000
87.5800 6.2992 1.0000
87.6400 8.8200 1.0000
87.7000 6.8445 1.0000
87.7600 11.9301 1.0000
87.8200 8.0307 1.0000
87.8800 13.8595 1.0000
87.9400 15.3856 1.0000
88.0000 5.3479 1.0000
88.0600 11.9119 1.0000
88.1200 5.8044 1.0000
88.1800 4.8769 1.0000
88.2400 11.3516 1.0000
88.3000 8.3006 1.0000
88.3600 9.3997 1.0000
88.4200 4.0747 1.0000
88.4800 3.1158 1.0000
88.5400 8.6309 1.0000
88.6000 8.5030 1.0000
88.6600 9.2628 1.0000
88.7200 7.8330 1.0000
88.7800 6.0589 1.0000
88.8400 9.0357 1.0000
88.9000 10.1498 1.0000
88.9600 7.0599 1.0000
89.0200 2.3262 1.0000
89.0800 7.3230 1.0000
89.1400 14.2260 1.0000
89.2000 4.6189 1.0000
89.2600 6.9458 1.0000
89.3200 8.2087 1.0000
89.3800 10.8723 1.0000
89.4400 6.6633 1.0000
89.5000 6.3249 1.0000
89.5600 7.7267 1.0000
89.6200 3.8055 1.0000
89.6800 6.8361 1.0000
89.7400 8.0786 1.0000
89.8000 8.5034 1.0000
89.8600 10.0669 1.0000
89.9200 12.8056 1.0000
89.9800 6.8011 1.0000
90.0400 21.9694 1.0000
90.1000 9.8235 1.0000
90.1600 10.4293 1.0000
90.2200 6.2817 1.0000
90.2800 11.7415 1.0000
90.3400 7.0516 1.0000
90.4000 8.0335 1.0000
90.4600 7.7257 1.0000
90.5200 6.8597 1.0000
90.5800 23.4072 1.0000
90.6400 5.8326 1.0000
90.7000 3.9760 1.0000
90.7600 6.7467 1.0000
90.8200 11.8467 1.0000
90.8800 9.6715 1.0000
90.9400 13.5798 1.0000
91.0000 3.0555 1.0000
91.0600 10.1103 1.0000
91.1200 17.1699 1.0000
91.1800 10.7996 1.0000
91.2400 13.7847 1.0000
91.3000 3.2207 1.0000
91.3600 9.0745 1.0000
91.4200 8.4220 1.0000
91.4800 11.1797 1.0000
91.5400 5.4442 1.0000
91.6000 9.7781 1.0000
91.6600 8.9986 1.0000
91.7200 11.1654 1.0000
91.7800 9.4720 1.0000
91.8400 2.3367 1.0000
91.9000 6.9955 1.0000
91.9600 7.1993 1.0000
92.0200 4.5804 1.0000
92.0800 13.1074 1.0000
92.1400 5.6263 1.0000
92.2000 5.6455 1.0000
92.2600 6.6995 1.0000
92.3200 10.9849 1.0000
92.3800 8.4406 1.0000
92.4400 3.0811 1.0000
92.5000 13.1035 1.0000
92.5600 9.1766 1.0000
92.6200 9.0283 1.0000
92.6800 8.0645 1.0000
92.7400 9.9243 1.0000
92.8000 3.1063 1.0000
92.8600 5.0273 1.0000
92.9200 6.1830 1.0000
92.9800 10.7762 1.0000
93.0400 6.9160 1.0000
93.1000 9.1788 1.0000
93.1600 9.0909 1.0000
93.2200 3.4966 1.0000
93.2800 12.2099 1.0000
93.3400 5.3419 1.0000
93.4000 6.4773 1.0000
93.4600 9.7846 1.0000
93.5200 6.8180 1.0000
93.5800 7.7478 1.0000
93.6400 4.9629 1.0000
93.7000 10.3504 1.0000
93.7600 5.2292 1.0000
93.8200 6.9396 1.0000
93.8800 8.4133 1.0000
93.9400 10.9973 1.0000
94.0000 7.0165 1.0000
94.0600 11.9972 1.0000
94.1200 6.6945 1.0000
94.1800 11.8211 1.0000
94.2400 4.3743 1.0000
94.3000 4.5228 1.0000
94.3600 4.5771 1.0000
94.4200 2.5224 1.0000
94.4800 12.6468 1.0000
94.5400 18.7250 1.0000
94.6000 11.9439 1.0000
94.6600 4.7559 1.0000
94.7200 5.3166 1.0000
94.7800 7.3104 1.0000
94.8400 4.3457 1.0000
94.9000 5.9783 1.0000
94.9600 10.4761 1.0000
95.0200 2.7920 1.0000
95.0800 13.0195 1.0000
95.1400 9.3564 1.0000
95.2000 7.2352 1.0000
95.2600 8.1107 1.0000
95.3200 15.3127 1.0000
95.3800 5.3989 1.0000
95.4400 12.1499 1.0000
95.5000 5.5819 1.0000
95.5600 7.0314 1.0000
95.6200 8.6307 1.0000
95.6800 6.5804 1.0000
95.7400 9.3954 1.0000
95.8000 6.0973 1.0000
95.8600 8.6098 1.0000
95.9200 11.3590 1.0000
95.9800 9.8962 1.0000
96.0400 8.8384 1.0000
96.1000 20.1486 1.0000
96.1600 5.2975 1.0000
96.2200 6.7338 1.0000
96.2800 10.1465 1.0000
96.3400 7.6579 1.0000
96.4000 4.7286 1.0000
96.4600 5.5313 1.0000
96.5200 13.4493 1.0000
96.5800 5.5270 1.0000
96.6400 7.9344 1.0000
96.7000 6.2803 1.0000
96.7600 6.3646 1.0000
96.8200 6.0844 1.0000
96.8800 7.4973 1.0000
96.9400 10.6182 1.0000
97.0000 6.3659 1.0000
97.0600 7.2127 1.0000
97.1200 8.2655 1.0000
97.1800 7.5074 1.0000
97.2400 13.2492 1.0000
97.3000 5.5277 1.0000
97.3600 8.9729 1.0000
97.4200 4.1188 1.0000
97.4800 5.7880 1.0000
97.5400 4.4746 1.0000
97.6000 5.6788 1.0000
97.6600 15.2989 1.0000
97.7200 10.3923 1.0000
97.7800 7.2135 1.0000
97.8400 6.1402 1.0000
97.9000 7.7684 1.0000
97.9600 3.1006 1.0000
98.0200 5.4670 1.0000
98.0800 10.8027 1.0000
98.1400 12.4606 1.0000
98.2000 6.6529 1.0000
98.2600 6.4495 1.0000
98.3200 13.2894 1.0000
98.3800 8.7034 1.0000
98.4400 10.5234 1.0000
98.5000 11.3488 1.0000
98.5600 8.3044 1.0000
98.6200 5.3083 1.0000
98.6800 10.4647 1.0000
98.7400 10.2829 1.0000
98.8000 5.2810 1.0000
98.8600 5.0165 1.0000
98.9200 14.2082 1.0000
98.9800 2.9477 1.0000
99.0400 4.1652 1.0000
99.1000 8.9787 1.0000
99.1600 8.7358 1.0000
99.2200 6.8455 1.0000
99.2800 6.4573 1.0000
99.3400 12.0581 1.0000
99.4000 8.9348 1.0000
99.4600 14.9779 1.0000
99.5200 37.7049 1.0000
99.5800 48.0447 1.0000
99.6400 33.3774 1.0000
99.7000 21.0582 1.0000
99.7600 11.3519 1.0000
99.8200 9.6904 1.0000
99.8800 10.7814 1.0000
99.9400 5.8518 1.0000
100.0000 8.2582 1.0000
100.0600 12.2925 1.0000
100.1200 7.2768 1.0000
100.1800 12.8071 1.0000
100.2400 7.6195 1.0000
100.3000 8.7607 1.0000
100.3600 13.5310 1.0000
100.4200 6.5864 1.0000
100.4800 6.8577 1.0000
100.5400 14.0415 1.0000
100.6000 12.9595 1.0000
100.6600 6.9530 1.0000
100.7200 6.4582 1.0000
100.7800 5.1344 1.0000
100.8400 3.7040 1.0000
100.9000 9.6470 1.0000
100.9600 8.1053 1.0000
101.0200 9.2945 1.0000
101.0800 10.2060 1.0000
101.1400 6.4124 1.0000
101.2000 5.1852 1.0000
101.2600 3.8939 1.0000
101.3200 5.3803 1.0000
101.3800 6.8774 1.0000
101.4400 6.3987 1.0000
101.5000 13.4336 1.0000
101.5600 6.3428 1.0000
101.6200 11.0096 1.0000
101.6800 8.2288 1.0000
101.7400 6.2489 1.0000
101.8000 7.8932 1.0000
101.8600 12.9542 1.0000
101.9200 10.5287 1.0000
101.9800 9.4383 1.0000
102.0400 15.5614 1.0000
102.1000 8.2482 1.0000
102.1600 6.0823 1.0000
102.2200 9.2036 1.0000
102.2800 9.4131 1.0000
102.3400 6.4847 1.0000
102.4000 6.7364 1.0000
102.4600 7.1857 1.0000
102.5200 8.5227 1.0000
102.5800 5.0225 1.0000
102.6400 7.1602 1.0000
102.7000 6.9392 1.0000
102.7600 8.4842 1.0000
102.8200 11.6676 1.0000
102.8800 11.8995 1.0000
102.9400 9.7521 1.0000
103.0000 12.1219 1.0000
103.0600 4.5599 1.0000
103.1200 10.6532 1.0000
103.1800 4.1414 1.0000
103.2400 2.7080 1.0000
103.3000 11.9574 1.0000
103.3600 7.5091 1.0000
103.4200 5.5441 1.0000
103.4800 6.8049 1.0000
103.5400 6.6419 1.0000
103.6000 7.8383 1.0000
103.6600 5.4728 1.0000
103.7200 7.6320 1.0000
103.7800 4.7201 1.0000
103.8400 6.1285 1.0000
103.9000 3.8810 1.0000
103.9600 7.9737 1.0000
104.0200 12.5040 1.0000
104.0800 7.7976 1.0000
104.1400 7.4861 1.0000
104.2000 7.1835 1.0000
104.2600 3.0230 1.0000
104.3200 9.9321 1.0000
104.3800 7.6452 1.0000
104.4400 5.6050 1.0000
104.5000 11.8940 1.0000
104.5600 5.5049 1.0000
104.6200 8.6937 1.0000
104.6800 7.3524 1.0000
104.7400 10.3309 1.0000
104.8000 12.1097 1.0000
104.8600 9.4626 1.0000
104.9200 5.2604 1.0000
104.9800 5.8658 1.0000
105.0400 5.7863 1.0000
105.1000 3.5177 1.0000
105.1600 4.3714 1.0000
105.2200 14.7155 1.0000
105.2800 6.0895 1.0000
105.3400 4.2940 1.0000
105.4000 8.4182 1.0000
105.4600 13.1702 1.0000
105.5200 7.8995 1.0000
105.5800 9.6330 1.0000
105.6400 17.7701 1.0000
105.7000 11.3954 1.0000
105.7600 10.3143 1.0000
105.8200 13.3662 1.0000
105.8800 5.4006 1.0000
105.9400 12.2962 1.0000
106.0000 7.0568 1.0000
106.0600 6.3152 1.0000
106.1200 11.0534 1.0000
106.1800 8.7642 1.0000
106.2400 8.8053 1.0000
106.3000 3.5916 1.0000
106.3600 6.0155 1.0000
106.4200 8.1064 1.0000
106.4800 12.2613 1.0000
106.5400 7.2300 1.0000
106.6000 4.6197 1.0000
106.6600 10.8030 1.0000
106.7200 6.8446 1.0000
106.7800 7.4150 1.0000
106.8400 8.4669 1.0000
106.9000 5.1978 1.0000
106.9600 7.0229 1.0000
107.0200 7.4320 1.0000
107.0800 3.7810 1.0000
107.1400 7.3532 1.0000
107.2000 5.1049 1.0000
107.2600 4.3419 1.0000
107.3200 5.0879 1.0000
107.3800 6.0633 1.0000
107.4400 7.6096 1.0000
107.5000 4.6786 1.0000
107.5600 7.9513 1.0000
107.6200 3.3951 1.0000
107.6800 11.8006 1.0000
[...]
67.3600 4.7888 1.0000
67.4200 12.6570 1.0000
67.4800 12.9928 1.0000
67.5400 8.2828 1.0000
67.6000 15.2583 1.0000
67.6600 8.1152 1.0000
67.7200 5.4576 1.0000
67.7800 8.6229 1.0000
67.8400 7.0257 1.0000
67.9000 11.5627 1.0000
67.9600 11.5686 1.0000
68.0200 7.8310 1.0000
68.0800 7.4131 1.0000
68.1400 6.7719 1.0000
68.2000 9.5350 1.0000
68.2600 9.4557 1.0000
68.3200 6.6131 1.0000
68.3800 13.7122 1.0000
68.4400 7.1526 1.0000
68.5000 6.9233 1.0000
68.5600 10.7870 1.0000
68.6200 4.9974 1.0000
68.6800 7.9324 1.0000
68.7400 7.6850 1.0000
68.8000 11.0487 1.0000
68.8600 11.4414 1.0000
68.9200 7.8739 1.0000
68.9800 9.3401 1.0000
69.0400 6.1250 1.0000
69.1000 5.6026 1.0000
69.1600 9.2241 1.0000
69.2200 8.7855 1.0000
69.2800 7.9067 1.0000
69.3400 11.1211 1.0000
69.4000 13.4881 1.0000
69.4600 13.5580 1.0000
69.5200 10.9239 1.0000
69.5800 8.8154 1.0000
69.6400 5.7032 1.0000
69.7000 12.7178 1.0000
69.7600 3.0561 1.0000
69.8200 7.3895 1.0000
69.8800 8.6219 1.0000
69.9400 3.6785 1.0000
70.0000 6.1589 1.0000
70.0600 4.8540 1.0000
70.1200 6.0933 1.0000
70.1800 5.1273 1.0000
70.2400 5.1760 1.0000
70.3000 9.2468 1.0000
70.3600 11.0708 1.0000
70.4200 6.3405 1.0000
70.4800 8.3893 1.0000
70.5400 8.6013 1.0000
70.6000 11.8746 1.0000
70.6600 12.5175 1.0000
70.7200 11.6607 1.0000
70.7800 7.1756 1.0000
70.8400 11.0343 1.0000
70.9000 10.3387 1.0000
70.9600 11.0996 1.0000
71.0200 10.3051 1.0000
71.0800 5.4179 1.0000
71.1400 6.3977 1.0000
71.2000 9.6485 1.0000
71.2600 10.5996 1.0000
71.3200 9.1236 1.0000
71.3800 9.1467 1.0000
71.4400 9.8465 1.0000
71.5000 8.5771 1.0000
71.5600 6.7039 1.0000
71.6200 6.5544 1.0000
71.6800 5.3816 1.0000
71.7400 6.3635 1.0000
71.8000 11.2373 1.0000
71.8600 13.3149 1.0000
71.9200 9.6485 1.0000
71.9800 6.8511 1.0000
72.0400 4.4350 1.0000
72.1000 5.7440 1.0000
72.1600 7.1959 1.0000
72.2200 7.6827 1.0000
72.2800 7.9010 1.0000
72.3400 5.3699 1.0000
72.4000 10.5581 1.0000
72.4600 8.7056 1.0000
72.5200 5.4673 1.0000
72.5800 9.9623 1.0000
72.6400 9.8342 1.0000
72.7000 14.0243 1.0000
72.7600 10.0839 1.0000
72.8200 9.2563 1.0000
72.8800 8.7664 1.0000
72.9400 6.9355 1.0000
73.0000 8.6676 1.0000
73.0600 6.5814 1.0000
73.1200 3.6262 1.0000
73.1800 8.1473 1.0000
73.2400 6.3791 1.0000
73.3000 6.5712 1.0000
73.3600 6.6775 1.0000
73.4200 9.1116 1.0000
73.4800 8.8982 1.0000
73.5400 7.0534 1.0000
73.6000 9.2241 1.0000
73.6600 8.9216 1.0000
73.7200 11.7127 1.0000
73.7800 2.4784 1.0000
73.8400 12.2056 1.0000
73.9000 5.0488 1.0000
73.9600 4.4819 1.0000
74.0200 10.6412 1.0000
74.0800 8.7408 1.0000
74.1400 5.2883 1.0000
74.2000 6.8188 1.0000
74.2600 16.3639 1.0000
74.3200 9.2741 1.0000
74.3800 5.7691 1.0000
74.4400 8.0749 1.0000
74.5000 10.6473 1.0000
74.5600 8.5202 1.0000
74.6200 13.4731 1.0000
74.6800 9.6757 1.0000
74.7400 10.9694 1.0000
74.8000 10.1702 1.0000
74.8600 5.9088 1.0000
74.9200 6.1683 1.0000
74.9800 10.7061 1.0000
75.0400 4.9949 1.0000
75.1000 8.3041 1.0000
75.1600 4.7769 1.0000
75.2200 6.2410 1.0000
75.2800 9.7967 1.0000
75.3400 9.1761 1.0000
75.4000 8.3607 1.0000
75.4600 10.6093 1.0000
75.5200 4.6898 1.0000
75.5800 6.8017 1.0000
75.6400 13.0970 1.0000
75.7000 9.3249 1.0000
75.7600 5.3355 1.0000
75.8200 10.9426 1.0000
75.8800 8.4553 1.0000
75.9400 7.0029 1.0000
76.0000 5.7469 1.0000
76.0600 4.0566 1.0000
76.1200 6.3590 1.0000
76.1800 11.2016 1.0000
76.2400 11.1895 1.0000
76.3000 8.4790 1.0000
76.3600 6.3609 1.0000
76.4200 9.5750 1.0000
76.4800 9.2296 1.0000
76.5400 8.6692 1.0000
76.6000 9.3545 1.0000
76.6600 10.2105 1.0000
76.7200 14.8253 1.0000
76.7800 12.0581 1.0000
76.8400 13.5915 1.0000
76.9000 10.4633 1.0000
76.9600 6.4683 1.0000
77.0200 7.5882 1.0000
77.0800 9.5272 1.0000
77.1400 17.5777 1.0000
77.2000 8.7809 1.0000
77.2600 5.3293 1.0000
77.3200 7.4170 1.0000
77.3800 3.8630 1.0000
77.4400 8.3000 1.0000
77.5000 10.3087 1.0000
77.5600 6.0863 1.0000
77.6200 8.4547 1.0000
77.6800 7.2278 1.0000
77.7400 12.7050 1.0000
77.8000 8.2491 1.0000
77.8600 7.2874 1.0000
77.9200 6.5388 1.0000
77.9800 9.1655 1.0000
78.0400 7.6685 1.0000
78.1000 4.9151 1.0000
78.1600 12.2854 1.0000
78.2200 10.1373 1.0000
78.2800 4.2119 1.0000
78.3400 5.6335 1.0000
78.4000 3.6587 1.0000
78.4600 9.7929 1.0000
78.5200 7.1663 1.0000
78.5800 6.5854 1.0000
78.6400 7.4852 1.0000
78.7000 8.0253 1.0000
78.7600 6.8347 1.0000
78.8200 7.3347 1.0000
78.8800 10.7483 1.0000
78.9400 13.9970 1.0000
79.0000 10.1183 1.0000
79.0600 7.6694 1.0000
79.1200 12.5341 1.0000
79.1800 13.3488 1.0000
79.2400 11.9083 1.0000
79.3000 6.6141 1.0000
79.3600 10.7004 1.0000
79.4200 5.7524 1.0000
79.4800 7.6915 1.0000
79.5400 8.4572 1.0000
79.6000 9.6389 1.0000
79.6600 10.0825 1.0000
79.7200 6.0697 1.0000
79.7800 7.3182 1.0000
79.8400 12.4549 1.0000
79.9000 16.2045 1.0000
79.9600 4.9174 1.0000
80.0200 5.2997 1.0000
80.0800 6.4713 1.0000
80.1400 11.2416 1.0000
80.2000 12.3720 1.0000
80.2600 12.6112 1.0000
80.3200 4.5701 1.0000
80.3800 9.4129 1.0000
80.4400 3.6348 1.0000
80.5000 10.5049 1.0000
80.5600 12.9795 1.0000
80.6200 8.7983 1.0000
80.6800 14.5376 1.0000
80.7400 8.4508 1.0000
80.8000 13.0954 1.0000
80.8600 5.5560 1.0000
80.9200 5.3932 1.0000
80.9800 6.3811 1.0000
81.0400 6.5611 1.0000
81.1000 6.9876 1.0000
81.1600 5.2763 1.0000
81.2200 13.5564 1.0000
81.2800 5.3059 1.0000
81.3400 5.8527 1.0000
81.4000 9.9690 1.0000
81.4600 6.9441 1.0000
81.5200 9.3178 1.0000
81.5800 11.1284 1.0000
81.6400 10.7572 1.0000
81.7000 6.0478 1.0000
81.7600 7.3609 1.0000
81.8200 4.5665 1.0000
81.8800 5.1249 1.0000
81.9400 7.7528 1.0000
82.0000 10.2479 1.0000
82.0600 4.8304 1.0000
82.1200 5.0402 1.0000
82.1800 6.8662 1.0000
82.2400 9.0066 1.0000
82.3000 4.1119 1.0000
82.3600 9.9787 1.0000
82.4200 5.7496 1.0000
82.4800 7.4119 1.0000
82.5400 10.3295 1.0000
82.6000 9.1534 1.0000
82.6600 6.7112 1.0000
82.7200 13.1784 1.0000
82.7800 10.6268 1.0000
82.8400 17.0401 1.0000
82.9000 17.5210 1.0000
82.9600 38.2183 1.0000
83.0200 57.2075 1.0000
83.0800 55.3661 1.0000
83.1400 49.6300 1.0000
83.2000 27.5352 1.0000
83.2600 14.4364 1.0000
83.3200 14.2258 1.0000
83.3800 5.3695 1.0000
83.4400 9.2261 1.0000
83.5000 4.9930 1.0000
83.5600 3.5734 1.0000
83.6200 11.3503 1.0000
83.6800 15.1437 1.0000
83.7400 9.9020 1.0000
83.8000 10.1766 1.0000
83.8600 7.1464 1.0000
83.9200 11.3218 1.0000
83.9800 8.0298 1.0000
84.0400 8.7754 1.0000
84.1000 9.4536 1.0000
84.1600 6.6627 1.0000
84.2200 7.6573 1.0000
84.2800 11.6062 1.0000
84.3400 3.1243 1.0000
84.4000 5.8949 1.0000
84.4600 5.0148 1.0000
84.5200 7.7419 1.0000
84.5800 10.9477 1.0000
84.6400 14.4628 1.0000
84.7000 8.4580 1.0000
84.7600 9.4769 1.0000
84.8200 7.9861 1.0000
84.8800 7.4553 1.0000
84.9400 11.6794 1.0000
85.0000 7.4995 1.0000
85.0600 1.7952 1.0000
85.1200 14.0745 1.0000
85.1800 5.3966 1.0000
85.2400 5.3143 1.0000
85.3000 8.2447 1.0000
85.3600 9.6088 1.0000
85.4200 7.1747 1.0000
85.4800 11.5013 1.0000
85.5400 9.9810 1.0000
85.6000 4.2195 1.0000
85.6600 8.1452 1.0000
85.7200 10.0994 1.0000
85.7800 9.8879 1.0000
85.8400 8.7021 1.0000
85.9000 10.6800 1.0000
85.9600 5.7535 1.0000
86.0200 9.2432 1.0000
86.0800 7.9566 1.0000
86.1400 11.9981 1.0000
86.2000 10.3890 1.0000
86.2600 3.3403 1.0000
86.3200 13.1273 1.0000
86.3800 10.9543 1.0000
86.4400 10.4186 1.0000
86.5000 6.9333 1.0000
86.5600 10.8089 1.0000
86.6200 12.1800 1.0000
86.6800 8.8331 1.0000
86.7400 8.0916 1.0000
86.8000 5.7589 1.0000
86.8600 13.4658 1.0000
86.9200 4.8733 1.0000
86.9800 9.3377 1.0000
87.0400 10.0873 1.0000
87.1000 3.4288 1.0000
87.1600 4.6173 1.0000
87.2200 9.6543 1.0000
87.2800 5.2694 1.0000
87.3400 12.2279 1.0000
87.4000 9.5215 1.0000
87.4600 6.8614 1.0000
87.5200 12.7980 1.0000
87.5800 6.5201 1.0000
87.6400 9.8643 1.0000
87.7000 11.7041 1.0000
87.7600 10.7357 1.0000
87.8200 7.4587 1.0000
87.8800 8.3831 1.0000
87.9400 9.0242 1.0000
88.0000 12.1871 1.0000
88.0600 5.7692 1.0000
88.1200 8.1362 1.0000
88.1800 4.2017 1.0000
88.2400 12.1471 1.0000
88.3000 10.4783 1.0000
88.3600 13.2929 1.0000
88.4200 15.6274 1.0000
88.4800 9.1183 1.0000
88.5400 4.5325 1.0000
88.6000 5.6948 1.0000
88.6600 5.8514 1.0000
88.7200 6.9952 1.0000
88.7800 9.1486 1.0000
88.8400 14.0156 1.0000
88.9000 9.3270 1.0000
88.9600 16.3751 1.0000
89.0200 3.7927 1.0000
89.0800 3.5147 1.0000
89.1400 6.6705 1.0000
89.2000 11.2409 1.0000
89.2600 5.1136 1.0000
89.3200 6.9743 1.0000
89.3800 11.7007 1.0000
89.4400 8.5737 1.0000
89.5000 5.7357 1.0000
89.5600 9.3370 1.0000
89.6200 9.0642 1.0000
89.6800 5.8724 1.0000
89.7400 8.4384 1.0000
89.8000 11.6707 1.0000
89.8600 7.2362 1.0000
89.9200 13.7635 1.0000
89.9800 5.3817 1.0000
90.0400 10.0430 1.0000
90.1000 11.9117 1.0000
90.1600 9.6803 1.0000
90.2200 12.7803 1.0000
90.2800 5.6831 1.0000
90.3400 7.9669 1.0000
90.4000 4.7432 1.0000
90.4600 3.3902 1.0000
90.5200 15.1975 1.0000
90.5800 9.6580 1.0000
90.6400 5.6539 1.0000
90.7000 14.3027 1.0000
90.7600 9.9530 1.0000
90.8200 8.2293 1.0000
90.8800 8.8645 1.0000
90.9400 5.9150 1.0000
91.0000 10.9678 1.0000
91.0600 4.8749 1.0000
91.1200 5.1850 1.0000
91.1800 5.9054 1.0000
91.2400 7.6173 1.0000
91.3000 9.0145 1.0000
91.3600 7.3104 1.0000
91.4200 12.7337 1.0000
91.4800 5.5383 1.0000
91.5400 9.4787 1.0000
91.6000 10.2334 1.0000
91.6600 10.9878 1.0000
91.7200 8.1128 1.0000
91.7800 5.2496 1.0000
91.8400 8.7739 1.0000
91.9000 6.7978 1.0000
91.9600 5.6837 1.0000
92.0200 8.9599 1.0000
92.0800 8.9556 1.0000
92.1400 7.8949 1.0000
92.2000 11.7585 1.0000
92.2600 3.9607 1.0000
92.3200 9.4090 1.0000
92.3800 5.7618 1.0000
92.4400 4.8885 1.0000
92.5000 4.5288 1.0000
92.5600 5.4859 1.0000
92.6200 5.4410 1.0000
92.6800 5.5916 1.0000
92.7400 5.8349 1.0000
92.8000 11.1081 1.0000
92.8600 6.8011 1.0000
92.9200 12.4428 1.0000
92.9800 4.8037 1.0000
93.0400 8.5351 1.0000
93.1000 2.9814 1.0000
93.1600 8.4751 1.0000
93.2200 10.9558 1.0000
93.2800 6.5170 1.0000
93.3400 3.5896 1.0000
93.4000 7.0580 1.0000
93.4600 6.5118 1.0000
93.5200 5.2959 1.0000
93.5800 7.2390 1.0000
93.6400 7.7935 1.0000
93.7000 8.6586 1.0000
93.7600 11.5584 1.0000
93.8200 9.2580 1.0000
93.8800 14.5639 1.0000
93.9400 8.0605 1.0000
94.0000 9.4025 1.0000
94.0600 6.2175 1.0000
94.1200 13.2133 1.0000
94.1800 2.1646 1.0000
94.2400 5.4022 1.0000
94.3000 6.4421 1.0000
94.3600 8.7437 1.0000
94.4200 12.7522 1.0000
94.4800 8.6940 1.0000
94.5400 7.5669 1.0000
94.6000 8.2455 1.0000
94.6600 8.2118 1.0000
94.7200 6.2991 1.0000
94.7800 6.5000 1.0000
94.8400 5.9722 1.0000
94.9000 4.1194 1.0000
94.9600 9.5347 1.0000
95.0200 2.3047 1.0000
95.0800 6.4712 1.0000
95.1400 3.9137 1.0000
95.2000 6.1513 1.0000
95.2600 9.6120 1.0000
95.3200 7.7292 1.0000
95.3800 10.8183 1.0000
95.4400 2.9205 1.0000
95.5000 11.2391 1.0000
95.5600 13.2707 1.0000
95.6200 4.7640 1.0000
95.6800 10.3604 1.0000
95.7400 5.2242 1.0000
95.8000 9.2766 1.0000
95.8600 8.7510 1.0000
95.9200 8.4148 1.0000
95.9800 8.0103 1.0000
96.0400 4.6666 1.0000
96.1000 3.2882 1.0000
96.1600 9.4513 1.0000
96.2200 6.9913 1.0000
96.2800 12.0259 1.0000
96.3400 4.9882 1.0000
96.4000 6.1264 1.0000
96.4600 5.8397 1.0000
96.5200 5.1623 1.0000
96.5800 10.7662 1.0000
96.6400 9.4915 1.0000
96.7000 6.7870 1.0000
96.7600 9.2511 1.0000
96.8200 6.7592 1.0000
96.8800 4.6908 1.0000
96.9400 8.9644 1.0000
97.0000 8.5561 1.0000
97.0600 7.5218 1.0000
97.1200 7.2641 1.0000
97.1800 4.6095 1.0000
97.2400 3.8175 1.0000
97.3000 4.8155 1.0000
97.3600 15.2137 1.0000
97.4200 11.6591 1.0000
97.4800 6.1753 1.0000
97.5400 7.0358 1.0000
97.6000 6.9687 1.0000
97.6600 7.8142 1.0000
97.7200 6.4081 1.0000
97.7800 1.2004 1.0000
97.8400 3.7371 1.0000
97.9000 7.1655 1.0000
97.9600 6.3338 1.0000
98.0200 11.5011 1.0000
98.0800 4.3641 1.0000
98.1400 10.2831 1.0000
98.2000 8.1645 1.0000
98.2600 4.6608 1.0000
98.3200 7.0016 1.0000
98.3800 17.8551 1.0000
98.4400 5.9890 1.0000
98.5000 5.4395 1.0000
98.5600 13.4201 1.0000
98.6200 6.9233 1.0000
98.6800 8.5575 1.0000
98.7400 5.2759 1.0000
98.8000 6.8161 1.0000
98.8600 5.1180 1.0000
98.9200 5.3057 1.0000
98.9800 5.6300 1.0000
99.0400 6.8088 1.0000
99.1000 8.7258 1.0000
99.1600 5.8339 1.0000
99.2200 6.7015 1.0000
99.2800 3.4171 1.0000
99.3400 11.8426 1.0000
99.4000 9.1189 1.0000
99.4600 27.5702 1.0000
99.5200 27.0104 1.0000
99.5800 36.3267 1.0000
99.6400 35.0667 1.0000
99.7000 33.0304 1.0000
99.7600 17.7194 1.0000
99.8200 5.8463 1.0000
99.8800 7.4187 1.0000
99.9400 7.9558 1.0000
100.0000 5.2796 1.0000
100.0600 6.9173 1.0000
100.1200 9.2250 1.0000
100.1800 15.4422 1.0000
100.2400 9.5172 1.0000
100.3000 8.8825 1.0000
100.3600 12.0923 1.0000
100.4200 13.8960 1.0000
100.4800 10.3435 1.0000
100.5400 9.3640 1.0000
100.6000 8.2519 1.0000
100.6600 7.1310 1.0000
100.7200 9.2418 1.0000
100.7800 15.5720 1.0000
100.8400 6.3117 1.0000
100.9000 6.9550 1.0000
100.9600 5.4126 1.0000
101.0200 6.7277 1.0000
101.0800 9.5461 1.0000
101.1400 5.6167 1.0000
101.2000 8.5876 1.0000
101.2600 4.3828 1.0000
101.3200 8.1591 1.0000
101.3800 4.2322 1.0000
101.4400 7.5993 1.0000
101.5000 10.3484 1.0000
101.5600 5.8913 1.0000
101.6200 7.2663 1.0000
101.6800 4.5135 1.0000
101.7400 4.2993 1.0000
101.8000 8.5104 1.0000
101.8600 6.9828 1.0000
101.9200 12.4573 1.0000
101.9800 4.5072 1.0000
102.0400 4.8841 1.0000
102.1000 8.4071 1.0000
102.1600 6.4844 1.0000
102.2200 3.4128 1.0000
102.2800 7.5961 1.0000
102.3400 4.4887 1.0000
102.4000 7.1619 1.0000
102.4600 3.6447 1.0000
102.5200 11.1281 1.0000
102.5800 11.0830 1.0000
102.6400 7.6719 1.0000
102.7000 6.9914 1.0000
102.7600 6.8342 1.0000
102.8200 10.2231 1.0000
102.8800 7.4974 1.0000
102.9400 7.5184 1.0000
103.0000 10.1649 1.0000
103.0600 7.7858 1.0000
103.1200 8.3292 1.0000
103.1800 5.8377 1.0000
103.2400 6.7803 1.0000
103.3000 10.4144 1.0000
103.3600 6.1502 1.0000
103.4200 10.0997 1.0000
103.4800 7.4791 1.0000
103.5400 3.9528 1.0000
103.6000 5.5873 1.0000
103.6600 5.8320 1.0000
103.7200 10.4440 1.0000
103.7800 7.3999 1.0000
103.8400 3.8771 1.0000
103.9000 7.3926 1.0000
103.9600 5.3584 1.0000
104.0200 10.4110 1.0000
104.0800 7.8587 1.0000
104.1400 6.2257 1.0000
104.2000 11.5508 1.0000
104.2600 10.2640 1.0000
104.3200 9.0298 1.0000
104.3800 6.0739 1.0000
104.4400 10.6268 1.0000
104.5000 8.2898 1.0000
104.5600 9.9977 1.0000
104.6200 12.0817 1.0000
104.6800 4.7296 1.0000
104.7400 3.2435 1.0000
104.8000 4.1267 1.0000
104.8600 9.9371 1.0000
104.9200 7.7955 1.0000
104.9800 8.3060 1.0000
105.0400 8.9602 1.0000
105.1000 7.6154 1.0000
105.1600 5.6256 1.0000
105.2200 9.5930 1.0000
105.2800 7.5357 1.0000
105.3400 9.3249 1.0000
105.4000 5.4296 1.0000
105.4600 4.2788 1.0000
105.5200 9.7940 1.0000
105.5800 18.0560 1.0000
105.6400 8.5578 1.0000
105.7000 5.4297 1.0000
105.7600 4.0899 1.0000
105.8200 11.4144 1.0000
105.8800 9.1369 1.0000
105.9400 7.1760 1.0000
106.0000 3.9598 1.0000
106.0600 7.8514 1.0000
106.1200 9.1092 1.0000
106.1800 12.9506 1.0000
106.2400 5.9908 1.0000
106.3000 6.6331 1.0000
106.3600 6.8037 1.0000
106.4200 6.7905 1.0000
106.4800 6.2354 1.0000
106.5400 10.3547 1.0000
106.6000 24.9630 1.0000
106.6600 10.1053 1.0000
106.7200 7.9992 1.0000
106.7800 9.0784 1.0000
106.8400 12.3003 1.0000
106.9000 10.3354 1.0000
106.9600 9.6848 1.0000
107.0200 8.9419 1.0000
107.0800 11.8928 1.0000
107.1400 8.6380 1.0000
107.2000 10.1697 1.0000
107.2600 7.8081 1.0000
107.3200 11.3692 1.0000
107.3800 6.3734 1.0000
107.4400 3.5398 1.0000
107.5000 3.5232 1.0000
107.5600 8.9470 1.0000
107.6200 13.8078 1.0000
107.6800 6.5595 1.0000
107.7400 4.2237 1.0000
107.8000 7.8809 1.0000
107.8600 3.1151 1.0000
107.9200 5.8383 1.0000
107.9800 7.2169 1.0000
108.0400 7.3664 1.0000
108.1000 18.2208 1.0000
108.1600 11.5669 1.0000
108.2200 10.0792 1.0000
108.2800 9.4299 1.0000
108.3400 8.9972 1.0000
108.4000 7.0372 1.0000
108.4600 6.1581 1.0000
108.5200 4.3658 1.0000
108.5800 10.6074 1.0000
108.6400 6.8395 1.0000
108.7000 6.9460 1.0000
108.7600 5.8337 1.0000
108.8200 3.6118 1.0000
108.8800 8.9265 1.0000
108.9400 14.0052 1.0000
109.0000 2.0389 1.0000
109.0600 7.4300 1.0000
109.1200 5.3587 1.0000
109.1800 8.5031 1.0000
109.2400 6.2886 1.0000
109.3000 5.2644 1.0000
109.3600 9.0124 1.0000
109.4200 8.8418 1.0000
109.4800 5.5855 1.0000
109.5400 2.1225 1.0000
109.6000 11.0861 1.0000
109.6600 7.4292 1.0000
109.7200 10.7943 1.0000
109.7800 10.5663 1.0000
109.8400 5.4440 1.0000
109.9000 4.4915 1.0000
109.9600 7.4954 1.0000
110.0200 8.5471 1.0000
110.0800 13.5344 1.0000
110.1400 9.7592 1.0000
110.2000 8.3745 1.0000
110.2600 11.1402 1.0000
110.3200 9.1415 1.0000
110.3800 7.6678 1.0000
110.4400 13.3776 1.0000
110.5000 8.3338 1.0000
110.5600 7.4635 1.0000
110.6200 6.3012 1.0000
110.6800 9.4524 1.0000
110.7400 7.1010 1.0000
110.8000 6.3418 1.0000
110.8600 4.2223 1.0000
110.9200 9.8362 1.0000
110.9800 7.9753 1.0000
111.0400 4.7567 1.0000
111.1000 4.4797 1.0000
111.1600 6.7209 1.0000
111.2200 7.1861 1.0000
111.2800 7.0454 1.0000
111.3400 6.6400 1.0000
111.4000 3.4970 1.0000
111.4600 6.9058 1.0000
111.5200 5.2629 1.0000
111.5800 8.4564 1.0000
111.6400 7.0910 1.0000
111.7000 5.5780 1.0000
111.7600 7.8679 1.0000
111.8200 8.7373 1.0000
111.8800 11.1705 1.0000
111.9400 10.8774 1.0000
112.0000 11.4513 1.0000
112.0600 6.0263 1.0000
112.1200 8.1142 1.0000
112.1800 1.8708 1.0000
112.2400 4.8379 1.0000
112.3000 5.5926 1.0000
112.3600 7.5651 1.0000
112.4200 12.6214 1.0000
112.4800 5.4418 1.0000
112.5400 5.1189 1.0000
112.6000 10.7621 1.0000
112.6600 8.5281 1.0000
112.7200 5.9290 1.0000
112.7800 9.3201 1.0000
112.8400 11.3557 1.0000
112.9000 9.3860 1.0000
112.9600 6.1728 1.0000
113.0200 9.9868 1.0000
113.0800 6.0978 1.0000
113.1400 11.2925 1.0000
113.2000 4.7825 1.0000
113.2600 13.4885 1.0000
113.3200 11.1801 1.0000
113.3800 9.8512 1.0000
113.4400 8.7166 1.0000
113.5000 3.8188 1.0000
113.5600 5.6711 1.0000
113.6200 9.5011 1.0000
113.6800 11.2157 1.0000
113.7400 16.2654 1.0000
113.8000 11.2648 1.0000
113.8600 7.9894 1.0000
113.9200 7.0294 1.0000
113.9800 12.1005 1.0000
114.0400 8.8241 1.0000
114.1000 5.4784 1.0000
114.1600 10.2769 1.0000
114.2200 12.9427 1.0000
114.2800 7.7321 1.0000
114.3400 4.7879 1.0000
114.4000 6.7921 1.0000
114.4600 4.0366 1.0000
114.5200 11.9751 1.0000
114.5800 11.1315 1.0000
114.6400 9.8761 1.0000
114.7000 9.2916 1.0000
114.7600 6.6924 1.0000
114.8200 6.4386 1.0000
114.8800 10.5768 1.0000
114.9400 11.9607 1.0000
115.0000 9.2661 1.0000
115.0600 10.4713 1.0000
115.1200 13.1076 1.0000
115.1800 10.2516 1.0000
115.2400 7.2773 1.0000
115.3000 7.1755 1.0000
115.3600 7.4228 1.0000
115.4200 6.2100 1.0000
115.4800 13.5423 1.0000
115.5400 10.9850 1.0000
115.6000 4.6589 1.0000
115.6600 5.9026 1.0000
115.7200 2.6052 1.0000
115.7800 13.2105 1.0000
115.8400 9.1474 1.0000
115.9000 3.3022 1.0000
115.9600 7.0366 1.0000
116.0200 10.5052 1.0000
116.0800 8.2433 1.0000
116.1400 4.8949 1.0000
116.2000 6.1605 1.0000
116.2600 7.2786 1.0000
116.3200 4.5256 1.0000
116.3800 11.9600 1.0000
116.4400 14.1590 1.0000
116.5000 11.8539 1.0000
116.5600 12.7664 1.0000
116.6200 8.8415 1.0000
116.6800 15.3886 1.0000
116.7400 13.4688 1.0000
116.8000 28.4732 1.0000
116.8600 22.0338 1.0000
116.9200 28.1436 1.0000
116.9800 26.7906 1.0000
117.0400 22.1684 1.0000
117.1000 14.0030 1.0000
117.1600 17.6410 1.0000
117.2200 7.9811 1.0000
117.2800 12.2389 1.0000
117.3400 4.8280 1.0000
117.4000 6.5051 1.0000
117.4600 9.3622 1.0000
117.5200 10.7426 1.0000
117.5800 11.4495 1.0000
117.6400 9.0533 1.0000
117.7000 5.3469 1.0000
117.7600 6.2212 1.0000
117.8200 6.1047 1.0000
117.8800 6.4287 1.0000
117.9400 8.5941 1.0000
118.0000 4.7797 1.0000
118.0600 7.7865 1.0000
118.1200 7.3524 1.0000
118.1800 6.0207 1.0000
118.2400 5.3856 1.0000
118.3000 8.7015 1.0000
118.3600 12.2496 1.0000
118.4200 6.3075 1.0000
118.4800 4.8368 1.0000
118.5400 5.4314 1.0000
118.6000 11.6838 1.0000
118.6600 9.1470 1.0000
118.7200 6.3692 1.0000
118.7800 10.1599 1.0000
118.8400 8.9907 1.0000
118.9000 8.3736 1.0000
118.9600 4.8814 1.0000
119.0200 6.0059 1.0000
119.0800 8.4049 1.0000
119.1400 8.7662 1.0000
119.2000 13.6020 1.0000
119.2600 11.6692 1.0000
119.3200 9.1705 1.0000
119.3800 10.7283 1.0000
119.4400 5.8523 1.0000
119.5000 13.1373 1.0000
119.5600 6.4315 1.0000
119.6200 3.1845 1.0000
119.6800 5.0007 1.0000
119.7400 6.8012 1.0000
119.8000 7.3517 1.0000
119.8600 5.0805 1.0000
119.9200 5.5022 1.0000
119.9800 15.0318 1.0000
119.9900 8.7116 1.0000
*RAS_INT_END
*RAS_TEMPERATURE_START
*RAS_TEMPERATURE_END
*RAS_DATA_END