File: XRD/PB_Ge220_5SS_500umDS_RS1_Rod_5SS_Hypix1D_EFRW1_BM_Unirradiated.ras
*RAS_DATA_START
*RAS_HEADER_START
*DISP_FMT_X "%.3f"
*DISP_FMT_Y "%.0f"
*DISP_FULLSCALE "332.0124223455"
*DISP_LINE_COLOR "255.0000000000"
*DISP_LINE_STYLE "0.0000000000"
*DISP_LINE_WIDTH "0.2500000000"
*DISP_NOTE "Collected Data-11"
*DISP_OFFSET_Y "0.0000000000"
*DISP_PEAKSEARCH_UNIT_Y "cps"
*DISP_RANGE_BOTTOM "0.0000000000"
*DISP_RANGE_LEFT "40.0000000000"
*DISP_RANGE_LOGCUTOFF "0.0100000000"
*DISP_RANGE_RIGHT "119.9968000000"
*DISP_RANGE_TOP "332.0124223455"
*DISP_SCALE_MODE_Y "0.0000000000"
*DISP_TAB_NAME "Theta/2-Theta"
*DISP_TITLE_Y "Intensity"
*DISP_UNIT_Y "cps"
*DISP_WINDOW_NAME "MSG_MACROENGINE"
*FILE_COMMENT " "
*FILE_MD5 ""
*FILE_MEMO " "
*FILE_OPERATOR "Administrator"
*FILE_PART_ID "MEAS_KHP2_00061"
*FILE_SAMPLE " "
*FILE_TYPE "RAS_RAW"
*FILE_USERGROUP "System Manager"
*FILE_VERSION "1.0000000000"
*HW_ATTACHMENT_ID "ATT0021"
*HW_ATTACHMENT_NAME "XY-20mm|XY-20mm"
*HW_COUNTER_ID-0 "CUT0041"
*HW_COUNTER_ID-1 "CUT0051"
*HW_COUNTER_ID-2 "CUT0020"
*HW_COUNTER_ID-3 "CSL0021"
*HW_COUNTER_ID-4 "CMC0021"
*HW_COUNTER_NAME-0 "D/teX Ultra 250|D/teX Ultra 250"
*HW_COUNTER_NAME-1 "HyPix 3000(H)|HyPix 3000(H)"
*HW_COUNTER_NAME-2 "None|None"
*HW_COUNTER_NAME-3 "BBM|BBM"
*HW_COUNTER_NAME-4 "検出器モノクロメータ|Detector monochromator"
*HW_COUNTER_SELECT_NAME "HyPix 3000(H)|HyPix 3000(H)"
*HW_GONIOMETER_ID "GON0024"
*HW_GONIOMETER_NAME "SmartLab(In-plane)|SmartLab(In-plane)"
*HW_GONIOMETER_RADIUS-0 "90.0"
*HW_GONIOMETER_RADIUS-1 "114.0"
*HW_GONIOMETER_RADIUS-2 "190.0"
*HW_GONIOMETER_RADIUS-3 "300.0"
*HW_GONIOMETER_RADIUS-4 "187.0"
*HW_GONIOMETER_RADIUS-5 "300.0"
*HW_GONIOMETER_RADIUS-6 "113.0"
*HW_GONIOMETER_RADIUS-7 "331.0"
*HW_I_OPT_ID-0 "CBO0021"
*HW_I_OPT_ID-1 "ICR0021"
*HW_I_OPT_ID-2 "ISL0021"
*HW_I_OPT_ID-3 "ISO0021"
*HW_I_OPT_ID-4 "IAD0021"
*HW_I_OPT_ID-5 "IPR0001"
*HW_I_OPT_NAME-0 "CBOユニット|CBO unit"
*HW_I_OPT_NAME-1 "標準入射光学ユニット|Standard incident optical unit"
*HW_I_OPT_NAME-2 "標準入射スリットボックス|Standard incident slit box"
*HW_I_OPT_NAME-3 "入射平行スリット|Incident parallel slit"
*HW_I_OPT_NAME-4 "長手制限スリット|Length limiting slit"
*HW_I_OPT_NAME-5 "None|None"
*HW_R_ATTENUATER_AUTOMODE "0"
*HW_R_OPT_ID-0 "RSS0022"
*HW_R_OPT_ID-1 "RCR0022"
*HW_R_OPT_ID-2 "RSO0021"
*HW_R_OPT_ID-3 "RRS0022"
*HW_R_OPT_ID-4 "ATN0020"
*HW_R_OPT_ID-5 "RFL0021"
*HW_R_OPT_ID-6 "RAD0021"
*HW_R_OPT_NAME-0 "受光スリットボックス1(Zr軸付)|Receiving slit box # 1 (w/ Zr Axis)"
*HW_R_OPT_NAME-1 "標準受光光学ユニット1|Standard receiving unit # 1"
*HW_R_OPT_NAME-2 "標準受光光学ユニット2|Standard receiving optical unit # 2"
*HW_R_OPT_NAME-3 "仮想受光スリット2|Virtual receiving slit #2"
*HW_R_OPT_NAME-4 "無し|None"
*HW_R_OPT_NAME-5 "Cu Kβ|Cu K-beta"
*HW_R_OPT_NAME-6 "調整用受光スリット|Alignment receiving slit"
*HW_SAMPLE_HOLDER_ID "SMP0021"
*HW_SAMPLE_HOLDER_NAME "χφZクレードル|Chi phi Z cradle"
*HW_XG_CURRENT_MAX "40"
*HW_XG_CURRENT_MIN "2"
*HW_XG_CURRENT_RESOLUTION "1"
*HW_XG_CURRENT_UNIT "mA"
*HW_XG_FOCUS "0.4mm x 8mm"
*HW_XG_FOCUS_TYPE "Fine"
*HW_XG_ID "1200"
*HW_XG_NAME "3kW 封入管(ID:1200)|3kW Sealed tube(ID:1200)"
*HW_XG_TARGET_ATOMIC_NUMBER "29.0000000000"
*HW_XG_TARGET_NAME "Cu"
*HW_XG_TYPE "Hermetic"
*HW_XG_VOLTAGE_MAX "40"
*HW_XG_VOLTAGE_MIN "20"
*HW_XG_VOLTAGE_RESOLUTION "1"
*HW_XG_VOLTAGE_UNIT "kV"
*HW_XG_WATT_MAX "1.500"
*HW_XG_WATT_UNIT "kW"
*HW_XG_WAVE_LENGTH_ALPHA1 "1.540593"
*HW_XG_WAVE_LENGTH_ALPHA2 "1.544414"
*HW_XG_WAVE_LENGTH_BETA "1.392250"
*MEAS_COND_AXIS_NAME-0 "Theta/2-Theta"
*MEAS_COND_AXIS_NAME-1 "2-Theta"
*MEAS_COND_AXIS_NAME-2 "Omega"
*MEAS_COND_AXIS_NAME-3 "Chi"
*MEAS_COND_AXIS_NAME-4 "Phi"
*MEAS_COND_AXIS_NAME-5 "Z"
*MEAS_COND_AXIS_NAME-6 "X"
*MEAS_COND_AXIS_NAME-7 "Y"
*MEAS_COND_AXIS_NAME-8 "2-Theta/Omega"
*MEAS_COND_AXIS_NAME-9 "2-ThetaChi"
*MEAS_COND_AXIS_NAME-10 "2-ThetaChi/Phi"
*MEAS_COND_AXIS_NAME-11 "Alpha"
*MEAS_COND_AXIS_NAME-12 "Beta"
*MEAS_COND_AXIS_NAME-13 "Theta_s"
*MEAS_COND_AXIS_NAME-14 "Theta_d"
*MEAS_COND_AXIS_NAME-15 "Ts"
*MEAS_COND_AXIS_NAME-16 "CBO selection slit"
*MEAS_COND_AXIS_NAME-17 "M"
*MEAS_COND_AXIS_NAME-18 "Incident parallel slit"
*MEAS_COND_AXIS_NAME-19 "Incident slit"
*MEAS_COND_AXIS_NAME-20 ""
*MEAS_COND_AXIS_NAME-21 "Zs"
*MEAS_COND_AXIS_NAME-22 "Incident optical device"
*MEAS_COND_AXIS_NAME-23 "Omega_m"
*MEAS_COND_AXIS_NAME-24 "Length limiting slit"
*MEAS_COND_AXIS_NAME-25 "Center slit"
*MEAS_COND_AXIS_NAME-26 "Filter"
*MEAS_COND_AXIS_NAME-27 "Receiving slit # 1"
*MEAS_COND_AXIS_NAME-28 "Receiving slit # 2"
*MEAS_COND_AXIS_NAME-29 "Receiving optical device"
*MEAS_COND_AXIS_NAME-30 "Receiving parallel slit"
*MEAS_COND_AXIS_NAME-31 "Alignment receiving slit"
*MEAS_COND_AXIS_NAME-32 ""
*MEAS_COND_AXIS_NAME-33 ""
*MEAS_COND_AXIS_NAME-34 "Zd"
*MEAS_COND_AXIS_NAME-35 "Attenuator"
*MEAS_COND_AXIS_NAME-36 "Diffracted beam monochromator"
*MEAS_COND_AXIS_NAME-37 "Monochromator slit"
*MEAS_COND_AXIS_NAME-38 "2-ThetaB"
*MEAS_COND_AXIS_NAME-39 ""
*MEAS_COND_AXIS_NAME-40 ""
*MEAS_COND_AXIS_NAME-41 "Zr"
*MEAS_COND_AXIS_NAME-42 "Primary beam"
*MEAS_COND_AXIS_NAME_INTERNAL-0 "TwoThetaTheta"
*MEAS_COND_AXIS_NAME_INTERNAL-1 "TwoTheta"
*MEAS_COND_AXIS_NAME_INTERNAL-2 "Omega"
*MEAS_COND_AXIS_NAME_INTERNAL-3 "Chi"
*MEAS_COND_AXIS_NAME_INTERNAL-4 "Phi"
*MEAS_COND_AXIS_NAME_INTERNAL-5 "Z"
*MEAS_COND_AXIS_NAME_INTERNAL-6 "X"
*MEAS_COND_AXIS_NAME_INTERNAL-7 "Y"
*MEAS_COND_AXIS_NAME_INTERNAL-8 "TwoThetaOmega"
*MEAS_COND_AXIS_NAME_INTERNAL-9 "TwoThetaChi"
*MEAS_COND_AXIS_NAME_INTERNAL-10 "TwoThetaChiPhi"
*MEAS_COND_AXIS_NAME_INTERNAL-11 "Alpha"
*MEAS_COND_AXIS_NAME_INTERNAL-12 "Beta"
*MEAS_COND_AXIS_NAME_INTERNAL-13 "ThetaS"
*MEAS_COND_AXIS_NAME_INTERNAL-14 "ThetaD"
*MEAS_COND_AXIS_NAME_INTERNAL-15 "Ts"
*MEAS_COND_AXIS_NAME_INTERNAL-16 "CBO"
*MEAS_COND_AXIS_NAME_INTERNAL-17 "CBO-M"
*MEAS_COND_AXIS_NAME_INTERNAL-18 "IncidentSollerSlit"
*MEAS_COND_AXIS_NAME_INTERNAL-19 "IncidentSlitBox"
*MEAS_COND_AXIS_NAME_INTERNAL-20 "IncidentSlitBox-_Axis"
*MEAS_COND_AXIS_NAME_INTERNAL-21 "Zs"
*MEAS_COND_AXIS_NAME_INTERNAL-22 "IncidentMonochromator"
*MEAS_COND_AXIS_NAME_INTERNAL-23 "IncidentMonochromator-OmegaM"
*MEAS_COND_AXIS_NAME_INTERNAL-24 "IncidentAxdSlit"
*MEAS_COND_AXIS_NAME_INTERNAL-25 "CenterSlit"
*MEAS_COND_AXIS_NAME_INTERNAL-26 "Filter"
*MEAS_COND_AXIS_NAME_INTERNAL-27 "ReceivingSlitBox1"
*MEAS_COND_AXIS_NAME_INTERNAL-28 "ReceivingSlitBox2"
*MEAS_COND_AXIS_NAME_INTERNAL-29 "ReceivingOptics"
*MEAS_COND_AXIS_NAME_INTERNAL-30 "ReceivingSollerSlit"
*MEAS_COND_AXIS_NAME_INTERNAL-31 "ReceivingAxdSlit"
*MEAS_COND_AXIS_NAME_INTERNAL-32 "ReceivingSlitBox1-_Axis"
*MEAS_COND_AXIS_NAME_INTERNAL-33 "ReceivingSlitBox2-_Axis"
*MEAS_COND_AXIS_NAME_INTERNAL-34 "ReceivingSlitBox2-Zd"
*MEAS_COND_AXIS_NAME_INTERNAL-35 "Attenuator"
*MEAS_COND_AXIS_NAME_INTERNAL-36 "CounterMonochromator"
*MEAS_COND_AXIS_NAME_INTERNAL-37 "CounterSlit"
*MEAS_COND_AXIS_NAME_INTERNAL-38 "TwoThetaB"
*MEAS_COND_AXIS_NAME_INTERNAL-39 "AlphaR"
*MEAS_COND_AXIS_NAME_INTERNAL-40 "BetaR"
*MEAS_COND_AXIS_NAME_INTERNAL-41 "ReceivingSlitBox1-Zr"
*MEAS_COND_AXIS_NAME_INTERNAL-42 "IncidentPrimary"
*MEAS_COND_AXIS_NAME_MAGICNO-0 "83951616.0000000000"
*MEAS_COND_AXIS_NAME_MAGICNO-1 "268632064.0000000000"
*MEAS_COND_AXIS_NAME_MAGICNO-2 "268500992.0000000000"
*MEAS_COND_AXIS_NAME_MAGICNO-3 "268500992.0000000000"
*MEAS_COND_AXIS_NAME_MAGICNO-4 "268500992.0000000000"
*MEAS_COND_AXIS_NAME_MAGICNO-5 "285278208.0000000000"
*MEAS_COND_AXIS_NAME_MAGICNO-6 "268500992.0000000000"
*MEAS_COND_AXIS_NAME_MAGICNO-7 "268500992.0000000000"
*MEAS_COND_AXIS_NAME_MAGICNO-8 "83951616.0000000000"
*MEAS_COND_AXIS_NAME_MAGICNO-9 "268632064.0000000000"
*MEAS_COND_AXIS_NAME_MAGICNO-10 "83951616.0000000000"
*MEAS_COND_AXIS_NAME_MAGICNO-11 "17039360.0000000000"
*MEAS_COND_AXIS_NAME_MAGICNO-12 "17039360.0000000000"
*MEAS_COND_AXIS_NAME_MAGICNO-13 "131072.0000000000"
*MEAS_COND_AXIS_NAME_MAGICNO-14 "131072.0000000000"
*MEAS_COND_AXIS_NAME_MAGICNO-15 "318898176.0000000000"
*MEAS_COND_AXIS_NAME_MAGICNO-16 "20971521.0000000000"
*MEAS_COND_AXIS_NAME_MAGICNO-17 "285343744.0000000000"
*MEAS_COND_AXIS_NAME_MAGICNO-18 "20971521.0000000000"
*MEAS_COND_AXIS_NAME_MAGICNO-19 "22020097.0000000000"
*MEAS_COND_AXIS_NAME_MAGICNO-20 "25165824.0000000000"
*MEAS_COND_AXIS_NAME_MAGICNO-21 "318898176.0000000000"
*MEAS_COND_AXIS_NAME_MAGICNO-22 "20971521.0000000000"
*MEAS_COND_AXIS_NAME_MAGICNO-23 "285343744.0000000000"
*MEAS_COND_AXIS_NAME_MAGICNO-24 "20971521.0000000000"
*MEAS_COND_AXIS_NAME_MAGICNO-25 "20971521.0000000000"
*MEAS_COND_AXIS_NAME_MAGICNO-26 "20971521.0000000000"
*MEAS_COND_AXIS_NAME_MAGICNO-27 "23068673.0000000000"
*MEAS_COND_AXIS_NAME_MAGICNO-28 "23068673.0000000000"
*MEAS_COND_AXIS_NAME_MAGICNO-29 "20971521.0000000000"
*MEAS_COND_AXIS_NAME_MAGICNO-30 "20971521.0000000000"
*MEAS_COND_AXIS_NAME_MAGICNO-31 "20971521.0000000000"
*MEAS_COND_AXIS_NAME_MAGICNO-32 "25165824.0000000000"
*MEAS_COND_AXIS_NAME_MAGICNO-33 "25165824.0000000000"
*MEAS_COND_AXIS_NAME_MAGICNO-34 "285343744.0000000000"
*MEAS_COND_AXIS_NAME_MAGICNO-35 "0.0000000000"
*MEAS_COND_AXIS_NAME_MAGICNO-36 "20971521.0000000000"
*MEAS_COND_AXIS_NAME_MAGICNO-37 "20971521.0000000000"
*MEAS_COND_AXIS_NAME_MAGICNO-38 "17039360.0000000000"
*MEAS_COND_AXIS_NAME_MAGICNO-39 "8388608.0000000000"
*MEAS_COND_AXIS_NAME_MAGICNO-40 "8388608.0000000000"
*MEAS_COND_AXIS_NAME_MAGICNO-41 "285343744.0000000000"
*MEAS_COND_AXIS_NAME_MAGICNO-42 "20971521.0000000000"
*MEAS_COND_AXIS_OFFSET-0 "-"
*MEAS_COND_AXIS_OFFSET-1 "0.9778000000"
*MEAS_COND_AXIS_OFFSET-2 "-0.4590000000"
*MEAS_COND_AXIS_OFFSET-3 "0.0000000000"
*MEAS_COND_AXIS_OFFSET-4 "0.0000000000"
*MEAS_COND_AXIS_OFFSET-5 "-"
*MEAS_COND_AXIS_OFFSET-6 "0.0000000000"
*MEAS_COND_AXIS_OFFSET-7 "0.0000000000"
*MEAS_COND_AXIS_OFFSET-8 "-"
*MEAS_COND_AXIS_OFFSET-9 "0.0000000000"
*MEAS_COND_AXIS_OFFSET-10 "-"
*MEAS_COND_AXIS_OFFSET-11 "-"
*MEAS_COND_AXIS_OFFSET-12 "-"
*MEAS_COND_AXIS_OFFSET-13 "-0.4590000000"
*MEAS_COND_AXIS_OFFSET-14 "1.4368000000"
*MEAS_COND_AXIS_OFFSET-15 "-"
*MEAS_COND_AXIS_OFFSET-16 "-"
*MEAS_COND_AXIS_OFFSET-17 "-"
*MEAS_COND_AXIS_OFFSET-18 "-"
*MEAS_COND_AXIS_OFFSET-19 "-"
*MEAS_COND_AXIS_OFFSET-20 "-"
*MEAS_COND_AXIS_OFFSET-21 "-"
*MEAS_COND_AXIS_OFFSET-22 "-"
*MEAS_COND_AXIS_OFFSET-23 "-"
*MEAS_COND_AXIS_OFFSET-24 "-"
*MEAS_COND_AXIS_OFFSET-25 "-"
*MEAS_COND_AXIS_OFFSET-26 "-"
*MEAS_COND_AXIS_OFFSET-27 "-"
*MEAS_COND_AXIS_OFFSET-28 "-"
*MEAS_COND_AXIS_OFFSET-29 "-"
*MEAS_COND_AXIS_OFFSET-30 "-"
*MEAS_COND_AXIS_OFFSET-31 "-"
*MEAS_COND_AXIS_OFFSET-32 "-"
*MEAS_COND_AXIS_OFFSET-33 "-"
*MEAS_COND_AXIS_OFFSET-34 "-"
*MEAS_COND_AXIS_OFFSET-35 "-"
*MEAS_COND_AXIS_OFFSET-36 "-"
*MEAS_COND_AXIS_OFFSET-37 "-"
*MEAS_COND_AXIS_OFFSET-38 "-"
*MEAS_COND_AXIS_OFFSET-39 "0.0000000000"
*MEAS_COND_AXIS_OFFSET-40 "0.0000000000"
*MEAS_COND_AXIS_OFFSET-41 "-"
*MEAS_COND_AXIS_OFFSET-42 "-"
*MEAS_COND_AXIS_POSITION-0 "40.0000000000"
*MEAS_COND_AXIS_POSITION-1 "40.0000000000"
*MEAS_COND_AXIS_POSITION-2 "20.0000000000"
*MEAS_COND_AXIS_POSITION-3 "0.0000000000"
*MEAS_COND_AXIS_POSITION-4 "0.0000000000"
*MEAS_COND_AXIS_POSITION-5 "-3.3662000000"
*MEAS_COND_AXIS_POSITION-6 "-0.0955000000"
*MEAS_COND_AXIS_POSITION-7 "-9.7150000000"
*MEAS_COND_AXIS_POSITION-8 "40.0000000000"
*MEAS_COND_AXIS_POSITION-9 "0.0000000000"
*MEAS_COND_AXIS_POSITION-10 "0.0000000000"
*MEAS_COND_AXIS_POSITION-11 "90.0000000000"
*MEAS_COND_AXIS_POSITION-12 "0.0000000000"
*MEAS_COND_AXIS_POSITION-13 "20.0000000000"
*MEAS_COND_AXIS_POSITION-14 "20.0000000000"
*MEAS_COND_AXIS_POSITION-15 "-5.6915000000"
*MEAS_COND_AXIS_POSITION-16 "PB"
*MEAS_COND_AXIS_POSITION-17 "0.0000000000"
*MEAS_COND_AXIS_POSITION-18 "Soller_slit_5.0deg_s"
*MEAS_COND_AXIS_POSITION-19 "1.000mm"
*MEAS_COND_AXIS_POSITION-20 "1.0000000000"
*MEAS_COND_AXIS_POSITION-21 "-1.4209400000"
*MEAS_COND_AXIS_POSITION-22 "Ge(220)x2"
*MEAS_COND_AXIS_POSITION-23 "0.0000000000"
*MEAS_COND_AXIS_POSITION-24 "0.5mm"
*MEAS_COND_AXIS_POSITION-25 "None"
*MEAS_COND_AXIS_POSITION-26 "None"
*MEAS_COND_AXIS_POSITION-27 "20.000mm"
*MEAS_COND_AXIS_POSITION-28 "38.500mm"
*MEAS_COND_AXIS_POSITION-29 "PSA_open"
*MEAS_COND_AXIS_POSITION-30 "Soller_slit_5.0deg"
*MEAS_COND_AXIS_POSITION-31 "None"
*MEAS_COND_AXIS_POSITION-32 "20.0000000000"
*MEAS_COND_AXIS_POSITION-33 "38.5000000000"
*MEAS_COND_AXIS_POSITION-34 "0.0000000000"
*MEAS_COND_AXIS_POSITION-35 "-"
*MEAS_COND_AXIS_POSITION-36 "No_unit"
*MEAS_COND_AXIS_POSITION-37 "None"
*MEAS_COND_AXIS_POSITION-38 "40.0000000000"
*MEAS_COND_AXIS_POSITION-39 "0.0000000000"
*MEAS_COND_AXIS_POSITION-40 "0.0000000000"
*MEAS_COND_AXIS_POSITION-41 "0.1312500000"
*MEAS_COND_AXIS_POSITION-42 "None"
*MEAS_COND_AXIS_UNIT-0 "deg"
*MEAS_COND_AXIS_UNIT-1 "deg"
*MEAS_COND_AXIS_UNIT-2 "deg"
*MEAS_COND_AXIS_UNIT-3 "deg"
*MEAS_COND_AXIS_UNIT-4 "deg"
*MEAS_COND_AXIS_UNIT-5 "mm"
*MEAS_COND_AXIS_UNIT-6 "mm"
*MEAS_COND_AXIS_UNIT-7 "mm"
*MEAS_COND_AXIS_UNIT-8 "deg"
*MEAS_COND_AXIS_UNIT-9 "deg"
*MEAS_COND_AXIS_UNIT-10 "deg"
*MEAS_COND_AXIS_UNIT-11 "deg"
*MEAS_COND_AXIS_UNIT-12 "deg"
*MEAS_COND_AXIS_UNIT-13 "deg"
*MEAS_COND_AXIS_UNIT-14 "deg"
*MEAS_COND_AXIS_UNIT-15 "mm"
*MEAS_COND_AXIS_UNIT-16 ""
*MEAS_COND_AXIS_UNIT-17 "pulse"
*MEAS_COND_AXIS_UNIT-18 ""
*MEAS_COND_AXIS_UNIT-19 ""
*MEAS_COND_AXIS_UNIT-20 "mm"
*MEAS_COND_AXIS_UNIT-21 "mm"
*MEAS_COND_AXIS_UNIT-22 ""
*MEAS_COND_AXIS_UNIT-23 "pulse"
*MEAS_COND_AXIS_UNIT-24 ""
*MEAS_COND_AXIS_UNIT-25 ""
*MEAS_COND_AXIS_UNIT-26 ""
*MEAS_COND_AXIS_UNIT-27 ""
*MEAS_COND_AXIS_UNIT-28 ""
*MEAS_COND_AXIS_UNIT-29 ""
*MEAS_COND_AXIS_UNIT-30 ""
*MEAS_COND_AXIS_UNIT-31 ""
*MEAS_COND_AXIS_UNIT-32 "mm"
*MEAS_COND_AXIS_UNIT-33 "mm"
*MEAS_COND_AXIS_UNIT-34 "mm"
*MEAS_COND_AXIS_UNIT-35 ""
*MEAS_COND_AXIS_UNIT-36 ""
*MEAS_COND_AXIS_UNIT-37 ""
*MEAS_COND_AXIS_UNIT-38 "deg"
*MEAS_COND_AXIS_UNIT-39 "deg"
*MEAS_COND_AXIS_UNIT-40 "deg"
*MEAS_COND_AXIS_UNIT-41 "mm"
*MEAS_COND_AXIS_UNIT-42 ""
*MEAS_COND_COUNTER_CNTLOSS_CORR "0.0000000000"
*MEAS_COND_COUNTER_TAUDIFF "0.0000000000"
*MEAS_COND_COUNTER_TAUINT "0.0000000000"
*MEAS_COND_COUNTER_TEMP_CONDITION "NORMAL"
*MEAS_COND_IRRADIATION_MODE "OFF"
*MEAS_COND_IRRADIATION_WIDTH ""
*MEAS_COND_OPT_ATTR "High resolution parallel beam Ge(220)x2/RS"
*MEAS_COND_OPT_NAME "@High resolution PB-Ge(220)x2"
*MEAS_COND_UNSYMMETRIC_MODE "OFF"
*MEAS_COND_XG_CURRENT "30.0000000000"
*MEAS_COND_XG_VOLTAGE "40.0000000000"
*MEAS_COND_XG_WAVE_TYPE "Ka1"
*MEAS_DATA_COUNT "8000.0000000000"
*MEAS_SCAN_AXIS_X "Theta/2-Theta"
*MEAS_SCAN_AXIS_X_INTERNAL "TwoThetaTheta"
*MEAS_SCAN_END_TIME "04/28/22 11:39:57"
*MEAS_SCAN_MODE "CONTINUOUS"
*MEAS_SCAN_MONITOR "0"
*MEAS_SCAN_RESOLUTION_X "0.0002"
*MEAS_SCAN_SPEED "0.503240"
*MEAS_SCAN_SPEED_UNIT "deg/min"
*MEAS_SCAN_SPEED_USER "0.5"
*MEAS_SCAN_START "40.0000000000"
*MEAS_SCAN_START_TIME "04/28/22 08:45:07"
*MEAS_SCAN_STEP "0.0100000000"
*MEAS_SCAN_STOP "119.9900000000"
*MEAS_SCAN_UNIT_X "deg"
*MEAS_SCAN_UNIT_Y "counts"
*RAS_HEADER_END
*RAS_INT_START
40.0000 15.1307 1.0000
40.0600 18.5728 1.0000
40.1200 15.0657 1.0000
40.1800 17.0370 1.0000
40.2400 15.1566 1.0000
40.3000 14.7100 1.0000
40.3600 16.7208 1.0000
40.4200 16.1945 1.0000
40.4800 18.9074 1.0000
40.5400 14.4615 1.0000
40.6000 11.6524 1.0000
40.6600 19.1789 1.0000
40.7200 21.5232 1.0000
40.7800 16.3960 1.0000
40.8400 17.1119 1.0000
40.9000 15.1581 1.0000
40.9600 14.2068 1.0000
41.0200 13.6802 1.0000
41.0800 12.3008 1.0000
41.1400 19.9183 1.0000
41.2000 22.5783 1.0000
41.2600 12.6282 1.0000
41.3200 20.6803 1.0000
41.3800 18.5299 1.0000
41.4400 19.9102 1.0000
41.5000 22.4035 1.0000
41.5600 34.8879 1.0000
41.6200 35.2567 1.0000
41.6800 51.8737 1.0000
41.7400 94.8344 1.0000
41.8000 131.3233 1.0000
41.8600 162.0810 1.0000
41.9200 222.3453 1.0000
41.9800 248.9894 1.0000
42.0400 303.0093 1.0000
42.1000 261.0400 1.0000
42.1600 179.2841 1.0000
42.2200 133.7620 1.0000
42.2800 74.8245 1.0000
42.3400 52.7157 1.0000
42.4000 45.0175 1.0000
42.4600 33.2241 1.0000
42.5200 25.3448 1.0000
42.5800 24.4909 1.0000
42.6400 14.5864 1.0000
42.7000 23.0359 1.0000
42.7600 15.0267 1.0000
42.8200 19.4527 1.0000
42.8800 14.2669 1.0000
42.9400 14.0287 1.0000
43.0000 16.4945 1.0000
43.0600 11.4595 1.0000
43.1200 16.4122 1.0000
43.1800 14.4518 1.0000
43.2400 9.3371 1.0000
43.3000 12.8118 1.0000
43.3600 14.6444 1.0000
43.4200 18.1512 1.0000
43.4800 12.9362 1.0000
43.5400 15.2847 1.0000
43.6000 13.9525 1.0000
43.6600 15.1416 1.0000
43.7200 8.7214 1.0000
43.7800 11.3919 1.0000
43.8400 6.9823 1.0000
43.9000 10.4276 1.0000
43.9600 23.0536 1.0000
44.0200 17.5051 1.0000
44.0800 14.7434 1.0000
44.1400 12.0756 1.0000
44.2000 20.6294 1.0000
44.2600 11.4610 1.0000
44.3200 14.7046 1.0000
44.3800 10.5605 1.0000
44.4400 14.0371 1.0000
44.5000 16.8977 1.0000
44.5600 9.9445 1.0000
44.6200 13.4951 1.0000
44.6800 13.4933 1.0000
44.7400 25.4977 1.0000
44.8000 14.3230 1.0000
44.8600 9.1353 1.0000
44.9200 13.4835 1.0000
44.9800 20.1379 1.0000
45.0400 20.4004 1.0000
45.1000 10.9236 1.0000
45.1600 16.3715 1.0000
45.2200 17.3450 1.0000
45.2800 9.5807 1.0000
45.3400 14.1089 1.0000
45.4000 11.9977 1.0000
45.4600 16.5868 1.0000
45.5200 7.2201 1.0000
45.5800 11.7307 1.0000
45.6400 14.6214 1.0000
45.7000 8.7147 1.0000
45.7600 15.3562 1.0000
45.8200 17.3191 1.0000
45.8800 13.9085 1.0000
45.9400 13.9624 1.0000
46.0000 14.4877 1.0000
46.0600 21.9114 1.0000
46.1200 14.2176 1.0000
46.1800 7.4482 1.0000
46.2400 17.3530 1.0000
46.3000 11.6940 1.0000
46.3600 16.1250 1.0000
46.4200 13.6222 1.0000
46.4800 16.7289 1.0000
46.5400 12.5061 1.0000
46.6000 23.4599 1.0000
46.6600 12.9276 1.0000
46.7200 5.3790 1.0000
46.7800 10.7822 1.0000
46.8400 11.4577 1.0000
46.9000 11.6574 1.0000
46.9600 14.3355 1.0000
47.0200 18.9034 1.0000
47.0800 14.5089 1.0000
47.1400 12.9779 1.0000
47.2000 13.9879 1.0000
47.2600 13.1023 1.0000
47.3200 9.4676 1.0000
47.3800 8.9746 1.0000
47.4400 12.3935 1.0000
47.5000 15.1075 1.0000
47.5600 9.1204 1.0000
47.6200 14.0566 1.0000
47.6800 7.8120 1.0000
47.7400 9.1160 1.0000
47.8000 13.3518 1.0000
47.8600 20.1346 1.0000
47.9200 14.1025 1.0000
47.9800 11.3020 1.0000
48.0400 13.3634 1.0000
48.1000 12.7851 1.0000
48.1600 18.1550 1.0000
48.2200 13.1498 1.0000
48.2800 11.5626 1.0000
48.3400 10.5077 1.0000
48.4000 14.7318 1.0000
48.4600 17.2290 1.0000
48.5200 10.5454 1.0000
48.5800 21.4034 1.0000
48.6400 15.4913 1.0000
48.7000 11.1603 1.0000
48.7600 9.9834 1.0000
48.8200 7.4854 1.0000
48.8800 16.5552 1.0000
48.9400 14.2761 1.0000
49.0000 10.5907 1.0000
49.0600 11.9956 1.0000
49.1200 5.6780 1.0000
49.1800 19.2418 1.0000
49.2400 15.7935 1.0000
49.3000 15.5284 1.0000
49.3600 15.9090 1.0000
49.4200 13.6110 1.0000
49.4800 10.1768 1.0000
49.5400 9.9489 1.0000
49.6000 13.6813 1.0000
49.6600 19.3043 1.0000
49.7200 15.3476 1.0000
49.7800 17.6912 1.0000
49.8400 10.6323 1.0000
49.9000 14.5338 1.0000
49.9600 10.4263 1.0000
50.0200 7.3527 1.0000
50.0800 10.8704 1.0000
50.1400 8.9677 1.0000
50.2000 15.4208 1.0000
50.2600 10.8991 1.0000
50.3200 15.7213 1.0000
50.3800 11.2673 1.0000
50.4400 19.9315 1.0000
50.5000 12.8215 1.0000
50.5600 13.7021 1.0000
50.6200 20.5104 1.0000
50.6800 11.4348 1.0000
50.7400 12.1516 1.0000
50.8000 13.2047 1.0000
50.8600 14.7209 1.0000
50.9200 16.4302 1.0000
50.9800 12.5686 1.0000
51.0400 15.6840 1.0000
51.1000 12.9641 1.0000
51.1600 11.5389 1.0000
51.2200 11.1676 1.0000
51.2800 6.0273 1.0000
51.3400 11.8366 1.0000
51.4000 16.0997 1.0000
51.4600 13.8478 1.0000
51.5200 10.4822 1.0000
51.5800 9.5350 1.0000
51.6400 14.1704 1.0000
51.7000 12.1645 1.0000
51.7600 12.8883 1.0000
51.8200 17.8387 1.0000
51.8800 11.1895 1.0000
51.9400 8.0505 1.0000
52.0000 6.0028 1.0000
52.0600 12.9652 1.0000
52.1200 14.5576 1.0000
52.1800 10.6011 1.0000
52.2400 7.4007 1.0000
52.3000 10.6836 1.0000
52.3600 14.1199 1.0000
52.4200 4.6159 1.0000
52.4800 20.5783 1.0000
52.5400 11.9620 1.0000
52.6000 17.2662 1.0000
52.6600 8.1478 1.0000
52.7200 19.5105 1.0000
52.7800 11.5329 1.0000
52.8400 10.0992 1.0000
52.9000 13.2895 1.0000
52.9600 10.1856 1.0000
53.0200 9.5767 1.0000
53.0800 7.0003 1.0000
53.1400 10.4952 1.0000
53.2000 8.9129 1.0000
53.2600 18.3052 1.0000
53.3200 9.8204 1.0000
53.3800 12.3574 1.0000
53.4400 9.4266 1.0000
53.5000 12.9140 1.0000
53.5600 6.2260 1.0000
53.6200 13.0015 1.0000
53.6800 12.6508 1.0000
53.7400 10.7891 1.0000
53.8000 10.6785 1.0000
53.8600 11.0548 1.0000
53.9200 14.3657 1.0000
53.9800 4.8065 1.0000
54.0400 11.4406 1.0000
54.1000 11.7742 1.0000
54.1600 12.9822 1.0000
54.2200 18.6895 1.0000
54.2800 10.4391 1.0000
54.3400 4.9529 1.0000
54.4000 11.6098 1.0000
54.4600 13.3728 1.0000
54.5200 13.3376 1.0000
54.5800 9.2556 1.0000
54.6400 11.9861 1.0000
54.7000 10.1269 1.0000
54.7600 8.1266 1.0000
54.8200 13.0797 1.0000
54.8800 4.6104 1.0000
54.9400 6.9392 1.0000
55.0000 9.4268 1.0000
55.0600 13.2178 1.0000
55.1200 5.9710 1.0000
55.1800 15.0960 1.0000
55.2400 8.8123 1.0000
55.3000 15.6722 1.0000
55.3600 7.5258 1.0000
55.4200 13.2843 1.0000
55.4800 8.3552 1.0000
55.5400 16.0768 1.0000
55.6000 8.5188 1.0000
55.6600 3.2013 1.0000
55.7200 14.7488 1.0000
55.7800 10.4241 1.0000
55.8400 11.8701 1.0000
55.9000 16.2990 1.0000
55.9600 9.0619 1.0000
56.0200 7.8449 1.0000
56.0800 12.2072 1.0000
56.1400 10.8502 1.0000
56.2000 6.9672 1.0000
56.2600 10.7198 1.0000
56.3200 9.4340 1.0000
56.3800 7.2622 1.0000
56.4400 9.3131 1.0000
56.5000 10.8688 1.0000
56.5600 9.0507 1.0000
56.6200 12.0745 1.0000
56.6800 7.0278 1.0000
56.7400 10.1825 1.0000
56.8000 16.6310 1.0000
56.8600 12.6422 1.0000
56.9200 12.0059 1.0000
56.9800 13.5580 1.0000
57.0400 12.2733 1.0000
57.1000 11.4946 1.0000
57.1600 7.5834 1.0000
57.2200 11.0625 1.0000
57.2800 11.7691 1.0000
57.3400 8.3816 1.0000
57.4000 8.3450 1.0000
57.4600 11.5129 1.0000
57.5200 11.2935 1.0000
57.5800 6.6809 1.0000
57.6400 14.5909 1.0000
57.7000 6.9734 1.0000
57.7600 12.3575 1.0000
57.8200 6.2759 1.0000
57.8800 8.9328 1.0000
57.9400 4.5383 1.0000
58.0000 10.8822 1.0000
58.0600 7.9945 1.0000
58.1200 10.6163 1.0000
58.1800 7.6217 1.0000
58.2400 4.5759 1.0000
58.3000 9.5501 1.0000
58.3600 12.0361 1.0000
58.4200 16.0365 1.0000
58.4800 7.7163 1.0000
58.5400 10.4521 1.0000
58.6000 10.1267 1.0000
58.6600 9.0207 1.0000
58.7200 11.3405 1.0000
58.7800 8.4755 1.0000
58.8400 12.0795 1.0000
58.9000 15.6605 1.0000
58.9600 12.9402 1.0000
59.0200 14.5232 1.0000
59.0800 8.1379 1.0000
59.1400 11.4681 1.0000
59.2000 8.6480 1.0000
59.2600 4.7814 1.0000
59.3200 16.8252 1.0000
59.3800 10.0632 1.0000
59.4400 5.6410 1.0000
59.5000 7.5364 1.0000
59.5600 11.2980 1.0000
59.6200 11.0391 1.0000
59.6800 14.1738 1.0000
59.7400 8.7803 1.0000
59.8000 13.1485 1.0000
59.8600 12.1319 1.0000
59.9200 15.8090 1.0000
59.9800 6.7169 1.0000
60.0400 7.9984 1.0000
60.1000 6.1551 1.0000
60.1600 6.9764 1.0000
60.2200 9.1956 1.0000
60.2800 7.4165 1.0000
60.3400 8.2352 1.0000
60.4000 16.0368 1.0000
60.4600 16.7216 1.0000
60.5200 11.4865 1.0000
60.5800 5.3035 1.0000
60.6400 8.2969 1.0000
60.7000 9.0673 1.0000
60.7600 4.1539 1.0000
60.8200 7.7517 1.0000
60.8800 11.1474 1.0000
60.9400 13.1104 1.0000
61.0000 9.7570 1.0000
61.0600 9.7281 1.0000
61.1200 12.8294 1.0000
61.1800 10.3077 1.0000
61.2400 12.7412 1.0000
61.3000 5.8404 1.0000
61.3600 11.7316 1.0000
61.4200 8.8539 1.0000
61.4800 9.6495 1.0000
61.5400 10.7212 1.0000
61.6000 8.3001 1.0000
61.6600 7.9863 1.0000
61.7200 7.1994 1.0000
61.7800 4.4696 1.0000
61.8400 10.0270 1.0000
61.9000 6.2877 1.0000
61.9600 8.6774 1.0000
62.0200 9.8597 1.0000
62.0800 8.0820 1.0000
62.1400 13.2243 1.0000
62.2000 7.0978 1.0000
62.2600 11.2607 1.0000
62.3200 9.1142 1.0000
62.3800 9.2118 1.0000
62.4400 9.2387 1.0000
62.5000 13.3347 1.0000
62.5600 7.7962 1.0000
62.6200 9.3351 1.0000
62.6800 10.1060 1.0000
62.7400 7.8206 1.0000
62.8000 10.0485 1.0000
62.8600 12.0626 1.0000
62.9200 15.2894 1.0000
62.9800 6.7813 1.0000
63.0400 14.5923 1.0000
63.1000 12.8259 1.0000
63.1600 5.3561 1.0000
63.2200 10.7945 1.0000
63.2800 6.7155 1.0000
63.3400 9.0909 1.0000
63.4000 7.8547 1.0000
63.4600 8.3085 1.0000
63.5200 10.2733 1.0000
63.5800 7.8529 1.0000
63.6400 5.3393 1.0000
63.7000 6.0144 1.0000
63.7600 11.5374 1.0000
63.8200 6.9126 1.0000
63.8800 8.1391 1.0000
63.9400 6.1309 1.0000
64.0000 11.7046 1.0000
64.0600 9.7206 1.0000
64.1200 10.5818 1.0000
64.1800 7.2823 1.0000
64.2400 8.2034 1.0000
64.3000 14.7276 1.0000
64.3600 10.0124 1.0000
64.4200 7.4763 1.0000
64.4800 13.3364 1.0000
64.5400 9.6907 1.0000
64.6000 5.3740 1.0000
64.6600 9.4048 1.0000
64.7200 11.6517 1.0000
64.7800 13.1734 1.0000
64.8400 7.4867 1.0000
64.9000 15.8091 1.0000
64.9600 8.1129 1.0000
65.0200 8.0021 1.0000
65.0800 10.2764 1.0000
65.1400 10.1089 1.0000
65.2000 3.8353 1.0000
65.2600 9.9785 1.0000
65.3200 13.2618 1.0000
65.3800 7.1504 1.0000
65.4400 6.4473 1.0000
65.5000 5.7021 1.0000
65.5600 8.4572 1.0000
65.6200 11.6814 1.0000
65.6800 12.6987 1.0000
65.7400 9.3544 1.0000
65.8000 9.1082 1.0000
65.8600 6.6524 1.0000
65.9200 6.7334 1.0000
65.9800 4.7637 1.0000
66.0400 11.0891 1.0000
66.1000 8.7554 1.0000
66.1600 8.7225 1.0000
66.2200 6.4061 1.0000
66.2800 10.7755 1.0000
66.3400 11.1491 1.0000
66.4000 4.4981 1.0000
66.4600 11.3363 1.0000
66.5200 9.7834 1.0000
66.5800 9.4559 1.0000
66.6400 13.2512 1.0000
66.7000 8.3649 1.0000
66.7600 6.4240 1.0000
66.8200 8.7450 1.0000
66.8800 12.9189 1.0000
66.9400 7.2847 1.0000
67.0000 7.2293 1.0000
67.0600 7.4768 1.0000
67.1200 7.7558 1.0000
67.1800 6.5118 1.0000
67.2400 8.5168 1.0000
67.3000 7.2644 1.0000
67.3600 6.0045 1.0000
67.4200 7.6581 1.0000
67.4800 7.8470 1.0000
67.5400 6.9061 1.0000
67.6000 10.7054 1.0000
67.6600 11.4193 1.0000
67.7200 9.8407 1.0000
67.7800 11.6286 1.0000
67.8400 6.5907 1.0000
67.9000 5.0101 1.0000
67.9600 7.6167 1.0000
68.0200 7.4460 1.0000
68.0800 6.8363 1.0000
68.1400 9.9675 1.0000
68.2000 10.7762 1.0000
68.2600 9.4685 1.0000
68.3200 11.3936 1.0000
68.3800 7.6937 1.0000
68.4400 6.3763 1.0000
68.5000 10.6376 1.0000
68.5600 4.4456 1.0000
68.6200 9.7353 1.0000
68.6800 11.2256 1.0000
68.7400 8.6954 1.0000
68.8000 7.6131 1.0000
68.8600 7.3267 1.0000
68.9200 7.1775 1.0000
68.9800 4.9450 1.0000
69.0400 3.2743 1.0000
69.1000 7.4364 1.0000
69.1600 3.7910 1.0000
69.2200 7.9486 1.0000
69.2800 8.1823 1.0000
69.3400 7.1439 1.0000
69.4000 13.1736 1.0000
69.4600 9.4583 1.0000
69.5200 5.7254 1.0000
69.5800 7.8957 1.0000
69.6400 6.5247 1.0000
69.7000 6.9470 1.0000
69.7600 8.3441 1.0000
69.8200 5.5902 1.0000
69.8800 15.0849 1.0000
69.9400 8.5562 1.0000
70.0000 5.9081 1.0000
70.0600 6.5995 1.0000
70.1200 5.2585 1.0000
70.1800 4.0133 1.0000
70.2400 5.3082 1.0000
70.3000 5.3335 1.0000
70.3600 8.0067 1.0000
70.4200 6.7534 1.0000
70.4800 6.8828 1.0000
70.5400 7.6519 1.0000
70.6000 4.1734 1.0000
70.6600 6.8965 1.0000
70.7200 4.1103 1.0000
70.7800 4.1933 1.0000
70.8400 8.0405 1.0000
70.9000 8.1255 1.0000
70.9600 7.3230 1.0000
71.0200 10.8359 1.0000
71.0800 4.8962 1.0000
71.1400 5.7430 1.0000
71.2000 9.4912 1.0000
71.2600 6.2059 1.0000
71.3200 9.9850 1.0000
71.3800 7.3011 1.0000
71.4400 9.0353 1.0000
71.5000 5.7748 1.0000
71.5600 5.6656 1.0000
71.6200 5.4628 1.0000
71.6800 3.1825 1.0000
71.7400 3.5447 1.0000
71.8000 10.9586 1.0000
71.8600 6.1292 1.0000
71.9200 7.8550 1.0000
71.9800 4.8981 1.0000
72.0400 5.6880 1.0000
72.1000 6.1574 1.0000
72.1600 14.2144 1.0000
72.2200 9.1058 1.0000
72.2800 13.2282 1.0000
72.3400 4.5341 1.0000
72.4000 3.8943 1.0000
72.4600 3.9907 1.0000
72.5200 7.5420 1.0000
72.5800 14.1628 1.0000
72.6400 10.6526 1.0000
72.7000 6.3270 1.0000
72.7600 4.0183 1.0000
72.8200 7.5415 1.0000
72.8800 8.3273 1.0000
72.9400 10.1316 1.0000
73.0000 10.1986 1.0000
73.0600 6.9893 1.0000
73.1200 5.9215 1.0000
73.1800 6.0095 1.0000
73.2400 8.8137 1.0000
73.3000 5.5903 1.0000
73.3600 9.6776 1.0000
73.4200 4.1568 1.0000
73.4800 9.6517 1.0000
73.5400 7.7487 1.0000
73.6000 6.8179 1.0000
73.6600 7.4353 1.0000
73.7200 6.4213 1.0000
73.7800 7.5903 1.0000
73.8400 6.7001 1.0000
73.9000 5.8836 1.0000
73.9600 5.4744 1.0000
74.0200 5.7360 1.0000
74.0800 7.4745 1.0000
74.1400 7.0422 1.0000
74.2000 5.9232 1.0000
74.2600 6.2399 1.0000
74.3200 9.0328 1.0000
74.3800 9.2960 1.0000
74.4400 8.4707 1.0000
74.5000 9.9205 1.0000
74.5600 10.1777 1.0000
74.6200 5.7729 1.0000
74.6800 6.3516 1.0000
74.7400 6.3398 1.0000
74.8000 9.7419 1.0000
74.8600 5.4260 1.0000
74.9200 6.3434 1.0000
74.9800 9.0726 1.0000
75.0400 9.7569 1.0000
75.1000 5.2180 1.0000
75.1600 6.8838 1.0000
75.2200 12.0953 1.0000
75.2800 8.3286 1.0000
75.3400 8.0265 1.0000
75.4000 5.1979 1.0000
75.4600 9.8403 1.0000
75.5200 7.5177 1.0000
75.5800 7.4811 1.0000
75.6400 5.1493 1.0000
75.7000 6.8294 1.0000
75.7600 4.7066 1.0000
75.8200 3.8534 1.0000
75.8800 5.6951 1.0000
75.9400 4.0203 1.0000
76.0000 6.5907 1.0000
76.0600 5.8949 1.0000
76.1200 7.3235 1.0000
76.1800 4.3731 1.0000
76.2400 5.5670 1.0000
76.3000 3.6570 1.0000
76.3600 4.1563 1.0000
76.4200 4.1794 1.0000
76.4800 10.1420 1.0000
76.5400 6.4470 1.0000
76.6000 3.3364 1.0000
76.6600 8.1074 1.0000
76.7200 5.0940 1.0000
76.7800 5.8315 1.0000
76.8400 6.8519 1.0000
76.9000 5.1436 1.0000
76.9600 6.3232 1.0000
77.0200 7.3123 1.0000
77.0800 4.8573 1.0000
77.1400 6.3380 1.0000
77.2000 9.3710 1.0000
77.2600 6.5512 1.0000
77.3200 6.7602 1.0000
77.3800 3.3997 1.0000
77.4400 4.2606 1.0000
77.5000 6.2508 1.0000
77.5600 6.1891 1.0000
77.6200 6.1963 1.0000
77.6800 8.8791 1.0000
77.7400 5.5730 1.0000
77.8000 4.5041 1.0000
77.8600 6.2544 1.0000
77.9200 5.9361 1.0000
77.9800 4.2813 1.0000
78.0400 8.9148 1.0000
78.1000 6.7773 1.0000
78.1600 5.0817 1.0000
78.2200 8.3393 1.0000
78.2800 9.0411 1.0000
78.3400 2.6827 1.0000
78.4000 5.4315 1.0000
78.4600 8.4873 1.0000
78.5200 5.5256 1.0000
78.5800 3.2416 1.0000
78.6400 4.9016 1.0000
78.7000 4.7351 1.0000
78.7600 5.6737 1.0000
78.8200 9.4448 1.0000
78.8800 8.3572 1.0000
78.9400 7.8016 1.0000
79.0000 6.1674 1.0000
79.0600 5.4151 1.0000
79.1200 8.9644 1.0000
79.1800 9.4859 1.0000
79.2400 6.2602 1.0000
79.3000 6.1509 1.0000
79.3600 7.2163 1.0000
79.4200 4.5095 1.0000
79.4800 4.6410 1.0000
79.5400 10.5606 1.0000
79.6000 11.3966 1.0000
79.6600 5.5714 1.0000
79.7200 6.5809 1.0000
79.7800 8.2797 1.0000
79.8400 4.2593 1.0000
79.9000 8.1495 1.0000
79.9600 9.0574 1.0000
80.0200 2.2707 1.0000
80.0800 5.0458 1.0000
80.1400 10.5079 1.0000
80.2000 4.2519 1.0000
80.2600 5.5957 1.0000
80.3200 6.2471 1.0000
80.3800 2.4286 1.0000
80.4400 5.6459 1.0000
80.5000 5.4980 1.0000
80.5600 3.7769 1.0000
80.6200 2.3031 1.0000
80.6800 6.3529 1.0000
80.7400 7.3356 1.0000
80.8000 6.8483 1.0000
80.8600 4.9910 1.0000
80.9200 3.5428 1.0000
80.9800 5.9749 1.0000
81.0400 3.4943 1.0000
81.1000 8.7169 1.0000
81.1600 6.3076 1.0000
81.2200 5.8248 1.0000
81.2800 10.8666 1.0000
81.3400 9.2275 1.0000
81.4000 10.8736 1.0000
81.4600 5.0942 1.0000
81.5200 5.0817 1.0000
81.5800 2.1970 1.0000
81.6400 4.1787 1.0000
81.7000 3.1622 1.0000
81.7600 9.0344 1.0000
81.8200 4.4281 1.0000
81.8800 7.7608 1.0000
81.9400 6.2479 1.0000
82.0000 4.1987 1.0000
82.0600 4.5194 1.0000
82.1200 6.1270 1.0000
82.1800 8.7138 1.0000
82.2400 7.9951 1.0000
82.3000 4.7172 1.0000
82.3600 4.4940 1.0000
82.4200 2.8721 1.0000
82.4800 4.5666 1.0000
82.5400 2.6603 1.0000
82.6000 7.5443 1.0000
82.6600 5.1518 1.0000
82.7200 8.4875 1.0000
82.7800 6.7339 1.0000
82.8400 6.6847 1.0000
82.9000 5.3507 1.0000
82.9600 9.1374 1.0000
83.0200 11.4977 1.0000
83.0800 6.1233 1.0000
83.1400 4.3186 1.0000
83.2000 4.3055 1.0000
83.2600 6.2445 1.0000
83.3200 5.7875 1.0000
83.3800 5.2450 1.0000
83.4400 3.5668 1.0000
83.5000 7.7084 1.0000
83.5600 3.4039 1.0000
83.6200 10.3606 1.0000
83.6800 8.1468 1.0000
83.7400 3.4291 1.0000
83.8000 4.7412 1.0000
83.8600 5.4325 1.0000
83.9200 3.0790 1.0000
83.9800 6.2206 1.0000
84.0400 4.0454 1.0000
84.1000 7.5632 1.0000
84.1600 7.3835 1.0000
84.2200 9.2116 1.0000
84.2800 4.6987 1.0000
84.3400 3.0892 1.0000
84.4000 5.2563 1.0000
84.4600 7.8415 1.0000
84.5200 3.9223 1.0000
84.5800 7.9258 1.0000
84.6400 9.3986 1.0000
84.7000 5.0443 1.0000
84.7600 7.0584 1.0000
84.8200 5.4729 1.0000
84.8800 4.9781 1.0000
84.9400 5.1609 1.0000
85.0000 1.7571 1.0000
85.0600 3.7354 1.0000
85.1200 4.6976 1.0000
85.1800 7.2385 1.0000
85.2400 7.7622 1.0000
85.3000 2.1725 1.0000
85.3600 5.6282 1.0000
85.4200 3.9170 1.0000
85.4800 0.6849 1.0000
85.5400 6.6202 1.0000
85.6000 8.5761 1.0000
85.6600 7.8833 1.0000
85.7200 4.2862 1.0000
85.7800 3.9777 1.0000
85.8400 5.4364 1.0000
85.9000 8.4536 1.0000
85.9600 3.0324 1.0000
86.0200 1.0398 1.0000
86.0800 9.1631 1.0000
86.1400 5.1303 1.0000
86.2000 4.4043 1.0000
86.2600 2.3675 1.0000
86.3200 8.9676 1.0000
86.3800 13.1642 1.0000
86.4400 2.9740 1.0000
86.5000 3.2400 1.0000
86.5600 5.3198 1.0000
86.6200 6.5600 1.0000
86.6800 4.9293 1.0000
86.7400 6.7101 1.0000
86.8000 5.6565 1.0000
86.8600 3.9122 1.0000
86.9200 3.5297 1.0000
86.9800 3.0253 1.0000
87.0400 1.5337 1.0000
87.1000 2.4885 1.0000
87.1600 6.1899 1.0000
87.2200 3.6750 1.0000
87.2800 7.3660 1.0000
87.3400 4.9844 1.0000
87.4000 2.2704 1.0000
87.4600 4.5060 1.0000
87.5200 4.3768 1.0000
87.5800 5.2510 1.0000
87.6400 6.6885 1.0000
87.7000 3.8867 1.0000
87.7600 5.7844 1.0000
87.8200 4.3362 1.0000
87.8800 6.9004 1.0000
87.9400 5.9656 1.0000
88.0000 0.9950 1.0000
88.0600 6.2080 1.0000
88.1200 2.1474 1.0000
88.1800 2.8427 1.0000
88.2400 1.0716 1.0000
88.3000 3.1591 1.0000
88.3600 7.2462 1.0000
88.4200 3.6774 1.0000
88.4800 12.6416 1.0000
88.5400 8.1764 1.0000
88.6000 4.5969 1.0000
88.6600 5.2295 1.0000
88.7200 4.8115 1.0000
88.7800 7.4016 1.0000
88.8400 3.7304 1.0000
88.9000 3.7550 1.0000
88.9600 4.8271 1.0000
89.0200 7.0898 1.0000
89.0800 6.6123 1.0000
89.1400 5.9966 1.0000
89.2000 1.8219 1.0000
89.2600 4.5914 1.0000
89.3200 5.3611 1.0000
89.3800 6.4568 1.0000
89.4400 8.2139 1.0000
89.5000 4.8096 1.0000
89.5600 6.8085 1.0000
89.6200 5.2565 1.0000
89.6800 5.6537 1.0000
89.7400 6.0341 1.0000
89.8000 4.2485 1.0000
89.8600 7.8413 1.0000
89.9200 3.7705 1.0000
89.9800 2.8779 1.0000
90.0400 3.2892 1.0000
90.1000 1.0607 1.0000
90.1600 3.0310 1.0000
90.2200 5.5057 1.0000
90.2800 3.2475 1.0000
90.3400 3.0273 1.0000
90.4000 5.9798 1.0000
90.4600 6.3256 1.0000
90.5200 5.3173 1.0000
90.5800 4.1387 1.0000
90.6400 3.5244 1.0000
90.7000 3.0824 1.0000
90.7600 3.4834 1.0000
90.8200 5.1566 1.0000
90.8800 8.3389 1.0000
90.9400 5.3784 1.0000
91.0000 3.0506 1.0000
91.0600 5.7324 1.0000
91.1200 9.1189 1.0000
91.1800 9.7663 1.0000
91.2400 0.6952 1.0000
91.3000 4.8754 1.0000
91.3600 5.2761 1.0000
91.4200 4.3497 1.0000
91.4800 5.5184 1.0000
91.5400 6.3460 1.0000
91.6000 5.1125 1.0000
91.6600 6.2528 1.0000
91.7200 4.1126 1.0000
91.7800 3.3527 1.0000
91.8400 4.8348 1.0000
91.9000 3.7067 1.0000
91.9600 3.1392 1.0000
92.0200 4.0898 1.0000
92.0800 4.5520 1.0000
92.1400 1.7133 1.0000
92.2000 3.2906 1.0000
92.2600 6.8406 1.0000
92.3200 7.7909 1.0000
92.3800 4.3490 1.0000
92.4400 5.2230 1.0000
92.5000 2.1959 1.0000
92.5600 2.4786 1.0000
92.6200 5.7762 1.0000
92.6800 8.2135 1.0000
92.7400 6.3941 1.0000
92.8000 6.4614 1.0000
92.8600 3.5854 1.0000
92.9200 6.0517 1.0000
92.9800 6.8857 1.0000
93.0400 7.7688 1.0000
93.1000 7.3132 1.0000
93.1600 2.5938 1.0000
93.2200 5.9623 1.0000
93.2800 2.2491 1.0000
93.3400 2.1007 1.0000
93.4000 4.8521 1.0000
93.4600 6.8856 1.0000
93.5200 5.3511 1.0000
93.5800 2.5208 1.0000
93.6400 4.2744 1.0000
93.7000 6.2229 1.0000
93.7600 4.4070 1.0000
93.8200 3.9502 1.0000
93.8800 6.5575 1.0000
93.9400 2.3924 1.0000
94.0000 2.6176 1.0000
94.0600 4.8186 1.0000
94.1200 6.2721 1.0000
94.1800 4.2789 1.0000
94.2400 2.9198 1.0000
94.3000 2.3337 1.0000
94.3600 1.3920 1.0000
94.4200 4.7098 1.0000
94.4800 5.6505 1.0000
94.5400 7.2121 1.0000
94.6000 7.3636 1.0000
94.6600 4.2579 1.0000
94.7200 6.1971 1.0000
94.7800 1.2427 1.0000
94.8400 2.6290 1.0000
94.9000 5.9676 1.0000
94.9600 6.3005 1.0000
95.0200 6.3085 1.0000
95.0800 1.8789 1.0000
95.1400 3.1753 1.0000
95.2000 2.2401 1.0000
95.2600 2.5971 1.0000
95.3200 2.4649 1.0000
95.3800 4.1524 1.0000
95.4400 5.2725 1.0000
95.5000 6.8770 1.0000
95.5600 6.3930 1.0000
95.6200 2.7335 1.0000
95.6800 6.0869 1.0000
95.7400 5.3190 1.0000
95.8000 7.3728 1.0000
95.8600 3.4219 1.0000
95.9200 3.1678 1.0000
95.9800 6.4120 1.0000
96.0400 3.2762 1.0000
96.1000 8.2808 1.0000
96.1600 6.3439 1.0000
96.2200 6.8392 1.0000
96.2800 5.8298 1.0000
96.3400 3.5912 1.0000
96.4000 3.9331 1.0000
96.4600 4.1833 1.0000
96.5200 8.2038 1.0000
96.5800 1.7640 1.0000
96.6400 8.3847 1.0000
96.7000 6.3964 1.0000
96.7600 3.9961 1.0000
96.8200 2.5895 1.0000
96.8800 2.6029 1.0000
96.9400 3.0564 1.0000
97.0000 2.1999 1.0000
97.0600 2.0980 1.0000
97.1200 8.1968 1.0000
97.1800 4.5787 1.0000
97.2400 0.9939 1.0000
97.3000 3.5246 1.0000
97.3600 5.9927 1.0000
97.4200 5.1218 1.0000
97.4800 5.0387 1.0000
97.5400 2.8161 1.0000
97.6000 2.0116 1.0000
97.6600 8.8709 1.0000
97.7200 2.3602 1.0000
97.7800 4.9551 1.0000
97.8400 4.2206 1.0000
97.9000 7.0020 1.0000
97.9600 6.5671 1.0000
98.0200 3.0952 1.0000
98.0800 8.2423 1.0000
98.1400 4.2310 1.0000
98.2000 4.3282 1.0000
98.2600 4.4577 1.0000
98.3200 5.6681 1.0000
98.3800 4.3398 1.0000
98.4400 2.4755 1.0000
98.5000 8.5688 1.0000
98.5600 3.2022 1.0000
98.6200 2.7466 1.0000
98.6800 4.2239 1.0000
98.7400 11.7307 1.0000
98.8000 5.6709 1.0000
98.8600 2.6752 1.0000
98.9200 6.1609 1.0000
98.9800 3.5362 1.0000
99.0400 7.0157 1.0000
99.1000 4.1038 1.0000
99.1600 5.5784 1.0000
99.2200 5.0541 1.0000
99.2800 4.0800 1.0000
99.3400 6.8384 1.0000
99.4000 2.9729 1.0000
99.4600 3.2821 1.0000
99.5200 4.0251 1.0000
99.5800 4.9151 1.0000
99.6400 6.7929 1.0000
99.7000 5.3769 1.0000
99.7600 1.7045 1.0000
99.8200 0.6255 1.0000
99.8800 7.3045 1.0000
99.9400 3.0844 1.0000
100.0000 3.2502 1.0000
100.0600 3.4950 1.0000
100.1200 3.2551 1.0000
100.1800 4.9233 1.0000
100.2400 1.6212 1.0000
100.3000 4.4282 1.0000
100.3600 5.0414 1.0000
100.4200 4.6111 1.0000
100.4800 4.5071 1.0000
100.5400 1.9762 1.0000
100.6000 4.1247 1.0000
100.6600 3.2683 1.0000
100.7200 2.2637 1.0000
100.7800 6.1969 1.0000
100.8400 7.4575 1.0000
100.9000 3.1404 1.0000
100.9600 3.3197 1.0000
101.0200 3.7651 1.0000
101.0800 5.3645 1.0000
101.1400 2.0371 1.0000
101.2000 7.1824 1.0000
101.2600 2.4268 1.0000
101.3200 2.9906 1.0000
101.3800 6.0861 1.0000
101.4400 5.1964 1.0000
101.5000 4.2305 1.0000
101.5600 5.6062 1.0000
101.6200 5.7544 1.0000
101.6800 3.5183 1.0000
101.7400 2.6968 1.0000
101.8000 7.3312 1.0000
101.8600 4.4400 1.0000
101.9200 5.9331 1.0000
101.9800 3.7669 1.0000
102.0400 4.8164 1.0000
102.1000 2.2591 1.0000
102.1600 2.0608 1.0000
102.2200 3.8952 1.0000
102.2800 2.8261 1.0000
102.3400 3.0876 1.0000
102.4000 2.0117 1.0000
102.4600 4.0735 1.0000
102.5200 4.2270 1.0000
102.5800 4.9010 1.0000
102.6400 4.7110 1.0000
102.7000 7.1213 1.0000
102.7600 2.8788 1.0000
102.8200 3.6660 1.0000
102.8800 2.1926 1.0000
102.9400 5.4973 1.0000
103.0000 1.4122 1.0000
103.0600 2.9125 1.0000
103.1200 3.8488 1.0000
103.1800 2.1175 1.0000
103.2400 1.0777 1.0000
103.3000 7.3324 1.0000
103.3600 3.6781 1.0000
103.4200 6.0349 1.0000
103.4800 7.0577 1.0000
103.5400 5.1441 1.0000
103.6000 2.2217 1.0000
103.6600 4.4145 1.0000
103.7200 6.0621 1.0000
103.7800 3.1657 1.0000
103.8400 1.2460 1.0000
103.9000 4.3683 1.0000
103.9600 2.7722 1.0000
104.0200 2.7961 1.0000
104.0800 7.8739 1.0000
104.1400 5.4265 1.0000
104.2000 6.7809 1.0000
104.2600 6.0881 1.0000
104.3200 4.3701 1.0000
104.3800 2.5572 1.0000
104.4400 2.4459 1.0000
104.5000 6.1099 1.0000
104.5600 6.1458 1.0000
104.6200 3.7226 1.0000
104.6800 4.1641 1.0000
104.7400 3.6676 1.0000
104.8000 5.8609 1.0000
104.8600 3.4895 1.0000
104.9200 3.9389 1.0000
104.9800 9.4846 1.0000
105.0400 4.3427 1.0000
105.1000 2.2033 1.0000
105.1600 3.9152 1.0000
105.2200 5.8627 1.0000
105.2800 6.6155 1.0000
105.3400 2.8565 1.0000
105.4000 2.5292 1.0000
105.4600 3.6045 1.0000
105.5200 5.2268 1.0000
105.5800 4.1720 1.0000
105.6400 2.8245 1.0000
105.7000 3.8768 1.0000
105.7600 5.9481 1.0000
105.8200 4.2760 1.0000
105.8800 0.6527 1.0000
105.9400 2.4145 1.0000
106.0000 6.0004 1.0000
106.0600 2.6393 1.0000
106.1200 6.5454 1.0000
106.1800 8.0723 1.0000
106.2400 5.7671 1.0000
106.3000 2.9061 1.0000
106.3600 3.4152 1.0000
106.4200 3.4669 1.0000
106.4800 8.0161 1.0000
106.5400 5.1454 1.0000
106.6000 5.2503 1.0000
106.6600 4.6059 1.0000
106.7200 7.0807 1.0000
106.7800 1.8783 1.0000
106.8400 3.2582 1.0000
106.9000 4.4787 1.0000
106.9600 3.1186 1.0000
107.0200 1.9287 1.0000
107.0800 7.0482 1.0000
107.1400 3.8288 1.0000
107.2000 6.2525 1.0000
107.2600 3.0539 1.0000
107.3200 5.3490 1.0000
107.3800 2.2300 1.0000
107.4400 8.2887 1.0000
107.5000 4.5116 1.0000
107.5600 3.7493 1.0000
107.6200 1.7856 1.0000
107.6800 1.4209 1.0000
107.7400 6.8798 1.0000
107.8000 6.6665 1.0000
[...]
66.8200 8.0041 1.0000
66.8800 6.6545 1.0000
66.9400 5.7713 1.0000
67.0000 5.9178 1.0000
67.0600 7.9031 1.0000
67.1200 4.7558 1.0000
67.1800 10.6924 1.0000
67.2400 8.7442 1.0000
67.3000 12.1409 1.0000
67.3600 7.9167 1.0000
67.4200 10.3883 1.0000
67.4800 2.5797 1.0000
67.5400 11.3567 1.0000
67.6000 3.5177 1.0000
67.6600 9.1256 1.0000
67.7200 8.9671 1.0000
67.7800 3.5208 1.0000
67.8400 5.0092 1.0000
67.9000 9.5312 1.0000
67.9600 10.6263 1.0000
68.0200 12.7521 1.0000
68.0800 5.4276 1.0000
68.1400 11.1230 1.0000
68.2000 8.8098 1.0000
68.2600 9.6413 1.0000
68.3200 9.5760 1.0000
68.3800 4.5972 1.0000
68.4400 11.7547 1.0000
68.5000 8.6031 1.0000
68.5600 9.9122 1.0000
68.6200 10.1021 1.0000
68.6800 6.6574 1.0000
68.7400 12.3364 1.0000
68.8000 7.7489 1.0000
68.8600 8.2947 1.0000
68.9200 5.4271 1.0000
68.9800 5.4130 1.0000
69.0400 4.3399 1.0000
69.1000 9.6496 1.0000
69.1600 9.4475 1.0000
69.2200 7.2554 1.0000
69.2800 6.4406 1.0000
69.3400 4.9543 1.0000
69.4000 6.3047 1.0000
69.4600 5.3504 1.0000
69.5200 6.1399 1.0000
69.5800 8.0447 1.0000
69.6400 6.3949 1.0000
69.7000 14.6738 1.0000
69.7600 9.0574 1.0000
69.8200 7.0150 1.0000
69.8800 5.1422 1.0000
69.9400 11.4114 1.0000
70.0000 7.4072 1.0000
70.0600 6.9569 1.0000
70.1200 7.0637 1.0000
70.1800 8.4400 1.0000
70.2400 7.2869 1.0000
70.3000 16.8094 1.0000
70.3600 5.2398 1.0000
70.4200 4.0898 1.0000
70.4800 7.4522 1.0000
70.5400 4.5200 1.0000
70.6000 5.6344 1.0000
70.6600 9.5264 1.0000
70.7200 5.4839 1.0000
70.7800 6.2613 1.0000
70.8400 6.8031 1.0000
70.9000 9.8907 1.0000
70.9600 9.4097 1.0000
71.0200 7.4636 1.0000
71.0800 11.4326 1.0000
71.1400 13.1367 1.0000
71.2000 9.5580 1.0000
71.2600 5.5156 1.0000
71.3200 8.4503 1.0000
71.3800 6.4990 1.0000
71.4400 3.8057 1.0000
71.5000 9.6717 1.0000
71.5600 6.6119 1.0000
71.6200 7.3940 1.0000
71.6800 9.1079 1.0000
71.7400 11.4371 1.0000
71.8000 11.5823 1.0000
71.8600 8.3460 1.0000
71.9200 8.2696 1.0000
71.9800 7.6430 1.0000
72.0400 16.2865 1.0000
72.1000 13.2262 1.0000
72.1600 3.7214 1.0000
72.2200 9.7074 1.0000
72.2800 8.7044 1.0000
72.3400 6.7260 1.0000
72.4000 8.5845 1.0000
72.4600 9.8395 1.0000
72.5200 10.1865 1.0000
72.5800 4.5468 1.0000
72.6400 3.6072 1.0000
72.7000 6.0832 1.0000
72.7600 11.3673 1.0000
72.8200 9.0766 1.0000
72.8800 4.5335 1.0000
72.9400 7.4295 1.0000
73.0000 8.0867 1.0000
73.0600 7.5672 1.0000
73.1200 7.9480 1.0000
73.1800 3.2654 1.0000
73.2400 8.2933 1.0000
73.3000 8.5591 1.0000
73.3600 12.6544 1.0000
73.4200 5.0837 1.0000
73.4800 8.2556 1.0000
73.5400 4.3087 1.0000
73.6000 7.7405 1.0000
73.6600 7.2408 1.0000
73.7200 7.0222 1.0000
73.7800 5.6811 1.0000
73.8400 5.2991 1.0000
73.9000 8.4661 1.0000
73.9600 7.7706 1.0000
74.0200 4.8740 1.0000
74.0800 8.3579 1.0000
74.1400 9.5717 1.0000
74.2000 7.2138 1.0000
74.2600 5.3334 1.0000
74.3200 8.5885 1.0000
74.3800 2.5033 1.0000
74.4400 8.9977 1.0000
74.5000 10.9728 1.0000
74.5600 8.3919 1.0000
74.6200 6.7009 1.0000
74.6800 5.7532 1.0000
74.7400 6.7759 1.0000
74.8000 8.2035 1.0000
74.8600 4.6284 1.0000
74.9200 8.0402 1.0000
74.9800 6.6783 1.0000
75.0400 4.4914 1.0000
75.1000 5.2573 1.0000
75.1600 5.7506 1.0000
75.2200 4.3865 1.0000
75.2800 6.4220 1.0000
75.3400 4.2453 1.0000
75.4000 6.0240 1.0000
75.4600 3.2716 1.0000
75.5200 6.9504 1.0000
75.5800 8.3116 1.0000
75.6400 8.2918 1.0000
75.7000 4.7018 1.0000
75.7600 10.7150 1.0000
75.8200 7.7267 1.0000
75.8800 5.3034 1.0000
75.9400 8.0388 1.0000
76.0000 5.6556 1.0000
76.0600 2.7301 1.0000
76.1200 4.2982 1.0000
76.1800 7.8451 1.0000
76.2400 8.2030 1.0000
76.3000 4.3035 1.0000
76.3600 8.3324 1.0000
76.4200 6.9943 1.0000
76.4800 6.5731 1.0000
76.5400 8.1003 1.0000
76.6000 6.2642 1.0000
76.6600 3.9236 1.0000
76.7200 6.9898 1.0000
76.7800 6.6800 1.0000
76.8400 8.9597 1.0000
76.9000 5.0318 1.0000
76.9600 11.1345 1.0000
77.0200 5.2688 1.0000
77.0800 4.4039 1.0000
77.1400 8.2149 1.0000
77.2000 2.7004 1.0000
77.2600 9.1776 1.0000
77.3200 7.9649 1.0000
77.3800 6.8806 1.0000
77.4400 7.2643 1.0000
77.5000 5.6854 1.0000
77.5600 8.4323 1.0000
77.6200 3.4097 1.0000
77.6800 7.5713 1.0000
77.7400 8.0227 1.0000
77.8000 4.0509 1.0000
77.8600 6.5715 1.0000
77.9200 1.6737 1.0000
77.9800 3.3500 1.0000
78.0400 5.0953 1.0000
78.1000 2.6757 1.0000
78.1600 9.4376 1.0000
78.2200 6.8515 1.0000
78.2800 6.5016 1.0000
78.3400 6.3128 1.0000
78.4000 8.4100 1.0000
78.4600 11.9401 1.0000
78.5200 9.0827 1.0000
78.5800 9.9901 1.0000
78.6400 6.2435 1.0000
78.7000 4.9531 1.0000
78.7600 5.6137 1.0000
78.8200 5.4962 1.0000
78.8800 6.2013 1.0000
78.9400 7.5014 1.0000
79.0000 4.4159 1.0000
79.0600 4.1108 1.0000
79.1200 5.3996 1.0000
79.1800 3.8628 1.0000
79.2400 7.3700 1.0000
79.3000 8.7535 1.0000
79.3600 5.3172 1.0000
79.4200 5.3407 1.0000
79.4800 4.3296 1.0000
79.5400 6.2522 1.0000
79.6000 9.4786 1.0000
79.6600 7.8392 1.0000
79.7200 8.4390 1.0000
79.7800 3.1153 1.0000
79.8400 7.6920 1.0000
79.9000 5.7376 1.0000
79.9600 6.0270 1.0000
80.0200 4.3812 1.0000
80.0800 3.4886 1.0000
80.1400 4.6327 1.0000
80.2000 5.1786 1.0000
80.2600 4.4365 1.0000
80.3200 5.1410 1.0000
80.3800 5.1521 1.0000
80.4400 6.8204 1.0000
80.5000 6.2128 1.0000
80.5600 5.0932 1.0000
80.6200 5.2259 1.0000
80.6800 9.2598 1.0000
80.7400 2.4187 1.0000
80.8000 7.1769 1.0000
80.8600 8.3053 1.0000
80.9200 6.0284 1.0000
80.9800 3.8620 1.0000
81.0400 8.2540 1.0000
81.1000 8.1463 1.0000
81.1600 5.0359 1.0000
81.2200 5.5079 1.0000
81.2800 4.4621 1.0000
81.3400 8.0592 1.0000
81.4000 7.8262 1.0000
81.4600 7.8023 1.0000
81.5200 8.5172 1.0000
81.5800 5.3071 1.0000
81.6400 6.5915 1.0000
81.7000 10.6642 1.0000
81.7600 4.9603 1.0000
81.8200 5.9889 1.0000
81.8800 10.2083 1.0000
81.9400 6.7506 1.0000
82.0000 8.0068 1.0000
82.0600 4.5090 1.0000
82.1200 7.9449 1.0000
82.1800 14.9467 1.0000
82.2400 5.4965 1.0000
82.3000 7.7677 1.0000
82.3600 9.2634 1.0000
82.4200 8.2114 1.0000
82.4800 6.2177 1.0000
82.5400 7.3892 1.0000
82.6000 5.2896 1.0000
82.6600 11.2863 1.0000
82.7200 6.3579 1.0000
82.7800 10.5646 1.0000
82.8400 6.2236 1.0000
82.9000 5.0732 1.0000
82.9600 4.1761 1.0000
83.0200 7.0396 1.0000
83.0800 7.3525 1.0000
83.1400 4.4182 1.0000
83.2000 2.1983 1.0000
83.2600 4.9166 1.0000
83.3200 6.8066 1.0000
83.3800 5.3195 1.0000
83.4400 8.3123 1.0000
83.5000 6.5316 1.0000
83.5600 2.0939 1.0000
83.6200 7.6335 1.0000
83.6800 5.3938 1.0000
83.7400 7.0511 1.0000
83.8000 3.0756 1.0000
83.8600 5.6592 1.0000
83.9200 8.9183 1.0000
83.9800 6.7792 1.0000
84.0400 7.0678 1.0000
84.1000 5.4500 1.0000
84.1600 3.3892 1.0000
84.2200 8.1612 1.0000
84.2800 1.7148 1.0000
84.3400 10.7198 1.0000
84.4000 5.5677 1.0000
84.4600 4.9209 1.0000
84.5200 5.9445 1.0000
84.5800 4.2121 1.0000
84.6400 3.1737 1.0000
84.7000 5.8616 1.0000
84.7600 7.3751 1.0000
84.8200 5.2813 1.0000
84.8800 10.0936 1.0000
84.9400 3.7089 1.0000
85.0000 4.8850 1.0000
85.0600 3.5362 1.0000
85.1200 3.7987 1.0000
85.1800 5.9787 1.0000
85.2400 4.7433 1.0000
85.3000 3.2144 1.0000
85.3600 4.8142 1.0000
85.4200 6.5415 1.0000
85.4800 4.3737 1.0000
85.5400 4.4205 1.0000
85.6000 9.3906 1.0000
85.6600 4.2212 1.0000
85.7200 5.3465 1.0000
85.7800 3.8978 1.0000
85.8400 6.4764 1.0000
85.9000 6.4218 1.0000
85.9600 1.5744 1.0000
86.0200 3.1847 1.0000
86.0800 4.5469 1.0000
86.1400 2.0753 1.0000
86.2000 5.3914 1.0000
86.2600 5.0758 1.0000
86.3200 6.3231 1.0000
86.3800 4.8192 1.0000
86.4400 4.1316 1.0000
86.5000 5.3488 1.0000
86.5600 6.2499 1.0000
86.6200 3.5964 1.0000
86.6800 5.9766 1.0000
86.7400 7.4358 1.0000
86.8000 6.3748 1.0000
86.8600 12.5818 1.0000
86.9200 5.7822 1.0000
86.9800 5.0846 1.0000
87.0400 6.0412 1.0000
87.1000 5.2317 1.0000
87.1600 6.5494 1.0000
87.2200 5.3374 1.0000
87.2800 5.0110 1.0000
87.3400 5.3382 1.0000
87.4000 4.1866 1.0000
87.4600 2.6111 1.0000
87.5200 3.0983 1.0000
87.5800 6.4706 1.0000
87.6400 0.2551 1.0000
87.7000 4.1303 1.0000
87.7600 7.8025 1.0000
87.8200 7.3486 1.0000
87.8800 6.0091 1.0000
87.9400 5.1177 1.0000
88.0000 7.6059 1.0000
88.0600 3.3263 1.0000
88.1200 5.1271 1.0000
88.1800 7.0803 1.0000
88.2400 1.8892 1.0000
88.3000 4.9734 1.0000
88.3600 3.1578 1.0000
88.4200 5.7120 1.0000
88.4800 2.8245 1.0000
88.5400 5.3794 1.0000
88.6000 6.7022 1.0000
88.6600 6.1828 1.0000
88.7200 6.1940 1.0000
88.7800 3.4757 1.0000
88.8400 7.1097 1.0000
88.9000 6.8446 1.0000
88.9600 0.7762 1.0000
89.0200 4.5338 1.0000
89.0800 3.3418 1.0000
89.1400 3.0991 1.0000
89.2000 1.2504 1.0000
89.2600 2.5929 1.0000
89.3200 4.1026 1.0000
89.3800 8.9665 1.0000
89.4400 4.1415 1.0000
89.5000 4.6683 1.0000
89.5600 3.6658 1.0000
89.6200 7.3075 1.0000
89.6800 5.3331 1.0000
89.7400 6.0990 1.0000
89.8000 3.9092 1.0000
89.8600 6.8415 1.0000
89.9200 6.3413 1.0000
89.9800 4.5562 1.0000
90.0400 2.4703 1.0000
90.1000 4.5055 1.0000
90.1600 12.0300 1.0000
90.2200 5.5638 1.0000
90.2800 8.1209 1.0000
90.3400 2.1382 1.0000
90.4000 4.3535 1.0000
90.4600 3.6882 1.0000
90.5200 6.5942 1.0000
90.5800 3.5001 1.0000
90.6400 5.7801 1.0000
90.7000 3.5668 1.0000
90.7600 2.5252 1.0000
90.8200 4.2877 1.0000
90.8800 4.8472 1.0000
90.9400 6.1444 1.0000
91.0000 3.1724 1.0000
91.0600 5.0579 1.0000
91.1200 6.1874 1.0000
91.1800 3.8046 1.0000
91.2400 4.9659 1.0000
91.3000 6.4586 1.0000
91.3600 5.3308 1.0000
91.4200 5.5413 1.0000
91.4800 3.8781 1.0000
91.5400 4.0774 1.0000
91.6000 4.1112 1.0000
91.6600 6.5472 1.0000
91.7200 2.8107 1.0000
91.7800 2.0984 1.0000
91.8400 4.1084 1.0000
91.9000 3.5477 1.0000
91.9600 6.2854 1.0000
92.0200 5.6143 1.0000
92.0800 6.7814 1.0000
92.1400 5.1913 1.0000
92.2000 6.3701 1.0000
92.2600 6.6200 1.0000
92.3200 5.1338 1.0000
92.3800 3.0607 1.0000
92.4400 2.9771 1.0000
92.5000 3.0692 1.0000
92.5600 2.8889 1.0000
92.6200 4.5298 1.0000
92.6800 8.0239 1.0000
92.7400 4.3565 1.0000
92.8000 6.5040 1.0000
92.8600 2.1493 1.0000
92.9200 5.1728 1.0000
92.9800 4.3128 1.0000
93.0400 2.8318 1.0000
93.1000 1.5737 1.0000
93.1600 5.2131 1.0000
93.2200 6.7762 1.0000
93.2800 2.7524 1.0000
93.3400 7.0652 1.0000
93.4000 2.6727 1.0000
93.4600 1.3774 1.0000
93.5200 5.7308 1.0000
93.5800 6.2425 1.0000
93.6400 5.5670 1.0000
93.7000 3.2662 1.0000
93.7600 3.6010 1.0000
93.8200 7.4522 1.0000
93.8800 3.1770 1.0000
93.9400 4.9381 1.0000
94.0000 6.9536 1.0000
94.0600 3.2775 1.0000
94.1200 2.1719 1.0000
94.1800 6.9826 1.0000
94.2400 4.1772 1.0000
94.3000 3.2384 1.0000
94.3600 6.7561 1.0000
94.4200 4.9148 1.0000
94.4800 3.3050 1.0000
94.5400 3.4759 1.0000
94.6000 2.2379 1.0000
94.6600 0.4944 1.0000
94.7200 3.9374 1.0000
94.7800 9.5328 1.0000
94.8400 7.6295 1.0000
94.9000 4.1449 1.0000
94.9600 3.6625 1.0000
95.0200 4.0754 1.0000
95.0800 6.3324 1.0000
95.1400 3.3363 1.0000
95.2000 1.9249 1.0000
95.2600 4.2248 1.0000
95.3200 3.6967 1.0000
95.3800 3.5590 1.0000
95.4400 1.6419 1.0000
95.5000 8.0518 1.0000
95.5600 1.9980 1.0000
95.6200 3.6309 1.0000
95.6800 3.9724 1.0000
95.7400 3.7408 1.0000
95.8000 4.2049 1.0000
95.8600 5.3222 1.0000
95.9200 4.5380 1.0000
95.9800 4.3878 1.0000
96.0400 6.8000 1.0000
96.1000 5.0099 1.0000
96.1600 2.0466 1.0000
96.2200 4.8110 1.0000
96.2800 3.4496 1.0000
96.3400 4.7685 1.0000
96.4000 3.2525 1.0000
96.4600 3.2860 1.0000
96.5200 4.2642 1.0000
96.5800 4.2162 1.0000
96.6400 3.0168 1.0000
96.7000 5.2537 1.0000
96.7600 5.9429 1.0000
96.8200 4.4556 1.0000
96.8800 4.2251 1.0000
96.9400 6.1891 1.0000
97.0000 3.1879 1.0000
97.0600 2.2311 1.0000
97.1200 2.7074 1.0000
97.1800 5.6275 1.0000
97.2400 3.4490 1.0000
97.3000 8.0056 1.0000
97.3600 4.0873 1.0000
97.4200 3.5822 1.0000
97.4800 6.3009 1.0000
97.5400 4.7082 1.0000
97.6000 3.5091 1.0000
97.6600 3.9923 1.0000
97.7200 5.2049 1.0000
97.7800 6.1155 1.0000
97.8400 6.3509 1.0000
97.9000 2.7906 1.0000
97.9600 3.3016 1.0000
98.0200 3.6064 1.0000
98.0800 3.7549 1.0000
98.1400 6.9000 1.0000
98.2000 4.8006 1.0000
98.2600 4.9927 1.0000
98.3200 0.2649 1.0000
98.3800 5.3422 1.0000
98.4400 5.7350 1.0000
98.5000 3.6857 1.0000
98.5600 3.1941 1.0000
98.6200 5.1344 1.0000
98.6800 6.9998 1.0000
98.7400 0.0945 1.0000
98.8000 10.7551 1.0000
98.8600 4.7554 1.0000
98.9200 3.8616 1.0000
98.9800 4.9939 1.0000
99.0400 0.5051 1.0000
99.1000 3.6961 1.0000
99.1600 6.1364 1.0000
99.2200 4.2426 1.0000
99.2800 2.5124 1.0000
99.3400 4.5372 1.0000
99.4000 3.6375 1.0000
99.4600 3.1637 1.0000
99.5200 5.5721 1.0000
99.5800 3.4859 1.0000
99.6400 3.8028 1.0000
99.7000 4.8203 1.0000
99.7600 5.2124 1.0000
99.8200 7.0059 1.0000
99.8800 6.7631 1.0000
99.9400 5.0735 1.0000
100.0000 4.6930 1.0000
100.0600 5.4108 1.0000
100.1200 6.2608 1.0000
100.1800 3.8917 1.0000
100.2400 5.5019 1.0000
100.3000 3.3977 1.0000
100.3600 3.3766 1.0000
100.4200 1.1904 1.0000
100.4800 6.6670 1.0000
100.5400 8.3733 1.0000
100.6000 0.8428 1.0000
100.6600 6.0760 1.0000
100.7200 6.2640 1.0000
100.7800 2.5094 1.0000
100.8400 3.5464 1.0000
100.9000 2.5752 1.0000
100.9600 5.0736 1.0000
101.0200 4.6580 1.0000
101.0800 2.5689 1.0000
101.1400 6.8303 1.0000
101.2000 0.7345 1.0000
101.2600 2.5840 1.0000
101.3200 4.9037 1.0000
101.3800 2.5096 1.0000
101.4400 7.7060 1.0000
101.5000 2.1183 1.0000
101.5600 5.7662 1.0000
101.6200 2.9120 1.0000
101.6800 3.8258 1.0000
101.7400 5.2607 1.0000
101.8000 8.7550 1.0000
101.8600 5.2982 1.0000
101.9200 3.1497 1.0000
101.9800 4.4524 1.0000
102.0400 7.9251 1.0000
102.1000 3.6184 1.0000
102.1600 4.6525 1.0000
102.2200 3.8511 1.0000
102.2800 7.3723 1.0000
102.3400 5.3132 1.0000
102.4000 3.1839 1.0000
102.4600 2.3303 1.0000
102.5200 4.3845 1.0000
102.5800 3.7129 1.0000
102.6400 3.3453 1.0000
102.7000 3.7522 1.0000
102.7600 5.1802 1.0000
102.8200 3.6013 1.0000
102.8800 1.2901 1.0000
102.9400 7.6964 1.0000
103.0000 8.9033 1.0000
103.0600 5.7423 1.0000
103.1200 4.5472 1.0000
103.1800 5.8929 1.0000
103.2400 6.2446 1.0000
103.3000 2.1057 1.0000
103.3600 2.9767 1.0000
103.4200 2.4631 1.0000
103.4800 8.5109 1.0000
103.5400 9.0212 1.0000
103.6000 3.0948 1.0000
103.6600 7.1205 1.0000
103.7200 3.8038 1.0000
103.7800 2.6377 1.0000
103.8400 0.4828 1.0000
103.9000 4.9272 1.0000
103.9600 3.5304 1.0000
104.0200 3.7922 1.0000
104.0800 7.0248 1.0000
104.1400 2.2154 1.0000
104.2000 4.8262 1.0000
104.2600 4.5048 1.0000
104.3200 6.3392 1.0000
104.3800 4.8363 1.0000
104.4400 2.7503 1.0000
104.5000 5.2551 1.0000
104.5600 3.9940 1.0000
104.6200 3.0911 1.0000
104.6800 2.2413 1.0000
104.7400 4.0628 1.0000
104.8000 4.1162 1.0000
104.8600 1.2333 1.0000
104.9200 6.0385 1.0000
104.9800 4.7091 1.0000
105.0400 4.0686 1.0000
105.1000 5.9899 1.0000
105.1600 7.9056 1.0000
105.2200 5.4987 1.0000
105.2800 6.2330 1.0000
105.3400 6.7528 1.0000
105.4000 7.6213 1.0000
105.4600 4.3041 1.0000
105.5200 5.0409 1.0000
105.5800 3.7655 1.0000
105.6400 6.0554 1.0000
105.7000 6.7165 1.0000
105.7600 6.5161 1.0000
105.8200 3.1543 1.0000
105.8800 4.1748 1.0000
105.9400 6.0223 1.0000
106.0000 3.6910 1.0000
106.0600 4.2673 1.0000
106.1200 7.1498 1.0000
106.1800 2.9639 1.0000
106.2400 6.1387 1.0000
106.3000 5.4332 1.0000
106.3600 6.9664 1.0000
106.4200 3.1660 1.0000
106.4800 5.7662 1.0000
106.5400 5.4578 1.0000
106.6000 3.4880 1.0000
106.6600 1.4276 1.0000
106.7200 7.6553 1.0000
106.7800 3.0450 1.0000
106.8400 6.7268 1.0000
106.9000 6.0356 1.0000
106.9600 2.7089 1.0000
107.0200 4.3504 1.0000
107.0800 5.9648 1.0000
107.1400 6.3054 1.0000
107.2000 7.4158 1.0000
107.2600 1.4981 1.0000
107.3200 7.9625 1.0000
107.3800 5.3821 1.0000
107.4400 3.0367 1.0000
107.5000 3.8864 1.0000
107.5600 4.6913 1.0000
107.6200 4.7995 1.0000
107.6800 6.1471 1.0000
107.7400 2.0306 1.0000
107.8000 2.0888 1.0000
107.8600 2.0616 1.0000
107.9200 5.1183 1.0000
107.9800 1.6866 1.0000
108.0400 5.3491 1.0000
108.1000 3.4380 1.0000
108.1600 4.1836 1.0000
108.2200 1.6112 1.0000
108.2800 3.0283 1.0000
108.3400 3.2665 1.0000
108.4000 5.8900 1.0000
108.4600 1.7580 1.0000
108.5200 5.6008 1.0000
108.5800 9.6097 1.0000
108.6400 3.4176 1.0000
108.7000 9.1887 1.0000
108.7600 4.9448 1.0000
108.8200 4.6954 1.0000
108.8800 2.8581 1.0000
108.9400 2.6771 1.0000
109.0000 6.0067 1.0000
109.0600 4.8142 1.0000
109.1200 3.1393 1.0000
109.1800 3.4709 1.0000
109.2400 1.2345 1.0000
109.3000 4.9022 1.0000
109.3600 3.2282 1.0000
109.4200 4.3937 1.0000
109.4800 3.4239 1.0000
109.5400 5.2422 1.0000
109.6000 4.8339 1.0000
109.6600 5.0520 1.0000
109.7200 5.3126 1.0000
109.7800 3.0400 1.0000
109.8400 2.1491 1.0000
109.9000 3.1736 1.0000
109.9600 8.2157 1.0000
110.0200 9.9562 1.0000
110.0800 5.3155 1.0000
110.1400 2.9537 1.0000
110.2000 2.3250 1.0000
110.2600 1.7963 1.0000
110.3200 4.9225 1.0000
110.3800 5.1962 1.0000
110.4400 7.2478 1.0000
110.5000 3.7434 1.0000
110.5600 5.7317 1.0000
110.6200 3.2127 1.0000
110.6800 6.3998 1.0000
110.7400 4.8399 1.0000
110.8000 10.3183 1.0000
110.8600 2.9639 1.0000
110.9200 1.0895 1.0000
110.9800 3.5382 1.0000
111.0400 2.3884 1.0000
111.1000 3.3728 1.0000
111.1600 5.7634 1.0000
111.2200 5.5935 1.0000
111.2800 3.5043 1.0000
111.3400 4.3252 1.0000
111.4000 6.6598 1.0000
111.4600 5.7104 1.0000
111.5200 2.6958 1.0000
111.5800 6.1677 1.0000
111.6400 3.7879 1.0000
111.7000 5.7704 1.0000
111.7600 3.1053 1.0000
111.8200 5.2780 1.0000
111.8800 1.2632 1.0000
111.9400 2.9460 1.0000
112.0000 5.0458 1.0000
112.0600 7.8249 1.0000
112.1200 3.3169 1.0000
112.1800 3.0323 1.0000
112.2400 4.4644 1.0000
112.3000 1.1594 1.0000
112.3600 2.4934 1.0000
112.4200 3.1182 1.0000
112.4800 2.8734 1.0000
112.5400 7.3390 1.0000
112.6000 3.8912 1.0000
112.6600 2.0900 1.0000
112.7200 4.4831 1.0000
112.7800 2.1815 1.0000
112.8400 6.1154 1.0000
112.9000 1.4722 1.0000
112.9600 6.0070 1.0000
113.0200 6.2498 1.0000
113.0800 4.4016 1.0000
113.1400 4.2818 1.0000
113.2000 2.6298 1.0000
113.2600 7.0234 1.0000
113.3200 2.3926 1.0000
113.3800 0.6476 1.0000
113.4400 3.4097 1.0000
113.5000 5.2633 1.0000
113.5600 4.4371 1.0000
113.6200 4.6755 1.0000
113.6800 6.1749 1.0000
113.7400 5.8883 1.0000
113.8000 4.3748 1.0000
113.8600 2.4953 1.0000
113.9200 7.7765 1.0000
113.9800 4.1459 1.0000
114.0400 3.2893 1.0000
114.1000 3.1336 1.0000
114.1600 3.1196 1.0000
114.2200 4.0417 1.0000
114.2800 3.2741 1.0000
114.3400 4.6047 1.0000
114.4000 7.4621 1.0000
114.4600 1.1851 1.0000
114.5200 7.1201 1.0000
114.5800 3.8409 1.0000
114.6400 3.9726 1.0000
114.7000 2.9911 1.0000
114.7600 3.0585 1.0000
114.8200 5.0580 1.0000
114.8800 4.0447 1.0000
114.9400 6.8095 1.0000
115.0000 3.9524 1.0000
115.0600 1.3207 1.0000
115.1200 0.0000 1.0000
115.1800 6.0679 1.0000
115.2400 4.5036 1.0000
115.3000 4.8514 1.0000
115.3600 6.5113 1.0000
115.4200 5.0890 1.0000
115.4800 5.2060 1.0000
115.5400 3.9195 1.0000
115.6000 6.9122 1.0000
115.6600 3.4483 1.0000
115.7200 6.5232 1.0000
115.7800 2.3427 1.0000
115.8400 1.5189 1.0000
115.9000 5.4685 1.0000
115.9600 5.9691 1.0000
116.0200 6.0997 1.0000
116.0800 0.0000 1.0000
116.1400 1.5663 1.0000
116.2000 2.6664 1.0000
116.2600 3.7695 1.0000
116.3200 4.2647 1.0000
116.3800 3.4360 1.0000
116.4400 4.1360 1.0000
116.5000 6.2288 1.0000
116.5600 2.7351 1.0000
116.6200 3.6476 1.0000
116.6800 1.0098 1.0000
116.7400 3.0248 1.0000
116.8000 0.9590 1.0000
116.8600 3.1521 1.0000
116.9200 4.3995 1.0000
116.9800 1.1032 1.0000
117.0400 1.3014 1.0000
117.1000 2.2746 1.0000
117.1600 6.0293 1.0000
117.2200 4.5664 1.0000
117.2800 2.2535 1.0000
117.3400 3.8414 1.0000
117.4000 2.0901 1.0000
117.4600 3.7026 1.0000
117.5200 8.8936 1.0000
117.5800 1.6631 1.0000
117.6400 5.2151 1.0000
117.7000 6.1707 1.0000
117.7600 6.8528 1.0000
117.8200 7.1017 1.0000
117.8800 6.0665 1.0000
117.9400 1.4746 1.0000
118.0000 7.3932 1.0000
118.0600 5.8425 1.0000
118.1200 3.1507 1.0000
118.1800 6.8651 1.0000
118.2400 1.9884 1.0000
118.3000 4.5110 1.0000
118.3600 5.2159 1.0000
118.4200 5.5758 1.0000
118.4800 2.0772 1.0000
118.5400 5.7410 1.0000
118.6000 4.7594 1.0000
118.6600 5.0840 1.0000
118.7200 1.4176 1.0000
118.7800 4.2632 1.0000
118.8400 1.8062 1.0000
118.9000 4.0456 1.0000
118.9600 3.7741 1.0000
119.0200 5.0924 1.0000
119.0800 4.2697 1.0000
119.1400 2.6968 1.0000
119.2000 4.1467 1.0000
119.2600 2.1789 1.0000
119.3200 4.0088 1.0000
119.3800 4.5664 1.0000
119.4400 7.5308 1.0000
119.5000 4.1610 1.0000
119.5600 4.8692 1.0000
119.6200 4.0601 1.0000
119.6800 6.3152 1.0000
119.7400 2.7942 1.0000
119.8000 7.3107 1.0000
119.8600 4.6948 1.0000
119.9200 6.2937 1.0000
119.9800 4.5639 1.0000
119.9900 3.5254 1.0000
*RAS_INT_END
*RAS_TEMPERATURE_START
*RAS_TEMPERATURE_END
*RAS_DATA_END