File: XRD/PB_Ge220_5SS_500umDS_RS1_Rod_5SS_Hypix1D_EFRW3_Irr-Parent_P-irradiated.ras
*RAS_DATA_START
*RAS_HEADER_START
*DISP_FMT_X "%.3f"
*DISP_FMT_Y "%.0f"
*DISP_FULLSCALE "285.2944983114"
*DISP_LINE_COLOR "255.0000000000"
*DISP_LINE_STYLE "0.0000000000"
*DISP_LINE_WIDTH "0.2500000000"
*DISP_NOTE "Collected Data-27"
*DISP_OFFSET_Y "0.0000000000"
*DISP_PEAKSEARCH_UNIT_Y "cps"
*DISP_RANGE_BOTTOM "0.0000000000"
*DISP_RANGE_LEFT "40.0000000000"
*DISP_RANGE_LOGCUTOFF "0.0100000000"
*DISP_RANGE_RIGHT "119.9968000000"
*DISP_RANGE_TOP "285.2944983114"
*DISP_SCALE_MODE_Y "0.0000000000"
*DISP_TAB_NAME "Theta/2-Theta"
*DISP_TITLE_Y "Intensity"
*DISP_UNIT_Y "cps"
*DISP_WINDOW_NAME "MSG_MACROENGINE"
*FILE_COMMENT " "
*FILE_MD5 ""
*FILE_MEMO " "
*FILE_OPERATOR "Administrator"
*FILE_PART_ID "MEAS_KHP2_00061"
*FILE_SAMPLE " "
*FILE_TYPE "RAS_RAW"
*FILE_USERGROUP "System Manager"
*FILE_VERSION "1.0000000000"
*HW_ATTACHMENT_ID "ATT0021"
*HW_ATTACHMENT_NAME "XY-20mm|XY-20mm"
*HW_COUNTER_ID-0 "CUT0041"
*HW_COUNTER_ID-1 "CUT0051"
*HW_COUNTER_ID-2 "CUT0020"
*HW_COUNTER_ID-3 "CSL0021"
*HW_COUNTER_ID-4 "CMC0021"
*HW_COUNTER_NAME-0 "D/teX Ultra 250|D/teX Ultra 250"
*HW_COUNTER_NAME-1 "HyPix 3000(H)|HyPix 3000(H)"
*HW_COUNTER_NAME-2 "None|None"
*HW_COUNTER_NAME-3 "BBM|BBM"
*HW_COUNTER_NAME-4 "検出器モノクロメータ|Detector monochromator"
*HW_COUNTER_SELECT_NAME "HyPix 3000(H)|HyPix 3000(H)"
*HW_GONIOMETER_ID "GON0024"
*HW_GONIOMETER_NAME "SmartLab(In-plane)|SmartLab(In-plane)"
*HW_GONIOMETER_RADIUS-0 "90.0"
*HW_GONIOMETER_RADIUS-1 "114.0"
*HW_GONIOMETER_RADIUS-2 "190.0"
*HW_GONIOMETER_RADIUS-3 "300.0"
*HW_GONIOMETER_RADIUS-4 "187.0"
*HW_GONIOMETER_RADIUS-5 "300.0"
*HW_GONIOMETER_RADIUS-6 "113.0"
*HW_GONIOMETER_RADIUS-7 "331.0"
*HW_I_OPT_ID-0 "CBO0021"
*HW_I_OPT_ID-1 "ICR0021"
*HW_I_OPT_ID-2 "ISL0021"
*HW_I_OPT_ID-3 "ISO0021"
*HW_I_OPT_ID-4 "IAD0021"
*HW_I_OPT_ID-5 "IPR0001"
*HW_I_OPT_NAME-0 "CBOユニット|CBO unit"
*HW_I_OPT_NAME-1 "標準入射光学ユニット|Standard incident optical unit"
*HW_I_OPT_NAME-2 "標準入射スリットボックス|Standard incident slit box"
*HW_I_OPT_NAME-3 "入射平行スリット|Incident parallel slit"
*HW_I_OPT_NAME-4 "長手制限スリット|Length limiting slit"
*HW_I_OPT_NAME-5 "None|None"
*HW_R_ATTENUATER_AUTOMODE "0"
*HW_R_OPT_ID-0 "RSS0022"
*HW_R_OPT_ID-1 "RCR0022"
*HW_R_OPT_ID-2 "RSO0021"
*HW_R_OPT_ID-3 "RRS0022"
*HW_R_OPT_ID-4 "ATN0020"
*HW_R_OPT_ID-5 "RFL0021"
*HW_R_OPT_ID-6 "RAD0021"
*HW_R_OPT_NAME-0 "受光スリットボックス1(Zr軸付)|Receiving slit box # 1 (w/ Zr Axis)"
*HW_R_OPT_NAME-1 "標準受光光学ユニット1|Standard receiving unit # 1"
*HW_R_OPT_NAME-2 "標準受光光学ユニット2|Standard receiving optical unit # 2"
*HW_R_OPT_NAME-3 "仮想受光スリット2|Virtual receiving slit #2"
*HW_R_OPT_NAME-4 "無し|None"
*HW_R_OPT_NAME-5 "Cu Kβ|Cu K-beta"
*HW_R_OPT_NAME-6 "調整用受光スリット|Alignment receiving slit"
*HW_SAMPLE_HOLDER_ID "SMP0021"
*HW_SAMPLE_HOLDER_NAME "χφZクレードル|Chi phi Z cradle"
*HW_XG_CURRENT_MAX "40"
*HW_XG_CURRENT_MIN "2"
*HW_XG_CURRENT_RESOLUTION "1"
*HW_XG_CURRENT_UNIT "mA"
*HW_XG_FOCUS "0.4mm x 8mm"
*HW_XG_FOCUS_TYPE "Fine"
*HW_XG_ID "1200"
*HW_XG_NAME "3kW 封入管(ID:1200)|3kW Sealed tube(ID:1200)"
*HW_XG_TARGET_ATOMIC_NUMBER "29.0000000000"
*HW_XG_TARGET_NAME "Cu"
*HW_XG_TYPE "Hermetic"
*HW_XG_VOLTAGE_MAX "40"
*HW_XG_VOLTAGE_MIN "20"
*HW_XG_VOLTAGE_RESOLUTION "1"
*HW_XG_VOLTAGE_UNIT "kV"
*HW_XG_WATT_MAX "1.500"
*HW_XG_WATT_UNIT "kW"
*HW_XG_WAVE_LENGTH_ALPHA1 "1.540593"
*HW_XG_WAVE_LENGTH_ALPHA2 "1.544414"
*HW_XG_WAVE_LENGTH_BETA "1.392250"
*MEAS_COND_AXIS_NAME-0 "Theta/2-Theta"
*MEAS_COND_AXIS_NAME-1 "2-Theta"
*MEAS_COND_AXIS_NAME-2 "Omega"
*MEAS_COND_AXIS_NAME-3 "Chi"
*MEAS_COND_AXIS_NAME-4 "Phi"
*MEAS_COND_AXIS_NAME-5 "Z"
*MEAS_COND_AXIS_NAME-6 "X"
*MEAS_COND_AXIS_NAME-7 "Y"
*MEAS_COND_AXIS_NAME-8 "2-Theta/Omega"
*MEAS_COND_AXIS_NAME-9 "2-ThetaChi"
*MEAS_COND_AXIS_NAME-10 "2-ThetaChi/Phi"
*MEAS_COND_AXIS_NAME-11 "Alpha"
*MEAS_COND_AXIS_NAME-12 "Beta"
*MEAS_COND_AXIS_NAME-13 "Theta_s"
*MEAS_COND_AXIS_NAME-14 "Theta_d"
*MEAS_COND_AXIS_NAME-15 "Ts"
*MEAS_COND_AXIS_NAME-16 "CBO selection slit"
*MEAS_COND_AXIS_NAME-17 "M"
*MEAS_COND_AXIS_NAME-18 "Incident parallel slit"
*MEAS_COND_AXIS_NAME-19 "Incident slit"
*MEAS_COND_AXIS_NAME-20 ""
*MEAS_COND_AXIS_NAME-21 "Zs"
*MEAS_COND_AXIS_NAME-22 "Incident optical device"
*MEAS_COND_AXIS_NAME-23 "Omega_m"
*MEAS_COND_AXIS_NAME-24 "Length limiting slit"
*MEAS_COND_AXIS_NAME-25 "Center slit"
*MEAS_COND_AXIS_NAME-26 "Filter"
*MEAS_COND_AXIS_NAME-27 "Receiving slit # 1"
*MEAS_COND_AXIS_NAME-28 "Receiving slit # 2"
*MEAS_COND_AXIS_NAME-29 "Receiving optical device"
*MEAS_COND_AXIS_NAME-30 "Receiving parallel slit"
*MEAS_COND_AXIS_NAME-31 "Alignment receiving slit"
*MEAS_COND_AXIS_NAME-32 ""
*MEAS_COND_AXIS_NAME-33 ""
*MEAS_COND_AXIS_NAME-34 "Zd"
*MEAS_COND_AXIS_NAME-35 "Attenuator"
*MEAS_COND_AXIS_NAME-36 "Diffracted beam monochromator"
*MEAS_COND_AXIS_NAME-37 "Monochromator slit"
*MEAS_COND_AXIS_NAME-38 "2-ThetaB"
*MEAS_COND_AXIS_NAME-39 ""
*MEAS_COND_AXIS_NAME-40 ""
*MEAS_COND_AXIS_NAME-41 "Zr"
*MEAS_COND_AXIS_NAME-42 "Primary beam"
*MEAS_COND_AXIS_NAME_INTERNAL-0 "TwoThetaTheta"
*MEAS_COND_AXIS_NAME_INTERNAL-1 "TwoTheta"
*MEAS_COND_AXIS_NAME_INTERNAL-2 "Omega"
*MEAS_COND_AXIS_NAME_INTERNAL-3 "Chi"
*MEAS_COND_AXIS_NAME_INTERNAL-4 "Phi"
*MEAS_COND_AXIS_NAME_INTERNAL-5 "Z"
*MEAS_COND_AXIS_NAME_INTERNAL-6 "X"
*MEAS_COND_AXIS_NAME_INTERNAL-7 "Y"
*MEAS_COND_AXIS_NAME_INTERNAL-8 "TwoThetaOmega"
*MEAS_COND_AXIS_NAME_INTERNAL-9 "TwoThetaChi"
*MEAS_COND_AXIS_NAME_INTERNAL-10 "TwoThetaChiPhi"
*MEAS_COND_AXIS_NAME_INTERNAL-11 "Alpha"
*MEAS_COND_AXIS_NAME_INTERNAL-12 "Beta"
*MEAS_COND_AXIS_NAME_INTERNAL-13 "ThetaS"
*MEAS_COND_AXIS_NAME_INTERNAL-14 "ThetaD"
*MEAS_COND_AXIS_NAME_INTERNAL-15 "Ts"
*MEAS_COND_AXIS_NAME_INTERNAL-16 "CBO"
*MEAS_COND_AXIS_NAME_INTERNAL-17 "CBO-M"
*MEAS_COND_AXIS_NAME_INTERNAL-18 "IncidentSollerSlit"
*MEAS_COND_AXIS_NAME_INTERNAL-19 "IncidentSlitBox"
*MEAS_COND_AXIS_NAME_INTERNAL-20 "IncidentSlitBox-_Axis"
*MEAS_COND_AXIS_NAME_INTERNAL-21 "Zs"
*MEAS_COND_AXIS_NAME_INTERNAL-22 "IncidentMonochromator"
*MEAS_COND_AXIS_NAME_INTERNAL-23 "IncidentMonochromator-OmegaM"
*MEAS_COND_AXIS_NAME_INTERNAL-24 "IncidentAxdSlit"
*MEAS_COND_AXIS_NAME_INTERNAL-25 "CenterSlit"
*MEAS_COND_AXIS_NAME_INTERNAL-26 "Filter"
*MEAS_COND_AXIS_NAME_INTERNAL-27 "ReceivingSlitBox1"
*MEAS_COND_AXIS_NAME_INTERNAL-28 "ReceivingSlitBox2"
*MEAS_COND_AXIS_NAME_INTERNAL-29 "ReceivingOptics"
*MEAS_COND_AXIS_NAME_INTERNAL-30 "ReceivingSollerSlit"
*MEAS_COND_AXIS_NAME_INTERNAL-31 "ReceivingAxdSlit"
*MEAS_COND_AXIS_NAME_INTERNAL-32 "ReceivingSlitBox1-_Axis"
*MEAS_COND_AXIS_NAME_INTERNAL-33 "ReceivingSlitBox2-_Axis"
*MEAS_COND_AXIS_NAME_INTERNAL-34 "ReceivingSlitBox2-Zd"
*MEAS_COND_AXIS_NAME_INTERNAL-35 "Attenuator"
*MEAS_COND_AXIS_NAME_INTERNAL-36 "CounterMonochromator"
*MEAS_COND_AXIS_NAME_INTERNAL-37 "CounterSlit"
*MEAS_COND_AXIS_NAME_INTERNAL-38 "TwoThetaB"
*MEAS_COND_AXIS_NAME_INTERNAL-39 "AlphaR"
*MEAS_COND_AXIS_NAME_INTERNAL-40 "BetaR"
*MEAS_COND_AXIS_NAME_INTERNAL-41 "ReceivingSlitBox1-Zr"
*MEAS_COND_AXIS_NAME_INTERNAL-42 "IncidentPrimary"
*MEAS_COND_AXIS_NAME_MAGICNO-0 "83951616.0000000000"
*MEAS_COND_AXIS_NAME_MAGICNO-1 "268632064.0000000000"
*MEAS_COND_AXIS_NAME_MAGICNO-2 "268500992.0000000000"
*MEAS_COND_AXIS_NAME_MAGICNO-3 "268500992.0000000000"
*MEAS_COND_AXIS_NAME_MAGICNO-4 "268500992.0000000000"
*MEAS_COND_AXIS_NAME_MAGICNO-5 "285278208.0000000000"
*MEAS_COND_AXIS_NAME_MAGICNO-6 "268500992.0000000000"
*MEAS_COND_AXIS_NAME_MAGICNO-7 "268500992.0000000000"
*MEAS_COND_AXIS_NAME_MAGICNO-8 "83951616.0000000000"
*MEAS_COND_AXIS_NAME_MAGICNO-9 "268632064.0000000000"
*MEAS_COND_AXIS_NAME_MAGICNO-10 "83951616.0000000000"
*MEAS_COND_AXIS_NAME_MAGICNO-11 "17039360.0000000000"
*MEAS_COND_AXIS_NAME_MAGICNO-12 "17039360.0000000000"
*MEAS_COND_AXIS_NAME_MAGICNO-13 "131072.0000000000"
*MEAS_COND_AXIS_NAME_MAGICNO-14 "131072.0000000000"
*MEAS_COND_AXIS_NAME_MAGICNO-15 "318898176.0000000000"
*MEAS_COND_AXIS_NAME_MAGICNO-16 "20971521.0000000000"
*MEAS_COND_AXIS_NAME_MAGICNO-17 "285343744.0000000000"
*MEAS_COND_AXIS_NAME_MAGICNO-18 "20971521.0000000000"
*MEAS_COND_AXIS_NAME_MAGICNO-19 "22020097.0000000000"
*MEAS_COND_AXIS_NAME_MAGICNO-20 "25165824.0000000000"
*MEAS_COND_AXIS_NAME_MAGICNO-21 "318898176.0000000000"
*MEAS_COND_AXIS_NAME_MAGICNO-22 "20971521.0000000000"
*MEAS_COND_AXIS_NAME_MAGICNO-23 "285343744.0000000000"
*MEAS_COND_AXIS_NAME_MAGICNO-24 "20971521.0000000000"
*MEAS_COND_AXIS_NAME_MAGICNO-25 "20971521.0000000000"
*MEAS_COND_AXIS_NAME_MAGICNO-26 "20971521.0000000000"
*MEAS_COND_AXIS_NAME_MAGICNO-27 "23068673.0000000000"
*MEAS_COND_AXIS_NAME_MAGICNO-28 "23068673.0000000000"
*MEAS_COND_AXIS_NAME_MAGICNO-29 "20971521.0000000000"
*MEAS_COND_AXIS_NAME_MAGICNO-30 "20971521.0000000000"
*MEAS_COND_AXIS_NAME_MAGICNO-31 "20971521.0000000000"
*MEAS_COND_AXIS_NAME_MAGICNO-32 "25165824.0000000000"
*MEAS_COND_AXIS_NAME_MAGICNO-33 "25165824.0000000000"
*MEAS_COND_AXIS_NAME_MAGICNO-34 "285343744.0000000000"
*MEAS_COND_AXIS_NAME_MAGICNO-35 "0.0000000000"
*MEAS_COND_AXIS_NAME_MAGICNO-36 "20971521.0000000000"
*MEAS_COND_AXIS_NAME_MAGICNO-37 "20971521.0000000000"
*MEAS_COND_AXIS_NAME_MAGICNO-38 "17039360.0000000000"
*MEAS_COND_AXIS_NAME_MAGICNO-39 "8388608.0000000000"
*MEAS_COND_AXIS_NAME_MAGICNO-40 "8388608.0000000000"
*MEAS_COND_AXIS_NAME_MAGICNO-41 "285343744.0000000000"
*MEAS_COND_AXIS_NAME_MAGICNO-42 "20971521.0000000000"
*MEAS_COND_AXIS_OFFSET-0 "-"
*MEAS_COND_AXIS_OFFSET-1 "0.8642000000"
*MEAS_COND_AXIS_OFFSET-2 "1.0640000000"
*MEAS_COND_AXIS_OFFSET-3 "0.0000000000"
*MEAS_COND_AXIS_OFFSET-4 "0.0000000000"
*MEAS_COND_AXIS_OFFSET-5 "-"
*MEAS_COND_AXIS_OFFSET-6 "0.0000000000"
*MEAS_COND_AXIS_OFFSET-7 "0.0000000000"
*MEAS_COND_AXIS_OFFSET-8 "-"
*MEAS_COND_AXIS_OFFSET-9 "0.0000000000"
*MEAS_COND_AXIS_OFFSET-10 "-"
*MEAS_COND_AXIS_OFFSET-11 "-"
*MEAS_COND_AXIS_OFFSET-12 "-"
*MEAS_COND_AXIS_OFFSET-13 "1.0640000000"
*MEAS_COND_AXIS_OFFSET-14 "-0.1998000000"
*MEAS_COND_AXIS_OFFSET-15 "-"
*MEAS_COND_AXIS_OFFSET-16 "-"
*MEAS_COND_AXIS_OFFSET-17 "-"
*MEAS_COND_AXIS_OFFSET-18 "-"
*MEAS_COND_AXIS_OFFSET-19 "-"
*MEAS_COND_AXIS_OFFSET-20 "-"
*MEAS_COND_AXIS_OFFSET-21 "-"
*MEAS_COND_AXIS_OFFSET-22 "-"
*MEAS_COND_AXIS_OFFSET-23 "-"
*MEAS_COND_AXIS_OFFSET-24 "-"
*MEAS_COND_AXIS_OFFSET-25 "-"
*MEAS_COND_AXIS_OFFSET-26 "-"
*MEAS_COND_AXIS_OFFSET-27 "-"
*MEAS_COND_AXIS_OFFSET-28 "-"
*MEAS_COND_AXIS_OFFSET-29 "-"
*MEAS_COND_AXIS_OFFSET-30 "-"
*MEAS_COND_AXIS_OFFSET-31 "-"
*MEAS_COND_AXIS_OFFSET-32 "-"
*MEAS_COND_AXIS_OFFSET-33 "-"
*MEAS_COND_AXIS_OFFSET-34 "-"
*MEAS_COND_AXIS_OFFSET-35 "-"
*MEAS_COND_AXIS_OFFSET-36 "-"
*MEAS_COND_AXIS_OFFSET-37 "-"
*MEAS_COND_AXIS_OFFSET-38 "-"
*MEAS_COND_AXIS_OFFSET-39 "0.0000000000"
*MEAS_COND_AXIS_OFFSET-40 "0.0000000000"
*MEAS_COND_AXIS_OFFSET-41 "-"
*MEAS_COND_AXIS_OFFSET-42 "-"
*MEAS_COND_AXIS_POSITION-0 "40.0000000000"
*MEAS_COND_AXIS_POSITION-1 "40.0000000000"
*MEAS_COND_AXIS_POSITION-2 "20.0000000000"
*MEAS_COND_AXIS_POSITION-3 "0.0000000000"
*MEAS_COND_AXIS_POSITION-4 "0.0000000000"
*MEAS_COND_AXIS_POSITION-5 "-1.7645000000"
*MEAS_COND_AXIS_POSITION-6 "-0.5280000000"
*MEAS_COND_AXIS_POSITION-7 "1.0980000000"
*MEAS_COND_AXIS_POSITION-8 "40.0000000000"
*MEAS_COND_AXIS_POSITION-9 "0.0000000000"
*MEAS_COND_AXIS_POSITION-10 "0.0000000000"
*MEAS_COND_AXIS_POSITION-11 "90.0000000000"
*MEAS_COND_AXIS_POSITION-12 "0.0000000000"
*MEAS_COND_AXIS_POSITION-13 "20.0000000000"
*MEAS_COND_AXIS_POSITION-14 "20.0000000000"
*MEAS_COND_AXIS_POSITION-15 "-5.4426900000"
*MEAS_COND_AXIS_POSITION-16 "PB"
*MEAS_COND_AXIS_POSITION-17 "0.0000000000"
*MEAS_COND_AXIS_POSITION-18 "Soller_slit_5.0deg_s"
*MEAS_COND_AXIS_POSITION-19 "1.000mm"
*MEAS_COND_AXIS_POSITION-20 "1.0000000000"
*MEAS_COND_AXIS_POSITION-21 "-1.3487500000"
*MEAS_COND_AXIS_POSITION-22 "Ge(220)x2"
*MEAS_COND_AXIS_POSITION-23 "0.0000000000"
*MEAS_COND_AXIS_POSITION-24 "0.5mm"
*MEAS_COND_AXIS_POSITION-25 "None"
*MEAS_COND_AXIS_POSITION-26 "None"
*MEAS_COND_AXIS_POSITION-27 "20.000mm"
*MEAS_COND_AXIS_POSITION-28 "38.500mm"
*MEAS_COND_AXIS_POSITION-29 "PSA_open"
*MEAS_COND_AXIS_POSITION-30 "Soller_slit_5.0deg"
*MEAS_COND_AXIS_POSITION-31 "None"
*MEAS_COND_AXIS_POSITION-32 "20.0000000000"
*MEAS_COND_AXIS_POSITION-33 "38.5000000000"
*MEAS_COND_AXIS_POSITION-34 "0.0000000000"
*MEAS_COND_AXIS_POSITION-35 "-"
*MEAS_COND_AXIS_POSITION-36 "No_unit"
*MEAS_COND_AXIS_POSITION-37 "None"
*MEAS_COND_AXIS_POSITION-38 "40.0000000000"
*MEAS_COND_AXIS_POSITION-39 "0.0000000000"
*MEAS_COND_AXIS_POSITION-40 "0.0000000000"
*MEAS_COND_AXIS_POSITION-41 "0.2584400000"
*MEAS_COND_AXIS_POSITION-42 "None"
*MEAS_COND_AXIS_UNIT-0 "deg"
*MEAS_COND_AXIS_UNIT-1 "deg"
*MEAS_COND_AXIS_UNIT-2 "deg"
*MEAS_COND_AXIS_UNIT-3 "deg"
*MEAS_COND_AXIS_UNIT-4 "deg"
*MEAS_COND_AXIS_UNIT-5 "mm"
*MEAS_COND_AXIS_UNIT-6 "mm"
*MEAS_COND_AXIS_UNIT-7 "mm"
*MEAS_COND_AXIS_UNIT-8 "deg"
*MEAS_COND_AXIS_UNIT-9 "deg"
*MEAS_COND_AXIS_UNIT-10 "deg"
*MEAS_COND_AXIS_UNIT-11 "deg"
*MEAS_COND_AXIS_UNIT-12 "deg"
*MEAS_COND_AXIS_UNIT-13 "deg"
*MEAS_COND_AXIS_UNIT-14 "deg"
*MEAS_COND_AXIS_UNIT-15 "mm"
*MEAS_COND_AXIS_UNIT-16 ""
*MEAS_COND_AXIS_UNIT-17 "pulse"
*MEAS_COND_AXIS_UNIT-18 ""
*MEAS_COND_AXIS_UNIT-19 ""
*MEAS_COND_AXIS_UNIT-20 "mm"
*MEAS_COND_AXIS_UNIT-21 "mm"
*MEAS_COND_AXIS_UNIT-22 ""
*MEAS_COND_AXIS_UNIT-23 "pulse"
*MEAS_COND_AXIS_UNIT-24 ""
*MEAS_COND_AXIS_UNIT-25 ""
*MEAS_COND_AXIS_UNIT-26 ""
*MEAS_COND_AXIS_UNIT-27 ""
*MEAS_COND_AXIS_UNIT-28 ""
*MEAS_COND_AXIS_UNIT-29 ""
*MEAS_COND_AXIS_UNIT-30 ""
*MEAS_COND_AXIS_UNIT-31 ""
*MEAS_COND_AXIS_UNIT-32 "mm"
*MEAS_COND_AXIS_UNIT-33 "mm"
*MEAS_COND_AXIS_UNIT-34 "mm"
*MEAS_COND_AXIS_UNIT-35 ""
*MEAS_COND_AXIS_UNIT-36 ""
*MEAS_COND_AXIS_UNIT-37 ""
*MEAS_COND_AXIS_UNIT-38 "deg"
*MEAS_COND_AXIS_UNIT-39 "deg"
*MEAS_COND_AXIS_UNIT-40 "deg"
*MEAS_COND_AXIS_UNIT-41 "mm"
*MEAS_COND_AXIS_UNIT-42 ""
*MEAS_COND_COUNTER_CNTLOSS_CORR "0.0000000000"
*MEAS_COND_COUNTER_TAUDIFF "0.0000000000"
*MEAS_COND_COUNTER_TAUINT "0.0000000000"
*MEAS_COND_COUNTER_TEMP_CONDITION "NORMAL"
*MEAS_COND_IRRADIATION_MODE "OFF"
*MEAS_COND_IRRADIATION_WIDTH ""
*MEAS_COND_OPT_ATTR "High resolution parallel beam Ge(220)x2/RS"
*MEAS_COND_OPT_NAME "@High resolution PB-Ge(220)x2"
*MEAS_COND_UNSYMMETRIC_MODE "OFF"
*MEAS_COND_XG_CURRENT "30.0000000000"
*MEAS_COND_XG_VOLTAGE "40.0000000000"
*MEAS_COND_XG_WAVE_TYPE "Ka1"
*MEAS_DATA_COUNT "8000.0000000000"
*MEAS_SCAN_AXIS_X "Theta/2-Theta"
*MEAS_SCAN_AXIS_X_INTERNAL "TwoThetaTheta"
*MEAS_SCAN_END_TIME "05/14/22 09:06:12"
*MEAS_SCAN_MODE "CONTINUOUS"
*MEAS_SCAN_MONITOR "0"
*MEAS_SCAN_RESOLUTION_X "0.0002"
*MEAS_SCAN_SPEED "0.503240"
*MEAS_SCAN_SPEED_UNIT "deg/min"
*MEAS_SCAN_SPEED_USER "0.5"
*MEAS_SCAN_START "40.0000000000"
*MEAS_SCAN_START_TIME "05/14/22 06:11:22"
*MEAS_SCAN_STEP "0.0100000000"
*MEAS_SCAN_STOP "119.9900000000"
*MEAS_SCAN_UNIT_X "deg"
*MEAS_SCAN_UNIT_Y "counts"
*RAS_HEADER_END
*RAS_INT_START
40.0000 6.3520 1.0000
40.0600 10.5981 1.0000
40.1200 4.9266 1.0000
40.1800 6.9541 1.0000
40.2400 7.6536 1.0000
40.3000 5.9057 1.0000
40.3600 6.2554 1.0000
40.4200 9.3389 1.0000
40.4800 2.3523 1.0000
40.5400 1.5313 1.0000
40.6000 11.5397 1.0000
40.6600 9.6111 1.0000
40.7200 6.8092 1.0000
40.7800 7.0099 1.0000
40.8400 7.1111 1.0000
40.9000 6.2582 1.0000
40.9600 8.6455 1.0000
41.0200 6.0059 1.0000
41.0800 9.4423 1.0000
41.1400 3.6147 1.0000
41.2000 4.6854 1.0000
41.2600 8.3945 1.0000
41.3200 4.3005 1.0000
41.3800 9.0568 1.0000
41.4400 6.4605 1.0000
41.5000 6.2784 1.0000
41.5600 7.5341 1.0000
41.6200 3.8932 1.0000
41.6800 5.6403 1.0000
41.7400 9.0208 1.0000
41.8000 3.3013 1.0000
41.8600 4.6391 1.0000
41.9200 5.5100 1.0000
41.9800 6.9606 1.0000
42.0400 5.0509 1.0000
42.1000 10.5324 1.0000
42.1600 10.4584 1.0000
42.2200 8.8697 1.0000
42.2800 3.5440 1.0000
42.3400 4.8015 1.0000
42.4000 8.0352 1.0000
42.4600 11.1108 1.0000
42.5200 10.0827 1.0000
42.5800 7.8346 1.0000
42.6400 8.3139 1.0000
42.7000 7.6679 1.0000
42.7600 7.8290 1.0000
42.8200 7.8938 1.0000
42.8800 6.2411 1.0000
42.9400 5.3284 1.0000
43.0000 10.7447 1.0000
43.0600 8.7305 1.0000
43.1200 7.5226 1.0000
43.1800 8.4717 1.0000
43.2400 5.4827 1.0000
43.3000 9.9439 1.0000
43.3600 6.1645 1.0000
43.4200 6.1464 1.0000
43.4800 7.0568 1.0000
43.5400 5.2497 1.0000
43.6000 4.1557 1.0000
43.6600 6.2792 1.0000
43.7200 6.4963 1.0000
43.7800 10.3670 1.0000
43.8400 4.8608 1.0000
43.9000 7.7119 1.0000
43.9600 6.1445 1.0000
44.0200 14.2182 1.0000
44.0800 16.7277 1.0000
44.1400 14.0554 1.0000
44.2000 15.0782 1.0000
44.2600 24.3493 1.0000
44.3200 25.5877 1.0000
44.3800 64.0221 1.0000
44.4400 151.7613 1.0000
44.5000 222.5370 1.0000
44.5600 254.5626 1.0000
44.6200 196.0661 1.0000
44.6800 95.9160 1.0000
44.7400 36.3303 1.0000
44.8000 19.1912 1.0000
44.8600 14.8961 1.0000
44.9200 9.1781 1.0000
44.9800 7.7063 1.0000
45.0400 5.5167 1.0000
45.1000 7.4466 1.0000
45.1600 7.9729 1.0000
45.2200 9.3008 1.0000
45.2800 11.5372 1.0000
45.3400 5.2704 1.0000
45.4000 2.1716 1.0000
45.4600 3.4132 1.0000
45.5200 5.0799 1.0000
45.5800 8.6252 1.0000
45.6400 9.7534 1.0000
45.7000 10.0794 1.0000
45.7600 5.5424 1.0000
45.8200 9.5361 1.0000
45.8800 9.9710 1.0000
45.9400 6.6041 1.0000
46.0000 4.5465 1.0000
46.0600 5.8512 1.0000
46.1200 5.9190 1.0000
46.1800 7.4715 1.0000
46.2400 4.5948 1.0000
46.3000 3.4127 1.0000
46.3600 9.4569 1.0000
46.4200 3.9671 1.0000
46.4800 3.4262 1.0000
46.5400 5.6908 1.0000
46.6000 6.9037 1.0000
46.6600 4.6769 1.0000
46.7200 6.1873 1.0000
46.7800 8.0494 1.0000
46.8400 8.6304 1.0000
46.9000 5.7140 1.0000
46.9600 6.9289 1.0000
47.0200 11.4456 1.0000
47.0800 7.0571 1.0000
47.1400 5.8552 1.0000
47.2000 7.1541 1.0000
47.2600 3.4705 1.0000
47.3200 5.3672 1.0000
47.3800 10.0152 1.0000
47.4400 6.2227 1.0000
47.5000 9.7552 1.0000
47.5600 7.9191 1.0000
47.6200 5.3674 1.0000
47.6800 7.2839 1.0000
47.7400 7.9172 1.0000
47.8000 5.9040 1.0000
47.8600 7.9311 1.0000
47.9200 3.5678 1.0000
47.9800 6.3986 1.0000
48.0400 6.3955 1.0000
48.1000 10.2091 1.0000
48.1600 7.0428 1.0000
48.2200 9.1437 1.0000
48.2800 2.8649 1.0000
48.3400 4.2106 1.0000
48.4000 10.6932 1.0000
48.4600 3.4905 1.0000
48.5200 7.8511 1.0000
48.5800 12.8098 1.0000
48.6400 13.1131 1.0000
48.7000 6.2529 1.0000
48.7600 4.9162 1.0000
48.8200 13.3529 1.0000
48.8800 9.8134 1.0000
48.9400 8.0819 1.0000
49.0000 4.7486 1.0000
49.0600 8.2834 1.0000
49.1200 10.6715 1.0000
49.1800 5.5549 1.0000
49.2400 4.8146 1.0000
49.3000 7.5918 1.0000
49.3600 5.6101 1.0000
49.4200 5.5422 1.0000
49.4800 7.0914 1.0000
49.5400 5.3291 1.0000
49.6000 5.2995 1.0000
49.6600 3.9713 1.0000
49.7200 6.1515 1.0000
49.7800 11.0649 1.0000
49.8400 5.9440 1.0000
49.9000 18.7388 1.0000
49.9600 4.0685 1.0000
50.0200 8.7428 1.0000
50.0800 7.5537 1.0000
50.1400 6.9881 1.0000
50.2000 7.7608 1.0000
50.2600 10.0788 1.0000
50.3200 5.5154 1.0000
50.3800 5.4075 1.0000
50.4400 5.1124 1.0000
50.5000 8.3280 1.0000
50.5600 6.3254 1.0000
50.6200 7.5322 1.0000
50.6800 8.6856 1.0000
50.7400 9.3631 1.0000
50.8000 6.7835 1.0000
50.8600 7.3722 1.0000
50.9200 8.1100 1.0000
50.9800 10.0706 1.0000
51.0400 3.6023 1.0000
51.1000 4.4571 1.0000
51.1600 6.9916 1.0000
51.2200 8.0281 1.0000
51.2800 4.3809 1.0000
51.3400 4.2905 1.0000
51.4000 5.6858 1.0000
51.4600 4.9630 1.0000
51.5200 4.9005 1.0000
51.5800 6.2505 1.0000
51.6400 5.9071 1.0000
51.7000 6.2678 1.0000
51.7600 2.1823 1.0000
51.8200 4.5160 1.0000
51.8800 4.5237 1.0000
51.9400 8.8189 1.0000
52.0000 3.4513 1.0000
52.0600 5.1474 1.0000
52.1200 6.0694 1.0000
52.1800 8.5953 1.0000
52.2400 6.7897 1.0000
52.3000 5.0663 1.0000
52.3600 9.3085 1.0000
52.4200 8.3797 1.0000
52.4800 3.8586 1.0000
52.5400 2.0203 1.0000
52.6000 4.6545 1.0000
52.6600 11.2333 1.0000
52.7200 3.5352 1.0000
52.7800 7.1121 1.0000
52.8400 6.1162 1.0000
52.9000 3.6323 1.0000
52.9600 7.0776 1.0000
53.0200 12.0841 1.0000
53.0800 9.3416 1.0000
53.1400 5.1120 1.0000
53.2000 7.9969 1.0000
53.2600 9.4835 1.0000
53.3200 6.5408 1.0000
53.3800 5.4923 1.0000
53.4400 9.3559 1.0000
53.5000 11.7034 1.0000
53.5600 6.8290 1.0000
53.6200 8.9400 1.0000
53.6800 6.2988 1.0000
53.7400 2.8489 1.0000
53.8000 7.7859 1.0000
53.8600 5.8650 1.0000
53.9200 6.2097 1.0000
53.9800 6.5198 1.0000
54.0400 7.5333 1.0000
54.1000 6.5791 1.0000
54.1600 4.4365 1.0000
54.2200 7.5120 1.0000
54.2800 1.0026 1.0000
54.3400 4.4772 1.0000
54.4000 5.6759 1.0000
54.4600 7.0519 1.0000
54.5200 9.6850 1.0000
54.5800 6.2406 1.0000
54.6400 7.2701 1.0000
54.7000 8.3786 1.0000
54.7600 10.1108 1.0000
54.8200 4.4469 1.0000
54.8800 6.2643 1.0000
54.9400 8.8912 1.0000
55.0000 2.0943 1.0000
55.0600 7.6773 1.0000
55.1200 5.7882 1.0000
55.1800 5.4356 1.0000
55.2400 7.2556 1.0000
55.3000 3.1416 1.0000
55.3600 6.3893 1.0000
55.4200 8.6607 1.0000
55.4800 6.6957 1.0000
55.5400 5.6813 1.0000
55.6000 8.3625 1.0000
55.6600 6.6044 1.0000
55.7200 2.8666 1.0000
55.7800 6.8243 1.0000
55.8400 5.2715 1.0000
55.9000 5.3803 1.0000
55.9600 5.5859 1.0000
56.0200 6.3109 1.0000
56.0800 7.0395 1.0000
56.1400 3.3362 1.0000
56.2000 7.3631 1.0000
56.2600 4.8933 1.0000
56.3200 8.9696 1.0000
56.3800 7.1034 1.0000
56.4400 7.9926 1.0000
56.5000 10.3093 1.0000
56.5600 4.5969 1.0000
56.6200 3.2673 1.0000
56.6800 5.2191 1.0000
56.7400 6.1816 1.0000
56.8000 5.6114 1.0000
56.8600 4.6039 1.0000
56.9200 4.4455 1.0000
56.9800 4.2551 1.0000
57.0400 3.6746 1.0000
57.1000 2.7528 1.0000
57.1600 6.4212 1.0000
57.2200 3.2011 1.0000
57.2800 4.2042 1.0000
57.3400 4.5794 1.0000
57.4000 6.3451 1.0000
57.4600 7.0279 1.0000
57.5200 3.3385 1.0000
57.5800 4.1476 1.0000
57.6400 3.2394 1.0000
57.7000 9.4400 1.0000
57.7600 7.9422 1.0000
57.8200 8.3532 1.0000
57.8800 3.8066 1.0000
57.9400 2.8295 1.0000
58.0000 8.6097 1.0000
58.0600 7.5417 1.0000
58.1200 6.2627 1.0000
58.1800 10.0198 1.0000
58.2400 3.7721 1.0000
58.3000 4.4667 1.0000
58.3600 5.4153 1.0000
58.4200 4.4641 1.0000
58.4800 4.5030 1.0000
58.5400 7.8267 1.0000
58.6000 7.1476 1.0000
58.6600 1.1087 1.0000
58.7200 0.7452 1.0000
58.7800 3.9183 1.0000
58.8400 9.0209 1.0000
58.9000 6.1868 1.0000
58.9600 10.3124 1.0000
59.0200 13.1287 1.0000
59.0800 8.4050 1.0000
59.1400 9.0718 1.0000
59.2000 2.5095 1.0000
59.2600 6.2475 1.0000
59.3200 5.6634 1.0000
59.3800 5.8648 1.0000
59.4400 4.8279 1.0000
59.5000 7.8246 1.0000
59.5600 3.7735 1.0000
59.6200 9.3626 1.0000
59.6800 12.2992 1.0000
59.7400 3.8121 1.0000
59.8000 9.8155 1.0000
59.8600 4.5775 1.0000
59.9200 8.3610 1.0000
59.9800 9.5693 1.0000
60.0400 3.4431 1.0000
60.1000 5.1750 1.0000
60.1600 3.0741 1.0000
60.2200 7.7810 1.0000
60.2800 6.5633 1.0000
60.3400 7.9967 1.0000
60.4000 10.0082 1.0000
60.4600 4.1181 1.0000
60.5200 4.6256 1.0000
60.5800 6.1303 1.0000
60.6400 2.8152 1.0000
60.7000 6.8086 1.0000
60.7600 6.1493 1.0000
60.8200 3.0904 1.0000
60.8800 2.4864 1.0000
60.9400 2.9833 1.0000
61.0000 5.8622 1.0000
61.0600 9.6877 1.0000
61.1200 11.9200 1.0000
61.1800 4.1284 1.0000
61.2400 10.2495 1.0000
61.3000 7.8887 1.0000
61.3600 5.8868 1.0000
61.4200 8.3689 1.0000
61.4800 7.0775 1.0000
61.5400 10.1667 1.0000
61.6000 6.2497 1.0000
61.6600 3.3567 1.0000
61.7200 5.3611 1.0000
61.7800 4.5537 1.0000
61.8400 3.2442 1.0000
61.9000 3.3899 1.0000
61.9600 5.1477 1.0000
62.0200 7.4691 1.0000
62.0800 12.4339 1.0000
62.1400 4.8350 1.0000
62.2000 5.1369 1.0000
62.2600 4.3793 1.0000
62.3200 10.7661 1.0000
62.3800 11.4210 1.0000
62.4400 3.1380 1.0000
62.5000 8.1470 1.0000
62.5600 8.2051 1.0000
62.6200 6.4471 1.0000
62.6800 5.2176 1.0000
62.7400 4.8957 1.0000
62.8000 6.9072 1.0000
62.8600 1.6301 1.0000
62.9200 3.4670 1.0000
62.9800 8.5641 1.0000
63.0400 1.2510 1.0000
63.1000 6.5488 1.0000
63.1600 4.7962 1.0000
63.2200 11.0917 1.0000
63.2800 2.5408 1.0000
63.3400 3.9375 1.0000
63.4000 2.8793 1.0000
63.4600 8.0858 1.0000
63.5200 5.7960 1.0000
63.5800 8.1771 1.0000
63.6400 6.9904 1.0000
63.7000 7.6813 1.0000
63.7600 7.6299 1.0000
63.8200 4.6514 1.0000
63.8800 9.8064 1.0000
63.9400 6.1873 1.0000
64.0000 9.9405 1.0000
64.0600 8.6510 1.0000
64.1200 7.5189 1.0000
64.1800 6.9397 1.0000
64.2400 7.6796 1.0000
64.3000 11.0685 1.0000
64.3600 10.1707 1.0000
64.4200 8.8576 1.0000
64.4800 7.4323 1.0000
64.5400 7.7953 1.0000
64.6000 18.0452 1.0000
64.6600 10.7751 1.0000
64.7200 13.0455 1.0000
64.7800 19.7213 1.0000
64.8400 15.4684 1.0000
64.9000 15.8817 1.0000
64.9600 19.7249 1.0000
65.0200 10.1824 1.0000
65.0800 13.6821 1.0000
65.1400 9.1883 1.0000
65.2000 8.7238 1.0000
65.2600 3.3899 1.0000
65.3200 5.6746 1.0000
65.3800 7.3507 1.0000
65.4400 7.8088 1.0000
65.5000 8.8725 1.0000
65.5600 5.2941 1.0000
65.6200 1.4826 1.0000
65.6800 8.3590 1.0000
65.7400 5.2502 1.0000
65.8000 4.6612 1.0000
65.8600 8.3171 1.0000
65.9200 9.2358 1.0000
65.9800 4.0389 1.0000
66.0400 4.1401 1.0000
66.1000 6.9625 1.0000
66.1600 9.1706 1.0000
66.2200 5.0506 1.0000
66.2800 3.2941 1.0000
66.3400 4.4645 1.0000
66.4000 6.1174 1.0000
66.4600 4.3255 1.0000
66.5200 6.5259 1.0000
66.5800 9.1042 1.0000
66.6400 7.3098 1.0000
66.7000 3.6472 1.0000
66.7600 17.1046 1.0000
66.8200 5.0373 1.0000
66.8800 4.9964 1.0000
66.9400 7.8163 1.0000
67.0000 6.2061 1.0000
67.0600 8.5616 1.0000
67.1200 9.8755 1.0000
67.1800 4.4390 1.0000
67.2400 11.1538 1.0000
67.3000 4.6744 1.0000
67.3600 3.8573 1.0000
67.4200 9.0481 1.0000
67.4800 7.3059 1.0000
67.5400 8.2744 1.0000
67.6000 10.3437 1.0000
67.6600 2.6741 1.0000
67.7200 5.6698 1.0000
67.7800 7.9647 1.0000
67.8400 7.8339 1.0000
67.9000 8.7563 1.0000
67.9600 4.6238 1.0000
68.0200 7.5261 1.0000
68.0800 8.7235 1.0000
68.1400 9.3475 1.0000
68.2000 7.5064 1.0000
68.2600 9.1156 1.0000
68.3200 4.0142 1.0000
68.3800 2.4260 1.0000
68.4400 2.1415 1.0000
68.5000 6.4129 1.0000
68.5600 7.5445 1.0000
68.6200 5.2467 1.0000
68.6800 6.7728 1.0000
68.7400 5.3023 1.0000
68.8000 4.8063 1.0000
68.8600 5.4729 1.0000
68.9200 3.2215 1.0000
68.9800 5.0286 1.0000
69.0400 4.3502 1.0000
69.1000 11.4076 1.0000
69.1600 5.5097 1.0000
69.2200 2.4624 1.0000
69.2800 7.2940 1.0000
69.3400 3.5970 1.0000
69.4000 11.7098 1.0000
69.4600 7.4722 1.0000
69.5200 5.0081 1.0000
69.5800 8.3763 1.0000
69.6400 9.4382 1.0000
69.7000 5.8817 1.0000
69.7600 7.2175 1.0000
69.8200 7.2967 1.0000
69.8800 7.6634 1.0000
69.9400 4.3947 1.0000
70.0000 5.0081 1.0000
70.0600 4.2109 1.0000
70.1200 11.9038 1.0000
70.1800 5.8775 1.0000
70.2400 9.9768 1.0000
70.3000 4.2230 1.0000
70.3600 2.1756 1.0000
70.4200 6.7660 1.0000
70.4800 10.1829 1.0000
70.5400 1.8799 1.0000
70.6000 3.8935 1.0000
70.6600 8.6773 1.0000
70.7200 3.2045 1.0000
70.7800 8.1064 1.0000
70.8400 5.4143 1.0000
70.9000 4.4820 1.0000
70.9600 7.1229 1.0000
71.0200 3.1968 1.0000
71.0800 4.2862 1.0000
71.1400 6.5533 1.0000
71.2000 7.2227 1.0000
71.2600 5.0539 1.0000
71.3200 4.1466 1.0000
71.3800 6.9848 1.0000
71.4400 2.8378 1.0000
71.5000 11.0634 1.0000
71.5600 5.0299 1.0000
71.6200 6.1694 1.0000
71.6800 5.8459 1.0000
71.7400 5.4463 1.0000
71.8000 4.8324 1.0000
71.8600 5.4686 1.0000
71.9200 4.1777 1.0000
71.9800 7.7692 1.0000
72.0400 5.0255 1.0000
72.1000 6.3656 1.0000
72.1600 7.0542 1.0000
72.2200 5.6981 1.0000
72.2800 9.8010 1.0000
72.3400 7.0302 1.0000
72.4000 3.9104 1.0000
72.4600 4.9248 1.0000
72.5200 3.7919 1.0000
72.5800 6.2165 1.0000
72.6400 8.4362 1.0000
72.7000 7.1526 1.0000
72.7600 0.6422 1.0000
72.8200 3.7485 1.0000
72.8800 5.0164 1.0000
72.9400 2.6811 1.0000
73.0000 7.8796 1.0000
73.0600 2.7257 1.0000
73.1200 8.8029 1.0000
73.1800 3.6538 1.0000
73.2400 9.7926 1.0000
73.3000 7.5493 1.0000
73.3600 5.0360 1.0000
73.4200 10.4421 1.0000
73.4800 8.3423 1.0000
73.5400 8.0533 1.0000
73.6000 5.1567 1.0000
73.6600 3.3990 1.0000
73.7200 7.7127 1.0000
73.7800 6.1742 1.0000
73.8400 4.7578 1.0000
73.9000 7.0323 1.0000
73.9600 6.4221 1.0000
74.0200 4.1037 1.0000
74.0800 7.8154 1.0000
74.1400 6.6578 1.0000
74.2000 5.3877 1.0000
74.2600 9.2083 1.0000
74.3200 10.7496 1.0000
74.3800 6.4765 1.0000
74.4400 9.7135 1.0000
74.5000 9.1061 1.0000
74.5600 5.2866 1.0000
74.6200 5.4576 1.0000
74.6800 5.4341 1.0000
74.7400 3.9614 1.0000
74.8000 9.8011 1.0000
74.8600 8.2224 1.0000
74.9200 2.8419 1.0000
74.9800 3.9948 1.0000
75.0400 7.2129 1.0000
75.1000 6.8553 1.0000
75.1600 4.2512 1.0000
75.2200 6.2416 1.0000
75.2800 3.0763 1.0000
75.3400 3.9878 1.0000
75.4000 5.5382 1.0000
75.4600 6.5990 1.0000
75.5200 3.1753 1.0000
75.5800 5.5624 1.0000
75.6400 7.1411 1.0000
75.7000 7.7087 1.0000
75.7600 8.1977 1.0000
75.8200 7.0550 1.0000
75.8800 6.2990 1.0000
75.9400 5.4414 1.0000
76.0000 8.2182 1.0000
76.0600 5.3229 1.0000
76.1200 7.8881 1.0000
76.1800 4.7152 1.0000
76.2400 5.9819 1.0000
76.3000 3.5024 1.0000
76.3600 4.0525 1.0000
76.4200 3.9154 1.0000
76.4800 2.7895 1.0000
76.5400 3.8516 1.0000
76.6000 8.2033 1.0000
76.6600 6.1703 1.0000
76.7200 6.0455 1.0000
76.7800 6.7856 1.0000
76.8400 6.3393 1.0000
76.9000 5.5645 1.0000
76.9600 8.1752 1.0000
77.0200 5.3410 1.0000
77.0800 7.3770 1.0000
77.1400 4.2441 1.0000
77.2000 9.8145 1.0000
77.2600 5.3560 1.0000
77.3200 5.9806 1.0000
77.3800 3.4809 1.0000
77.4400 3.0135 1.0000
77.5000 6.7364 1.0000
77.5600 2.1804 1.0000
77.6200 1.4042 1.0000
77.6800 4.3203 1.0000
77.7400 5.7205 1.0000
77.8000 5.4165 1.0000
77.8600 4.1185 1.0000
77.9200 4.7368 1.0000
77.9800 8.0691 1.0000
78.0400 6.9122 1.0000
78.1000 8.9923 1.0000
78.1600 6.5474 1.0000
78.2200 7.8011 1.0000
78.2800 6.3405 1.0000
78.3400 2.5983 1.0000
78.4000 4.1449 1.0000
78.4600 4.1930 1.0000
78.5200 4.3601 1.0000
78.5800 6.6933 1.0000
78.6400 6.3987 1.0000
78.7000 6.8345 1.0000
78.7600 6.7822 1.0000
78.8200 5.6613 1.0000
78.8800 2.4885 1.0000
78.9400 6.0791 1.0000
79.0000 5.8837 1.0000
79.0600 3.9351 1.0000
79.1200 5.7409 1.0000
79.1800 4.1898 1.0000
79.2400 4.3193 1.0000
79.3000 1.9368 1.0000
79.3600 4.5083 1.0000
79.4200 6.7377 1.0000
79.4800 5.8428 1.0000
79.5400 7.6556 1.0000
79.6000 3.7388 1.0000
79.6600 2.0880 1.0000
79.7200 3.5841 1.0000
79.7800 7.1519 1.0000
79.8400 5.9032 1.0000
79.9000 6.2209 1.0000
79.9600 5.8336 1.0000
80.0200 6.5433 1.0000
80.0800 5.3722 1.0000
80.1400 5.8420 1.0000
80.2000 5.3359 1.0000
80.2600 6.2288 1.0000
80.3200 6.9727 1.0000
80.3800 8.8094 1.0000
80.4400 8.1791 1.0000
80.5000 9.2771 1.0000
80.5600 4.6017 1.0000
80.6200 10.2787 1.0000
80.6800 2.2693 1.0000
80.7400 7.8604 1.0000
80.8000 4.5750 1.0000
80.8600 6.1112 1.0000
80.9200 2.5057 1.0000
80.9800 3.5151 1.0000
81.0400 3.5465 1.0000
81.1000 1.5628 1.0000
81.1600 4.6157 1.0000
81.2200 2.2104 1.0000
81.2800 7.3557 1.0000
81.3400 10.0069 1.0000
81.4000 5.3046 1.0000
81.4600 6.5196 1.0000
81.5200 6.4245 1.0000
81.5800 5.3689 1.0000
81.6400 6.2226 1.0000
81.7000 6.8821 1.0000
81.7600 4.4027 1.0000
81.8200 9.2308 1.0000
81.8800 12.1456 1.0000
81.9400 17.6151 1.0000
82.0000 17.1464 1.0000
82.0600 26.4887 1.0000
82.1200 33.5439 1.0000
82.1800 29.1545 1.0000
82.2400 24.3547 1.0000
82.3000 18.6963 1.0000
82.3600 18.4657 1.0000
82.4200 11.7955 1.0000
82.4800 10.4573 1.0000
82.5400 6.2575 1.0000
82.6000 10.0096 1.0000
82.6600 7.1115 1.0000
82.7200 6.2373 1.0000
82.7800 8.9096 1.0000
82.8400 9.4252 1.0000
82.9000 5.1693 1.0000
82.9600 6.1972 1.0000
83.0200 5.3371 1.0000
83.0800 11.1442 1.0000
83.1400 3.7700 1.0000
83.2000 8.9766 1.0000
83.2600 5.9434 1.0000
83.3200 6.8907 1.0000
83.3800 11.2365 1.0000
83.4400 11.1227 1.0000
83.5000 0.3301 1.0000
83.5600 8.6894 1.0000
83.6200 12.3541 1.0000
83.6800 4.7344 1.0000
83.7400 10.3871 1.0000
83.8000 5.4596 1.0000
83.8600 6.4374 1.0000
83.9200 2.1370 1.0000
83.9800 6.0457 1.0000
84.0400 9.2114 1.0000
84.1000 4.6603 1.0000
84.1600 4.6401 1.0000
84.2200 6.1541 1.0000
84.2800 15.2406 1.0000
84.3400 8.2647 1.0000
84.4000 3.8408 1.0000
84.4600 5.4980 1.0000
84.5200 3.4153 1.0000
84.5800 5.2881 1.0000
84.6400 7.5516 1.0000
84.7000 3.6458 1.0000
84.7600 14.2410 1.0000
84.8200 6.3934 1.0000
84.8800 3.4721 1.0000
84.9400 7.3729 1.0000
85.0000 6.7443 1.0000
85.0600 9.4140 1.0000
85.1200 4.3038 1.0000
85.1800 9.6620 1.0000
85.2400 5.5006 1.0000
85.3000 7.0047 1.0000
85.3600 2.4331 1.0000
85.4200 10.0059 1.0000
85.4800 8.9691 1.0000
85.5400 3.5172 1.0000
85.6000 6.1121 1.0000
85.6600 14.8980 1.0000
85.7200 4.3133 1.0000
85.7800 7.4776 1.0000
85.8400 3.6276 1.0000
85.9000 5.6693 1.0000
85.9600 3.3692 1.0000
86.0200 3.4846 1.0000
86.0800 6.8323 1.0000
86.1400 3.8354 1.0000
86.2000 7.3493 1.0000
86.2600 6.6007 1.0000
86.3200 3.8117 1.0000
86.3800 5.5239 1.0000
86.4400 4.0952 1.0000
86.5000 9.2235 1.0000
86.5600 3.3409 1.0000
86.6200 6.6190 1.0000
86.6800 4.2430 1.0000
86.7400 6.2478 1.0000
86.8000 16.8563 1.0000
86.8600 5.9207 1.0000
86.9200 6.7456 1.0000
86.9800 5.3730 1.0000
87.0400 7.2259 1.0000
87.1000 6.2204 1.0000
87.1600 3.0528 1.0000
87.2200 5.6404 1.0000
87.2800 6.6604 1.0000
87.3400 4.0868 1.0000
87.4000 5.2708 1.0000
87.4600 3.7696 1.0000
87.5200 4.3284 1.0000
87.5800 6.2778 1.0000
87.6400 6.1453 1.0000
87.7000 2.7986 1.0000
87.7600 8.8923 1.0000
87.8200 10.5324 1.0000
87.8800 9.6692 1.0000
87.9400 5.2621 1.0000
88.0000 10.0610 1.0000
88.0600 4.3570 1.0000
88.1200 3.8490 1.0000
88.1800 3.5933 1.0000
88.2400 10.4552 1.0000
88.3000 4.9090 1.0000
88.3600 3.1103 1.0000
88.4200 3.1535 1.0000
88.4800 7.2409 1.0000
88.5400 6.4948 1.0000
88.6000 7.8337 1.0000
88.6600 6.6037 1.0000
88.7200 4.1793 1.0000
88.7800 4.3741 1.0000
88.8400 5.7949 1.0000
88.9000 7.3391 1.0000
88.9600 3.0997 1.0000
89.0200 5.5953 1.0000
89.0800 4.9320 1.0000
89.1400 5.9704 1.0000
89.2000 5.3146 1.0000
89.2600 2.5772 1.0000
89.3200 7.3064 1.0000
89.3800 7.8932 1.0000
89.4400 5.7155 1.0000
89.5000 9.4833 1.0000
89.5600 11.8399 1.0000
89.6200 7.8501 1.0000
89.6800 2.0644 1.0000
89.7400 4.4300 1.0000
89.8000 7.8588 1.0000
89.8600 4.2762 1.0000
89.9200 12.1005 1.0000
89.9800 2.8737 1.0000
90.0400 2.7810 1.0000
90.1000 6.3757 1.0000
90.1600 5.3085 1.0000
90.2200 8.6285 1.0000
90.2800 2.5715 1.0000
90.3400 5.2881 1.0000
90.4000 5.2714 1.0000
90.4600 4.6444 1.0000
90.5200 5.1609 1.0000
90.5800 5.3380 1.0000
90.6400 7.9329 1.0000
90.7000 9.3692 1.0000
90.7600 4.9307 1.0000
90.8200 6.2594 1.0000
90.8800 8.1752 1.0000
90.9400 8.4478 1.0000
91.0000 4.2315 1.0000
91.0600 4.7621 1.0000
91.1200 7.3751 1.0000
91.1800 4.0520 1.0000
91.2400 2.3901 1.0000
91.3000 6.3560 1.0000
91.3600 5.9044 1.0000
91.4200 4.6983 1.0000
91.4800 6.4056 1.0000
91.5400 6.4030 1.0000
91.6000 9.9189 1.0000
91.6600 5.0245 1.0000
91.7200 2.6363 1.0000
91.7800 2.4753 1.0000
91.8400 6.5405 1.0000
91.9000 5.1265 1.0000
91.9600 2.7630 1.0000
92.0200 3.4242 1.0000
92.0800 4.9813 1.0000
92.1400 11.3959 1.0000
92.2000 8.5237 1.0000
92.2600 3.9682 1.0000
92.3200 4.3373 1.0000
92.3800 2.7485 1.0000
92.4400 2.6999 1.0000
92.5000 11.5393 1.0000
92.5600 5.9605 1.0000
92.6200 6.6938 1.0000
92.6800 6.1139 1.0000
92.7400 3.1633 1.0000
92.8000 6.0782 1.0000
92.8600 6.5188 1.0000
92.9200 8.1217 1.0000
92.9800 9.3782 1.0000
93.0400 6.1601 1.0000
93.1000 7.6192 1.0000
93.1600 6.1732 1.0000
93.2200 9.0258 1.0000
93.2800 8.4960 1.0000
93.3400 3.2410 1.0000
93.4000 5.7344 1.0000
93.4600 3.2364 1.0000
93.5200 6.6492 1.0000
93.5800 5.7900 1.0000
93.6400 6.2678 1.0000
93.7000 8.9841 1.0000
93.7600 3.5934 1.0000
93.8200 2.1728 1.0000
93.8800 6.3578 1.0000
93.9400 5.2605 1.0000
94.0000 3.9204 1.0000
94.0600 3.6240 1.0000
94.1200 3.1156 1.0000
94.1800 4.1242 1.0000
94.2400 4.1599 1.0000
94.3000 5.1088 1.0000
94.3600 3.2146 1.0000
94.4200 9.8265 1.0000
94.4800 5.1050 1.0000
94.5400 4.9266 1.0000
94.6000 4.3777 1.0000
94.6600 5.6101 1.0000
94.7200 3.4509 1.0000
94.7800 3.6952 1.0000
94.8400 8.2650 1.0000
94.9000 12.1359 1.0000
94.9600 5.4273 1.0000
95.0200 10.2812 1.0000
95.0800 8.2893 1.0000
95.1400 7.3820 1.0000
95.2000 4.8178 1.0000
95.2600 8.3298 1.0000
95.3200 0.9816 1.0000
95.3800 10.0902 1.0000
95.4400 9.1142 1.0000
95.5000 6.6001 1.0000
95.5600 8.1856 1.0000
95.6200 7.0230 1.0000
95.6800 4.5305 1.0000
95.7400 3.9741 1.0000
95.8000 4.8763 1.0000
95.8600 5.4987 1.0000
95.9200 4.8418 1.0000
95.9800 9.8729 1.0000
96.0400 8.0794 1.0000
96.1000 6.5887 1.0000
96.1600 3.1232 1.0000
96.2200 6.0018 1.0000
96.2800 6.2661 1.0000
96.3400 9.3330 1.0000
96.4000 5.0846 1.0000
96.4600 5.4883 1.0000
96.5200 10.2932 1.0000
96.5800 5.2026 1.0000
96.6400 10.5657 1.0000
96.7000 8.6378 1.0000
96.7600 5.7236 1.0000
96.8200 8.0373 1.0000
96.8800 4.8936 1.0000
96.9400 3.7974 1.0000
97.0000 4.5887 1.0000
97.0600 11.6021 1.0000
97.1200 7.6445 1.0000
97.1800 7.0767 1.0000
97.2400 5.7609 1.0000
97.3000 5.4236 1.0000
97.3600 4.0535 1.0000
97.4200 6.5470 1.0000
97.4800 7.3203 1.0000
97.5400 4.1081 1.0000
97.6000 7.5763 1.0000
97.6600 5.4385 1.0000
97.7200 5.5462 1.0000
97.7800 7.9139 1.0000
97.8400 4.5604 1.0000
97.9000 9.3353 1.0000
97.9600 4.4888 1.0000
98.0200 6.3437 1.0000
98.0800 23.7073 1.0000
98.1400 4.2724 1.0000
98.2000 7.6889 1.0000
98.2600 8.8734 1.0000
98.3200 6.8245 1.0000
98.3800 8.3597 1.0000
98.4400 10.0212 1.0000
98.5000 10.0686 1.0000
98.5600 14.4497 1.0000
98.6200 17.5971 1.0000
98.6800 16.7776 1.0000
98.7400 21.3333 1.0000
98.8000 13.3042 1.0000
98.8600 9.0445 1.0000
98.9200 8.0158 1.0000
98.9800 13.8942 1.0000
99.0400 9.5149 1.0000
99.1000 3.2152 1.0000
99.1600 15.3086 1.0000
99.2200 3.7073 1.0000
99.2800 9.1415 1.0000
99.3400 4.9964 1.0000
99.4000 4.6136 1.0000
99.4600 5.2158 1.0000
99.5200 7.8503 1.0000
99.5800 9.4505 1.0000
99.6400 9.5884 1.0000
99.7000 7.5421 1.0000
99.7600 3.4979 1.0000
99.8200 4.5963 1.0000
99.8800 5.9121 1.0000
99.9400 4.0916 1.0000
100.0000 12.4694 1.0000
100.0600 9.4053 1.0000
100.1200 11.2570 1.0000
100.1800 7.1570 1.0000
100.2400 6.1590 1.0000
100.3000 7.4784 1.0000
100.3600 12.3528 1.0000
100.4200 6.3827 1.0000
100.4800 4.0859 1.0000
100.5400 5.0485 1.0000
100.6000 9.6009 1.0000
100.6600 11.7442 1.0000
100.7200 6.0394 1.0000
100.7800 8.6870 1.0000
100.8400 5.3001 1.0000
100.9000 5.7031 1.0000
100.9600 3.1128 1.0000
101.0200 5.6219 1.0000
101.0800 6.2473 1.0000
101.1400 6.1840 1.0000
101.2000 4.8469 1.0000
101.2600 0.2675 1.0000
101.3200 2.7457 1.0000
101.3800 5.0615 1.0000
101.4400 4.3322 1.0000
101.5000 2.5591 1.0000
101.5600 3.8179 1.0000
101.6200 1.9975 1.0000
101.6800 5.9327 1.0000
101.7400 6.4426 1.0000
101.8000 6.8073 1.0000
101.8600 5.4981 1.0000
101.9200 8.9753 1.0000
101.9800 7.7969 1.0000
102.0400 3.4987 1.0000
102.1000 5.5082 1.0000
102.1600 4.3227 1.0000
102.2200 6.8131 1.0000
102.2800 9.6940 1.0000
102.3400 8.1627 1.0000
102.4000 10.0542 1.0000
102.4600 5.2918 1.0000
102.5200 5.9313 1.0000
102.5800 8.7789 1.0000
102.6400 8.7822 1.0000
102.7000 13.0645 1.0000
102.7600 7.3155 1.0000
102.8200 3.0655 1.0000
102.8800 5.2338 1.0000
102.9400 5.1862 1.0000
103.0000 2.1294 1.0000
103.0600 5.3262 1.0000
103.1200 5.0127 1.0000
103.1800 8.0620 1.0000
103.2400 4.6883 1.0000
103.3000 4.2816 1.0000
103.3600 5.2911 1.0000
103.4200 7.9368 1.0000
103.4800 9.3994 1.0000
103.5400 6.1742 1.0000
103.6000 8.5710 1.0000
103.6600 1.8288 1.0000
103.7200 7.0957 1.0000
103.7800 7.5462 1.0000
103.8400 8.1508 1.0000
103.9000 5.8600 1.0000
103.9600 12.7691 1.0000
104.0200 6.1700 1.0000
104.0800 4.2537 1.0000
104.1400 6.3520 1.0000
104.2000 5.2252 1.0000
104.2600 2.9883 1.0000
104.3200 5.5583 1.0000
104.3800 4.8256 1.0000
104.4400 9.7483 1.0000
104.5000 9.2822 1.0000
104.5600 2.1616 1.0000
104.6200 2.7947 1.0000
104.6800 4.7986 1.0000
104.7400 3.2017 1.0000
104.8000 5.3674 1.0000
104.8600 5.9769 1.0000
104.9200 5.9757 1.0000
104.9800 5.5812 1.0000
105.0400 4.8829 1.0000
105.1000 10.5351 1.0000
105.1600 7.2698 1.0000
105.2200 6.7169 1.0000
105.2800 6.8883 1.0000
105.3400 5.8392 1.0000
105.4000 5.5616 1.0000
105.4600 4.1443 1.0000
105.5200 8.5324 1.0000
105.5800 8.8775 1.0000
105.6400 3.5393 1.0000
105.7000 13.0775 1.0000
105.7600 10.2738 1.0000
105.8200 6.9273 1.0000
105.8800 2.9612 1.0000
105.9400 5.3709 1.0000
106.0000 3.5672 1.0000
106.0600 7.2234 1.0000
106.1200 7.4835 1.0000
106.1800 5.1832 1.0000
106.2400 6.7834 1.0000
106.3000 6.7560 1.0000
106.3600 6.8264 1.0000
106.4200 7.0440 1.0000
106.4800 3.0300 1.0000
106.5400 5.2737 1.0000
106.6000 6.4948 1.0000
106.6600 7.9564 1.0000
106.7200 5.8450 1.0000
106.7800 3.5640 1.0000
106.8400 6.3144 1.0000
106.9000 7.4832 1.0000
106.9600 3.1365 1.0000
107.0200 3.3481 1.0000
107.0800 5.3563 1.0000
107.1400 7.0728 1.0000
107.2000 5.8088 1.0000
107.2600 7.2273 1.0000
107.3200 4.2501 1.0000
107.3800 9.9276 1.0000
107.4400 5.0910 1.0000
107.5000 6.1777 1.0000
107.5600 3.6931 1.0000
107.6200 3.1731 1.0000
107.6800 7.6591 1.0000
107.7400 6.2087 1.0000
107.8000 6.1800 1.0000
107.8600 5.1759 1.0000
107.9200 5.2380 1.0000
107.9800 4.1323 1.0000
108.0400 8.2846 1.0000
108.1000 12.0311 1.0000
108.1600 9.9871 1.0000
108.2200 6.4604 1.0000
108.2800 11.4436 1.0000
[...]
67.0000 7.0119 1.0000
67.0600 7.3729 1.0000
67.1200 5.2612 1.0000
67.1800 3.5427 1.0000
67.2400 5.1984 1.0000
67.3000 5.1775 1.0000
67.3600 4.7690 1.0000
67.4200 6.3918 1.0000
67.4800 5.4145 1.0000
67.5400 4.9158 1.0000
67.6000 7.2904 1.0000
67.6600 4.4511 1.0000
67.7200 5.5611 1.0000
67.7800 7.9343 1.0000
67.8400 10.1354 1.0000
67.9000 5.1488 1.0000
67.9600 4.9753 1.0000
68.0200 4.1045 1.0000
68.0800 5.1409 1.0000
68.1400 10.5316 1.0000
68.2000 4.8290 1.0000
68.2600 4.8804 1.0000
68.3200 5.0800 1.0000
68.3800 3.9738 1.0000
68.4400 2.3826 1.0000
68.5000 4.3663 1.0000
68.5600 5.1257 1.0000
68.6200 2.7046 1.0000
68.6800 7.8769 1.0000
68.7400 7.6267 1.0000
68.8000 2.0022 1.0000
68.8600 5.2344 1.0000
68.9200 3.5226 1.0000
68.9800 4.9711 1.0000
69.0400 7.8782 1.0000
69.1000 7.1347 1.0000
69.1600 5.0015 1.0000
69.2200 4.7410 1.0000
69.2800 5.2661 1.0000
69.3400 5.6075 1.0000
69.4000 11.0550 1.0000
69.4600 7.0704 1.0000
69.5200 2.7852 1.0000
69.5800 4.2450 1.0000
69.6400 8.3282 1.0000
69.7000 2.4960 1.0000
69.7600 5.6060 1.0000
69.8200 13.2720 1.0000
69.8800 6.4300 1.0000
69.9400 9.0161 1.0000
70.0000 8.8493 1.0000
70.0600 7.9670 1.0000
70.1200 6.5095 1.0000
70.1800 10.0376 1.0000
70.2400 7.2128 1.0000
70.3000 4.1656 1.0000
70.3600 2.7529 1.0000
70.4200 7.7380 1.0000
70.4800 6.6060 1.0000
70.5400 4.6336 1.0000
70.6000 2.4846 1.0000
70.6600 7.4604 1.0000
70.7200 3.1496 1.0000
70.7800 5.5837 1.0000
70.8400 5.4242 1.0000
70.9000 9.0834 1.0000
70.9600 7.7576 1.0000
71.0200 6.6170 1.0000
71.0800 12.0841 1.0000
71.1400 5.0701 1.0000
71.2000 6.1302 1.0000
71.2600 4.2445 1.0000
71.3200 3.2754 1.0000
71.3800 9.7914 1.0000
71.4400 10.0151 1.0000
71.5000 5.2923 1.0000
71.5600 9.7338 1.0000
71.6200 6.1310 1.0000
71.6800 4.5860 1.0000
71.7400 4.5797 1.0000
71.8000 5.8403 1.0000
71.8600 5.5849 1.0000
71.9200 5.8776 1.0000
71.9800 3.5505 1.0000
72.0400 6.1766 1.0000
72.1000 3.6776 1.0000
72.1600 4.6232 1.0000
72.2200 7.2151 1.0000
72.2800 4.6453 1.0000
72.3400 5.4143 1.0000
72.4000 7.6270 1.0000
72.4600 4.5776 1.0000
72.5200 10.2481 1.0000
72.5800 9.1562 1.0000
72.6400 3.0586 1.0000
72.7000 3.2307 1.0000
72.7600 3.6025 1.0000
72.8200 2.8836 1.0000
72.8800 4.6583 1.0000
72.9400 10.0155 1.0000
73.0000 7.1323 1.0000
73.0600 7.0670 1.0000
73.1200 4.3794 1.0000
73.1800 7.6835 1.0000
73.2400 7.5114 1.0000
73.3000 14.2890 1.0000
73.3600 3.3762 1.0000
73.4200 14.2721 1.0000
73.4800 10.5953 1.0000
73.5400 6.1058 1.0000
73.6000 9.8661 1.0000
73.6600 4.3188 1.0000
73.7200 3.2459 1.0000
73.7800 6.9344 1.0000
73.8400 9.5555 1.0000
73.9000 5.7899 1.0000
73.9600 6.3341 1.0000
74.0200 4.2885 1.0000
74.0800 7.5251 1.0000
74.1400 7.3685 1.0000
74.2000 9.9381 1.0000
74.2600 7.5188 1.0000
74.3200 7.6449 1.0000
74.3800 6.3434 1.0000
74.4400 6.8269 1.0000
74.5000 6.6146 1.0000
74.5600 3.4018 1.0000
74.6200 4.5113 1.0000
74.6800 1.9183 1.0000
74.7400 2.7531 1.0000
74.8000 6.1214 1.0000
74.8600 7.3807 1.0000
74.9200 7.5947 1.0000
74.9800 3.4008 1.0000
75.0400 4.0576 1.0000
75.1000 3.9891 1.0000
75.1600 2.5643 1.0000
75.2200 6.2166 1.0000
75.2800 5.1871 1.0000
75.3400 8.7549 1.0000
75.4000 11.1736 1.0000
75.4600 7.5220 1.0000
75.5200 6.2247 1.0000
75.5800 4.3456 1.0000
75.6400 8.9450 1.0000
75.7000 4.8108 1.0000
75.7600 5.5501 1.0000
75.8200 6.6572 1.0000
75.8800 5.8631 1.0000
75.9400 3.4305 1.0000
76.0000 4.6027 1.0000
76.0600 3.8786 1.0000
76.1200 4.2799 1.0000
76.1800 9.4140 1.0000
76.2400 11.4790 1.0000
76.3000 7.9683 1.0000
76.3600 5.2219 1.0000
76.4200 5.5816 1.0000
76.4800 12.3819 1.0000
76.5400 5.5486 1.0000
76.6000 16.9859 1.0000
76.6600 3.9891 1.0000
76.7200 3.2594 1.0000
76.7800 5.0896 1.0000
76.8400 7.1742 1.0000
76.9000 5.8491 1.0000
76.9600 5.5904 1.0000
77.0200 3.9874 1.0000
77.0800 5.3412 1.0000
77.1400 12.6008 1.0000
77.2000 7.8119 1.0000
77.2600 3.1592 1.0000
77.3200 6.0787 1.0000
77.3800 2.2935 1.0000
77.4400 6.0772 1.0000
77.5000 6.7061 1.0000
77.5600 6.5108 1.0000
77.6200 2.9969 1.0000
77.6800 9.2305 1.0000
77.7400 7.6203 1.0000
77.8000 3.9837 1.0000
77.8600 5.8893 1.0000
77.9200 3.4732 1.0000
77.9800 5.4728 1.0000
78.0400 3.4244 1.0000
78.1000 4.4485 1.0000
78.1600 6.0587 1.0000
78.2200 4.6407 1.0000
78.2800 4.5298 1.0000
78.3400 4.8054 1.0000
78.4000 4.3184 1.0000
78.4600 6.6757 1.0000
78.5200 8.0525 1.0000
78.5800 6.8519 1.0000
78.6400 9.1992 1.0000
78.7000 7.4342 1.0000
78.7600 3.0770 1.0000
78.8200 5.6673 1.0000
78.8800 4.9342 1.0000
78.9400 8.5610 1.0000
79.0000 6.3318 1.0000
79.0600 6.8315 1.0000
79.1200 2.4533 1.0000
79.1800 8.2600 1.0000
79.2400 5.1809 1.0000
79.3000 4.5237 1.0000
79.3600 4.1520 1.0000
79.4200 3.0051 1.0000
79.4800 6.9053 1.0000
79.5400 6.3472 1.0000
79.6000 1.8864 1.0000
79.6600 5.7636 1.0000
79.7200 5.4022 1.0000
79.7800 7.9224 1.0000
79.8400 7.2722 1.0000
79.9000 10.8150 1.0000
79.9600 5.3662 1.0000
80.0200 3.8074 1.0000
80.0800 12.0565 1.0000
80.1400 4.9685 1.0000
80.2000 3.5383 1.0000
80.2600 3.9994 1.0000
80.3200 9.4903 1.0000
80.3800 7.6251 1.0000
80.4400 2.9693 1.0000
80.5000 6.6795 1.0000
80.5600 5.2862 1.0000
80.6200 3.6097 1.0000
80.6800 5.0456 1.0000
80.7400 7.2304 1.0000
80.8000 4.5573 1.0000
80.8600 3.8280 1.0000
80.9200 8.6883 1.0000
80.9800 2.3523 1.0000
81.0400 11.6017 1.0000
81.1000 3.4961 1.0000
81.1600 9.2357 1.0000
81.2200 4.5767 1.0000
81.2800 8.8800 1.0000
81.3400 7.3142 1.0000
81.4000 4.3668 1.0000
81.4600 11.5177 1.0000
81.5200 8.8338 1.0000
81.5800 13.3819 1.0000
81.6400 9.0174 1.0000
81.7000 6.1428 1.0000
81.7600 9.0276 1.0000
81.8200 10.8410 1.0000
81.8800 13.8223 1.0000
81.9400 21.9891 1.0000
82.0000 35.9719 1.0000
82.0600 31.9793 1.0000
82.1200 39.4537 1.0000
82.1800 33.7733 1.0000
82.2400 24.6293 1.0000
82.3000 18.6797 1.0000
82.3600 14.5376 1.0000
82.4200 6.8448 1.0000
82.4800 13.8065 1.0000
82.5400 9.3564 1.0000
82.6000 10.8399 1.0000
82.6600 8.5391 1.0000
82.7200 7.4373 1.0000
82.7800 8.4146 1.0000
82.8400 4.1370 1.0000
82.9000 4.8296 1.0000
82.9600 5.4769 1.0000
83.0200 6.1726 1.0000
83.0800 7.2217 1.0000
83.1400 7.2076 1.0000
83.2000 2.0544 1.0000
83.2600 6.6709 1.0000
83.3200 7.1790 1.0000
83.3800 5.4179 1.0000
83.4400 7.9011 1.0000
83.5000 5.5610 1.0000
83.5600 6.6750 1.0000
83.6200 9.2686 1.0000
83.6800 8.7134 1.0000
83.7400 8.4461 1.0000
83.8000 7.2625 1.0000
83.8600 4.6189 1.0000
83.9200 3.3300 1.0000
83.9800 8.1986 1.0000
84.0400 14.2150 1.0000
84.1000 3.6810 1.0000
84.1600 3.6945 1.0000
84.2200 9.7390 1.0000
84.2800 7.7326 1.0000
84.3400 10.0077 1.0000
84.4000 4.6797 1.0000
84.4600 4.7810 1.0000
84.5200 5.1809 1.0000
84.5800 8.0918 1.0000
84.6400 6.2133 1.0000
84.7000 6.1496 1.0000
84.7600 6.0825 1.0000
84.8200 3.7930 1.0000
84.8800 6.7120 1.0000
84.9400 4.3535 1.0000
85.0000 6.0429 1.0000
85.0600 8.9027 1.0000
85.1200 2.6358 1.0000
85.1800 2.0717 1.0000
85.2400 4.6223 1.0000
85.3000 6.9058 1.0000
85.3600 6.1701 1.0000
85.4200 9.1442 1.0000
85.4800 9.1553 1.0000
85.5400 6.2580 1.0000
85.6000 5.2308 1.0000
85.6600 10.6295 1.0000
85.7200 4.0161 1.0000
85.7800 6.4795 1.0000
85.8400 4.5663 1.0000
85.9000 5.3788 1.0000
85.9600 3.0251 1.0000
86.0200 2.7220 1.0000
86.0800 5.6069 1.0000
86.1400 3.1440 1.0000
86.2000 2.9546 1.0000
86.2600 6.4391 1.0000
86.3200 6.8384 1.0000
86.3800 5.4512 1.0000
86.4400 6.0230 1.0000
86.5000 5.9888 1.0000
86.5600 4.4095 1.0000
86.6200 10.8441 1.0000
86.6800 11.4579 1.0000
86.7400 8.8895 1.0000
86.8000 5.1868 1.0000
86.8600 3.5816 1.0000
86.9200 3.6243 1.0000
86.9800 6.1228 1.0000
87.0400 5.3333 1.0000
87.1000 8.9185 1.0000
87.1600 8.8689 1.0000
87.2200 3.4800 1.0000
87.2800 4.3564 1.0000
87.3400 4.8195 1.0000
87.4000 7.9591 1.0000
87.4600 3.7688 1.0000
87.5200 4.1039 1.0000
87.5800 6.3192 1.0000
87.6400 2.2053 1.0000
87.7000 6.2805 1.0000
87.7600 5.6113 1.0000
87.8200 4.3261 1.0000
87.8800 4.4518 1.0000
87.9400 8.0582 1.0000
88.0000 19.7577 1.0000
88.0600 9.5672 1.0000
88.1200 7.0725 1.0000
88.1800 5.2600 1.0000
88.2400 3.0873 1.0000
88.3000 5.3871 1.0000
88.3600 4.1076 1.0000
88.4200 3.4311 1.0000
88.4800 2.2397 1.0000
88.5400 6.7703 1.0000
88.6000 8.0515 1.0000
88.6600 9.2314 1.0000
88.7200 6.1027 1.0000
88.7800 9.3704 1.0000
88.8400 4.2497 1.0000
88.9000 4.6846 1.0000
88.9600 6.4186 1.0000
89.0200 4.1395 1.0000
89.0800 6.4767 1.0000
89.1400 6.8777 1.0000
89.2000 5.8921 1.0000
89.2600 10.3698 1.0000
89.3200 7.4659 1.0000
89.3800 6.0710 1.0000
89.4400 9.7335 1.0000
89.5000 4.4816 1.0000
89.5600 11.3639 1.0000
89.6200 6.5477 1.0000
89.6800 3.0537 1.0000
89.7400 4.1583 1.0000
89.8000 3.8250 1.0000
89.8600 5.9274 1.0000
89.9200 3.9958 1.0000
89.9800 3.0413 1.0000
90.0400 6.4215 1.0000
90.1000 6.1062 1.0000
90.1600 7.2152 1.0000
90.2200 3.0667 1.0000
90.2800 9.5089 1.0000
90.3400 10.8288 1.0000
90.4000 6.7393 1.0000
90.4600 7.0586 1.0000
90.5200 5.3355 1.0000
90.5800 7.3072 1.0000
90.6400 5.6937 1.0000
90.7000 7.9128 1.0000
90.7600 5.4671 1.0000
90.8200 5.5648 1.0000
90.8800 10.5896 1.0000
90.9400 7.0512 1.0000
91.0000 4.2876 1.0000
91.0600 4.2127 1.0000
91.1200 6.9045 1.0000
91.1800 8.4996 1.0000
91.2400 3.8028 1.0000
91.3000 6.9004 1.0000
91.3600 3.5045 1.0000
91.4200 8.5207 1.0000
91.4800 6.4392 1.0000
91.5400 3.1862 1.0000
91.6000 8.8900 1.0000
91.6600 7.5024 1.0000
91.7200 5.9610 1.0000
91.7800 7.3019 1.0000
91.8400 6.4751 1.0000
91.9000 2.4337 1.0000
91.9600 3.0703 1.0000
92.0200 8.4720 1.0000
92.0800 9.7191 1.0000
92.1400 10.0494 1.0000
92.2000 5.3527 1.0000
92.2600 5.1163 1.0000
92.3200 5.1107 1.0000
92.3800 6.6125 1.0000
92.4400 5.2756 1.0000
92.5000 3.2082 1.0000
92.5600 4.4703 1.0000
92.6200 3.6482 1.0000
92.6800 7.6028 1.0000
92.7400 2.9628 1.0000
92.8000 4.9817 1.0000
92.8600 8.5697 1.0000
92.9200 14.9828 1.0000
92.9800 4.5100 1.0000
93.0400 7.9682 1.0000
93.1000 2.3175 1.0000
93.1600 2.4418 1.0000
93.2200 7.9593 1.0000
93.2800 9.1486 1.0000
93.3400 6.4184 1.0000
93.4000 6.5564 1.0000
93.4600 3.9604 1.0000
93.5200 3.4983 1.0000
93.5800 5.9779 1.0000
93.6400 9.6258 1.0000
93.7000 5.3183 1.0000
93.7600 2.0795 1.0000
93.8200 5.1626 1.0000
93.8800 4.1482 1.0000
93.9400 9.1268 1.0000
94.0000 3.1380 1.0000
94.0600 7.2332 1.0000
94.1200 4.0663 1.0000
94.1800 2.2960 1.0000
94.2400 3.0990 1.0000
94.3000 10.3139 1.0000
94.3600 2.9752 1.0000
94.4200 4.3411 1.0000
94.4800 3.0874 1.0000
94.5400 9.6221 1.0000
94.6000 9.7410 1.0000
94.6600 6.1158 1.0000
94.7200 7.8997 1.0000
94.7800 4.0996 1.0000
94.8400 6.5295 1.0000
94.9000 4.2126 1.0000
94.9600 4.8259 1.0000
95.0200 5.6920 1.0000
95.0800 6.5902 1.0000
95.1400 5.3103 1.0000
95.2000 3.6299 1.0000
95.2600 4.0108 1.0000
95.3200 9.0828 1.0000
95.3800 4.1377 1.0000
95.4400 3.6586 1.0000
95.5000 9.3117 1.0000
95.5600 4.4108 1.0000
95.6200 9.8826 1.0000
95.6800 2.5293 1.0000
95.7400 7.2463 1.0000
95.8000 5.3857 1.0000
95.8600 5.6840 1.0000
95.9200 1.8271 1.0000
95.9800 0.1349 1.0000
96.0400 6.1800 1.0000
96.1000 2.8229 1.0000
96.1600 2.5183 1.0000
96.2200 3.0484 1.0000
96.2800 2.7325 1.0000
96.3400 7.5761 1.0000
96.4000 4.1107 1.0000
96.4600 8.4001 1.0000
96.5200 5.4425 1.0000
96.5800 5.6411 1.0000
96.6400 6.5257 1.0000
96.7000 6.3953 1.0000
96.7600 2.8046 1.0000
96.8200 3.8443 1.0000
96.8800 6.1889 1.0000
96.9400 9.8675 1.0000
97.0000 7.1702 1.0000
97.0600 6.0939 1.0000
97.1200 5.4865 1.0000
97.1800 8.5919 1.0000
97.2400 6.0909 1.0000
97.3000 2.3915 1.0000
97.3600 1.5745 1.0000
97.4200 14.1294 1.0000
97.4800 4.2737 1.0000
97.5400 5.8526 1.0000
97.6000 7.0661 1.0000
97.6600 6.7924 1.0000
97.7200 3.6538 1.0000
97.7800 12.1690 1.0000
97.8400 5.8780 1.0000
97.9000 2.5736 1.0000
97.9600 7.1655 1.0000
98.0200 11.0152 1.0000
98.0800 2.3240 1.0000
98.1400 7.7615 1.0000
98.2000 14.1788 1.0000
98.2600 8.0293 1.0000
98.3200 4.8035 1.0000
98.3800 11.5505 1.0000
98.4400 16.7021 1.0000
98.5000 10.6373 1.0000
98.5600 19.0508 1.0000
98.6200 16.7558 1.0000
98.6800 22.4180 1.0000
98.7400 9.3844 1.0000
98.8000 13.8617 1.0000
98.8600 14.0270 1.0000
98.9200 6.7567 1.0000
98.9800 9.3293 1.0000
99.0400 4.4560 1.0000
99.1000 6.5478 1.0000
99.1600 4.3940 1.0000
99.2200 7.5848 1.0000
99.2800 6.0715 1.0000
99.3400 6.1415 1.0000
99.4000 6.7144 1.0000
99.4600 7.1859 1.0000
99.5200 7.1505 1.0000
99.5800 7.4982 1.0000
99.6400 2.7585 1.0000
99.7000 4.3542 1.0000
99.7600 7.0359 1.0000
99.8200 7.5330 1.0000
99.8800 10.3729 1.0000
99.9400 8.9662 1.0000
100.0000 17.2645 1.0000
100.0600 11.0451 1.0000
100.1200 14.0523 1.0000
100.1800 5.8248 1.0000
100.2400 6.5234 1.0000
100.3000 3.0677 1.0000
100.3600 9.3178 1.0000
100.4200 6.9768 1.0000
100.4800 4.8147 1.0000
100.5400 1.3656 1.0000
100.6000 1.6245 1.0000
100.6600 5.7216 1.0000
100.7200 4.9195 1.0000
100.7800 5.3955 1.0000
100.8400 4.6274 1.0000
100.9000 4.2751 1.0000
100.9600 7.3051 1.0000
101.0200 6.2402 1.0000
101.0800 6.1139 1.0000
101.1400 1.8536 1.0000
101.2000 2.3103 1.0000
101.2600 5.7957 1.0000
101.3200 4.5467 1.0000
101.3800 6.9869 1.0000
101.4400 11.0041 1.0000
101.5000 5.2242 1.0000
101.5600 5.8799 1.0000
101.6200 5.4590 1.0000
101.6800 9.7259 1.0000
101.7400 5.8135 1.0000
101.8000 6.5074 1.0000
101.8600 17.8096 1.0000
101.9200 10.6595 1.0000
101.9800 9.9775 1.0000
102.0400 6.8567 1.0000
102.1000 6.7603 1.0000
102.1600 4.8934 1.0000
102.2200 3.1300 1.0000
102.2800 7.6061 1.0000
102.3400 13.3054 1.0000
102.4000 9.4569 1.0000
102.4600 5.5318 1.0000
102.5200 5.4270 1.0000
102.5800 10.1562 1.0000
102.6400 3.4016 1.0000
102.7000 5.6445 1.0000
102.7600 3.1782 1.0000
102.8200 5.1266 1.0000
102.8800 9.1040 1.0000
102.9400 9.5705 1.0000
103.0000 5.3215 1.0000
103.0600 3.4669 1.0000
103.1200 7.2682 1.0000
103.1800 13.3538 1.0000
103.2400 2.8195 1.0000
103.3000 7.4017 1.0000
103.3600 7.1400 1.0000
103.4200 5.1582 1.0000
103.4800 4.1030 1.0000
103.5400 6.3655 1.0000
103.6000 5.4730 1.0000
103.6600 6.4235 1.0000
103.7200 3.2948 1.0000
103.7800 5.9012 1.0000
103.8400 10.5262 1.0000
103.9000 3.8846 1.0000
103.9600 5.6622 1.0000
104.0200 3.4514 1.0000
104.0800 10.5956 1.0000
104.1400 8.7384 1.0000
104.2000 4.1505 1.0000
104.2600 1.5949 1.0000
104.3200 5.4971 1.0000
104.3800 1.5501 1.0000
104.4400 1.5055 1.0000
104.5000 7.3600 1.0000
104.5600 4.1333 1.0000
104.6200 13.4663 1.0000
104.6800 1.2162 1.0000
104.7400 4.5486 1.0000
104.8000 3.2901 1.0000
104.8600 6.6830 1.0000
104.9200 3.5610 1.0000
104.9800 6.1287 1.0000
105.0400 9.4619 1.0000
105.1000 11.0454 1.0000
105.1600 4.1186 1.0000
105.2200 8.7596 1.0000
105.2800 8.3696 1.0000
105.3400 7.7190 1.0000
105.4000 7.9818 1.0000
105.4600 1.3387 1.0000
105.5200 7.9182 1.0000
105.5800 5.8265 1.0000
105.6400 4.0820 1.0000
105.7000 8.9410 1.0000
105.7600 13.7075 1.0000
105.8200 5.0959 1.0000
105.8800 7.6821 1.0000
105.9400 9.8984 1.0000
106.0000 4.6594 1.0000
106.0600 9.1646 1.0000
106.1200 6.5963 1.0000
106.1800 6.1229 1.0000
106.2400 3.8760 1.0000
106.3000 8.7803 1.0000
106.3600 6.8878 1.0000
106.4200 5.1958 1.0000
106.4800 5.0241 1.0000
106.5400 4.5351 1.0000
106.6000 5.5117 1.0000
106.6600 6.2587 1.0000
106.7200 3.3561 1.0000
106.7800 6.0813 1.0000
106.8400 4.0745 1.0000
106.9000 6.4652 1.0000
106.9600 7.7908 1.0000
107.0200 2.3067 1.0000
107.0800 5.1755 1.0000
107.1400 8.1417 1.0000
107.2000 2.2355 1.0000
107.2600 12.7944 1.0000
107.3200 5.3115 1.0000
107.3800 7.0046 1.0000
107.4400 5.3559 1.0000
107.5000 11.8571 1.0000
107.5600 10.1256 1.0000
107.6200 2.8414 1.0000
107.6800 4.6754 1.0000
107.7400 5.9715 1.0000
107.8000 8.0914 1.0000
107.8600 6.0549 1.0000
107.9200 3.1051 1.0000
107.9800 10.1871 1.0000
108.0400 5.2161 1.0000
108.1000 4.4156 1.0000
108.1600 7.5998 1.0000
108.2200 6.0135 1.0000
108.2800 10.3912 1.0000
108.3400 9.3172 1.0000
108.4000 8.6277 1.0000
108.4600 9.8328 1.0000
108.5200 12.0703 1.0000
108.5800 6.2178 1.0000
108.6400 4.9042 1.0000
108.7000 7.3027 1.0000
108.7600 4.4646 1.0000
108.8200 6.3136 1.0000
108.8800 7.2293 1.0000
108.9400 10.7780 1.0000
109.0000 5.5393 1.0000
109.0600 8.7124 1.0000
109.1200 2.6299 1.0000
109.1800 4.4603 1.0000
109.2400 6.1503 1.0000
109.3000 7.3032 1.0000
109.3600 3.2048 1.0000
109.4200 4.8236 1.0000
109.4800 10.1460 1.0000
109.5400 2.3103 1.0000
109.6000 4.4380 1.0000
109.6600 7.1453 1.0000
109.7200 4.8325 1.0000
109.7800 4.0393 1.0000
109.8400 6.9804 1.0000
109.9000 7.7913 1.0000
109.9600 7.1281 1.0000
110.0200 4.4335 1.0000
110.0800 3.3261 1.0000
110.1400 5.3572 1.0000
110.2000 5.5436 1.0000
110.2600 4.9455 1.0000
110.3200 9.3706 1.0000
110.3800 11.4206 1.0000
110.4400 8.8954 1.0000
110.5000 9.6583 1.0000
110.5600 8.2348 1.0000
110.6200 6.0969 1.0000
110.6800 2.0202 1.0000
110.7400 6.2070 1.0000
110.8000 8.5210 1.0000
110.8600 9.2372 1.0000
110.9200 3.2698 1.0000
110.9800 6.3326 1.0000
111.0400 4.2250 1.0000
111.1000 1.6637 1.0000
111.1600 7.8384 1.0000
111.2200 3.0070 1.0000
111.2800 3.2647 1.0000
111.3400 8.1361 1.0000
111.4000 5.6617 1.0000
111.4600 7.2866 1.0000
111.5200 6.1020 1.0000
111.5800 8.5166 1.0000
111.6400 11.9559 1.0000
111.7000 7.6527 1.0000
111.7600 4.3207 1.0000
111.8200 11.3963 1.0000
111.8800 8.1163 1.0000
111.9400 11.5402 1.0000
112.0000 7.5632 1.0000
112.0600 3.8216 1.0000
112.1200 1.6949 1.0000
112.1800 6.1783 1.0000
112.2400 5.3841 1.0000
112.3000 10.6140 1.0000
112.3600 6.1324 1.0000
112.4200 6.3689 1.0000
112.4800 9.5277 1.0000
112.5400 7.0154 1.0000
112.6000 5.3789 1.0000
112.6600 4.4189 1.0000
112.7200 3.3215 1.0000
112.7800 5.8134 1.0000
112.8400 5.1100 1.0000
112.9000 5.9203 1.0000
112.9600 7.9122 1.0000
113.0200 4.6573 1.0000
113.0800 7.1244 1.0000
113.1400 5.4368 1.0000
113.2000 5.8600 1.0000
113.2600 12.4218 1.0000
113.3200 7.4318 1.0000
113.3800 2.8580 1.0000
113.4400 6.5685 1.0000
113.5000 3.7531 1.0000
113.5600 4.5223 1.0000
113.6200 6.2545 1.0000
113.6800 7.4094 1.0000
113.7400 1.5354 1.0000
113.8000 2.6070 1.0000
113.8600 7.6431 1.0000
113.9200 9.3012 1.0000
113.9800 5.1884 1.0000
114.0400 8.1716 1.0000
114.1000 3.6251 1.0000
114.1600 3.7737 1.0000
114.2200 8.9504 1.0000
114.2800 9.1223 1.0000
114.3400 4.8168 1.0000
114.4000 2.7366 1.0000
114.4600 11.6497 1.0000
114.5200 5.2802 1.0000
114.5800 13.0413 1.0000
114.6400 5.9435 1.0000
114.7000 8.8293 1.0000
114.7600 7.2201 1.0000
114.8200 1.8916 1.0000
114.8800 13.4337 1.0000
114.9400 9.7765 1.0000
115.0000 19.8600 1.0000
115.0600 5.3223 1.0000
115.1200 8.9800 1.0000
115.1800 10.0707 1.0000
115.2400 8.2572 1.0000
115.3000 7.8030 1.0000
115.3600 7.7354 1.0000
115.4200 8.9684 1.0000
115.4800 7.3382 1.0000
115.5400 10.3753 1.0000
115.6000 10.0860 1.0000
115.6600 9.5938 1.0000
115.7200 12.7834 1.0000
115.7800 12.9096 1.0000
115.8400 9.1090 1.0000
115.9000 10.7332 1.0000
115.9600 13.0463 1.0000
116.0200 14.7227 1.0000
116.0800 14.0776 1.0000
116.1400 11.6464 1.0000
116.2000 10.9995 1.0000
116.2600 10.3497 1.0000
116.3200 13.2577 1.0000
116.3800 11.0866 1.0000
116.4400 11.5006 1.0000
116.5000 11.9042 1.0000
116.5600 7.5108 1.0000
116.6200 14.3942 1.0000
116.6800 3.8938 1.0000
116.7400 5.7337 1.0000
116.8000 4.7587 1.0000
116.8600 4.1271 1.0000
116.9200 8.3716 1.0000
116.9800 11.2164 1.0000
117.0400 13.4388 1.0000
117.1000 11.3036 1.0000
117.1600 3.9131 1.0000
117.2200 3.5891 1.0000
117.2800 4.1772 1.0000
117.3400 7.3006 1.0000
117.4000 6.7155 1.0000
117.4600 3.1508 1.0000
117.5200 5.5430 1.0000
117.5800 4.8658 1.0000
117.6400 4.2015 1.0000
117.7000 7.1024 1.0000
117.7600 3.3066 1.0000
117.8200 8.9693 1.0000
117.8800 6.9691 1.0000
117.9400 4.8995 1.0000
118.0000 10.1410 1.0000
118.0600 4.6188 1.0000
118.1200 3.8030 1.0000
118.1800 8.2334 1.0000
118.2400 5.5382 1.0000
118.3000 8.0983 1.0000
118.3600 2.9647 1.0000
118.4200 9.2817 1.0000
118.4800 7.2104 1.0000
118.5400 7.0459 1.0000
118.6000 7.8075 1.0000
118.6600 5.9901 1.0000
118.7200 10.7741 1.0000
118.7800 6.6985 1.0000
118.8400 7.7559 1.0000
118.9000 6.4789 1.0000
118.9600 7.2298 1.0000
119.0200 8.1731 1.0000
119.0800 9.9780 1.0000
119.1400 8.3534 1.0000
119.2000 6.8679 1.0000
119.2600 1.8069 1.0000
119.3200 5.0287 1.0000
119.3800 8.5769 1.0000
119.4400 6.9620 1.0000
119.5000 5.1431 1.0000
119.5600 4.2849 1.0000
119.6200 8.7605 1.0000
119.6800 7.0726 1.0000
119.7400 9.2223 1.0000
119.8000 7.7150 1.0000
119.8600 4.5707 1.0000
119.9200 6.4298 1.0000
119.9800 2.0979 1.0000
119.9900 5.7112 1.0000
*RAS_INT_END
*RAS_TEMPERATURE_START
*RAS_TEMPERATURE_END
*RAS_DATA_END