File: XRD/PB_Ge220_2.5SS_500umDS_RS1_Rod_2.5SS_Hypix1D_EFRW1_HAZ_Unirradiated.ras
*RAS_DATA_START
*RAS_HEADER_START
*DISP_FMT_X "%.3f"
*DISP_FMT_Y "%.0f"
*DISP_FULLSCALE "237.4013288854"
*DISP_LINE_COLOR "255.0000000000"
*DISP_LINE_STYLE "0.0000000000"
*DISP_LINE_WIDTH "0.2500000000"
*DISP_NOTE "Collected Data-230"
*DISP_OFFSET_Y "0.0000000000"
*DISP_PEAKSEARCH_UNIT_Y "cps"
*DISP_RANGE_BOTTOM "0.0000000000"
*DISP_RANGE_LEFT "40.0000000000"
*DISP_RANGE_LOGCUTOFF "0.0100000000"
*DISP_RANGE_RIGHT "119.9968000000"
*DISP_RANGE_TOP "237.4013288854"
*DISP_SCALE_MODE_Y "0.0000000000"
*DISP_TAB_NAME "Theta/2-Theta"
*DISP_TITLE_Y "Intensity"
*DISP_UNIT_Y "cps"
*DISP_WINDOW_NAME "MSG_MACROENGINE"
*FILE_COMMENT " "
*FILE_MD5 ""
*FILE_MEMO " "
*FILE_OPERATOR "Administrator"
*FILE_PART_ID "MEAS_KHP2_00061"
*FILE_SAMPLE " "
*FILE_TYPE "RAS_RAW"
*FILE_USERGROUP "System Manager"
*FILE_VERSION "1.0000000000"
*HW_ATTACHMENT_ID "ATT0021"
*HW_ATTACHMENT_NAME "XY-20mm|XY-20mm"
*HW_COUNTER_ID-0 "CUT0041"
*HW_COUNTER_ID-1 "CUT0051"
*HW_COUNTER_ID-2 "CUT0020"
*HW_COUNTER_ID-3 "CSL0021"
*HW_COUNTER_ID-4 "CMC0021"
*HW_COUNTER_NAME-0 "D/teX Ultra 250|D/teX Ultra 250"
*HW_COUNTER_NAME-1 "HyPix 3000(H)|HyPix 3000(H)"
*HW_COUNTER_NAME-2 "None|None"
*HW_COUNTER_NAME-3 "BBM|BBM"
*HW_COUNTER_NAME-4 "検出器モノクロメータ|Detector monochromator"
*HW_COUNTER_SELECT_NAME "HyPix 3000(H)|HyPix 3000(H)"
*HW_GONIOMETER_ID "GON0024"
*HW_GONIOMETER_NAME "SmartLab(In-plane)|SmartLab(In-plane)"
*HW_GONIOMETER_RADIUS-0 "90.0"
*HW_GONIOMETER_RADIUS-1 "114.0"
*HW_GONIOMETER_RADIUS-2 "190.0"
*HW_GONIOMETER_RADIUS-3 "300.0"
*HW_GONIOMETER_RADIUS-4 "187.0"
*HW_GONIOMETER_RADIUS-5 "300.0"
*HW_GONIOMETER_RADIUS-6 "113.0"
*HW_GONIOMETER_RADIUS-7 "331.0"
*HW_I_OPT_ID-0 "CBO0021"
*HW_I_OPT_ID-1 "ICR0021"
*HW_I_OPT_ID-2 "ISL0021"
*HW_I_OPT_ID-3 "ISO0021"
*HW_I_OPT_ID-4 "IAD0021"
*HW_I_OPT_ID-5 "IPR0001"
*HW_I_OPT_NAME-0 "CBOユニット|CBO unit"
*HW_I_OPT_NAME-1 "標準入射光学ユニット|Standard incident optical unit"
*HW_I_OPT_NAME-2 "標準入射スリットボックス|Standard incident slit box"
*HW_I_OPT_NAME-3 "入射平行スリット|Incident parallel slit"
*HW_I_OPT_NAME-4 "長手制限スリット|Length limiting slit"
*HW_I_OPT_NAME-5 "None|None"
*HW_R_ATTENUATER_AUTOMODE "0"
*HW_R_OPT_ID-0 "RSS0022"
*HW_R_OPT_ID-1 "RCR0022"
*HW_R_OPT_ID-2 "RSO0021"
*HW_R_OPT_ID-3 "RRS0022"
*HW_R_OPT_ID-4 "ATN0020"
*HW_R_OPT_ID-5 "RFL0021"
*HW_R_OPT_ID-6 "RAD0021"
*HW_R_OPT_NAME-0 "受光スリットボックス1(Zr軸付)|Receiving slit box # 1 (w/ Zr Axis)"
*HW_R_OPT_NAME-1 "標準受光光学ユニット1|Standard receiving unit # 1"
*HW_R_OPT_NAME-2 "標準受光光学ユニット2|Standard receiving optical unit # 2"
*HW_R_OPT_NAME-3 "仮想受光スリット2|Virtual receiving slit #2"
*HW_R_OPT_NAME-4 "無し|None"
*HW_R_OPT_NAME-5 "Cu Kβ|Cu K-beta"
*HW_R_OPT_NAME-6 "調整用受光スリット|Alignment receiving slit"
*HW_SAMPLE_HOLDER_ID "SMP0021"
*HW_SAMPLE_HOLDER_NAME "χφZクレードル|Chi phi Z cradle"
*HW_XG_CURRENT_MAX "40"
*HW_XG_CURRENT_MIN "2"
*HW_XG_CURRENT_RESOLUTION "1"
*HW_XG_CURRENT_UNIT "mA"
*HW_XG_FOCUS "0.4mm x 8mm"
*HW_XG_FOCUS_TYPE "Fine"
*HW_XG_ID "1200"
*HW_XG_NAME "3kW 封入管(ID:1200)|3kW Sealed tube(ID:1200)"
*HW_XG_TARGET_ATOMIC_NUMBER "29.0000000000"
*HW_XG_TARGET_NAME "Cu"
*HW_XG_TYPE "Hermetic"
*HW_XG_VOLTAGE_MAX "40"
*HW_XG_VOLTAGE_MIN "20"
*HW_XG_VOLTAGE_RESOLUTION "1"
*HW_XG_VOLTAGE_UNIT "kV"
*HW_XG_WATT_MAX "1.500"
*HW_XG_WATT_UNIT "kW"
*HW_XG_WAVE_LENGTH_ALPHA1 "1.540593"
*HW_XG_WAVE_LENGTH_ALPHA2 "1.544414"
*HW_XG_WAVE_LENGTH_BETA "1.392250"
*MEAS_COND_AXIS_NAME-0 "Theta/2-Theta"
*MEAS_COND_AXIS_NAME-1 "2-Theta"
*MEAS_COND_AXIS_NAME-2 "Omega"
*MEAS_COND_AXIS_NAME-3 "Chi"
*MEAS_COND_AXIS_NAME-4 "Phi"
*MEAS_COND_AXIS_NAME-5 "Z"
*MEAS_COND_AXIS_NAME-6 "X"
*MEAS_COND_AXIS_NAME-7 "Y"
*MEAS_COND_AXIS_NAME-8 "2-Theta/Omega"
*MEAS_COND_AXIS_NAME-9 "2-ThetaChi"
*MEAS_COND_AXIS_NAME-10 "2-ThetaChi/Phi"
*MEAS_COND_AXIS_NAME-11 "Alpha"
*MEAS_COND_AXIS_NAME-12 "Beta"
*MEAS_COND_AXIS_NAME-13 "Theta_s"
*MEAS_COND_AXIS_NAME-14 "Theta_d"
*MEAS_COND_AXIS_NAME-15 "Ts"
*MEAS_COND_AXIS_NAME-16 "CBO selection slit"
*MEAS_COND_AXIS_NAME-17 "M"
*MEAS_COND_AXIS_NAME-18 "Incident parallel slit"
*MEAS_COND_AXIS_NAME-19 "Incident slit"
*MEAS_COND_AXIS_NAME-20 ""
*MEAS_COND_AXIS_NAME-21 "Zs"
*MEAS_COND_AXIS_NAME-22 "Incident optical device"
*MEAS_COND_AXIS_NAME-23 "Omega_m"
*MEAS_COND_AXIS_NAME-24 "Length limiting slit"
*MEAS_COND_AXIS_NAME-25 "Center slit"
*MEAS_COND_AXIS_NAME-26 "Filter"
*MEAS_COND_AXIS_NAME-27 "Receiving slit # 1"
*MEAS_COND_AXIS_NAME-28 "Receiving slit # 2"
*MEAS_COND_AXIS_NAME-29 "Receiving optical device"
*MEAS_COND_AXIS_NAME-30 "Receiving parallel slit"
*MEAS_COND_AXIS_NAME-31 "Alignment receiving slit"
*MEAS_COND_AXIS_NAME-32 ""
*MEAS_COND_AXIS_NAME-33 ""
*MEAS_COND_AXIS_NAME-34 "Zd"
*MEAS_COND_AXIS_NAME-35 "Attenuator"
*MEAS_COND_AXIS_NAME-36 "Diffracted beam monochromator"
*MEAS_COND_AXIS_NAME-37 "Monochromator slit"
*MEAS_COND_AXIS_NAME-38 "2-ThetaB"
*MEAS_COND_AXIS_NAME-39 ""
*MEAS_COND_AXIS_NAME-40 ""
*MEAS_COND_AXIS_NAME-41 "Zr"
*MEAS_COND_AXIS_NAME-42 "Primary beam"
*MEAS_COND_AXIS_NAME_INTERNAL-0 "TwoThetaTheta"
*MEAS_COND_AXIS_NAME_INTERNAL-1 "TwoTheta"
*MEAS_COND_AXIS_NAME_INTERNAL-2 "Omega"
*MEAS_COND_AXIS_NAME_INTERNAL-3 "Chi"
*MEAS_COND_AXIS_NAME_INTERNAL-4 "Phi"
*MEAS_COND_AXIS_NAME_INTERNAL-5 "Z"
*MEAS_COND_AXIS_NAME_INTERNAL-6 "X"
*MEAS_COND_AXIS_NAME_INTERNAL-7 "Y"
*MEAS_COND_AXIS_NAME_INTERNAL-8 "TwoThetaOmega"
*MEAS_COND_AXIS_NAME_INTERNAL-9 "TwoThetaChi"
*MEAS_COND_AXIS_NAME_INTERNAL-10 "TwoThetaChiPhi"
*MEAS_COND_AXIS_NAME_INTERNAL-11 "Alpha"
*MEAS_COND_AXIS_NAME_INTERNAL-12 "Beta"
*MEAS_COND_AXIS_NAME_INTERNAL-13 "ThetaS"
*MEAS_COND_AXIS_NAME_INTERNAL-14 "ThetaD"
*MEAS_COND_AXIS_NAME_INTERNAL-15 "Ts"
*MEAS_COND_AXIS_NAME_INTERNAL-16 "CBO"
*MEAS_COND_AXIS_NAME_INTERNAL-17 "CBO-M"
*MEAS_COND_AXIS_NAME_INTERNAL-18 "IncidentSollerSlit"
*MEAS_COND_AXIS_NAME_INTERNAL-19 "IncidentSlitBox"
*MEAS_COND_AXIS_NAME_INTERNAL-20 "IncidentSlitBox-_Axis"
*MEAS_COND_AXIS_NAME_INTERNAL-21 "Zs"
*MEAS_COND_AXIS_NAME_INTERNAL-22 "IncidentMonochromator"
*MEAS_COND_AXIS_NAME_INTERNAL-23 "IncidentMonochromator-OmegaM"
*MEAS_COND_AXIS_NAME_INTERNAL-24 "IncidentAxdSlit"
*MEAS_COND_AXIS_NAME_INTERNAL-25 "CenterSlit"
*MEAS_COND_AXIS_NAME_INTERNAL-26 "Filter"
*MEAS_COND_AXIS_NAME_INTERNAL-27 "ReceivingSlitBox1"
*MEAS_COND_AXIS_NAME_INTERNAL-28 "ReceivingSlitBox2"
*MEAS_COND_AXIS_NAME_INTERNAL-29 "ReceivingOptics"
*MEAS_COND_AXIS_NAME_INTERNAL-30 "ReceivingSollerSlit"
*MEAS_COND_AXIS_NAME_INTERNAL-31 "ReceivingAxdSlit"
*MEAS_COND_AXIS_NAME_INTERNAL-32 "ReceivingSlitBox1-_Axis"
*MEAS_COND_AXIS_NAME_INTERNAL-33 "ReceivingSlitBox2-_Axis"
*MEAS_COND_AXIS_NAME_INTERNAL-34 "ReceivingSlitBox2-Zd"
*MEAS_COND_AXIS_NAME_INTERNAL-35 "Attenuator"
*MEAS_COND_AXIS_NAME_INTERNAL-36 "CounterMonochromator"
*MEAS_COND_AXIS_NAME_INTERNAL-37 "CounterSlit"
*MEAS_COND_AXIS_NAME_INTERNAL-38 "TwoThetaB"
*MEAS_COND_AXIS_NAME_INTERNAL-39 "AlphaR"
*MEAS_COND_AXIS_NAME_INTERNAL-40 "BetaR"
*MEAS_COND_AXIS_NAME_INTERNAL-41 "ReceivingSlitBox1-Zr"
*MEAS_COND_AXIS_NAME_INTERNAL-42 "IncidentPrimary"
*MEAS_COND_AXIS_NAME_MAGICNO-0 "83951616.0000000000"
*MEAS_COND_AXIS_NAME_MAGICNO-1 "268632064.0000000000"
*MEAS_COND_AXIS_NAME_MAGICNO-2 "268500992.0000000000"
*MEAS_COND_AXIS_NAME_MAGICNO-3 "268500992.0000000000"
*MEAS_COND_AXIS_NAME_MAGICNO-4 "268500992.0000000000"
*MEAS_COND_AXIS_NAME_MAGICNO-5 "285278208.0000000000"
*MEAS_COND_AXIS_NAME_MAGICNO-6 "268500992.0000000000"
*MEAS_COND_AXIS_NAME_MAGICNO-7 "268500992.0000000000"
*MEAS_COND_AXIS_NAME_MAGICNO-8 "83951616.0000000000"
*MEAS_COND_AXIS_NAME_MAGICNO-9 "268632064.0000000000"
*MEAS_COND_AXIS_NAME_MAGICNO-10 "83951616.0000000000"
*MEAS_COND_AXIS_NAME_MAGICNO-11 "17039360.0000000000"
*MEAS_COND_AXIS_NAME_MAGICNO-12 "17039360.0000000000"
*MEAS_COND_AXIS_NAME_MAGICNO-13 "131072.0000000000"
*MEAS_COND_AXIS_NAME_MAGICNO-14 "131072.0000000000"
*MEAS_COND_AXIS_NAME_MAGICNO-15 "318898176.0000000000"
*MEAS_COND_AXIS_NAME_MAGICNO-16 "20971521.0000000000"
*MEAS_COND_AXIS_NAME_MAGICNO-17 "285343744.0000000000"
*MEAS_COND_AXIS_NAME_MAGICNO-18 "20971521.0000000000"
*MEAS_COND_AXIS_NAME_MAGICNO-19 "22020097.0000000000"
*MEAS_COND_AXIS_NAME_MAGICNO-20 "25165824.0000000000"
*MEAS_COND_AXIS_NAME_MAGICNO-21 "318898176.0000000000"
*MEAS_COND_AXIS_NAME_MAGICNO-22 "20971521.0000000000"
*MEAS_COND_AXIS_NAME_MAGICNO-23 "285343744.0000000000"
*MEAS_COND_AXIS_NAME_MAGICNO-24 "20971521.0000000000"
*MEAS_COND_AXIS_NAME_MAGICNO-25 "20971521.0000000000"
*MEAS_COND_AXIS_NAME_MAGICNO-26 "20971521.0000000000"
*MEAS_COND_AXIS_NAME_MAGICNO-27 "23068673.0000000000"
*MEAS_COND_AXIS_NAME_MAGICNO-28 "23068673.0000000000"
*MEAS_COND_AXIS_NAME_MAGICNO-29 "20971521.0000000000"
*MEAS_COND_AXIS_NAME_MAGICNO-30 "20971521.0000000000"
*MEAS_COND_AXIS_NAME_MAGICNO-31 "20971521.0000000000"
*MEAS_COND_AXIS_NAME_MAGICNO-32 "25165824.0000000000"
*MEAS_COND_AXIS_NAME_MAGICNO-33 "25165824.0000000000"
*MEAS_COND_AXIS_NAME_MAGICNO-34 "285343744.0000000000"
*MEAS_COND_AXIS_NAME_MAGICNO-35 "0.0000000000"
*MEAS_COND_AXIS_NAME_MAGICNO-36 "20971521.0000000000"
*MEAS_COND_AXIS_NAME_MAGICNO-37 "20971521.0000000000"
*MEAS_COND_AXIS_NAME_MAGICNO-38 "17039360.0000000000"
*MEAS_COND_AXIS_NAME_MAGICNO-39 "8388608.0000000000"
*MEAS_COND_AXIS_NAME_MAGICNO-40 "8388608.0000000000"
*MEAS_COND_AXIS_NAME_MAGICNO-41 "285343744.0000000000"
*MEAS_COND_AXIS_NAME_MAGICNO-42 "20971521.0000000000"
*MEAS_COND_AXIS_OFFSET-0 "-"
*MEAS_COND_AXIS_OFFSET-1 "0.9151000000"
*MEAS_COND_AXIS_OFFSET-2 "-0.1071000000"
*MEAS_COND_AXIS_OFFSET-3 "0.0000000000"
*MEAS_COND_AXIS_OFFSET-4 "0.0000000000"
*MEAS_COND_AXIS_OFFSET-5 "-"
*MEAS_COND_AXIS_OFFSET-6 "0.0000000000"
*MEAS_COND_AXIS_OFFSET-7 "0.0000000000"
*MEAS_COND_AXIS_OFFSET-8 "-"
*MEAS_COND_AXIS_OFFSET-9 "0.0000000000"
*MEAS_COND_AXIS_OFFSET-10 "-"
*MEAS_COND_AXIS_OFFSET-11 "-"
*MEAS_COND_AXIS_OFFSET-12 "-"
*MEAS_COND_AXIS_OFFSET-13 "-0.1071000000"
*MEAS_COND_AXIS_OFFSET-14 "1.0222000000"
*MEAS_COND_AXIS_OFFSET-15 "-"
*MEAS_COND_AXIS_OFFSET-16 "-"
*MEAS_COND_AXIS_OFFSET-17 "-"
*MEAS_COND_AXIS_OFFSET-18 "-"
*MEAS_COND_AXIS_OFFSET-19 "-"
*MEAS_COND_AXIS_OFFSET-20 "-"
*MEAS_COND_AXIS_OFFSET-21 "-"
*MEAS_COND_AXIS_OFFSET-22 "-"
*MEAS_COND_AXIS_OFFSET-23 "-"
*MEAS_COND_AXIS_OFFSET-24 "-"
*MEAS_COND_AXIS_OFFSET-25 "-"
*MEAS_COND_AXIS_OFFSET-26 "-"
*MEAS_COND_AXIS_OFFSET-27 "-"
*MEAS_COND_AXIS_OFFSET-28 "-"
*MEAS_COND_AXIS_OFFSET-29 "-"
*MEAS_COND_AXIS_OFFSET-30 "-"
*MEAS_COND_AXIS_OFFSET-31 "-"
*MEAS_COND_AXIS_OFFSET-32 "-"
*MEAS_COND_AXIS_OFFSET-33 "-"
*MEAS_COND_AXIS_OFFSET-34 "-"
*MEAS_COND_AXIS_OFFSET-35 "-"
*MEAS_COND_AXIS_OFFSET-36 "-"
*MEAS_COND_AXIS_OFFSET-37 "-"
*MEAS_COND_AXIS_OFFSET-38 "-"
*MEAS_COND_AXIS_OFFSET-39 "0.0000000000"
*MEAS_COND_AXIS_OFFSET-40 "0.0000000000"
*MEAS_COND_AXIS_OFFSET-41 "-"
*MEAS_COND_AXIS_OFFSET-42 "-"
*MEAS_COND_AXIS_POSITION-0 "40.0000000000"
*MEAS_COND_AXIS_POSITION-1 "40.0000000000"
*MEAS_COND_AXIS_POSITION-2 "20.0000000000"
*MEAS_COND_AXIS_POSITION-3 "0.0000000000"
*MEAS_COND_AXIS_POSITION-4 "0.0000000000"
*MEAS_COND_AXIS_POSITION-5 "-3.5486000000"
*MEAS_COND_AXIS_POSITION-6 "-0.0955000000"
*MEAS_COND_AXIS_POSITION-7 "-2.9210000000"
*MEAS_COND_AXIS_POSITION-8 "40.0000000000"
*MEAS_COND_AXIS_POSITION-9 "0.0000000000"
*MEAS_COND_AXIS_POSITION-10 "0.0000000000"
*MEAS_COND_AXIS_POSITION-11 "90.0000000000"
*MEAS_COND_AXIS_POSITION-12 "0.0000000000"
*MEAS_COND_AXIS_POSITION-13 "20.0000000000"
*MEAS_COND_AXIS_POSITION-14 "20.0000000000"
*MEAS_COND_AXIS_POSITION-15 "-5.5036300000"
*MEAS_COND_AXIS_POSITION-16 "PB"
*MEAS_COND_AXIS_POSITION-17 "0.0000000000"
*MEAS_COND_AXIS_POSITION-18 "Soller_slit_2.5deg_s"
*MEAS_COND_AXIS_POSITION-19 "1.000mm"
*MEAS_COND_AXIS_POSITION-20 "1.0000000000"
*MEAS_COND_AXIS_POSITION-21 "-1.0678100000"
*MEAS_COND_AXIS_POSITION-22 "Ge(220)x2"
*MEAS_COND_AXIS_POSITION-23 "0.0000000000"
*MEAS_COND_AXIS_POSITION-24 "0.5mm"
*MEAS_COND_AXIS_POSITION-25 "None"
*MEAS_COND_AXIS_POSITION-26 "None"
*MEAS_COND_AXIS_POSITION-27 "20.000mm"
*MEAS_COND_AXIS_POSITION-28 "38.500mm"
*MEAS_COND_AXIS_POSITION-29 "PSA_open"
*MEAS_COND_AXIS_POSITION-30 "Soller_slit_2.5deg"
*MEAS_COND_AXIS_POSITION-31 "None"
*MEAS_COND_AXIS_POSITION-32 "20.0000000000"
*MEAS_COND_AXIS_POSITION-33 "38.5000000000"
*MEAS_COND_AXIS_POSITION-34 "0.0000000000"
*MEAS_COND_AXIS_POSITION-35 "-"
*MEAS_COND_AXIS_POSITION-36 "No_unit"
*MEAS_COND_AXIS_POSITION-37 "None"
*MEAS_COND_AXIS_POSITION-38 "40.0000000000"
*MEAS_COND_AXIS_POSITION-39 "0.0000000000"
*MEAS_COND_AXIS_POSITION-40 "0.0000000000"
*MEAS_COND_AXIS_POSITION-41 "0.1412500000"
*MEAS_COND_AXIS_POSITION-42 "None"
*MEAS_COND_AXIS_UNIT-0 "deg"
*MEAS_COND_AXIS_UNIT-1 "deg"
*MEAS_COND_AXIS_UNIT-2 "deg"
*MEAS_COND_AXIS_UNIT-3 "deg"
*MEAS_COND_AXIS_UNIT-4 "deg"
*MEAS_COND_AXIS_UNIT-5 "mm"
*MEAS_COND_AXIS_UNIT-6 "mm"
*MEAS_COND_AXIS_UNIT-7 "mm"
*MEAS_COND_AXIS_UNIT-8 "deg"
*MEAS_COND_AXIS_UNIT-9 "deg"
*MEAS_COND_AXIS_UNIT-10 "deg"
*MEAS_COND_AXIS_UNIT-11 "deg"
*MEAS_COND_AXIS_UNIT-12 "deg"
*MEAS_COND_AXIS_UNIT-13 "deg"
*MEAS_COND_AXIS_UNIT-14 "deg"
*MEAS_COND_AXIS_UNIT-15 "mm"
*MEAS_COND_AXIS_UNIT-16 ""
*MEAS_COND_AXIS_UNIT-17 "pulse"
*MEAS_COND_AXIS_UNIT-18 ""
*MEAS_COND_AXIS_UNIT-19 ""
*MEAS_COND_AXIS_UNIT-20 "mm"
*MEAS_COND_AXIS_UNIT-21 "mm"
*MEAS_COND_AXIS_UNIT-22 ""
*MEAS_COND_AXIS_UNIT-23 "pulse"
*MEAS_COND_AXIS_UNIT-24 ""
*MEAS_COND_AXIS_UNIT-25 ""
*MEAS_COND_AXIS_UNIT-26 ""
*MEAS_COND_AXIS_UNIT-27 ""
*MEAS_COND_AXIS_UNIT-28 ""
*MEAS_COND_AXIS_UNIT-29 ""
*MEAS_COND_AXIS_UNIT-30 ""
*MEAS_COND_AXIS_UNIT-31 ""
*MEAS_COND_AXIS_UNIT-32 "mm"
*MEAS_COND_AXIS_UNIT-33 "mm"
*MEAS_COND_AXIS_UNIT-34 "mm"
*MEAS_COND_AXIS_UNIT-35 ""
*MEAS_COND_AXIS_UNIT-36 ""
*MEAS_COND_AXIS_UNIT-37 ""
*MEAS_COND_AXIS_UNIT-38 "deg"
*MEAS_COND_AXIS_UNIT-39 "deg"
*MEAS_COND_AXIS_UNIT-40 "deg"
*MEAS_COND_AXIS_UNIT-41 "mm"
*MEAS_COND_AXIS_UNIT-42 ""
*MEAS_COND_COUNTER_CNTLOSS_CORR "0.0000000000"
*MEAS_COND_COUNTER_TAUDIFF "0.0000000000"
*MEAS_COND_COUNTER_TAUINT "0.0000000000"
*MEAS_COND_COUNTER_TEMP_CONDITION "NORMAL"
*MEAS_COND_IRRADIATION_MODE "OFF"
*MEAS_COND_IRRADIATION_WIDTH ""
*MEAS_COND_OPT_ATTR "High resolution parallel beam Ge(220)x2/RS"
*MEAS_COND_OPT_NAME "@High resolution PB-Ge(220)x2"
*MEAS_COND_UNSYMMETRIC_MODE "OFF"
*MEAS_COND_XG_CURRENT "30.0000000000"
*MEAS_COND_XG_VOLTAGE "40.0000000000"
*MEAS_COND_XG_WAVE_TYPE "Ka1"
*MEAS_DATA_COUNT "8000.0000000000"
*MEAS_SCAN_AXIS_X "Theta/2-Theta"
*MEAS_SCAN_AXIS_X_INTERNAL "TwoThetaTheta"
*MEAS_SCAN_END_TIME "03/30/22 08:43:42"
*MEAS_SCAN_MODE "CONTINUOUS"
*MEAS_SCAN_MONITOR "0"
*MEAS_SCAN_RESOLUTION_X "0.0002"
*MEAS_SCAN_SPEED "0.503240"
*MEAS_SCAN_SPEED_UNIT "deg/min"
*MEAS_SCAN_SPEED_USER "0.5"
*MEAS_SCAN_START "40.0000000000"
*MEAS_SCAN_START_TIME "03/30/22 05:48:52"
*MEAS_SCAN_STEP "0.0100000000"
*MEAS_SCAN_STOP "119.9900000000"
*MEAS_SCAN_UNIT_X "deg"
*MEAS_SCAN_UNIT_Y "counts"
*RAS_HEADER_END
*RAS_INT_START
40.0000 6.2640 1.0000
40.0600 6.4848 1.0000
40.1200 7.0572 1.0000
40.1800 5.8489 1.0000
40.2400 2.3608 1.0000
40.3000 2.7367 1.0000
40.3600 6.7972 1.0000
40.4200 6.0017 1.0000
40.4800 5.3698 1.0000
40.5400 6.0566 1.0000
40.6000 4.9280 1.0000
40.6600 7.5981 1.0000
40.7200 2.4694 1.0000
40.7800 3.3114 1.0000
40.8400 3.8391 1.0000
40.9000 8.3878 1.0000
40.9600 6.1215 1.0000
41.0200 4.2839 1.0000
41.0800 2.7198 1.0000
41.1400 4.1173 1.0000
41.2000 5.5955 1.0000
41.2600 7.3196 1.0000
41.3200 7.4617 1.0000
41.3800 5.5408 1.0000
41.4400 1.8377 1.0000
41.5000 3.5671 1.0000
41.5600 2.2351 1.0000
41.6200 8.1644 1.0000
41.6800 2.7908 1.0000
41.7400 5.4410 1.0000
41.8000 8.2109 1.0000
41.8600 8.4964 1.0000
41.9200 4.0831 1.0000
41.9800 7.7751 1.0000
42.0400 7.2191 1.0000
42.1000 2.5333 1.0000
42.1600 5.1043 1.0000
42.2200 2.5912 1.0000
42.2800 4.0323 1.0000
42.3400 3.8029 1.0000
42.4000 3.4787 1.0000
42.4600 3.2676 1.0000
42.5200 4.2464 1.0000
42.5800 3.7514 1.0000
42.6400 2.6440 1.0000
42.7000 7.4244 1.0000
42.7600 1.7534 1.0000
42.8200 8.1123 1.0000
42.8800 4.1977 1.0000
42.9400 7.5049 1.0000
43.0000 3.9172 1.0000
43.0600 3.2174 1.0000
43.1200 5.2366 1.0000
43.1800 4.1114 1.0000
43.2400 5.2958 1.0000
43.3000 3.9362 1.0000
43.3600 3.3570 1.0000
43.4200 1.3232 1.0000
43.4800 6.1289 1.0000
43.5400 6.1952 1.0000
43.6000 11.4309 1.0000
43.6600 3.3379 1.0000
43.7200 3.7044 1.0000
43.7800 5.1973 1.0000
43.8400 5.9458 1.0000
43.9000 4.8314 1.0000
43.9600 5.2289 1.0000
44.0200 6.4680 1.0000
44.0800 8.7004 1.0000
44.1400 10.7449 1.0000
44.2000 9.0262 1.0000
44.2600 13.8087 1.0000
44.3200 28.4641 1.0000
44.3800 47.6524 1.0000
44.4400 85.9552 1.0000
44.5000 169.7765 1.0000
44.5600 197.6934 1.0000
44.6200 192.4541 1.0000
44.6800 119.9337 1.0000
44.7400 61.3813 1.0000
44.8000 27.2954 1.0000
44.8600 19.7147 1.0000
44.9200 6.9600 1.0000
44.9800 10.5434 1.0000
45.0400 5.9993 1.0000
45.1000 2.9066 1.0000
45.1600 6.6871 1.0000
45.2200 5.8102 1.0000
45.2800 4.8551 1.0000
45.3400 3.3889 1.0000
45.4000 9.5199 1.0000
45.4600 8.3601 1.0000
45.5200 5.0052 1.0000
45.5800 6.6009 1.0000
45.6400 4.3029 1.0000
45.7000 2.4387 1.0000
45.7600 1.2279 1.0000
45.8200 2.0686 1.0000
45.8800 6.9412 1.0000
45.9400 4.4685 1.0000
46.0000 5.9794 1.0000
46.0600 6.4617 1.0000
46.1200 6.8712 1.0000
46.1800 3.9487 1.0000
46.2400 5.7993 1.0000
46.3000 4.0514 1.0000
46.3600 7.7830 1.0000
46.4200 5.0323 1.0000
46.4800 2.3807 1.0000
46.5400 4.4080 1.0000
46.6000 0.9795 1.0000
46.6600 5.5191 1.0000
46.7200 4.9888 1.0000
46.7800 6.3839 1.0000
46.8400 4.0164 1.0000
46.9000 3.9615 1.0000
46.9600 3.0938 1.0000
47.0200 8.4053 1.0000
47.0800 8.9631 1.0000
47.1400 3.0062 1.0000
47.2000 4.6693 1.0000
47.2600 4.4090 1.0000
47.3200 4.3397 1.0000
47.3800 3.4373 1.0000
47.4400 6.4392 1.0000
47.5000 2.5325 1.0000
47.5600 7.4222 1.0000
47.6200 8.8124 1.0000
47.6800 8.1197 1.0000
47.7400 3.4608 1.0000
47.8000 2.9256 1.0000
47.8600 5.2200 1.0000
47.9200 4.1931 1.0000
47.9800 6.0792 1.0000
48.0400 5.4992 1.0000
48.1000 6.0234 1.0000
48.1600 5.6498 1.0000
48.2200 3.1573 1.0000
48.2800 3.8828 1.0000
48.3400 5.3210 1.0000
48.4000 8.9896 1.0000
48.4600 7.0875 1.0000
48.5200 5.0317 1.0000
48.5800 1.5306 1.0000
48.6400 6.3008 1.0000
48.7000 6.4865 1.0000
48.7600 1.9383 1.0000
48.8200 1.2373 1.0000
48.8800 2.8922 1.0000
48.9400 4.4583 1.0000
49.0000 8.5830 1.0000
49.0600 2.2786 1.0000
49.1200 1.0229 1.0000
49.1800 3.1025 1.0000
49.2400 4.9855 1.0000
49.3000 4.3180 1.0000
49.3600 3.1005 1.0000
49.4200 3.4816 1.0000
49.4800 6.4878 1.0000
49.5400 8.2061 1.0000
49.6000 5.8186 1.0000
49.6600 2.8901 1.0000
49.7200 2.2163 1.0000
49.7800 2.5572 1.0000
49.8400 4.2330 1.0000
49.9000 3.3002 1.0000
49.9600 4.1554 1.0000
50.0200 4.2287 1.0000
50.0800 6.1644 1.0000
50.1400 3.3459 1.0000
50.2000 3.8798 1.0000
50.2600 3.0788 1.0000
50.3200 7.4642 1.0000
50.3800 4.7458 1.0000
50.4400 3.6516 1.0000
50.5000 3.4398 1.0000
50.5600 1.7991 1.0000
50.6200 4.3851 1.0000
50.6800 0.9955 1.0000
50.7400 5.0815 1.0000
50.8000 4.3268 1.0000
50.8600 1.2972 1.0000
50.9200 3.4451 1.0000
50.9800 3.8038 1.0000
51.0400 2.1088 1.0000
51.1000 3.1438 1.0000
51.1600 1.3840 1.0000
51.2200 6.7230 1.0000
51.2800 4.0687 1.0000
51.3400 2.5574 1.0000
51.4000 5.2887 1.0000
51.4600 3.6581 1.0000
51.5200 5.0584 1.0000
51.5800 4.8460 1.0000
51.6400 2.8495 1.0000
51.7000 5.8294 1.0000
51.7600 3.7174 1.0000
51.8200 3.2927 1.0000
51.8800 2.4197 1.0000
51.9400 5.2172 1.0000
52.0000 5.5682 1.0000
52.0600 4.6267 1.0000
52.1200 4.0904 1.0000
52.1800 3.2791 1.0000
52.2400 8.5517 1.0000
52.3000 0.9901 1.0000
52.3600 2.2484 1.0000
52.4200 3.8031 1.0000
52.4800 5.1041 1.0000
52.5400 1.4269 1.0000
52.6000 2.6642 1.0000
52.6600 1.4643 1.0000
52.7200 4.3817 1.0000
52.7800 5.0533 1.0000
52.8400 2.0203 1.0000
52.9000 2.8555 1.0000
52.9600 3.1191 1.0000
53.0200 5.2459 1.0000
53.0800 3.0593 1.0000
53.1400 5.9234 1.0000
53.2000 9.3752 1.0000
53.2600 3.5427 1.0000
53.3200 1.5947 1.0000
53.3800 7.6748 1.0000
53.4400 4.7509 1.0000
53.5000 4.2027 1.0000
53.5600 1.5012 1.0000
53.6200 8.2006 1.0000
53.6800 5.1154 1.0000
53.7400 5.1175 1.0000
53.8000 2.2602 1.0000
53.8600 3.3458 1.0000
53.9200 5.9215 1.0000
53.9800 2.4640 1.0000
54.0400 6.1277 1.0000
54.1000 3.4233 1.0000
54.1600 1.9790 1.0000
54.2200 7.7637 1.0000
54.2800 4.0807 1.0000
54.3400 7.2990 1.0000
54.4000 4.0483 1.0000
54.4600 6.4638 1.0000
54.5200 2.1669 1.0000
54.5800 3.8009 1.0000
54.6400 5.3703 1.0000
54.7000 5.8060 1.0000
54.7600 2.7574 1.0000
54.8200 8.0271 1.0000
54.8800 5.3055 1.0000
54.9400 4.0799 1.0000
55.0000 7.7971 1.0000
55.0600 5.5705 1.0000
55.1200 6.7440 1.0000
55.1800 4.3079 1.0000
55.2400 5.2059 1.0000
55.3000 4.9366 1.0000
55.3600 4.6842 1.0000
55.4200 11.1251 1.0000
55.4800 3.5003 1.0000
55.5400 8.9212 1.0000
55.6000 2.9814 1.0000
55.6600 1.4036 1.0000
55.7200 4.0421 1.0000
55.7800 5.9114 1.0000
55.8400 3.0565 1.0000
55.9000 2.4849 1.0000
55.9600 5.0344 1.0000
56.0200 2.0930 1.0000
56.0800 5.4981 1.0000
56.1400 4.3142 1.0000
56.2000 6.5749 1.0000
56.2600 2.2822 1.0000
56.3200 4.8371 1.0000
56.3800 5.3411 1.0000
56.4400 8.7265 1.0000
56.5000 5.1679 1.0000
56.5600 4.7513 1.0000
56.6200 3.8010 1.0000
56.6800 3.0894 1.0000
56.7400 2.5673 1.0000
56.8000 3.4382 1.0000
56.8600 3.6082 1.0000
56.9200 5.4486 1.0000
56.9800 2.1904 1.0000
57.0400 4.1054 1.0000
57.1000 6.9934 1.0000
57.1600 5.5346 1.0000
57.2200 5.8725 1.0000
57.2800 4.6929 1.0000
57.3400 3.8492 1.0000
57.4000 6.3994 1.0000
57.4600 5.1360 1.0000
57.5200 7.9287 1.0000
57.5800 3.8520 1.0000
57.6400 5.0628 1.0000
57.7000 4.6458 1.0000
57.7600 2.8731 1.0000
57.8200 4.7122 1.0000
57.8800 4.2567 1.0000
57.9400 2.8328 1.0000
58.0000 6.1301 1.0000
58.0600 4.0922 1.0000
58.1200 2.6909 1.0000
58.1800 4.0509 1.0000
58.2400 6.2470 1.0000
58.3000 3.6882 1.0000
58.3600 3.8294 1.0000
58.4200 4.5878 1.0000
58.4800 5.1803 1.0000
58.5400 4.2696 1.0000
58.6000 5.5666 1.0000
58.6600 3.4840 1.0000
58.7200 2.0205 1.0000
58.7800 3.4335 1.0000
58.8400 5.2371 1.0000
58.9000 1.9620 1.0000
58.9600 2.6203 1.0000
59.0200 5.8310 1.0000
59.0800 2.1636 1.0000
59.1400 4.9955 1.0000
59.2000 4.3441 1.0000
59.2600 4.2430 1.0000
59.3200 1.2861 1.0000
59.3800 0.4639 1.0000
59.4400 4.4557 1.0000
59.5000 5.9124 1.0000
59.5600 6.6821 1.0000
59.6200 1.6232 1.0000
59.6800 3.3479 1.0000
59.7400 7.7275 1.0000
59.8000 5.1454 1.0000
59.8600 6.9424 1.0000
59.9200 3.3733 1.0000
59.9800 5.8352 1.0000
60.0400 3.7014 1.0000
60.1000 2.5056 1.0000
60.1600 1.3667 1.0000
60.2200 5.9477 1.0000
60.2800 3.0589 1.0000
60.3400 4.7654 1.0000
60.4000 4.1519 1.0000
60.4600 3.8759 1.0000
60.5200 6.1453 1.0000
60.5800 2.6108 1.0000
60.6400 6.1561 1.0000
60.7000 4.4815 1.0000
60.7600 3.1082 1.0000
60.8200 8.1983 1.0000
60.8800 4.9464 1.0000
60.9400 2.1542 1.0000
61.0000 5.7881 1.0000
61.0600 3.0348 1.0000
61.1200 5.5478 1.0000
61.1800 6.1053 1.0000
61.2400 5.2418 1.0000
61.3000 2.5184 1.0000
61.3600 1.0996 1.0000
61.4200 4.7215 1.0000
61.4800 2.9933 1.0000
61.5400 6.2857 1.0000
61.6000 4.0507 1.0000
61.6600 4.1275 1.0000
61.7200 5.2659 1.0000
61.7800 4.2269 1.0000
61.8400 2.7844 1.0000
61.9000 4.1298 1.0000
61.9600 3.4336 1.0000
62.0200 5.2779 1.0000
62.0800 3.8516 1.0000
62.1400 3.8610 1.0000
62.2000 1.4239 1.0000
62.2600 5.3246 1.0000
62.3200 2.9165 1.0000
62.3800 0.5819 1.0000
62.4400 4.4763 1.0000
62.5000 3.9499 1.0000
62.5600 2.7006 1.0000
62.6200 3.1086 1.0000
62.6800 8.7612 1.0000
62.7400 5.7899 1.0000
62.8000 2.2283 1.0000
62.8600 6.1685 1.0000
62.9200 3.0907 1.0000
62.9800 2.4411 1.0000
63.0400 5.9781 1.0000
63.1000 3.2029 1.0000
63.1600 8.2947 1.0000
63.2200 5.9640 1.0000
63.2800 5.4460 1.0000
63.3400 4.0337 1.0000
63.4000 4.2639 1.0000
63.4600 5.5038 1.0000
63.5200 5.4831 1.0000
63.5800 5.6054 1.0000
63.6400 3.5501 1.0000
63.7000 3.9742 1.0000
63.7600 9.1333 1.0000
63.8200 1.9692 1.0000
63.8800 5.7089 1.0000
63.9400 3.8560 1.0000
64.0000 4.1014 1.0000
64.0600 5.5834 1.0000
64.1200 6.5862 1.0000
64.1800 3.1792 1.0000
64.2400 8.9676 1.0000
64.3000 6.6318 1.0000
64.3600 7.0565 1.0000
64.4200 2.1670 1.0000
64.4800 6.4030 1.0000
64.5400 10.7674 1.0000
64.6000 7.9671 1.0000
64.6600 4.3117 1.0000
64.7200 11.2776 1.0000
64.7800 8.8025 1.0000
64.8400 11.4909 1.0000
64.9000 9.0463 1.0000
64.9600 10.3898 1.0000
65.0200 6.2539 1.0000
65.0800 5.8318 1.0000
65.1400 6.2370 1.0000
65.2000 9.2147 1.0000
65.2600 5.4045 1.0000
65.3200 6.2752 1.0000
65.3800 6.2029 1.0000
65.4400 5.0289 1.0000
65.5000 4.5822 1.0000
65.5600 5.6971 1.0000
65.6200 10.4086 1.0000
65.6800 2.3994 1.0000
65.7400 5.3095 1.0000
65.8000 1.4180 1.0000
65.8600 4.0416 1.0000
65.9200 5.8174 1.0000
65.9800 11.1884 1.0000
66.0400 3.9257 1.0000
66.1000 1.3228 1.0000
66.1600 3.2171 1.0000
66.2200 8.2134 1.0000
66.2800 2.8040 1.0000
66.3400 5.7417 1.0000
66.4000 4.6878 1.0000
66.4600 4.4311 1.0000
66.5200 7.8848 1.0000
66.5800 4.9787 1.0000
66.6400 4.6955 1.0000
66.7000 3.7335 1.0000
66.7600 3.9839 1.0000
66.8200 1.4884 1.0000
66.8800 1.8686 1.0000
66.9400 4.7112 1.0000
67.0000 7.3611 1.0000
67.0600 7.1938 1.0000
67.1200 0.3582 1.0000
67.1800 2.3162 1.0000
67.2400 3.2477 1.0000
67.3000 2.9792 1.0000
67.3600 3.6326 1.0000
67.4200 5.7211 1.0000
67.4800 2.3463 1.0000
67.5400 1.4969 1.0000
67.6000 2.0720 1.0000
67.6600 5.3720 1.0000
67.7200 6.1765 1.0000
67.7800 2.0243 1.0000
67.8400 2.8712 1.0000
67.9000 2.0133 1.0000
67.9600 2.6729 1.0000
68.0200 2.2291 1.0000
68.0800 5.2380 1.0000
68.1400 6.3173 1.0000
68.2000 1.7617 1.0000
68.2600 7.3302 1.0000
68.3200 4.2790 1.0000
68.3800 3.0083 1.0000
68.4400 2.1892 1.0000
68.5000 5.5302 1.0000
68.5600 7.5312 1.0000
68.6200 4.7821 1.0000
68.6800 3.7718 1.0000
68.7400 8.9994 1.0000
68.8000 4.9748 1.0000
68.8600 2.0878 1.0000
68.9200 6.6639 1.0000
68.9800 3.1060 1.0000
69.0400 6.7768 1.0000
69.1000 2.1121 1.0000
69.1600 4.7744 1.0000
69.2200 1.0830 1.0000
69.2800 5.0366 1.0000
69.3400 8.4457 1.0000
69.4000 3.1565 1.0000
69.4600 4.4535 1.0000
69.5200 3.6110 1.0000
69.5800 2.8518 1.0000
69.6400 4.8000 1.0000
69.7000 1.4596 1.0000
69.7600 3.6093 1.0000
69.8200 6.2462 1.0000
69.8800 2.1589 1.0000
69.9400 3.2508 1.0000
70.0000 1.8256 1.0000
70.0600 2.6723 1.0000
70.1200 4.6507 1.0000
70.1800 1.8494 1.0000
70.2400 4.1961 1.0000
70.3000 2.7090 1.0000
70.3600 1.3743 1.0000
70.4200 4.5318 1.0000
70.4800 4.6965 1.0000
70.5400 1.7822 1.0000
70.6000 4.2119 1.0000
70.6600 3.3962 1.0000
70.7200 2.7382 1.0000
70.7800 5.3406 1.0000
70.8400 4.6871 1.0000
70.9000 3.8065 1.0000
70.9600 5.5515 1.0000
71.0200 3.5240 1.0000
71.0800 4.4105 1.0000
71.1400 6.3401 1.0000
71.2000 3.2293 1.0000
71.2600 4.6944 1.0000
71.3200 3.8956 1.0000
71.3800 4.6449 1.0000
71.4400 5.8250 1.0000
71.5000 2.4586 1.0000
71.5600 1.8953 1.0000
71.6200 1.4878 1.0000
71.6800 3.3915 1.0000
71.7400 5.0286 1.0000
71.8000 6.2326 1.0000
71.8600 3.8627 1.0000
71.9200 5.2058 1.0000
71.9800 4.3591 1.0000
72.0400 7.0994 1.0000
72.1000 2.1517 1.0000
72.1600 8.7880 1.0000
72.2200 5.0031 1.0000
72.2800 5.0784 1.0000
72.3400 5.8144 1.0000
72.4000 3.0160 1.0000
72.4600 3.9058 1.0000
72.5200 2.6390 1.0000
72.5800 3.1433 1.0000
72.6400 4.6758 1.0000
72.7000 7.6333 1.0000
72.7600 3.8172 1.0000
72.8200 6.4249 1.0000
72.8800 4.1679 1.0000
72.9400 2.2259 1.0000
73.0000 1.2358 1.0000
73.0600 6.6559 1.0000
73.1200 9.0780 1.0000
73.1800 6.3643 1.0000
73.2400 5.5435 1.0000
73.3000 3.9978 1.0000
73.3600 3.2177 1.0000
73.4200 6.6612 1.0000
73.4800 5.2200 1.0000
73.5400 3.3941 1.0000
73.6000 4.9233 1.0000
73.6600 4.2480 1.0000
73.7200 3.8009 1.0000
73.7800 2.0650 1.0000
73.8400 1.1959 1.0000
73.9000 2.1168 1.0000
73.9600 0.9421 1.0000
74.0200 2.7803 1.0000
74.0800 4.1945 1.0000
74.1400 3.7085 1.0000
74.2000 4.0820 1.0000
74.2600 3.6902 1.0000
74.3200 2.9973 1.0000
74.3800 5.3073 1.0000
74.4400 1.6977 1.0000
74.5000 5.6667 1.0000
74.5600 12.4978 1.0000
74.6200 3.5924 1.0000
74.6800 3.4799 1.0000
74.7400 3.9978 1.0000
74.8000 3.9609 1.0000
74.8600 3.8017 1.0000
74.9200 2.3408 1.0000
74.9800 4.4968 1.0000
75.0400 2.9114 1.0000
75.1000 5.2860 1.0000
75.1600 3.8106 1.0000
75.2200 1.5002 1.0000
75.2800 3.2631 1.0000
75.3400 8.1690 1.0000
75.4000 2.7674 1.0000
75.4600 5.9233 1.0000
75.5200 3.7411 1.0000
75.5800 2.4330 1.0000
75.6400 1.5974 1.0000
75.7000 2.0873 1.0000
75.7600 3.0216 1.0000
75.8200 4.4984 1.0000
75.8800 7.4886 1.0000
75.9400 6.0270 1.0000
76.0000 3.4294 1.0000
76.0600 3.0254 1.0000
76.1200 4.5384 1.0000
76.1800 6.1282 1.0000
76.2400 3.1761 1.0000
76.3000 3.1337 1.0000
76.3600 1.9396 1.0000
76.4200 3.9661 1.0000
76.4800 5.8703 1.0000
76.5400 4.6042 1.0000
76.6000 1.4792 1.0000
76.6600 3.5266 1.0000
76.7200 2.9926 1.0000
76.7800 3.6347 1.0000
76.8400 3.8871 1.0000
76.9000 1.9785 1.0000
76.9600 3.1850 1.0000
77.0200 6.7679 1.0000
77.0800 5.6903 1.0000
77.1400 4.0269 1.0000
77.2000 7.1212 1.0000
77.2600 5.7144 1.0000
77.3200 4.4038 1.0000
77.3800 6.1604 1.0000
77.4400 5.1768 1.0000
77.5000 6.6340 1.0000
77.5600 8.2043 1.0000
77.6200 3.0034 1.0000
77.6800 6.9026 1.0000
77.7400 6.1325 1.0000
77.8000 0.8110 1.0000
77.8600 5.9979 1.0000
77.9200 3.5853 1.0000
77.9800 2.3143 1.0000
78.0400 4.5305 1.0000
78.1000 3.9814 1.0000
78.1600 4.6158 1.0000
78.2200 4.3819 1.0000
78.2800 5.7148 1.0000
78.3400 2.7432 1.0000
78.4000 2.9636 1.0000
78.4600 2.0866 1.0000
78.5200 3.7668 1.0000
78.5800 5.1625 1.0000
78.6400 6.2443 1.0000
78.7000 2.2786 1.0000
78.7600 2.6658 1.0000
78.8200 7.3367 1.0000
78.8800 4.1735 1.0000
78.9400 3.9296 1.0000
79.0000 4.7326 1.0000
79.0600 6.2919 1.0000
79.1200 7.0203 1.0000
79.1800 3.0805 1.0000
79.2400 5.1095 1.0000
79.3000 3.1447 1.0000
79.3600 2.4637 1.0000
79.4200 3.6089 1.0000
79.4800 3.6665 1.0000
79.5400 0.9354 1.0000
79.6000 9.4372 1.0000
79.6600 4.3917 1.0000
79.7200 3.2782 1.0000
79.7800 6.3674 1.0000
79.8400 3.6365 1.0000
79.9000 5.3253 1.0000
79.9600 6.6622 1.0000
80.0200 2.8328 1.0000
80.0800 2.1830 1.0000
80.1400 3.6771 1.0000
80.2000 5.5796 1.0000
80.2600 5.5207 1.0000
80.3200 2.7759 1.0000
80.3800 5.5602 1.0000
80.4400 6.4075 1.0000
80.5000 9.1922 1.0000
80.5600 3.4407 1.0000
80.6200 3.3637 1.0000
80.6800 3.5763 1.0000
80.7400 2.0971 1.0000
80.8000 6.3252 1.0000
80.8600 1.5472 1.0000
80.9200 5.0225 1.0000
80.9800 3.0803 1.0000
81.0400 0.9673 1.0000
81.1000 4.2346 1.0000
81.1600 4.1553 1.0000
81.2200 4.5231 1.0000
81.2800 2.8426 1.0000
81.3400 5.7479 1.0000
81.4000 4.2543 1.0000
81.4600 5.8915 1.0000
81.5200 12.1307 1.0000
81.5800 7.1643 1.0000
81.6400 3.9216 1.0000
81.7000 6.0381 1.0000
81.7600 4.7451 1.0000
81.8200 11.0555 1.0000
81.8800 5.0121 1.0000
81.9400 15.3404 1.0000
82.0000 13.5441 1.0000
82.0600 18.3601 1.0000
82.1200 19.9070 1.0000
82.1800 26.0565 1.0000
82.2400 18.0458 1.0000
82.3000 15.2982 1.0000
82.3600 14.3228 1.0000
82.4200 9.0955 1.0000
82.4800 10.4871 1.0000
82.5400 7.6646 1.0000
82.6000 8.8691 1.0000
82.6600 3.7818 1.0000
82.7200 3.4244 1.0000
82.7800 3.7461 1.0000
82.8400 3.5783 1.0000
82.9000 2.5336 1.0000
82.9600 6.2912 1.0000
83.0200 7.8075 1.0000
83.0800 2.0727 1.0000
83.1400 2.7870 1.0000
83.2000 0.7373 1.0000
83.2600 6.8517 1.0000
83.3200 0.4218 1.0000
83.3800 3.7459 1.0000
83.4400 1.0250 1.0000
83.5000 2.8755 1.0000
83.5600 3.9665 1.0000
83.6200 2.4892 1.0000
83.6800 4.5160 1.0000
83.7400 3.9332 1.0000
83.8000 4.1561 1.0000
83.8600 2.9887 1.0000
83.9200 2.0355 1.0000
83.9800 5.8032 1.0000
84.0400 3.6586 1.0000
84.1000 2.2316 1.0000
84.1600 3.7121 1.0000
84.2200 4.3696 1.0000
84.2800 5.1656 1.0000
84.3400 4.4900 1.0000
84.4000 4.7312 1.0000
84.4600 6.2389 1.0000
84.5200 0.3021 1.0000
84.5800 2.9212 1.0000
84.6400 2.5437 1.0000
84.7000 3.3995 1.0000
84.7600 2.2788 1.0000
84.8200 7.6277 1.0000
84.8800 2.4275 1.0000
84.9400 7.1228 1.0000
85.0000 5.9872 1.0000
85.0600 3.2944 1.0000
85.1200 1.0325 1.0000
85.1800 4.0539 1.0000
85.2400 5.4980 1.0000
85.3000 3.3931 1.0000
85.3600 3.4970 1.0000
85.4200 3.9216 1.0000
85.4800 6.2793 1.0000
85.5400 1.4289 1.0000
85.6000 6.2460 1.0000
85.6600 1.7343 1.0000
85.7200 3.1368 1.0000
85.7800 2.4187 1.0000
85.8400 6.7849 1.0000
85.9000 4.6735 1.0000
85.9600 4.8814 1.0000
86.0200 4.1158 1.0000
86.0800 7.2986 1.0000
86.1400 3.8099 1.0000
86.2000 3.8204 1.0000
86.2600 4.2025 1.0000
86.3200 1.7417 1.0000
86.3800 3.6223 1.0000
86.4400 1.0926 1.0000
86.5000 3.5728 1.0000
86.5600 4.0759 1.0000
86.6200 8.0823 1.0000
86.6800 6.2887 1.0000
86.7400 4.8052 1.0000
86.8000 1.8854 1.0000
86.8600 3.3036 1.0000
86.9200 5.0385 1.0000
86.9800 5.6497 1.0000
87.0400 3.2548 1.0000
87.1000 3.2145 1.0000
87.1600 1.4588 1.0000
87.2200 4.4141 1.0000
87.2800 4.9501 1.0000
87.3400 3.7142 1.0000
87.4000 6.3638 1.0000
87.4600 7.7071 1.0000
87.5200 4.1396 1.0000
87.5800 7.2366 1.0000
87.6400 4.8389 1.0000
87.7000 3.8004 1.0000
87.7600 5.0703 1.0000
87.8200 2.1636 1.0000
87.8800 6.3506 1.0000
87.9400 5.1748 1.0000
88.0000 7.2201 1.0000
88.0600 3.2737 1.0000
88.1200 5.9500 1.0000
88.1800 5.1648 1.0000
88.2400 4.3375 1.0000
88.3000 2.2267 1.0000
88.3600 1.4206 1.0000
88.4200 2.0270 1.0000
88.4800 2.1718 1.0000
88.5400 4.7809 1.0000
88.6000 0.9927 1.0000
88.6600 2.2424 1.0000
88.7200 3.8738 1.0000
88.7800 4.3416 1.0000
88.8400 4.2644 1.0000
88.9000 3.3757 1.0000
88.9600 3.9250 1.0000
89.0200 5.3495 1.0000
89.0800 7.1438 1.0000
89.1400 5.0761 1.0000
89.2000 7.5898 1.0000
89.2600 2.8018 1.0000
89.3200 1.1555 1.0000
89.3800 3.5673 1.0000
89.4400 6.5162 1.0000
89.5000 5.7044 1.0000
89.5600 0.3671 1.0000
89.6200 1.2365 1.0000
89.6800 4.8506 1.0000
89.7400 0.2917 1.0000
89.8000 5.9739 1.0000
89.8600 4.6110 1.0000
89.9200 7.8688 1.0000
89.9800 1.3753 1.0000
90.0400 9.1719 1.0000
90.1000 0.4381 1.0000
90.1600 5.0784 1.0000
90.2200 1.9948 1.0000
90.2800 4.3513 1.0000
90.3400 3.8734 1.0000
90.4000 5.7199 1.0000
90.4600 3.4986 1.0000
90.5200 4.2672 1.0000
90.5800 6.5608 1.0000
90.6400 4.1187 1.0000
90.7000 5.5082 1.0000
90.7600 3.7554 1.0000
90.8200 4.0413 1.0000
90.8800 6.3624 1.0000
90.9400 2.5736 1.0000
91.0000 7.1668 1.0000
91.0600 3.2411 1.0000
91.1200 2.2642 1.0000
91.1800 16.5547 1.0000
91.2400 3.1725 1.0000
91.3000 3.0315 1.0000
91.3600 6.0573 1.0000
91.4200 3.2851 1.0000
91.4800 4.4040 1.0000
91.5400 2.2300 1.0000
91.6000 3.4935 1.0000
91.6600 5.0886 1.0000
91.7200 9.0108 1.0000
91.7800 7.9038 1.0000
91.8400 2.3759 1.0000
91.9000 4.0169 1.0000
91.9600 2.1456 1.0000
92.0200 3.9019 1.0000
92.0800 5.8576 1.0000
92.1400 4.8498 1.0000
92.2000 1.9954 1.0000
92.2600 3.0861 1.0000
92.3200 3.3165 1.0000
92.3800 1.9114 1.0000
92.4400 3.0962 1.0000
92.5000 0.5753 1.0000
92.5600 1.8906 1.0000
92.6200 5.3944 1.0000
92.6800 2.4579 1.0000
92.7400 2.8260 1.0000
92.8000 5.2674 1.0000
92.8600 4.2756 1.0000
92.9200 5.0514 1.0000
92.9800 3.3228 1.0000
93.0400 3.3991 1.0000
93.1000 4.4064 1.0000
93.1600 4.8972 1.0000
93.2200 3.2956 1.0000
93.2800 1.0723 1.0000
93.3400 4.2518 1.0000
93.4000 3.7734 1.0000
93.4600 4.0875 1.0000
93.5200 5.1206 1.0000
93.5800 6.3939 1.0000
93.6400 5.0135 1.0000
93.7000 4.9549 1.0000
93.7600 5.1361 1.0000
93.8200 3.6384 1.0000
93.8800 4.0592 1.0000
93.9400 6.5241 1.0000
94.0000 7.7643 1.0000
94.0600 5.7092 1.0000
94.1200 4.2126 1.0000
94.1800 4.6459 1.0000
94.2400 3.2024 1.0000
94.3000 3.6846 1.0000
94.3600 3.0502 1.0000
94.4200 3.6120 1.0000
94.4800 5.0483 1.0000
94.5400 4.1112 1.0000
94.6000 2.6783 1.0000
94.6600 4.8423 1.0000
94.7200 9.0013 1.0000
94.7800 4.6272 1.0000
94.8400 10.2505 1.0000
94.9000 2.8018 1.0000
94.9600 3.1347 1.0000
95.0200 7.8801 1.0000
95.0800 3.2417 1.0000
95.1400 6.2758 1.0000
95.2000 3.0516 1.0000
95.2600 3.6816 1.0000
95.3200 6.4006 1.0000
95.3800 1.2184 1.0000
95.4400 3.5990 1.0000
95.5000 4.3696 1.0000
95.5600 4.5675 1.0000
95.6200 5.1401 1.0000
95.6800 3.9552 1.0000
95.7400 3.3155 1.0000
95.8000 5.6518 1.0000
95.8600 5.0763 1.0000
95.9200 2.6164 1.0000
95.9800 3.9442 1.0000
96.0400 5.2679 1.0000
96.1000 2.5517 1.0000
96.1600 3.7745 1.0000
96.2200 3.6100 1.0000
96.2800 2.9832 1.0000
96.3400 7.0349 1.0000
96.4000 2.7345 1.0000
96.4600 4.6825 1.0000
96.5200 5.0403 1.0000
96.5800 4.3967 1.0000
96.6400 5.9008 1.0000
96.7000 4.3409 1.0000
96.7600 7.5178 1.0000
96.8200 5.1889 1.0000
96.8800 2.2267 1.0000
96.9400 3.3527 1.0000
97.0000 6.4790 1.0000
97.0600 6.9572 1.0000
97.1200 6.4768 1.0000
97.1800 3.2169 1.0000
97.2400 1.6593 1.0000
97.3000 4.0059 1.0000
97.3600 4.1355 1.0000
97.4200 5.9803 1.0000
97.4800 9.5599 1.0000
97.5400 4.3592 1.0000
97.6000 3.8851 1.0000
97.6600 6.1560 1.0000
97.7200 7.5795 1.0000
97.7800 7.1078 1.0000
97.8400 3.1935 1.0000
97.9000 6.0282 1.0000
97.9600 7.8962 1.0000
98.0200 7.8949 1.0000
98.0800 4.0880 1.0000
98.1400 10.7808 1.0000
98.2000 4.5153 1.0000
98.2600 5.2156 1.0000
98.3200 6.0647 1.0000
98.3800 7.6122 1.0000
98.4400 12.2623 1.0000
98.5000 12.3703 1.0000
98.5600 8.5712 1.0000
98.6200 15.9624 1.0000
98.6800 18.2241 1.0000
98.7400 19.9384 1.0000
98.8000 10.5171 1.0000
98.8600 7.9162 1.0000
98.9200 9.9426 1.0000
98.9800 6.7556 1.0000
99.0400 6.9499 1.0000
99.1000 6.3982 1.0000
99.1600 3.3600 1.0000
99.2200 4.1902 1.0000
99.2800 5.2548 1.0000
99.3400 3.8427 1.0000
99.4000 5.7376 1.0000
99.4600 5.9822 1.0000
99.5200 4.1086 1.0000
99.5800 5.0651 1.0000
99.6400 2.6305 1.0000
99.7000 6.1349 1.0000
99.7600 5.3195 1.0000
99.8200 4.3966 1.0000
99.8800 2.8468 1.0000
99.9400 4.6680 1.0000
100.0000 7.4389 1.0000
100.0600 3.1134 1.0000
100.1200 2.3774 1.0000
100.1800 6.1906 1.0000
100.2400 7.9808 1.0000
100.3000 4.1739 1.0000
100.3600 5.0536 1.0000
100.4200 5.9272 1.0000
100.4800 3.9541 1.0000
100.5400 6.4598 1.0000
100.6000 5.0490 1.0000
100.6600 3.1482 1.0000
100.7200 1.0939 1.0000
100.7800 2.8697 1.0000
100.8400 6.4583 1.0000
100.9000 6.2791 1.0000
100.9600 6.4595 1.0000
101.0200 5.1983 1.0000
101.0800 5.3208 1.0000
101.1400 5.2274 1.0000
101.2000 4.2264 1.0000
101.2600 3.4795 1.0000
101.3200 5.7189 1.0000
101.3800 5.2123 1.0000
101.4400 4.0327 1.0000
101.5000 4.0481 1.0000
101.5600 6.8313 1.0000
101.6200 3.2163 1.0000
101.6800 3.2476 1.0000
101.7400 3.7573 1.0000
101.8000 3.6555 1.0000
101.8600 4.7810 1.0000
101.9200 3.3094 1.0000
101.9800 2.5041 1.0000
102.0400 6.6865 1.0000
102.1000 2.6519 1.0000
102.1600 7.1718 1.0000
102.2200 0.6645 1.0000
102.2800 1.2970 1.0000
102.3400 8.1694 1.0000
102.4000 4.2822 1.0000
102.4600 3.0821 1.0000
102.5200 4.7771 1.0000
102.5800 4.5910 1.0000
102.6400 5.3690 1.0000
102.7000 3.2968 1.0000
102.7600 1.3910 1.0000
102.8200 3.1375 1.0000
102.8800 4.8983 1.0000
102.9400 3.7986 1.0000
103.0000 4.6423 1.0000
103.0600 4.8719 1.0000
103.1200 8.7735 1.0000
103.1800 3.2535 1.0000
103.2400 2.2996 1.0000
103.3000 7.2748 1.0000
103.3600 3.9969 1.0000
103.4200 3.5668 1.0000
103.4800 3.6607 1.0000
103.5400 5.8436 1.0000
103.6000 4.8539 1.0000
103.6600 2.3997 1.0000
103.7200 2.3316 1.0000
103.7800 4.5751 1.0000
103.8400 3.4471 1.0000
103.9000 7.8580 1.0000
103.9600 2.2351 1.0000
104.0200 5.0083 1.0000
104.0800 2.0549 1.0000
104.1400 2.1473 1.0000
104.2000 3.6706 1.0000
104.2600 1.5472 1.0000
104.3200 5.2526 1.0000
104.3800 3.2344 1.0000
104.4400 5.0283 1.0000
104.5000 3.2462 1.0000
104.5600 3.1544 1.0000
104.6200 8.6551 1.0000
104.6800 8.2217 1.0000
104.7400 4.7549 1.0000
104.8000 4.8012 1.0000
104.8600 5.0125 1.0000
104.9200 1.5012 1.0000
104.9800 5.1928 1.0000
105.0400 4.7463 1.0000
105.1000 2.9302 1.0000
105.1600 3.0492 1.0000
105.2200 2.9612 1.0000
105.2800 5.6949 1.0000
105.3400 6.1565 1.0000
105.4000 3.2835 1.0000
105.4600 5.9336 1.0000
105.5200 10.3958 1.0000
105.5800 3.2566 1.0000
105.6400 2.0751 1.0000
105.7000 5.6624 1.0000
105.7600 2.2713 1.0000
105.8200 5.0578 1.0000
105.8800 3.2871 1.0000
105.9400 0.0000 1.0000
106.0000 6.7983 1.0000
106.0600 4.7998 1.0000
106.1200 6.2860 1.0000
106.1800 4.0834 1.0000
106.2400 5.4426 1.0000
106.3000 5.7357 1.0000
106.3600 4.2313 1.0000
106.4200 4.5975 1.0000
106.4800 5.3132 1.0000
106.5400 6.1451 1.0000
106.6000 4.1504 1.0000
106.6600 5.5468 1.0000
106.7200 6.3999 1.0000
106.7800 3.9534 1.0000
106.8400 7.2498 1.0000
106.9000 1.2042 1.0000
106.9600 1.9379 1.0000
107.0200 2.3409 1.0000
107.0800 1.3191 1.0000
107.1400 3.0933 1.0000
107.2000 3.1050 1.0000
107.2600 5.7656 1.0000
107.3200 2.2865 1.0000
107.3800 3.7946 1.0000
107.4400 3.6029 1.0000
107.5000 1.7521 1.0000
107.5600 4.3537 1.0000
107.6200 3.3002 1.0000
107.6800 0.7473 1.0000
107.7400 5.5284 1.0000
107.8000 4.6885 1.0000
107.8600 4.5152 1.0000
107.9200 3.3760 1.0000
107.9800 3.6797 1.0000
108.0400 4.8287 1.0000
108.1000 3.4751 1.0000
108.1600 2.1820 1.0000
108.2200 5.1585 1.0000
108.2800 4.1966 1.0000
108.3400 5.9896 1.0000
108.4000 4.7828 1.0000
108.4600 6.4552 1.0000
108.5200 5.0377 1.0000
[...]
66.7600 6.0255 1.0000
66.8200 5.3643 1.0000
66.8800 4.9518 1.0000
66.9400 2.5285 1.0000
67.0000 1.8851 1.0000
67.0600 5.2456 1.0000
67.1200 2.6265 1.0000
67.1800 8.1095 1.0000
67.2400 6.7988 1.0000
67.3000 4.3694 1.0000
67.3600 4.6327 1.0000
67.4200 3.0706 1.0000
67.4800 5.2233 1.0000
67.5400 1.5710 1.0000
67.6000 4.0926 1.0000
67.6600 2.4529 1.0000
67.7200 1.9320 1.0000
67.7800 1.7418 1.0000
67.8400 2.8348 1.0000
67.9000 4.5967 1.0000
67.9600 3.9299 1.0000
68.0200 4.2487 1.0000
68.0800 2.6673 1.0000
68.1400 5.1125 1.0000
68.2000 3.7632 1.0000
68.2600 3.8347 1.0000
68.3200 3.7777 1.0000
68.3800 7.6731 1.0000
68.4400 3.0356 1.0000
68.5000 6.0736 1.0000
68.5600 5.2002 1.0000
68.6200 5.1945 1.0000
68.6800 5.0196 1.0000
68.7400 6.0412 1.0000
68.8000 4.2354 1.0000
68.8600 5.1120 1.0000
68.9200 5.2545 1.0000
68.9800 7.2234 1.0000
69.0400 6.6246 1.0000
69.1000 2.6683 1.0000
69.1600 4.3632 1.0000
69.2200 5.5541 1.0000
69.2800 3.0326 1.0000
69.3400 1.4906 1.0000
69.4000 3.4304 1.0000
69.4600 2.5831 1.0000
69.5200 3.8404 1.0000
69.5800 6.1969 1.0000
69.6400 4.3315 1.0000
69.7000 8.2545 1.0000
69.7600 1.7215 1.0000
69.8200 4.0558 1.0000
69.8800 2.0273 1.0000
69.9400 5.7759 1.0000
70.0000 0.3627 1.0000
70.0600 3.2932 1.0000
70.1200 4.5883 1.0000
70.1800 3.5667 1.0000
70.2400 6.9926 1.0000
70.3000 3.7179 1.0000
70.3600 3.1367 1.0000
70.4200 9.3986 1.0000
70.4800 5.7184 1.0000
70.5400 7.3807 1.0000
70.6000 2.7237 1.0000
70.6600 7.1531 1.0000
70.7200 5.2278 1.0000
70.7800 5.0251 1.0000
70.8400 7.0186 1.0000
70.9000 2.1370 1.0000
70.9600 2.9901 1.0000
71.0200 6.6286 1.0000
71.0800 3.7637 1.0000
71.1400 3.1509 1.0000
71.2000 3.4048 1.0000
71.2600 1.6702 1.0000
71.3200 1.4690 1.0000
71.3800 3.1048 1.0000
71.4400 1.3287 1.0000
71.5000 5.9266 1.0000
71.5600 3.8094 1.0000
71.6200 2.9567 1.0000
71.6800 4.4798 1.0000
71.7400 2.1401 1.0000
71.8000 7.2965 1.0000
71.8600 3.1967 1.0000
71.9200 5.1616 1.0000
71.9800 8.0351 1.0000
72.0400 3.1903 1.0000
72.1000 3.8652 1.0000
72.1600 9.9708 1.0000
72.2200 3.7802 1.0000
72.2800 4.1533 1.0000
72.3400 4.0760 1.0000
72.4000 2.6637 1.0000
72.4600 10.0275 1.0000
72.5200 5.6278 1.0000
72.5800 10.9726 1.0000
72.6400 2.0167 1.0000
72.7000 6.9164 1.0000
72.7600 4.8488 1.0000
72.8200 4.4391 1.0000
72.8800 3.6381 1.0000
72.9400 4.8358 1.0000
73.0000 1.4730 1.0000
73.0600 4.0294 1.0000
73.1200 3.9177 1.0000
73.1800 7.4340 1.0000
73.2400 7.0452 1.0000
73.3000 3.5419 1.0000
73.3600 3.2070 1.0000
73.4200 4.2310 1.0000
73.4800 0.5584 1.0000
73.5400 7.0308 1.0000
73.6000 2.3218 1.0000
73.6600 5.0147 1.0000
73.7200 1.8689 1.0000
73.7800 6.9510 1.0000
73.8400 4.5067 1.0000
73.9000 5.9576 1.0000
73.9600 7.2670 1.0000
74.0200 4.3437 1.0000
74.0800 8.1558 1.0000
74.1400 1.0636 1.0000
74.2000 4.9398 1.0000
74.2600 4.6988 1.0000
74.3200 3.7954 1.0000
74.3800 5.2530 1.0000
74.4400 7.3927 1.0000
74.5000 9.1054 1.0000
74.5600 4.1130 1.0000
74.6200 1.0792 1.0000
74.6800 7.8091 1.0000
74.7400 6.4991 1.0000
74.8000 2.1782 1.0000
74.8600 4.1361 1.0000
74.9200 4.0383 1.0000
74.9800 4.4162 1.0000
75.0400 9.2689 1.0000
75.1000 7.8901 1.0000
75.1600 2.9256 1.0000
75.2200 4.8771 1.0000
75.2800 4.6422 1.0000
75.3400 6.1048 1.0000
75.4000 7.7345 1.0000
75.4600 6.8452 1.0000
75.5200 5.4793 1.0000
75.5800 4.1803 1.0000
75.6400 9.8651 1.0000
75.7000 3.8172 1.0000
75.7600 5.1711 1.0000
75.8200 5.6505 1.0000
75.8800 1.4943 1.0000
75.9400 3.6589 1.0000
76.0000 4.2058 1.0000
76.0600 2.3490 1.0000
76.1200 3.5211 1.0000
76.1800 3.5259 1.0000
76.2400 3.5501 1.0000
76.3000 0.4022 1.0000
76.3600 6.9773 1.0000
76.4200 3.5559 1.0000
76.4800 10.0977 1.0000
76.5400 2.3855 1.0000
76.6000 4.1755 1.0000
76.6600 4.4331 1.0000
76.7200 4.9314 1.0000
76.7800 4.4010 1.0000
76.8400 2.0674 1.0000
76.9000 4.8734 1.0000
76.9600 8.4038 1.0000
77.0200 2.4408 1.0000
77.0800 3.0712 1.0000
77.1400 5.5553 1.0000
77.2000 9.2619 1.0000
77.2600 9.2100 1.0000
77.3200 4.1654 1.0000
77.3800 3.5281 1.0000
77.4400 4.6554 1.0000
77.5000 8.0631 1.0000
77.5600 4.9550 1.0000
77.6200 3.5768 1.0000
77.6800 5.3705 1.0000
77.7400 4.8893 1.0000
77.8000 6.0861 1.0000
77.8600 0.5014 1.0000
77.9200 1.5493 1.0000
77.9800 3.1536 1.0000
78.0400 2.8872 1.0000
78.1000 4.4070 1.0000
78.1600 3.9058 1.0000
78.2200 4.8933 1.0000
78.2800 2.2701 1.0000
78.3400 1.0483 1.0000
78.4000 9.2934 1.0000
78.4600 3.7553 1.0000
78.5200 6.0112 1.0000
78.5800 4.9536 1.0000
78.6400 5.7364 1.0000
78.7000 4.7923 1.0000
78.7600 5.8525 1.0000
78.8200 5.8050 1.0000
78.8800 6.4630 1.0000
78.9400 5.1338 1.0000
79.0000 3.9743 1.0000
79.0600 6.1151 1.0000
79.1200 7.2037 1.0000
79.1800 3.2143 1.0000
79.2400 7.3770 1.0000
79.3000 2.6106 1.0000
79.3600 5.2870 1.0000
79.4200 2.9858 1.0000
79.4800 1.1364 1.0000
79.5400 5.1539 1.0000
79.6000 4.9956 1.0000
79.6600 1.2267 1.0000
79.7200 4.5462 1.0000
79.7800 5.9957 1.0000
79.8400 3.4279 1.0000
79.9000 10.4637 1.0000
79.9600 1.2964 1.0000
80.0200 6.2188 1.0000
80.0800 9.3530 1.0000
80.1400 2.5464 1.0000
80.2000 3.0311 1.0000
80.2600 3.2366 1.0000
80.3200 4.3913 1.0000
80.3800 4.5312 1.0000
80.4400 4.2735 1.0000
80.5000 5.1093 1.0000
80.5600 2.8354 1.0000
80.6200 3.4109 1.0000
80.6800 4.8037 1.0000
80.7400 4.0023 1.0000
80.8000 3.1788 1.0000
80.8600 7.1892 1.0000
80.9200 6.2700 1.0000
80.9800 2.6595 1.0000
81.0400 3.3449 1.0000
81.1000 6.7295 1.0000
81.1600 4.2923 1.0000
81.2200 6.9857 1.0000
81.2800 2.2936 1.0000
81.3400 6.5471 1.0000
81.4000 4.6458 1.0000
81.4600 6.3353 1.0000
81.5200 3.5338 1.0000
81.5800 4.4457 1.0000
81.6400 2.6131 1.0000
81.7000 3.3329 1.0000
81.7600 7.6722 1.0000
81.8200 6.6303 1.0000
81.8800 12.1470 1.0000
81.9400 12.9601 1.0000
82.0000 25.0747 1.0000
82.0600 27.6874 1.0000
82.1200 24.7637 1.0000
82.1800 22.6310 1.0000
82.2400 24.3532 1.0000
82.3000 10.5263 1.0000
82.3600 8.2292 1.0000
82.4200 9.9273 1.0000
82.4800 10.5887 1.0000
82.5400 8.6304 1.0000
82.6000 3.1572 1.0000
82.6600 8.5841 1.0000
82.7200 5.4142 1.0000
82.7800 5.9949 1.0000
82.8400 3.1624 1.0000
82.9000 4.5187 1.0000
82.9600 4.0167 1.0000
83.0200 7.8211 1.0000
83.0800 2.1445 1.0000
83.1400 3.5717 1.0000
83.2000 5.2468 1.0000
83.2600 4.2789 1.0000
83.3200 5.5002 1.0000
83.3800 4.7071 1.0000
83.4400 8.2700 1.0000
83.5000 2.3478 1.0000
83.5600 7.4632 1.0000
83.6200 3.5037 1.0000
83.6800 3.8976 1.0000
83.7400 2.4970 1.0000
83.8000 5.3475 1.0000
83.8600 5.7995 1.0000
83.9200 2.2860 1.0000
83.9800 6.3601 1.0000
84.0400 8.2519 1.0000
84.1000 3.0383 1.0000
84.1600 6.2493 1.0000
84.2200 7.0735 1.0000
84.2800 5.6864 1.0000
84.3400 3.9427 1.0000
84.4000 8.7800 1.0000
84.4600 4.1879 1.0000
84.5200 8.7331 1.0000
84.5800 3.7423 1.0000
84.6400 4.6695 1.0000
84.7000 4.2259 1.0000
84.7600 2.5706 1.0000
84.8200 5.0093 1.0000
84.8800 4.1750 1.0000
84.9400 2.7190 1.0000
85.0000 4.7388 1.0000
85.0600 3.1681 1.0000
85.1200 1.7418 1.0000
85.1800 6.3342 1.0000
85.2400 4.8339 1.0000
85.3000 4.9184 1.0000
85.3600 3.8068 1.0000
85.4200 3.9996 1.0000
85.4800 7.8248 1.0000
85.5400 1.1235 1.0000
85.6000 5.8508 1.0000
85.6600 3.2468 1.0000
85.7200 4.2276 1.0000
85.7800 4.3536 1.0000
85.8400 6.5331 1.0000
85.9000 7.6604 1.0000
85.9600 2.8444 1.0000
86.0200 3.0794 1.0000
86.0800 6.1883 1.0000
86.1400 7.2702 1.0000
86.2000 5.1731 1.0000
86.2600 5.8479 1.0000
86.3200 3.7140 1.0000
86.3800 3.5650 1.0000
86.4400 8.6486 1.0000
86.5000 3.8904 1.0000
86.5600 2.3766 1.0000
86.6200 4.1723 1.0000
86.6800 1.2540 1.0000
86.7400 6.0909 1.0000
86.8000 3.3563 1.0000
86.8600 2.8334 1.0000
86.9200 4.1489 1.0000
86.9800 6.4857 1.0000
87.0400 5.6844 1.0000
87.1000 4.3478 1.0000
87.1600 6.7808 1.0000
87.2200 1.7515 1.0000
87.2800 4.3417 1.0000
87.3400 3.0941 1.0000
87.4000 6.1289 1.0000
87.4600 6.1569 1.0000
87.5200 4.1463 1.0000
87.5800 2.5881 1.0000
87.6400 3.8149 1.0000
87.7000 4.9435 1.0000
87.7600 5.3934 1.0000
87.8200 5.3123 1.0000
87.8800 4.1398 1.0000
87.9400 4.0949 1.0000
88.0000 3.9736 1.0000
88.0600 4.4071 1.0000
88.1200 2.4564 1.0000
88.1800 2.6865 1.0000
88.2400 2.9742 1.0000
88.3000 3.9202 1.0000
88.3600 3.2600 1.0000
88.4200 7.8635 1.0000
88.4800 6.2989 1.0000
88.5400 0.7207 1.0000
88.6000 5.8713 1.0000
88.6600 4.0509 1.0000
88.7200 2.2588 1.0000
88.7800 3.8755 1.0000
88.8400 5.1487 1.0000
88.9000 1.1347 1.0000
88.9600 6.7931 1.0000
89.0200 5.6282 1.0000
89.0800 1.8525 1.0000
89.1400 4.4112 1.0000
89.2000 3.3153 1.0000
89.2600 2.1710 1.0000
89.3200 5.5359 1.0000
89.3800 5.5189 1.0000
89.4400 9.8662 1.0000
89.5000 2.0092 1.0000
89.5600 0.7015 1.0000
89.6200 3.7376 1.0000
89.6800 3.7937 1.0000
89.7400 3.2892 1.0000
89.8000 2.9393 1.0000
89.8600 3.6662 1.0000
89.9200 6.5801 1.0000
89.9800 8.1104 1.0000
90.0400 6.7084 1.0000
90.1000 3.5756 1.0000
90.1600 6.1635 1.0000
90.2200 4.2359 1.0000
90.2800 1.3326 1.0000
90.3400 3.2515 1.0000
90.4000 5.6870 1.0000
90.4600 2.1239 1.0000
90.5200 4.3057 1.0000
90.5800 3.3498 1.0000
90.6400 4.6441 1.0000
90.7000 7.7233 1.0000
90.7600 10.9516 1.0000
90.8200 1.9570 1.0000
90.8800 2.3699 1.0000
90.9400 3.7148 1.0000
91.0000 2.0496 1.0000
91.0600 5.2137 1.0000
91.1200 6.3213 1.0000
91.1800 0.9336 1.0000
91.2400 1.4144 1.0000
91.3000 5.9127 1.0000
91.3600 2.6395 1.0000
91.4200 1.2808 1.0000
91.4800 2.4771 1.0000
91.5400 4.8621 1.0000
91.6000 8.6097 1.0000
91.6600 8.5018 1.0000
91.7200 4.0331 1.0000
91.7800 4.0152 1.0000
91.8400 3.2174 1.0000
91.9000 3.7847 1.0000
91.9600 3.4016 1.0000
92.0200 4.3942 1.0000
92.0800 4.2013 1.0000
92.1400 4.9680 1.0000
92.2000 1.7553 1.0000
92.2600 2.7124 1.0000
92.3200 6.7921 1.0000
92.3800 4.1275 1.0000
92.4400 6.0809 1.0000
92.5000 3.8229 1.0000
92.5600 1.4692 1.0000
92.6200 1.9148 1.0000
92.6800 6.2302 1.0000
92.7400 2.4762 1.0000
92.8000 4.8540 1.0000
92.8600 7.2906 1.0000
92.9200 4.3327 1.0000
92.9800 4.6446 1.0000
93.0400 4.3141 1.0000
93.1000 1.5646 1.0000
93.1600 3.4080 1.0000
93.2200 7.0970 1.0000
93.2800 3.3957 1.0000
93.3400 5.8722 1.0000
93.4000 6.6223 1.0000
93.4600 5.3781 1.0000
93.5200 1.3423 1.0000
93.5800 5.2086 1.0000
93.6400 5.6307 1.0000
93.7000 2.9129 1.0000
93.7600 3.1203 1.0000
93.8200 2.6014 1.0000
93.8800 0.2840 1.0000
93.9400 3.0483 1.0000
94.0000 7.6975 1.0000
94.0600 3.7996 1.0000
94.1200 5.2174 1.0000
94.1800 5.0029 1.0000
94.2400 5.2874 1.0000
94.3000 7.2986 1.0000
94.3600 2.2444 1.0000
94.4200 2.4676 1.0000
94.4800 5.7316 1.0000
94.5400 5.4868 1.0000
94.6000 0.0000 1.0000
94.6600 4.2315 1.0000
94.7200 5.1645 1.0000
94.7800 3.8253 1.0000
94.8400 4.1724 1.0000
94.9000 3.2891 1.0000
94.9600 3.0784 1.0000
95.0200 6.5396 1.0000
95.0800 3.3329 1.0000
95.1400 8.5923 1.0000
95.2000 5.6531 1.0000
95.2600 3.5933 1.0000
95.3200 6.9110 1.0000
95.3800 3.8382 1.0000
95.4400 4.1482 1.0000
95.5000 5.0366 1.0000
95.5600 4.5417 1.0000
95.6200 5.0365 1.0000
95.6800 4.0592 1.0000
95.7400 4.8695 1.0000
95.8000 2.6646 1.0000
95.8600 5.8536 1.0000
95.9200 2.3686 1.0000
95.9800 11.0045 1.0000
96.0400 4.6424 1.0000
96.1000 1.9665 1.0000
96.1600 3.6671 1.0000
96.2200 4.6151 1.0000
96.2800 1.5939 1.0000
96.3400 3.2379 1.0000
96.4000 10.2797 1.0000
96.4600 6.2973 1.0000
96.5200 4.9606 1.0000
96.5800 4.2563 1.0000
96.6400 5.2640 1.0000
96.7000 4.5967 1.0000
96.7600 6.8053 1.0000
96.8200 5.2075 1.0000
96.8800 3.2138 1.0000
96.9400 3.1147 1.0000
97.0000 2.0933 1.0000
97.0600 4.2047 1.0000
97.1200 3.8415 1.0000
97.1800 3.4352 1.0000
97.2400 5.7662 1.0000
97.3000 2.8390 1.0000
97.3600 1.2746 1.0000
97.4200 2.0990 1.0000
97.4800 2.3047 1.0000
97.5400 8.2671 1.0000
97.6000 5.6114 1.0000
97.6600 3.2038 1.0000
97.7200 6.7594 1.0000
97.7800 4.9718 1.0000
97.8400 7.3827 1.0000
97.9000 8.1054 1.0000
97.9600 6.5348 1.0000
98.0200 4.5701 1.0000
98.0800 1.3025 1.0000
98.1400 5.7581 1.0000
98.2000 8.3244 1.0000
98.2600 11.9972 1.0000
98.3200 9.3467 1.0000
98.3800 13.3239 1.0000
98.4400 9.9127 1.0000
98.5000 15.0370 1.0000
98.5600 9.5410 1.0000
98.6200 12.2476 1.0000
98.6800 15.8379 1.0000
98.7400 14.4901 1.0000
98.8000 9.7921 1.0000
98.8600 9.0404 1.0000
98.9200 9.0026 1.0000
98.9800 7.5627 1.0000
99.0400 6.2599 1.0000
99.1000 12.4149 1.0000
99.1600 4.2977 1.0000
99.2200 5.7729 1.0000
99.2800 0.9581 1.0000
99.3400 3.7736 1.0000
99.4000 1.6292 1.0000
99.4600 2.1875 1.0000
99.5200 3.0068 1.0000
99.5800 6.4205 1.0000
99.6400 4.1364 1.0000
99.7000 4.2272 1.0000
99.7600 4.4237 1.0000
99.8200 3.9690 1.0000
99.8800 1.5764 1.0000
99.9400 1.9781 1.0000
100.0000 3.2098 1.0000
100.0600 6.0629 1.0000
100.1200 6.4082 1.0000
100.1800 5.5513 1.0000
100.2400 6.8866 1.0000
100.3000 4.5553 1.0000
100.3600 3.3025 1.0000
100.4200 2.8174 1.0000
100.4800 7.9141 1.0000
100.5400 3.0773 1.0000
100.6000 6.2538 1.0000
100.6600 3.4194 1.0000
100.7200 4.7379 1.0000
100.7800 0.8192 1.0000
100.8400 7.6486 1.0000
100.9000 7.3465 1.0000
100.9600 6.0863 1.0000
101.0200 3.1399 1.0000
101.0800 6.0994 1.0000
101.1400 3.7653 1.0000
101.2000 4.0129 1.0000
101.2600 4.5236 1.0000
101.3200 1.8177 1.0000
101.3800 4.2120 1.0000
101.4400 5.1401 1.0000
101.5000 7.1327 1.0000
101.5600 3.5204 1.0000
101.6200 7.8687 1.0000
101.6800 2.3860 1.0000
101.7400 5.0059 1.0000
101.8000 1.9048 1.0000
101.8600 4.5015 1.0000
101.9200 3.2877 1.0000
101.9800 4.9310 1.0000
102.0400 4.5400 1.0000
102.1000 3.1950 1.0000
102.1600 3.5291 1.0000
102.2200 5.2173 1.0000
102.2800 4.3819 1.0000
102.3400 9.1431 1.0000
102.4000 2.7153 1.0000
102.4600 4.4701 1.0000
102.5200 5.2136 1.0000
102.5800 2.4098 1.0000
102.6400 1.3518 1.0000
102.7000 6.1527 1.0000
102.7600 2.4612 1.0000
102.8200 2.5045 1.0000
102.8800 8.2099 1.0000
102.9400 3.0848 1.0000
103.0000 3.0829 1.0000
103.0600 5.6089 1.0000
103.1200 5.8997 1.0000
103.1800 0.0000 1.0000
103.2400 4.9935 1.0000
103.3000 6.2551 1.0000
103.3600 8.6983 1.0000
103.4200 5.2083 1.0000
103.4800 1.4627 1.0000
103.5400 3.6789 1.0000
103.6000 5.2783 1.0000
103.6600 3.8471 1.0000
103.7200 4.1652 1.0000
103.7800 1.9563 1.0000
103.8400 6.2209 1.0000
103.9000 4.2120 1.0000
103.9600 4.2881 1.0000
104.0200 3.0385 1.0000
104.0800 1.6826 1.0000
104.1400 7.4290 1.0000
104.2000 4.1409 1.0000
104.2600 3.2089 1.0000
104.3200 5.7981 1.0000
104.3800 3.0268 1.0000
104.4400 6.7470 1.0000
104.5000 5.8496 1.0000
104.5600 6.0021 1.0000
104.6200 6.2627 1.0000
104.6800 4.0782 1.0000
104.7400 1.8458 1.0000
104.8000 2.1531 1.0000
104.8600 3.3398 1.0000
104.9200 4.5387 1.0000
104.9800 2.4036 1.0000
105.0400 6.6174 1.0000
105.1000 3.9784 1.0000
105.1600 3.2420 1.0000
105.2200 3.9552 1.0000
105.2800 6.0943 1.0000
105.3400 10.4546 1.0000
105.4000 3.4881 1.0000
105.4600 5.5362 1.0000
105.5200 4.5463 1.0000
105.5800 4.8129 1.0000
105.6400 3.7949 1.0000
105.7000 2.0863 1.0000
105.7600 4.5773 1.0000
105.8200 0.2369 1.0000
105.8800 4.4407 1.0000
105.9400 1.0945 1.0000
106.0000 4.9540 1.0000
106.0600 3.1260 1.0000
106.1200 6.0634 1.0000
106.1800 3.1265 1.0000
106.2400 4.1754 1.0000
106.3000 4.9836 1.0000
106.3600 1.9839 1.0000
106.4200 3.5619 1.0000
106.4800 1.4393 1.0000
106.5400 5.4776 1.0000
106.6000 4.2362 1.0000
106.6600 6.5942 1.0000
106.7200 9.4515 1.0000
106.7800 1.8308 1.0000
106.8400 5.2494 1.0000
106.9000 3.0806 1.0000
106.9600 2.9413 1.0000
107.0200 3.2066 1.0000
107.0800 9.0195 1.0000
107.1400 7.5638 1.0000
107.2000 5.2708 1.0000
107.2600 2.4420 1.0000
107.3200 4.0579 1.0000
107.3800 4.8541 1.0000
107.4400 4.1723 1.0000
107.5000 4.8421 1.0000
107.5600 2.9778 1.0000
107.6200 2.1156 1.0000
107.6800 3.1697 1.0000
107.7400 0.3569 1.0000
107.8000 2.7837 1.0000
107.8600 9.3869 1.0000
107.9200 3.9780 1.0000
107.9800 4.9130 1.0000
108.0400 5.2746 1.0000
108.1000 3.8032 1.0000
108.1600 5.2594 1.0000
108.2200 5.6055 1.0000
108.2800 2.1243 1.0000
108.3400 5.0547 1.0000
108.4000 5.9998 1.0000
108.4600 8.2627 1.0000
108.5200 4.3942 1.0000
108.5800 4.2466 1.0000
108.6400 8.5342 1.0000
108.7000 5.0819 1.0000
108.7600 7.1201 1.0000
108.8200 8.1906 1.0000
108.8800 5.0112 1.0000
108.9400 4.2773 1.0000
109.0000 4.9946 1.0000
109.0600 5.6971 1.0000
109.1200 2.2062 1.0000
109.1800 6.7240 1.0000
109.2400 4.9875 1.0000
109.3000 5.1367 1.0000
109.3600 7.1384 1.0000
109.4200 1.6953 1.0000
109.4800 5.4560 1.0000
109.5400 6.9593 1.0000
109.6000 1.0614 1.0000
109.6600 4.0818 1.0000
109.7200 3.9189 1.0000
109.7800 3.3434 1.0000
109.8400 3.6202 1.0000
109.9000 2.3489 1.0000
109.9600 3.4484 1.0000
110.0200 9.5921 1.0000
110.0800 3.1558 1.0000
110.1400 3.8765 1.0000
110.2000 2.5808 1.0000
110.2600 2.1934 1.0000
110.3200 0.7557 1.0000
110.3800 1.9743 1.0000
110.4400 10.2022 1.0000
110.5000 1.3668 1.0000
110.5600 7.7435 1.0000
110.6200 1.3365 1.0000
110.6800 4.2364 1.0000
110.7400 3.2910 1.0000
110.8000 8.5068 1.0000
110.8600 3.5860 1.0000
110.9200 6.7460 1.0000
110.9800 3.0276 1.0000
111.0400 8.9180 1.0000
111.1000 6.9951 1.0000
111.1600 5.0392 1.0000
111.2200 3.1644 1.0000
111.2800 4.7246 1.0000
111.3400 1.8287 1.0000
111.4000 3.1210 1.0000
111.4600 5.0489 1.0000
111.5200 1.9085 1.0000
111.5800 4.0250 1.0000
111.6400 5.7079 1.0000
111.7000 2.0065 1.0000
111.7600 4.0386 1.0000
111.8200 8.1063 1.0000
111.8800 5.9439 1.0000
111.9400 3.4952 1.0000
112.0000 4.9703 1.0000
112.0600 4.0728 1.0000
112.1200 0.0000 1.0000
112.1800 12.2126 1.0000
112.2400 5.2718 1.0000
112.3000 4.2336 1.0000
112.3600 2.1341 1.0000
112.4200 4.1677 1.0000
112.4800 7.9564 1.0000
112.5400 3.8133 1.0000
112.6000 4.0377 1.0000
112.6600 2.4628 1.0000
112.7200 6.1035 1.0000
112.7800 1.6721 1.0000
112.8400 5.2131 1.0000
112.9000 5.5372 1.0000
112.9600 5.2221 1.0000
113.0200 3.7119 1.0000
113.0800 1.8067 1.0000
113.1400 6.0767 1.0000
113.2000 4.1560 1.0000
113.2600 5.2613 1.0000
113.3200 4.6704 1.0000
113.3800 6.9151 1.0000
113.4400 6.7371 1.0000
113.5000 5.6655 1.0000
113.5600 4.5758 1.0000
113.6200 2.4553 1.0000
113.6800 8.0021 1.0000
113.7400 3.3005 1.0000
113.8000 4.1952 1.0000
113.8600 6.2942 1.0000
113.9200 3.0138 1.0000
113.9800 2.2362 1.0000
114.0400 4.9037 1.0000
114.1000 5.0127 1.0000
114.1600 5.8460 1.0000
114.2200 3.1434 1.0000
114.2800 5.1490 1.0000
114.3400 1.4268 1.0000
114.4000 3.8649 1.0000
114.4600 4.4070 1.0000
114.5200 3.2677 1.0000
114.5800 7.2058 1.0000
114.6400 2.3217 1.0000
114.7000 5.3709 1.0000
114.7600 6.9944 1.0000
114.8200 6.0934 1.0000
114.8800 4.1158 1.0000
114.9400 7.0311 1.0000
115.0000 3.5616 1.0000
115.0600 2.9609 1.0000
115.1200 7.4099 1.0000
115.1800 7.7297 1.0000
115.2400 7.1937 1.0000
115.3000 7.5625 1.0000
115.3600 4.8148 1.0000
115.4200 3.9712 1.0000
115.4800 7.3302 1.0000
115.5400 6.3165 1.0000
115.6000 8.7566 1.0000
115.6600 7.2958 1.0000
115.7200 14.5770 1.0000
115.7800 9.0146 1.0000
115.8400 10.3421 1.0000
115.9000 9.2376 1.0000
115.9600 5.3520 1.0000
116.0200 12.2495 1.0000
116.0800 13.1143 1.0000
116.1400 8.3501 1.0000
116.2000 6.3762 1.0000
116.2600 7.0707 1.0000
116.3200 5.4685 1.0000
116.3800 3.3446 1.0000
116.4400 5.0570 1.0000
116.5000 8.6579 1.0000
116.5600 9.5036 1.0000
116.6200 6.5306 1.0000
116.6800 5.3518 1.0000
116.7400 6.5980 1.0000
116.8000 6.0337 1.0000
116.8600 3.4190 1.0000
116.9200 6.6211 1.0000
116.9800 3.8408 1.0000
117.0400 5.3828 1.0000
117.1000 5.5399 1.0000
117.1600 5.1629 1.0000
117.2200 6.8103 1.0000
117.2800 2.2031 1.0000
117.3400 5.5901 1.0000
117.4000 3.4688 1.0000
117.4600 5.5128 1.0000
117.5200 5.4263 1.0000
117.5800 5.5941 1.0000
117.6400 2.0946 1.0000
117.7000 1.5422 1.0000
117.7600 3.8583 1.0000
117.8200 5.1071 1.0000
117.8800 6.1942 1.0000
117.9400 6.1884 1.0000
118.0000 9.0001 1.0000
118.0600 6.1123 1.0000
118.1200 8.9069 1.0000
118.1800 5.6420 1.0000
118.2400 6.1451 1.0000
118.3000 4.1078 1.0000
118.3600 6.9920 1.0000
118.4200 6.6459 1.0000
118.4800 4.8779 1.0000
118.5400 5.8057 1.0000
118.6000 2.7474 1.0000
118.6600 4.1310 1.0000
118.7200 1.6364 1.0000
118.7800 5.0445 1.0000
118.8400 2.6459 1.0000
118.9000 3.3390 1.0000
118.9600 5.0123 1.0000
119.0200 4.8267 1.0000
119.0800 3.1581 1.0000
119.1400 2.6390 1.0000
119.2000 1.9884 1.0000
119.2600 1.7502 1.0000
119.3200 4.2841 1.0000
119.3800 2.4732 1.0000
119.4400 3.9420 1.0000
119.5000 8.0293 1.0000
119.5600 2.2122 1.0000
119.6200 6.2797 1.0000
119.6800 7.1817 1.0000
119.7400 6.5723 1.0000
119.8000 4.0052 1.0000
119.8600 8.3522 1.0000
119.9200 4.0460 1.0000
119.9800 7.7297 1.0000
119.9900 2.8005 1.0000
*RAS_INT_END
*RAS_TEMPERATURE_START
*RAS_TEMPERATURE_END
*RAS_DATA_END