File: XRD/PB_Ge220_2.5SS_500umDS_RS1_Rod_2.5SS_Hypix1D_EFRW2_Weld_Centre_Unirradiated_Z-Reset.ras
*RAS_DATA_START
*RAS_HEADER_START
*DISP_FMT_X "%.3f"
*DISP_FMT_Y "%.0f"
*DISP_FULLSCALE "22.0547502249"
*DISP_LINE_COLOR "255.0000000000"
*DISP_LINE_STYLE "0.0000000000"
*DISP_LINE_WIDTH "0.2500000000"
*DISP_NOTE "Collected Data-22"
*DISP_OFFSET_Y "0.0000000000"
*DISP_PEAKSEARCH_UNIT_Y "cps"
*DISP_RANGE_BOTTOM "0.0000000000"
*DISP_RANGE_LEFT "40.0000000000"
*DISP_RANGE_LOGCUTOFF "0.0100000000"
*DISP_RANGE_RIGHT "119.9968000000"
*DISP_RANGE_TOP "22.0547502249"
*DISP_SCALE_MODE_Y "0.0000000000"
*DISP_TAB_NAME "Theta/2-Theta"
*DISP_TITLE_Y "Intensity"
*DISP_UNIT_Y "cps"
*DISP_WINDOW_NAME "MSG_MACROENGINE"
*FILE_COMMENT " "
*FILE_MD5 ""
*FILE_MEMO " "
*FILE_OPERATOR "Administrator"
*FILE_PART_ID "MEAS_KHP2_00061"
*FILE_SAMPLE " "
*FILE_TYPE "RAS_RAW"
*FILE_USERGROUP "System Manager"
*FILE_VERSION "1.0000000000"
*HW_ATTACHMENT_ID "ATT0021"
*HW_ATTACHMENT_NAME "XY-20mm|XY-20mm"
*HW_COUNTER_ID-0 "CUT0041"
*HW_COUNTER_ID-1 "CUT0051"
*HW_COUNTER_ID-2 "CUT0020"
*HW_COUNTER_ID-3 "CSL0021"
*HW_COUNTER_ID-4 "CMC0021"
*HW_COUNTER_NAME-0 "D/teX Ultra 250|D/teX Ultra 250"
*HW_COUNTER_NAME-1 "HyPix 3000(H)|HyPix 3000(H)"
*HW_COUNTER_NAME-2 "None|None"
*HW_COUNTER_NAME-3 "BBM|BBM"
*HW_COUNTER_NAME-4 "検出器モノクロメータ|Detector monochromator"
*HW_COUNTER_SELECT_NAME "HyPix 3000(H)|HyPix 3000(H)"
*HW_GONIOMETER_ID "GON0024"
*HW_GONIOMETER_NAME "SmartLab(In-plane)|SmartLab(In-plane)"
*HW_GONIOMETER_RADIUS-0 "90.0"
*HW_GONIOMETER_RADIUS-1 "114.0"
*HW_GONIOMETER_RADIUS-2 "190.0"
*HW_GONIOMETER_RADIUS-3 "300.0"
*HW_GONIOMETER_RADIUS-4 "187.0"
*HW_GONIOMETER_RADIUS-5 "300.0"
*HW_GONIOMETER_RADIUS-6 "113.0"
*HW_GONIOMETER_RADIUS-7 "331.0"
*HW_I_OPT_ID-0 "CBO0021"
*HW_I_OPT_ID-1 "ICR0021"
*HW_I_OPT_ID-2 "ISL0021"
*HW_I_OPT_ID-3 "ISO0021"
*HW_I_OPT_ID-4 "IAD0021"
*HW_I_OPT_ID-5 "IPR0001"
*HW_I_OPT_NAME-0 "CBOユニット|CBO unit"
*HW_I_OPT_NAME-1 "標準入射光学ユニット|Standard incident optical unit"
*HW_I_OPT_NAME-2 "標準入射スリットボックス|Standard incident slit box"
*HW_I_OPT_NAME-3 "入射平行スリット|Incident parallel slit"
*HW_I_OPT_NAME-4 "長手制限スリット|Length limiting slit"
*HW_I_OPT_NAME-5 "None|None"
*HW_R_ATTENUATER_AUTOMODE "0"
*HW_R_OPT_ID-0 "RSS0022"
*HW_R_OPT_ID-1 "RCR0022"
*HW_R_OPT_ID-2 "RSO0021"
*HW_R_OPT_ID-3 "RRS0022"
*HW_R_OPT_ID-4 "ATN0020"
*HW_R_OPT_ID-5 "RFL0021"
*HW_R_OPT_ID-6 "RAD0021"
*HW_R_OPT_NAME-0 "受光スリットボックス1(Zr軸付)|Receiving slit box # 1 (w/ Zr Axis)"
*HW_R_OPT_NAME-1 "標準受光光学ユニット1|Standard receiving unit # 1"
*HW_R_OPT_NAME-2 "標準受光光学ユニット2|Standard receiving optical unit # 2"
*HW_R_OPT_NAME-3 "仮想受光スリット2|Virtual receiving slit #2"
*HW_R_OPT_NAME-4 "無し|None"
*HW_R_OPT_NAME-5 "Cu Kβ|Cu K-beta"
*HW_R_OPT_NAME-6 "調整用受光スリット|Alignment receiving slit"
*HW_SAMPLE_HOLDER_ID "SMP0021"
*HW_SAMPLE_HOLDER_NAME "χφZクレードル|Chi phi Z cradle"
*HW_XG_CURRENT_MAX "40"
*HW_XG_CURRENT_MIN "2"
*HW_XG_CURRENT_RESOLUTION "1"
*HW_XG_CURRENT_UNIT "mA"
*HW_XG_FOCUS "0.4mm x 8mm"
*HW_XG_FOCUS_TYPE "Fine"
*HW_XG_ID "1200"
*HW_XG_NAME "3kW 封入管(ID:1200)|3kW Sealed tube(ID:1200)"
*HW_XG_TARGET_ATOMIC_NUMBER "29.0000000000"
*HW_XG_TARGET_NAME "Cu"
*HW_XG_TYPE "Hermetic"
*HW_XG_VOLTAGE_MAX "40"
*HW_XG_VOLTAGE_MIN "20"
*HW_XG_VOLTAGE_RESOLUTION "1"
*HW_XG_VOLTAGE_UNIT "kV"
*HW_XG_WATT_MAX "1.500"
*HW_XG_WATT_UNIT "kW"
*HW_XG_WAVE_LENGTH_ALPHA1 "1.540593"
*HW_XG_WAVE_LENGTH_ALPHA2 "1.544414"
*HW_XG_WAVE_LENGTH_BETA "1.392250"
*MEAS_COND_AXIS_NAME-0 "Theta/2-Theta"
*MEAS_COND_AXIS_NAME-1 "2-Theta"
*MEAS_COND_AXIS_NAME-2 "Omega"
*MEAS_COND_AXIS_NAME-3 "Chi"
*MEAS_COND_AXIS_NAME-4 "Phi"
*MEAS_COND_AXIS_NAME-5 "Z"
*MEAS_COND_AXIS_NAME-6 "X"
*MEAS_COND_AXIS_NAME-7 "Y"
*MEAS_COND_AXIS_NAME-8 "2-Theta/Omega"
*MEAS_COND_AXIS_NAME-9 "2-ThetaChi"
*MEAS_COND_AXIS_NAME-10 "2-ThetaChi/Phi"
*MEAS_COND_AXIS_NAME-11 "Alpha"
*MEAS_COND_AXIS_NAME-12 "Beta"
*MEAS_COND_AXIS_NAME-13 "Theta_s"
*MEAS_COND_AXIS_NAME-14 "Theta_d"
*MEAS_COND_AXIS_NAME-15 "Ts"
*MEAS_COND_AXIS_NAME-16 "CBO selection slit"
*MEAS_COND_AXIS_NAME-17 "M"
*MEAS_COND_AXIS_NAME-18 "Incident parallel slit"
*MEAS_COND_AXIS_NAME-19 "Incident slit"
*MEAS_COND_AXIS_NAME-20 ""
*MEAS_COND_AXIS_NAME-21 "Zs"
*MEAS_COND_AXIS_NAME-22 "Incident optical device"
*MEAS_COND_AXIS_NAME-23 "Omega_m"
*MEAS_COND_AXIS_NAME-24 "Length limiting slit"
*MEAS_COND_AXIS_NAME-25 "Center slit"
*MEAS_COND_AXIS_NAME-26 "Filter"
*MEAS_COND_AXIS_NAME-27 "Receiving slit # 1"
*MEAS_COND_AXIS_NAME-28 "Receiving slit # 2"
*MEAS_COND_AXIS_NAME-29 "Receiving optical device"
*MEAS_COND_AXIS_NAME-30 "Receiving parallel slit"
*MEAS_COND_AXIS_NAME-31 "Alignment receiving slit"
*MEAS_COND_AXIS_NAME-32 ""
*MEAS_COND_AXIS_NAME-33 ""
*MEAS_COND_AXIS_NAME-34 "Zd"
*MEAS_COND_AXIS_NAME-35 "Attenuator"
*MEAS_COND_AXIS_NAME-36 "Diffracted beam monochromator"
*MEAS_COND_AXIS_NAME-37 "Monochromator slit"
*MEAS_COND_AXIS_NAME-38 "2-ThetaB"
*MEAS_COND_AXIS_NAME-39 ""
*MEAS_COND_AXIS_NAME-40 ""
*MEAS_COND_AXIS_NAME-41 "Zr"
*MEAS_COND_AXIS_NAME-42 "Primary beam"
*MEAS_COND_AXIS_NAME_INTERNAL-0 "TwoThetaTheta"
*MEAS_COND_AXIS_NAME_INTERNAL-1 "TwoTheta"
*MEAS_COND_AXIS_NAME_INTERNAL-2 "Omega"
*MEAS_COND_AXIS_NAME_INTERNAL-3 "Chi"
*MEAS_COND_AXIS_NAME_INTERNAL-4 "Phi"
*MEAS_COND_AXIS_NAME_INTERNAL-5 "Z"
*MEAS_COND_AXIS_NAME_INTERNAL-6 "X"
*MEAS_COND_AXIS_NAME_INTERNAL-7 "Y"
*MEAS_COND_AXIS_NAME_INTERNAL-8 "TwoThetaOmega"
*MEAS_COND_AXIS_NAME_INTERNAL-9 "TwoThetaChi"
*MEAS_COND_AXIS_NAME_INTERNAL-10 "TwoThetaChiPhi"
*MEAS_COND_AXIS_NAME_INTERNAL-11 "Alpha"
*MEAS_COND_AXIS_NAME_INTERNAL-12 "Beta"
*MEAS_COND_AXIS_NAME_INTERNAL-13 "ThetaS"
*MEAS_COND_AXIS_NAME_INTERNAL-14 "ThetaD"
*MEAS_COND_AXIS_NAME_INTERNAL-15 "Ts"
*MEAS_COND_AXIS_NAME_INTERNAL-16 "CBO"
*MEAS_COND_AXIS_NAME_INTERNAL-17 "CBO-M"
*MEAS_COND_AXIS_NAME_INTERNAL-18 "IncidentSollerSlit"
*MEAS_COND_AXIS_NAME_INTERNAL-19 "IncidentSlitBox"
*MEAS_COND_AXIS_NAME_INTERNAL-20 "IncidentSlitBox-_Axis"
*MEAS_COND_AXIS_NAME_INTERNAL-21 "Zs"
*MEAS_COND_AXIS_NAME_INTERNAL-22 "IncidentMonochromator"
*MEAS_COND_AXIS_NAME_INTERNAL-23 "IncidentMonochromator-OmegaM"
*MEAS_COND_AXIS_NAME_INTERNAL-24 "IncidentAxdSlit"
*MEAS_COND_AXIS_NAME_INTERNAL-25 "CenterSlit"
*MEAS_COND_AXIS_NAME_INTERNAL-26 "Filter"
*MEAS_COND_AXIS_NAME_INTERNAL-27 "ReceivingSlitBox1"
*MEAS_COND_AXIS_NAME_INTERNAL-28 "ReceivingSlitBox2"
*MEAS_COND_AXIS_NAME_INTERNAL-29 "ReceivingOptics"
*MEAS_COND_AXIS_NAME_INTERNAL-30 "ReceivingSollerSlit"
*MEAS_COND_AXIS_NAME_INTERNAL-31 "ReceivingAxdSlit"
*MEAS_COND_AXIS_NAME_INTERNAL-32 "ReceivingSlitBox1-_Axis"
*MEAS_COND_AXIS_NAME_INTERNAL-33 "ReceivingSlitBox2-_Axis"
*MEAS_COND_AXIS_NAME_INTERNAL-34 "ReceivingSlitBox2-Zd"
*MEAS_COND_AXIS_NAME_INTERNAL-35 "Attenuator"
*MEAS_COND_AXIS_NAME_INTERNAL-36 "CounterMonochromator"
*MEAS_COND_AXIS_NAME_INTERNAL-37 "CounterSlit"
*MEAS_COND_AXIS_NAME_INTERNAL-38 "TwoThetaB"
*MEAS_COND_AXIS_NAME_INTERNAL-39 "AlphaR"
*MEAS_COND_AXIS_NAME_INTERNAL-40 "BetaR"
*MEAS_COND_AXIS_NAME_INTERNAL-41 "ReceivingSlitBox1-Zr"
*MEAS_COND_AXIS_NAME_INTERNAL-42 "IncidentPrimary"
*MEAS_COND_AXIS_NAME_MAGICNO-0 "83951616.0000000000"
*MEAS_COND_AXIS_NAME_MAGICNO-1 "268632064.0000000000"
*MEAS_COND_AXIS_NAME_MAGICNO-2 "268500992.0000000000"
*MEAS_COND_AXIS_NAME_MAGICNO-3 "268500992.0000000000"
*MEAS_COND_AXIS_NAME_MAGICNO-4 "268500992.0000000000"
*MEAS_COND_AXIS_NAME_MAGICNO-5 "285278208.0000000000"
*MEAS_COND_AXIS_NAME_MAGICNO-6 "268500992.0000000000"
*MEAS_COND_AXIS_NAME_MAGICNO-7 "268500992.0000000000"
*MEAS_COND_AXIS_NAME_MAGICNO-8 "83951616.0000000000"
*MEAS_COND_AXIS_NAME_MAGICNO-9 "268632064.0000000000"
*MEAS_COND_AXIS_NAME_MAGICNO-10 "83951616.0000000000"
*MEAS_COND_AXIS_NAME_MAGICNO-11 "17039360.0000000000"
*MEAS_COND_AXIS_NAME_MAGICNO-12 "17039360.0000000000"
*MEAS_COND_AXIS_NAME_MAGICNO-13 "131072.0000000000"
*MEAS_COND_AXIS_NAME_MAGICNO-14 "131072.0000000000"
*MEAS_COND_AXIS_NAME_MAGICNO-15 "318898176.0000000000"
*MEAS_COND_AXIS_NAME_MAGICNO-16 "20971521.0000000000"
*MEAS_COND_AXIS_NAME_MAGICNO-17 "285343744.0000000000"
*MEAS_COND_AXIS_NAME_MAGICNO-18 "20971521.0000000000"
*MEAS_COND_AXIS_NAME_MAGICNO-19 "22020097.0000000000"
*MEAS_COND_AXIS_NAME_MAGICNO-20 "25165824.0000000000"
*MEAS_COND_AXIS_NAME_MAGICNO-21 "318898176.0000000000"
*MEAS_COND_AXIS_NAME_MAGICNO-22 "20971521.0000000000"
*MEAS_COND_AXIS_NAME_MAGICNO-23 "285343744.0000000000"
*MEAS_COND_AXIS_NAME_MAGICNO-24 "20971521.0000000000"
*MEAS_COND_AXIS_NAME_MAGICNO-25 "20971521.0000000000"
*MEAS_COND_AXIS_NAME_MAGICNO-26 "20971521.0000000000"
*MEAS_COND_AXIS_NAME_MAGICNO-27 "23068673.0000000000"
*MEAS_COND_AXIS_NAME_MAGICNO-28 "23068673.0000000000"
*MEAS_COND_AXIS_NAME_MAGICNO-29 "20971521.0000000000"
*MEAS_COND_AXIS_NAME_MAGICNO-30 "20971521.0000000000"
*MEAS_COND_AXIS_NAME_MAGICNO-31 "20971521.0000000000"
*MEAS_COND_AXIS_NAME_MAGICNO-32 "25165824.0000000000"
*MEAS_COND_AXIS_NAME_MAGICNO-33 "25165824.0000000000"
*MEAS_COND_AXIS_NAME_MAGICNO-34 "285343744.0000000000"
*MEAS_COND_AXIS_NAME_MAGICNO-35 "0.0000000000"
*MEAS_COND_AXIS_NAME_MAGICNO-36 "20971521.0000000000"
*MEAS_COND_AXIS_NAME_MAGICNO-37 "20971521.0000000000"
*MEAS_COND_AXIS_NAME_MAGICNO-38 "17039360.0000000000"
*MEAS_COND_AXIS_NAME_MAGICNO-39 "8388608.0000000000"
*MEAS_COND_AXIS_NAME_MAGICNO-40 "8388608.0000000000"
*MEAS_COND_AXIS_NAME_MAGICNO-41 "285343744.0000000000"
*MEAS_COND_AXIS_NAME_MAGICNO-42 "20971521.0000000000"
*MEAS_COND_AXIS_OFFSET-0 "-"
*MEAS_COND_AXIS_OFFSET-1 "0.9081000000"
*MEAS_COND_AXIS_OFFSET-2 "-0.2665000000"
*MEAS_COND_AXIS_OFFSET-3 "0.0000000000"
*MEAS_COND_AXIS_OFFSET-4 "0.0000000000"
*MEAS_COND_AXIS_OFFSET-5 "-"
*MEAS_COND_AXIS_OFFSET-6 "0.0000000000"
*MEAS_COND_AXIS_OFFSET-7 "0.0000000000"
*MEAS_COND_AXIS_OFFSET-8 "-"
*MEAS_COND_AXIS_OFFSET-9 "0.0000000000"
*MEAS_COND_AXIS_OFFSET-10 "-"
*MEAS_COND_AXIS_OFFSET-11 "-"
*MEAS_COND_AXIS_OFFSET-12 "-"
*MEAS_COND_AXIS_OFFSET-13 "-0.2665000000"
*MEAS_COND_AXIS_OFFSET-14 "1.1746000000"
*MEAS_COND_AXIS_OFFSET-15 "-"
*MEAS_COND_AXIS_OFFSET-16 "-"
*MEAS_COND_AXIS_OFFSET-17 "-"
*MEAS_COND_AXIS_OFFSET-18 "-"
*MEAS_COND_AXIS_OFFSET-19 "-"
*MEAS_COND_AXIS_OFFSET-20 "-"
*MEAS_COND_AXIS_OFFSET-21 "-"
*MEAS_COND_AXIS_OFFSET-22 "-"
*MEAS_COND_AXIS_OFFSET-23 "-"
*MEAS_COND_AXIS_OFFSET-24 "-"
*MEAS_COND_AXIS_OFFSET-25 "-"
*MEAS_COND_AXIS_OFFSET-26 "-"
*MEAS_COND_AXIS_OFFSET-27 "-"
*MEAS_COND_AXIS_OFFSET-28 "-"
*MEAS_COND_AXIS_OFFSET-29 "-"
*MEAS_COND_AXIS_OFFSET-30 "-"
*MEAS_COND_AXIS_OFFSET-31 "-"
*MEAS_COND_AXIS_OFFSET-32 "-"
*MEAS_COND_AXIS_OFFSET-33 "-"
*MEAS_COND_AXIS_OFFSET-34 "-"
*MEAS_COND_AXIS_OFFSET-35 "-"
*MEAS_COND_AXIS_OFFSET-36 "-"
*MEAS_COND_AXIS_OFFSET-37 "-"
*MEAS_COND_AXIS_OFFSET-38 "-"
*MEAS_COND_AXIS_OFFSET-39 "0.0000000000"
*MEAS_COND_AXIS_OFFSET-40 "0.0000000000"
*MEAS_COND_AXIS_OFFSET-41 "-"
*MEAS_COND_AXIS_OFFSET-42 "-"
*MEAS_COND_AXIS_POSITION-0 "40.0000000000"
*MEAS_COND_AXIS_POSITION-1 "40.0000000000"
*MEAS_COND_AXIS_POSITION-2 "20.0000000000"
*MEAS_COND_AXIS_POSITION-3 "0.0000000000"
*MEAS_COND_AXIS_POSITION-4 "0.0000000000"
*MEAS_COND_AXIS_POSITION-5 "-2.0050000000"
*MEAS_COND_AXIS_POSITION-6 "3.0990000000"
*MEAS_COND_AXIS_POSITION-7 "0.4590000000"
*MEAS_COND_AXIS_POSITION-8 "40.0000000000"
*MEAS_COND_AXIS_POSITION-9 "0.0000000000"
*MEAS_COND_AXIS_POSITION-10 "0.0000000000"
*MEAS_COND_AXIS_POSITION-11 "90.0000000000"
*MEAS_COND_AXIS_POSITION-12 "0.0000000000"
*MEAS_COND_AXIS_POSITION-13 "20.0000000000"
*MEAS_COND_AXIS_POSITION-14 "20.0000000000"
*MEAS_COND_AXIS_POSITION-15 "-5.4488800000"
*MEAS_COND_AXIS_POSITION-16 "PB"
*MEAS_COND_AXIS_POSITION-17 "0.0000000000"
*MEAS_COND_AXIS_POSITION-18 "Soller_slit_2.5deg_s"
*MEAS_COND_AXIS_POSITION-19 "1.000mm"
*MEAS_COND_AXIS_POSITION-20 "1.0000000000"
*MEAS_COND_AXIS_POSITION-21 "-1.2250000000"
*MEAS_COND_AXIS_POSITION-22 "Ge(220)x2"
*MEAS_COND_AXIS_POSITION-23 "0.0000000000"
*MEAS_COND_AXIS_POSITION-24 "0.5mm"
*MEAS_COND_AXIS_POSITION-25 "None"
*MEAS_COND_AXIS_POSITION-26 "None"
*MEAS_COND_AXIS_POSITION-27 "20.000mm"
*MEAS_COND_AXIS_POSITION-28 "38.500mm"
*MEAS_COND_AXIS_POSITION-29 "PSA_open"
*MEAS_COND_AXIS_POSITION-30 "Soller_slit_2.5deg"
*MEAS_COND_AXIS_POSITION-31 "None"
*MEAS_COND_AXIS_POSITION-32 "20.0000000000"
*MEAS_COND_AXIS_POSITION-33 "38.5000000000"
*MEAS_COND_AXIS_POSITION-34 "0.0000000000"
*MEAS_COND_AXIS_POSITION-35 "-"
*MEAS_COND_AXIS_POSITION-36 "No_unit"
*MEAS_COND_AXIS_POSITION-37 "None"
*MEAS_COND_AXIS_POSITION-38 "40.0000000000"
*MEAS_COND_AXIS_POSITION-39 "0.0000000000"
*MEAS_COND_AXIS_POSITION-40 "0.0000000000"
*MEAS_COND_AXIS_POSITION-41 "0.1315600000"
*MEAS_COND_AXIS_POSITION-42 "None"
*MEAS_COND_AXIS_UNIT-0 "deg"
*MEAS_COND_AXIS_UNIT-1 "deg"
*MEAS_COND_AXIS_UNIT-2 "deg"
*MEAS_COND_AXIS_UNIT-3 "deg"
*MEAS_COND_AXIS_UNIT-4 "deg"
*MEAS_COND_AXIS_UNIT-5 "mm"
*MEAS_COND_AXIS_UNIT-6 "mm"
*MEAS_COND_AXIS_UNIT-7 "mm"
*MEAS_COND_AXIS_UNIT-8 "deg"
*MEAS_COND_AXIS_UNIT-9 "deg"
*MEAS_COND_AXIS_UNIT-10 "deg"
*MEAS_COND_AXIS_UNIT-11 "deg"
*MEAS_COND_AXIS_UNIT-12 "deg"
*MEAS_COND_AXIS_UNIT-13 "deg"
*MEAS_COND_AXIS_UNIT-14 "deg"
*MEAS_COND_AXIS_UNIT-15 "mm"
*MEAS_COND_AXIS_UNIT-16 ""
*MEAS_COND_AXIS_UNIT-17 "pulse"
*MEAS_COND_AXIS_UNIT-18 ""
*MEAS_COND_AXIS_UNIT-19 ""
*MEAS_COND_AXIS_UNIT-20 "mm"
*MEAS_COND_AXIS_UNIT-21 "mm"
*MEAS_COND_AXIS_UNIT-22 ""
*MEAS_COND_AXIS_UNIT-23 "pulse"
*MEAS_COND_AXIS_UNIT-24 ""
*MEAS_COND_AXIS_UNIT-25 ""
*MEAS_COND_AXIS_UNIT-26 ""
*MEAS_COND_AXIS_UNIT-27 ""
*MEAS_COND_AXIS_UNIT-28 ""
*MEAS_COND_AXIS_UNIT-29 ""
*MEAS_COND_AXIS_UNIT-30 ""
*MEAS_COND_AXIS_UNIT-31 ""
*MEAS_COND_AXIS_UNIT-32 "mm"
*MEAS_COND_AXIS_UNIT-33 "mm"
*MEAS_COND_AXIS_UNIT-34 "mm"
*MEAS_COND_AXIS_UNIT-35 ""
*MEAS_COND_AXIS_UNIT-36 ""
*MEAS_COND_AXIS_UNIT-37 ""
*MEAS_COND_AXIS_UNIT-38 "deg"
*MEAS_COND_AXIS_UNIT-39 "deg"
*MEAS_COND_AXIS_UNIT-40 "deg"
*MEAS_COND_AXIS_UNIT-41 "mm"
*MEAS_COND_AXIS_UNIT-42 ""
*MEAS_COND_COUNTER_CNTLOSS_CORR "0.0000000000"
*MEAS_COND_COUNTER_TAUDIFF "0.0000000000"
*MEAS_COND_COUNTER_TAUINT "0.0000000000"
*MEAS_COND_COUNTER_TEMP_CONDITION "NORMAL"
*MEAS_COND_IRRADIATION_MODE "OFF"
*MEAS_COND_IRRADIATION_WIDTH ""
*MEAS_COND_OPT_ATTR "High resolution parallel beam Ge(220)x2/RS"
*MEAS_COND_OPT_NAME "@High resolution PB-Ge(220)x2"
*MEAS_COND_UNSYMMETRIC_MODE "OFF"
*MEAS_COND_XG_CURRENT "30.0000000000"
*MEAS_COND_XG_VOLTAGE "40.0000000000"
*MEAS_COND_XG_WAVE_TYPE "Ka1"
*MEAS_DATA_COUNT "8000.0000000000"
*MEAS_SCAN_AXIS_X "Theta/2-Theta"
*MEAS_SCAN_AXIS_X_INTERNAL "TwoThetaTheta"
*MEAS_SCAN_END_TIME "04/13/22 13:10:34"
*MEAS_SCAN_MODE "CONTINUOUS"
*MEAS_SCAN_MONITOR "0"
*MEAS_SCAN_RESOLUTION_X "0.0002"
*MEAS_SCAN_SPEED "0.503240"
*MEAS_SCAN_SPEED_UNIT "deg/min"
*MEAS_SCAN_SPEED_USER "0.5"
*MEAS_SCAN_START "40.0000000000"
*MEAS_SCAN_START_TIME "04/13/22 10:15:44"
*MEAS_SCAN_STEP "0.0100000000"
*MEAS_SCAN_STOP "119.9900000000"
*MEAS_SCAN_UNIT_X "deg"
*MEAS_SCAN_UNIT_Y "counts"
*RAS_HEADER_END
*RAS_INT_START
40.0000 0.0000 1.0000
40.0600 1.1131 1.0000
40.1200 0.4354 1.0000
40.1800 2.3977 1.0000
40.2400 1.9059 1.0000
40.3000 0.7126 1.0000
40.3600 0.1434 1.0000
40.4200 0.5936 1.0000
40.4800 0.0000 1.0000
40.5400 0.9073 1.0000
40.6000 0.0000 1.0000
40.6600 0.0000 1.0000
40.7200 0.0000 1.0000
40.7800 1.3163 1.0000
40.8400 2.5046 1.0000
40.9000 0.0000 1.0000
40.9600 0.0000 1.0000
41.0200 1.0598 1.0000
41.0800 1.0378 1.0000
41.1400 0.0000 1.0000
41.2000 3.0065 1.0000
41.2600 1.3120 1.0000
41.3200 1.9669 1.0000
41.3800 0.0000 1.0000
41.4400 0.8865 1.0000
41.5000 1.7124 1.0000
41.5600 1.8391 1.0000
41.6200 0.0000 1.0000
41.6800 1.1179 1.0000
41.7400 0.9679 1.0000
41.8000 0.9612 1.0000
41.8600 0.2150 1.0000
41.9200 0.0000 1.0000
41.9800 0.2312 1.0000
42.0400 0.2744 1.0000
42.1000 0.0000 1.0000
42.1600 1.1014 1.0000
42.2200 0.6086 1.0000
42.2800 0.0000 1.0000
42.3400 0.0000 1.0000
42.4000 1.9101 1.0000
42.4600 0.7283 1.0000
42.5200 0.6391 1.0000
42.5800 0.9977 1.0000
42.6400 0.9582 1.0000
42.7000 1.1069 1.0000
42.7600 0.0000 1.0000
42.8200 0.0000 1.0000
42.8800 0.0000 1.0000
42.9400 0.0000 1.0000
43.0000 0.9832 1.0000
43.0600 0.0000 1.0000
43.1200 3.9551 1.0000
43.1800 1.1267 1.0000
43.2400 0.9395 1.0000
43.3000 0.9820 1.0000
43.3600 0.2565 1.0000
43.4200 2.1665 1.0000
43.4800 0.0000 1.0000
43.5400 0.9369 1.0000
43.6000 0.0000 1.0000
43.6600 1.0102 1.0000
43.7200 0.0000 1.0000
43.7800 0.0000 1.0000
43.8400 0.0000 1.0000
43.9000 0.0000 1.0000
43.9600 0.9102 1.0000
44.0200 1.1979 1.0000
44.0800 1.0927 1.0000
44.1400 0.6308 1.0000
44.2000 0.8818 1.0000
44.2600 0.0000 1.0000
44.3200 1.2868 1.0000
44.3800 1.9305 1.0000
44.4400 3.2211 1.0000
44.5000 10.4873 1.0000
44.5600 17.6410 1.0000
44.6200 9.0093 1.0000
44.6800 3.0588 1.0000
44.7400 2.1063 1.0000
44.8000 1.9250 1.0000
44.8600 0.6993 1.0000
44.9200 1.1741 1.0000
44.9800 0.5309 1.0000
45.0400 0.9827 1.0000
45.1000 1.6380 1.0000
45.1600 0.0000 1.0000
45.2200 0.1187 1.0000
45.2800 0.0000 1.0000
45.3400 0.0000 1.0000
45.4000 0.0000 1.0000
45.4600 0.0390 1.0000
45.5200 1.6809 1.0000
45.5800 1.8399 1.0000
45.6400 0.9714 1.0000
45.7000 0.3546 1.0000
45.7600 0.1714 1.0000
45.8200 0.0000 1.0000
45.8800 1.1520 1.0000
45.9400 0.9629 1.0000
46.0000 2.9617 1.0000
46.0600 0.0000 1.0000
46.1200 1.5725 1.0000
46.1800 1.3164 1.0000
46.2400 0.0000 1.0000
46.3000 0.0000 1.0000
46.3600 2.0519 1.0000
46.4200 0.0000 1.0000
46.4800 0.9902 1.0000
46.5400 0.0000 1.0000
46.6000 0.0000 1.0000
46.6600 0.0000 1.0000
46.7200 1.0771 1.0000
46.7800 0.5442 1.0000
46.8400 0.9760 1.0000
46.9000 0.0000 1.0000
46.9600 2.0409 1.0000
47.0200 0.0000 1.0000
47.0800 0.7372 1.0000
47.1400 0.9386 1.0000
47.2000 1.4359 1.0000
47.2600 0.0896 1.0000
47.3200 0.0000 1.0000
47.3800 1.7442 1.0000
47.4400 0.3097 1.0000
47.5000 0.3281 1.0000
47.5600 2.3147 1.0000
47.6200 2.8612 1.0000
47.6800 0.0515 1.0000
47.7400 0.4713 1.0000
47.8000 0.5033 1.0000
47.8600 1.7767 1.0000
47.9200 1.0940 1.0000
47.9800 1.2324 1.0000
48.0400 0.0000 1.0000
48.1000 0.0000 1.0000
48.1600 0.5620 1.0000
48.2200 0.0000 1.0000
48.2800 0.9931 1.0000
48.3400 0.0000 1.0000
48.4000 0.0000 1.0000
48.4600 0.9960 1.0000
48.5200 0.0000 1.0000
48.5800 0.0000 1.0000
48.6400 0.2032 1.0000
48.7000 0.4153 1.0000
48.7600 1.1948 1.0000
48.8200 0.0000 1.0000
48.8800 0.0000 1.0000
48.9400 0.0000 1.0000
49.0000 0.0000 1.0000
49.0600 1.9933 1.0000
49.1200 0.0000 1.0000
49.1800 0.0000 1.0000
49.2400 0.0000 1.0000
49.3000 0.7273 1.0000
49.3600 0.0000 1.0000
49.4200 0.0000 1.0000
49.4800 1.9373 1.0000
49.5400 1.5107 1.0000
49.6000 1.2609 1.0000
49.6600 0.0000 1.0000
49.7200 0.7842 1.0000
49.7800 0.8390 1.0000
49.8400 1.4117 1.0000
49.9000 0.0000 1.0000
49.9600 1.5417 1.0000
50.0200 2.9847 1.0000
50.0800 0.3989 1.0000
50.1400 0.8321 1.0000
50.2000 0.0000 1.0000
50.2600 0.0000 1.0000
50.3200 0.0000 1.0000
50.3800 0.0000 1.0000
50.4400 0.0000 1.0000
50.5000 0.0000 1.0000
50.5600 1.0263 1.0000
50.6200 0.0000 1.0000
50.6800 0.5729 1.0000
50.7400 0.3352 1.0000
50.8000 2.0577 1.0000
50.8600 0.9986 1.0000
50.9200 1.4921 1.0000
50.9800 1.0318 1.0000
51.0400 0.0000 1.0000
51.1000 0.0000 1.0000
51.1600 0.2190 1.0000
51.2200 1.7219 1.0000
51.2800 0.0000 1.0000
51.3400 1.1118 1.0000
51.4000 0.9536 1.0000
51.4600 0.3656 1.0000
51.5200 0.0000 1.0000
51.5800 0.2259 1.0000
51.6400 0.6865 1.0000
51.7000 1.0591 1.0000
51.7600 0.0000 1.0000
51.8200 0.0000 1.0000
51.8800 1.0133 1.0000
51.9400 0.2432 1.0000
52.0000 0.8276 1.0000
52.0600 1.0104 1.0000
52.1200 0.0000 1.0000
52.1800 1.0701 1.0000
52.2400 0.0086 1.0000
52.3000 0.0000 1.0000
52.3600 0.2202 1.0000
52.4200 0.2984 1.0000
52.4800 0.3452 1.0000
52.5400 0.9344 1.0000
52.6000 1.0640 1.0000
52.6600 0.0514 1.0000
52.7200 0.9294 1.0000
52.7800 0.0000 1.0000
52.8400 0.0000 1.0000
52.9000 0.0000 1.0000
52.9600 0.9780 1.0000
53.0200 0.0000 1.0000
53.0800 0.0922 1.0000
53.1400 1.5027 1.0000
53.2000 0.9032 1.0000
53.2600 0.7087 1.0000
53.3200 0.0000 1.0000
53.3800 1.9219 1.0000
53.4400 0.7857 1.0000
53.5000 1.9511 1.0000
53.5600 0.5646 1.0000
53.6200 0.0000 1.0000
53.6800 0.0000 1.0000
53.7400 0.0000 1.0000
53.8000 0.0000 1.0000
53.8600 1.0247 1.0000
53.9200 0.0000 1.0000
53.9800 0.9535 1.0000
54.0400 1.9934 1.0000
54.1000 1.6757 1.0000
54.1600 1.0157 1.0000
54.2200 0.3020 1.0000
54.2800 0.7582 1.0000
54.3400 0.8950 1.0000
54.4000 0.0000 1.0000
54.4600 0.0000 1.0000
54.5200 0.6203 1.0000
54.5800 0.0000 1.0000
54.6400 0.0000 1.0000
54.7000 0.6504 1.0000
54.7600 0.4352 1.0000
54.8200 0.0000 1.0000
54.8800 0.9900 1.0000
54.9400 0.0000 1.0000
55.0000 0.0000 1.0000
55.0600 0.0000 1.0000
55.1200 0.6585 1.0000
55.1800 0.9814 1.0000
55.2400 0.4013 1.0000
55.3000 0.0000 1.0000
55.3600 1.5336 1.0000
55.4200 1.9851 1.0000
55.4800 0.0000 1.0000
55.5400 0.0000 1.0000
55.6000 1.5965 1.0000
55.6600 0.7071 1.0000
55.7200 1.9837 1.0000
55.7800 1.1475 1.0000
55.8400 0.0000 1.0000
55.9000 1.9957 1.0000
55.9600 1.0486 1.0000
56.0200 0.0000 1.0000
56.0800 0.0000 1.0000
56.1400 0.1787 1.0000
56.2000 1.5107 1.0000
56.2600 0.0000 1.0000
56.3200 2.4714 1.0000
56.3800 0.9278 1.0000
56.4400 0.7568 1.0000
56.5000 1.8468 1.0000
56.5600 0.2232 1.0000
56.6200 0.4184 1.0000
56.6800 0.0917 1.0000
56.7400 1.5116 1.0000
56.8000 0.9456 1.0000
56.8600 0.7385 1.0000
56.9200 0.0000 1.0000
56.9800 0.5392 1.0000
57.0400 0.0000 1.0000
57.1000 0.1276 1.0000
57.1600 0.5723 1.0000
57.2200 0.9475 1.0000
57.2800 0.0000 1.0000
57.3400 1.1160 1.0000
57.4000 0.0000 1.0000
57.4600 1.9320 1.0000
57.5200 0.9913 1.0000
57.5800 0.9363 1.0000
57.6400 0.0000 1.0000
57.7000 0.4861 1.0000
57.7600 0.1919 1.0000
57.8200 2.2080 1.0000
57.8800 0.9805 1.0000
57.9400 1.0195 1.0000
58.0000 0.0000 1.0000
58.0600 0.0739 1.0000
58.1200 0.0000 1.0000
58.1800 0.9385 1.0000
58.2400 0.9522 1.0000
58.3000 0.0000 1.0000
58.3600 0.0000 1.0000
58.4200 0.0000 1.0000
58.4800 1.1622 1.0000
58.5400 1.5798 1.0000
58.6000 0.0000 1.0000
58.6600 0.0000 1.0000
58.7200 0.0000 1.0000
58.7800 0.2637 1.0000
58.8400 0.0000 1.0000
58.9000 0.9930 1.0000
58.9600 0.0000 1.0000
59.0200 0.0000 1.0000
59.0800 0.0000 1.0000
59.1400 0.0000 1.0000
59.2000 0.0000 1.0000
59.2600 0.0000 1.0000
59.3200 0.0000 1.0000
59.3800 2.4340 1.0000
59.4400 2.1512 1.0000
59.5000 0.0000 1.0000
59.5600 0.1836 1.0000
59.6200 1.7317 1.0000
59.6800 0.9706 1.0000
59.7400 0.9547 1.0000
59.8000 1.0036 1.0000
59.8600 0.0000 1.0000
59.9200 0.0000 1.0000
59.9800 0.0000 1.0000
60.0400 1.1037 1.0000
60.1000 1.5913 1.0000
60.1600 0.0000 1.0000
60.2200 0.0000 1.0000
60.2800 1.0398 1.0000
60.3400 0.9216 1.0000
60.4000 0.0000 1.0000
60.4600 1.6566 1.0000
60.5200 1.0601 1.0000
60.5800 2.1053 1.0000
60.6400 0.0000 1.0000
60.7000 1.2128 1.0000
60.7600 0.5983 1.0000
60.8200 1.1449 1.0000
60.8800 0.9699 1.0000
60.9400 0.0000 1.0000
61.0000 1.1269 1.0000
61.0600 0.0000 1.0000
61.1200 0.3795 1.0000
61.1800 0.4658 1.0000
61.2400 0.9865 1.0000
61.3000 0.6128 1.0000
61.3600 0.1611 1.0000
61.4200 0.7410 1.0000
61.4800 0.0000 1.0000
61.5400 0.8306 1.0000
61.6000 0.4578 1.0000
61.6600 2.0176 1.0000
61.7200 3.1033 1.0000
61.7800 1.3978 1.0000
61.8400 0.0000 1.0000
61.9000 0.0000 1.0000
61.9600 1.3690 1.0000
62.0200 1.3038 1.0000
62.0800 0.0000 1.0000
62.1400 1.0033 1.0000
62.2000 0.9574 1.0000
62.2600 0.0000 1.0000
62.3200 1.9776 1.0000
62.3800 3.1115 1.0000
62.4400 0.0000 1.0000
62.5000 0.0000 1.0000
62.5600 0.0000 1.0000
62.6200 0.0000 1.0000
62.6800 1.0081 1.0000
62.7400 1.1333 1.0000
62.8000 1.8437 1.0000
62.8600 0.0000 1.0000
62.9200 1.1787 1.0000
62.9800 1.6424 1.0000
63.0400 2.1214 1.0000
63.1000 0.9425 1.0000
63.1600 1.9895 1.0000
63.2200 0.0000 1.0000
63.2800 0.6117 1.0000
63.3400 1.7729 1.0000
63.4000 0.4148 1.0000
63.4600 1.9519 1.0000
63.5200 0.5670 1.0000
63.5800 0.0000 1.0000
63.6400 0.0000 1.0000
63.7000 0.0000 1.0000
63.7600 0.9729 1.0000
63.8200 0.0000 1.0000
63.8800 0.0000 1.0000
63.9400 0.0000 1.0000
64.0000 1.3496 1.0000
64.0600 0.0000 1.0000
64.1200 0.2224 1.0000
64.1800 1.0378 1.0000
64.2400 0.7494 1.0000
64.3000 0.0000 1.0000
64.3600 1.0915 1.0000
64.4200 0.9875 1.0000
64.4800 0.5992 1.0000
64.5400 0.0000 1.0000
64.6000 0.9859 1.0000
64.6600 0.1004 1.0000
64.7200 0.2049 1.0000
64.7800 1.5988 1.0000
64.8400 2.9267 1.0000
64.9000 6.0600 1.0000
64.9600 0.4649 1.0000
65.0200 2.2970 1.0000
65.0800 1.1209 1.0000
65.1400 0.0000 1.0000
65.2000 7.8750 1.0000
65.2600 3.0153 1.0000
65.3200 0.5387 1.0000
65.3800 1.0214 1.0000
65.4400 0.4270 1.0000
65.5000 2.6204 1.0000
65.5600 2.0436 1.0000
65.6200 0.6892 1.0000
65.6800 0.2796 1.0000
65.7400 1.0205 1.0000
65.8000 0.0000 1.0000
65.8600 0.8966 1.0000
65.9200 0.0000 1.0000
65.9800 1.2452 1.0000
66.0400 0.0000 1.0000
66.1000 1.9974 1.0000
66.1600 0.0000 1.0000
66.2200 1.0180 1.0000
66.2800 0.0000 1.0000
66.3400 0.9820 1.0000
66.4000 0.0000 1.0000
66.4600 0.0000 1.0000
66.5200 1.9582 1.0000
66.5800 0.3027 1.0000
66.6400 0.9948 1.0000
66.7000 0.9783 1.0000
66.7600 0.0000 1.0000
66.8200 1.5355 1.0000
66.8800 0.0000 1.0000
66.9400 0.0000 1.0000
67.0000 0.7087 1.0000
67.0600 0.9788 1.0000
67.1200 1.5188 1.0000
67.1800 2.2439 1.0000
67.2400 0.0000 1.0000
67.3000 0.2387 1.0000
67.3600 0.8404 1.0000
67.4200 0.7532 1.0000
67.4800 0.9315 1.0000
67.5400 0.5074 1.0000
67.6000 0.9592 1.0000
67.6600 0.0000 1.0000
67.7200 0.9136 1.0000
67.7800 1.3258 1.0000
67.8400 0.0000 1.0000
67.9000 0.0000 1.0000
67.9600 0.0000 1.0000
68.0200 1.3574 1.0000
68.0800 0.0000 1.0000
68.1400 0.0000 1.0000
68.2000 0.3538 1.0000
68.2600 0.0000 1.0000
68.3200 0.0000 1.0000
68.3800 0.0000 1.0000
68.4400 1.0656 1.0000
68.5000 0.0000 1.0000
68.5600 0.2674 1.0000
68.6200 0.0000 1.0000
68.6800 0.9091 1.0000
68.7400 0.8155 1.0000
68.8000 0.0000 1.0000
68.8600 1.0567 1.0000
68.9200 1.0057 1.0000
68.9800 1.9186 1.0000
69.0400 1.4091 1.0000
69.1000 2.4707 1.0000
69.1600 0.0000 1.0000
69.2200 0.9890 1.0000
69.2800 1.1334 1.0000
69.3400 0.6313 1.0000
69.4000 0.0298 1.0000
69.4600 0.0000 1.0000
69.5200 0.9722 1.0000
69.5800 0.3099 1.0000
69.6400 0.3127 1.0000
69.7000 0.8642 1.0000
69.7600 0.0000 1.0000
69.8200 0.0000 1.0000
69.8800 0.6376 1.0000
69.9400 0.9293 1.0000
70.0000 0.3494 1.0000
70.0600 0.0000 1.0000
70.1200 0.0000 1.0000
70.1800 1.6994 1.0000
70.2400 0.2034 1.0000
70.3000 0.5600 1.0000
70.3600 0.0000 1.0000
70.4200 1.0571 1.0000
70.4800 0.0000 1.0000
70.5400 0.0000 1.0000
70.6000 0.9841 1.0000
70.6600 3.8646 1.0000
70.7200 1.9655 1.0000
70.7800 0.0027 1.0000
70.8400 0.0000 1.0000
70.9000 0.8233 1.0000
70.9600 0.0000 1.0000
71.0200 1.0738 1.0000
71.0800 0.0000 1.0000
71.1400 0.5144 1.0000
71.2000 0.0565 1.0000
71.2600 0.4552 1.0000
71.3200 2.1580 1.0000
71.3800 0.6869 1.0000
71.4400 0.0000 1.0000
71.5000 0.5556 1.0000
71.5600 1.4789 1.0000
71.6200 0.9942 1.0000
71.6800 1.5577 1.0000
71.7400 2.5074 1.0000
71.8000 2.3666 1.0000
71.8600 0.0000 1.0000
71.9200 2.8841 1.0000
71.9800 1.5041 1.0000
72.0400 0.0000 1.0000
72.1000 0.5708 1.0000
72.1600 0.9385 1.0000
72.2200 0.9728 1.0000
72.2800 0.2467 1.0000
72.3400 0.9758 1.0000
72.4000 0.0000 1.0000
72.4600 0.0000 1.0000
72.5200 0.9574 1.0000
72.5800 0.0000 1.0000
72.6400 0.0000 1.0000
72.7000 1.8307 1.0000
72.7600 1.7838 1.0000
72.8200 0.0000 1.0000
72.8800 1.0952 1.0000
72.9400 0.9815 1.0000
73.0000 0.0478 1.0000
73.0600 1.8946 1.0000
73.1200 2.6540 1.0000
73.1800 0.7122 1.0000
73.2400 0.3180 1.0000
73.3000 0.0000 1.0000
73.3600 0.0000 1.0000
73.4200 0.0000 1.0000
73.4800 1.5494 1.0000
73.5400 1.0714 1.0000
73.6000 1.6552 1.0000
73.6600 0.0000 1.0000
73.7200 1.0114 1.0000
73.7800 0.0000 1.0000
73.8400 0.9774 1.0000
73.9000 1.0907 1.0000
73.9600 0.0000 1.0000
74.0200 0.6692 1.0000
74.0800 0.5246 1.0000
74.1400 0.7595 1.0000
74.2000 1.3532 1.0000
74.2600 0.1593 1.0000
74.3200 1.5372 1.0000
74.3800 0.9313 1.0000
74.4400 0.4513 1.0000
74.5000 1.4217 1.0000
74.5600 0.0000 1.0000
74.6200 0.7529 1.0000
74.6800 3.0826 1.0000
74.7400 0.6223 1.0000
74.8000 0.0000 1.0000
74.8600 0.0000 1.0000
74.9200 0.0000 1.0000
74.9800 0.0000 1.0000
75.0400 1.2431 1.0000
75.1000 0.0000 1.0000
75.1600 0.0000 1.0000
75.2200 1.9526 1.0000
75.2800 1.5480 1.0000
75.3400 0.9740 1.0000
75.4000 0.0000 1.0000
75.4600 0.0000 1.0000
75.5200 0.9691 1.0000
75.5800 0.3922 1.0000
75.6400 0.0000 1.0000
75.7000 0.0000 1.0000
75.7600 1.2043 1.0000
75.8200 1.7180 1.0000
75.8800 2.0622 1.0000
75.9400 0.9870 1.0000
76.0000 0.0000 1.0000
76.0600 1.9475 1.0000
76.1200 0.0000 1.0000
76.1800 0.1156 1.0000
76.2400 0.0000 1.0000
76.3000 0.9436 1.0000
76.3600 1.0503 1.0000
76.4200 0.0000 1.0000
76.4800 0.9356 1.0000
76.5400 1.6187 1.0000
76.6000 0.9722 1.0000
76.6600 1.2133 1.0000
76.7200 0.1659 1.0000
76.7800 0.0000 1.0000
76.8400 1.4732 1.0000
76.9000 0.0000 1.0000
76.9600 0.4608 1.0000
77.0200 0.0000 1.0000
77.0800 0.0000 1.0000
77.1400 0.1560 1.0000
77.2000 2.0921 1.0000
77.2600 0.2683 1.0000
77.3200 0.2645 1.0000
77.3800 0.0000 1.0000
77.4400 0.0000 1.0000
77.5000 0.9827 1.0000
77.5600 0.0000 1.0000
77.6200 1.8522 1.0000
77.6800 0.8552 1.0000
77.7400 0.7652 1.0000
77.8000 1.6639 1.0000
77.8600 0.0000 1.0000
77.9200 0.0000 1.0000
77.9800 1.0300 1.0000
78.0400 1.6331 1.0000
78.1000 0.8791 1.0000
78.1600 1.9725 1.0000
78.2200 0.0000 1.0000
78.2800 1.0089 1.0000
78.3400 1.6039 1.0000
78.4000 0.9769 1.0000
78.4600 1.0242 1.0000
78.5200 1.0471 1.0000
78.5800 2.0355 1.0000
78.6400 0.0000 1.0000
78.7000 0.8349 1.0000
78.7600 1.6510 1.0000
78.8200 0.2170 1.0000
78.8800 0.0000 1.0000
78.9400 1.9491 1.0000
79.0000 0.9887 1.0000
79.0600 0.0000 1.0000
79.1200 0.0000 1.0000
79.1800 0.9642 1.0000
79.2400 0.1387 1.0000
79.3000 1.6114 1.0000
79.3600 0.0000 1.0000
79.4200 0.9778 1.0000
79.4800 3.2607 1.0000
79.5400 2.0542 1.0000
79.6000 0.0000 1.0000
79.6600 0.0000 1.0000
79.7200 3.3127 1.0000
79.7800 0.0465 1.0000
79.8400 1.0297 1.0000
79.9000 0.9656 1.0000
79.9600 0.0000 1.0000
80.0200 0.0000 1.0000
80.0800 0.0000 1.0000
80.1400 0.0000 1.0000
80.2000 1.1327 1.0000
80.2600 4.4405 1.0000
80.3200 3.0994 1.0000
80.3800 1.6850 1.0000
80.4400 0.0000 1.0000
80.5000 0.0000 1.0000
80.5600 1.4516 1.0000
80.6200 0.9640 1.0000
80.6800 0.5232 1.0000
80.7400 0.0000 1.0000
80.8000 0.4365 1.0000
80.8600 0.2470 1.0000
80.9200 0.0000 1.0000
80.9800 0.7508 1.0000
81.0400 0.0000 1.0000
81.1000 0.5398 1.0000
81.1600 1.0034 1.0000
81.2200 0.6501 1.0000
81.2800 1.2665 1.0000
81.3400 0.7477 1.0000
81.4000 0.0000 1.0000
81.4600 1.9889 1.0000
81.5200 0.0000 1.0000
81.5800 0.0386 1.0000
81.6400 0.4506 1.0000
81.7000 2.8497 1.0000
81.7600 1.1075 1.0000
81.8200 0.0000 1.0000
81.8800 0.0000 1.0000
81.9400 0.0000 1.0000
82.0000 0.9616 1.0000
82.0600 1.1139 1.0000
82.1200 1.2317 1.0000
82.1800 3.9135 1.0000
82.2400 8.0989 1.0000
82.3000 2.9559 1.0000
82.3600 1.0627 1.0000
82.4200 0.0000 1.0000
82.4800 0.0000 1.0000
82.5400 0.9648 1.0000
82.6000 0.0000 1.0000
82.6600 0.2476 1.0000
82.7200 3.8587 1.0000
82.7800 1.9551 1.0000
82.8400 1.1016 1.0000
82.9000 2.8389 1.0000
82.9600 0.1273 1.0000
83.0200 0.4610 1.0000
83.0800 0.0000 1.0000
83.1400 0.3161 1.0000
83.2000 0.0000 1.0000
83.2600 0.0000 1.0000
83.3200 0.5980 1.0000
83.3800 1.0568 1.0000
83.4400 0.4902 1.0000
83.5000 0.0000 1.0000
83.5600 1.0143 1.0000
83.6200 0.8114 1.0000
83.6800 0.8770 1.0000
83.7400 0.0000 1.0000
83.8000 0.0947 1.0000
83.8600 1.0904 1.0000
83.9200 0.1362 1.0000
83.9800 0.6803 1.0000
84.0400 0.0000 1.0000
84.1000 3.0478 1.0000
84.1600 1.0023 1.0000
84.2200 0.0000 1.0000
84.2800 0.0000 1.0000
84.3400 0.0000 1.0000
84.4000 0.6273 1.0000
84.4600 0.9846 1.0000
84.5200 0.0000 1.0000
84.5800 0.9895 1.0000
84.6400 1.0187 1.0000
84.7000 3.0847 1.0000
84.7600 0.1171 1.0000
84.8200 1.1056 1.0000
84.8800 1.0393 1.0000
84.9400 0.0000 1.0000
85.0000 0.7632 1.0000
85.0600 0.8615 1.0000
85.1200 0.9629 1.0000
85.1800 0.0791 1.0000
85.2400 0.9465 1.0000
85.3000 0.0000 1.0000
85.3600 1.0012 1.0000
85.4200 0.7638 1.0000
85.4800 0.0000 1.0000
85.5400 0.0000 1.0000
85.6000 0.1112 1.0000
85.6600 0.0000 1.0000
85.7200 0.0000 1.0000
85.7800 0.9740 1.0000
85.8400 0.0000 1.0000
85.9000 0.0000 1.0000
85.9600 1.7211 1.0000
86.0200 0.0000 1.0000
86.0800 1.0604 1.0000
86.1400 1.9454 1.0000
86.2000 1.6899 1.0000
86.2600 0.0000 1.0000
86.3200 0.0000 1.0000
86.3800 0.9858 1.0000
86.4400 1.0515 1.0000
86.5000 1.9839 1.0000
86.5600 0.0000 1.0000
86.6200 0.6260 1.0000
86.6800 0.9574 1.0000
86.7400 0.0000 1.0000
86.8000 1.0075 1.0000
86.8600 0.8368 1.0000
86.9200 0.6286 1.0000
86.9800 0.0000 1.0000
87.0400 0.5089 1.0000
87.1000 0.9162 1.0000
87.1600 0.0000 1.0000
87.2200 0.5466 1.0000
87.2800 0.0000 1.0000
87.3400 2.0574 1.0000
87.4000 0.9859 1.0000
87.4600 1.5485 1.0000
87.5200 1.0217 1.0000
87.5800 0.0000 1.0000
87.6400 1.2412 1.0000
87.7000 0.2844 1.0000
87.7600 0.6906 1.0000
87.8200 0.0000 1.0000
87.8800 0.0000 1.0000
87.9400 0.0829 1.0000
88.0000 0.5942 1.0000
88.0600 0.0000 1.0000
88.1200 1.4837 1.0000
88.1800 0.7481 1.0000
88.2400 0.9053 1.0000
88.3000 0.0000 1.0000
88.3600 0.0565 1.0000
88.4200 0.0000 1.0000
88.4800 0.0000 1.0000
88.5400 0.0000 1.0000
88.6000 0.0000 1.0000
88.6600 0.2337 1.0000
88.7200 0.0000 1.0000
88.7800 0.0000 1.0000
88.8400 0.0000 1.0000
88.9000 0.0000 1.0000
88.9600 0.3698 1.0000
89.0200 0.0000 1.0000
89.0800 0.0000 1.0000
89.1400 0.0000 1.0000
89.2000 0.0000 1.0000
89.2600 0.5609 1.0000
89.3200 0.9969 1.0000
89.3800 0.0000 1.0000
89.4400 1.6613 1.0000
89.5000 0.0000 1.0000
89.5600 0.0000 1.0000
89.6200 0.0000 1.0000
89.6800 0.0000 1.0000
89.7400 2.0331 1.0000
89.8000 0.0000 1.0000
89.8600 1.8107 1.0000
89.9200 0.0000 1.0000
89.9800 0.3193 1.0000
90.0400 0.2135 1.0000
90.1000 0.0000 1.0000
90.1600 0.0664 1.0000
90.2200 1.0842 1.0000
90.2800 0.8782 1.0000
90.3400 0.3469 1.0000
90.4000 0.9724 1.0000
90.4600 0.0000 1.0000
90.5200 1.9479 1.0000
90.5800 0.0983 1.0000
90.6400 0.9849 1.0000
90.7000 0.9500 1.0000
90.7600 0.0000 1.0000
90.8200 0.2589 1.0000
90.8800 0.2735 1.0000
90.9400 0.0000 1.0000
91.0000 0.0000 1.0000
91.0600 0.0000 1.0000
91.1200 1.0679 1.0000
91.1800 0.0000 1.0000
91.2400 0.0000 1.0000
91.3000 0.7662 1.0000
91.3600 0.0000 1.0000
91.4200 0.1766 1.0000
91.4800 0.0000 1.0000
91.5400 1.0373 1.0000
91.6000 0.6433 1.0000
91.6600 0.0000 1.0000
91.7200 0.3193 1.0000
91.7800 0.3195 1.0000
91.8400 0.0000 1.0000
91.9000 1.0349 1.0000
91.9600 4.0475 1.0000
92.0200 0.6451 1.0000
92.0800 1.2154 1.0000
92.1400 1.9226 1.0000
92.2000 0.3019 1.0000
92.2600 0.0000 1.0000
92.3200 0.0000 1.0000
92.3800 2.0490 1.0000
92.4400 1.0074 1.0000
92.5000 0.0000 1.0000
92.5600 0.4449 1.0000
92.6200 0.0000 1.0000
92.6800 0.5662 1.0000
92.7400 0.9696 1.0000
92.8000 1.0404 1.0000
92.8600 0.0000 1.0000
92.9200 0.9957 1.0000
92.9800 1.5722 1.0000
93.0400 0.0000 1.0000
93.1000 0.0000 1.0000
93.1600 0.0000 1.0000
93.2200 0.1817 1.0000
93.2800 0.9836 1.0000
93.3400 0.1422 1.0000
93.4000 0.0000 1.0000
93.4600 0.0000 1.0000
93.5200 1.0224 1.0000
93.5800 1.8440 1.0000
93.6400 0.0000 1.0000
93.7000 0.4266 1.0000
93.7600 3.9176 1.0000
93.8200 1.0801 1.0000
93.8800 1.2639 1.0000
93.9400 0.0000 1.0000
94.0000 0.0000 1.0000
94.0600 0.0000 1.0000
94.1200 0.0000 1.0000
94.1800 0.1216 1.0000
94.2400 0.0000 1.0000
94.3000 0.0000 1.0000
94.3600 0.6652 1.0000
94.4200 0.2350 1.0000
94.4800 1.0752 1.0000
94.5400 1.0777 1.0000
94.6000 0.0000 1.0000
94.6600 0.4950 1.0000
94.7200 1.9894 1.0000
94.7800 0.4873 1.0000
94.8400 0.2092 1.0000
94.9000 0.3143 1.0000
94.9600 0.0000 1.0000
95.0200 2.8296 1.0000
95.0800 0.0000 1.0000
95.1400 1.0303 1.0000
95.2000 1.0000 1.0000
95.2600 0.9279 1.0000
95.3200 0.0000 1.0000
95.3800 1.0072 1.0000
95.4400 0.0000 1.0000
95.5000 1.6006 1.0000
95.5600 0.9474 1.0000
95.6200 2.0663 1.0000
95.6800 1.9565 1.0000
95.7400 2.1744 1.0000
95.8000 0.0000 1.0000
95.8600 0.0000 1.0000
95.9200 1.4420 1.0000
95.9800 0.0000 1.0000
96.0400 0.5304 1.0000
96.1000 0.0000 1.0000
96.1600 0.0000 1.0000
96.2200 0.8574 1.0000
96.2800 0.0000 1.0000
96.3400 0.0000 1.0000
96.4000 0.0000 1.0000
96.4600 0.0000 1.0000
96.5200 0.0289 1.0000
96.5800 0.4612 1.0000
96.6400 0.9104 1.0000
96.7000 0.7569 1.0000
96.7600 0.9997 1.0000
96.8200 0.4078 1.0000
96.8800 0.0000 1.0000
96.9400 1.9667 1.0000
97.0000 1.4886 1.0000
97.0600 0.0000 1.0000
97.1200 0.0000 1.0000
97.1800 0.0000 1.0000
97.2400 1.0182 1.0000
97.3000 0.0000 1.0000
97.3600 0.1014 1.0000
97.4200 1.0264 1.0000
97.4800 0.9918 1.0000
97.5400 0.4001 1.0000
97.6000 0.0000 1.0000
97.6600 0.8705 1.0000
97.7200 0.3914 1.0000
97.7800 0.0000 1.0000
97.8400 0.0000 1.0000
97.9000 0.0000 1.0000
97.9600 0.4452 1.0000
98.0200 0.0000 1.0000
98.0800 0.0000 1.0000
98.1400 0.9667 1.0000
98.2000 0.0000 1.0000
98.2600 0.4838 1.0000
98.3200 0.9573 1.0000
98.3800 0.9404 1.0000
98.4400 0.3637 1.0000
98.5000 1.5150 1.0000
98.5600 2.2856 1.0000
98.6200 0.0000 1.0000
98.6800 0.0000 1.0000
98.7400 1.1761 1.0000
98.8000 3.0367 1.0000
98.8600 1.0754 1.0000
98.9200 1.3996 1.0000
98.9800 0.2857 1.0000
99.0400 0.0000 1.0000
99.1000 2.0959 1.0000
99.1600 0.0000 1.0000
99.2200 0.0000 1.0000
99.2800 0.0000 1.0000
99.3400 0.0000 1.0000
99.4000 0.9929 1.0000
99.4600 0.9897 1.0000
99.5200 0.3760 1.0000
99.5800 1.1198 1.0000
99.6400 2.0376 1.0000
99.7000 2.0580 1.0000
99.7600 2.9776 1.0000
99.8200 0.8473 1.0000
99.8800 2.0115 1.0000
99.9400 0.0000 1.0000
100.0000 0.0000 1.0000
100.0600 0.0000 1.0000
100.1200 0.0512 1.0000
100.1800 0.0000 1.0000
100.2400 0.0000 1.0000
100.3000 0.0000 1.0000
100.3600 0.0000 1.0000
100.4200 0.0000 1.0000
100.4800 0.0000 1.0000
100.5400 2.0052 1.0000
100.6000 2.2425 1.0000
100.6600 0.0000 1.0000
100.7200 0.9441 1.0000
100.7800 0.0000 1.0000
100.8400 0.8780 1.0000
100.9000 2.0305 1.0000
100.9600 0.9535 1.0000
101.0200 0.5497 1.0000
101.0800 1.1992 1.0000
101.1400 0.6978 1.0000
101.2000 0.9853 1.0000
101.2600 1.5669 1.0000
101.3200 0.0000 1.0000
101.3800 0.0000 1.0000
101.4400 0.4974 1.0000
101.5000 0.0000 1.0000
101.5600 1.4705 1.0000
101.6200 0.9396 1.0000
101.6800 0.0000 1.0000
101.7400 0.0000 1.0000
101.8000 0.1892 1.0000
101.8600 0.0000 1.0000
101.9200 0.9790 1.0000
101.9800 0.0000 1.0000
102.0400 2.0843 1.0000
102.1000 3.0409 1.0000
102.1600 0.9948 1.0000
102.2200 0.0000 1.0000
102.2800 0.0000 1.0000
102.3400 0.0921 1.0000
102.4000 0.0000 1.0000
102.4600 0.0000 1.0000
102.5200 0.4333 1.0000
102.5800 1.8797 1.0000
102.6400 1.9742 1.0000
102.7000 0.0000 1.0000
102.7600 2.9025 1.0000
102.8200 2.1893 1.0000
102.8800 1.0016 1.0000
102.9400 0.0000 1.0000
103.0000 0.8797 1.0000
103.0600 0.2874 1.0000
103.1200 0.0000 1.0000
103.1800 0.0000 1.0000
103.2400 0.0000 1.0000
103.3000 0.0000 1.0000
103.3600 0.0000 1.0000
103.4200 1.2339 1.0000
103.4800 0.0000 1.0000
103.5400 0.0000 1.0000
103.6000 1.2400 1.0000
103.6600 0.5853 1.0000
103.7200 0.0274 1.0000
103.7800 0.0827 1.0000
103.8400 1.8370 1.0000
103.9000 0.0000 1.0000
103.9600 0.0000 1.0000
104.0200 0.2310 1.0000
104.0800 0.9763 1.0000
104.1400 0.0000 1.0000
104.2000 0.0000 1.0000
104.2600 0.9744 1.0000
104.3200 0.0000 1.0000
104.3800 0.2602 1.0000
104.4400 0.0000 1.0000
104.5000 0.0000 1.0000
104.5600 2.0353 1.0000
104.6200 1.6321 1.0000
104.6800 0.0000 1.0000
104.7400 0.0000 1.0000
104.8000 0.0000 1.0000
104.8600 0.0000 1.0000
104.9200 0.7112 1.0000
104.9800 0.0000 1.0000
105.0400 0.4787 1.0000
105.1000 0.9256 1.0000
105.1600 0.0000 1.0000
105.2200 0.9425 1.0000
105.2800 0.0000 1.0000
105.3400 0.0000 1.0000
105.4000 0.0000 1.0000
105.4600 0.4254 1.0000
105.5200 1.0036 1.0000
105.5800 0.0000 1.0000
105.6400 0.0000 1.0000
105.7000 0.0000 1.0000
105.7600 0.0000 1.0000
105.8200 0.0000 1.0000
105.8800 0.3289 1.0000
105.9400 1.0787 1.0000
106.0000 0.0000 1.0000
106.0600 1.0136 1.0000
106.1200 0.0000 1.0000
106.1800 3.0030 1.0000
106.2400 1.0132 1.0000
106.3000 0.0000 1.0000
106.3600 0.1399 1.0000
106.4200 0.0000 1.0000
106.4800 0.0000 1.0000
106.5400 0.4190 1.0000
106.6000 0.9341 1.0000
106.6600 0.3293 1.0000
106.7200 0.0000 1.0000
106.7800 0.1703 1.0000
106.8400 1.9449 1.0000
106.9000 0.9777 1.0000
106.9600 0.0000 1.0000
107.0200 0.0000 1.0000
107.0800 0.7173 1.0000
107.1400 0.0000 1.0000
107.2000 1.0542 1.0000
107.2600 0.9751 1.0000
107.3200 0.0000 1.0000
107.3800 0.5175 1.0000
107.4400 0.0000 1.0000
107.5000 0.7738 1.0000
107.5600 0.8131 1.0000
107.6200 0.2519 1.0000
107.6800 0.0000 1.0000
107.7400 0.0000 1.0000
107.8000 0.5413 1.0000
107.8600 0.1072 1.0000
107.9200 0.9815 1.0000
107.9800 1.1686 1.0000
108.0400 0.0000 1.0000
108.1000 0.0000 1.0000
108.1600 0.0000 1.0000
108.2200 1.6193 1.0000
108.2800 0.0713 1.0000
108.3400 0.6387 1.0000
108.4000 0.0000 1.0000
108.4600 0.0000 1.0000
108.5200 0.0000 1.0000
108.5800 0.1840 1.0000
108.6400 0.0000 1.0000
108.7000 0.0717 1.0000
108.7600 0.0000 1.0000
108.8200 2.1844 1.0000
108.8800 0.9740 1.0000
108.9400 0.0000 1.0000
109.0000 3.5135 1.0000
109.0600 0.9876 1.0000
109.1200 0.0009 1.0000
109.1800 0.0000 1.0000
109.2400 0.9623 1.0000
109.3000 0.9968 1.0000
109.3600 0.9515 1.0000
109.4200 0.8200 1.0000
109.4800 0.0000 1.0000
109.5400 0.0000 1.0000
109.6000 2.1052 1.0000
109.6600 1.0202 1.0000
109.7200 0.0000 1.0000
109.7800 0.2173 1.0000
109.8400 0.2945 1.0000
109.9000 0.7306 1.0000
109.9600 0.0000 1.0000
110.0200 0.5698 1.0000
110.0800 1.0268 1.0000
110.1400 0.9523 1.0000
110.2000 0.3945 1.0000
110.2600 0.0000 1.0000
110.3200 0.0000 1.0000
110.3800 0.9646 1.0000
110.4400 0.0000 1.0000
110.5000 0.0656 1.0000
110.5600 0.0000 1.0000
110.6200 0.1609 1.0000
110.6800 0.0000 1.0000
110.7400 0.0000 1.0000
110.8000 1.0253 1.0000
110.8600 0.4488 1.0000
110.9200 0.9612 1.0000
110.9800 0.0000 1.0000
111.0400 1.0377 1.0000
111.1000 0.0000 1.0000
111.1600 1.7746 1.0000
111.2200 0.0000 1.0000
111.2800 1.7630 1.0000
111.3400 0.1323 1.0000
111.4000 0.5357 1.0000
111.4600 1.0886 1.0000
111.5200 0.0000 1.0000
111.5800 0.0000 1.0000
111.6400 0.0000 1.0000
111.7000 0.0000 1.0000
111.7600 1.0838 1.0000
111.8200 0.0000 1.0000
111.8800 0.9783 1.0000
111.9400 0.0000 1.0000
112.0000 0.0000 1.0000
112.0600 0.3464 1.0000
112.1200 0.0000 1.0000
112.1800 2.0455 1.0000
112.2400 0.0000 1.0000
112.3000 0.1375 1.0000
112.3600 0.0000 1.0000
112.4200 0.0000 1.0000
112.4800 1.4841 1.0000
112.5400 0.0000 1.0000
112.6000 0.2351 1.0000
112.6600 0.7021 1.0000
112.7200 0.9617 1.0000
112.7800 0.0000 1.0000
112.8400 0.0000 1.0000
112.9000 0.0000 1.0000
112.9600 0.9668 1.0000
113.0200 0.0000 1.0000
113.0800 0.4062 1.0000
113.1400 0.0000 1.0000
113.2000 0.5078 1.0000
113.2600 2.0633 1.0000
113.3200 0.0000 1.0000
113.3800 0.0000 1.0000
113.4400 1.2194 1.0000
113.5000 1.0472 1.0000
113.5600 0.3582 1.0000
113.6200 0.0000 1.0000
113.6800 0.0000 1.0000
113.7400 1.0180 1.0000
113.8000 0.0000 1.0000
113.8600 0.8400 1.0000
113.9200 0.0000 1.0000
113.9800 0.8445 1.0000
114.0400 0.0000 1.0000
114.1000 1.0103 1.0000
114.1600 0.0000 1.0000
114.2200 0.0000 1.0000
114.2800 0.0000 1.0000
114.3400 0.8141 1.0000
114.4000 1.8499 1.0000
114.4600 0.6773 1.0000
114.5200 1.0250 1.0000
114.5800 0.0000 1.0000
114.6400 1.0647 1.0000
114.7000 0.6496 1.0000
114.7600 1.2563 1.0000
114.8200 0.0000 1.0000
114.8800 0.4084 1.0000
114.9400 0.0000 1.0000
115.0000 0.0000 1.0000
115.0600 0.0000 1.0000
115.1200 0.0000 1.0000
115.1800 0.0000 1.0000
115.2400 0.0000 1.0000
115.3000 1.3344 1.0000
115.3600 0.9139 1.0000
115.4200 0.4868 1.0000
115.4800 0.0923 1.0000
115.5400 3.7831 1.0000
115.6000 0.0000 1.0000
115.6600 0.0000 1.0000
115.7200 1.0389 1.0000
115.7800 1.0463 1.0000
115.8400 0.9738 1.0000
115.9000 0.0000 1.0000
115.9600 0.9774 1.0000
116.0200 0.0000 1.0000
116.0800 1.4447 1.0000
116.1400 2.4658 1.0000
116.2000 0.0000 1.0000
116.2600 0.0000 1.0000
116.3200 1.3784 1.0000
116.3800 0.9599 1.0000
116.4400 0.4051 1.0000
116.5000 1.0253 1.0000
116.5600 0.0000 1.0000
116.6200 0.0000 1.0000
116.6800 0.7269 1.0000
116.7400 0.0000 1.0000
116.8000 0.0000 1.0000
116.8600 2.0317 1.0000
116.9200 0.4565 1.0000
116.9800 0.0000 1.0000
117.0400 0.7401 1.0000
117.1000 2.0863 1.0000
117.1600 0.2047 1.0000
117.2200 0.7291 1.0000
117.2800 0.1451 1.0000
117.3400 0.0000 1.0000
117.4000 0.9326 1.0000
117.4600 0.7444 1.0000
117.5200 1.7270 1.0000
117.5800 0.0000 1.0000
117.6400 0.0000 1.0000
117.7000 0.9681 1.0000
117.7600 0.0000 1.0000
117.8200 0.9607 1.0000
117.8800 0.0000 1.0000
117.9400 0.0000 1.0000
118.0000 0.9451 1.0000
118.0600 0.7102 1.0000
118.1200 0.9848 1.0000
118.1800 0.5543 1.0000
118.2400 1.0853 1.0000
118.3000 0.0000 1.0000
118.3600 0.9655 1.0000
118.4200 0.0000 1.0000
118.4800 0.0000 1.0000
118.5400 0.8873 1.0000
118.6000 0.0000 1.0000
118.6600 0.0000 1.0000
118.7200 0.6068 1.0000
118.7800 1.0381 1.0000
118.8400 0.3920 1.0000
118.9000 1.0128 1.0000
118.9600 0.8427 1.0000
119.0200 0.9680 1.0000
119.0800 3.1386 1.0000
119.1400 0.0000 1.0000
119.2000 1.9631 1.0000
119.2600 0.0000 1.0000
119.3200 2.5540 1.0000
119.3800 2.8262 1.0000
119.4400 2.3818 1.0000
119.5000 2.1203 1.0000
119.5600 0.0000 1.0000
119.6200 0.0000 1.0000
119.6800 0.8225 1.0000
119.7400 0.2454 1.0000
119.8000 1.7730 1.0000
119.8600 0.0000 1.0000
119.9200 0.0000 1.0000
119.9800 0.0000 1.0000
119.9900 0.6322 1.0000
*RAS_INT_END
*RAS_TEMPERATURE_START
*RAS_TEMPERATURE_END
*RAS_DATA_END