File: XRD/May_2022/EFRW3_Unirr_and_Irr_regions/PB_Ge220_2.5SS_500umDS_RS1_Rod_2.5SS_Hypix1D_EFRW3_HAZ_P-irradiated_LastPoint.ras
*RAS_DATA_START
*RAS_HEADER_START
*DISP_FMT_X "%.3f"
*DISP_FMT_Y "%.0f"
*DISP_FULLSCALE "322.4484678294"
*DISP_LINE_COLOR "255.0000000000"
*DISP_LINE_STYLE "0.0000000000"
*DISP_LINE_WIDTH "0.2500000000"
*DISP_NOTE "Collected Data-47"
*DISP_OFFSET_Y "0.0000000000"
*DISP_PEAKSEARCH_UNIT_Y "cps"
*DISP_RANGE_BOTTOM "0.0000000000"
*DISP_RANGE_LEFT "40.0000000000"
*DISP_RANGE_LOGCUTOFF "0.0100000000"
*DISP_RANGE_RIGHT "119.9968000000"
*DISP_RANGE_TOP "322.4484678294"
*DISP_SCALE_MODE_Y "0.0000000000"
*DISP_TAB_NAME "Theta/2-Theta"
*DISP_TITLE_Y "Intensity"
*DISP_UNIT_Y "cps"
*DISP_WINDOW_NAME "MSG_MACROENGINE"
*FILE_COMMENT " "
*FILE_MD5 ""
*FILE_MEMO " "
*FILE_OPERATOR "Administrator"
*FILE_PART_ID "MEAS_KHP2_00061"
*FILE_SAMPLE " "
*FILE_TYPE "RAS_RAW"
*FILE_USERGROUP "System Manager"
*FILE_VERSION "1.0000000000"
*HW_ATTACHMENT_ID "ATT0021"
*HW_ATTACHMENT_NAME "XY-20mm|XY-20mm"
*HW_COUNTER_ID-0 "CUT0041"
*HW_COUNTER_ID-1 "CUT0051"
*HW_COUNTER_ID-2 "CUT0020"
*HW_COUNTER_ID-3 "CSL0021"
*HW_COUNTER_ID-4 "CMC0021"
*HW_COUNTER_NAME-0 "D/teX Ultra 250|D/teX Ultra 250"
*HW_COUNTER_NAME-1 "HyPix 3000(H)|HyPix 3000(H)"
*HW_COUNTER_NAME-2 "None|None"
*HW_COUNTER_NAME-3 "BBM|BBM"
*HW_COUNTER_NAME-4 "検出器モノクロメータ|Detector monochromator"
*HW_COUNTER_SELECT_NAME "HyPix 3000(H)|HyPix 3000(H)"
*HW_GONIOMETER_ID "GON0024"
*HW_GONIOMETER_NAME "SmartLab(In-plane)|SmartLab(In-plane)"
*HW_GONIOMETER_RADIUS-0 "90.0"
*HW_GONIOMETER_RADIUS-1 "114.0"
*HW_GONIOMETER_RADIUS-2 "190.0"
*HW_GONIOMETER_RADIUS-3 "300.0"
*HW_GONIOMETER_RADIUS-4 "187.0"
*HW_GONIOMETER_RADIUS-5 "300.0"
*HW_GONIOMETER_RADIUS-6 "113.0"
*HW_GONIOMETER_RADIUS-7 "331.0"
*HW_I_OPT_ID-0 "CBO0021"
*HW_I_OPT_ID-1 "ICR0021"
*HW_I_OPT_ID-2 "ISL0021"
*HW_I_OPT_ID-3 "ISO0021"
*HW_I_OPT_ID-4 "IAD0021"
*HW_I_OPT_ID-5 "IPR0001"
*HW_I_OPT_NAME-0 "CBOユニット|CBO unit"
*HW_I_OPT_NAME-1 "標準入射光学ユニット|Standard incident optical unit"
*HW_I_OPT_NAME-2 "標準入射スリットボックス|Standard incident slit box"
*HW_I_OPT_NAME-3 "入射平行スリット|Incident parallel slit"
*HW_I_OPT_NAME-4 "長手制限スリット|Length limiting slit"
*HW_I_OPT_NAME-5 "None|None"
*HW_R_ATTENUATER_AUTOMODE "0"
*HW_R_OPT_ID-0 "RSS0022"
*HW_R_OPT_ID-1 "RCR0022"
*HW_R_OPT_ID-2 "RSO0021"
*HW_R_OPT_ID-3 "RRS0022"
*HW_R_OPT_ID-4 "ATN0020"
*HW_R_OPT_ID-5 "RFL0021"
*HW_R_OPT_ID-6 "RAD0021"
*HW_R_OPT_NAME-0 "受光スリットボックス1(Zr軸付)|Receiving slit box # 1 (w/ Zr Axis)"
*HW_R_OPT_NAME-1 "標準受光光学ユニット1|Standard receiving unit # 1"
*HW_R_OPT_NAME-2 "標準受光光学ユニット2|Standard receiving optical unit # 2"
*HW_R_OPT_NAME-3 "仮想受光スリット2|Virtual receiving slit #2"
*HW_R_OPT_NAME-4 "無し|None"
*HW_R_OPT_NAME-5 "Cu Kβ|Cu K-beta"
*HW_R_OPT_NAME-6 "調整用受光スリット|Alignment receiving slit"
*HW_SAMPLE_HOLDER_ID "SMP0021"
*HW_SAMPLE_HOLDER_NAME "χφZクレードル|Chi phi Z cradle"
*HW_XG_CURRENT_MAX "40"
*HW_XG_CURRENT_MIN "2"
*HW_XG_CURRENT_RESOLUTION "1"
*HW_XG_CURRENT_UNIT "mA"
*HW_XG_FOCUS "0.4mm x 8mm"
*HW_XG_FOCUS_TYPE "Fine"
*HW_XG_ID "1200"
*HW_XG_NAME "3kW 封入管(ID:1200)|3kW Sealed tube(ID:1200)"
*HW_XG_TARGET_ATOMIC_NUMBER "29.0000000000"
*HW_XG_TARGET_NAME "Cu"
*HW_XG_TYPE "Hermetic"
*HW_XG_VOLTAGE_MAX "40"
*HW_XG_VOLTAGE_MIN "20"
*HW_XG_VOLTAGE_RESOLUTION "1"
*HW_XG_VOLTAGE_UNIT "kV"
*HW_XG_WATT_MAX "1.500"
*HW_XG_WATT_UNIT "kW"
*HW_XG_WAVE_LENGTH_ALPHA1 "1.540593"
*HW_XG_WAVE_LENGTH_ALPHA2 "1.544414"
*HW_XG_WAVE_LENGTH_BETA "1.392250"
*MEAS_COND_AXIS_NAME-0 "Theta/2-Theta"
*MEAS_COND_AXIS_NAME-1 "2-Theta"
*MEAS_COND_AXIS_NAME-2 "Omega"
*MEAS_COND_AXIS_NAME-3 "Chi"
*MEAS_COND_AXIS_NAME-4 "Phi"
*MEAS_COND_AXIS_NAME-5 "Z"
*MEAS_COND_AXIS_NAME-6 "X"
*MEAS_COND_AXIS_NAME-7 "Y"
*MEAS_COND_AXIS_NAME-8 "2-Theta/Omega"
*MEAS_COND_AXIS_NAME-9 "2-ThetaChi"
*MEAS_COND_AXIS_NAME-10 "2-ThetaChi/Phi"
*MEAS_COND_AXIS_NAME-11 "Alpha"
*MEAS_COND_AXIS_NAME-12 "Beta"
*MEAS_COND_AXIS_NAME-13 "Theta_s"
*MEAS_COND_AXIS_NAME-14 "Theta_d"
*MEAS_COND_AXIS_NAME-15 "Ts"
*MEAS_COND_AXIS_NAME-16 "CBO selection slit"
*MEAS_COND_AXIS_NAME-17 "M"
*MEAS_COND_AXIS_NAME-18 "Incident parallel slit"
*MEAS_COND_AXIS_NAME-19 "Incident slit"
*MEAS_COND_AXIS_NAME-20 ""
*MEAS_COND_AXIS_NAME-21 "Zs"
*MEAS_COND_AXIS_NAME-22 "Incident optical device"
*MEAS_COND_AXIS_NAME-23 "Omega_m"
*MEAS_COND_AXIS_NAME-24 "Length limiting slit"
*MEAS_COND_AXIS_NAME-25 "Center slit"
*MEAS_COND_AXIS_NAME-26 "Filter"
*MEAS_COND_AXIS_NAME-27 "Receiving slit # 1"
*MEAS_COND_AXIS_NAME-28 "Receiving slit # 2"
*MEAS_COND_AXIS_NAME-29 "Receiving optical device"
*MEAS_COND_AXIS_NAME-30 "Receiving parallel slit"
*MEAS_COND_AXIS_NAME-31 "Alignment receiving slit"
*MEAS_COND_AXIS_NAME-32 ""
*MEAS_COND_AXIS_NAME-33 ""
*MEAS_COND_AXIS_NAME-34 "Zd"
*MEAS_COND_AXIS_NAME-35 "Attenuator"
*MEAS_COND_AXIS_NAME-36 "Diffracted beam monochromator"
*MEAS_COND_AXIS_NAME-37 "Monochromator slit"
*MEAS_COND_AXIS_NAME-38 "2-ThetaB"
*MEAS_COND_AXIS_NAME-39 ""
*MEAS_COND_AXIS_NAME-40 ""
*MEAS_COND_AXIS_NAME-41 "Zr"
*MEAS_COND_AXIS_NAME-42 "Primary beam"
*MEAS_COND_AXIS_NAME_INTERNAL-0 "TwoThetaTheta"
*MEAS_COND_AXIS_NAME_INTERNAL-1 "TwoTheta"
*MEAS_COND_AXIS_NAME_INTERNAL-2 "Omega"
*MEAS_COND_AXIS_NAME_INTERNAL-3 "Chi"
*MEAS_COND_AXIS_NAME_INTERNAL-4 "Phi"
*MEAS_COND_AXIS_NAME_INTERNAL-5 "Z"
*MEAS_COND_AXIS_NAME_INTERNAL-6 "X"
*MEAS_COND_AXIS_NAME_INTERNAL-7 "Y"
*MEAS_COND_AXIS_NAME_INTERNAL-8 "TwoThetaOmega"
*MEAS_COND_AXIS_NAME_INTERNAL-9 "TwoThetaChi"
*MEAS_COND_AXIS_NAME_INTERNAL-10 "TwoThetaChiPhi"
*MEAS_COND_AXIS_NAME_INTERNAL-11 "Alpha"
*MEAS_COND_AXIS_NAME_INTERNAL-12 "Beta"
*MEAS_COND_AXIS_NAME_INTERNAL-13 "ThetaS"
*MEAS_COND_AXIS_NAME_INTERNAL-14 "ThetaD"
*MEAS_COND_AXIS_NAME_INTERNAL-15 "Ts"
*MEAS_COND_AXIS_NAME_INTERNAL-16 "CBO"
*MEAS_COND_AXIS_NAME_INTERNAL-17 "CBO-M"
*MEAS_COND_AXIS_NAME_INTERNAL-18 "IncidentSollerSlit"
*MEAS_COND_AXIS_NAME_INTERNAL-19 "IncidentSlitBox"
*MEAS_COND_AXIS_NAME_INTERNAL-20 "IncidentSlitBox-_Axis"
*MEAS_COND_AXIS_NAME_INTERNAL-21 "Zs"
*MEAS_COND_AXIS_NAME_INTERNAL-22 "IncidentMonochromator"
*MEAS_COND_AXIS_NAME_INTERNAL-23 "IncidentMonochromator-OmegaM"
*MEAS_COND_AXIS_NAME_INTERNAL-24 "IncidentAxdSlit"
*MEAS_COND_AXIS_NAME_INTERNAL-25 "CenterSlit"
*MEAS_COND_AXIS_NAME_INTERNAL-26 "Filter"
*MEAS_COND_AXIS_NAME_INTERNAL-27 "ReceivingSlitBox1"
*MEAS_COND_AXIS_NAME_INTERNAL-28 "ReceivingSlitBox2"
*MEAS_COND_AXIS_NAME_INTERNAL-29 "ReceivingOptics"
*MEAS_COND_AXIS_NAME_INTERNAL-30 "ReceivingSollerSlit"
*MEAS_COND_AXIS_NAME_INTERNAL-31 "ReceivingAxdSlit"
*MEAS_COND_AXIS_NAME_INTERNAL-32 "ReceivingSlitBox1-_Axis"
*MEAS_COND_AXIS_NAME_INTERNAL-33 "ReceivingSlitBox2-_Axis"
*MEAS_COND_AXIS_NAME_INTERNAL-34 "ReceivingSlitBox2-Zd"
*MEAS_COND_AXIS_NAME_INTERNAL-35 "Attenuator"
*MEAS_COND_AXIS_NAME_INTERNAL-36 "CounterMonochromator"
*MEAS_COND_AXIS_NAME_INTERNAL-37 "CounterSlit"
*MEAS_COND_AXIS_NAME_INTERNAL-38 "TwoThetaB"
*MEAS_COND_AXIS_NAME_INTERNAL-39 "AlphaR"
*MEAS_COND_AXIS_NAME_INTERNAL-40 "BetaR"
*MEAS_COND_AXIS_NAME_INTERNAL-41 "ReceivingSlitBox1-Zr"
*MEAS_COND_AXIS_NAME_INTERNAL-42 "IncidentPrimary"
*MEAS_COND_AXIS_NAME_MAGICNO-0 "83951616.0000000000"
*MEAS_COND_AXIS_NAME_MAGICNO-1 "268632064.0000000000"
*MEAS_COND_AXIS_NAME_MAGICNO-2 "268500992.0000000000"
*MEAS_COND_AXIS_NAME_MAGICNO-3 "268500992.0000000000"
*MEAS_COND_AXIS_NAME_MAGICNO-4 "268500992.0000000000"
*MEAS_COND_AXIS_NAME_MAGICNO-5 "285278208.0000000000"
*MEAS_COND_AXIS_NAME_MAGICNO-6 "268500992.0000000000"
*MEAS_COND_AXIS_NAME_MAGICNO-7 "268500992.0000000000"
*MEAS_COND_AXIS_NAME_MAGICNO-8 "83951616.0000000000"
*MEAS_COND_AXIS_NAME_MAGICNO-9 "268632064.0000000000"
*MEAS_COND_AXIS_NAME_MAGICNO-10 "83951616.0000000000"
*MEAS_COND_AXIS_NAME_MAGICNO-11 "17039360.0000000000"
*MEAS_COND_AXIS_NAME_MAGICNO-12 "17039360.0000000000"
*MEAS_COND_AXIS_NAME_MAGICNO-13 "131072.0000000000"
*MEAS_COND_AXIS_NAME_MAGICNO-14 "131072.0000000000"
*MEAS_COND_AXIS_NAME_MAGICNO-15 "318898176.0000000000"
*MEAS_COND_AXIS_NAME_MAGICNO-16 "20971521.0000000000"
*MEAS_COND_AXIS_NAME_MAGICNO-17 "285343744.0000000000"
*MEAS_COND_AXIS_NAME_MAGICNO-18 "20971521.0000000000"
*MEAS_COND_AXIS_NAME_MAGICNO-19 "22020097.0000000000"
*MEAS_COND_AXIS_NAME_MAGICNO-20 "25165824.0000000000"
*MEAS_COND_AXIS_NAME_MAGICNO-21 "318898176.0000000000"
*MEAS_COND_AXIS_NAME_MAGICNO-22 "20971521.0000000000"
*MEAS_COND_AXIS_NAME_MAGICNO-23 "285343744.0000000000"
*MEAS_COND_AXIS_NAME_MAGICNO-24 "20971521.0000000000"
*MEAS_COND_AXIS_NAME_MAGICNO-25 "20971521.0000000000"
*MEAS_COND_AXIS_NAME_MAGICNO-26 "20971521.0000000000"
*MEAS_COND_AXIS_NAME_MAGICNO-27 "23068673.0000000000"
*MEAS_COND_AXIS_NAME_MAGICNO-28 "23068673.0000000000"
*MEAS_COND_AXIS_NAME_MAGICNO-29 "20971521.0000000000"
*MEAS_COND_AXIS_NAME_MAGICNO-30 "20971521.0000000000"
*MEAS_COND_AXIS_NAME_MAGICNO-31 "20971521.0000000000"
*MEAS_COND_AXIS_NAME_MAGICNO-32 "25165824.0000000000"
*MEAS_COND_AXIS_NAME_MAGICNO-33 "25165824.0000000000"
*MEAS_COND_AXIS_NAME_MAGICNO-34 "285343744.0000000000"
*MEAS_COND_AXIS_NAME_MAGICNO-35 "0.0000000000"
*MEAS_COND_AXIS_NAME_MAGICNO-36 "20971521.0000000000"
*MEAS_COND_AXIS_NAME_MAGICNO-37 "20971521.0000000000"
*MEAS_COND_AXIS_NAME_MAGICNO-38 "17039360.0000000000"
*MEAS_COND_AXIS_NAME_MAGICNO-39 "8388608.0000000000"
*MEAS_COND_AXIS_NAME_MAGICNO-40 "8388608.0000000000"
*MEAS_COND_AXIS_NAME_MAGICNO-41 "285343744.0000000000"
*MEAS_COND_AXIS_NAME_MAGICNO-42 "20971521.0000000000"
*MEAS_COND_AXIS_OFFSET-0 "-"
*MEAS_COND_AXIS_OFFSET-1 "0.8642000000"
*MEAS_COND_AXIS_OFFSET-2 "1.0640000000"
*MEAS_COND_AXIS_OFFSET-3 "0.0000000000"
*MEAS_COND_AXIS_OFFSET-4 "0.0000000000"
*MEAS_COND_AXIS_OFFSET-5 "-"
*MEAS_COND_AXIS_OFFSET-6 "0.0000000000"
*MEAS_COND_AXIS_OFFSET-7 "0.0000000000"
*MEAS_COND_AXIS_OFFSET-8 "-"
*MEAS_COND_AXIS_OFFSET-9 "0.0000000000"
*MEAS_COND_AXIS_OFFSET-10 "-"
*MEAS_COND_AXIS_OFFSET-11 "-"
*MEAS_COND_AXIS_OFFSET-12 "-"
*MEAS_COND_AXIS_OFFSET-13 "1.0640000000"
*MEAS_COND_AXIS_OFFSET-14 "-0.1998000000"
*MEAS_COND_AXIS_OFFSET-15 "-"
*MEAS_COND_AXIS_OFFSET-16 "-"
*MEAS_COND_AXIS_OFFSET-17 "-"
*MEAS_COND_AXIS_OFFSET-18 "-"
*MEAS_COND_AXIS_OFFSET-19 "-"
*MEAS_COND_AXIS_OFFSET-20 "-"
*MEAS_COND_AXIS_OFFSET-21 "-"
*MEAS_COND_AXIS_OFFSET-22 "-"
*MEAS_COND_AXIS_OFFSET-23 "-"
*MEAS_COND_AXIS_OFFSET-24 "-"
*MEAS_COND_AXIS_OFFSET-25 "-"
*MEAS_COND_AXIS_OFFSET-26 "-"
*MEAS_COND_AXIS_OFFSET-27 "-"
*MEAS_COND_AXIS_OFFSET-28 "-"
*MEAS_COND_AXIS_OFFSET-29 "-"
*MEAS_COND_AXIS_OFFSET-30 "-"
*MEAS_COND_AXIS_OFFSET-31 "-"
*MEAS_COND_AXIS_OFFSET-32 "-"
*MEAS_COND_AXIS_OFFSET-33 "-"
*MEAS_COND_AXIS_OFFSET-34 "-"
*MEAS_COND_AXIS_OFFSET-35 "-"
*MEAS_COND_AXIS_OFFSET-36 "-"
*MEAS_COND_AXIS_OFFSET-37 "-"
*MEAS_COND_AXIS_OFFSET-38 "-"
*MEAS_COND_AXIS_OFFSET-39 "0.0000000000"
*MEAS_COND_AXIS_OFFSET-40 "0.0000000000"
*MEAS_COND_AXIS_OFFSET-41 "-"
*MEAS_COND_AXIS_OFFSET-42 "-"
*MEAS_COND_AXIS_POSITION-0 "40.0000000000"
*MEAS_COND_AXIS_POSITION-1 "40.0000000000"
*MEAS_COND_AXIS_POSITION-2 "20.0000000000"
*MEAS_COND_AXIS_POSITION-3 "0.0000000000"
*MEAS_COND_AXIS_POSITION-4 "0.0000000000"
*MEAS_COND_AXIS_POSITION-5 "-1.7645000000"
*MEAS_COND_AXIS_POSITION-6 "-2.0000000000"
*MEAS_COND_AXIS_POSITION-7 "8.0000000000"
*MEAS_COND_AXIS_POSITION-8 "40.0000000000"
*MEAS_COND_AXIS_POSITION-9 "0.0000000000"
*MEAS_COND_AXIS_POSITION-10 "0.0000000000"
*MEAS_COND_AXIS_POSITION-11 "90.0000000000"
*MEAS_COND_AXIS_POSITION-12 "0.0000000000"
*MEAS_COND_AXIS_POSITION-13 "20.0000000000"
*MEAS_COND_AXIS_POSITION-14 "20.0000000000"
*MEAS_COND_AXIS_POSITION-15 "-5.4426900000"
*MEAS_COND_AXIS_POSITION-16 "PB"
*MEAS_COND_AXIS_POSITION-17 "0.0000000000"
*MEAS_COND_AXIS_POSITION-18 "Soller_slit_5.0deg_s"
*MEAS_COND_AXIS_POSITION-19 "1.000mm"
*MEAS_COND_AXIS_POSITION-20 "1.0000000000"
*MEAS_COND_AXIS_POSITION-21 "-1.3487500000"
*MEAS_COND_AXIS_POSITION-22 "Ge(220)x2"
*MEAS_COND_AXIS_POSITION-23 "0.0000000000"
*MEAS_COND_AXIS_POSITION-24 "0.5mm"
*MEAS_COND_AXIS_POSITION-25 "None"
*MEAS_COND_AXIS_POSITION-26 "None"
*MEAS_COND_AXIS_POSITION-27 "20.000mm"
*MEAS_COND_AXIS_POSITION-28 "38.500mm"
*MEAS_COND_AXIS_POSITION-29 "PSA_open"
*MEAS_COND_AXIS_POSITION-30 "Soller_slit_5.0deg"
*MEAS_COND_AXIS_POSITION-31 "None"
*MEAS_COND_AXIS_POSITION-32 "20.0000000000"
*MEAS_COND_AXIS_POSITION-33 "38.5000000000"
*MEAS_COND_AXIS_POSITION-34 "0.0000000000"
*MEAS_COND_AXIS_POSITION-35 "-"
*MEAS_COND_AXIS_POSITION-36 "No_unit"
*MEAS_COND_AXIS_POSITION-37 "None"
*MEAS_COND_AXIS_POSITION-38 "40.0000000000"
*MEAS_COND_AXIS_POSITION-39 "0.0000000000"
*MEAS_COND_AXIS_POSITION-40 "0.0000000000"
*MEAS_COND_AXIS_POSITION-41 "0.2584400000"
*MEAS_COND_AXIS_POSITION-42 "None"
*MEAS_COND_AXIS_UNIT-0 "deg"
*MEAS_COND_AXIS_UNIT-1 "deg"
*MEAS_COND_AXIS_UNIT-2 "deg"
*MEAS_COND_AXIS_UNIT-3 "deg"
*MEAS_COND_AXIS_UNIT-4 "deg"
*MEAS_COND_AXIS_UNIT-5 "mm"
*MEAS_COND_AXIS_UNIT-6 "mm"
*MEAS_COND_AXIS_UNIT-7 "mm"
*MEAS_COND_AXIS_UNIT-8 "deg"
*MEAS_COND_AXIS_UNIT-9 "deg"
*MEAS_COND_AXIS_UNIT-10 "deg"
*MEAS_COND_AXIS_UNIT-11 "deg"
*MEAS_COND_AXIS_UNIT-12 "deg"
*MEAS_COND_AXIS_UNIT-13 "deg"
*MEAS_COND_AXIS_UNIT-14 "deg"
*MEAS_COND_AXIS_UNIT-15 "mm"
*MEAS_COND_AXIS_UNIT-16 ""
*MEAS_COND_AXIS_UNIT-17 "pulse"
*MEAS_COND_AXIS_UNIT-18 ""
*MEAS_COND_AXIS_UNIT-19 ""
*MEAS_COND_AXIS_UNIT-20 "mm"
*MEAS_COND_AXIS_UNIT-21 "mm"
*MEAS_COND_AXIS_UNIT-22 ""
*MEAS_COND_AXIS_UNIT-23 "pulse"
*MEAS_COND_AXIS_UNIT-24 ""
*MEAS_COND_AXIS_UNIT-25 ""
*MEAS_COND_AXIS_UNIT-26 ""
*MEAS_COND_AXIS_UNIT-27 ""
*MEAS_COND_AXIS_UNIT-28 ""
*MEAS_COND_AXIS_UNIT-29 ""
*MEAS_COND_AXIS_UNIT-30 ""
*MEAS_COND_AXIS_UNIT-31 ""
*MEAS_COND_AXIS_UNIT-32 "mm"
*MEAS_COND_AXIS_UNIT-33 "mm"
*MEAS_COND_AXIS_UNIT-34 "mm"
*MEAS_COND_AXIS_UNIT-35 ""
*MEAS_COND_AXIS_UNIT-36 ""
*MEAS_COND_AXIS_UNIT-37 ""
*MEAS_COND_AXIS_UNIT-38 "deg"
*MEAS_COND_AXIS_UNIT-39 "deg"
*MEAS_COND_AXIS_UNIT-40 "deg"
*MEAS_COND_AXIS_UNIT-41 "mm"
*MEAS_COND_AXIS_UNIT-42 ""
*MEAS_COND_COUNTER_CNTLOSS_CORR "0.0000000000"
*MEAS_COND_COUNTER_TAUDIFF "0.0000000000"
*MEAS_COND_COUNTER_TAUINT "0.0000000000"
*MEAS_COND_COUNTER_TEMP_CONDITION "NORMAL"
*MEAS_COND_IRRADIATION_MODE "OFF"
*MEAS_COND_IRRADIATION_WIDTH ""
*MEAS_COND_OPT_ATTR "High resolution parallel beam Ge(220)x2/RS"
*MEAS_COND_OPT_NAME "@High resolution PB-Ge(220)x2"
*MEAS_COND_UNSYMMETRIC_MODE "OFF"
*MEAS_COND_XG_CURRENT "30.0000000000"
*MEAS_COND_XG_VOLTAGE "40.0000000000"
*MEAS_COND_XG_WAVE_TYPE "Ka1"
*MEAS_DATA_COUNT "8000.0000000000"
*MEAS_SCAN_AXIS_X "Theta/2-Theta"
*MEAS_SCAN_AXIS_X_INTERNAL "TwoThetaTheta"
*MEAS_SCAN_END_TIME "05/18/22 17:28:37"
*MEAS_SCAN_MODE "CONTINUOUS"
*MEAS_SCAN_MONITOR "0"
*MEAS_SCAN_RESOLUTION_X "0.0002"
*MEAS_SCAN_SPEED "0.503240"
*MEAS_SCAN_SPEED_UNIT "deg/min"
*MEAS_SCAN_SPEED_USER "0.5"
*MEAS_SCAN_START "40.0000000000"
*MEAS_SCAN_START_TIME "05/18/22 14:33:47"
*MEAS_SCAN_STEP "0.0100000000"
*MEAS_SCAN_STOP "119.9900000000"
*MEAS_SCAN_UNIT_X "deg"
*MEAS_SCAN_UNIT_Y "counts"
*RAS_HEADER_END
*RAS_INT_START
40.0000 5.3319 1.0000
40.0600 6.4337 1.0000
40.1200 5.4497 1.0000
40.1800 10.9992 1.0000
40.2400 6.1701 1.0000
40.3000 12.2062 1.0000
40.3600 8.0449 1.0000
40.4200 7.1832 1.0000
40.4800 5.8320 1.0000
40.5400 7.2522 1.0000
40.6000 5.4562 1.0000
40.6600 8.1583 1.0000
40.7200 5.9989 1.0000
40.7800 4.0555 1.0000
40.8400 7.9060 1.0000
40.9000 8.2493 1.0000
40.9600 12.0590 1.0000
41.0200 5.4050 1.0000
41.0800 4.7112 1.0000
41.1400 4.9488 1.0000
41.2000 6.1707 1.0000
41.2600 12.0267 1.0000
41.3200 9.7494 1.0000
41.3800 8.3502 1.0000
41.4400 14.6847 1.0000
41.5000 10.9500 1.0000
41.5600 9.3448 1.0000
41.6200 9.1254 1.0000
41.6800 5.3492 1.0000
41.7400 3.1804 1.0000
41.8000 10.4907 1.0000
41.8600 7.5969 1.0000
41.9200 8.8519 1.0000
41.9800 5.1263 1.0000
42.0400 8.0979 1.0000
42.1000 8.2638 1.0000
42.1600 3.5174 1.0000
42.2200 5.3513 1.0000
42.2800 6.5230 1.0000
42.3400 5.3893 1.0000
42.4000 9.0486 1.0000
42.4600 9.7639 1.0000
42.5200 13.6535 1.0000
42.5800 8.6825 1.0000
42.6400 5.7518 1.0000
42.7000 6.2355 1.0000
42.7600 7.8634 1.0000
42.8200 9.9209 1.0000
42.8800 6.3259 1.0000
42.9400 8.3592 1.0000
43.0000 9.0280 1.0000
43.0600 9.9685 1.0000
43.1200 5.7728 1.0000
43.1800 15.2705 1.0000
43.2400 13.5596 1.0000
43.3000 4.1105 1.0000
43.3600 8.0286 1.0000
43.4200 5.7134 1.0000
43.4800 2.4480 1.0000
43.5400 6.9428 1.0000
43.6000 6.9108 1.0000
43.6600 5.1530 1.0000
43.7200 4.3889 1.0000
43.7800 8.8085 1.0000
43.8400 10.9784 1.0000
43.9000 9.4123 1.0000
43.9600 3.8447 1.0000
44.0200 8.7183 1.0000
44.0800 7.8018 1.0000
44.1400 8.5475 1.0000
44.2000 11.8542 1.0000
44.2600 12.3163 1.0000
44.3200 18.3626 1.0000
44.3800 61.3377 1.0000
44.4400 131.9967 1.0000
44.5000 236.2273 1.0000
44.5600 252.9408 1.0000
44.6200 139.9275 1.0000
44.6800 26.8124 1.0000
44.7400 17.2796 1.0000
44.8000 11.6569 1.0000
44.8600 7.2903 1.0000
44.9200 3.2227 1.0000
44.9800 7.6638 1.0000
45.0400 8.4350 1.0000
45.1000 16.9628 1.0000
45.1600 7.0777 1.0000
45.2200 5.0343 1.0000
45.2800 5.7939 1.0000
45.3400 3.2129 1.0000
45.4000 6.4407 1.0000
45.4600 11.2041 1.0000
45.5200 2.9983 1.0000
45.5800 4.7726 1.0000
45.6400 5.3941 1.0000
45.7000 6.0913 1.0000
45.7600 5.8623 1.0000
45.8200 8.5627 1.0000
45.8800 6.2416 1.0000
45.9400 3.5051 1.0000
46.0000 5.3300 1.0000
46.0600 2.1519 1.0000
46.1200 5.1634 1.0000
46.1800 5.9835 1.0000
46.2400 6.2537 1.0000
46.3000 7.4807 1.0000
46.3600 9.4979 1.0000
46.4200 6.9119 1.0000
46.4800 7.1252 1.0000
46.5400 5.2925 1.0000
46.6000 12.3227 1.0000
46.6600 9.0054 1.0000
46.7200 10.7554 1.0000
46.7800 3.2427 1.0000
46.8400 8.0329 1.0000
46.9000 8.8043 1.0000
46.9600 11.8395 1.0000
47.0200 3.7339 1.0000
47.0800 4.5381 1.0000
47.1400 10.9230 1.0000
47.2000 5.2406 1.0000
47.2600 2.2734 1.0000
47.3200 3.8027 1.0000
47.3800 9.3109 1.0000
47.4400 8.3780 1.0000
47.5000 7.9113 1.0000
47.5600 4.2671 1.0000
47.6200 9.3710 1.0000
47.6800 5.3836 1.0000
47.7400 2.5044 1.0000
47.8000 7.3304 1.0000
47.8600 5.2130 1.0000
47.9200 8.6340 1.0000
47.9800 6.9829 1.0000
48.0400 4.4418 1.0000
48.1000 11.0150 1.0000
48.1600 5.5621 1.0000
48.2200 7.1130 1.0000
48.2800 10.0098 1.0000
48.3400 9.5480 1.0000
48.4000 4.8439 1.0000
48.4600 10.3126 1.0000
48.5200 9.3792 1.0000
48.5800 7.2844 1.0000
48.6400 8.9761 1.0000
48.7000 6.0858 1.0000
48.7600 8.1936 1.0000
48.8200 6.8481 1.0000
48.8800 3.9635 1.0000
48.9400 5.4154 1.0000
49.0000 5.3568 1.0000
49.0600 6.5189 1.0000
49.1200 7.2528 1.0000
49.1800 4.4190 1.0000
49.2400 6.5096 1.0000
49.3000 5.9519 1.0000
49.3600 10.4352 1.0000
49.4200 6.1578 1.0000
49.4800 9.3586 1.0000
49.5400 9.4092 1.0000
49.6000 8.7337 1.0000
49.6600 5.7198 1.0000
49.7200 4.3291 1.0000
49.7800 5.3146 1.0000
49.8400 10.6104 1.0000
49.9000 9.0092 1.0000
49.9600 6.9068 1.0000
50.0200 9.0081 1.0000
50.0800 6.1520 1.0000
50.1400 3.1038 1.0000
50.2000 7.0138 1.0000
50.2600 4.2381 1.0000
50.3200 4.4799 1.0000
50.3800 10.5651 1.0000
50.4400 7.5942 1.0000
50.5000 9.6302 1.0000
50.5600 10.1611 1.0000
50.6200 7.9629 1.0000
50.6800 6.1665 1.0000
50.7400 3.2603 1.0000
50.8000 5.5094 1.0000
50.8600 6.3208 1.0000
50.9200 5.7355 1.0000
50.9800 8.0842 1.0000
51.0400 8.0668 1.0000
51.1000 5.2830 1.0000
51.1600 11.8580 1.0000
51.2200 9.0709 1.0000
51.2800 8.0056 1.0000
51.3400 7.5335 1.0000
51.4000 5.5395 1.0000
51.4600 1.8093 1.0000
51.5200 8.3438 1.0000
51.5800 7.6608 1.0000
51.6400 7.5226 1.0000
51.7000 3.2706 1.0000
51.7600 8.3389 1.0000
51.8200 10.7482 1.0000
51.8800 7.7697 1.0000
51.9400 3.2976 1.0000
52.0000 7.8073 1.0000
52.0600 9.8963 1.0000
52.1200 9.5359 1.0000
52.1800 7.1981 1.0000
52.2400 6.1557 1.0000
52.3000 10.4576 1.0000
52.3600 7.6356 1.0000
52.4200 10.9455 1.0000
52.4800 2.1492 1.0000
52.5400 2.5849 1.0000
52.6000 5.8107 1.0000
52.6600 8.5418 1.0000
52.7200 4.3672 1.0000
52.7800 5.9908 1.0000
52.8400 8.6341 1.0000
52.9000 13.0707 1.0000
52.9600 12.7262 1.0000
53.0200 9.8011 1.0000
53.0800 6.1726 1.0000
53.1400 8.1713 1.0000
53.2000 7.9698 1.0000
53.2600 3.1603 1.0000
53.3200 6.2761 1.0000
53.3800 19.3108 1.0000
53.4400 7.4265 1.0000
53.5000 8.3025 1.0000
53.5600 5.0569 1.0000
53.6200 5.8613 1.0000
53.6800 1.7769 1.0000
53.7400 6.3839 1.0000
53.8000 5.3681 1.0000
53.8600 10.6294 1.0000
53.9200 6.9301 1.0000
53.9800 4.6042 1.0000
54.0400 7.4223 1.0000
54.1000 5.2571 1.0000
54.1600 5.9001 1.0000
54.2200 4.1617 1.0000
54.2800 6.8546 1.0000
54.3400 7.1816 1.0000
54.4000 6.4910 1.0000
54.4600 8.3788 1.0000
54.5200 6.4886 1.0000
54.5800 11.0825 1.0000
54.6400 5.8904 1.0000
54.7000 16.9215 1.0000
54.7600 5.5806 1.0000
54.8200 3.3987 1.0000
54.8800 6.2876 1.0000
54.9400 10.4876 1.0000
55.0000 6.5214 1.0000
55.0600 3.9628 1.0000
55.1200 8.7361 1.0000
55.1800 4.4717 1.0000
55.2400 7.0593 1.0000
55.3000 6.1377 1.0000
55.3600 5.6434 1.0000
55.4200 5.2335 1.0000
55.4800 5.6770 1.0000
55.5400 4.2189 1.0000
55.6000 5.5469 1.0000
55.6600 2.4858 1.0000
55.7200 5.4396 1.0000
55.7800 5.6967 1.0000
55.8400 7.4470 1.0000
55.9000 7.0835 1.0000
55.9600 3.4436 1.0000
56.0200 9.7524 1.0000
56.0800 10.2034 1.0000
56.1400 9.9912 1.0000
56.2000 9.7692 1.0000
56.2600 8.3591 1.0000
56.3200 7.0353 1.0000
56.3800 7.2030 1.0000
56.4400 5.0969 1.0000
56.5000 5.5204 1.0000
56.5600 5.4586 1.0000
56.6200 4.1421 1.0000
56.6800 6.0842 1.0000
56.7400 7.2263 1.0000
56.8000 8.8834 1.0000
56.8600 4.3252 1.0000
56.9200 5.6558 1.0000
56.9800 5.6510 1.0000
57.0400 7.3223 1.0000
57.1000 6.1029 1.0000
57.1600 6.4199 1.0000
57.2200 6.2147 1.0000
57.2800 6.1623 1.0000
57.3400 5.9379 1.0000
57.4000 9.7928 1.0000
57.4600 10.6890 1.0000
57.5200 4.1480 1.0000
57.5800 8.8005 1.0000
57.6400 6.4461 1.0000
57.7000 6.4658 1.0000
57.7600 5.1991 1.0000
57.8200 5.9411 1.0000
57.8800 5.9539 1.0000
57.9400 8.7914 1.0000
58.0000 7.9226 1.0000
58.0600 6.1900 1.0000
58.1200 3.0564 1.0000
58.1800 6.0151 1.0000
58.2400 7.2377 1.0000
58.3000 7.0566 1.0000
58.3600 4.0292 1.0000
58.4200 5.8887 1.0000
58.4800 2.5139 1.0000
58.5400 2.5584 1.0000
58.6000 6.8985 1.0000
58.6600 7.5676 1.0000
58.7200 9.4639 1.0000
58.7800 5.0912 1.0000
58.8400 8.0674 1.0000
58.9000 6.1802 1.0000
58.9600 7.7503 1.0000
59.0200 2.2242 1.0000
59.0800 4.7161 1.0000
59.1400 5.6332 1.0000
59.2000 3.2138 1.0000
59.2600 10.0758 1.0000
59.3200 5.9886 1.0000
59.3800 6.4110 1.0000
59.4400 5.1173 1.0000
59.5000 7.8572 1.0000
59.5600 4.7858 1.0000
59.6200 3.6688 1.0000
59.6800 6.1910 1.0000
59.7400 3.0183 1.0000
59.8000 7.7909 1.0000
59.8600 4.2926 1.0000
59.9200 2.6587 1.0000
59.9800 9.4144 1.0000
60.0400 7.6271 1.0000
60.1000 2.4797 1.0000
60.1600 6.9362 1.0000
60.2200 6.5785 1.0000
60.2800 5.3482 1.0000
60.3400 5.2490 1.0000
60.4000 8.6419 1.0000
60.4600 8.6667 1.0000
60.5200 7.2432 1.0000
60.5800 13.5630 1.0000
60.6400 7.7056 1.0000
60.7000 5.6286 1.0000
60.7600 3.7422 1.0000
60.8200 8.4117 1.0000
60.8800 6.6022 1.0000
60.9400 6.0119 1.0000
61.0000 6.5759 1.0000
61.0600 10.9739 1.0000
61.1200 8.7108 1.0000
61.1800 10.5668 1.0000
61.2400 3.5349 1.0000
61.3000 11.1544 1.0000
61.3600 5.1736 1.0000
61.4200 8.9150 1.0000
61.4800 3.0391 1.0000
61.5400 5.9011 1.0000
61.6000 6.7994 1.0000
61.6600 4.8246 1.0000
61.7200 6.1977 1.0000
61.7800 9.6339 1.0000
61.8400 6.0915 1.0000
61.9000 2.2667 1.0000
61.9600 3.1677 1.0000
62.0200 13.8272 1.0000
62.0800 8.0240 1.0000
62.1400 2.5776 1.0000
62.2000 6.0875 1.0000
62.2600 6.2951 1.0000
62.3200 6.9341 1.0000
62.3800 9.6012 1.0000
62.4400 6.2760 1.0000
62.5000 3.4839 1.0000
62.5600 4.1222 1.0000
62.6200 3.2443 1.0000
62.6800 5.2895 1.0000
62.7400 4.7288 1.0000
62.8000 6.9341 1.0000
62.8600 7.8672 1.0000
62.9200 13.1120 1.0000
62.9800 3.3803 1.0000
63.0400 4.4169 1.0000
63.1000 6.6830 1.0000
63.1600 5.9534 1.0000
63.2200 6.7593 1.0000
63.2800 3.6307 1.0000
63.3400 6.9074 1.0000
63.4000 5.7419 1.0000
63.4600 2.4368 1.0000
63.5200 4.2766 1.0000
63.5800 3.6472 1.0000
63.6400 8.0954 1.0000
63.7000 7.5281 1.0000
63.7600 6.3762 1.0000
63.8200 3.4804 1.0000
63.8800 2.2300 1.0000
63.9400 6.5791 1.0000
64.0000 4.5202 1.0000
64.0600 6.4318 1.0000
64.1200 2.9785 1.0000
64.1800 7.4742 1.0000
64.2400 6.0753 1.0000
64.3000 9.3780 1.0000
64.3600 9.8000 1.0000
64.4200 6.4441 1.0000
64.4800 3.2105 1.0000
64.5400 7.8728 1.0000
64.6000 13.4262 1.0000
64.6600 7.1848 1.0000
64.7200 10.3304 1.0000
64.7800 18.4480 1.0000
64.8400 22.5019 1.0000
64.9000 26.1162 1.0000
64.9600 14.2703 1.0000
65.0200 8.2920 1.0000
65.0800 6.4037 1.0000
65.1400 9.9025 1.0000
65.2000 3.3470 1.0000
65.2600 5.6046 1.0000
65.3200 4.8423 1.0000
65.3800 5.0645 1.0000
65.4400 5.8272 1.0000
65.5000 2.4193 1.0000
65.5600 5.4187 1.0000
65.6200 4.7123 1.0000
65.6800 4.9256 1.0000
65.7400 7.3240 1.0000
65.8000 3.2719 1.0000
65.8600 4.0605 1.0000
65.9200 1.9497 1.0000
65.9800 11.9511 1.0000
66.0400 6.3357 1.0000
66.1000 7.0318 1.0000
66.1600 7.7527 1.0000
66.2200 10.1416 1.0000
66.2800 5.3494 1.0000
66.3400 4.0126 1.0000
66.4000 4.8113 1.0000
66.4600 2.2657 1.0000
66.5200 4.6442 1.0000
66.5800 12.7501 1.0000
66.6400 8.2110 1.0000
66.7000 6.8235 1.0000
66.7600 10.1963 1.0000
66.8200 7.4231 1.0000
66.8800 3.3458 1.0000
66.9400 6.6518 1.0000
67.0000 6.6891 1.0000
67.0600 3.3070 1.0000
67.1200 7.1049 1.0000
67.1800 5.3681 1.0000
67.2400 4.7145 1.0000
67.3000 10.3470 1.0000
67.3600 7.0264 1.0000
67.4200 9.6209 1.0000
67.4800 5.0685 1.0000
67.5400 4.0795 1.0000
67.6000 7.5866 1.0000
67.6600 6.3836 1.0000
67.7200 5.2461 1.0000
67.7800 3.5053 1.0000
67.8400 4.6595 1.0000
67.9000 1.4374 1.0000
67.9600 4.3493 1.0000
68.0200 9.1567 1.0000
68.0800 3.8621 1.0000
68.1400 3.4217 1.0000
68.2000 7.0845 1.0000
68.2600 5.3177 1.0000
68.3200 3.9022 1.0000
68.3800 2.3114 1.0000
68.4400 3.4124 1.0000
68.5000 5.7616 1.0000
68.5600 12.2845 1.0000
68.6200 6.1948 1.0000
68.6800 2.7037 1.0000
68.7400 8.9228 1.0000
68.8000 6.0320 1.0000
68.8600 4.4835 1.0000
68.9200 8.4347 1.0000
68.9800 7.5157 1.0000
69.0400 9.6473 1.0000
69.1000 6.5228 1.0000
69.1600 3.7244 1.0000
69.2200 5.4494 1.0000
69.2800 3.3337 1.0000
69.3400 10.2214 1.0000
69.4000 5.0644 1.0000
69.4600 7.9696 1.0000
69.5200 5.8135 1.0000
69.5800 6.0619 1.0000
69.6400 4.7039 1.0000
69.7000 5.1093 1.0000
69.7600 9.5897 1.0000
69.8200 3.7727 1.0000
69.8800 3.8180 1.0000
69.9400 4.2760 1.0000
70.0000 4.9524 1.0000
70.0600 7.1873 1.0000
70.1200 5.1584 1.0000
70.1800 8.3337 1.0000
70.2400 6.5048 1.0000
70.3000 9.0203 1.0000
70.3600 3.6900 1.0000
70.4200 6.5659 1.0000
70.4800 10.3006 1.0000
70.5400 6.3208 1.0000
70.6000 4.7334 1.0000
70.6600 11.3620 1.0000
70.7200 7.2608 1.0000
70.7800 2.2257 1.0000
70.8400 7.3124 1.0000
70.9000 9.0804 1.0000
70.9600 4.8232 1.0000
71.0200 6.3799 1.0000
71.0800 11.4060 1.0000
71.1400 9.2583 1.0000
71.2000 3.1324 1.0000
71.2600 8.7110 1.0000
71.3200 2.1669 1.0000
71.3800 5.1261 1.0000
71.4400 3.3264 1.0000
71.5000 7.0842 1.0000
71.5600 9.2380 1.0000
71.6200 4.0458 1.0000
71.6800 6.6024 1.0000
71.7400 7.8728 1.0000
71.8000 7.8960 1.0000
71.8600 5.3017 1.0000
71.9200 3.9406 1.0000
71.9800 6.1187 1.0000
72.0400 4.0742 1.0000
72.1000 4.9675 1.0000
72.1600 5.1042 1.0000
72.2200 2.8160 1.0000
72.2800 4.8433 1.0000
72.3400 5.2261 1.0000
72.4000 7.7648 1.0000
72.4600 10.2793 1.0000
72.5200 4.6736 1.0000
72.5800 9.3959 1.0000
72.6400 10.5088 1.0000
72.7000 7.7076 1.0000
72.7600 12.2122 1.0000
72.8200 10.7127 1.0000
72.8800 4.5138 1.0000
72.9400 4.6928 1.0000
73.0000 9.2698 1.0000
73.0600 3.5400 1.0000
73.1200 3.2757 1.0000
73.1800 6.5731 1.0000
73.2400 8.0143 1.0000
73.3000 6.3369 1.0000
73.3600 7.0595 1.0000
73.4200 1.6746 1.0000
73.4800 7.0102 1.0000
73.5400 7.4969 1.0000
73.6000 5.9315 1.0000
73.6600 7.4406 1.0000
73.7200 4.0770 1.0000
73.7800 1.7522 1.0000
73.8400 3.0756 1.0000
73.9000 11.6556 1.0000
73.9600 6.0308 1.0000
74.0200 8.1233 1.0000
74.0800 8.0522 1.0000
74.1400 5.2617 1.0000
74.2000 6.6845 1.0000
74.2600 7.9440 1.0000
74.3200 8.9780 1.0000
74.3800 4.0487 1.0000
74.4400 2.1250 1.0000
74.5000 10.9593 1.0000
74.5600 7.5101 1.0000
74.6200 5.9449 1.0000
74.6800 5.5251 1.0000
74.7400 3.1193 1.0000
74.8000 7.6661 1.0000
74.8600 5.0898 1.0000
74.9200 6.6404 1.0000
74.9800 3.7517 1.0000
75.0400 7.8604 1.0000
75.1000 6.7704 1.0000
75.1600 7.0747 1.0000
75.2200 2.0415 1.0000
75.2800 5.6160 1.0000
75.3400 4.4226 1.0000
75.4000 7.3159 1.0000
75.4600 4.7222 1.0000
75.5200 6.6365 1.0000
75.5800 3.2513 1.0000
75.6400 4.9950 1.0000
75.7000 5.8104 1.0000
75.7600 5.7773 1.0000
75.8200 3.5520 1.0000
75.8800 7.3751 1.0000
75.9400 4.8601 1.0000
76.0000 11.4361 1.0000
76.0600 8.1706 1.0000
76.1200 9.2090 1.0000
76.1800 7.4002 1.0000
76.2400 2.4986 1.0000
76.3000 5.7332 1.0000
76.3600 7.8725 1.0000
76.4200 5.6780 1.0000
76.4800 11.5444 1.0000
76.5400 7.0246 1.0000
76.6000 9.2952 1.0000
76.6600 6.5015 1.0000
76.7200 4.6989 1.0000
76.7800 6.9707 1.0000
76.8400 6.4681 1.0000
76.9000 6.5563 1.0000
76.9600 8.2622 1.0000
77.0200 13.4113 1.0000
77.0800 2.0744 1.0000
77.1400 7.6529 1.0000
77.2000 4.0330 1.0000
77.2600 6.2036 1.0000
77.3200 9.4395 1.0000
77.3800 11.6708 1.0000
77.4400 6.6163 1.0000
77.5000 6.5386 1.0000
77.5600 6.5241 1.0000
77.6200 4.1556 1.0000
77.6800 2.1738 1.0000
77.7400 3.8948 1.0000
77.8000 4.7422 1.0000
77.8600 5.4376 1.0000
77.9200 8.8051 1.0000
77.9800 3.2451 1.0000
78.0400 3.3759 1.0000
78.1000 3.2453 1.0000
78.1600 5.9619 1.0000
78.2200 8.1680 1.0000
78.2800 4.0911 1.0000
78.3400 2.8776 1.0000
78.4000 7.1024 1.0000
78.4600 12.6697 1.0000
78.5200 7.3278 1.0000
78.5800 6.6179 1.0000
78.6400 6.6853 1.0000
78.7000 5.6012 1.0000
78.7600 6.6052 1.0000
78.8200 8.8661 1.0000
78.8800 8.8536 1.0000
78.9400 5.5176 1.0000
79.0000 2.7513 1.0000
79.0600 7.1238 1.0000
79.1200 5.3535 1.0000
79.1800 2.7023 1.0000
79.2400 3.3832 1.0000
79.3000 7.2667 1.0000
79.3600 5.2473 1.0000
79.4200 5.3771 1.0000
79.4800 6.1656 1.0000
79.5400 6.7230 1.0000
79.6000 7.6254 1.0000
79.6600 6.6831 1.0000
79.7200 7.0273 1.0000
79.7800 7.2927 1.0000
79.8400 8.3038 1.0000
79.9000 6.6426 1.0000
79.9600 4.4750 1.0000
80.0200 4.7052 1.0000
80.0800 6.9805 1.0000
80.1400 8.2539 1.0000
80.2000 10.9119 1.0000
80.2600 7.6607 1.0000
80.3200 11.2784 1.0000
80.3800 4.9657 1.0000
80.4400 3.5411 1.0000
80.5000 6.0600 1.0000
80.5600 4.7411 1.0000
80.6200 5.1688 1.0000
80.6800 6.8313 1.0000
80.7400 11.9225 1.0000
80.8000 9.6657 1.0000
80.8600 6.1745 1.0000
80.9200 7.3320 1.0000
80.9800 4.9413 1.0000
81.0400 11.7621 1.0000
81.1000 4.5179 1.0000
81.1600 7.5289 1.0000
81.2200 10.2010 1.0000
81.2800 5.2798 1.0000
81.3400 3.6224 1.0000
81.4000 7.7948 1.0000
81.4600 5.0486 1.0000
81.5200 7.2282 1.0000
81.5800 7.1935 1.0000
81.6400 6.6090 1.0000
81.7000 6.2255 1.0000
81.7600 4.7566 1.0000
81.8200 5.7523 1.0000
81.8800 10.7318 1.0000
81.9400 12.5000 1.0000
82.0000 18.1023 1.0000
82.0600 41.7428 1.0000
82.1200 38.7811 1.0000
82.1800 42.7816 1.0000
82.2400 28.6299 1.0000
82.3000 14.2042 1.0000
82.3600 4.2221 1.0000
82.4200 7.6212 1.0000
82.4800 6.6475 1.0000
82.5400 5.1833 1.0000
82.6000 16.4671 1.0000
82.6600 4.9473 1.0000
82.7200 6.8051 1.0000
82.7800 8.4109 1.0000
82.8400 5.9398 1.0000
82.9000 4.6183 1.0000
82.9600 3.1033 1.0000
83.0200 5.7787 1.0000
83.0800 6.0140 1.0000
83.1400 4.3362 1.0000
83.2000 6.7778 1.0000
83.2600 12.2682 1.0000
83.3200 5.7177 1.0000
83.3800 6.2633 1.0000
83.4400 4.1317 1.0000
83.5000 5.6700 1.0000
83.5600 2.6820 1.0000
83.6200 5.1373 1.0000
83.6800 7.7221 1.0000
83.7400 6.7885 1.0000
83.8000 6.2180 1.0000
83.8600 7.7476 1.0000
83.9200 10.6423 1.0000
83.9800 6.1634 1.0000
84.0400 5.8934 1.0000
84.1000 6.6363 1.0000
84.1600 8.8134 1.0000
84.2200 8.7761 1.0000
84.2800 5.1354 1.0000
84.3400 15.6469 1.0000
84.4000 3.0695 1.0000
84.4600 5.9940 1.0000
84.5200 6.4104 1.0000
84.5800 4.8412 1.0000
84.6400 5.2903 1.0000
84.7000 8.9619 1.0000
84.7600 8.4254 1.0000
84.8200 5.8393 1.0000
84.8800 7.1307 1.0000
84.9400 7.1044 1.0000
85.0000 8.8688 1.0000
85.0600 5.1987 1.0000
85.1200 3.7541 1.0000
85.1800 5.5456 1.0000
85.2400 4.3698 1.0000
85.3000 4.6224 1.0000
85.3600 7.2654 1.0000
85.4200 9.1969 1.0000
85.4800 9.6607 1.0000
85.5400 11.0596 1.0000
85.6000 9.3613 1.0000
85.6600 4.7309 1.0000
85.7200 6.9292 1.0000
85.7800 5.1413 1.0000
85.8400 4.7267 1.0000
85.9000 6.2453 1.0000
85.9600 3.4572 1.0000
86.0200 5.7458 1.0000
86.0800 7.0160 1.0000
86.1400 5.5891 1.0000
86.2000 7.1515 1.0000
86.2600 6.3804 1.0000
86.3200 5.3548 1.0000
86.3800 2.0820 1.0000
86.4400 4.7630 1.0000
86.5000 5.6036 1.0000
86.5600 4.3364 1.0000
86.6200 5.7811 1.0000
86.6800 5.2868 1.0000
86.7400 7.2463 1.0000
86.8000 1.3007 1.0000
86.8600 5.6117 1.0000
86.9200 5.4533 1.0000
86.9800 4.3089 1.0000
87.0400 12.5324 1.0000
87.1000 5.6773 1.0000
87.1600 5.1252 1.0000
87.2200 8.0403 1.0000
87.2800 9.0584 1.0000
87.3400 9.3130 1.0000
87.4000 6.2578 1.0000
87.4600 6.7295 1.0000
87.5200 10.1544 1.0000
87.5800 5.0824 1.0000
87.6400 5.3299 1.0000
87.7000 7.7339 1.0000
87.7600 6.2524 1.0000
87.8200 4.8117 1.0000
87.8800 7.7704 1.0000
87.9400 7.5074 1.0000
88.0000 5.3423 1.0000
88.0600 7.2010 1.0000
88.1200 6.3521 1.0000
88.1800 16.0020 1.0000
88.2400 7.5132 1.0000
88.3000 7.1135 1.0000
88.3600 5.2069 1.0000
88.4200 7.2506 1.0000
88.4800 4.4156 1.0000
88.5400 1.7638 1.0000
88.6000 5.3526 1.0000
88.6600 5.5548 1.0000
88.7200 6.5308 1.0000
88.7800 10.7979 1.0000
88.8400 5.3101 1.0000
88.9000 3.8424 1.0000
88.9600 3.9375 1.0000
89.0200 11.6961 1.0000
89.0800 5.7957 1.0000
89.1400 5.3122 1.0000
89.2000 2.7957 1.0000
89.2600 6.4404 1.0000
89.3200 8.8514 1.0000
89.3800 7.4207 1.0000
89.4400 9.7594 1.0000
89.5000 8.0409 1.0000
89.5600 8.9945 1.0000
89.6200 1.2929 1.0000
89.6800 6.4465 1.0000
89.7400 4.4431 1.0000
89.8000 13.8397 1.0000
89.8600 12.7714 1.0000
89.9200 9.2769 1.0000
89.9800 7.5699 1.0000
90.0400 2.8170 1.0000
90.1000 6.2764 1.0000
90.1600 6.9618 1.0000
90.2200 6.7133 1.0000
90.2800 5.8011 1.0000
90.3400 1.9602 1.0000
90.4000 6.7652 1.0000
90.4600 4.0338 1.0000
90.5200 8.4075 1.0000
90.5800 10.3068 1.0000
90.6400 7.8746 1.0000
90.7000 0.5121 1.0000
90.7600 5.7458 1.0000
90.8200 3.0937 1.0000
90.8800 7.2327 1.0000
90.9400 6.9348 1.0000
91.0000 3.8790 1.0000
91.0600 9.5864 1.0000
91.1200 16.2714 1.0000
91.1800 9.4811 1.0000
91.2400 5.8379 1.0000
91.3000 3.9459 1.0000
91.3600 6.3707 1.0000
91.4200 5.4109 1.0000
91.4800 10.2073 1.0000
91.5400 5.1227 1.0000
91.6000 5.9656 1.0000
91.6600 10.2307 1.0000
91.7200 5.0256 1.0000
91.7800 4.2466 1.0000
91.8400 11.7459 1.0000
91.9000 11.7946 1.0000
91.9600 8.1312 1.0000
92.0200 5.9026 1.0000
92.0800 3.8280 1.0000
92.1400 5.1191 1.0000
92.2000 3.7878 1.0000
92.2600 6.4451 1.0000
92.3200 2.6447 1.0000
92.3800 6.1413 1.0000
92.4400 8.3777 1.0000
92.5000 9.9857 1.0000
92.5600 2.6717 1.0000
92.6200 8.3713 1.0000
92.6800 4.9917 1.0000
92.7400 6.4047 1.0000
92.8000 8.1455 1.0000
92.8600 8.0935 1.0000
92.9200 7.8022 1.0000
92.9800 5.6140 1.0000
93.0400 5.7856 1.0000
93.1000 9.7384 1.0000
93.1600 4.9469 1.0000
93.2200 4.6660 1.0000
93.2800 9.7135 1.0000
93.3400 7.2393 1.0000
93.4000 7.6615 1.0000
93.4600 9.9185 1.0000
93.5200 4.6816 1.0000
93.5800 5.7515 1.0000
93.6400 6.1867 1.0000
93.7000 4.2746 1.0000
93.7600 7.1496 1.0000
93.8200 6.3210 1.0000
93.8800 10.6534 1.0000
93.9400 9.0465 1.0000
94.0000 8.2769 1.0000
94.0600 10.0824 1.0000
94.1200 3.5353 1.0000
94.1800 5.6034 1.0000
94.2400 6.1522 1.0000
94.3000 8.4823 1.0000
94.3600 5.4954 1.0000
94.4200 6.1806 1.0000
94.4800 7.2683 1.0000
94.5400 7.6729 1.0000
94.6000 5.7847 1.0000
94.6600 6.1163 1.0000
94.7200 5.2708 1.0000
94.7800 7.2839 1.0000
94.8400 5.7685 1.0000
94.9000 10.6406 1.0000
94.9600 4.6301 1.0000
95.0200 6.9507 1.0000
95.0800 6.6648 1.0000
95.1400 7.0095 1.0000
95.2000 4.3229 1.0000
95.2600 3.7139 1.0000
95.3200 1.5500 1.0000
95.3800 5.4994 1.0000
95.4400 9.2339 1.0000
95.5000 4.9133 1.0000
95.5600 3.7443 1.0000
95.6200 7.1431 1.0000
95.6800 3.2443 1.0000
95.7400 12.2334 1.0000
95.8000 4.8558 1.0000
95.8600 9.3044 1.0000
95.9200 4.6564 1.0000
95.9800 6.8635 1.0000
96.0400 2.7445 1.0000
96.1000 3.5658 1.0000
96.1600 2.3507 1.0000
96.2200 0.2477 1.0000
96.2800 5.0039 1.0000
96.3400 6.7499 1.0000
96.4000 10.0464 1.0000
96.4600 9.6579 1.0000
96.5200 5.2822 1.0000
96.5800 7.0733 1.0000
96.6400 9.0895 1.0000
96.7000 11.9795 1.0000
96.7600 18.5214 1.0000
96.8200 8.7963 1.0000
96.8800 6.0526 1.0000
96.9400 7.3269 1.0000
97.0000 4.8277 1.0000
97.0600 3.1328 1.0000
97.1200 7.3528 1.0000
97.1800 4.7193 1.0000
97.2400 8.4899 1.0000
97.3000 5.9003 1.0000
97.3600 6.7768 1.0000
97.4200 6.6803 1.0000
97.4800 8.3894 1.0000
97.5400 11.3096 1.0000
97.6000 5.6436 1.0000
97.6600 6.7402 1.0000
97.7200 7.2267 1.0000
97.7800 4.4426 1.0000
97.8400 5.5432 1.0000
97.9000 6.1568 1.0000
97.9600 4.8390 1.0000
98.0200 4.2594 1.0000
98.0800 3.6320 1.0000
98.1400 6.3893 1.0000
98.2000 3.5182 1.0000
98.2600 6.0068 1.0000
98.3200 2.2104 1.0000
98.3800 11.4341 1.0000
98.4400 4.5325 1.0000
98.5000 5.9534 1.0000
98.5600 16.1664 1.0000
98.6200 28.7669 1.0000
98.6800 22.5357 1.0000
98.7400 17.1804 1.0000
98.8000 11.8297 1.0000
98.8600 10.5677 1.0000
98.9200 9.1892 1.0000
98.9800 8.7900 1.0000
99.0400 6.4762 1.0000
99.1000 7.7330 1.0000
99.1600 11.5950 1.0000
99.2200 1.0419 1.0000
99.2800 2.2079 1.0000
99.3400 8.6121 1.0000
99.4000 8.7687 1.0000
99.4600 7.5338 1.0000
99.5200 5.5039 1.0000
99.5800 3.2160 1.0000
99.6400 2.0960 1.0000
99.7000 2.1875 1.0000
99.7600 7.7582 1.0000
99.8200 3.5745 1.0000
99.8800 6.6163 1.0000
99.9400 5.6784 1.0000
100.0000 3.7671 1.0000
100.0600 4.0029 1.0000
100.1200 8.4358 1.0000
100.1800 9.4173 1.0000
100.2400 8.1500 1.0000
100.3000 3.5599 1.0000
100.3600 7.3233 1.0000
100.4200 4.8059 1.0000
100.4800 3.0232 1.0000
100.5400 2.2788 1.0000
100.6000 8.7376 1.0000
100.6600 6.0083 1.0000
100.7200 5.8668 1.0000
100.7800 4.8723 1.0000
100.8400 4.7372 1.0000
100.9000 8.0758 1.0000
100.9600 4.1808 1.0000
101.0200 7.9075 1.0000
101.0800 9.8772 1.0000
101.1400 9.8970 1.0000
101.2000 5.4323 1.0000
101.2600 2.4826 1.0000
101.3200 7.5020 1.0000
101.3800 6.0592 1.0000
101.4400 4.2228 1.0000
101.5000 11.1709 1.0000
101.5600 4.7050 1.0000
101.6200 9.6379 1.0000
101.6800 11.5105 1.0000
101.7400 7.0523 1.0000
101.8000 11.1701 1.0000
101.8600 7.3127 1.0000
101.9200 5.3144 1.0000
101.9800 10.6732 1.0000
102.0400 11.3789 1.0000
102.1000 4.1842 1.0000
102.1600 7.7755 1.0000
102.2200 4.2094 1.0000
102.2800 6.9530 1.0000
102.3400 4.4645 1.0000
102.4000 7.0074 1.0000
102.4600 5.9042 1.0000
102.5200 4.5648 1.0000
102.5800 12.9484 1.0000
102.6400 7.9330 1.0000
102.7000 9.8651 1.0000
102.7600 9.1358 1.0000
102.8200 5.2880 1.0000
102.8800 7.3422 1.0000
102.9400 4.4894 1.0000
103.0000 7.7696 1.0000
103.0600 11.5737 1.0000
103.1200 6.8724 1.0000
103.1800 3.3030 1.0000
103.2400 6.3965 1.0000
103.3000 9.6190 1.0000
103.3600 5.5566 1.0000
103.4200 6.5070 1.0000
103.4800 2.6912 1.0000
103.5400 9.7078 1.0000
103.6000 4.6723 1.0000
103.6600 5.7485 1.0000
103.7200 6.3434 1.0000
103.7800 7.5692 1.0000
103.8400 9.1875 1.0000
103.9000 4.2243 1.0000
103.9600 6.8091 1.0000
104.0200 3.0635 1.0000
104.0800 7.0144 1.0000
104.1400 3.9143 1.0000
104.2000 2.7026 1.0000
104.2600 10.0550 1.0000
104.3200 6.4207 1.0000
104.3800 1.0944 1.0000
104.4400 4.8219 1.0000
104.5000 5.3709 1.0000
104.5600 2.6516 1.0000
104.6200 7.9118 1.0000
104.6800 6.2338 1.0000
104.7400 6.0677 1.0000
104.8000 8.8171 1.0000
104.8600 6.0989 1.0000
104.9200 8.8148 1.0000
104.9800 5.9200 1.0000
105.0400 4.8912 1.0000
105.1000 7.1377 1.0000
105.1600 7.7187 1.0000
105.2200 5.0763 1.0000
105.2800 5.7748 1.0000
105.3400 11.6791 1.0000
105.4000 8.2384 1.0000
105.4600 3.8943 1.0000
105.5200 5.3713 1.0000
105.5800 8.0394 1.0000
105.6400 9.0585 1.0000
105.7000 4.1401 1.0000
105.7600 6.3333 1.0000
105.8200 7.0025 1.0000
105.8800 5.7290 1.0000
105.9400 3.1394 1.0000
106.0000 6.4908 1.0000
106.0600 14.8681 1.0000
106.1200 12.9502 1.0000
106.1800 5.7883 1.0000
106.2400 6.4755 1.0000
106.3000 5.9941 1.0000
106.3600 5.4763 1.0000
106.4200 4.5208 1.0000
106.4800 5.6446 1.0000
106.5400 9.0465 1.0000
106.6000 5.5629 1.0000
106.6600 9.8944 1.0000
106.7200 5.3947 1.0000
106.7800 2.7797 1.0000
106.8400 8.5113 1.0000
106.9000 5.2925 1.0000
106.9600 8.3482 1.0000
107.0200 4.6866 1.0000
107.0800 9.1909 1.0000
107.1400 3.5461 1.0000
107.2000 10.0445 1.0000
107.2600 6.2717 1.0000
107.3200 7.8973 1.0000
107.3800 4.7254 1.0000
107.4400 9.0834 1.0000
107.5000 16.1793 1.0000
107.5600 6.6846 1.0000
107.6200 3.3761 1.0000
107.6800 3.0794 1.0000
107.7400 2.4926 1.0000
107.8000 5.6418 1.0000
107.8600 3.4994 1.0000
107.9200 9.2914 1.0000
107.9800 8.9186 1.0000
108.0400 3.8009 1.0000
108.1000 4.1054 1.0000
108.1600 4.9241 1.0000
108.2200 6.0235 1.0000
108.2800 9.2466 1.0000
[...]
67.0000 5.7359 1.0000
67.0600 4.2234 1.0000
67.1200 5.5952 1.0000
67.1800 9.5511 1.0000
67.2400 5.2800 1.0000
67.3000 8.2935 1.0000
67.3600 7.8482 1.0000
67.4200 5.5475 1.0000
67.4800 2.0842 1.0000
67.5400 6.7445 1.0000
67.6000 5.4829 1.0000
67.6600 3.7089 1.0000
67.7200 4.6767 1.0000
67.7800 5.2147 1.0000
67.8400 10.1425 1.0000
67.9000 4.7450 1.0000
67.9600 8.4807 1.0000
68.0200 5.0988 1.0000
68.0800 3.5511 1.0000
68.1400 10.9514 1.0000
68.2000 5.4034 1.0000
68.2600 9.2866 1.0000
68.3200 4.7789 1.0000
68.3800 7.0649 1.0000
68.4400 14.2628 1.0000
68.5000 6.9230 1.0000
68.5600 10.1614 1.0000
68.6200 4.9771 1.0000
68.6800 9.2257 1.0000
68.7400 4.7817 1.0000
68.8000 7.1583 1.0000
68.8600 8.7414 1.0000
68.9200 3.7460 1.0000
68.9800 3.1561 1.0000
69.0400 8.6742 1.0000
69.1000 6.0804 1.0000
69.1600 9.1757 1.0000
69.2200 4.6009 1.0000
69.2800 6.9737 1.0000
69.3400 5.2281 1.0000
69.4000 2.1715 1.0000
69.4600 9.3442 1.0000
69.5200 6.4003 1.0000
69.5800 7.2152 1.0000
69.6400 3.6393 1.0000
69.7000 9.8593 1.0000
69.7600 3.9597 1.0000
69.8200 5.1194 1.0000
69.8800 5.9733 1.0000
69.9400 10.4560 1.0000
70.0000 5.5158 1.0000
70.0600 4.4452 1.0000
70.1200 5.1501 1.0000
70.1800 6.9858 1.0000
70.2400 4.9350 1.0000
70.3000 9.0720 1.0000
70.3600 2.3098 1.0000
70.4200 7.1665 1.0000
70.4800 4.5639 1.0000
70.5400 5.3589 1.0000
70.6000 7.7178 1.0000
70.6600 6.2356 1.0000
70.7200 6.5885 1.0000
70.7800 6.0512 1.0000
70.8400 6.4050 1.0000
70.9000 2.1137 1.0000
70.9600 8.0666 1.0000
71.0200 3.1850 1.0000
71.0800 8.8373 1.0000
71.1400 9.7403 1.0000
71.2000 3.0712 1.0000
71.2600 6.5099 1.0000
71.3200 6.1082 1.0000
71.3800 3.6714 1.0000
71.4400 2.8961 1.0000
71.5000 6.5984 1.0000
71.5600 4.9654 1.0000
71.6200 5.9752 1.0000
71.6800 7.7097 1.0000
71.7400 7.0106 1.0000
71.8000 9.3393 1.0000
71.8600 5.5610 1.0000
71.9200 9.7811 1.0000
71.9800 5.0002 1.0000
72.0400 6.9401 1.0000
72.1000 1.7120 1.0000
72.1600 3.5502 1.0000
72.2200 9.5323 1.0000
72.2800 4.8137 1.0000
72.3400 3.0992 1.0000
72.4000 11.0657 1.0000
72.4600 4.8323 1.0000
72.5200 6.6778 1.0000
72.5800 7.6509 1.0000
72.6400 11.3590 1.0000
72.7000 9.4317 1.0000
72.7600 10.7436 1.0000
72.8200 3.0841 1.0000
72.8800 8.2597 1.0000
72.9400 3.0229 1.0000
73.0000 11.2006 1.0000
73.0600 6.7408 1.0000
73.1200 8.4095 1.0000
73.1800 5.6492 1.0000
73.2400 5.1352 1.0000
73.3000 8.1981 1.0000
73.3600 9.1320 1.0000
73.4200 5.6846 1.0000
73.4800 6.1517 1.0000
73.5400 9.2498 1.0000
73.6000 7.9807 1.0000
73.6600 3.6648 1.0000
73.7200 7.4627 1.0000
73.7800 5.5449 1.0000
73.8400 6.8048 1.0000
73.9000 7.7674 1.0000
73.9600 8.4657 1.0000
74.0200 8.2257 1.0000
74.0800 5.7502 1.0000
74.1400 5.8830 1.0000
74.2000 9.7945 1.0000
74.2600 4.0013 1.0000
74.3200 7.9284 1.0000
74.3800 1.5760 1.0000
74.4400 3.4228 1.0000
74.5000 3.4007 1.0000
74.5600 3.9077 1.0000
74.6200 5.0358 1.0000
74.6800 3.9866 1.0000
74.7400 3.4325 1.0000
74.8000 2.8924 1.0000
74.8600 14.1296 1.0000
74.9200 7.6371 1.0000
74.9800 7.7349 1.0000
75.0400 12.6636 1.0000
75.1000 5.4642 1.0000
75.1600 10.7557 1.0000
75.2200 6.3827 1.0000
75.2800 5.1374 1.0000
75.3400 4.3892 1.0000
75.4000 4.5767 1.0000
75.4600 3.3044 1.0000
75.5200 2.4570 1.0000
75.5800 8.1077 1.0000
75.6400 7.8505 1.0000
75.7000 2.7251 1.0000
75.7600 5.8448 1.0000
75.8200 8.7542 1.0000
75.8800 6.1517 1.0000
75.9400 9.4102 1.0000
76.0000 5.1745 1.0000
76.0600 5.1527 1.0000
76.1200 9.7341 1.0000
76.1800 3.1143 1.0000
76.2400 6.8213 1.0000
76.3000 6.4504 1.0000
76.3600 11.3233 1.0000
76.4200 9.4175 1.0000
76.4800 3.7508 1.0000
76.5400 7.0225 1.0000
76.6000 4.5563 1.0000
76.6600 6.3391 1.0000
76.7200 3.1542 1.0000
76.7800 5.2267 1.0000
76.8400 2.3377 1.0000
76.9000 4.0781 1.0000
76.9600 5.9764 1.0000
77.0200 5.0425 1.0000
77.0800 6.8616 1.0000
77.1400 7.8004 1.0000
77.2000 6.0659 1.0000
77.2600 2.2473 1.0000
77.3200 6.2009 1.0000
77.3800 4.5582 1.0000
77.4400 6.8009 1.0000
77.5000 7.3639 1.0000
77.5600 7.6720 1.0000
77.6200 5.2375 1.0000
77.6800 4.4127 1.0000
77.7400 6.0913 1.0000
77.8000 7.6170 1.0000
77.8600 10.0438 1.0000
77.9200 5.7702 1.0000
77.9800 1.1705 1.0000
78.0400 2.3896 1.0000
78.1000 7.3207 1.0000
78.1600 4.5583 1.0000
78.2200 3.6485 1.0000
78.2800 5.3959 1.0000
78.3400 8.1916 1.0000
78.4000 8.3129 1.0000
78.4600 9.1406 1.0000
78.5200 2.1059 1.0000
78.5800 6.4361 1.0000
78.6400 4.4282 1.0000
78.7000 6.0547 1.0000
78.7600 7.8326 1.0000
78.8200 2.0480 1.0000
78.8800 5.3124 1.0000
78.9400 2.8495 1.0000
79.0000 3.4753 1.0000
79.0600 10.6634 1.0000
79.1200 1.6831 1.0000
79.1800 4.8402 1.0000
79.2400 4.8231 1.0000
79.3000 4.2223 1.0000
79.3600 7.2317 1.0000
79.4200 6.6252 1.0000
79.4800 2.5286 1.0000
79.5400 6.1835 1.0000
79.6000 6.0477 1.0000
79.6600 13.0423 1.0000
79.7200 5.3745 1.0000
79.7800 6.1231 1.0000
79.8400 9.1218 1.0000
79.9000 5.8721 1.0000
79.9600 5.5488 1.0000
80.0200 7.1405 1.0000
80.0800 11.7156 1.0000
80.1400 2.9402 1.0000
80.2000 4.2545 1.0000
80.2600 6.5562 1.0000
80.3200 2.7920 1.0000
80.3800 2.6270 1.0000
80.4400 7.9040 1.0000
80.5000 7.8904 1.0000
80.5600 2.1323 1.0000
80.6200 8.1289 1.0000
80.6800 3.7437 1.0000
80.7400 4.4145 1.0000
80.8000 7.4840 1.0000
80.8600 7.4661 1.0000
80.9200 3.1889 1.0000
80.9800 5.3325 1.0000
81.0400 5.6137 1.0000
81.1000 10.0360 1.0000
81.1600 12.6644 1.0000
81.2200 5.2416 1.0000
81.2800 6.9240 1.0000
81.3400 8.0214 1.0000
81.4000 12.1731 1.0000
81.4600 4.6145 1.0000
81.5200 5.8883 1.0000
81.5800 6.0589 1.0000
81.6400 11.9202 1.0000
81.7000 5.2223 1.0000
81.7600 7.7557 1.0000
81.8200 10.8229 1.0000
81.8800 2.0524 1.0000
81.9400 13.9638 1.0000
82.0000 18.5828 1.0000
82.0600 43.9876 1.0000
82.1200 48.6774 1.0000
82.1800 36.1228 1.0000
82.2400 17.7214 1.0000
82.3000 15.4282 1.0000
82.3600 13.1311 1.0000
82.4200 7.0309 1.0000
82.4800 5.4620 1.0000
82.5400 2.4146 1.0000
82.6000 6.0875 1.0000
82.6600 2.2822 1.0000
82.7200 3.5997 1.0000
82.7800 5.4732 1.0000
82.8400 4.3125 1.0000
82.9000 10.5832 1.0000
82.9600 7.4025 1.0000
83.0200 6.6680 1.0000
83.0800 10.2111 1.0000
83.1400 6.3749 1.0000
83.2000 5.4080 1.0000
83.2600 6.0121 1.0000
83.3200 3.1292 1.0000
83.3800 7.5153 1.0000
83.4400 9.9019 1.0000
83.5000 14.2084 1.0000
83.5600 4.9327 1.0000
83.6200 2.2186 1.0000
83.6800 3.3934 1.0000
83.7400 4.3601 1.0000
83.8000 7.3576 1.0000
83.8600 8.2152 1.0000
83.9200 4.1832 1.0000
83.9800 7.7240 1.0000
84.0400 6.0834 1.0000
84.1000 3.8521 1.0000
84.1600 7.5008 1.0000
84.2200 5.9362 1.0000
84.2800 3.6720 1.0000
84.3400 6.6076 1.0000
84.4000 6.0162 1.0000
84.4600 4.2294 1.0000
84.5200 2.6981 1.0000
84.5800 6.2059 1.0000
84.6400 2.1288 1.0000
84.7000 4.6142 1.0000
84.7600 7.5836 1.0000
84.8200 5.5745 1.0000
84.8800 5.7206 1.0000
84.9400 7.0760 1.0000
85.0000 7.2272 1.0000
85.0600 1.6503 1.0000
85.1200 3.9178 1.0000
85.1800 10.2011 1.0000
85.2400 9.0284 1.0000
85.3000 5.0855 1.0000
85.3600 2.4032 1.0000
85.4200 8.0727 1.0000
85.4800 4.3997 1.0000
85.5400 8.5343 1.0000
85.6000 5.4470 1.0000
85.6600 7.6474 1.0000
85.7200 14.3242 1.0000
85.7800 6.5079 1.0000
85.8400 5.2173 1.0000
85.9000 8.3179 1.0000
85.9600 7.4047 1.0000
86.0200 7.0099 1.0000
86.0800 7.6207 1.0000
86.1400 5.0442 1.0000
86.2000 3.9221 1.0000
86.2600 4.8141 1.0000
86.3200 4.8751 1.0000
86.3800 6.3715 1.0000
86.4400 3.1631 1.0000
86.5000 6.0124 1.0000
86.5600 2.2820 1.0000
86.6200 8.3579 1.0000
86.6800 6.5210 1.0000
86.7400 5.1289 1.0000
86.8000 12.7764 1.0000
86.8600 14.3261 1.0000
86.9200 5.0699 1.0000
86.9800 2.2837 1.0000
87.0400 3.4886 1.0000
87.1000 5.3629 1.0000
87.1600 3.0500 1.0000
87.2200 5.7339 1.0000
87.2800 6.0563 1.0000
87.3400 4.1357 1.0000
87.4000 9.2675 1.0000
87.4600 8.9324 1.0000
87.5200 4.8251 1.0000
87.5800 4.3021 1.0000
87.6400 5.8984 1.0000
87.7000 8.6841 1.0000
87.7600 8.0044 1.0000
87.8200 8.8160 1.0000
87.8800 6.5250 1.0000
87.9400 4.4206 1.0000
88.0000 5.2770 1.0000
88.0600 6.5184 1.0000
88.1200 10.1197 1.0000
88.1800 8.2813 1.0000
88.2400 8.4994 1.0000
88.3000 6.6657 1.0000
88.3600 9.6379 1.0000
88.4200 7.5970 1.0000
88.4800 6.5400 1.0000
88.5400 9.7705 1.0000
88.6000 7.2929 1.0000
88.6600 6.4994 1.0000
88.7200 4.4054 1.0000
88.7800 10.3542 1.0000
88.8400 6.2080 1.0000
88.9000 7.8416 1.0000
88.9600 6.9596 1.0000
89.0200 3.1598 1.0000
89.0800 5.3669 1.0000
89.1400 5.8321 1.0000
89.2000 4.1286 1.0000
89.2600 5.6402 1.0000
89.3200 4.0733 1.0000
89.3800 5.2308 1.0000
89.4400 7.0382 1.0000
89.5000 8.2051 1.0000
89.5600 2.4896 1.0000
89.6200 3.9570 1.0000
89.6800 6.6712 1.0000
89.7400 5.1982 1.0000
89.8000 8.4564 1.0000
89.8600 8.4041 1.0000
89.9200 5.5023 1.0000
89.9800 8.2936 1.0000
90.0400 7.4623 1.0000
90.1000 5.5510 1.0000
90.1600 9.3180 1.0000
90.2200 8.1850 1.0000
90.2800 8.0331 1.0000
90.3400 3.8451 1.0000
90.4000 7.9637 1.0000
90.4600 4.0775 1.0000
90.5200 6.4467 1.0000
90.5800 5.1802 1.0000
90.6400 6.7621 1.0000
90.7000 1.9225 1.0000
90.7600 4.4833 1.0000
90.8200 4.5347 1.0000
90.8800 7.7510 1.0000
90.9400 6.9958 1.0000
91.0000 5.4710 1.0000
91.0600 7.4844 1.0000
91.1200 5.1531 1.0000
91.1800 7.1276 1.0000
91.2400 6.4877 1.0000
91.3000 6.0998 1.0000
91.3600 7.2225 1.0000
91.4200 4.6807 1.0000
91.4800 6.7659 1.0000
91.5400 5.1805 1.0000
91.6000 6.7474 1.0000
91.6600 2.5778 1.0000
91.7200 6.8353 1.0000
91.7800 6.3402 1.0000
91.8400 4.9214 1.0000
91.9000 11.0782 1.0000
91.9600 7.9394 1.0000
92.0200 7.0051 1.0000
92.0800 6.9679 1.0000
92.1400 8.3304 1.0000
92.2000 4.1159 1.0000
92.2600 9.2671 1.0000
92.3200 8.7976 1.0000
92.3800 4.2937 1.0000
92.4400 6.8041 1.0000
92.5000 10.3373 1.0000
92.5600 9.0961 1.0000
92.6200 3.4067 1.0000
92.6800 8.8861 1.0000
92.7400 10.4793 1.0000
92.8000 7.7891 1.0000
92.8600 5.2472 1.0000
92.9200 5.2298 1.0000
92.9800 7.5070 1.0000
93.0400 8.1930 1.0000
93.1000 13.3935 1.0000
93.1600 8.0740 1.0000
93.2200 10.6259 1.0000
93.2800 6.3283 1.0000
93.3400 3.0414 1.0000
93.4000 4.9734 1.0000
93.4600 6.6570 1.0000
93.5200 6.5140 1.0000
93.5800 5.3988 1.0000
93.6400 4.9774 1.0000
93.7000 5.5091 1.0000
93.7600 3.0778 1.0000
93.8200 4.2959 1.0000
93.8800 4.1332 1.0000
93.9400 7.1799 1.0000
94.0000 11.1533 1.0000
94.0600 7.0278 1.0000
94.1200 3.1547 1.0000
94.1800 2.1416 1.0000
94.2400 5.4327 1.0000
94.3000 9.2910 1.0000
94.3600 7.0753 1.0000
94.4200 4.9257 1.0000
94.4800 5.9698 1.0000
94.5400 4.9296 1.0000
94.6000 5.2295 1.0000
94.6600 7.6200 1.0000
94.7200 9.9849 1.0000
94.7800 8.6157 1.0000
94.8400 8.6976 1.0000
94.9000 6.3183 1.0000
94.9600 3.7500 1.0000
95.0200 11.8887 1.0000
95.0800 4.0948 1.0000
95.1400 11.3147 1.0000
95.2000 6.9998 1.0000
95.2600 6.2470 1.0000
95.3200 7.6223 1.0000
95.3800 5.0987 1.0000
95.4400 8.5633 1.0000
95.5000 4.6351 1.0000
95.5600 8.3220 1.0000
95.6200 11.2945 1.0000
95.6800 8.2343 1.0000
95.7400 6.6191 1.0000
95.8000 6.0000 1.0000
95.8600 4.7835 1.0000
95.9200 4.0328 1.0000
95.9800 5.4365 1.0000
96.0400 5.3287 1.0000
96.1000 8.3681 1.0000
96.1600 7.9519 1.0000
96.2200 4.8237 1.0000
96.2800 7.8923 1.0000
96.3400 3.1729 1.0000
96.4000 6.8733 1.0000
96.4600 9.3491 1.0000
96.5200 3.1719 1.0000
96.5800 6.9236 1.0000
96.6400 6.8573 1.0000
96.7000 8.2143 1.0000
96.7600 7.6845 1.0000
96.8200 5.7757 1.0000
96.8800 4.0875 1.0000
96.9400 1.3563 1.0000
97.0000 9.6112 1.0000
97.0600 7.6546 1.0000
97.1200 2.3928 1.0000
97.1800 4.9439 1.0000
97.2400 9.7814 1.0000
97.3000 4.3043 1.0000
97.3600 11.9117 1.0000
97.4200 10.6245 1.0000
97.4800 3.2592 1.0000
97.5400 2.9617 1.0000
97.6000 15.4243 1.0000
97.6600 13.6988 1.0000
97.7200 7.1680 1.0000
97.7800 6.0881 1.0000
97.8400 5.5860 1.0000
97.9000 7.0981 1.0000
97.9600 5.7988 1.0000
98.0200 2.8006 1.0000
98.0800 8.9917 1.0000
98.1400 2.4070 1.0000
98.2000 11.9570 1.0000
98.2600 7.5299 1.0000
98.3200 10.1468 1.0000
98.3800 13.1361 1.0000
98.4400 8.3619 1.0000
98.5000 13.7520 1.0000
98.5600 19.0343 1.0000
98.6200 32.6242 1.0000
98.6800 24.1179 1.0000
98.7400 8.8495 1.0000
98.8000 14.4710 1.0000
98.8600 10.8571 1.0000
98.9200 12.5712 1.0000
98.9800 7.6635 1.0000
99.0400 10.5257 1.0000
99.1000 4.7151 1.0000
99.1600 11.2743 1.0000
99.2200 10.1172 1.0000
99.2800 5.6039 1.0000
99.3400 5.4735 1.0000
99.4000 14.3082 1.0000
99.4600 6.4672 1.0000
99.5200 4.6658 1.0000
99.5800 8.6430 1.0000
99.6400 6.2744 1.0000
99.7000 7.1215 1.0000
99.7600 7.7888 1.0000
99.8200 4.4870 1.0000
99.8800 8.7210 1.0000
99.9400 6.5896 1.0000
100.0000 3.0514 1.0000
100.0600 3.1211 1.0000
100.1200 4.4056 1.0000
100.1800 5.9542 1.0000
100.2400 4.4954 1.0000
100.3000 8.2949 1.0000
100.3600 7.8793 1.0000
100.4200 7.3729 1.0000
100.4800 5.5086 1.0000
100.5400 9.2060 1.0000
100.6000 10.7668 1.0000
100.6600 7.0787 1.0000
100.7200 3.7309 1.0000
100.7800 7.0876 1.0000
100.8400 3.1041 1.0000
100.9000 9.1957 1.0000
100.9600 6.2011 1.0000
101.0200 12.1406 1.0000
101.0800 12.2871 1.0000
101.1400 6.5980 1.0000
101.2000 4.4289 1.0000
101.2600 7.9761 1.0000
101.3200 8.4872 1.0000
101.3800 2.0466 1.0000
101.4400 4.8374 1.0000
101.5000 5.0654 1.0000
101.5600 4.5819 1.0000
101.6200 11.8101 1.0000
101.6800 3.9170 1.0000
101.7400 7.5641 1.0000
101.8000 6.1896 1.0000
101.8600 2.0736 1.0000
101.9200 7.1419 1.0000
101.9800 5.0739 1.0000
102.0400 11.8638 1.0000
102.1000 4.4743 1.0000
102.1600 6.0080 1.0000
102.2200 8.4009 1.0000
102.2800 4.8804 1.0000
102.3400 6.2062 1.0000
102.4000 6.6813 1.0000
102.4600 6.4816 1.0000
102.5200 2.2110 1.0000
102.5800 7.3858 1.0000
102.6400 4.9288 1.0000
102.7000 2.4521 1.0000
102.7600 6.2712 1.0000
102.8200 10.5558 1.0000
102.8800 2.9926 1.0000
102.9400 6.2786 1.0000
103.0000 4.6055 1.0000
103.0600 4.8630 1.0000
103.1200 7.6494 1.0000
103.1800 4.0182 1.0000
103.2400 4.3786 1.0000
103.3000 4.2990 1.0000
103.3600 3.7615 1.0000
103.4200 7.0687 1.0000
103.4800 8.4371 1.0000
103.5400 4.9679 1.0000
103.6000 3.1206 1.0000
103.6600 5.8699 1.0000
103.7200 5.1142 1.0000
103.7800 6.8431 1.0000
103.8400 6.0196 1.0000
103.9000 7.5073 1.0000
103.9600 11.3230 1.0000
104.0200 8.0973 1.0000
104.0800 7.6123 1.0000
104.1400 4.5360 1.0000
104.2000 6.4083 1.0000
104.2600 4.9983 1.0000
104.3200 6.5083 1.0000
104.3800 8.3400 1.0000
104.4400 6.8035 1.0000
104.5000 8.9169 1.0000
104.5600 13.1474 1.0000
104.6200 7.7092 1.0000
104.6800 8.6310 1.0000
104.7400 10.5204 1.0000
104.8000 10.3375 1.0000
104.8600 6.6405 1.0000
104.9200 7.3875 1.0000
104.9800 4.9725 1.0000
105.0400 5.1817 1.0000
105.1000 10.2888 1.0000
105.1600 7.6728 1.0000
105.2200 3.0580 1.0000
105.2800 4.3294 1.0000
105.3400 7.9996 1.0000
105.4000 6.5386 1.0000
105.4600 2.9116 1.0000
105.5200 4.1352 1.0000
105.5800 7.9670 1.0000
105.6400 9.2508 1.0000
105.7000 9.0398 1.0000
105.7600 5.6947 1.0000
105.8200 4.5313 1.0000
105.8800 4.4567 1.0000
105.9400 5.9940 1.0000
106.0000 4.8045 1.0000
106.0600 13.2509 1.0000
106.1200 11.8998 1.0000
106.1800 4.0561 1.0000
106.2400 3.9736 1.0000
106.3000 11.7924 1.0000
106.3600 12.2163 1.0000
106.4200 3.1022 1.0000
106.4800 6.0240 1.0000
106.5400 4.6208 1.0000
106.6000 4.0338 1.0000
106.6600 4.0436 1.0000
106.7200 7.4223 1.0000
106.7800 7.0145 1.0000
106.8400 2.2935 1.0000
106.9000 2.2798 1.0000
106.9600 6.9718 1.0000
107.0200 4.5797 1.0000
107.0800 4.8685 1.0000
107.1400 7.1132 1.0000
107.2000 7.4185 1.0000
107.2600 6.4995 1.0000
107.3200 4.6928 1.0000
107.3800 4.9735 1.0000
107.4400 4.2102 1.0000
107.5000 9.0473 1.0000
107.5600 5.6623 1.0000
107.6200 10.0117 1.0000
107.6800 4.6955 1.0000
107.7400 9.1152 1.0000
107.8000 2.7660 1.0000
107.8600 5.9791 1.0000
107.9200 9.7651 1.0000
107.9800 4.9335 1.0000
108.0400 7.5369 1.0000
108.1000 5.1074 1.0000
108.1600 4.5593 1.0000
108.2200 9.0422 1.0000
108.2800 6.3278 1.0000
108.3400 10.8940 1.0000
108.4000 4.1696 1.0000
108.4600 2.8466 1.0000
108.5200 9.6983 1.0000
108.5800 3.2578 1.0000
108.6400 9.1882 1.0000
108.7000 3.7293 1.0000
108.7600 4.3684 1.0000
108.8200 4.5684 1.0000
108.8800 4.6091 1.0000
108.9400 2.0938 1.0000
109.0000 10.1141 1.0000
109.0600 8.6108 1.0000
109.1200 10.4336 1.0000
109.1800 1.9608 1.0000
109.2400 2.2461 1.0000
109.3000 5.8099 1.0000
109.3600 4.4634 1.0000
109.4200 6.5546 1.0000
109.4800 2.9515 1.0000
109.5400 4.6618 1.0000
109.6000 8.8586 1.0000
109.6600 7.9094 1.0000
109.7200 6.2808 1.0000
109.7800 4.8676 1.0000
109.8400 4.1093 1.0000
109.9000 8.9480 1.0000
109.9600 2.1258 1.0000
110.0200 9.2038 1.0000
110.0800 13.9483 1.0000
110.1400 3.9311 1.0000
110.2000 10.5301 1.0000
110.2600 7.7989 1.0000
110.3200 5.7198 1.0000
110.3800 6.2396 1.0000
110.4400 9.7214 1.0000
110.5000 7.2659 1.0000
110.5600 7.8080 1.0000
110.6200 4.2246 1.0000
110.6800 4.2282 1.0000
110.7400 4.3037 1.0000
110.8000 4.1175 1.0000
110.8600 6.3277 1.0000
110.9200 7.5586 1.0000
110.9800 4.2634 1.0000
111.0400 3.7924 1.0000
111.1000 1.4421 1.0000
111.1600 3.9577 1.0000
111.2200 9.4748 1.0000
111.2800 6.3725 1.0000
111.3400 3.7091 1.0000
111.4000 6.8124 1.0000
111.4600 6.3122 1.0000
111.5200 3.9184 1.0000
111.5800 8.2422 1.0000
111.6400 6.5601 1.0000
111.7000 4.5800 1.0000
111.7600 6.8086 1.0000
111.8200 8.3433 1.0000
111.8800 7.3648 1.0000
111.9400 3.8509 1.0000
112.0000 8.5352 1.0000
112.0600 7.0705 1.0000
112.1200 3.6440 1.0000
112.1800 5.6691 1.0000
112.2400 6.5238 1.0000
112.3000 6.4163 1.0000
112.3600 5.2049 1.0000
112.4200 7.2019 1.0000
112.4800 7.3738 1.0000
112.5400 10.7943 1.0000
112.6000 2.4465 1.0000
112.6600 2.4386 1.0000
112.7200 4.9792 1.0000
112.7800 4.5535 1.0000
112.8400 3.1551 1.0000
112.9000 3.8182 1.0000
112.9600 5.3801 1.0000
113.0200 2.5720 1.0000
113.0800 6.3433 1.0000
113.1400 6.0100 1.0000
113.2000 7.6744 1.0000
113.2600 4.2166 1.0000
113.3200 7.5687 1.0000
113.3800 6.7204 1.0000
113.4400 10.4331 1.0000
113.5000 6.6240 1.0000
113.5600 3.2216 1.0000
113.6200 2.4323 1.0000
113.6800 11.1376 1.0000
113.7400 4.5871 1.0000
113.8000 5.0950 1.0000
113.8600 5.5029 1.0000
113.9200 12.0880 1.0000
113.9800 8.2836 1.0000
114.0400 5.0824 1.0000
114.1000 5.3130 1.0000
114.1600 5.3125 1.0000
114.2200 6.3242 1.0000
114.2800 11.5015 1.0000
114.3400 6.3701 1.0000
114.4000 11.9838 1.0000
114.4600 5.8306 1.0000
114.5200 7.7402 1.0000
114.5800 7.0194 1.0000
114.6400 4.5204 1.0000
114.7000 6.8977 1.0000
114.7600 2.1309 1.0000
114.8200 7.0331 1.0000
114.8800 6.9308 1.0000
114.9400 4.0131 1.0000
115.0000 5.4124 1.0000
115.0600 8.2170 1.0000
115.1200 9.3638 1.0000
115.1800 11.3461 1.0000
115.2400 7.3337 1.0000
115.3000 7.4508 1.0000
115.3600 3.9230 1.0000
115.4200 5.6841 1.0000
115.4800 7.0067 1.0000
115.5400 6.3596 1.0000
115.6000 9.9707 1.0000
115.6600 8.9453 1.0000
115.7200 6.1783 1.0000
115.7800 7.8720 1.0000
115.8400 14.5688 1.0000
115.9000 14.4420 1.0000
115.9600 22.6908 1.0000
116.0200 26.8559 1.0000
116.0800 21.4790 1.0000
116.1400 18.2815 1.0000
116.2000 18.1738 1.0000
116.2600 14.3571 1.0000
116.3200 8.1812 1.0000
116.3800 11.3037 1.0000
116.4400 3.4834 1.0000
116.5000 7.0464 1.0000
116.5600 6.8340 1.0000
116.6200 12.0186 1.0000
116.6800 4.8401 1.0000
116.7400 6.5541 1.0000
116.8000 10.4261 1.0000
116.8600 9.4986 1.0000
116.9200 7.5928 1.0000
116.9800 6.0465 1.0000
117.0400 7.3145 1.0000
117.1000 8.2705 1.0000
117.1600 6.3203 1.0000
117.2200 10.3597 1.0000
117.2800 7.4797 1.0000
117.3400 2.8184 1.0000
117.4000 7.6458 1.0000
117.4600 9.5808 1.0000
117.5200 7.3686 1.0000
117.5800 9.5638 1.0000
117.6400 8.3941 1.0000
117.7000 8.6936 1.0000
117.7600 8.8658 1.0000
117.8200 2.4530 1.0000
117.8800 10.1264 1.0000
117.9400 5.6302 1.0000
118.0000 9.3128 1.0000
118.0600 6.2106 1.0000
118.1200 13.0714 1.0000
118.1800 13.6311 1.0000
118.2400 10.1069 1.0000
118.3000 5.0178 1.0000
118.3600 4.0947 1.0000
118.4200 5.9823 1.0000
118.4800 5.7088 1.0000
118.5400 1.6073 1.0000
118.6000 6.3440 1.0000
118.6600 8.1489 1.0000
118.7200 9.5321 1.0000
118.7800 4.9475 1.0000
118.8400 8.6741 1.0000
118.9000 7.7974 1.0000
118.9600 8.0501 1.0000
119.0200 12.9767 1.0000
119.0800 11.5381 1.0000
119.1400 4.8780 1.0000
119.2000 8.3808 1.0000
119.2600 6.5160 1.0000
119.3200 8.0995 1.0000
119.3800 10.6654 1.0000
119.4400 14.6424 1.0000
119.5000 13.1021 1.0000
119.5600 8.7739 1.0000
119.6200 4.2309 1.0000
119.6800 3.8686 1.0000
119.7400 2.5435 1.0000
119.8000 6.1150 1.0000
119.8600 11.6119 1.0000
119.9200 7.3590 1.0000
119.9800 7.0507 1.0000
119.9900 5.0951 1.0000
*RAS_INT_END
*RAS_TEMPERATURE_START
*RAS_TEMPERATURE_END
*RAS_DATA_END