File: XRD/May_2022/EFRW3_Unirr_and_Irr_regions/PB_Ge220_5SS_500umDS_RS1_Rod_5SS_Hypix1D_EFRW3_Irr-HAZ_P-irradiated.ras
*RAS_DATA_START
*RAS_HEADER_START
*DISP_FMT_X "%.3f"
*DISP_FMT_Y "%.0f"
*DISP_FULLSCALE "239.0844650904"
*DISP_LINE_COLOR "255.0000000000"
*DISP_LINE_STYLE "0.0000000000"
*DISP_LINE_WIDTH "0.2500000000"
*DISP_NOTE "Collected Data-21"
*DISP_OFFSET_Y "0.0000000000"
*DISP_PEAKSEARCH_UNIT_Y "cps"
*DISP_RANGE_BOTTOM "0.0000000000"
*DISP_RANGE_LEFT "40.0000000000"
*DISP_RANGE_LOGCUTOFF "0.0100000000"
*DISP_RANGE_RIGHT "119.9968000000"
*DISP_RANGE_TOP "239.0844650904"
*DISP_SCALE_MODE_Y "0.0000000000"
*DISP_TAB_NAME "Theta/2-Theta"
*DISP_TITLE_Y "Intensity"
*DISP_UNIT_Y "cps"
*DISP_WINDOW_NAME "MSG_MACROENGINE"
*FILE_COMMENT " "
*FILE_MD5 ""
*FILE_MEMO " "
*FILE_OPERATOR "Administrator"
*FILE_PART_ID "MEAS_KHP2_00061"
*FILE_SAMPLE " "
*FILE_TYPE "RAS_RAW"
*FILE_USERGROUP "System Manager"
*FILE_VERSION "1.0000000000"
*HW_ATTACHMENT_ID "ATT0021"
*HW_ATTACHMENT_NAME "XY-20mm|XY-20mm"
*HW_COUNTER_ID-0 "CUT0041"
*HW_COUNTER_ID-1 "CUT0051"
*HW_COUNTER_ID-2 "CUT0020"
*HW_COUNTER_ID-3 "CSL0021"
*HW_COUNTER_ID-4 "CMC0021"
*HW_COUNTER_NAME-0 "D/teX Ultra 250|D/teX Ultra 250"
*HW_COUNTER_NAME-1 "HyPix 3000(H)|HyPix 3000(H)"
*HW_COUNTER_NAME-2 "None|None"
*HW_COUNTER_NAME-3 "BBM|BBM"
*HW_COUNTER_NAME-4 "検出器モノクロメータ|Detector monochromator"
*HW_COUNTER_SELECT_NAME "HyPix 3000(H)|HyPix 3000(H)"
*HW_GONIOMETER_ID "GON0024"
*HW_GONIOMETER_NAME "SmartLab(In-plane)|SmartLab(In-plane)"
*HW_GONIOMETER_RADIUS-0 "90.0"
*HW_GONIOMETER_RADIUS-1 "114.0"
*HW_GONIOMETER_RADIUS-2 "190.0"
*HW_GONIOMETER_RADIUS-3 "300.0"
*HW_GONIOMETER_RADIUS-4 "187.0"
*HW_GONIOMETER_RADIUS-5 "300.0"
*HW_GONIOMETER_RADIUS-6 "113.0"
*HW_GONIOMETER_RADIUS-7 "331.0"
*HW_I_OPT_ID-0 "CBO0021"
*HW_I_OPT_ID-1 "ICR0021"
*HW_I_OPT_ID-2 "ISL0021"
*HW_I_OPT_ID-3 "ISO0021"
*HW_I_OPT_ID-4 "IAD0021"
*HW_I_OPT_ID-5 "IPR0001"
*HW_I_OPT_NAME-0 "CBOユニット|CBO unit"
*HW_I_OPT_NAME-1 "標準入射光学ユニット|Standard incident optical unit"
*HW_I_OPT_NAME-2 "標準入射スリットボックス|Standard incident slit box"
*HW_I_OPT_NAME-3 "入射平行スリット|Incident parallel slit"
*HW_I_OPT_NAME-4 "長手制限スリット|Length limiting slit"
*HW_I_OPT_NAME-5 "None|None"
*HW_R_ATTENUATER_AUTOMODE "0"
*HW_R_OPT_ID-0 "RSS0022"
*HW_R_OPT_ID-1 "RCR0022"
*HW_R_OPT_ID-2 "RSO0021"
*HW_R_OPT_ID-3 "RRS0022"
*HW_R_OPT_ID-4 "ATN0020"
*HW_R_OPT_ID-5 "RFL0021"
*HW_R_OPT_ID-6 "RAD0021"
*HW_R_OPT_NAME-0 "受光スリットボックス1(Zr軸付)|Receiving slit box # 1 (w/ Zr Axis)"
*HW_R_OPT_NAME-1 "標準受光光学ユニット1|Standard receiving unit # 1"
*HW_R_OPT_NAME-2 "標準受光光学ユニット2|Standard receiving optical unit # 2"
*HW_R_OPT_NAME-3 "仮想受光スリット2|Virtual receiving slit #2"
*HW_R_OPT_NAME-4 "無し|None"
*HW_R_OPT_NAME-5 "Cu Kβ|Cu K-beta"
*HW_R_OPT_NAME-6 "調整用受光スリット|Alignment receiving slit"
*HW_SAMPLE_HOLDER_ID "SMP0021"
*HW_SAMPLE_HOLDER_NAME "χφZクレードル|Chi phi Z cradle"
*HW_XG_CURRENT_MAX "40"
*HW_XG_CURRENT_MIN "2"
*HW_XG_CURRENT_RESOLUTION "1"
*HW_XG_CURRENT_UNIT "mA"
*HW_XG_FOCUS "0.4mm x 8mm"
*HW_XG_FOCUS_TYPE "Fine"
*HW_XG_ID "1200"
*HW_XG_NAME "3kW 封入管(ID:1200)|3kW Sealed tube(ID:1200)"
*HW_XG_TARGET_ATOMIC_NUMBER "29.0000000000"
*HW_XG_TARGET_NAME "Cu"
*HW_XG_TYPE "Hermetic"
*HW_XG_VOLTAGE_MAX "40"
*HW_XG_VOLTAGE_MIN "20"
*HW_XG_VOLTAGE_RESOLUTION "1"
*HW_XG_VOLTAGE_UNIT "kV"
*HW_XG_WATT_MAX "1.500"
*HW_XG_WATT_UNIT "kW"
*HW_XG_WAVE_LENGTH_ALPHA1 "1.540593"
*HW_XG_WAVE_LENGTH_ALPHA2 "1.544414"
*HW_XG_WAVE_LENGTH_BETA "1.392250"
*MEAS_COND_AXIS_NAME-0 "Theta/2-Theta"
*MEAS_COND_AXIS_NAME-1 "2-Theta"
*MEAS_COND_AXIS_NAME-2 "Omega"
*MEAS_COND_AXIS_NAME-3 "Chi"
*MEAS_COND_AXIS_NAME-4 "Phi"
*MEAS_COND_AXIS_NAME-5 "Z"
*MEAS_COND_AXIS_NAME-6 "X"
*MEAS_COND_AXIS_NAME-7 "Y"
*MEAS_COND_AXIS_NAME-8 "2-Theta/Omega"
*MEAS_COND_AXIS_NAME-9 "2-ThetaChi"
*MEAS_COND_AXIS_NAME-10 "2-ThetaChi/Phi"
*MEAS_COND_AXIS_NAME-11 "Alpha"
*MEAS_COND_AXIS_NAME-12 "Beta"
*MEAS_COND_AXIS_NAME-13 "Theta_s"
*MEAS_COND_AXIS_NAME-14 "Theta_d"
*MEAS_COND_AXIS_NAME-15 "Ts"
*MEAS_COND_AXIS_NAME-16 "CBO selection slit"
*MEAS_COND_AXIS_NAME-17 "M"
*MEAS_COND_AXIS_NAME-18 "Incident parallel slit"
*MEAS_COND_AXIS_NAME-19 "Incident slit"
*MEAS_COND_AXIS_NAME-20 ""
*MEAS_COND_AXIS_NAME-21 "Zs"
*MEAS_COND_AXIS_NAME-22 "Incident optical device"
*MEAS_COND_AXIS_NAME-23 "Omega_m"
*MEAS_COND_AXIS_NAME-24 "Length limiting slit"
*MEAS_COND_AXIS_NAME-25 "Center slit"
*MEAS_COND_AXIS_NAME-26 "Filter"
*MEAS_COND_AXIS_NAME-27 "Receiving slit # 1"
*MEAS_COND_AXIS_NAME-28 "Receiving slit # 2"
*MEAS_COND_AXIS_NAME-29 "Receiving optical device"
*MEAS_COND_AXIS_NAME-30 "Receiving parallel slit"
*MEAS_COND_AXIS_NAME-31 "Alignment receiving slit"
*MEAS_COND_AXIS_NAME-32 ""
*MEAS_COND_AXIS_NAME-33 ""
*MEAS_COND_AXIS_NAME-34 "Zd"
*MEAS_COND_AXIS_NAME-35 "Attenuator"
*MEAS_COND_AXIS_NAME-36 "Diffracted beam monochromator"
*MEAS_COND_AXIS_NAME-37 "Monochromator slit"
*MEAS_COND_AXIS_NAME-38 "2-ThetaB"
*MEAS_COND_AXIS_NAME-39 ""
*MEAS_COND_AXIS_NAME-40 ""
*MEAS_COND_AXIS_NAME-41 "Zr"
*MEAS_COND_AXIS_NAME-42 "Primary beam"
*MEAS_COND_AXIS_NAME_INTERNAL-0 "TwoThetaTheta"
*MEAS_COND_AXIS_NAME_INTERNAL-1 "TwoTheta"
*MEAS_COND_AXIS_NAME_INTERNAL-2 "Omega"
*MEAS_COND_AXIS_NAME_INTERNAL-3 "Chi"
*MEAS_COND_AXIS_NAME_INTERNAL-4 "Phi"
*MEAS_COND_AXIS_NAME_INTERNAL-5 "Z"
*MEAS_COND_AXIS_NAME_INTERNAL-6 "X"
*MEAS_COND_AXIS_NAME_INTERNAL-7 "Y"
*MEAS_COND_AXIS_NAME_INTERNAL-8 "TwoThetaOmega"
*MEAS_COND_AXIS_NAME_INTERNAL-9 "TwoThetaChi"
*MEAS_COND_AXIS_NAME_INTERNAL-10 "TwoThetaChiPhi"
*MEAS_COND_AXIS_NAME_INTERNAL-11 "Alpha"
*MEAS_COND_AXIS_NAME_INTERNAL-12 "Beta"
*MEAS_COND_AXIS_NAME_INTERNAL-13 "ThetaS"
*MEAS_COND_AXIS_NAME_INTERNAL-14 "ThetaD"
*MEAS_COND_AXIS_NAME_INTERNAL-15 "Ts"
*MEAS_COND_AXIS_NAME_INTERNAL-16 "CBO"
*MEAS_COND_AXIS_NAME_INTERNAL-17 "CBO-M"
*MEAS_COND_AXIS_NAME_INTERNAL-18 "IncidentSollerSlit"
*MEAS_COND_AXIS_NAME_INTERNAL-19 "IncidentSlitBox"
*MEAS_COND_AXIS_NAME_INTERNAL-20 "IncidentSlitBox-_Axis"
*MEAS_COND_AXIS_NAME_INTERNAL-21 "Zs"
*MEAS_COND_AXIS_NAME_INTERNAL-22 "IncidentMonochromator"
*MEAS_COND_AXIS_NAME_INTERNAL-23 "IncidentMonochromator-OmegaM"
*MEAS_COND_AXIS_NAME_INTERNAL-24 "IncidentAxdSlit"
*MEAS_COND_AXIS_NAME_INTERNAL-25 "CenterSlit"
*MEAS_COND_AXIS_NAME_INTERNAL-26 "Filter"
*MEAS_COND_AXIS_NAME_INTERNAL-27 "ReceivingSlitBox1"
*MEAS_COND_AXIS_NAME_INTERNAL-28 "ReceivingSlitBox2"
*MEAS_COND_AXIS_NAME_INTERNAL-29 "ReceivingOptics"
*MEAS_COND_AXIS_NAME_INTERNAL-30 "ReceivingSollerSlit"
*MEAS_COND_AXIS_NAME_INTERNAL-31 "ReceivingAxdSlit"
*MEAS_COND_AXIS_NAME_INTERNAL-32 "ReceivingSlitBox1-_Axis"
*MEAS_COND_AXIS_NAME_INTERNAL-33 "ReceivingSlitBox2-_Axis"
*MEAS_COND_AXIS_NAME_INTERNAL-34 "ReceivingSlitBox2-Zd"
*MEAS_COND_AXIS_NAME_INTERNAL-35 "Attenuator"
*MEAS_COND_AXIS_NAME_INTERNAL-36 "CounterMonochromator"
*MEAS_COND_AXIS_NAME_INTERNAL-37 "CounterSlit"
*MEAS_COND_AXIS_NAME_INTERNAL-38 "TwoThetaB"
*MEAS_COND_AXIS_NAME_INTERNAL-39 "AlphaR"
*MEAS_COND_AXIS_NAME_INTERNAL-40 "BetaR"
*MEAS_COND_AXIS_NAME_INTERNAL-41 "ReceivingSlitBox1-Zr"
*MEAS_COND_AXIS_NAME_INTERNAL-42 "IncidentPrimary"
*MEAS_COND_AXIS_NAME_MAGICNO-0 "83951616.0000000000"
*MEAS_COND_AXIS_NAME_MAGICNO-1 "268632064.0000000000"
*MEAS_COND_AXIS_NAME_MAGICNO-2 "268500992.0000000000"
*MEAS_COND_AXIS_NAME_MAGICNO-3 "268500992.0000000000"
*MEAS_COND_AXIS_NAME_MAGICNO-4 "268500992.0000000000"
*MEAS_COND_AXIS_NAME_MAGICNO-5 "285278208.0000000000"
*MEAS_COND_AXIS_NAME_MAGICNO-6 "268500992.0000000000"
*MEAS_COND_AXIS_NAME_MAGICNO-7 "268500992.0000000000"
*MEAS_COND_AXIS_NAME_MAGICNO-8 "83951616.0000000000"
*MEAS_COND_AXIS_NAME_MAGICNO-9 "268632064.0000000000"
*MEAS_COND_AXIS_NAME_MAGICNO-10 "83951616.0000000000"
*MEAS_COND_AXIS_NAME_MAGICNO-11 "17039360.0000000000"
*MEAS_COND_AXIS_NAME_MAGICNO-12 "17039360.0000000000"
*MEAS_COND_AXIS_NAME_MAGICNO-13 "131072.0000000000"
*MEAS_COND_AXIS_NAME_MAGICNO-14 "131072.0000000000"
*MEAS_COND_AXIS_NAME_MAGICNO-15 "318898176.0000000000"
*MEAS_COND_AXIS_NAME_MAGICNO-16 "20971521.0000000000"
*MEAS_COND_AXIS_NAME_MAGICNO-17 "285343744.0000000000"
*MEAS_COND_AXIS_NAME_MAGICNO-18 "20971521.0000000000"
*MEAS_COND_AXIS_NAME_MAGICNO-19 "22020097.0000000000"
*MEAS_COND_AXIS_NAME_MAGICNO-20 "25165824.0000000000"
*MEAS_COND_AXIS_NAME_MAGICNO-21 "318898176.0000000000"
*MEAS_COND_AXIS_NAME_MAGICNO-22 "20971521.0000000000"
*MEAS_COND_AXIS_NAME_MAGICNO-23 "285343744.0000000000"
*MEAS_COND_AXIS_NAME_MAGICNO-24 "20971521.0000000000"
*MEAS_COND_AXIS_NAME_MAGICNO-25 "20971521.0000000000"
*MEAS_COND_AXIS_NAME_MAGICNO-26 "20971521.0000000000"
*MEAS_COND_AXIS_NAME_MAGICNO-27 "23068673.0000000000"
*MEAS_COND_AXIS_NAME_MAGICNO-28 "23068673.0000000000"
*MEAS_COND_AXIS_NAME_MAGICNO-29 "20971521.0000000000"
*MEAS_COND_AXIS_NAME_MAGICNO-30 "20971521.0000000000"
*MEAS_COND_AXIS_NAME_MAGICNO-31 "20971521.0000000000"
*MEAS_COND_AXIS_NAME_MAGICNO-32 "25165824.0000000000"
*MEAS_COND_AXIS_NAME_MAGICNO-33 "25165824.0000000000"
*MEAS_COND_AXIS_NAME_MAGICNO-34 "285343744.0000000000"
*MEAS_COND_AXIS_NAME_MAGICNO-35 "0.0000000000"
*MEAS_COND_AXIS_NAME_MAGICNO-36 "20971521.0000000000"
*MEAS_COND_AXIS_NAME_MAGICNO-37 "20971521.0000000000"
*MEAS_COND_AXIS_NAME_MAGICNO-38 "17039360.0000000000"
*MEAS_COND_AXIS_NAME_MAGICNO-39 "8388608.0000000000"
*MEAS_COND_AXIS_NAME_MAGICNO-40 "8388608.0000000000"
*MEAS_COND_AXIS_NAME_MAGICNO-41 "285343744.0000000000"
*MEAS_COND_AXIS_NAME_MAGICNO-42 "20971521.0000000000"
*MEAS_COND_AXIS_OFFSET-0 "-"
*MEAS_COND_AXIS_OFFSET-1 "0.8642000000"
*MEAS_COND_AXIS_OFFSET-2 "1.0640000000"
*MEAS_COND_AXIS_OFFSET-3 "0.0000000000"
*MEAS_COND_AXIS_OFFSET-4 "0.0000000000"
*MEAS_COND_AXIS_OFFSET-5 "-"
*MEAS_COND_AXIS_OFFSET-6 "0.0000000000"
*MEAS_COND_AXIS_OFFSET-7 "0.0000000000"
*MEAS_COND_AXIS_OFFSET-8 "-"
*MEAS_COND_AXIS_OFFSET-9 "0.0000000000"
*MEAS_COND_AXIS_OFFSET-10 "-"
*MEAS_COND_AXIS_OFFSET-11 "-"
*MEAS_COND_AXIS_OFFSET-12 "-"
*MEAS_COND_AXIS_OFFSET-13 "1.0640000000"
*MEAS_COND_AXIS_OFFSET-14 "-0.1998000000"
*MEAS_COND_AXIS_OFFSET-15 "-"
*MEAS_COND_AXIS_OFFSET-16 "-"
*MEAS_COND_AXIS_OFFSET-17 "-"
*MEAS_COND_AXIS_OFFSET-18 "-"
*MEAS_COND_AXIS_OFFSET-19 "-"
*MEAS_COND_AXIS_OFFSET-20 "-"
*MEAS_COND_AXIS_OFFSET-21 "-"
*MEAS_COND_AXIS_OFFSET-22 "-"
*MEAS_COND_AXIS_OFFSET-23 "-"
*MEAS_COND_AXIS_OFFSET-24 "-"
*MEAS_COND_AXIS_OFFSET-25 "-"
*MEAS_COND_AXIS_OFFSET-26 "-"
*MEAS_COND_AXIS_OFFSET-27 "-"
*MEAS_COND_AXIS_OFFSET-28 "-"
*MEAS_COND_AXIS_OFFSET-29 "-"
*MEAS_COND_AXIS_OFFSET-30 "-"
*MEAS_COND_AXIS_OFFSET-31 "-"
*MEAS_COND_AXIS_OFFSET-32 "-"
*MEAS_COND_AXIS_OFFSET-33 "-"
*MEAS_COND_AXIS_OFFSET-34 "-"
*MEAS_COND_AXIS_OFFSET-35 "-"
*MEAS_COND_AXIS_OFFSET-36 "-"
*MEAS_COND_AXIS_OFFSET-37 "-"
*MEAS_COND_AXIS_OFFSET-38 "-"
*MEAS_COND_AXIS_OFFSET-39 "0.0000000000"
*MEAS_COND_AXIS_OFFSET-40 "0.0000000000"
*MEAS_COND_AXIS_OFFSET-41 "-"
*MEAS_COND_AXIS_OFFSET-42 "-"
*MEAS_COND_AXIS_POSITION-0 "40.0000000000"
*MEAS_COND_AXIS_POSITION-1 "40.0000000000"
*MEAS_COND_AXIS_POSITION-2 "20.0000000000"
*MEAS_COND_AXIS_POSITION-3 "0.0000000000"
*MEAS_COND_AXIS_POSITION-4 "0.0000000000"
*MEAS_COND_AXIS_POSITION-5 "-1.7645000000"
*MEAS_COND_AXIS_POSITION-6 "-0.9195000000"
*MEAS_COND_AXIS_POSITION-7 "0.4610000000"
*MEAS_COND_AXIS_POSITION-8 "40.0000000000"
*MEAS_COND_AXIS_POSITION-9 "0.0000000000"
*MEAS_COND_AXIS_POSITION-10 "0.0000000000"
*MEAS_COND_AXIS_POSITION-11 "90.0000000000"
*MEAS_COND_AXIS_POSITION-12 "0.0000000000"
*MEAS_COND_AXIS_POSITION-13 "20.0000000000"
*MEAS_COND_AXIS_POSITION-14 "20.0000000000"
*MEAS_COND_AXIS_POSITION-15 "-5.4426900000"
*MEAS_COND_AXIS_POSITION-16 "PB"
*MEAS_COND_AXIS_POSITION-17 "0.0000000000"
*MEAS_COND_AXIS_POSITION-18 "Soller_slit_5.0deg_s"
*MEAS_COND_AXIS_POSITION-19 "1.000mm"
*MEAS_COND_AXIS_POSITION-20 "1.0000000000"
*MEAS_COND_AXIS_POSITION-21 "-1.3487500000"
*MEAS_COND_AXIS_POSITION-22 "Ge(220)x2"
*MEAS_COND_AXIS_POSITION-23 "0.0000000000"
*MEAS_COND_AXIS_POSITION-24 "0.5mm"
*MEAS_COND_AXIS_POSITION-25 "None"
*MEAS_COND_AXIS_POSITION-26 "None"
*MEAS_COND_AXIS_POSITION-27 "20.000mm"
*MEAS_COND_AXIS_POSITION-28 "38.500mm"
*MEAS_COND_AXIS_POSITION-29 "PSA_open"
*MEAS_COND_AXIS_POSITION-30 "Soller_slit_5.0deg"
*MEAS_COND_AXIS_POSITION-31 "None"
*MEAS_COND_AXIS_POSITION-32 "20.0000000000"
*MEAS_COND_AXIS_POSITION-33 "38.5000000000"
*MEAS_COND_AXIS_POSITION-34 "0.0000000000"
*MEAS_COND_AXIS_POSITION-35 "-"
*MEAS_COND_AXIS_POSITION-36 "No_unit"
*MEAS_COND_AXIS_POSITION-37 "None"
*MEAS_COND_AXIS_POSITION-38 "40.0000000000"
*MEAS_COND_AXIS_POSITION-39 "0.0000000000"
*MEAS_COND_AXIS_POSITION-40 "0.0000000000"
*MEAS_COND_AXIS_POSITION-41 "0.2584400000"
*MEAS_COND_AXIS_POSITION-42 "None"
*MEAS_COND_AXIS_UNIT-0 "deg"
*MEAS_COND_AXIS_UNIT-1 "deg"
*MEAS_COND_AXIS_UNIT-2 "deg"
*MEAS_COND_AXIS_UNIT-3 "deg"
*MEAS_COND_AXIS_UNIT-4 "deg"
*MEAS_COND_AXIS_UNIT-5 "mm"
*MEAS_COND_AXIS_UNIT-6 "mm"
*MEAS_COND_AXIS_UNIT-7 "mm"
*MEAS_COND_AXIS_UNIT-8 "deg"
*MEAS_COND_AXIS_UNIT-9 "deg"
*MEAS_COND_AXIS_UNIT-10 "deg"
*MEAS_COND_AXIS_UNIT-11 "deg"
*MEAS_COND_AXIS_UNIT-12 "deg"
*MEAS_COND_AXIS_UNIT-13 "deg"
*MEAS_COND_AXIS_UNIT-14 "deg"
*MEAS_COND_AXIS_UNIT-15 "mm"
*MEAS_COND_AXIS_UNIT-16 ""
*MEAS_COND_AXIS_UNIT-17 "pulse"
*MEAS_COND_AXIS_UNIT-18 ""
*MEAS_COND_AXIS_UNIT-19 ""
*MEAS_COND_AXIS_UNIT-20 "mm"
*MEAS_COND_AXIS_UNIT-21 "mm"
*MEAS_COND_AXIS_UNIT-22 ""
*MEAS_COND_AXIS_UNIT-23 "pulse"
*MEAS_COND_AXIS_UNIT-24 ""
*MEAS_COND_AXIS_UNIT-25 ""
*MEAS_COND_AXIS_UNIT-26 ""
*MEAS_COND_AXIS_UNIT-27 ""
*MEAS_COND_AXIS_UNIT-28 ""
*MEAS_COND_AXIS_UNIT-29 ""
*MEAS_COND_AXIS_UNIT-30 ""
*MEAS_COND_AXIS_UNIT-31 ""
*MEAS_COND_AXIS_UNIT-32 "mm"
*MEAS_COND_AXIS_UNIT-33 "mm"
*MEAS_COND_AXIS_UNIT-34 "mm"
*MEAS_COND_AXIS_UNIT-35 ""
*MEAS_COND_AXIS_UNIT-36 ""
*MEAS_COND_AXIS_UNIT-37 ""
*MEAS_COND_AXIS_UNIT-38 "deg"
*MEAS_COND_AXIS_UNIT-39 "deg"
*MEAS_COND_AXIS_UNIT-40 "deg"
*MEAS_COND_AXIS_UNIT-41 "mm"
*MEAS_COND_AXIS_UNIT-42 ""
*MEAS_COND_COUNTER_CNTLOSS_CORR "0.0000000000"
*MEAS_COND_COUNTER_TAUDIFF "0.0000000000"
*MEAS_COND_COUNTER_TAUINT "0.0000000000"
*MEAS_COND_COUNTER_TEMP_CONDITION "NORMAL"
*MEAS_COND_IRRADIATION_MODE "OFF"
*MEAS_COND_IRRADIATION_WIDTH ""
*MEAS_COND_OPT_ATTR "High resolution parallel beam Ge(220)x2/RS"
*MEAS_COND_OPT_NAME "@High resolution PB-Ge(220)x2"
*MEAS_COND_UNSYMMETRIC_MODE "OFF"
*MEAS_COND_XG_CURRENT "30.0000000000"
*MEAS_COND_XG_VOLTAGE "40.0000000000"
*MEAS_COND_XG_WAVE_TYPE "Ka1"
*MEAS_DATA_COUNT "8000.0000000000"
*MEAS_SCAN_AXIS_X "Theta/2-Theta"
*MEAS_SCAN_AXIS_X_INTERNAL "TwoThetaTheta"
*MEAS_SCAN_END_TIME "05/13/22 15:35:20"
*MEAS_SCAN_MODE "CONTINUOUS"
*MEAS_SCAN_MONITOR "0"
*MEAS_SCAN_RESOLUTION_X "0.0002"
*MEAS_SCAN_SPEED "0.503240"
*MEAS_SCAN_SPEED_UNIT "deg/min"
*MEAS_SCAN_SPEED_USER "0.5"
*MEAS_SCAN_START "40.0000000000"
*MEAS_SCAN_START_TIME "05/13/22 12:40:30"
*MEAS_SCAN_STEP "0.0100000000"
*MEAS_SCAN_STOP "119.9900000000"
*MEAS_SCAN_UNIT_X "deg"
*MEAS_SCAN_UNIT_Y "counts"
*RAS_HEADER_END
*RAS_INT_START
40.0000 8.2795 1.0000
40.0600 5.1201 1.0000
40.1200 2.4725 1.0000
40.1800 7.7476 1.0000
40.2400 5.8682 1.0000
40.3000 5.2661 1.0000
40.3600 8.9858 1.0000
40.4200 3.0416 1.0000
40.4800 8.3726 1.0000
40.5400 11.2405 1.0000
40.6000 11.1828 1.0000
40.6600 9.3573 1.0000
40.7200 7.9973 1.0000
40.7800 6.3175 1.0000
40.8400 5.1423 1.0000
40.9000 1.0172 1.0000
40.9600 6.5950 1.0000
41.0200 8.4560 1.0000
41.0800 6.3206 1.0000
41.1400 6.5346 1.0000
41.2000 8.1694 1.0000
41.2600 5.6835 1.0000
41.3200 5.3245 1.0000
41.3800 6.3099 1.0000
41.4400 5.4164 1.0000
41.5000 4.7362 1.0000
41.5600 2.8746 1.0000
41.6200 2.7748 1.0000
41.6800 4.9805 1.0000
41.7400 9.6165 1.0000
41.8000 6.3976 1.0000
41.8600 3.1000 1.0000
41.9200 7.8787 1.0000
41.9800 6.2397 1.0000
42.0400 11.4850 1.0000
42.1000 9.2675 1.0000
42.1600 7.5655 1.0000
42.2200 6.9971 1.0000
42.2800 5.6534 1.0000
42.3400 8.1831 1.0000
42.4000 4.6097 1.0000
42.4600 9.4583 1.0000
42.5200 4.7112 1.0000
42.5800 8.3836 1.0000
42.6400 11.4781 1.0000
42.7000 3.5896 1.0000
42.7600 3.8500 1.0000
42.8200 4.7401 1.0000
42.8800 3.5891 1.0000
42.9400 6.6249 1.0000
43.0000 4.9426 1.0000
43.0600 16.5717 1.0000
43.1200 5.8922 1.0000
43.1800 9.0910 1.0000
43.2400 7.1831 1.0000
43.3000 6.4451 1.0000
43.3600 10.9565 1.0000
43.4200 7.1708 1.0000
43.4800 3.4554 1.0000
43.5400 5.3326 1.0000
43.6000 4.1009 1.0000
43.6600 5.4898 1.0000
43.7200 10.3044 1.0000
43.7800 6.2621 1.0000
43.8400 8.9906 1.0000
43.9000 8.3867 1.0000
43.9600 12.4989 1.0000
44.0200 4.4343 1.0000
44.0800 7.6918 1.0000
44.1400 10.0899 1.0000
44.2000 21.9036 1.0000
44.2600 24.2405 1.0000
44.3200 38.3290 1.0000
44.3800 74.7472 1.0000
44.4400 146.1597 1.0000
44.5000 190.0650 1.0000
44.5600 198.6194 1.0000
44.6200 145.7834 1.0000
44.6800 64.1845 1.0000
44.7400 31.4093 1.0000
44.8000 20.1048 1.0000
44.8600 5.9993 1.0000
44.9200 11.7543 1.0000
44.9800 3.2342 1.0000
45.0400 19.2431 1.0000
45.1000 3.0542 1.0000
45.1600 8.7249 1.0000
45.2200 6.7889 1.0000
45.2800 3.0805 1.0000
45.3400 5.1063 1.0000
45.4000 3.2161 1.0000
45.4600 2.2129 1.0000
45.5200 7.2031 1.0000
45.5800 6.4588 1.0000
45.6400 4.0699 1.0000
45.7000 7.1977 1.0000
45.7600 8.2532 1.0000
45.8200 4.4509 1.0000
45.8800 5.4474 1.0000
45.9400 5.9331 1.0000
46.0000 1.5443 1.0000
46.0600 5.0565 1.0000
46.1200 8.9106 1.0000
46.1800 11.6197 1.0000
46.2400 10.4695 1.0000
46.3000 5.5585 1.0000
46.3600 7.2736 1.0000
46.4200 5.4225 1.0000
46.4800 1.0321 1.0000
46.5400 6.1146 1.0000
46.6000 3.0758 1.0000
46.6600 14.2341 1.0000
46.7200 3.5054 1.0000
46.7800 3.0685 1.0000
46.8400 9.9090 1.0000
46.9000 4.4945 1.0000
46.9600 2.9654 1.0000
47.0200 4.5741 1.0000
47.0800 6.2654 1.0000
47.1400 11.0334 1.0000
47.2000 5.8825 1.0000
47.2600 11.1656 1.0000
47.3200 10.1209 1.0000
47.3800 5.0742 1.0000
47.4400 6.7482 1.0000
47.5000 6.4290 1.0000
47.5600 7.0527 1.0000
47.6200 9.7321 1.0000
47.6800 6.7680 1.0000
47.7400 5.7739 1.0000
47.8000 6.7794 1.0000
47.8600 5.2365 1.0000
47.9200 9.0347 1.0000
47.9800 5.2067 1.0000
48.0400 5.3825 1.0000
48.1000 2.4994 1.0000
48.1600 5.7113 1.0000
48.2200 4.9204 1.0000
48.2800 10.5686 1.0000
48.3400 10.8090 1.0000
48.4000 6.7325 1.0000
48.4600 4.2362 1.0000
48.5200 3.4017 1.0000
48.5800 5.3586 1.0000
48.6400 9.3139 1.0000
48.7000 6.7778 1.0000
48.7600 7.2545 1.0000
48.8200 3.7343 1.0000
48.8800 6.7877 1.0000
48.9400 4.5119 1.0000
49.0000 9.3722 1.0000
49.0600 9.3273 1.0000
49.1200 11.9054 1.0000
49.1800 8.7266 1.0000
49.2400 8.3301 1.0000
49.3000 7.3539 1.0000
49.3600 4.6674 1.0000
49.4200 8.6928 1.0000
49.4800 11.1527 1.0000
49.5400 6.7684 1.0000
49.6000 5.8717 1.0000
49.6600 8.1372 1.0000
49.7200 9.7366 1.0000
49.7800 3.6613 1.0000
49.8400 18.2246 1.0000
49.9000 9.3287 1.0000
49.9600 5.7795 1.0000
50.0200 5.1354 1.0000
50.0800 8.4972 1.0000
50.1400 5.2743 1.0000
50.2000 5.3276 1.0000
50.2600 2.4839 1.0000
50.3200 3.4714 1.0000
50.3800 3.3232 1.0000
50.4400 8.5029 1.0000
50.5000 6.7491 1.0000
50.5600 7.1338 1.0000
50.6200 7.8757 1.0000
50.6800 4.7490 1.0000
50.7400 5.2128 1.0000
50.8000 7.6182 1.0000
50.8600 5.2049 1.0000
50.9200 6.4481 1.0000
50.9800 5.1214 1.0000
51.0400 2.3123 1.0000
51.1000 4.3804 1.0000
51.1600 7.6747 1.0000
51.2200 5.0449 1.0000
51.2800 8.1044 1.0000
51.3400 6.6178 1.0000
51.4000 11.1212 1.0000
51.4600 7.6276 1.0000
51.5200 3.8456 1.0000
51.5800 7.4302 1.0000
51.6400 9.8066 1.0000
51.7000 3.9227 1.0000
51.7600 7.5273 1.0000
51.8200 6.2145 1.0000
51.8800 5.1427 1.0000
51.9400 4.9411 1.0000
52.0000 4.4720 1.0000
52.0600 7.4645 1.0000
52.1200 6.8671 1.0000
52.1800 4.2016 1.0000
52.2400 10.0275 1.0000
52.3000 4.7180 1.0000
52.3600 2.1950 1.0000
52.4200 3.1082 1.0000
52.4800 5.8347 1.0000
52.5400 5.4161 1.0000
52.6000 5.4284 1.0000
52.6600 6.4037 1.0000
52.7200 9.7723 1.0000
52.7800 12.0709 1.0000
52.8400 7.0398 1.0000
52.9000 6.1906 1.0000
52.9600 6.9123 1.0000
53.0200 4.1934 1.0000
53.0800 3.4790 1.0000
53.1400 5.9341 1.0000
53.2000 6.0784 1.0000
53.2600 12.1901 1.0000
53.3200 7.0476 1.0000
53.3800 7.8705 1.0000
53.4400 8.2246 1.0000
53.5000 1.1984 1.0000
53.5600 2.7092 1.0000
53.6200 3.2443 1.0000
53.6800 7.1604 1.0000
53.7400 5.2407 1.0000
53.8000 5.5901 1.0000
53.8600 2.0074 1.0000
53.9200 3.8952 1.0000
53.9800 4.2829 1.0000
54.0400 5.2165 1.0000
54.1000 4.7579 1.0000
54.1600 4.6963 1.0000
54.2200 5.0987 1.0000
54.2800 2.8269 1.0000
54.3400 1.3595 1.0000
54.4000 3.1920 1.0000
54.4600 10.2406 1.0000
54.5200 6.8145 1.0000
54.5800 3.8765 1.0000
54.6400 8.0937 1.0000
54.7000 4.9351 1.0000
54.7600 2.9535 1.0000
54.8200 4.8530 1.0000
54.8800 6.0864 1.0000
54.9400 8.8255 1.0000
55.0000 7.6189 1.0000
55.0600 9.2801 1.0000
55.1200 10.2850 1.0000
55.1800 8.8391 1.0000
55.2400 8.2411 1.0000
55.3000 11.1530 1.0000
55.3600 5.5052 1.0000
55.4200 12.2344 1.0000
55.4800 3.8010 1.0000
55.5400 5.5523 1.0000
55.6000 6.2756 1.0000
55.6600 6.0044 1.0000
55.7200 5.8027 1.0000
55.7800 7.3545 1.0000
55.8400 5.4132 1.0000
55.9000 3.7658 1.0000
55.9600 6.4887 1.0000
56.0200 15.1584 1.0000
56.0800 3.5888 1.0000
56.1400 7.9958 1.0000
56.2000 6.3454 1.0000
56.2600 6.1508 1.0000
56.3200 5.7907 1.0000
56.3800 8.1172 1.0000
56.4400 3.9484 1.0000
56.5000 4.7856 1.0000
56.5600 8.2657 1.0000
56.6200 6.8164 1.0000
56.6800 10.2692 1.0000
56.7400 5.5090 1.0000
56.8000 3.3011 1.0000
56.8600 4.2106 1.0000
56.9200 7.6949 1.0000
56.9800 7.2149 1.0000
57.0400 5.2592 1.0000
57.1000 3.1768 1.0000
57.1600 10.4361 1.0000
57.2200 10.0727 1.0000
57.2800 3.1846 1.0000
57.3400 7.5345 1.0000
57.4000 5.3739 1.0000
57.4600 7.9191 1.0000
57.5200 3.5827 1.0000
57.5800 2.9250 1.0000
57.6400 2.4413 1.0000
57.7000 6.5203 1.0000
57.7600 7.1511 1.0000
57.8200 8.3536 1.0000
57.8800 7.2791 1.0000
57.9400 3.3768 1.0000
58.0000 4.9855 1.0000
58.0600 3.4894 1.0000
58.1200 4.6545 1.0000
58.1800 4.1542 1.0000
58.2400 8.9738 1.0000
58.3000 2.8086 1.0000
58.3600 10.3550 1.0000
58.4200 4.0398 1.0000
58.4800 1.1018 1.0000
58.5400 7.1882 1.0000
58.6000 5.2070 1.0000
58.6600 7.8203 1.0000
58.7200 2.9508 1.0000
58.7800 3.7535 1.0000
58.8400 4.9895 1.0000
58.9000 4.6004 1.0000
58.9600 7.6556 1.0000
59.0200 9.3726 1.0000
59.0800 10.2925 1.0000
59.1400 11.8899 1.0000
59.2000 5.4114 1.0000
59.2600 5.7863 1.0000
59.3200 3.6188 1.0000
59.3800 5.1592 1.0000
59.4400 3.3436 1.0000
59.5000 6.5014 1.0000
59.5600 9.9886 1.0000
59.6200 5.7423 1.0000
59.6800 5.2435 1.0000
59.7400 5.8580 1.0000
59.8000 3.9098 1.0000
59.8600 5.3358 1.0000
59.9200 6.9973 1.0000
59.9800 6.9704 1.0000
60.0400 15.9210 1.0000
60.1000 7.6535 1.0000
60.1600 5.8768 1.0000
60.2200 5.7222 1.0000
60.2800 10.1219 1.0000
60.3400 5.0642 1.0000
60.4000 10.4407 1.0000
60.4600 5.1205 1.0000
60.5200 6.1668 1.0000
60.5800 8.4945 1.0000
60.6400 6.9803 1.0000
60.7000 6.1117 1.0000
60.7600 8.8306 1.0000
60.8200 6.3234 1.0000
60.8800 4.0969 1.0000
60.9400 6.0414 1.0000
61.0000 5.3719 1.0000
61.0600 11.5675 1.0000
61.1200 6.6623 1.0000
61.1800 6.9316 1.0000
61.2400 4.8678 1.0000
61.3000 10.4158 1.0000
61.3600 11.6588 1.0000
61.4200 6.9692 1.0000
61.4800 4.4846 1.0000
61.5400 8.3952 1.0000
61.6000 6.8673 1.0000
61.6600 8.4304 1.0000
61.7200 3.1325 1.0000
61.7800 5.1055 1.0000
61.8400 8.0074 1.0000
61.9000 6.1334 1.0000
61.9600 7.3146 1.0000
62.0200 8.0387 1.0000
62.0800 7.4962 1.0000
62.1400 10.6504 1.0000
62.2000 4.2599 1.0000
62.2600 2.1379 1.0000
62.3200 7.7576 1.0000
62.3800 3.4678 1.0000
62.4400 6.5983 1.0000
62.5000 4.1117 1.0000
62.5600 7.4890 1.0000
62.6200 4.2383 1.0000
62.6800 7.5248 1.0000
62.7400 5.1943 1.0000
62.8000 9.0852 1.0000
62.8600 5.5425 1.0000
62.9200 8.4882 1.0000
62.9800 7.1842 1.0000
63.0400 6.0920 1.0000
63.1000 7.2733 1.0000
63.1600 7.4347 1.0000
63.2200 5.7666 1.0000
63.2800 12.1917 1.0000
63.3400 7.5190 1.0000
63.4000 8.5499 1.0000
63.4600 2.2503 1.0000
63.5200 2.2689 1.0000
63.5800 1.9382 1.0000
63.6400 5.3624 1.0000
63.7000 5.5578 1.0000
63.7600 7.4399 1.0000
63.8200 6.4880 1.0000
63.8800 4.7786 1.0000
63.9400 2.5360 1.0000
64.0000 11.2757 1.0000
64.0600 3.5239 1.0000
64.1200 8.4470 1.0000
64.1800 7.5921 1.0000
64.2400 6.3897 1.0000
64.3000 5.9824 1.0000
64.3600 3.5386 1.0000
64.4200 10.2930 1.0000
64.4800 7.1130 1.0000
64.5400 9.1304 1.0000
64.6000 4.3360 1.0000
64.6600 15.1312 1.0000
64.7200 20.4146 1.0000
64.7800 15.8238 1.0000
64.8400 18.0602 1.0000
64.9000 26.2403 1.0000
64.9600 18.6189 1.0000
65.0200 17.6382 1.0000
65.0800 10.8573 1.0000
65.1400 8.9480 1.0000
65.2000 10.0131 1.0000
65.2600 7.2939 1.0000
65.3200 6.6976 1.0000
65.3800 4.1711 1.0000
65.4400 2.9372 1.0000
65.5000 3.9324 1.0000
65.5600 2.2904 1.0000
65.6200 5.7914 1.0000
65.6800 4.5975 1.0000
65.7400 5.2158 1.0000
65.8000 5.3380 1.0000
65.8600 7.3944 1.0000
65.9200 6.1833 1.0000
65.9800 4.1266 1.0000
66.0400 6.9559 1.0000
66.1000 6.7819 1.0000
66.1600 6.6511 1.0000
66.2200 3.1122 1.0000
66.2800 3.3687 1.0000
66.3400 5.3255 1.0000
66.4000 6.0587 1.0000
66.4600 8.3378 1.0000
66.5200 3.0401 1.0000
66.5800 7.3992 1.0000
66.6400 3.7025 1.0000
66.7000 7.9295 1.0000
66.7600 2.6198 1.0000
66.8200 3.9085 1.0000
66.8800 8.0643 1.0000
66.9400 9.4000 1.0000
67.0000 4.2139 1.0000
67.0600 2.1578 1.0000
67.1200 4.9935 1.0000
67.1800 7.2773 1.0000
67.2400 5.8332 1.0000
67.3000 4.8389 1.0000
67.3600 8.1921 1.0000
67.4200 7.4964 1.0000
67.4800 7.7570 1.0000
67.5400 10.4485 1.0000
67.6000 5.9736 1.0000
67.6600 4.9030 1.0000
67.7200 4.9777 1.0000
67.7800 3.6556 1.0000
67.8400 3.6997 1.0000
67.9000 5.6585 1.0000
67.9600 4.7439 1.0000
68.0200 6.9934 1.0000
68.0800 3.5331 1.0000
68.1400 5.0913 1.0000
68.2000 12.3671 1.0000
68.2600 5.7799 1.0000
68.3200 5.0873 1.0000
68.3800 5.0569 1.0000
68.4400 5.0523 1.0000
68.5000 6.3264 1.0000
68.5600 10.1061 1.0000
68.6200 2.7920 1.0000
68.6800 2.0858 1.0000
68.7400 5.4715 1.0000
68.8000 10.7991 1.0000
68.8600 7.3897 1.0000
68.9200 1.5824 1.0000
68.9800 7.8383 1.0000
69.0400 10.6463 1.0000
69.1000 7.7212 1.0000
69.1600 4.7442 1.0000
69.2200 7.3520 1.0000
69.2800 5.8849 1.0000
69.3400 4.9554 1.0000
69.4000 3.9662 1.0000
69.4600 5.1110 1.0000
69.5200 3.9946 1.0000
69.5800 5.4800 1.0000
69.6400 5.7465 1.0000
69.7000 8.6776 1.0000
69.7600 9.0733 1.0000
69.8200 8.1509 1.0000
69.8800 8.4669 1.0000
69.9400 10.0391 1.0000
70.0000 4.1576 1.0000
70.0600 8.0510 1.0000
70.1200 2.3522 1.0000
70.1800 6.2543 1.0000
70.2400 6.4388 1.0000
70.3000 4.1314 1.0000
70.3600 7.2258 1.0000
70.4200 1.9823 1.0000
70.4800 8.9685 1.0000
70.5400 6.3502 1.0000
70.6000 7.4241 1.0000
70.6600 8.3061 1.0000
70.7200 2.7219 1.0000
70.7800 7.2798 1.0000
70.8400 2.4152 1.0000
70.9000 4.3235 1.0000
70.9600 8.0126 1.0000
71.0200 13.4709 1.0000
71.0800 8.5001 1.0000
71.1400 5.1042 1.0000
71.2000 6.3626 1.0000
71.2600 8.0815 1.0000
71.3200 3.1413 1.0000
71.3800 5.6512 1.0000
71.4400 5.6780 1.0000
71.5000 6.6654 1.0000
71.5600 6.0113 1.0000
71.6200 5.3238 1.0000
71.6800 5.1549 1.0000
71.7400 0.4641 1.0000
71.8000 5.6961 1.0000
71.8600 3.5502 1.0000
71.9200 6.8133 1.0000
71.9800 4.5336 1.0000
72.0400 6.1698 1.0000
72.1000 3.6747 1.0000
72.1600 8.4017 1.0000
72.2200 5.8992 1.0000
72.2800 9.4406 1.0000
72.3400 7.7186 1.0000
72.4000 6.2699 1.0000
72.4600 7.2122 1.0000
72.5200 8.1634 1.0000
72.5800 7.6148 1.0000
72.6400 4.8484 1.0000
72.7000 7.3302 1.0000
72.7600 7.5576 1.0000
72.8200 8.3136 1.0000
72.8800 7.3970 1.0000
72.9400 9.2582 1.0000
73.0000 4.1340 1.0000
73.0600 6.5380 1.0000
73.1200 5.3466 1.0000
73.1800 5.6331 1.0000
73.2400 5.7328 1.0000
73.3000 2.3552 1.0000
73.3600 6.3147 1.0000
73.4200 2.3616 1.0000
73.4800 4.2249 1.0000
73.5400 7.8074 1.0000
73.6000 4.4171 1.0000
73.6600 6.7908 1.0000
73.7200 4.3827 1.0000
73.7800 3.9043 1.0000
73.8400 6.9246 1.0000
73.9000 10.7958 1.0000
73.9600 7.3204 1.0000
74.0200 6.3791 1.0000
74.0800 4.1545 1.0000
74.1400 5.5083 1.0000
74.2000 2.8534 1.0000
74.2600 9.1430 1.0000
74.3200 9.7813 1.0000
74.3800 7.6596 1.0000
74.4400 3.5429 1.0000
74.5000 5.2876 1.0000
74.5600 10.0871 1.0000
74.6200 4.9956 1.0000
74.6800 10.3807 1.0000
74.7400 5.9068 1.0000
74.8000 4.4210 1.0000
74.8600 4.2762 1.0000
74.9200 7.1970 1.0000
74.9800 3.5828 1.0000
75.0400 6.6419 1.0000
75.1000 7.2164 1.0000
75.1600 4.5193 1.0000
75.2200 5.4351 1.0000
75.2800 4.5394 1.0000
75.3400 3.8044 1.0000
75.4000 3.5558 1.0000
75.4600 5.9592 1.0000
75.5200 2.8662 1.0000
75.5800 4.2806 1.0000
75.6400 4.1822 1.0000
75.7000 6.9703 1.0000
75.7600 3.1047 1.0000
75.8200 7.3114 1.0000
75.8800 4.5409 1.0000
75.9400 11.8148 1.0000
76.0000 6.8855 1.0000
76.0600 5.5362 1.0000
76.1200 8.3961 1.0000
76.1800 11.1324 1.0000
76.2400 5.3242 1.0000
76.3000 5.5702 1.0000
76.3600 5.4056 1.0000
76.4200 5.7476 1.0000
76.4800 4.8351 1.0000
76.5400 4.0505 1.0000
76.6000 4.3486 1.0000
76.6600 10.1861 1.0000
76.7200 3.5613 1.0000
76.7800 4.0647 1.0000
76.8400 5.3298 1.0000
76.9000 6.7630 1.0000
76.9600 4.4538 1.0000
77.0200 8.7880 1.0000
77.0800 7.0103 1.0000
77.1400 4.0283 1.0000
77.2000 8.0121 1.0000
77.2600 7.9406 1.0000
77.3200 4.4329 1.0000
77.3800 9.2363 1.0000
77.4400 4.1284 1.0000
77.5000 9.4101 1.0000
77.5600 9.9176 1.0000
77.6200 5.5491 1.0000
77.6800 3.5287 1.0000
77.7400 3.9286 1.0000
77.8000 8.2047 1.0000
77.8600 4.8441 1.0000
77.9200 3.2797 1.0000
77.9800 6.4744 1.0000
78.0400 6.5391 1.0000
78.1000 5.1442 1.0000
78.1600 9.9233 1.0000
78.2200 3.0486 1.0000
78.2800 2.0179 1.0000
78.3400 9.7106 1.0000
78.4000 8.3853 1.0000
78.4600 7.9080 1.0000
78.5200 1.2614 1.0000
78.5800 5.0240 1.0000
78.6400 7.0399 1.0000
78.7000 6.3739 1.0000
78.7600 3.3412 1.0000
78.8200 4.0134 1.0000
78.8800 14.0317 1.0000
78.9400 3.7080 1.0000
79.0000 1.7503 1.0000
79.0600 3.8597 1.0000
79.1200 8.1877 1.0000
79.1800 3.9499 1.0000
79.2400 1.4712 1.0000
79.3000 6.1688 1.0000
79.3600 10.5844 1.0000
79.4200 6.3337 1.0000
79.4800 6.9536 1.0000
79.5400 6.1366 1.0000
79.6000 5.3323 1.0000
79.6600 7.9057 1.0000
79.7200 5.0026 1.0000
79.7800 4.2471 1.0000
79.8400 9.2921 1.0000
79.9000 4.3868 1.0000
79.9600 7.9232 1.0000
80.0200 3.7479 1.0000
80.0800 4.7733 1.0000
80.1400 7.9294 1.0000
80.2000 2.3486 1.0000
80.2600 6.2675 1.0000
80.3200 7.1893 1.0000
80.3800 4.7413 1.0000
80.4400 5.3392 1.0000
80.5000 7.2922 1.0000
80.5600 8.5603 1.0000
80.6200 5.1607 1.0000
80.6800 9.5328 1.0000
80.7400 9.4847 1.0000
80.8000 7.3122 1.0000
80.8600 4.8024 1.0000
80.9200 5.9447 1.0000
80.9800 3.8604 1.0000
81.0400 2.5832 1.0000
81.1000 5.9411 1.0000
81.1600 5.4326 1.0000
81.2200 4.8524 1.0000
81.2800 8.2908 1.0000
81.3400 3.3409 1.0000
81.4000 4.6390 1.0000
81.4600 7.2287 1.0000
81.5200 14.2421 1.0000
81.5800 9.0638 1.0000
81.6400 7.9222 1.0000
81.7000 5.5662 1.0000
81.7600 8.6040 1.0000
81.8200 20.0714 1.0000
81.8800 17.1674 1.0000
81.9400 22.5478 1.0000
82.0000 31.8322 1.0000
82.0600 42.4397 1.0000
82.1200 32.1613 1.0000
82.1800 30.7421 1.0000
82.2400 21.5015 1.0000
82.3000 17.7938 1.0000
82.3600 13.5015 1.0000
82.4200 9.8827 1.0000
82.4800 5.9020 1.0000
82.5400 4.4754 1.0000
82.6000 8.0710 1.0000
82.6600 7.0220 1.0000
82.7200 9.9629 1.0000
82.7800 6.9883 1.0000
82.8400 4.5477 1.0000
82.9000 1.7161 1.0000
82.9600 5.0795 1.0000
83.0200 6.3674 1.0000
83.0800 6.5690 1.0000
83.1400 7.7474 1.0000
83.2000 5.6866 1.0000
83.2600 4.2700 1.0000
83.3200 7.1748 1.0000
83.3800 5.3132 1.0000
83.4400 4.3871 1.0000
83.5000 3.0751 1.0000
83.5600 7.1198 1.0000
83.6200 10.3967 1.0000
83.6800 9.0666 1.0000
83.7400 1.8985 1.0000
83.8000 7.0928 1.0000
83.8600 6.0110 1.0000
83.9200 6.9566 1.0000
83.9800 3.0819 1.0000
84.0400 4.6951 1.0000
84.1000 2.3988 1.0000
84.1600 8.4676 1.0000
84.2200 8.7460 1.0000
84.2800 5.3008 1.0000
84.3400 5.4034 1.0000
84.4000 8.3905 1.0000
84.4600 4.6205 1.0000
84.5200 7.7658 1.0000
84.5800 3.6108 1.0000
84.6400 6.8159 1.0000
84.7000 9.9119 1.0000
84.7600 12.2762 1.0000
84.8200 8.1689 1.0000
84.8800 6.4832 1.0000
84.9400 9.4400 1.0000
85.0000 3.7119 1.0000
85.0600 7.6012 1.0000
85.1200 5.9361 1.0000
85.1800 8.1674 1.0000
85.2400 6.0471 1.0000
85.3000 8.1768 1.0000
85.3600 6.0211 1.0000
85.4200 3.8217 1.0000
85.4800 6.6513 1.0000
85.5400 7.8999 1.0000
85.6000 4.1308 1.0000
85.6600 5.3144 1.0000
85.7200 4.2669 1.0000
85.7800 7.1017 1.0000
85.8400 6.9266 1.0000
85.9000 5.4986 1.0000
85.9600 10.2696 1.0000
86.0200 6.5428 1.0000
86.0800 10.5710 1.0000
86.1400 12.4812 1.0000
86.2000 3.9396 1.0000
86.2600 5.1579 1.0000
86.3200 3.2143 1.0000
86.3800 7.4561 1.0000
86.4400 5.2201 1.0000
86.5000 12.5215 1.0000
86.5600 3.3107 1.0000
86.6200 7.1612 1.0000
86.6800 7.1410 1.0000
86.7400 4.2708 1.0000
86.8000 2.7261 1.0000
86.8600 4.3821 1.0000
86.9200 4.5884 1.0000
86.9800 6.5655 1.0000
87.0400 6.3940 1.0000
87.1000 2.9298 1.0000
87.1600 6.5533 1.0000
87.2200 5.9464 1.0000
87.2800 6.0439 1.0000
87.3400 7.1378 1.0000
87.4000 5.9291 1.0000
87.4600 4.8307 1.0000
87.5200 4.1997 1.0000
87.5800 2.5572 1.0000
87.6400 2.4305 1.0000
87.7000 7.2794 1.0000
87.7600 6.4608 1.0000
87.8200 8.1382 1.0000
87.8800 3.7686 1.0000
87.9400 21.2894 1.0000
88.0000 5.6030 1.0000
88.0600 4.1744 1.0000
88.1200 6.6979 1.0000
88.1800 6.7454 1.0000
88.2400 4.2066 1.0000
88.3000 5.6720 1.0000
88.3600 6.2042 1.0000
88.4200 7.8443 1.0000
88.4800 8.3859 1.0000
88.5400 5.3023 1.0000
88.6000 3.0412 1.0000
88.6600 6.6959 1.0000
88.7200 3.6856 1.0000
88.7800 7.6117 1.0000
88.8400 4.6198 1.0000
88.9000 1.0775 1.0000
88.9600 3.8050 1.0000
89.0200 6.3942 1.0000
89.0800 3.6029 1.0000
89.1400 6.2635 1.0000
89.2000 7.1722 1.0000
89.2600 4.0239 1.0000
89.3200 7.0259 1.0000
89.3800 2.6742 1.0000
89.4400 9.3507 1.0000
89.5000 6.9613 1.0000
89.5600 5.4477 1.0000
89.6200 7.1663 1.0000
89.6800 4.0674 1.0000
89.7400 2.4074 1.0000
89.8000 7.2791 1.0000
89.8600 3.5710 1.0000
89.9200 5.2953 1.0000
89.9800 5.0887 1.0000
90.0400 1.3079 1.0000
90.1000 7.7172 1.0000
90.1600 2.5168 1.0000
90.2200 7.7246 1.0000
90.2800 5.5964 1.0000
90.3400 5.1328 1.0000
90.4000 9.4612 1.0000
90.4600 6.7755 1.0000
90.5200 9.5442 1.0000
90.5800 5.0219 1.0000
90.6400 7.9090 1.0000
90.7000 2.6038 1.0000
90.7600 7.7975 1.0000
90.8200 7.6202 1.0000
90.8800 5.5524 1.0000
90.9400 5.0263 1.0000
91.0000 5.9697 1.0000
91.0600 9.1074 1.0000
91.1200 4.3908 1.0000
91.1800 0.8758 1.0000
91.2400 4.3665 1.0000
91.3000 1.6405 1.0000
91.3600 9.3289 1.0000
91.4200 4.0694 1.0000
91.4800 5.6052 1.0000
91.5400 5.2919 1.0000
91.6000 5.5344 1.0000
91.6600 4.4820 1.0000
91.7200 3.9198 1.0000
91.7800 7.3631 1.0000
91.8400 9.4714 1.0000
91.9000 6.7660 1.0000
91.9600 12.2503 1.0000
92.0200 5.0493 1.0000
92.0800 6.5918 1.0000
92.1400 4.2204 1.0000
92.2000 9.1904 1.0000
92.2600 5.5415 1.0000
92.3200 8.3718 1.0000
92.3800 8.8491 1.0000
92.4400 8.4065 1.0000
92.5000 3.3287 1.0000
92.5600 6.8830 1.0000
92.6200 6.6116 1.0000
92.6800 2.7624 1.0000
92.7400 11.9352 1.0000
92.8000 6.8678 1.0000
92.8600 0.5188 1.0000
92.9200 8.1465 1.0000
92.9800 10.4947 1.0000
93.0400 4.1467 1.0000
93.1000 7.9634 1.0000
93.1600 1.3367 1.0000
93.2200 5.9154 1.0000
93.2800 4.5113 1.0000
93.3400 5.2022 1.0000
93.4000 7.4214 1.0000
93.4600 4.0934 1.0000
93.5200 7.5907 1.0000
93.5800 5.9290 1.0000
93.6400 4.9583 1.0000
93.7000 7.1399 1.0000
93.7600 5.2653 1.0000
93.8200 3.2246 1.0000
93.8800 7.3043 1.0000
93.9400 9.5319 1.0000
94.0000 6.4091 1.0000
94.0600 7.8882 1.0000
94.1200 4.9908 1.0000
94.1800 14.9215 1.0000
94.2400 6.4118 1.0000
94.3000 9.1520 1.0000
94.3600 10.1502 1.0000
94.4200 4.7010 1.0000
94.4800 1.5156 1.0000
94.5400 7.3660 1.0000
94.6000 2.4501 1.0000
94.6600 9.4443 1.0000
94.7200 4.3190 1.0000
94.7800 8.9711 1.0000
94.8400 3.9201 1.0000
94.9000 4.7311 1.0000
94.9600 3.4208 1.0000
95.0200 7.3591 1.0000
95.0800 7.8450 1.0000
95.1400 4.0196 1.0000
95.2000 4.0513 1.0000
95.2600 7.8036 1.0000
95.3200 9.5057 1.0000
95.3800 8.6302 1.0000
95.4400 4.3852 1.0000
95.5000 5.2020 1.0000
95.5600 12.1968 1.0000
95.6200 7.8535 1.0000
95.6800 8.9094 1.0000
95.7400 8.8806 1.0000
95.8000 7.7896 1.0000
95.8600 7.9169 1.0000
95.9200 6.8854 1.0000
95.9800 5.7378 1.0000
96.0400 3.8385 1.0000
96.1000 3.1969 1.0000
96.1600 4.0937 1.0000
96.2200 6.4964 1.0000
96.2800 7.8660 1.0000
96.3400 2.5245 1.0000
96.4000 2.0564 1.0000
96.4600 5.7533 1.0000
96.5200 6.2935 1.0000
96.5800 5.6040 1.0000
96.6400 3.5575 1.0000
96.7000 6.7490 1.0000
96.7600 3.9608 1.0000
96.8200 6.8142 1.0000
96.8800 6.7881 1.0000
96.9400 5.3793 1.0000
97.0000 5.5050 1.0000
97.0600 2.8045 1.0000
97.1200 4.5808 1.0000
97.1800 5.8534 1.0000
97.2400 4.1119 1.0000
97.3000 9.4313 1.0000
97.3600 7.2198 1.0000
97.4200 10.1944 1.0000
97.4800 5.9038 1.0000
97.5400 4.8109 1.0000
97.6000 8.0725 1.0000
97.6600 3.3648 1.0000
97.7200 6.0259 1.0000
97.7800 5.7668 1.0000
97.8400 7.1422 1.0000
97.9000 10.1981 1.0000
97.9600 4.6707 1.0000
98.0200 6.3152 1.0000
98.0800 7.3905 1.0000
98.1400 3.2745 1.0000
98.2000 5.5340 1.0000
98.2600 8.7913 1.0000
98.3200 11.8250 1.0000
98.3800 14.1254 1.0000
98.4400 11.2624 1.0000
98.5000 15.2739 1.0000
98.5600 12.8061 1.0000
98.6200 13.5372 1.0000
98.6800 17.4414 1.0000
98.7400 12.9582 1.0000
98.8000 14.6966 1.0000
98.8600 18.0114 1.0000
98.9200 12.2708 1.0000
98.9800 13.5262 1.0000
99.0400 5.5231 1.0000
99.1000 12.3937 1.0000
99.1600 11.3793 1.0000
99.2200 5.8407 1.0000
99.2800 5.1827 1.0000
99.3400 1.4761 1.0000
99.4000 4.7730 1.0000
99.4600 1.9442 1.0000
99.5200 9.3029 1.0000
99.5800 3.3951 1.0000
99.6400 3.7217 1.0000
99.7000 6.1497 1.0000
99.7600 10.5398 1.0000
99.8200 4.0964 1.0000
99.8800 7.7544 1.0000
99.9400 5.0498 1.0000
100.0000 9.0998 1.0000
100.0600 3.7759 1.0000
100.1200 5.3175 1.0000
100.1800 5.4917 1.0000
100.2400 8.9030 1.0000
100.3000 4.0064 1.0000
100.3600 8.1123 1.0000
100.4200 6.5567 1.0000
100.4800 7.6093 1.0000
100.5400 6.9775 1.0000
100.6000 5.1292 1.0000
100.6600 3.5275 1.0000
100.7200 10.0086 1.0000
100.7800 10.7874 1.0000
100.8400 7.2450 1.0000
100.9000 5.6470 1.0000
100.9600 5.0356 1.0000
101.0200 6.2365 1.0000
101.0800 10.3212 1.0000
101.1400 5.0945 1.0000
101.2000 8.0682 1.0000
101.2600 2.2973 1.0000
101.3200 11.0717 1.0000
101.3800 4.3009 1.0000
101.4400 9.4475 1.0000
101.5000 9.7393 1.0000
101.5600 3.2073 1.0000
101.6200 4.6468 1.0000
101.6800 3.3484 1.0000
101.7400 9.0107 1.0000
101.8000 9.5151 1.0000
101.8600 14.6951 1.0000
101.9200 9.2054 1.0000
101.9800 7.7973 1.0000
102.0400 5.2236 1.0000
102.1000 3.8136 1.0000
102.1600 9.2706 1.0000
102.2200 7.9521 1.0000
102.2800 8.0410 1.0000
102.3400 6.3096 1.0000
102.4000 5.9009 1.0000
102.4600 7.2716 1.0000
102.5200 7.2590 1.0000
102.5800 1.3763 1.0000
102.6400 3.9768 1.0000
102.7000 10.2999 1.0000
102.7600 6.1692 1.0000
102.8200 8.4097 1.0000
102.8800 4.1499 1.0000
102.9400 11.7969 1.0000
103.0000 4.0164 1.0000
103.0600 4.3981 1.0000
103.1200 4.1533 1.0000
103.1800 3.3170 1.0000
103.2400 6.7973 1.0000
103.3000 4.1356 1.0000
103.3600 12.4930 1.0000
103.4200 6.0449 1.0000
103.4800 8.1035 1.0000
103.5400 4.6670 1.0000
103.6000 10.1356 1.0000
103.6600 6.2450 1.0000
103.7200 5.4261 1.0000
103.7800 9.0472 1.0000
103.8400 6.2342 1.0000
103.9000 3.1841 1.0000
103.9600 2.6599 1.0000
104.0200 10.9822 1.0000
104.0800 2.7334 1.0000
104.1400 5.9024 1.0000
104.2000 11.2170 1.0000
104.2600 2.3129 1.0000
104.3200 2.3331 1.0000
104.3800 8.2879 1.0000
104.4400 7.4751 1.0000
104.5000 4.7375 1.0000
104.5600 7.2180 1.0000
104.6200 7.9679 1.0000
104.6800 9.0993 1.0000
104.7400 4.1540 1.0000
104.8000 8.4583 1.0000
104.8600 3.8533 1.0000
104.9200 6.5875 1.0000
104.9800 7.3886 1.0000
105.0400 5.6374 1.0000
105.1000 8.3574 1.0000
105.1600 5.6685 1.0000
105.2200 4.1423 1.0000
105.2800 7.4926 1.0000
105.3400 6.4290 1.0000
105.4000 4.3188 1.0000
105.4600 5.8573 1.0000
105.5200 4.3005 1.0000
105.5800 1.7269 1.0000
105.6400 7.0776 1.0000
105.7000 2.5182 1.0000
105.7600 3.3956 1.0000
105.8200 7.6024 1.0000
105.8800 7.0356 1.0000
105.9400 5.0971 1.0000
106.0000 10.3587 1.0000
106.0600 5.3583 1.0000
106.1200 6.6540 1.0000
106.1800 8.2125 1.0000
106.2400 5.7166 1.0000
106.3000 6.4372 1.0000
106.3600 2.5677 1.0000
106.4200 9.2335 1.0000
106.4800 13.9006 1.0000
106.5400 5.2865 1.0000
106.6000 8.5612 1.0000
106.6600 5.7754 1.0000
106.7200 5.6747 1.0000
106.7800 8.4226 1.0000
106.8400 2.4988 1.0000
106.9000 4.1728 1.0000
106.9600 4.1847 1.0000
107.0200 6.9635 1.0000
107.0800 2.3127 1.0000
107.1400 3.3714 1.0000
107.2000 3.7443 1.0000
107.2600 5.8468 1.0000
107.3200 1.2375 1.0000
107.3800 3.4989 1.0000
107.4400 4.1002 1.0000
107.5000 5.4894 1.0000
107.5600 5.7391 1.0000
107.6200 5.7204 1.0000
107.6800 7.9566 1.0000
107.7400 5.1701 1.0000
107.8000 13.7076 1.0000
107.8600 6.8982 1.0000
107.9200 9.7774 1.0000
107.9800 5.3215 1.0000
108.0400 3.5699 1.0000
108.1000 6.5116 1.0000
108.1600 4.3612 1.0000
108.2200 7.7000 1.0000
108.2800 4.1509 1.0000
[...]
67.0000 7.3918 1.0000
67.0600 4.2538 1.0000
67.1200 3.8278 1.0000
67.1800 5.9394 1.0000
67.2400 4.6126 1.0000
67.3000 13.2494 1.0000
67.3600 4.6564 1.0000
67.4200 7.4090 1.0000
67.4800 3.3081 1.0000
67.5400 6.4613 1.0000
67.6000 5.0166 1.0000
67.6600 6.6594 1.0000
67.7200 8.9584 1.0000
67.7800 9.1438 1.0000
67.8400 3.1707 1.0000
67.9000 1.8868 1.0000
67.9600 7.0618 1.0000
68.0200 2.3349 1.0000
68.0800 4.7770 1.0000
68.1400 6.6806 1.0000
68.2000 12.4343 1.0000
68.2600 9.8968 1.0000
68.3200 12.5275 1.0000
68.3800 8.6509 1.0000
68.4400 9.3061 1.0000
68.5000 7.4319 1.0000
68.5600 3.9588 1.0000
68.6200 4.6973 1.0000
68.6800 5.4389 1.0000
68.7400 18.2249 1.0000
68.8000 9.4937 1.0000
68.8600 4.4959 1.0000
68.9200 7.1169 1.0000
68.9800 6.5172 1.0000
69.0400 4.7144 1.0000
69.1000 5.7141 1.0000
69.1600 7.4503 1.0000
69.2200 4.5087 1.0000
69.2800 5.9306 1.0000
69.3400 8.6806 1.0000
69.4000 3.2506 1.0000
69.4600 8.0395 1.0000
69.5200 8.9754 1.0000
69.5800 8.2616 1.0000
69.6400 5.1332 1.0000
69.7000 4.8099 1.0000
69.7600 5.8182 1.0000
69.8200 10.2929 1.0000
69.8800 5.0809 1.0000
69.9400 8.2133 1.0000
70.0000 8.4397 1.0000
70.0600 9.3003 1.0000
70.1200 4.7999 1.0000
70.1800 7.0198 1.0000
70.2400 5.2917 1.0000
70.3000 4.7657 1.0000
70.3600 5.2478 1.0000
70.4200 5.2595 1.0000
70.4800 11.7632 1.0000
70.5400 3.9051 1.0000
70.6000 8.2560 1.0000
70.6600 11.1976 1.0000
70.7200 6.0894 1.0000
70.7800 8.2447 1.0000
70.8400 2.3976 1.0000
70.9000 5.8716 1.0000
70.9600 7.7541 1.0000
71.0200 4.0829 1.0000
71.0800 8.0383 1.0000
71.1400 9.0143 1.0000
71.2000 4.5521 1.0000
71.2600 3.5019 1.0000
71.3200 2.9994 1.0000
71.3800 5.0700 1.0000
71.4400 5.0721 1.0000
71.5000 5.8858 1.0000
71.5600 6.1904 1.0000
71.6200 11.1080 1.0000
71.6800 6.1125 1.0000
71.7400 3.6920 1.0000
71.8000 12.7007 1.0000
71.8600 12.1496 1.0000
71.9200 7.3485 1.0000
71.9800 7.5400 1.0000
72.0400 3.4451 1.0000
72.1000 6.3298 1.0000
72.1600 8.2293 1.0000
72.2200 4.4026 1.0000
72.2800 7.3282 1.0000
72.3400 7.5854 1.0000
72.4000 7.7389 1.0000
72.4600 6.5796 1.0000
72.5200 5.4430 1.0000
72.5800 2.3413 1.0000
72.6400 7.7215 1.0000
72.7000 10.7744 1.0000
72.7600 9.1988 1.0000
72.8200 5.3975 1.0000
72.8800 3.3965 1.0000
72.9400 7.1028 1.0000
73.0000 5.4802 1.0000
73.0600 8.2543 1.0000
73.1200 7.1880 1.0000
73.1800 6.6791 1.0000
73.2400 6.0627 1.0000
73.3000 6.4311 1.0000
73.3600 3.3503 1.0000
73.4200 10.1232 1.0000
73.4800 6.8397 1.0000
73.5400 8.4914 1.0000
73.6000 5.9764 1.0000
73.6600 9.8273 1.0000
73.7200 6.1722 1.0000
73.7800 9.6288 1.0000
73.8400 7.7007 1.0000
73.9000 5.1984 1.0000
73.9600 8.2550 1.0000
74.0200 5.4818 1.0000
74.0800 1.1725 1.0000
74.1400 4.7885 1.0000
74.2000 2.4199 1.0000
74.2600 4.5580 1.0000
74.3200 3.8957 1.0000
74.3800 4.2717 1.0000
74.4400 5.2668 1.0000
74.5000 11.4917 1.0000
74.5600 3.9886 1.0000
74.6200 2.9932 1.0000
74.6800 3.7338 1.0000
74.7400 9.7574 1.0000
74.8000 3.1666 1.0000
74.8600 5.0415 1.0000
74.9200 1.2713 1.0000
74.9800 5.2029 1.0000
75.0400 6.0547 1.0000
75.1000 8.3669 1.0000
75.1600 4.4801 1.0000
75.2200 8.2192 1.0000
75.2800 7.7511 1.0000
75.3400 4.1903 1.0000
75.4000 3.7582 1.0000
75.4600 4.4031 1.0000
75.5200 4.7601 1.0000
75.5800 5.8824 1.0000
75.6400 4.9144 1.0000
75.7000 4.7184 1.0000
75.7600 5.4445 1.0000
75.8200 4.7868 1.0000
75.8800 7.6502 1.0000
75.9400 1.1805 1.0000
76.0000 5.5760 1.0000
76.0600 5.4966 1.0000
76.1200 4.2741 1.0000
76.1800 4.2928 1.0000
76.2400 3.9213 1.0000
76.3000 6.2288 1.0000
76.3600 9.0943 1.0000
76.4200 4.8988 1.0000
76.4800 5.5176 1.0000
76.5400 6.5959 1.0000
76.6000 7.2950 1.0000
76.6600 5.4988 1.0000
76.7200 4.0956 1.0000
76.7800 6.3390 1.0000
76.8400 2.6721 1.0000
76.9000 6.0091 1.0000
76.9600 5.7183 1.0000
77.0200 4.0856 1.0000
77.0800 7.2523 1.0000
77.1400 2.6987 1.0000
77.2000 5.7326 1.0000
77.2600 7.2322 1.0000
77.3200 6.0830 1.0000
77.3800 3.9557 1.0000
77.4400 6.2009 1.0000
77.5000 5.1329 1.0000
77.5600 6.1873 1.0000
77.6200 6.2076 1.0000
77.6800 8.3926 1.0000
77.7400 5.6654 1.0000
77.8000 3.1723 1.0000
77.8600 5.4555 1.0000
77.9200 5.8990 1.0000
77.9800 12.1652 1.0000
78.0400 13.1128 1.0000
78.1000 7.9380 1.0000
78.1600 9.3136 1.0000
78.2200 9.9192 1.0000
78.2800 6.3650 1.0000
78.3400 9.9063 1.0000
78.4000 7.2523 1.0000
78.4600 4.6044 1.0000
78.5200 11.7416 1.0000
78.5800 4.0152 1.0000
78.6400 7.3735 1.0000
78.7000 3.2110 1.0000
78.7600 5.3624 1.0000
78.8200 11.6354 1.0000
78.8800 3.6977 1.0000
78.9400 3.9431 1.0000
79.0000 6.3485 1.0000
79.0600 6.2904 1.0000
79.1200 8.4814 1.0000
79.1800 3.8383 1.0000
79.2400 3.6029 1.0000
79.3000 8.3565 1.0000
79.3600 11.4183 1.0000
79.4200 7.5130 1.0000
79.4800 3.8588 1.0000
79.5400 6.9652 1.0000
79.6000 1.4324 1.0000
79.6600 5.9573 1.0000
79.7200 4.0091 1.0000
79.7800 6.1603 1.0000
79.8400 8.0023 1.0000
79.9000 12.4331 1.0000
79.9600 3.6852 1.0000
80.0200 10.1965 1.0000
80.0800 3.1003 1.0000
80.1400 11.6872 1.0000
80.2000 3.8682 1.0000
80.2600 10.3641 1.0000
80.3200 6.9982 1.0000
80.3800 8.6394 1.0000
80.4400 8.3769 1.0000
80.5000 6.2883 1.0000
80.5600 4.0121 1.0000
80.6200 3.2880 1.0000
80.6800 10.7071 1.0000
80.7400 3.2387 1.0000
80.8000 5.8581 1.0000
80.8600 5.6792 1.0000
80.9200 9.8503 1.0000
80.9800 9.2378 1.0000
81.0400 6.9683 1.0000
81.1000 8.1682 1.0000
81.1600 6.3468 1.0000
81.2200 7.1747 1.0000
81.2800 5.3104 1.0000
81.3400 8.8623 1.0000
81.4000 5.0824 1.0000
81.4600 0.8663 1.0000
81.5200 7.2454 1.0000
81.5800 5.2688 1.0000
81.6400 8.8944 1.0000
81.7000 6.8512 1.0000
81.7600 12.0921 1.0000
81.8200 21.0238 1.0000
81.8800 15.8077 1.0000
81.9400 23.3266 1.0000
82.0000 34.6347 1.0000
82.0600 26.4042 1.0000
82.1200 25.2966 1.0000
82.1800 34.8198 1.0000
82.2400 23.3631 1.0000
82.3000 21.1814 1.0000
82.3600 15.6799 1.0000
82.4200 7.8207 1.0000
82.4800 5.7973 1.0000
82.5400 6.3057 1.0000
82.6000 2.9517 1.0000
82.6600 9.6019 1.0000
82.7200 7.2164 1.0000
82.7800 6.5531 1.0000
82.8400 4.2407 1.0000
82.9000 5.2712 1.0000
82.9600 14.6991 1.0000
83.0200 4.2443 1.0000
83.0800 5.1138 1.0000
83.1400 8.0974 1.0000
83.2000 7.6683 1.0000
83.2600 3.4255 1.0000
83.3200 6.7443 1.0000
83.3800 6.5694 1.0000
83.4400 7.1804 1.0000
83.5000 3.0547 1.0000
83.5600 9.9101 1.0000
83.6200 5.6881 1.0000
83.6800 7.1814 1.0000
83.7400 5.4937 1.0000
83.8000 7.2997 1.0000
83.8600 6.3427 1.0000
83.9200 8.1337 1.0000
83.9800 7.5792 1.0000
84.0400 9.1054 1.0000
84.1000 6.5896 1.0000
84.1600 6.6531 1.0000
84.2200 7.1034 1.0000
84.2800 12.1997 1.0000
84.3400 9.2260 1.0000
84.4000 5.4088 1.0000
84.4600 7.6936 1.0000
84.5200 9.3609 1.0000
84.5800 6.2748 1.0000
84.6400 6.9575 1.0000
84.7000 3.3011 1.0000
84.7600 8.4038 1.0000
84.8200 4.8036 1.0000
84.8800 2.8673 1.0000
84.9400 1.6950 1.0000
85.0000 7.3480 1.0000
85.0600 9.7979 1.0000
85.1200 4.8563 1.0000
85.1800 8.1016 1.0000
85.2400 10.8755 1.0000
85.3000 3.9630 1.0000
85.3600 1.6920 1.0000
85.4200 8.5857 1.0000
85.4800 6.2558 1.0000
85.5400 7.2655 1.0000
85.6000 9.6084 1.0000
85.6600 7.5238 1.0000
85.7200 3.0147 1.0000
85.7800 3.3329 1.0000
85.8400 9.9909 1.0000
85.9000 7.6223 1.0000
85.9600 10.6242 1.0000
86.0200 11.5119 1.0000
86.0800 5.9972 1.0000
86.1400 7.0895 1.0000
86.2000 6.9230 1.0000
86.2600 6.0562 1.0000
86.3200 4.9121 1.0000
86.3800 4.5746 1.0000
86.4400 2.6112 1.0000
86.5000 4.9440 1.0000
86.5600 4.1881 1.0000
86.6200 9.9337 1.0000
86.6800 4.8889 1.0000
86.7400 4.3328 1.0000
86.8000 3.7216 1.0000
86.8600 3.1324 1.0000
86.9200 5.2514 1.0000
86.9800 12.5795 1.0000
87.0400 6.2579 1.0000
87.1000 7.4666 1.0000
87.1600 5.7925 1.0000
87.2200 3.4693 1.0000
87.2800 2.2567 1.0000
87.3400 6.1580 1.0000
87.4000 5.7054 1.0000
87.4600 8.2351 1.0000
87.5200 3.2619 1.0000
87.5800 5.9078 1.0000
87.6400 3.7194 1.0000
87.7000 3.2032 1.0000
87.7600 11.1172 1.0000
87.8200 5.5848 1.0000
87.8800 8.3706 1.0000
87.9400 5.0770 1.0000
88.0000 5.7504 1.0000
88.0600 6.6813 1.0000
88.1200 4.7703 1.0000
88.1800 9.9861 1.0000
88.2400 4.3118 1.0000
88.3000 6.9629 1.0000
88.3600 1.2811 1.0000
88.4200 6.6961 1.0000
88.4800 8.7800 1.0000
88.5400 4.8545 1.0000
88.6000 6.0278 1.0000
88.6600 6.8717 1.0000
88.7200 2.1852 1.0000
88.7800 2.1122 1.0000
88.8400 4.0912 1.0000
88.9000 2.9461 1.0000
88.9600 5.0929 1.0000
89.0200 3.9105 1.0000
89.0800 9.1621 1.0000
89.1400 11.1765 1.0000
89.2000 6.3429 1.0000
89.2600 4.7596 1.0000
89.3200 5.5859 1.0000
89.3800 3.1364 1.0000
89.4400 9.1334 1.0000
89.5000 4.5403 1.0000
89.5600 4.9607 1.0000
89.6200 11.2245 1.0000
89.6800 3.0952 1.0000
89.7400 4.0723 1.0000
89.8000 2.3267 1.0000
89.8600 1.8764 1.0000
89.9200 13.5297 1.0000
89.9800 2.6203 1.0000
90.0400 13.8951 1.0000
90.1000 2.8691 1.0000
90.1600 7.3669 1.0000
90.2200 3.9098 1.0000
90.2800 6.2540 1.0000
90.3400 3.1814 1.0000
90.4000 6.2291 1.0000
90.4600 4.0307 1.0000
90.5200 4.9506 1.0000
90.5800 4.6590 1.0000
90.6400 8.8421 1.0000
90.7000 1.8298 1.0000
90.7600 3.6560 1.0000
90.8200 3.9151 1.0000
90.8800 3.7231 1.0000
90.9400 6.4757 1.0000
91.0000 4.9447 1.0000
91.0600 7.4769 1.0000
91.1200 6.0048 1.0000
91.1800 8.4168 1.0000
91.2400 2.6383 1.0000
91.3000 8.4409 1.0000
91.3600 9.2906 1.0000
91.4200 6.7709 1.0000
91.4800 14.3610 1.0000
91.5400 14.0007 1.0000
91.6000 7.0046 1.0000
91.6600 6.8631 1.0000
91.7200 3.2887 1.0000
91.7800 6.4658 1.0000
91.8400 4.7711 1.0000
91.9000 4.8250 1.0000
91.9600 4.5392 1.0000
92.0200 9.2827 1.0000
92.0800 9.0413 1.0000
92.1400 6.1388 1.0000
92.2000 7.2611 1.0000
92.2600 6.4939 1.0000
92.3200 6.0693 1.0000
92.3800 7.8995 1.0000
92.4400 4.1390 1.0000
92.5000 5.4224 1.0000
92.5600 5.6677 1.0000
92.6200 3.9975 1.0000
92.6800 9.4395 1.0000
92.7400 3.5839 1.0000
92.8000 5.7282 1.0000
92.8600 3.9908 1.0000
92.9200 4.3255 1.0000
92.9800 3.2142 1.0000
93.0400 3.5269 1.0000
93.1000 6.1163 1.0000
93.1600 5.4678 1.0000
93.2200 11.0359 1.0000
93.2800 9.4086 1.0000
93.3400 3.1960 1.0000
93.4000 9.2107 1.0000
93.4600 7.1676 1.0000
93.5200 3.8200 1.0000
93.5800 3.2108 1.0000
93.6400 2.7128 1.0000
93.7000 6.2560 1.0000
93.7600 12.3607 1.0000
93.8200 12.3590 1.0000
93.8800 6.6130 1.0000
93.9400 7.9131 1.0000
94.0000 3.0385 1.0000
94.0600 5.4826 1.0000
94.1200 7.9801 1.0000
94.1800 9.2033 1.0000
94.2400 8.6947 1.0000
94.3000 6.5913 1.0000
94.3600 6.0584 1.0000
94.4200 7.7619 1.0000
94.4800 3.3547 1.0000
94.5400 5.2448 1.0000
94.6000 4.2069 1.0000
94.6600 5.6076 1.0000
94.7200 7.2968 1.0000
94.7800 6.3026 1.0000
94.8400 8.8675 1.0000
94.9000 15.5632 1.0000
94.9600 8.3740 1.0000
95.0200 7.3916 1.0000
95.0800 6.2429 1.0000
95.1400 10.2380 1.0000
95.2000 8.0423 1.0000
95.2600 6.1791 1.0000
95.3200 8.2450 1.0000
95.3800 5.9941 1.0000
95.4400 3.4297 1.0000
95.5000 7.2776 1.0000
95.5600 4.9978 1.0000
95.6200 5.4306 1.0000
95.6800 11.5665 1.0000
95.7400 4.7634 1.0000
95.8000 12.5375 1.0000
95.8600 7.4367 1.0000
95.9200 4.8981 1.0000
95.9800 7.7320 1.0000
96.0400 5.9088 1.0000
96.1000 6.3806 1.0000
96.1600 12.5456 1.0000
96.2200 4.3280 1.0000
96.2800 6.5689 1.0000
96.3400 6.7371 1.0000
96.4000 7.4963 1.0000
96.4600 6.0648 1.0000
96.5200 5.6051 1.0000
96.5800 5.6651 1.0000
96.6400 8.7707 1.0000
96.7000 2.7247 1.0000
96.7600 5.1683 1.0000
96.8200 5.4731 1.0000
96.8800 4.6765 1.0000
96.9400 8.1490 1.0000
97.0000 7.0125 1.0000
97.0600 4.1460 1.0000
97.1200 8.7298 1.0000
97.1800 7.4048 1.0000
97.2400 4.7169 1.0000
97.3000 8.0719 1.0000
97.3600 4.2413 1.0000
97.4200 5.8295 1.0000
97.4800 9.0365 1.0000
97.5400 4.8997 1.0000
97.6000 13.6312 1.0000
97.6600 9.0744 1.0000
97.7200 9.2176 1.0000
97.7800 5.8028 1.0000
97.8400 4.1325 1.0000
97.9000 8.6649 1.0000
97.9600 6.3545 1.0000
98.0200 5.0362 1.0000
98.0800 6.1806 1.0000
98.1400 5.3611 1.0000
98.2000 6.8181 1.0000
98.2600 5.9212 1.0000
98.3200 10.7329 1.0000
98.3800 9.4282 1.0000
98.4400 12.3159 1.0000
98.5000 10.0878 1.0000
98.5600 15.5996 1.0000
98.6200 14.3623 1.0000
98.6800 17.7260 1.0000
98.7400 13.7491 1.0000
98.8000 17.8491 1.0000
98.8600 12.5261 1.0000
98.9200 9.3750 1.0000
98.9800 12.0713 1.0000
99.0400 5.2847 1.0000
99.1000 4.9120 1.0000
99.1600 5.2777 1.0000
99.2200 9.7069 1.0000
99.2800 5.0147 1.0000
99.3400 11.8338 1.0000
99.4000 6.7720 1.0000
99.4600 3.0240 1.0000
99.5200 5.9030 1.0000
99.5800 2.1643 1.0000
99.6400 9.9117 1.0000
99.7000 10.4776 1.0000
99.7600 11.5638 1.0000
99.8200 3.1114 1.0000
99.8800 8.5399 1.0000
99.9400 5.0703 1.0000
100.0000 5.3629 1.0000
100.0600 4.8686 1.0000
100.1200 9.2758 1.0000
100.1800 4.9114 1.0000
100.2400 5.1544 1.0000
100.3000 6.0497 1.0000
100.3600 6.8456 1.0000
100.4200 7.0943 1.0000
100.4800 6.3363 1.0000
100.5400 2.3382 1.0000
100.6000 6.2818 1.0000
100.6600 6.3349 1.0000
100.7200 6.4889 1.0000
100.7800 8.0414 1.0000
100.8400 4.1611 1.0000
100.9000 6.9246 1.0000
100.9600 4.1709 1.0000
101.0200 6.7573 1.0000
101.0800 5.0057 1.0000
101.1400 3.1961 1.0000
101.2000 8.1679 1.0000
101.2600 6.7575 1.0000
101.3200 4.7528 1.0000
101.3800 6.5981 1.0000
101.4400 5.1761 1.0000
101.5000 8.2307 1.0000
101.5600 6.6404 1.0000
101.6200 6.1394 1.0000
101.6800 3.4802 1.0000
101.7400 3.9491 1.0000
101.8000 3.5231 1.0000
101.8600 5.7991 1.0000
101.9200 3.3525 1.0000
101.9800 5.3506 1.0000
102.0400 10.9163 1.0000
102.1000 7.2181 1.0000
102.1600 8.2053 1.0000
102.2200 7.2028 1.0000
102.2800 8.9826 1.0000
102.3400 8.6314 1.0000
102.4000 8.0567 1.0000
102.4600 6.5224 1.0000
102.5200 3.8236 1.0000
102.5800 7.6664 1.0000
102.6400 7.3723 1.0000
102.7000 9.3073 1.0000
102.7600 3.2286 1.0000
102.8200 6.8915 1.0000
102.8800 4.1589 1.0000
102.9400 8.8391 1.0000
103.0000 6.8791 1.0000
103.0600 6.0820 1.0000
103.1200 4.7784 1.0000
103.1800 5.2552 1.0000
103.2400 6.7569 1.0000
103.3000 9.0301 1.0000
103.3600 5.4478 1.0000
103.4200 3.6023 1.0000
103.4800 5.3315 1.0000
103.5400 4.1622 1.0000
103.6000 5.0642 1.0000
103.6600 7.6401 1.0000
103.7200 6.0906 1.0000
103.7800 4.2256 1.0000
103.8400 5.9466 1.0000
103.9000 6.0295 1.0000
103.9600 5.4164 1.0000
104.0200 4.1145 1.0000
104.0800 2.8092 1.0000
104.1400 4.0995 1.0000
104.2000 5.2017 1.0000
104.2600 9.6855 1.0000
104.3200 3.9929 1.0000
104.3800 6.4276 1.0000
104.4400 5.3957 1.0000
104.5000 4.4848 1.0000
104.5600 3.0996 1.0000
104.6200 6.8116 1.0000
104.6800 5.0677 1.0000
104.7400 6.5033 1.0000
104.8000 5.6809 1.0000
104.8600 2.5687 1.0000
104.9200 8.2123 1.0000
104.9800 6.5098 1.0000
105.0400 7.3224 1.0000
105.1000 6.7835 1.0000
105.1600 4.3675 1.0000
105.2200 4.0562 1.0000
105.2800 5.8748 1.0000
105.3400 4.9837 1.0000
105.4000 7.6583 1.0000
105.4600 3.2316 1.0000
105.5200 3.4588 1.0000
105.5800 7.9968 1.0000
105.6400 4.2637 1.0000
105.7000 9.9851 1.0000
105.7600 13.0236 1.0000
105.8200 9.4260 1.0000
105.8800 7.2905 1.0000
105.9400 10.2446 1.0000
106.0000 10.5938 1.0000
106.0600 10.0932 1.0000
106.1200 6.0326 1.0000
106.1800 6.9885 1.0000
106.2400 6.2377 1.0000
106.3000 4.0896 1.0000
106.3600 8.9779 1.0000
106.4200 5.8157 1.0000
106.4800 5.2696 1.0000
106.5400 4.8504 1.0000
106.6000 11.8701 1.0000
106.6600 5.5826 1.0000
106.7200 3.6007 1.0000
106.7800 1.0959 1.0000
106.8400 3.7003 1.0000
106.9000 9.2535 1.0000
106.9600 3.7406 1.0000
107.0200 13.8118 1.0000
107.0800 2.2809 1.0000
107.1400 4.4527 1.0000
107.2000 4.9253 1.0000
107.2600 7.0022 1.0000
107.3200 3.9918 1.0000
107.3800 7.4562 1.0000
107.4400 10.5116 1.0000
107.5000 5.6314 1.0000
107.5600 7.8190 1.0000
107.6200 6.8295 1.0000
107.6800 7.1551 1.0000
107.7400 5.7250 1.0000
107.8000 5.9703 1.0000
107.8600 5.1063 1.0000
107.9200 2.8996 1.0000
107.9800 1.9234 1.0000
108.0400 1.4718 1.0000
108.1000 8.0415 1.0000
108.1600 6.0079 1.0000
108.2200 10.0185 1.0000
108.2800 9.1748 1.0000
108.3400 5.4851 1.0000
108.4000 6.4648 1.0000
108.4600 6.0931 1.0000
108.5200 8.2355 1.0000
108.5800 6.7767 1.0000
108.6400 6.6599 1.0000
108.7000 2.7540 1.0000
108.7600 5.4992 1.0000
108.8200 7.7192 1.0000
108.8800 5.4806 1.0000
108.9400 4.2864 1.0000
109.0000 1.7088 1.0000
109.0600 3.1014 1.0000
109.1200 6.9555 1.0000
109.1800 7.7771 1.0000
109.2400 9.8252 1.0000
109.3000 7.8417 1.0000
109.3600 5.0945 1.0000
109.4200 4.1171 1.0000
109.4800 5.1581 1.0000
109.5400 4.2495 1.0000
109.6000 1.5890 1.0000
109.6600 3.1375 1.0000
109.7200 9.2159 1.0000
109.7800 6.2415 1.0000
109.8400 8.7444 1.0000
109.9000 3.6165 1.0000
109.9600 8.7044 1.0000
110.0200 3.7744 1.0000
110.0800 7.9959 1.0000
110.1400 6.2376 1.0000
110.2000 5.5656 1.0000
110.2600 2.6308 1.0000
110.3200 7.1166 1.0000
110.3800 7.2015 1.0000
110.4400 3.9156 1.0000
110.5000 8.1863 1.0000
110.5600 3.3738 1.0000
110.6200 9.4337 1.0000
110.6800 7.2376 1.0000
110.7400 4.8347 1.0000
110.8000 7.1266 1.0000
110.8600 5.9229 1.0000
110.9200 2.1542 1.0000
110.9800 5.0181 1.0000
111.0400 8.3575 1.0000
111.1000 7.7272 1.0000
111.1600 4.7410 1.0000
111.2200 5.1027 1.0000
111.2800 3.7300 1.0000
111.3400 10.2691 1.0000
111.4000 9.1818 1.0000
111.4600 4.3044 1.0000
111.5200 3.4060 1.0000
111.5800 6.0085 1.0000
111.6400 7.3234 1.0000
111.7000 5.2794 1.0000
111.7600 7.3111 1.0000
111.8200 8.5221 1.0000
111.8800 7.2112 1.0000
111.9400 3.9319 1.0000
112.0000 8.7936 1.0000
112.0600 3.2257 1.0000
112.1200 3.8362 1.0000
112.1800 7.2027 1.0000
112.2400 3.5238 1.0000
112.3000 10.6070 1.0000
112.3600 4.7170 1.0000
112.4200 9.4328 1.0000
112.4800 8.6103 1.0000
112.5400 4.7704 1.0000
112.6000 5.9515 1.0000
112.6600 3.3179 1.0000
112.7200 7.0450 1.0000
112.7800 10.0181 1.0000
112.8400 8.3874 1.0000
112.9000 8.1466 1.0000
112.9600 4.5639 1.0000
113.0200 6.6211 1.0000
113.0800 14.5484 1.0000
113.1400 6.8220 1.0000
113.2000 4.7981 1.0000
113.2600 6.2838 1.0000
113.3200 5.0416 1.0000
113.3800 8.6914 1.0000
113.4400 6.7348 1.0000
113.5000 1.8482 1.0000
113.5600 10.0762 1.0000
113.6200 6.0562 1.0000
113.6800 4.6298 1.0000
113.7400 8.6524 1.0000
113.8000 5.4507 1.0000
113.8600 7.2153 1.0000
113.9200 4.6227 1.0000
113.9800 11.4615 1.0000
114.0400 6.2843 1.0000
114.1000 9.1759 1.0000
114.1600 7.6214 1.0000
114.2200 5.4140 1.0000
114.2800 5.2033 1.0000
114.3400 11.0476 1.0000
114.4000 8.4274 1.0000
114.4600 5.0074 1.0000
114.5200 9.4353 1.0000
114.5800 7.2942 1.0000
114.6400 4.2201 1.0000
114.7000 8.4345 1.0000
114.7600 4.7087 1.0000
114.8200 0.9441 1.0000
114.8800 8.2384 1.0000
114.9400 3.0171 1.0000
115.0000 7.1380 1.0000
115.0600 2.8827 1.0000
115.1200 12.3279 1.0000
115.1800 3.7835 1.0000
115.2400 10.7756 1.0000
115.3000 6.7701 1.0000
115.3600 7.6085 1.0000
115.4200 4.8716 1.0000
115.4800 6.2192 1.0000
115.5400 8.1523 1.0000
115.6000 6.9784 1.0000
115.6600 10.6279 1.0000
115.7200 14.2026 1.0000
115.7800 13.2760 1.0000
115.8400 9.6632 1.0000
115.9000 12.3181 1.0000
115.9600 10.7263 1.0000
116.0200 15.0881 1.0000
116.0800 10.9095 1.0000
116.1400 14.0059 1.0000
116.2000 19.2171 1.0000
116.2600 9.1622 1.0000
116.3200 11.5994 1.0000
116.3800 8.5859 1.0000
116.4400 10.0302 1.0000
116.5000 10.0300 1.0000
116.5600 8.6815 1.0000
116.6200 11.3366 1.0000
116.6800 4.2665 1.0000
116.7400 6.6203 1.0000
116.8000 8.3567 1.0000
116.8600 9.4978 1.0000
116.9200 2.8038 1.0000
116.9800 6.0792 1.0000
117.0400 6.8427 1.0000
117.1000 7.4022 1.0000
117.1600 8.2149 1.0000
117.2200 7.8335 1.0000
117.2800 4.2762 1.0000
117.3400 7.4364 1.0000
117.4000 5.4464 1.0000
117.4600 13.7751 1.0000
117.5200 6.4129 1.0000
117.5800 4.2929 1.0000
117.6400 5.2465 1.0000
117.7000 2.2179 1.0000
117.7600 5.7792 1.0000
117.8200 7.0589 1.0000
117.8800 10.4208 1.0000
117.9400 7.2154 1.0000
118.0000 4.1712 1.0000
118.0600 5.2136 1.0000
118.1200 6.9308 1.0000
118.1800 4.9226 1.0000
118.2400 9.3944 1.0000
118.3000 4.8693 1.0000
118.3600 7.0234 1.0000
118.4200 3.2413 1.0000
118.4800 7.8812 1.0000
118.5400 3.5997 1.0000
118.6000 5.6752 1.0000
118.6600 9.1498 1.0000
118.7200 5.0701 1.0000
118.7800 3.6403 1.0000
118.8400 4.5244 1.0000
118.9000 6.7808 1.0000
118.9600 9.3285 1.0000
119.0200 6.2331 1.0000
119.0800 6.6054 1.0000
119.1400 8.7649 1.0000
119.2000 6.1538 1.0000
119.2600 12.0420 1.0000
119.3200 5.4674 1.0000
119.3800 9.5260 1.0000
119.4400 1.7992 1.0000
119.5000 6.0592 1.0000
119.5600 8.6475 1.0000
119.6200 4.4183 1.0000
119.6800 6.6516 1.0000
119.7400 7.3994 1.0000
119.8000 7.6026 1.0000
119.8600 2.1243 1.0000
119.9200 5.2333 1.0000
119.9800 5.2716 1.0000
119.9900 7.5298 1.0000
*RAS_INT_END
*RAS_TEMPERATURE_START
*RAS_TEMPERATURE_END
*RAS_DATA_END